Workbook

Sheet BẢNG CC
A1: BẢNG CHẤM CÔNG
P3: Tháng | R3: 6 | S3: Năm | T3: 2026 | AN3: =SUM(AN8:AN36) -> 708
A4: Thông tin nhân viên | D4: Các ngày trong tháng | AI4: Tổng Ngày Công | AM4: Tổng | AN4: Tổng ngày công tính lương | AO4: Ngày nhận việc
A5: STT | B5: Mã NV | C5: Họ và tên | D5: =DATE(T3,R3,1) -> 46174 | E5: =D5+1 -> 46175 | F5: =E5+1 -> 46176 | G5: =F5+1 -> 46177 | H5: =G5+1 -> 46178 | I5: =H5+1 -> 46179 | J5: =I5+1 -> 46180 | K5: =J5+1 -> 46181 | L5: =K5+1 -> 46182 | ... AH5: =AG5+1 -> 46204 | AI5: TT | AJ5: P | AK5: L | AL5: KL
D6: =TEXT(D5,"ddd") -> hai | E6: =TEXT(E5,"ddd") -> ba | F6: =TEXT(F5,"ddd") -> tư | G6: =TEXT(G5,"ddd") -> năm | H6: =TEXT(H5,"ddd") -> sáu | I6: =TEXT(I5,"ddd") -> bảy | J6: =TEXT(J5,"ddd") -> cn | K6: =TEXT(K5,"ddd") -> hai | ... AH6: =TEXT(AH5,"ddd") -> tư
A7: MEDIGO | AI7: =SUM(AI8:AI36) -> 689 | AJ7: =SUM(AJ8:AJ36) -> 19 | AK7: =SUM(AK8:AK36) -> 0 | AL7: =SUM(AL8:AL36) -> 0 | AM7: =SUM(AM8:AM36) -> 708 | AN7: =SUM(AN8:AN36) -> 708
A8: 1 | C8: Le Huu Ha | D8: 1 | E8: 1 | F8: 1 | G8: 1 | H8: 1 | I8: 1 | K8: 1 | L8: 1 | M8: 1 | N8: 1 | O8: 1 | P8: 1 | R8: 1 | S8: 1 | T8: 1 | U8: 1 | V8: 1 | W8: 1 | Y8: 1 | Z8: 1 | AA8: 1 | AB8: 1 | AC8: 1 | AD8: 1 | AF8: 1 | AG8: 1 | AI8: =SUM(D8:AH8)+(COUNTIF(D8:AH8,"0,5KL")/2)+(COUNTIF(D8:AH8,"0,5P")/2)+(COUNTIF(D8:AH8,"0.5L")/2) -> 26 | AJ8: =(COUNTIF(D8:AG8,"P"))+(COUNTIF(D8:AG8,"P/2")/2)+(COUNTIF(D8:AG8,"0,5P")/2)+(COUNTIF(D8:AG8,"L/P")/2)+(COUNTIF(D8:AG8,"P/KL")/2) -> 0 | AK8: =COUNTIF(D8:AG8,"L")+(COUNTIF(D8:AG8,"L/2")/2)+(COUNTIF(D8:AG8,"L/P")/2)+(COUNTIF(D8:AG8,"L/KL")/2) -> 0 | AL8: =COUNTIF(D8:AG8,"KL")+COUNTIF(D8:AG8,"0,5KL")/2+COUNTIF(D8:AG8,"L/KL")/2+COUNTIF(D8:AG8,"KL/2")/2+COUNTIF(D8:AG8,"P/KL")/2+COUNTIF(D8:AG8,"0.5")/2 -> 0 | AM8: =SUM(AI8:AL8) -> 26 | AN8: =AI8+AJ8+AK8 -> 26 | AO8: 2019
A9: 2 | C9: Trần Thị Minh Phượng | D9: 1 | E9: 1 | F9: 1 | G9: 1 | H9: 1 | I9: 1 | K9: 1 | L9: 1 | M9: 1 | N9: 1 | O9: 1 | P9: 0,5P | R9: 1 | S9: 1 | T9: 1 | U9: 1 | V9: 1 | W9: 1 | Y9: 1 | Z9: 1 | AA9: 1 | AB9: 1 | AC9: 1 | AD9: 1 | AF9: 1 | AG9: 1 | AI9: =SUM(D9:AH9)+(COUNTIF(D9:AH9,"0,5KL")/2)+(COUNTIF(D9:AH9,"0,5P")/2)+(COUNTIF(D9:AH9,"0.5L")/2) -> 25.5 | AJ9: =(COUNTIF(D9:AG9,"P"))+(COUNTIF(D9:AG9,"P/2")/2)+(COUNTIF(D9:AG9,"0,5P")/2)+(COUNTIF(D9:AG9,"L/P")/2)+(COUNTIF(D9:AG9,"P/KL")/2) -> 0.5 | AK9: =COUNTIF(D9:AG9,"L")+(COUNTIF(D9:AG9,"L/2")/2)+(COUNTIF(D9:AG9,"L/P")/2)+(COUNTIF(D9:AG9,"L/KL")/2) -> 0 | AL9: =COUNTIF(D9:AG9,"KL")+COUNTIF(D9:AG9,"0,5KL")/2+COUNTIF(D9:AG9,"L/KL")/2+COUNTIF(D9:AG9,"KL/2")/2+COUNTIF(D9:AG9,"P/KL")/2+COUNTIF(D9:AG9,"0.5")/2 -> 0 | AM9: =SUM(AI9:AL9) -> 26 | AN9: =AI9+AJ9+AK9 -> 26 | AO9: =VLOOKUP(C9,'[1]1. MEDIGO'!$C$4:$BL$100,62,0) -> 2/2/2026
A10: 3 | C10: Nguyễn Thị Thúy Na | D10: 1 | E10: 1 | F10: 1 | G10: 1 | H10: 1 | I10: 1 | K10: P | L10: 1 | M10: 1 | N10: 1 | O10: 1 | P10: 1 | R10: 1 | S10: 1 | T10: 1 | U10: 1 | V10: 1 | W10: 1 | Y10: 1 | Z10: 1 | AA10: 1 | AB10: 1 | AC10: 1 | AD10: 1 | AF10: 1 | AG10: 1 | AI10: =SUM(D10:AH10)+(COUNTIF(D10:AH10,"0,5KL")/2)+(COUNTIF(D10:AH10,"0,5P")/2)+(COUNTIF(D10:AH10,"0.5L")/2) -> 25 | AJ10: =(COUNTIF(D10:AG10,"P"))+(COUNTIF(D10:AG10,"P/2")/2)+(COUNTIF(D10:AG10,"0,5P")/2)+(COUNTIF(D10:AG10,"L/P")/2)+(COUNTIF(D10:AG10,"P/KL")/2) -> 1 | AK10: =COUNTIF(D10:AG10,"L")+(COUNTIF(D10:AG10,"L/2")/2)+(COUNTIF(D10:AG10,"L/P")/2)+(COUNTIF(D10:AG10,"L/KL")/2) -> 0 | AL10: =COUNTIF(D10:AG10,"KL")+COUNTIF(D10:AG10,"0,5KL")/2+COUNTIF(D10:AG10,"L/KL")/2+COUNTIF(D10:AG10,"KL/2")/2+COUNTIF(D10:AG10,"P/KL")/2+COUNTIF(D10:AG10,"0.5")/2 -> 0 | AM10: =SUM(AI10:AL10) -> 26 | AN10: =AI10+AJ10+AK10 -> 26 | AO10: =VLOOKUP(C10,'[1]1. MEDIGO'!$C$4:$BL$100,62,0) -> 14/8/2025
A11: 4 | C11: Nguyễn Thành Tài | D11: 1 | E11: 1 | F11: 1 | G11: 1 | H11: 1 | I11: 1 | K11: 1 | L11: 1 | M11: 1 | N11: 1 | O11: 1 | P11: 1 | R11: 1 | S11: 1 | T11: 1 | U11: 1 | V11: 1 | W11: 0,5P | Y11: 1 | Z11: 1 | AA11: 1 | AB11: 1 | AC11: 1 | AD11: 1 | AF11: 1 | AG11: 1 | AI11: =SUM(D11:AH11)+(COUNTIF(D11:AH11,"0,5KL")/2)+(COUNTIF(D11:AH11,"0,5P")/2)+(COUNTIF(D11:AH11,"0.5L")/2) -> 25.5 | AJ11: =(COUNTIF(D11:AG11,"P"))+(COUNTIF(D11:AG11,"P/2")/2)+(COUNTIF(D11:AG11,"0,5P")/2)+(COUNTIF(D11:AG11,"L/P")/2)+(COUNTIF(D11:AG11,"P/KL")/2) -> 0.5 | AK11: =COUNTIF(D11:AG11,"L")+(COUNTIF(D11:AG11,"L/2")/2)+(COUNTIF(D11:AG11,"L/P")/2)+(COUNTIF(D11:AG11,"L/KL")/2) -> 0 | AL11: =COUNTIF(D11:AG11,"KL")+COUNTIF(D11:AG11,"0,5KL")/2+COUNTIF(D11:AG11,"L/KL")/2+COUNTIF(D11:AG11,"KL/2")/2+COUNTIF(D11:AG11,"P/KL")/2+COUNTIF(D11:AG11,"0.5")/2 -> 0 | AM11: =SUM(AI11:AL11) -> 26 | AN11: =AI11+AJ11+AK11 -> 26 | AO11: =VLOOKUP(C11,'[1]1. MEDIGO'!$C$4:$BL$100,62,0) -> 28/3/2022
A12: 5 | C12: Tô Ngọc Thiên Phú | D12: 1 | E12: 1 | F12: 1 | G12: 1 | H12: 1 | I12: 1 | K12: P | L12: 1 | M12: 1 | N12: 1 | O12: 1 | P12: 1 | R12: 1 | S12: 1 | T12: 1 | U12: 1 | V12: 1 | W12: 0,5P | Y12: 1 | Z12: 1 | AA12: 1 | AB12: 1 | AC12: 0,5P | AD12: 0,5P | AF12: 1 | AG12: 1 | AI12: =SUM(D12:AH12)+(COUNTIF(D12:AH12,"0,5KL")/2)+(COUNTIF(D12:AH12,"0,5P")/2)+(COUNTIF(D12:AH12,"0.5L")/2) -> 23.5 | AJ12: =(COUNTIF(D12:AG12,"P"))+(COUNTIF(D12:AG12,"P/2")/2)+(COUNTIF(D12:AG12,"0,5P")/2)+(COUNTIF(D12:AG12,"L/P")/2)+(COUNTIF(D12:AG12,"P/KL")/2) -> 2.5 | AK12: =COUNTIF(D12:AG12,"L")+(COUNTIF(D12:AG12,"L/2")/2)+(COUNTIF(D12:AG12,"L/P")/2)+(COUNTIF(D12:AG12,"L/KL")/2) -> 0 | AL12: =COUNTIF(D12:AG12,"KL")+COUNTIF(D12:AG12,"0,5KL")/2+COUNTIF(D12:AG12,"L/KL")/2+COUNTIF(D12:AG12,"KL/2")/2+COUNTIF(D12:AG12,"P/KL")/2+COUNTIF(D12:AG12,"0.5")/2 -> 0 | AM12: =SUM(AI12:AL12) -> 26 | AN12: =AI12+AJ12+AK12 -> 26 | AO12: =VLOOKUP(C12,'[1]1. MEDIGO'!$C$4:$BL$100,62,0) -> 27/10/2025
A13: 6 | C13: Huỳnh Quang Toàn | D13: 1 | E13: 1 | F13: 1 | G13: 1 | H13: 1 | I13: 1 | K13: 1 | L13: 1 | M13: 1 | N13: 1 | O13: 1 | P13: 1 | R13: 1 | S13: 1 | T13: 1 | U13: 1 | V13: 1 | W13: 1 | Y13: 1 | Z13: 1 | AA13: 1 | AB13: 1 | AC13: 1 | AD13: 1 | AF13: 1 | AG13: 1 | AI13: =SUM(D13:AH13)+(COUNTIF(D13:AH13,"0,5KL")/2)+(COUNTIF(D13:AH13,"0,5P")/2)+(COUNTIF(D13:AH13,"0.5L")/2) -> 26 | AJ13: =(COUNTIF(D13:AG13,"P"))+(COUNTIF(D13:AG13,"P/2")/2)+(COUNTIF(D13:AG13,"0,5P")/2)+(COUNTIF(D13:AG13,"L/P")/2)+(COUNTIF(D13:AG13,"P/KL")/2) -> 0 | AK13: =COUNTIF(D13:AG13,"L")+(COUNTIF(D13:AG13,"L/2")/2)+(COUNTIF(D13:AG13,"L/P")/2)+(COUNTIF(D13:AG13,"L/KL")/2) -> 0 | AL13: =COUNTIF(D13:AG13,"KL")+COUNTIF(D13:AG13,"0,5KL")/2+COUNTIF(D13:AG13,"L/KL")/2+COUNTIF(D13:AG13,"KL/2")/2+COUNTIF(D13:AG13,"P/KL")/2+COUNTIF(D13:AG13,"0.5")/2 -> 0 | AM13: =SUM(AI13:AL13) -> 26 | AN13: =AI13+AJ13+AK13 -> 26 | AO13: HĐ CÔNG TÁC VIÊN TỪ THÁNG 4/2026
C14: Nguyễn Tuấn Vinh | D14: 1 | E14: 1 | AI14: =SUM(D14:AH14)+(COUNTIF(D14:AH14,"0,5KL")/2)+(COUNTIF(D14:AH14,"0,5P")/2)+(COUNTIF(D14:AH14,"0.5L")/2) -> 2 | AJ14: =(COUNTIF(D14:AG14,"P"))+(COUNTIF(D14:AG14,"P/2")/2)+(COUNTIF(D14:AG14,"0,5P")/2)+(COUNTIF(D14:AG14,"L/P")/2)+(COUNTIF(D14:AG14,"P/KL")/2) -> 0 | AK14: =COUNTIF(D14:AG14,"L")+(COUNTIF(D14:AG14,"L/2")/2)+(COUNTIF(D14:AG14,"L/P")/2)+(COUNTIF(D14:AG14,"L/KL")/2) -> 0 | AL14: =COUNTIF(D14:AG14,"KL")+COUNTIF(D14:AG14,"0,5KL")/2+COUNTIF(D14:AG14,"L/KL")/2+COUNTIF(D14:AG14,"KL/2")/2+COUNTIF(D14:AG14,"P/KL")/2+COUNTIF(D14:AG14,"0.5")/2 -> 0 | AM14: =SUM(AI14:AL14) -> 2 | AN14: =AI14+AJ14+AK14 -> 2 | AO14: HĐ CÔNG TÁC VIÊN TỪ THÁNG 5/2026
A15: 7 | C15: Hoàng Lê Thanh Vương | D15: 1 | E15: 1 | F15: 1 | G15: 1 | H15: 1 | I15: 1 | K15: 1 | L15: 1 | M15: 1 | N15: 1 | O15: 1 | P15: 0,5P | R15: 1 | S15: 1 | T15: 1 | U15: 1 | V15: 1 | W15: 1 | Y15: 1 | Z15: 1 | AA15: 1 | AB15: 1 | AC15: 1 | AD15: 1 | AF15: 1 | AG15: 1 | AI15: =SUM(D15:AH15)+(COUNTIF(D15:AH15,"0,5KL")/2)+(COUNTIF(D15:AH15,"0,5P")/2)+(COUNTIF(D15:AH15,"0.5L")/2) -> 25.5 | AJ15: =(COUNTIF(D15:AG15,"P"))+(COUNTIF(D15:AG15,"P/2")/2)+(COUNTIF(D15:AG15,"0,5P")/2)+(COUNTIF(D15:AG15,"L/P")/2)+(COUNTIF(D15:AG15,"P/KL")/2) -> 0.5 | AK15: =COUNTIF(D15:AG15,"L")+(COUNTIF(D15:AG15,"L/2")/2)+(COUNTIF(D15:AG15,"L/P")/2)+(COUNTIF(D15:AG15,"L/KL")/2) -> 0 | AL15: =COUNTIF(D15:AG15,"KL")+COUNTIF(D15:AG15,"0,5KL")/2+COUNTIF(D15:AG15,"L/KL")/2+COUNTIF(D15:AG15,"KL/2")/2+COUNTIF(D15:AG15,"P/KL")/2+COUNTIF(D15:AG15,"0.5")/2 -> 0 | AM15: =SUM(AI15:AL15) -> 26 | AN15: =AI15+AJ15+AK15 -> 26 | AO15: =VLOOKUP(C15,'[1]1. MEDIGO'!$C$4:$BL$100,62,0) -> 3/11/2025
A16: 8 | C16: Nguyễn Hoàng Nguyên Đan | D16: 1 | E16: 1 | F16: 1 | G16: 1 | H16: 1 | I16: 1 | K16: 1 | L16: 1 | M16: 1 | N16: 1 | O16: 1 | P16: 1 | R16: 1 | S16: 1 | T16: 1 | U16: 1 | V16: 1 | W16: 1 | Y16: 1 | Z16: 1 | AA16: 1 | AB16: 1 | AC16: 1 | AD16: 1 | AF16: 1 | AG16: P | AI16: =SUM(D16:AH16)+(COUNTIF(D16:AH16,"0,5KL")/2)+(COUNTIF(D16:AH16,"0,5P")/2)+(COUNTIF(D16:AH16,"0.5L")/2) -> 25 | AJ16: =(COUNTIF(D16:AG16,"P"))+(COUNTIF(D16:AG16,"P/2")/2)+(COUNTIF(D16:AG16,"0,5P")/2)+(COUNTIF(D16:AG16,"L/P")/2)+(COUNTIF(D16:AG16,"P/KL")/2) -> 1 | AK16: =COUNTIF(D16:AG16,"L")+(COUNTIF(D16:AG16,"L/2")/2)+(COUNTIF(D16:AG16,"L/P")/2)+(COUNTIF(D16:AG16,"L/KL")/2) -> 0 | AL16: =COUNTIF(D16:AG16,"KL")+COUNTIF(D16:AG16,"0,5KL")/2+COUNTIF(D16:AG16,"L/KL")/2+COUNTIF(D16:AG16,"KL/2")/2+COUNTIF(D16:AG16,"P/KL")/2+COUNTIF(D16:AG16,"0.5")/2 -> 0 | AM16: =SUM(AI16:AL16) -> 26 | AN16: =AI16+AJ16+AK16 -> 26 | AO16: =VLOOKUP(C16,'[1]1. MEDIGO'!$C$4:$BL$100,62,0) -> 8/9/2021
A17: 9 | C17: Nguyễn Văn Toàn | D17: 1 | E17: 1 | F17: 1 | G17: 1 | H17: 1 | I17: 1 | K17: 1 | L17: 1 | M17: 1 | N17: 1 | O17: 1 | P17: 1 | R17: 1 | S17: 1 | T17: 1 | U17: 1 | V17: 1 | W17: 1 | Y17: 1 | Z17: 1 | AA17: 1 | AB17: 1 | AC17: 1 | AD17: 1 | AF17: 1 | AG17: 1 | AI17: =SUM(D17:AH17)+(COUNTIF(D17:AH17,"0,5KL")/2)+(COUNTIF(D17:AH17,"0,5P")/2)+(COUNTIF(D17:AH17,"0.5L")/2) -> 26 | AJ17: =(COUNTIF(D17:AG17,"P"))+(COUNTIF(D17:AG17,"P/2")/2)+(COUNTIF(D17:AG17,"0,5P")/2)+(COUNTIF(D17:AG17,"L/P")/2)+(COUNTIF(D17:AG17,"P/KL")/2) -> 0 | AK17: =COUNTIF(D17:AG17,"L")+(COUNTIF(D17:AG17,"L/2")/2)+(COUNTIF(D17:AG17,"L/P")/2)+(COUNTIF(D17:AG17,"L/KL")/2) -> 0 | AL17: =COUNTIF(D17:AG17,"KL")+COUNTIF(D17:AG17,"0,5KL")/2+COUNTIF(D17:AG17,"L/KL")/2+COUNTIF(D17:AG17,"KL/2")/2+COUNTIF(D17:AG17,"P/KL")/2+COUNTIF(D17:AG17,"0.5")/2 -> 0 | AM17: =SUM(AI17:AL17) -> 26 | AN17: =AI17+AJ17+AK17 -> 26 | AO17: =VLOOKUP(C17,'[1]1. MEDIGO'!$C$4:$BL$100,62,0) -> 7/7/2025
A18: 10 | C18: Lê Phú Quí | D18: 1 | E18: 1 | F18: 1 | G18: 1 | H18: 1 | I18: 1 | K18: 1 | L18: 1 | M18: 1 | N18: 1 | O18: 1 | P18: 1 | R18: 1 | S18: 1 | T18: 1 | U18: 1 | V18: 1 | W18: 1 | Y18: 1 | Z18: 1 | AA18: 0,5P | AB18: 1 | AC18: 1 | AD18: 1 | AF18: 1 | AG18: 1 | AI18: =SUM(D18:AH18)+(COUNTIF(D18:AH18,"0,5KL")/2)+(COUNTIF(D18:AH18,"0,5P")/2)+(COUNTIF(D18:AH18,"0.5L")/2) -> 25.5 | AJ18: =(COUNTIF(D18:AG18,"P"))+(COUNTIF(D18:AG18,"P/2")/2)+(COUNTIF(D18:AG18,"0,5P")/2)+(COUNTIF(D18:AG18,"L/P")/2)+(COUNTIF(D18:AG18,"P/KL")/2) -> 0.5 | AK18: =COUNTIF(D18:AG18,"L")+(COUNTIF(D18:AG18,"L/2")/2)+(COUNTIF(D18:AG18,"L/P")/2)+(COUNTIF(D18:AG18,"L/KL")/2) -> 0 | AL18: =COUNTIF(D18:AG18,"KL")+COUNTIF(D18:AG18,"0,5KL")/2+COUNTIF(D18:AG18,"L/KL")/2+COUNTIF(D18:AG18,"KL/2")/2+COUNTIF(D18:AG18,"P/KL")/2+COUNTIF(D18:AG18,"0.5")/2 -> 0 | AM18: =SUM(AI18:AL18) -> 26 | AN18: =AI18+AJ18+AK18 -> 26 | AO18: =VLOOKUP(C18,'[1]1. MEDIGO'!$C$4:$BL$100,62,0) -> 20/6/2024
A19: 11 | C19: Nguyễn Hồ Phương Anh | D19: 1 | E19: 1 | G19: 1 | H19: 1 | I19: 1 | J19: 1 | K19: 1 | L19: 1 | M19: 1 | N19: 1 | O19: 1 | P19: 1 | R19: 1 | S19: 1 | U19: 1 | V19: 1 | W19: 1 | X19: 1 | Y19: 1 | AA19: 1 | AB19: 1 | AC19: 1 | AD19: 1 | AE19: 1 | AF19: P | AI19: =SUM(D19:AH19)+(COUNTIF(D19:AH19,"0,5KL")/2)+(COUNTIF(D19:AH19,"0,5P")/2)+(COUNTIF(D19:AH19,"0.5L")/2) -> 24 | AJ19: =(COUNTIF(D19:AG19,"P"))+(COUNTIF(D19:AG19,"P/2")/2)+(COUNTIF(D19:AG19,"0,5P")/2)+(COUNTIF(D19:AG19,"L/P")/2)+(COUNTIF(D19:AG19,"P/KL")/2) -> 1 | AK19: =COUNTIF(D19:AG19,"L")+(COUNTIF(D19:AG19,"L/2")/2)+(COUNTIF(D19:AG19,"L/P")/2)+(COUNTIF(D19:AG19,"L/KL")/2) -> 0 | AL19: =COUNTIF(D19:AG19,"KL")+COUNTIF(D19:AG19,"0,5KL")/2+COUNTIF(D19:AG19,"L/KL")/2+COUNTIF(D19:AG19,"KL/2")/2+COUNTIF(D19:AG19,"P/KL")/2+COUNTIF(D19:AG19,"0.5")/2 -> 0 | AM19: =SUM(AI19:AL19) -> 25 | AN19: =AI19+AJ19+AK19 -> 25 | AO19: =VLOOKUP(C19,'[1]1. MEDIGO'!$C$4:$BL$100,62,0) -> 27/7/2021
A20: 12 | C20: Nguyễn Thị Ngọc Hân | D20: 1 | E20: 1 | F20: 1 | G20: 1 | H20: 1 | I20: 1 | K20: 1 | L20: 1 | M20: 1 | N20: P | P20: 1 | Q20: 1 | R20: 1 | T20: 1 | U20: 1 | V20: 1 | W20: 1 | X20: 1 | Z20: 1 | AA20: 1 | AB20: 1 | AC20: 1 | AD20: 1 | AE20: 1 | AF20: 1 | AG20: 1 | AI20: =SUM(D20:AH20)+(COUNTIF(D20:AH20,"0,5KL")/2)+(COUNTIF(D20:AH20,"0,5P")/2)+(COUNTIF(D20:AH20,"0.5L")/2) -> 25 | AJ20: =(COUNTIF(D20:AG20,"P"))+(COUNTIF(D20:AG20,"P/2")/2)+(COUNTIF(D20:AG20,"0,5P")/2)+(COUNTIF(D20:AG20,"L/P")/2)+(COUNTIF(D20:AG20,"P/KL")/2) -> 1 | AK20: =COUNTIF(D20:AG20,"L")+(COUNTIF(D20:AG20,"L/2")/2)+(COUNTIF(D20:AG20,"L/P")/2)+(COUNTIF(D20:AG20,"L/KL")/2) -> 0 | AL20: =COUNTIF(D20:AG20,"KL")+COUNTIF(D20:AG20,"0,5KL")/2+COUNTIF(D20:AG20,"L/KL")/2+COUNTIF(D20:AG20,"KL/2")/2+COUNTIF(D20:AG20,"P/KL")/2+COUNTIF(D20:AG20,"0.5")/2 -> 0 | AM20: =SUM(AI20:AL20) -> 26 | AN20: =AI20+AJ20+AK20 -> 26 | AO20: =VLOOKUP(C20,'[1]1. MEDIGO'!$C$4:$BL$100,62,0) -> 28/2/2022
A21: 13 | C21: Võ Thị Diệu Hiền | D21: 1 | E21: 1 | F21: 1 | G21: 1 | I21: 1 | J21: 1 | K21: 1 | M21: 1 | N21: 1 | O21: 1 | P21: 1 | Q21: 1 | S21: 1 | T21: 1 | U21: 1 | V21: 1 | W21: 1 | X21: P | Y21: 1 | Z21: 1 | AA21: 1 | AB21: 1 | AC21: 1 | AD21: 1 | AF21: 1 | AG21: 1 | AI21: =SUM(D21:AH21)+(COUNTIF(D21:AH21,"0,5KL")/2)+(COUNTIF(D21:AH21,"0,5P")/2)+(COUNTIF(D21:AH21,"0.5L")/2) -> 25 | AJ21: =(COUNTIF(D21:AG21,"P"))+(COUNTIF(D21:AG21,"P/2")/2)+(COUNTIF(D21:AG21,"0,5P")/2)+(COUNTIF(D21:AG21,"L/P")/2)+(COUNTIF(D21:AG21,"P/KL")/2) -> 1 | AK21: =COUNTIF(D21:AG21,"L")+(COUNTIF(D21:AG21,"L/2")/2)+(COUNTIF(D21:AG21,"L/P")/2)+(COUNTIF(D21:AG21,"L/KL")/2) -> 0 | AL21: =COUNTIF(D21:AG21,"KL")+COUNTIF(D21:AG21,"0,5KL")/2+COUNTIF(D21:AG21,"L/KL")/2+COUNTIF(D21:AG21,"KL/2")/2+COUNTIF(D21:AG21,"P/KL")/2+COUNTIF(D21:AG21,"0.5")/2 -> 0 | AM21: =SUM(AI21:AL21) -> 26 | AN21: =AI21+AJ21+AK21 -> 26 | AO21: =VLOOKUP(C21,'[1]1. MEDIGO'!$C$4:$BL$100,62,0) -> 10/8/2023
A22: 14 | C22: Lưu Thanh Tuyền | E22: P | F22: 1 | G22: 1 | H22: 1 | I22: 1 | J22: 1 | K22: 1 | L22: 1 | N22: 1 | O22: 1 | P22: 1 | Q22: 1 | R22: 1 | S22: 1 | T22: 1 | V22: 1 | W22: 1 | X22: 1 | Y22: 1 | Z22: 1 | AA22: 1 | AC22: 1 | AD22: 1 | AE22: 1 | AF22: 1 | AG22: 1 | AI22: =SUM(D22:AH22)+(COUNTIF(D22:AH22,"0,5KL")/2)+(COUNTIF(D22:AH22,"0,5P")/2)+(COUNTIF(D22:AH22,"0.5L")/2) -> 25 | AJ22: =(COUNTIF(D22:AG22,"P"))+(COUNTIF(D22:AG22,"P/2")/2)+(COUNTIF(D22:AG22,"0,5P")/2)+(COUNTIF(D22:AG22,"L/P")/2)+(COUNTIF(D22:AG22,"P/KL")/2) -> 1 | AK22: =COUNTIF(D22:AG22,"L")+(COUNTIF(D22:AG22,"L/2")/2)+(COUNTIF(D22:AG22,"L/P")/2)+(COUNTIF(D22:AG22,"L/KL")/2) -> 0 | AL22: =COUNTIF(D22:AG22,"KL")+COUNTIF(D22:AG22,"0,5KL")/2+COUNTIF(D22:AG22,"L/KL")/2+COUNTIF(D22:AG22,"KL/2")/2+COUNTIF(D22:AG22,"P/KL")/2+COUNTIF(D22:AG22,"0.5")/2 -> 0 | AM22: =SUM(AI22:AL22) -> 26 | AN22: =AI22+AJ22+AK22 -> 26 | AO22: =VLOOKUP(C22,'[1]1. MEDIGO'!$C$4:$BL$100,62,0) -> 30/12/2019
A23: 15 | C23: Võ Tấn Trường | D23: 1 | E23: 1 | F23: 1 | G23: 1 | H23: 1 | J23: 1 | K23: 1 | L23: 1 | M23: 1 | N23: 1 | O23: 1 | Q23: 1 | R23: 1 | S23: 1 | T23: 1 | U23: 1 | V23: 1 | X23: 1 | Y23: 1 | Z23: 1 | AA23: 1 | AB23: 1 | AC23: 1 | AE23: 1 | AF23: 1 | AG23: 1 | AI23: =SUM(D23:AH23)+(COUNTIF(D23:AH23,"0,5KL")/2)+(COUNTIF(D23:AH23,"0,5P")/2)+(COUNTIF(D23:AH23,"0.5L")/2) -> 26 | AJ23: =(COUNTIF(D23:AG23,"P"))+(COUNTIF(D23:AG23,"P/2")/2)+(COUNTIF(D23:AG23,"0,5P")/2)+(COUNTIF(D23:AG23,"L/P")/2)+(COUNTIF(D23:AG23,"P/KL")/2) -> 0 | AK23: =COUNTIF(D23:AG23,"L")+(COUNTIF(D23:AG23,"L/2")/2)+(COUNTIF(D23:AG23,"L/P")/2)+(COUNTIF(D23:AG23,"L/KL")/2) -> 0 | AL23: =COUNTIF(D23:AG23,"KL")+COUNTIF(D23:AG23,"0,5KL")/2+COUNTIF(D23:AG23,"L/KL")/2+COUNTIF(D23:AG23,"KL/2")/2+COUNTIF(D23:AG23,"P/KL")/2+COUNTIF(D23:AG23,"0.5")/2 -> 0 | AM23: =SUM(AI23:AL23) -> 26 | AN23: =AI23+AJ23+AK23 -> 26 | AO23: =VLOOKUP(C23,'[1]1. MEDIGO'!$C$4:$BL$100,62,0) -> 14/4/2025
A24: 16 | C24: Trần Thị Tâm Nhung | D24: 1 | E24: 1 | F24: 1 | H24: 1 | I24: 1 | J24: 1 | L24: 1 | M24: 1 | N24: 1 | O24: 1 | P24: 1 | Q24: 1 | R24: 1 | S24: 1 | T24: 1 | U24: 1 | W24: 1 | X24: 1 | Y24: 1 | Z24: 1 | AB24: 1 | AC24: 1 | AD24: 1 | AE24: 1 | AF24: 1 | AG24: 1 | AI24: =SUM(D24:AH24)+(COUNTIF(D24:AH24,"0,5KL")/2)+(COUNTIF(D24:AH24,"0,5P")/2)+(COUNTIF(D24:AH24,"0.5L")/2) -> 26 | AJ24: =(COUNTIF(D24:AG24,"P"))+(COUNTIF(D24:AG24,"P/2")/2)+(COUNTIF(D24:AG24,"0,5P")/2)+(COUNTIF(D24:AG24,"L/P")/2)+(COUNTIF(D24:AG24,"P/KL")/2) -> 0 | AK24: =COUNTIF(D24:AG24,"L")+(COUNTIF(D24:AG24,"L/2")/2)+(COUNTIF(D24:AG24,"L/P")/2)+(COUNTIF(D24:AG24,"L/KL")/2) -> 0 | AL24: =COUNTIF(D24:AG24,"KL")+COUNTIF(D24:AG24,"0,5KL")/2+COUNTIF(D24:AG24,"L/KL")/2+COUNTIF(D24:AG24,"KL/2")/2+COUNTIF(D24:AG24,"P/KL")/2+COUNTIF(D24:AG24,"0.5")/2 -> 0 | AM24: =SUM(AI24:AL24) -> 26 | AN24: =AI24+AJ24+AK24 -> 26 | AO24: =VLOOKUP(C24,'[1]1. MEDIGO'!$C$4:$BL$100,62,0) -> 20/8/2025
A25: 17 | C25: Nguyễn Tuấn Nghĩa | D25: 1 | E25: 1 | F25: 1 | G25: 1 | H25: 1 | I25: 1 | K25: 1 | L25: 1 | M25: 1 | N25: 1 | O25: 1 | P25: 1 | R25: 1 | S25: 1 | T25: 1 | U25: 1 | V25: 1 | W25: 1 | Y25: 1 | Z25: 1 | AA25: 1 | AB25: 1 | AC25: 1 | AD25: 1 | AF25: 1 | AG25: 1 | AI25: =SUM(D25:AH25)+(COUNTIF(D25:AH25,"0,5KL")/2)+(COUNTIF(D25:AH25,"0,5P")/2)+(COUNTIF(D25:AH25,"0.5L")/2) -> 26 | AJ25: =(COUNTIF(D25:AG25,"P"))+(COUNTIF(D25:AG25,"P/2")/2)+(COUNTIF(D25:AG25,"0,5P")/2)+(COUNTIF(D25:AG25,"L/P")/2)+(COUNTIF(D25:AG25,"P/KL")/2) -> 0 | AK25: =COUNTIF(D25:AG25,"L")+(COUNTIF(D25:AG25,"L/2")/2)+(COUNTIF(D25:AG25,"L/P")/2)+(COUNTIF(D25:AG25,"L/KL")/2) -> 0 | AL25: 0 | AM25: =SUM(AI25:AL25) -> 26 | AN25: =AI25+AJ25+AK25 -> 26 | AO25: =VLOOKUP(C25,'[1]1. MEDIGO'!$C$4:$BL$100,62,0) -> 18/9/2023
A26: 18 | C26: Nguyễn Thị Cẩm Bình | D26: 1 | E26: 1 | F26: P | G26: P | H26: P | I26: 1 | K26: 1 | L26: 1 | M26: 1 | N26: 1 | O26: 1 | P26: 1 | R26: 1 | S26: 1 | T26: 1 | U26: 1 | V26: 1 | W26: 1 | Y26: 1 | Z26: 1 | AA26: 1 | AB26: 1 | AC26: 1 | AD26: 1 | AF26: 1 | AG26: 1 | AI26: =SUM(D26:AH26)+(COUNTIF(D26:AH26,"0,5KL")/2)+(COUNTIF(D26:AH26,"0,5P")/2)+(COUNTIF(D26:AH26,"0.5L")/2) -> 23 | AJ26: =(COUNTIF(D26:AG26,"P"))+(COUNTIF(D26:AG26,"P/2")/2)+(COUNTIF(D26:AG26,"0,5P")/2)+(COUNTIF(D26:AG26,"L/P")/2)+(COUNTIF(D26:AG26,"P/KL")/2) -> 3 | AK26: =COUNTIF(D26:AG26,"L")+(COUNTIF(D26:AG26,"L/2")/2)+(COUNTIF(D26:AG26,"L/P")/2)+(COUNTIF(D26:AG26,"L/KL")/2) -> 0 | AL26: =COUNTIF(D26:AG26,"KL")+COUNTIF(D26:AG26,"0,5KL")/2+COUNTIF(D26:AG26,"L/KL")/2+COUNTIF(D26:AG26,"KL/2")/2+COUNTIF(D26:AG26,"P/KL")/2+COUNTIF(D26:AG26,"0.5")/2 -> 0 | AM26: =SUM(AI26:AL26) -> 26 | AN26: =AI26+AJ26+AK26 -> 26 | AO26: =VLOOKUP(C26,'[1]1. MEDIGO'!$C$4:$BL$100,62,0) -> 1/6/2023
A27: 19 | C27: Nguyễn Cao Nhân | D27: 1 | E27: 1 | F27: 1 | G27: 1 | H27: 1 | I27: 1 | K27: 1 | L27: 1 | M27: 1 | N27: 1 | O27: 1 | P27: 1 | R27: 1 | S27: 1 | T27: 1 | U27: 1 | V27: 1 | W27: 1 | Y27: 1 | Z27: 1 | AA27: 1 | AB27: 1 | AC27: 1 | AD27: 1 | AF27: 1 | AG27: 1 | AI27: =SUM(D27:AH27)+(COUNTIF(D27:AH27,"0,5KL")/2)+(COUNTIF(D27:AH27,"0,5P")/2)+(COUNTIF(D27:AH27,"0.5L")/2) -> 26 | AJ27: =(COUNTIF(D27:AG27,"P"))+(COUNTIF(D27:AG27,"P/2")/2)+(COUNTIF(D27:AG27,"0,5P")/2)+(COUNTIF(D27:AG27,"L/P")/2)+(COUNTIF(D27:AG27,"P/KL")/2) -> 0 | AK27: =COUNTIF(D27:AG27,"L")+(COUNTIF(D27:AG27,"L/2")/2)+(COUNTIF(D27:AG27,"L/P")/2)+(COUNTIF(D27:AG27,"L/KL")/2) -> 0 | AL27: =COUNTIF(D27:AG27,"KL")+COUNTIF(D27:AG27,"0,5KL")/2+COUNTIF(D27:AG27,"L/KL")/2+COUNTIF(D27:AG27,"KL/2")/2+COUNTIF(D27:AG27,"P/KL")/2+COUNTIF(D27:AG27,"0.5")/2 -> 0 | AM27: =SUM(AI27:AL27) -> 26 | AN27: =AI27+AJ27+AK27 -> 26 | AO27: =VLOOKUP(C27,'[1]1. MEDIGO'!$C$4:$BL$100,62,0) -> 1/7/2024
A28: 20 | C28: Đặng Thị Quế Anh | D28: 1 | E28: 1 | F28: 1 | G28: 1 | H28: 1 | I28: 1 | K28: 1 | L28: 1 | M28: 1 | N28: 1 | O28: 1 | P28: 1 | R28: 1 | S28: 1 | T28: 1 | U28: 1 | V28: 1 | W28: 1 | Y28: 1 | Z28: P | AA28: 1 | AB28: 1 | AC28: 1 | AD28: 1 | AF28: 1 | AG28: 1 | AI28: =SUM(D28:AH28)+(COUNTIF(D28:AH28,"0,5KL")/2)+(COUNTIF(D28:AH28,"0,5P")/2)+(COUNTIF(D28:AH28,"0.5L")/2) -> 25 | AJ28: =(COUNTIF(D28:AG28,"P"))+(COUNTIF(D28:AG28,"P/2")/2)+(COUNTIF(D28:AG28,"0,5P")/2)+(COUNTIF(D28:AG28,"L/P")/2)+(COUNTIF(D28:AG28,"P/KL")/2) -> 1 | AK28: =COUNTIF(D28:AG28,"L")+(COUNTIF(D28:AG28,"L/2")/2)+(COUNTIF(D28:AG28,"L/P")/2)+(COUNTIF(D28:AG28,"L/KL")/2) -> 0 | AL28: =COUNTIF(D28:AG28,"KL")+COUNTIF(D28:AG28,"0,5KL")/2+COUNTIF(D28:AG28,"L/KL")/2+COUNTIF(D28:AG28,"KL/2")/2+COUNTIF(D28:AG28,"P/KL")/2+COUNTIF(D28:AG28,"0.5")/2 -> 0 | AM28: =SUM(AI28:AL28) -> 26 | AN28: =AI28+AJ28+AK28 -> 26 | AO28: =VLOOKUP(C28,'[1]1. MEDIGO'!$C$4:$BL$100,62,0) -> 26/11/2024
A29: 21 | C29: Nguyễn Thị Ánh Hồng | D29: 1 | E29: 1 | F29: 1 | G29: 1 | H29: 1 | I29: 1 | K29: 1 | L29: 1 | M29: 1 | N29: 1 | O29: 1 | P29: 1 | R29: 1 | S29: 1 | T29: 1 | U29: 1 | V29: 1 | W29: 1 | Y29: 1 | Z29: 1 | AA29: 1 | AB29: 1 | AC29: 1 | AD29: 1 | AF29: 1 | AG29: 1 | AI29: =SUM(D29:AH29)+(COUNTIF(D29:AH29,"0,5KL")/2)+(COUNTIF(D29:AH29,"0,5P")/2)+(COUNTIF(D29:AH29,"0.5L")/2) -> 26 | AJ29: =(COUNTIF(D29:AG29,"P"))+(COUNTIF(D29:AG29,"P/2")/2)+(COUNTIF(D29:AG29,"0,5P")/2)+(COUNTIF(D29:AG29,"L/P")/2)+(COUNTIF(D29:AG29,"P/KL")/2) -> 0 | AK29: =COUNTIF(D29:AG29,"L")+(COUNTIF(D29:AG29,"L/2")/2)+(COUNTIF(D29:AG29,"L/P")/2)+(COUNTIF(D29:AG29,"L/KL")/2) -> 0 | AL29: =COUNTIF(D29:AG29,"KL")+COUNTIF(D29:AG29,"0,5KL")/2+COUNTIF(D29:AG29,"L/KL")/2+COUNTIF(D29:AG29,"KL/2")/2+COUNTIF(D29:AG29,"P/KL")/2+COUNTIF(D29:AG29,"0.5")/2 -> 0 | AM29: =SUM(AI29:AL29) -> 26 | AN29: =AI29+AJ29+AK29 -> 26 | AO29: =VLOOKUP(C29,'[1]1. MEDIGO'!$C$4:$BL$100,62,0) -> 2/12/2024
A30: 22 | C30: Phan Thị Kim Hiên | D30: 1 | E30: 1 | F30: 1 | G30: 1 | H30: 1 | I30: 1 | K30: 1 | L30: 1 | M30: 1 | N30: 1 | O30: 1 | P30: 1 | R30: 1 | S30: 1 | T30: 1 | U30: 1 | V30: 1 | W30: 1 | Y30: 1 | Z30: 1 | AA30: 1 | AB30: 1 | AC30: 1 | AD30: 1 | AF30: 1 | AG30: 1 | AI30: =SUM(D30:AH30)+(COUNTIF(D30:AH30,"0,5KL")/2)+(COUNTIF(D30:AH30,"0,5P")/2)+(COUNTIF(D30:AH30,"0.5L")/2) -> 26 | AJ30: =(COUNTIF(D30:AG30,"P"))+(COUNTIF(D30:AG30,"P/2")/2)+(COUNTIF(D30:AG30,"0,5P")/2)+(COUNTIF(D30:AG30,"L/P")/2)+(COUNTIF(D30:AG30,"P/KL")/2) -> 0 | AK30: =COUNTIF(D30:AG30,"L")+(COUNTIF(D30:AG30,"L/2")/2)+(COUNTIF(D30:AG30,"L/P")/2)+(COUNTIF(D30:AG30,"L/KL")/2) -> 0 | AL30: =COUNTIF(D30:AG30,"KL")+COUNTIF(D30:AG30,"0,5KL")/2+COUNTIF(D30:AG30,"L/KL")/2+COUNTIF(D30:AG30,"KL/2")/2+COUNTIF(D30:AG30,"P/KL")/2+COUNTIF(D30:AG30,"0.5")/2 -> 0 | AM30: =SUM(AI30:AL30) -> 26 | AN30: =AI30+AJ30+AK30 -> 26 | AO30: =VLOOKUP(C30,'[1]1. MEDIGO'!$C$4:$BL$100,62,0) -> 14/7/2025
A31: 23 | C31: Lê Thị Phương Thảo | D31: 1 | E31: 1 | F31: 1 | G31: 1 | H31: 1 | I31: 1 | K31: 1 | L31: 1 | M31: 1 | N31: 1 | O31: 1 | P31: 1 | R31: 1 | S31: 1 | T31: 1 | U31: 1 | V31: 1 | W31: 1 | Y31: 1 | Z31: 1 | AA31: 1 | AB31: 1 | AC31: 1 | AD31: 1 | AF31: 1 | AG31: 1 | AI31: =SUM(D31:AH31)+(COUNTIF(D31:AH31,"0,5KL")/2)+(COUNTIF(D31:AH31,"0,5P")/2)+(COUNTIF(D31:AH31,"0.5L")/2) -> 26 | AJ31: =(COUNTIF(D31:AG31,"P"))+(COUNTIF(D31:AG31,"P/2")/2)+(COUNTIF(D31:AG31,"0,5P")/2)+(COUNTIF(D31:AG31,"L/P")/2)+(COUNTIF(D31:AG31,"P/KL")/2) -> 0 | AK31: =COUNTIF(D31:AG31,"L")+(COUNTIF(D31:AG31,"L/2")/2)+(COUNTIF(D31:AG31,"L/P")/2)+(COUNTIF(D31:AG31,"L/KL")/2) -> 0 | AL31: =COUNTIF(D31:AG31,"KL")+COUNTIF(D31:AG31,"0,5KL")/2+COUNTIF(D31:AG31,"L/KL")/2+COUNTIF(D31:AG31,"KL/2")/2+COUNTIF(D31:AG31,"P/KL")/2+COUNTIF(D31:AG31,"0.5")/2 -> 0 | AM31: =SUM(AI31:AL31) -> 26 | AN31: =AI31+AJ31+AK31 -> 26 | AO31: =VLOOKUP(C31,'[1]1. MEDIGO'!$C$4:$BL$100,62,0) -> 25/8/2025
A32: 25 | C32: Huỳnh Tấn Nhân | D32: 1 | E32: 1 | F32: 1 | G32: 1 | H32: 1 | I32: 1 | K32: 1 | L32: 1 | M32: 1 | N32: 1 | O32: 1 | P32: 1 | R32: 1 | S32: P | T32: 1 | U32: 1 | V32: 1 | W32: 1 | Y32: 1 | Z32: 1 | AA32: 1 | AB32: 1 | AC32: 1 | AD32: 1 | AF32: 1 | AG32: 1 | AI32: =SUM(D32:AH32)+(COUNTIF(D32:AH32,"0,5KL")/2)+(COUNTIF(D32:AH32,"0,5P")/2)+(COUNTIF(D32:AH32,"0.5L")/2) -> 25 | AJ32: =(COUNTIF(D32:AG32,"P"))+(COUNTIF(D32:AG32,"P/2")/2)+(COUNTIF(D32:AG32,"0,5P")/2)+(COUNTIF(D32:AG32,"L/P")/2)+(COUNTIF(D32:AG32,"P/KL")/2) -> 1 | AK32: =COUNTIF(D32:AG32,"L")+(COUNTIF(D32:AG32,"L/2")/2)+(COUNTIF(D32:AG32,"L/P")/2)+(COUNTIF(D32:AG32,"L/KL")/2) -> 0 | AL32: =COUNTIF(D32:AG32,"KL")+COUNTIF(D32:AG32,"0,5KL")/2+COUNTIF(D32:AG32,"L/KL")/2+COUNTIF(D32:AG32,"KL/2")/2+COUNTIF(D32:AG32,"P/KL")/2+COUNTIF(D32:AG32,"0.5")/2 -> 0 | AM32: =SUM(AI32:AL32) -> 26 | AN32: =AI32+AJ32+AK32 -> 26 | AO32: =VLOOKUP(C32,'[1]1. MEDIGO'!$C$4:$BL$100,62,0) -> 1/8/2025
A33: 26 | C33: Nguyễn Thị Kim Ngọc | D33: 1 | E33: 1 | F33: 1 | G33: 1 | H33: 1 | I33: 1 | K33: 1 | L33: 1 | M33: 1 | N33: 1 | O33: 1 | P33: 1 | R33: 1 | S33: P | T33: P | U33: 1 | V33: 1 | W33: 1 | Y33: 1 | Z33: 1 | AA33: 1 | AB33: 1 | AC33: 1 | AD33: 0,5P | AF33: 1 | AG33: 1 | AI33: =SUM(D33:AH33)+(COUNTIF(D33:AH33,"0,5KL")/2)+(COUNTIF(D33:AH33,"0,5P")/2)+(COUNTIF(D33:AH33,"0.5L")/2) -> 23.5 | AJ33: =(COUNTIF(D33:AG33,"P"))+(COUNTIF(D33:AG33,"P/2")/2)+(COUNTIF(D33:AG33,"0,5P")/2)+(COUNTIF(D33:AG33,"L/P")/2)+(COUNTIF(D33:AG33,"P/KL")/2) -> 2.5 | AK33: =COUNTIF(D33:AG33,"L")+(COUNTIF(D33:AG33,"L/2")/2)+(COUNTIF(D33:AG33,"L/P")/2)+(COUNTIF(D33:AG33,"L/KL")/2) -> 0 | AL33: =COUNTIF(D33:AG33,"KL")+COUNTIF(D33:AG33,"0,5KL")/2+COUNTIF(D33:AG33,"L/KL")/2+COUNTIF(D33:AG33,"KL/2")/2+COUNTIF(D33:AG33,"P/KL")/2+COUNTIF(D33:AG33,"0.5")/2 -> 0 | AM33: =SUM(AI33:AL33) -> 26 | AN33: =AI33+AJ33+AK33 -> 26 | AO33: =VLOOKUP(C33,'[1]1. MEDIGO'!$C$4:$BL$100,62,0) -> 11/8/2025
A34: 27 | C34: Lê Thị Phương Anh | D34: 1 | E34: 1 | F34: 1 | G34: 1 | H34: 1 | I34: 1 | K34: 1 | L34: 1 | M34: 1 | N34: 1 | O34: 1 | P34: 1 | R34: 1 | S34: 1 | T34: P | U34: 1 | V34: 1 | W34: 1 | Y34: 1 | Z34: 1 | AA34: 1 | AB34: 1 | AC34: 1 | AD34: 1 | AF34: 1 | AG34: 1 | AI34: =SUM(D34:AH34)+(COUNTIF(D34:AH34,"0,5KL")/2)+(COUNTIF(D34:AH34,"0,5P")/2)+(COUNTIF(D34:AH34,"0.5L")/2) -> 25 | AJ34: =(COUNTIF(D34:AG34,"P"))+(COUNTIF(D34:AG34,"P/2")/2)+(COUNTIF(D34:AG34,"0,5P")/2)+(COUNTIF(D34:AG34,"L/P")/2)+(COUNTIF(D34:AG34,"P/KL")/2) -> 1 | AK34: =COUNTIF(D34:AG34,"L")+(COUNTIF(D34:AG34,"L/2")/2)+(COUNTIF(D34:AG34,"L/P")/2)+(COUNTIF(D34:AG34,"L/KL")/2) -> 0 | AL34: =COUNTIF(D34:AG34,"KL")+COUNTIF(D34:AG34,"0,5KL")/2+COUNTIF(D34:AG34,"L/KL")/2+COUNTIF(D34:AG34,"KL/2")/2+COUNTIF(D34:AG34,"P/KL")/2+COUNTIF(D34:AG34,"0.5")/2 -> 0 | AM34: =SUM(AI34:AL34) -> 26 | AN34: =AI34+AJ34+AK34 -> 26 | AO34: =VLOOKUP(C34,'[1]1. MEDIGO'!$C$4:$BL$100,62,0) -> 11/9/2025
A35: 28 | C35: Nguyễn Vũ Khôi | D35: 1 | E35: 1 | F35: 1 | G35: 1 | H35: 1 | AI35: =SUM(D35:AH35)+(COUNTIF(D35:AH35,"0,5KL")/2)+(COUNTIF(D35:AH35,"0,5P")/2)+(COUNTIF(D35:AH35,"0.5L")/2) -> 5 | AJ35: =(COUNTIF(D35:AG35,"P"))+(COUNTIF(D35:AG35,"P/2")/2)+(COUNTIF(D35:AG35,"0,5P")/2)+(COUNTIF(D35:AG35,"L/P")/2)+(COUNTIF(D35:AG35,"P/KL")/2) -> 0 | AK35: =COUNTIF(D35:AG35,"L")+(COUNTIF(D35:AG35,"L/2")/2)+(COUNTIF(D35:AG35,"L/P")/2)+(COUNTIF(D35:AG35,"L/KL")/2) -> 0 | AL35: =COUNTIF(D35:AG35,"KL")+COUNTIF(D35:AG35,"0,5KL")/2+COUNTIF(D35:AG35,"L/KL")/2+COUNTIF(D35:AG35,"KL/2")/2+COUNTIF(D35:AG35,"P/KL")/2+COUNTIF(D35:AG35,"0.5")/2 -> 0 | AM35: =SUM(AI35:AL35) -> 5 | AN35: =AI35+AJ35+AK35 -> 5 | AO35: =VLOOKUP(C35,'[1]1. MEDIGO'!$C$4:$BL$100,62,0) -> 25/12/2025
A36: 29 | C36: Lai Thị Bích Châu | D36: 1 | E36: 1 | F36: 1 | G36: 1 | H36: 1 | I36: 1 | K36: 1 | L36: 1 | M36: 1 | N36: 1 | O36: 1 | P36: 1 | R36: 1 | S36: 1 | T36: 1 | U36: 1 | V36: 1 | W36: 1 | Y36: 1 | Z36: 1 | AA36: 1 | AB36: 1 | AC36: 1 | AD36: 1 | AF36: 1 | AG36: 1 | AI36: =SUM(D36:AH36)+(COUNTIF(D36:AH36,"0,5KL")/2)+(COUNTIF(D36:AH36,"0,5P")/2)+(COUNTIF(D36:AH36,"0.5L")/2) -> 26 | AJ36: =(COUNTIF(D36:AG36,"P"))+(COUNTIF(D36:AG36,"P/2")/2)+(COUNTIF(D36:AG36,"0,5P")/2)+(COUNTIF(D36:AG36,"L/P")/2)+(COUNTIF(D36:AG36,"P/KL")/2) -> 0 | AK36: =COUNTIF(D36:AG36,"L")+(COUNTIF(D36:AG36,"L/2")/2)+(COUNTIF(D36:AG36,"L/P")/2)+(COUNTIF(D36:AG36,"L/KL")/2) -> 0 | AL36: =COUNTIF(D36:AG36,"KL")+COUNTIF(D36:AG36,"0,5KL")/2+COUNTIF(D36:AG36,"L/KL")/2+COUNTIF(D36:AG36,"KL/2")/2+COUNTIF(D36:AG36,"P/KL")/2+COUNTIF(D36:AG36,"0.5")/2 -> 0 | AM36: =SUM(AI36:AL36) -> 26 | AN36: =AI36+AJ36+AK36 -> 26 | AO36: =VLOOKUP(C36,'[1]1. MEDIGO'!$C$4:$BL$100,62,0) -> 12/1/2026
B37: MED | D37: 1 | E37: 1 | F37: 1 | G37: 1 | H37: 1 | I37: 1 | K37: 1 | L37: 1 | M37: 1 | N37: 1 | O37: 1 | P37: 1 | R37: 1 | S37: 1 | T37: 1 | U37: 1 | V37: 1 | W37: 1 | Y37: 1 | Z37: 1 | AA37: 1 | AB37: 1 | AC37: 1 | AD37: 1 | AF37: 1 | AG37: 1 | AI37: =SUM(AI38:AI56) -> 435 | AJ37: =SUM(AJ38:AJ56) -> 11 | AK37: =SUM(AK38:AK56) -> 0 | AL37: =SUM(AL38:AL56) -> 10 | AM37: =SUM(AM38:AM49) -> 284 | AN37: =SUM(AN38:AN49) -> 283
A38: =A37+1 -> 1 | C38: Le Huu Ha | D38: 1 | E38: 1 | F38: 1 | G38: 1 | H38: 1 | I38: 1 | K38: 1 | L38: 1 | M38: 1 | N38: 1 | O38: 1 | P38: 1 | R38: 1 | S38: 1 | T38: 1 | U38: 1 | V38: 1 | W38: 1 | Y38: 1 | Z38: 1 | AA38: 1 | AB38: 1 | AC38: 1 | AD38: 1 | AF38: 1 | AG38: 1 | AI38: =SUM(D38:AH38)+(COUNTIF(D38:AH38,"0,5KL")/2)+(COUNTIF(D38:AH38,"0,5P")/2)+(COUNTIF(D38:AH38,"0.5L")/2) -> 26 | AJ38: =(COUNTIF(D38:AG38,"P"))+(COUNTIF(D38:AG38,"P/2")/2)+(COUNTIF(D38:AG38,"0,5P")/2)+(COUNTIF(D38:AG38,"L/P")/2)+(COUNTIF(D38:AG38,"P/KL")/2) -> 0 | AK38: =COUNTIF(D38:AG38,"L")+(COUNTIF(D38:AG38,"L/2")/2)+(COUNTIF(D38:AG38,"L/P")/2)+(COUNTIF(D38:AG38,"L/KL")/2) -> 0 | AL38: =COUNTIF(D38:AG38,"KL")+COUNTIF(D38:AG38,"0,5KL")/2+COUNTIF(D38:AG38,"L/KL")/2+COUNTIF(D38:AG38,"KL/2")/2+COUNTIF(D38:AG38,"P/KL")/2+COUNTIF(D38:AG38,"0.5")/2 -> 0 | AM38: =SUM(AI38:AL38) -> 26 | AN38: =AI38+AJ38+AK38 -> 26 | AO38: 10/8/2021
A39: =A38+1 -> 2 | C39: Đoàn Hữu Luận | D39: 1 | E39: 1 | F39: 1 | G39: 1 | H39: 1 | I39: 1 | K39: 1 | L39: 1 | M39: 1 | N39: 1 | O39: 1 | P39: 1 | R39: 1 | S39: 1 | T39: 1 | U39: 1 | V39: 1 | W39: 1 | Y39: 1 | Z39: 1 | AA39: 1 | AB39: 1 | AC39: 1 | AD39: 1 | AF39: 1 | AG39: 1 | AI39: =SUM(D39:AH39)+(COUNTIF(D39:AH39,"0,5KL")/2)+(COUNTIF(D39:AH39,"0,5P")/2)+(COUNTIF(D39:AH39,"0.5L")/2) -> 26 | AJ39: =(COUNTIF(D39:AG39,"P"))+(COUNTIF(D39:AG39,"P/2")/2)+(COUNTIF(D39:AG39,"0,5P")/2)+(COUNTIF(D39:AG39,"L/P")/2)+(COUNTIF(D39:AG39,"P/KL")/2) -> 0 | AK39: =COUNTIF(D39:AG39,"L")+(COUNTIF(D39:AG39,"L/2")/2)+(COUNTIF(D39:AG39,"L/P")/2)+(COUNTIF(D39:AG39,"L/KL")/2) -> 0 | AL39: =COUNTIF(D39:AG39,"KL")+COUNTIF(D39:AG39,"0,5KL")/2+COUNTIF(D39:AG39,"L/KL")/2+COUNTIF(D39:AG39,"KL/2")/2+COUNTIF(D39:AG39,"P/KL")/2+COUNTIF(D39:AG39,"0.5")/2 -> 0 | AM39: =SUM(AI39:AL39) -> 26 | AN39: =AI39+AJ39+AK39 -> 26 | AO39: 10/8/2022
A40: =A39+1 -> 3 | C40: Lê Thị Quý Ngọc | D40: 1 | E40: 1 | F40: 1 | G40: 1 | H40: 1 | I40: 1 | K40: 1 | L40: 1 | M40: 1 | N40: 1 | O40: 1 | P40: 1 | R40: 1 | S40: 1 | T40: 1 | U40: 1 | V40: 1 | W40: 1 | Y40: 1 | Z40: 1 | AA40: 1 | AB40: 1 | AC40: 1 | AD40: 1 | AF40: 1 | AG40: 1 | AI40: =SUM(D40:AH40)+(COUNTIF(D40:AH40,"0,5KL")/2)+(COUNTIF(D40:AH40,"0,5P")/2)+(COUNTIF(D40:AH40,"0.5L")/2) -> 26 | AJ40: =(COUNTIF(D40:AG40,"P"))+(COUNTIF(D40:AG40,"P/2")/2)+(COUNTIF(D40:AG40,"0,5P")/2)+(COUNTIF(D40:AG40,"L/P")/2)+(COUNTIF(D40:AG40,"P/KL")/2) -> 0 | AK40: =COUNTIF(D40:AG40,"L")+(COUNTIF(D40:AG40,"L/2")/2)+(COUNTIF(D40:AG40,"L/P")/2)+(COUNTIF(D40:AG40,"L/KL")/2) -> 0 | AL40: =COUNTIF(D40:AG40,"KL")+COUNTIF(D40:AG40,"0,5KL")/2+COUNTIF(D40:AG40,"L/KL")/2+COUNTIF(D40:AG40,"KL/2")/2+COUNTIF(D40:AG40,"P/KL")/2+COUNTIF(D40:AG40,"0.5")/2 -> 0 | AM40: =SUM(AI40:AL40) -> 26 | AN40: =AI40+AJ40+AK40 -> 26 | AO40: 24/4/2023
A41: =A40+1 -> 4 | C41: Lê Thu Hà | D41: P | E41: 1 | F41: 1 | G41: 1 | H41: 1 | I41: 1 | K41: 1 | L41: 1 | M41: 1 | N41: 1 | O41: 1 | P41: 1 | R41: 1 | S41: 1 | T41: 1 | U41: 1 | V41: 1 | W41: 1 | Y41: 1 | Z41: 1 | AA41: 1 | AB41: 1 | AC41: 1 | AD41: 1 | AF41: 1 | AG41: 1 | AI41: =SUM(D41:AH41)+(COUNTIF(D41:AH41,"0,5KL")/2)+(COUNTIF(D41:AH41,"0,5P")/2)+(COUNTIF(D41:AH41,"0.5L")/2) -> 25 | AJ41: =(COUNTIF(D41:AG41,"P"))+(COUNTIF(D41:AG41,"P/2")/2)+(COUNTIF(D41:AG41,"0,5P")/2)+(COUNTIF(D41:AG41,"L/P")/2)+(COUNTIF(D41:AG41,"P/KL")/2) -> 1 | AK41: =COUNTIF(D41:AG41,"L")+(COUNTIF(D41:AG41,"L/2")/2)+(COUNTIF(D41:AG41,"L/P")/2)+(COUNTIF(D41:AG41,"L/KL")/2) -> 0 | AL41: =COUNTIF(D41:AG41,"KL")+COUNTIF(D41:AG41,"0,5KL")/2+COUNTIF(D41:AG41,"L/KL")/2+COUNTIF(D41:AG41,"KL/2")/2+COUNTIF(D41:AG41,"P/KL")/2+COUNTIF(D41:AG41,"0.5")/2 -> 0 | AM41: =SUM(AI41:AL41) -> 26 | AN41: =AI41+AJ41+AK41 -> 26 | AO41: 1/9/2020
...

Sheet Med Service
H1: BẢNG LƯƠNG THÁNG 6
G2: Ngày bắt đầu | H2: 46174 | I2: Ngày kết thúc | J2: 46203
CM7: 1 | CN7: 4 | CO7: 2024 | CP7: 5 | CQ7: 2026 | DA7: 05/2026 | DB7: 05/2026
A8: STT | B8: Tháng | C8: Mã NV | D8: Họ tên | E8: Loại Hợp đồng | F8: Bộ phận | G8: Chức vụ | H8: Ngày vào công ty | I8: Số tài khoản | J8: CN Ngân hàng | K8: Ngày công chuẩn | L8: Ngày công thực tế | M8: CNT ca ngày (giờ) | N8: CNT ca đêm (giờ) | O8: Số giờ TC ngày thường | P8: Số giờ TC ngày CN (*2) | Q8: Số giờ TC ngày Lễ, tết (*3) | R8: HT hiệu quả làm việc | S8: Lương cơ bản (đóng BHXH) | T8: Hỗ trợ tiền ăn | U8: Hỗ trợ đồng phục | V8: Hỗ trợ điện thoại, xăng xe | W8: Hỗ trợ tiền gởi xe | X8: Hỗ trợ nhà ở | Y8: Hỗ trợ nuôi con nhỏ | Z8: Hỗ trợ phụ trách dự án/ sáng kiến | AA8: CNT - Phụ cấp lưu động | AB8: CNT - Phụ cấp tăng cường vận hành | AC8: Lương thỏa thuận | AD8: Lương chính thức | AE8: Lương thử việc | AF8: Lương thực tế | AG8: CNT- Lương ca ngày | AH8: CNT- Lương ca đêm | AI8: Lương tăng ca ngày thường | AJ8: Lương TC ngày CN (*2) | AK8: Lương TC ngày lễ, tết (*3) | AL8: CNT- Tiền HT trách nhiệm | AM8: CNT-Tiền HT cửa hàng mới | AN8: CNT- Tiền HT quy trình/dự án | AO8: CNT- Tiền hỗ trợ đạt KPI | AP8: CNT- tiền HT hàng điểm + Cắt liều | AQ8: CNT- Tiền HT hàng cận date | AR8: CNT- Tiền hỗ trợ chương trình Maps | AS8: CNT- HT Thưởng khác | AT8: Bổ sung lương tính thiếu tháng trước | AU8: CNT - Thưởng dự án Mini | AV8: CNT - Thường Whatsapp | AW8: Hỗ trợ đạt KPI Quý | AX8: HT lễ, tết / thưởng khác | AY8: HT đi CT tỉnh/ gởi xe | AZ8: HT sinh nhật | BA8: HT khấu hao máy tính/ kiêm nhiệm/ hỗ trợ đứng bằng | BB8: CNT trừ hết date | BC8: CNT trừ quy chế, quy trình | BD8: CNT trừ App- Kiot | BE8: CNT trừ Ecom | BF8: CNT các khoản trừ khác | BG8: Khoản trừ KPI, trừ khác | BH8: Tổng thu nhập thực tế | BI8: BHXH Cty (17.5%) | BJ8: BHYT Cty (3%) | BK8: BHTN CTy 1% | BL8: KPCĐ Cty (2%) | BM8: Cộng Cty 23,5% | BN8: BHXH NV (8%) | BO8: BHYT NV (1,5%) | BP8: BHTN NV (1%) | BQ8: ĐP NV (1%) | BR8: BHXH, BHYT, BHTN của NV (11,5%) | BS8: Tổng miễn giảm thuế TNCN (gởi xe, PC điện thoại, tiền ăn, đồng phục) | BT8: Thu nhập chịu thuế | BU8: Giảm trừ TTNCN Bản thân | BV8: Số người phụ thuộc | BW8: Giảm trừ TTNCN Người PT | BX8: Giảm trừ TTNCN 10.5% BHXH, BHYT, BHTN | BY8: Tổng các khoản giảm trừ | BZ8: Thu nhập tính thuế | CA8: Thuế TNCN phải nộp | CB8: Tổng thực nhận sau khi trừ TTNCN, BHXH | CC8: Trả lại lương Cty tính sai/thiếu | CD8: Trừ tạm ứng/ mượn/ bồi thường/ khác | CE8: Tổng thu nhập còn lại | CF8: CK TM | CG8: CK TK | CH8: ESHOP | CI8: Email | CJ8: Lý do bổ sung lương/ trừ lương | CK8: Tháng sinh | CL8: Giờ công đào tạo | CM8: Ngày nhận việc | CN8: Tháng nhận việc | CO8: Năm nhận việc | CP8: thâm niên trước tháng 04/2024 đến 01/4/2024 | CQ8: thâm niên cho NV chưa đủ 12 tháng trong CSTN cũ -> hưởng theo CSTN mới | CR8: Thâm niên cho NV vừa theo chính sách cũ vừa theo chính sách mới | CS8: Số năm TN làm tròn xuống theo CS cũ | CT8: Số năm TN làm tròn xuống theo CS mới | CU8: Số năm TN làm tròn xuống NV hưởng CS mới+ cũ | CV8: Lương thâm niên theo chính sách cũ trước tháng 04/2024 | CW8: Lương thâm niên theo chính sách mới từ 01/04/2024 | CX8: Lương thâm niên cho NV vừa theo chính sách mới + cũ | CY8: Lương Thâm niên của NV | CZ8: Lý do cộng trừ của HC-NS | DA8: Lý do cộng trừ của nhà thuốc | DB8: Lý do chung
A9: 1 | B9: =1+A9 -> 2 | C9: 3 | D9: 4 | E9: 5 | F9: 6 | G9: 7 | H9: 8 | I9: 9 | J9: 10 | K9: 11 | L9: 12 | M9: 13 | N9: 14 | O9: 15 | P9: 16 | Q9: 17 | R9: 18 | S9: 19 | T9: 20 | U9: 21 | V9: 22 | W9: 23 | X9: 24 | Y9: 25 | Z9: 26 | AA9: 44 | AB9: 44 | AC9: 27 | AD9: 28 | AE9: 29 | AF9: 30 | AG9: 31 | AH9: 32 | AI9: 33 | AJ9: 34 | AK9: 35 | AL9: 36 | AM9: 37 | AN9: 38 | AO9: 39 | AP9: 40 | AQ9: 41 | AR9: 42 | AS9: 43 | AT9: 44 | AU9: 44 | AV9: 44 | AW9: 46 | AX9: 47 | AY9: 48 | AZ9: 49 | BA9: 50 | BB9: 51 | BC9: 52 | BD9: 53 | BE9: 54 | BF9: 55 | BG9: 56 | BH9: 57 | BI9: 58 | BJ9: 59 | BK9: 60 | BL9: 61 | BM9: 62 | BN9: 63 | BO9: 64 | BP9: 65 | BQ9: 66 | BR9: 67 | BS9: 68 | BT9: 69 | BU9: 70 | BV9: 71 | BW9: 72 | BX9: 73 | BY9: 74 | BZ9: 75 | CA9: 76 | CB9: 77 | CC9: 78 | CD9: 79 | CE9: 80 | CF9: 81 | CG9: 82 | CH9: 83 | CI9: 84 | CJ9: 85 | CK9: 86 | CL9: 87 | CM9: 88 | CN9: 89 | CO9: 90 | CP9: 91 | CQ9: 92 | CR9: 93 | CS9: 94 | CT9: 95 | CU9: 96 | CV9: 97 | CW9: 98 | CX9: 99 | CY9: 100 | CZ9: 102 | DA9: 103 | DB9: 104 | DC9: 105
A10: V. | B10: CHUỖI NHÀ THUỐC | K10: =K16+K24+K29+K35+K45+K52+K58+K64+K70+K76 -> 896 | L10: =L16+L24+L29+L35+L45+L52+L58+L64+L70+L76 -> 705 | M10: =M16+M24+M29+M35+M45+M52+M58+M64+M70+M76 -> 3505.03 | N10: =N16+N24+N29+N35+N45+N52+N58+N64+N70+N76 -> 2974.34 | O10: =O16+O24+O29+O35+O45+O52+O58+O64+O70+O76 -> 0 | P10: =P16+P24+P29+P35+P45+P52+P58+P64+P70+P76 -> 0 | Q10: =Q16+Q24+Q29+Q35+Q45+Q52+Q58+Q64+Q70+Q76 -> 0 | R10: =R16+R24+R29+R35+R45+R52+R58+R64+R70+R76 -> 0 | ... Z10: =Z16+Z24+Z29+Z35+Z45+Z52+Z58+Z64+Z70+Z76 -> 0 | AC10: =AC16+AC24+AC29+AC35+AC45+AC52+AC58+AC64+AC70+AC76 -> 197809058 | AD10: =AD16+AD24+AD29+AD35+AD45+AD52+AD58+AD64+AD70+AD76 -> 0 | AE10: =AE16+AE24+AE29+AE35+AE45+AE52+AE58+AE64+AE70+AE76 -> 0 | AF10: =AF16+AF24+AF29+AF35+AF45+AF52+AF58+AF64+AF70+AF76 -> 0 | AG10: =AG16+AG24+AG29+AG35+AG45+AG52+AG58+AG64+AG70+AG76 -> 99569588 | AH10: =AH16+AH24+AH29+AH35+AH45+AH52+AH58+AH64+AH70+AH76 -> 1.261177e+08 | AI10: =AI16+AI24+AI29+AI35+AI45+AI52+AI58+AI64+AI70+AI76 -> 0 | AJ10: =AJ16+AJ24+AJ29+AJ35+AJ45+AJ52+AJ58+AJ64+AJ70+AJ76 -> 0 | ... AT10: =AT16+AT24+AT29+AT35+AT45+AT52+AT58+AT64+AT70+AT76 -> 0 | AW10: =AW16+AW24+AW29+AW35+AW45+AW52+AW58+AW64+AW70+AW76 -> 0 | AX10: =AX16+AX24+AX29+AX35+AX45+AX52+AX58+AX64+AX70+AX76 -> 0 | AY10: =AY16+AY24+AY29+AY35+AY45+AY52+AY58+AY64+AY70+AY76 -> 0 | AZ10: =AZ16+AZ24+AZ29+AZ35+AZ45+AZ52+AZ58+AZ64+AZ70+AZ76 -> 200000 | BA10: =BA16+BA24+BA29+BA35+BA45+BA52+BA58+BA64+BA70+BA76 -> 0 | BB10: =BB16+BB24+BB29+BB35+BB45+BB52+BB58+BB64+BB70+BB76 -> 820800 | BC10: =BC16+BC24+BC29+BC35+BC45+BC52+BC58+BC64+BC70+BC76 -> 330000 | BD10: =BD16+BD24+BD29+BD35+BD45+BD52+BD58+BD64+BD70+BD76 -> 273200 | ... CH10: =CH16+CH24+CH29+CH35+CH45+CH52+CH58+CH64+CH70+CH76 -> 0 | CL10: =CL16+CL24+CL29+CL35+CL45+CL52+CL58+CL64+CL70+CL76 -> 75
A11: 1 | B11: 6 | C11: Ho Thi Minh Hoa | D11: Hồ Thị Minh Hòa | E11: =IF(OR(G11="CHT",G11="DSBC"),"HĐLĐ",IF(OR(G11="DSTV",G11="Q.CHT"),"HĐTV","HĐCTV")) -> HĐLĐ | F11: 24H | G11: DSBC | H11: 45352 | I11: 0051000542226 | J11: Vietcombank | K11: 28 | L11: =VLOOKUP($D11,CNT!C4:AL67,14,0) -> 30 | M11: =VLOOKUP($D11,CNT!C4:AL67,3,0) -> 157.8 | N11: =VLOOKUP($D11,CNT!C4:AL67,4,0) -> 120 | S11: =IF(E11="HĐLĐ",5310000,0) -> 5310000 | T11: =IF(500000/28*L11>500000,500000,500000/28*L11) -> 500000 | AA11: =VLOOKUP(D11,CNT!C4:AL67,20,0) -> 0 | AB11: =VLOOKUP(D11,CNT!C4:AL67,21,0) -> 0 | AC11: =CY11 -> 6500000 | AG11: =AC11/28/8*M11 -> 4579017.9 | AH11: =AC11/28/8*N11*1.5 -> 5223214.3 | AL11: =VLOOKUP(D11,CNT!C4:AL67,18,0) -> 500000 | AM11: =VLOOKUP(D11,CNT!C4:AL68,19,0) -> 0 | AN11: =VLOOKUP(D11,CNT!C4:AL67,24,0) -> 1600000 | AO11: =VLOOKUP(D11,CNT!C4:AL67,25,0) -> 0 | AP11: =VLOOKUP(D11,CNT!C4:AL67,26,0) -> 2291050 | AQ11: =VLOOKUP(D11,CNT!C4:AL67,27,0) -> 12451 | AR11: =VLOOKUP(D11,CNT!C4:AL67,28,0) -> 0 | AS11: =VLOOKUP(D11,CNT!C4:AL67,29,0) -> 300000 | AU11: =VLOOKUP(D11,CNT!C4:AL67,22,0) -> 0 | AV11: =VLOOKUP(D11,CNT!C4:AL67,23,0) -> 0 | BB11: =VLOOKUP($D11,CNT!C4:AL67,31,0) -> 68625 | BC11: =VLOOKUP(D11,CNT!C4:AL67,32,0) -> 0 | BD11: =VLOOKUP(D11,CNT!C4:AL67,33,0) -> 0 | BE11: =VLOOKUP(D11,CNT!C4:AL67,34,0) -> 0 | BF11: =VLOOKUP($D11,CNT!C4:AL67,35,0) -> 0 | BH11: =SUM(AF11:BA11)-SUM(BB11:BG11)+T11 -> 14937108 | BI11: =S11*17.5% -> 929250 | BJ11: =S11*3% -> 159300 | BK11: =S11*1% -> 53100 | BM11: =SUM(BI11:BL11) -> 1141650 | BN11: =S11*8% -> 424800 | BO11: =S11*1.5% -> 79650 | BP11: =S11*1% -> 53100 | BR11: =SUM(BN11:BQ11) -> 557550 | BS11: =T11+U11+V11+W11 -> 500000 | BT11: =BH11-BS11 -> 14437108 | BU11: =IF(E11="HĐLĐ",15500000,0) -> 15500000 | BW11: =BV11*6200000 -> 0 | BX11: =BR11 -> 557550 | BY11: =BU11+BW11+BX11 -> 16057550 | BZ11: =IF(BT11-BY11>0,BT11-BY11,0) -> 0 | CA11: =IF(AND(OR($E11="HĐTV",$E11="HĐCTV"),$BZ11<2000000),0,IF(OR($E11="HĐTV",$E11="HĐCTV"),$BZ11*10%,ROUND(IF($BZ11<=10000000,$BZ11*5%,IF($BZ11<=30000000,$BZ11*10%-500000,IF($BZ11<=60000000,$BZ11*20%-3500000,IF($BZ11<=100000000,$BZ11*30%-9500000,$BZ11*35%-14500000)))),0))) -> 0 | CB11: =ROUND(BH11-BR11-CA11,0) -> 14379558 | CD11: =AW11+AX11 -> 0 | CE11: =CB11+CC11-CD11 -> 14379558 | CF11: =CE11-CG11 -> 0 | CG11: =CE11 -> 14379558 | CI11: =VLOOKUP($C11,[2]Sheet1!$C$5:$K$139,9,0) -> medigo.hoa.ho@gmail.com | CJ11: =VLOOKUP(D11,CNT!C4:AL67,36,0) -> 0 | CK11: 11 | CL11: =VLOOKUP(D11,CNT!C4:AL67,15,0) -> 2 | CM11: 1 | CN11: 3 | CO11: 2024 | CP11: =IF((($CO$7-CO11)*12)+($CN$7-CN11)>=12,((($CO$7-CO11)*12)+($CN$7-CN11))-1,0) -> 0 | CQ11: =IF(CP11<12,(($CQ$7-CO11)*12)+($CP$7-CN11),0) -> 26 | CR11: =IF(OR(CP11>12,CP11=12),((CP11-(CS11*12))+((($CQ$7-2024)*12)+($CP$7-4)))+1,0) -> 0 | CS11: =IF(OR(CP11>12,CP11=12),ROUNDDOWN(CP11/12,0),0) -> 0 | CT11: =IF(CQ11>11,ROUNDDOWN(CQ11/12,0),0) -> 2 | CU11: =IF(CR11>11,ROUNDDOWN(CR11/12,0),0) -> 0 | CV11: =IF(CP11=0,0,6000000*1.07^CS11) -> 0 | CW11: =IF(CT11<2,0,6000000+(CT11-1)*500000) -> 6500000 | CX11: =IF(CU11=0,CV11,IF(CU11<1,0,CV11+CU11*500000)) -> 0 | CY11: =IF(CX11>0,CX11,IF(CW11>0,CW11,6000000)) -> 6500000 | DB11: =CZ11&";"&" "&DA11 -> ; | DE11: =VLOOKUP($D11,'[4]Med Service'!$D$11:$DI$87,110,0) -> 1035547 | DF11: =VLOOKUP($D11,'[5]BẢNG LƯƠNG'!$C$3:$AH$102,32,0)
A12: =1+A11 -> 2 | B12: 6 | C12: Tran Thi Kim Khanh | D12: Trần Thị Kim Khánh | E12: =IF(OR(G12="CHT",G12="DSBC"),"HĐLĐ",IF(OR(G12="DSTV",G12="Q.CHT"),"HĐTV","HĐCTV")) -> HĐLĐ | F12: 24H | G12: DSBC | H12: 45099 | I12: 69110000565904 | J12: BIDV | K12: 28 | L12: =VLOOKUP($D12,CNT!C5:AL68,14,0) -> 30 | M12: =VLOOKUP($D12,CNT!C5:AL68,3,0) -> 210.2 | N12: =VLOOKUP($D12,CNT!C5:AL68,4,0) -> 94.47 | S12: =IF(E12="HĐLĐ",5310000,0) -> 5310000 | T12: =IF(500000/28*L12>500000,500000,500000/28*L12) -> 500000 | AA12: =VLOOKUP(D12,CNT!C5:AL68,20,0) -> 0 | AB12: =VLOOKUP(D12,CNT!C5:AL68,21,0) -> 0 | AC12: =CY12 -> 6500000 | AG12: =AC12/28/8*M12 -> 6099553.6 | AH12: =AC12/28/8*N12*1.5 -> 4111975.4 | AL12: =VLOOKUP(D12,CNT!C5:AL68,18,0) -> 0 | AM12: =VLOOKUP(D12,CNT!C5:AL69,19,0) -> 0 | AN12: =VLOOKUP(D12,CNT!C5:AL68,24,0) -> 4000000 | AO12: =VLOOKUP(D12,CNT!C5:AL68,25,0) -> 2127830 | AP12: =VLOOKUP(D12,CNT!C5:AL68,26,0) -> 4568550 | AQ12: =VLOOKUP(D12,CNT!C5:AL68,27,0) -> 2454 | AR12: =VLOOKUP(D12,CNT!C5:AL68,28,0) -> 0 | AS12: =VLOOKUP(D12,CNT!C5:AL68,29,0) -> 120000 | AU12: =VLOOKUP(D12,CNT!C5:AL68,22,0) -> 0 | AV12: =VLOOKUP(D12,CNT!C5:AL68,23,0) -> 0 | BB12: =VLOOKUP($D12,CNT!C5:AL68,31,0) -> 68625 | BC12: =VLOOKUP(D12,CNT!C5:AL68,32,0) -> 0 | BD12: =VLOOKUP(D12,CNT!C5:AL68,33,0) -> 0 | BE12: =VLOOKUP(D12,CNT!C5:AL68,34,0) -> 0 | BF12: =VLOOKUP($D12,CNT!C5:AL68,35,0) -> 0 | BH12: =SUM(AF12:BA12)-SUM(BB12:BG12)+T12 -> 21461738 | BI12: =S12*17.5% -> 929250 | BJ12: =S12*3% -> 159300 | BK12: =S12*1% -> 53100 | BM12: =SUM(BI12:BL12) -> 1141650 | BN12: =S12*8% -> 424800 | BO12: =S12*1.5% -> 79650 | BP12: =S12*1% -> 53100 | BR12: =SUM(BN12:BQ12) -> 557550 | BS12: =T12+U12+V12+W12 -> 500000 | BT12: =BH12-BS12 -> 20961738 | BU12: =IF(E12="HĐLĐ",15500000,0) -> 15500000 | BW12: =BV12*6200000 -> 0 | BX12: =BR12 -> 557550 | BY12: =BU12+BW12+BX12 -> 16057550 | BZ12: =IF(BT12-BY12>0,BT12-BY12,0) -> 4904188 | CA12: =IF(AND(OR($E12="HĐTV",$E12="HĐCTV"),$BZ12<2000000),0,IF(OR($E12="HĐTV",$E12="HĐCTV"),$BZ12*10%,ROUND(IF($BZ12<=10000000,$BZ12*5%,IF($BZ12<=30000000,$BZ12*10%-500000,IF($BZ12<=60000000,$BZ12*20%-3500000,IF($BZ12<=100000000,$BZ12*30%-9500000,$BZ12*35%-14500000)))),0))) -> 245209 | CB12: =ROUND(BH12-BR12-CA12,0) -> 20658979 | CD12: =AW12+AX12 -> 0 | CE12: =CB12+CC12-CD12 -> 20658979 | CF12: =CE12-CG12 -> 0 | CG12: =CE12 -> 20658979 | CI12: =VLOOKUP($C12,[2]Sheet1!$C$5:$K$139,9,0) -> medigo.khanh.tran@gmail.com | CJ12: =VLOOKUP(D12,CNT!C5:AL68,36,0) -> 0 | CK12: 8 | CL12: =VLOOKUP(D12,CNT!C5:AL68,15,0) -> 2 | CM12: 22 | CN12: 6 | CO12: 2023 | CP12: =IF((($CO$7-CO12)*12)+($CN$7-CN12)>=12,((($CO$7-CO12)*12)+($CN$7-CN12))-1,0) -> 0 | CQ12: =IF(CP12<12,(($CQ$7-CO12)*12)+($CP$7-CN12),0) -> 35 | CR12: =IF(OR(CP12>12,CP12=12),((CP12-(CS12*12))+((($CQ$7-2024)*12)+($CP$7-4)))+1,0) -> 0 | CS12: =IF(OR(CP12>12,CP12=12),ROUNDDOWN(CP12/12,0),0) -> 0 | CT12: =IF(CQ12>11,ROUNDDOWN(CQ12/12,0),0) -> 2 | CU12: =IF(CR12>11,ROUNDDOWN(CR12/12,0),0) -> 0 | CV12: =IF(CP12=0,0,6000000*1.07^CS12) -> 0 | CW12: =IF(CT12<2,0,6000000+(CT12-1)*500000) -> 6500000 | CX12: =IF(CU12=0,CV12,IF(CU12<1,0,CV12+CU12*500000)) -> 0 | CY12: =IF(CX12>0,CX12,IF(CW12>0,CW12,6000000)) -> 6500000 | DB12: =CZ12&";"&" "&DA12 -> ; | DE12: =VLOOKUP($D12,'[4]Med Service'!$D$11:$DI$87,110,0) -> 0 | DF12: =VLOOKUP($D12,'[5]BẢNG LƯƠNG'!$C$3:$AH$102,32,0)
A13: =1+A12 -> 3 | B13: 6 | C13: Pham Nguyen Ngoc Quy | D13: Phạm Nguyễn Ngọc Quý | E13: =IF(OR(G13="CHT",G13="DSBC"),"HĐLĐ",IF(OR(G13="DSTV",G13="Q.CHT"),"HĐTV","HĐCTV")) -> HĐLĐ | F13: 24H | G13: DSBC | H13: 01/11/2024 | I13: 1026764251 | J13: Vietcombank | K13: 28 | L13: =VLOOKUP($D13,CNT!C6:AL69,14,0) -> 30 | M13: =VLOOKUP($D13,CNT!C6:AL69,3,0) -> 143.02 | N13: =VLOOKUP($D13,CNT!C6:AL69,4,0) -> 136.38 | S13: =IF(E13="HĐLĐ",5310000,0) -> 5310000 | T13: =IF(500000/28*L13>500000,500000,500000/28*L13) -> 500000 | AA13: =VLOOKUP(D13,CNT!C6:AL69,20,0) -> 0 | AB13: =VLOOKUP(D13,CNT!C6:AL69,21,0) -> 0 | AC13: =CY13 -> 6000000 | AG13: =AC13/28/8*M13 -> 3830892.9 | AH13: =AC13/28/8*N13*1.5 -> 5479553.6 | AL13: =VLOOKUP(D13,CNT!C6:AL69,18,0) -> 0 | AM13: =VLOOKUP(D13,CNT!C6:AL70,19,0) -> 0 | AN13: =VLOOKUP(D13,CNT!C6:AL69,24,0) -> 2200000 | AO13: =VLOOKUP(D13,CNT!C6:AL69,25,0) -> 0 | AP13: =VLOOKUP(D13,CNT!C6:AL69,26,0) -> 2690700 | AQ13: =VLOOKUP(D13,CNT!C6:AL69,27,0) -> 2100 | AR13: =VLOOKUP(D13,CNT!C6:AL69,28,0) -> 0 | AS13: =VLOOKUP(D13,CNT!C6:AL69,29,0) -> 0 | AU13: =VLOOKUP(D13,CNT!C6:AL69,22,0) -> 0 | AV13: =VLOOKUP(D13,CNT!C6:AL69,23,0) -> 0 | AZ13: 100000 | BB13: =VLOOKUP($D13,CNT!C6:AL69,31,0) -> 68625 | BC13: =VLOOKUP(D13,CNT!C6:AL69,32,0) -> 0 | BD13: =VLOOKUP(D13,CNT!C6:AL69,33,0) -> 0 | BE13: =VLOOKUP(D13,CNT!C6:AL69,34,0) -> 0 | BF13: =VLOOKUP($D13,CNT!C6:AL69,35,0) -> 0 | BH13: =SUM(AF13:BA13)-SUM(BB13:BG13)+T13 -> 14734621 | BI13: =S13*17.5% -> 929250 | BJ13: =S13*3% -> 159300 | BK13: =S13*1% -> 53100 | BM13: =SUM(BI13:BL13) -> 1141650 | BN13: =S13*8% -> 424800 | BO13: =S13*1.5% -> 79650 | BP13: =S13*1% -> 53100 | BR13: =SUM(BN13:BQ13) -> 557550 | BS13: =T13+U13+V13+W13 -> 500000 | BT13: =BH13-BS13 -> 14234621 | BU13: =IF(E13="HĐLĐ",15500000,0) -> 15500000 | BW13: =BV13*6200000 -> 0 | BX13: =BR13 -> 557550 | BY13: =BU13+BW13+BX13 -> 16057550 | BZ13: =IF(BT13-BY13>0,BT13-BY13,0) -> 0 | CA13: =IF(AND(OR($E13="HĐTV",$E13="HĐCTV"),$BZ13<2000000),0,IF(OR($E13="HĐTV",$E13="HĐCTV"),$BZ13*10%,ROUND(IF($BZ13<=10000000,$BZ13*5%,IF($BZ13<=30000000,$BZ13*10%-500000,IF($BZ13<=60000000,$BZ13*20%-3500000,IF($BZ13<=100000000,$BZ13*30%-9500000,$BZ13*35%-14500000)))),0))) -> 0 | CB13: =ROUND(BH13-BR13-CA13,0) -> 14177071 | CD13: =AW13+AX13 -> 0 | CE13: =CB13+CC13-CD13 -> 14177071 | CF13: =CE13-CG13 -> 0 | CG13: =CE13 -> 14177071 | CI13: =VLOOKUP($C13,[2]Sheet1!$C$5:$K$139,9,0) -> medigo.quy.pham@gmail.com | CJ13: =VLOOKUP(D13,CNT!C6:AL69,36,0) -> 0 | CK13: 6 | CL13: =VLOOKUP(D13,CNT!C6:AL69,15,0) -> 0 | CM13: 1 | CN13: 11 | CO13: 2024 | CP13: =IF((($CO$7-CO13)*12)+($CN$7-CN13)>=12,((($CO$7-CO13)*12)+($CN$7-CN13))-1,0) -> 0 | CQ13: =IF(CP13<12,(($CQ$7-CO13)*12)+($CP$7-CN13),0) -> 18 | CR13: =IF(OR(CP13>12,CP13=12),((CP13-(CS13*12))+((($CQ$7-2024)*12)+($CP$7-4)))+1,0) -> 0 | CS13: =IF(OR(CP13>12,CP13=12),ROUNDDOWN(CP13/12,0),0) -> 0 | CT13: =IF(CQ13>11,ROUNDDOWN(CQ13/12,0),0) -> 1 | CU13: =IF(CR13>11,ROUNDDOWN(CR13/12,0),0) -> 0 | CV13: =IF(CP13=0,0,6000000*1.07^CS13) -> 0 | CW13: =IF(CT13<2,0,6000000+(CT13-1)*500000) -> 0 | CX13: =IF(CU13=0,CV13,IF(CU13<1,0,CV13+CU13*500000)) -> 0 | CY13: =IF(CX13>0,CX13,IF(CW13>0,CW13,6000000)) -> 6000000 | DB13: =CZ13&";"&" "&DA13 -> ; | DE13: =VLOOKUP($D13,'[4]Med Service'!$D$11:$DI$87,110,0) -> 0 | DF13: =VLOOKUP($D13,'[5]BẢNG LƯƠNG'!$C$3:$AH$102,32,0)
A14: =1+A13 -> 4 | B14: 6 | C14: Ngo Tran Tuyet Vy | D14: Ngô Trần Tuyết Vy | E14: =IF(OR(G14="CHT",G14="DSBC"),"HĐLĐ",IF(OR(G14="DSTV",G14="Q.CHT"),"HĐTV","HĐCTV")) -> HĐLĐ | F14: 24H | G14: DSBC | H14: 44743 | I14: 060260188766 | J14: Sacombank | K14: 28 | L14: =VLOOKUP($D14,CNT!C7:AL70,14,0) -> 27 | M14: =VLOOKUP($D14,CNT!C7:AL70,3,0) -> 104.02 | N14: =VLOOKUP($D14,CNT!C7:AL70,4,0) -> 129.83 | S14: =IF(E14="HĐLĐ",5310000,0) -> 5310000 | T14: =IF(500000/28*L14>500000,500000,500000/28*L14) -> 482142.86 | AA14: =VLOOKUP(D14,CNT!C7:AL70,20,0) -> 0 | AB14: =VLOOKUP(D14,CNT!C7:AL70,21,0) -> 0 | AC14: =CY14 -> 8350258 | AG14: =AC14/28/8*M14 -> 3877651.1 | AH14: =AC14/28/8*N14*1.5 -> 7259691.9 | AL14: =VLOOKUP(D14,CNT!C7:AL70,18,0) -> 0 | AM14: =VLOOKUP(D14,CNT!C7:AL71,19,0) -> 0 | AN14: =VLOOKUP(D14,CNT!C7:AL70,24,0) -> 2200000 | AO14: =VLOOKUP(D14,CNT!C7:AL70,25,0) -> 0 | AP14: =VLOOKUP(D14,CNT!C7:AL70,26,0) -> 3020550 | AQ14: =VLOOKUP(D14,CNT!C7:AL70,27,0) -> 0 | AR14: =VLOOKUP(D14,CNT!C7:AL70,28,0) -> 0 | AS14: =VLOOKUP(D14,CNT!C7:AL70,29,0) -> 0 | AU14: =VLOOKUP(D14,CNT!C7:AL70,22,0) -> 0 | AV14: =VLOOKUP(D14,CNT!C7:AL70,23,0) -> 0 | BB14: =VLOOKUP($D14,CNT!C7:AL70,31,0) -> 68625 | BC14: =VLOOKUP(D14,CNT!C7:AL70,32,0) -> 0 | BD14: =VLOOKUP(D14,CNT!C7:AL70,33,0) -> 0 | BE14: =VLOOKUP(D14,CNT!C7:AL70,34,0) -> 200000 | BF14: =VLOOKUP($D14,CNT!C7:AL70,35,0) -> 0 | BH14: =SUM(AF14:BA14)-SUM(BB14:BG14)+T14 -> 16571411 | BI14: =S14*17.5% -> 929250 | BJ14: =S14*3% -> 159300 | BK14: =S14*1% -> 53100 | BM14: =SUM(BI14:BL14) -> 1141650 | BN14: =S14*8% -> 424800 | BO14: =S14*1.5% -> 79650 | BP14: =S14*1% -> 53100 | BR14: =SUM(BN14:BQ14) -> 557550 | BS14: =T14+U14+V14+W14 -> 482142.86 | BT14: =BH14-BS14 -> 16089268 | BU14: =IF(E14="HĐLĐ",15500000,0) -> 15500000 | BW14: =BV14*6200000 -> 0 | BX14: =BR14 -> 557550 | BY14: =BU14+BW14+BX14 -> 16057550 | BZ14: =IF(BT14-BY14>0,BT14-BY14,0) -> 31717.997 | CA14: =IF(AND(OR($E14="HĐTV",$E14="HĐCTV"),$BZ14<2000000),0,IF(OR($E14="HĐTV",$E14="HĐCTV"),$BZ14*10%,ROUND(IF($BZ14<=10000000,$BZ14*5%,IF($BZ14<=30000000,$BZ14*10%-500000,IF($BZ14<=60000000,$BZ14*20%-3500000,IF($BZ14<=100000000,$BZ14*30%-9500000,$BZ14*35%-14500000)))),0))) -> 1586 | CB14: =ROUND(BH14-BR14-CA14,0) -> 16012275 | CD14: =AW14+AX14 -> 0 | CE14: =CB14+CC14-CD14 -> 16012275 | CF14: =CE14-CG14 -> 0 | CG14: =CE14 -> 16012275 | CI14: =VLOOKUP($C14,[2]Sheet1!$C$5:$K$139,9,0) -> vy.ngo@medigoapp.com | CJ14: =VLOOKUP(D14,CNT!C7:AL70,36,0) -> Làm mất CHBH, Không thực hiện chào kết | CK14: 3 | CL14: =VLOOKUP(D14,CNT!C7:AL70,15,0) -> 0 | CM14: 14 | CN14: 2 | CO14: 2021 | CP14: =IF((($CO$7-CO14)*12)+($CN$7-CN14)>=12,((($CO$7-CO14)*12)+($CN$7-CN14))-1,0) -> 37 | CQ14: =IF(CP14<12,(($CQ$7-CO14)*12)+($CP$7-CN14),0) -> 0 | CR14: =IF(OR(CP14>12,CP14=12),((CP14-(CS14*12))+((($CQ$7-2024)*12)+($CP$7-4)))+1,0) -> 27 | CS14: =IF(OR(CP14>12,CP14=12),ROUNDDOWN(CP14/12,0),0) -> 3 | CT14: =IF(CQ14>11,ROUNDDOWN(CQ14/12,0),0) -> 0 | CU14: =IF(CR14>11,ROUNDDOWN(CR14/12,0),0) -> 2 | CV14: =IF(CP14=0,0,6000000*1.07^CS14) -> 7350258 | CW14: =IF(CT14<2,0,6000000+(CT14-1)*500000) -> 0 | CX14: =IF(CU14=0,CV14,IF(CU14<1,0,CV14+CU14*500000)) -> 8350258 | CY14: =IF(CX14>0,CX14,IF(CW14>0,CW14,6000000)) -> 8350258 | DB14: =CZ14&";"&" "&DA14 -> ; | DE14: =VLOOKUP($D14,'[4]Med Service'!$D$11:$DI$87,110,0) -> 0 | DF14: =VLOOKUP($D14,'[5]BẢNG LƯƠNG'!$C$3:$AH$102,32,0)
A15: =1+A14 -> 5 | B15: 6 | C15: Nguyen Tran Ngoc Phuong | D15: Nguyễn Trần Ngọc Phương | E15: =IF(OR(G15="CHT",G15="DSBC"),"HĐLĐ",IF(OR(G15="DSTV",G15="Q.CHT"),"HĐTV","HĐCTV")) -> HĐTV | F15: 24H | G15: Q.CHT | H15: 46196 | I15: 0721000550950 | J15: Vietcombank | K15: 28 | L15: =VLOOKUP($D15,CNT!C8:AL71,14,0) -> 0 | M15: =VLOOKUP($D15,CNT!C8:AL71,3,0) -> 9 | N15: =VLOOKUP($D15,CNT!C8:AL71,4,0) -> 0 | S15: =IF(E15="HĐLĐ",5310000,0) -> 0 | T15: =IF(500000/28*L15>500000,500000,500000/28*L15) -> 0 | AA15: =VLOOKUP(D15,CNT!C8:AL71,20,0) -> 0 | AB15: =VLOOKUP(D15,CNT!C8:AL71,21,0) -> 0 | AC15: =CY15 -> 6000000 | AG15: =AC15/28/8*M15 -> 241071.43 | AH15: =AC15/28/8*N15*1.5 -> 0 | AL15: =VLOOKUP(D15,CNT!C8:AL71,18,0) -> 400000 | AM15: =VLOOKUP(D15,CNT!C8:AL72,19,0) -> 0 | AN15: =VLOOKUP(D15,CNT!C8:AL71,24,0) -> 0 | AO15: =VLOOKUP(D15,CNT!C8:AL71,25,0) -> 0 | AP15: =VLOOKUP(D15,CNT!C8:AL71,26,0) -> 0 | AQ15: =VLOOKUP(D15,CNT!C8:AL71,27,0) -> 0 | AR15: =VLOOKUP(D15,CNT!C8:AL71,28,0) -> 0 | AS15: =VLOOKUP(D15,CNT!C8:AL71,29,0) -> 0 | AU15: =VLOOKUP(D15,CNT!C8:AL71,22,0) -> 0 | AV15: =VLOOKUP(D15,CNT!C8:AL71,23,0) -> 0 | BB15: =VLOOKUP($D15,CNT!C8:AL71,31,0) -> 0 | BC15: =VLOOKUP(D15,CNT!C8:AL71,32,0) -> 0 | BD15: =VLOOKUP(D15,CNT!C8:AL71,33,0) -> 0 | BE15: =VLOOKUP(D15,CNT!C8:AL71,34,0) -> 0 | BF15: =VLOOKUP($D15,CNT!C8:AL71,35,0) -> 0 | BH15: =SUM(AF15:BA15)-SUM(BB15:BG15)+T15 -> 641071.43 | BI15: =S15*17.5% -> 0 | BJ15: =S15*3% -> 0 | BK15: =S15*1% -> 0 | BM15: =SUM(BI15:BL15) -> 0 | BN15: =S15*8% -> 0 | BO15: =S15*1.5% -> 0 | BP15: =S15*1% -> 0 | BR15: =SUM(BN15:BQ15) -> 0 | BS15: =T15+U15+V15+W15 -> 0 | BT15: =BH15-BS15 -> 641071.43 | BU15: =IF(E15="HĐLĐ",15500000,0) -> 0 | BW15: =BV15*6200000 -> 0 | BX15: =BR15 -> 0 | BY15: =BU15+BW15+BX15 -> 0 | BZ15: =IF(BT15-BY15>0,BT15-BY15,0) -> 641071.43 | CA15: =IF(AND(OR(E15="HĐTV",E15="HĐCTV"),BZ15<2000000),0,IF(OR(E15="HĐTV",E15="HĐCTV"),BZ15*10%,ROUND(+IF(AND(BZ15>=0,BZ15<=5000000),BZ15*0.05,IF(AND(BZ15>5000000,BZ15<=10000000),BZ15*0.1-250000,IF(AND(BZ15>10000000,BZ15<=18000000),BZ15*0.15-750000,IF(AND(BZ15>18000000,BZ15<=32000000),BZ15*0.2-1650000,IF(AND(BZ15>32000000,BZ15<=52000000),BZ15*0.25-3250000,IF(AND(BZ15>52000000,BZ15<=80000000),BZ15*0.3-5850000,BZ15*0.35-9850000)))))),0))) -> 0 | CB15: =ROUND(BH15-BR15-CA15,0) -> 641071 | CD15: =AW15+AX15 -> 0 | CE15: =CB15+CC15-CD15 -> 641071 | CF15: =CE15-CG15 -> 0 | CG15: =CE15 -> 641071 | CI15: phuong.nguyen@medigoapp.com | CJ15: =VLOOKUP(D15,CNT!C8:AL71,36,0) -> 0 | CK15: 9 | CL15: =VLOOKUP(D15,CNT!C8:AL71,15,0) -> 9 | CM15: 23 | CN15: 6 | CO15: 2026 | CP15: =IF((($CO$7-CO15)*12)+($CN$7-CN15)>=12,((($CO$7-CO15)*12)+($CN$7-CN15))-1,0) -> 0 | CQ15: =IF(CP15<12,(($CQ$7-CO15)*12)+($CP$7-CN15),0) -> -1 | CR15: =IF(OR(CP15>12,CP15=12),((CP15-(CS15*12))+((($CQ$7-2024)*12)+($CP$7-4)))+1,0) -> 0 | CS15: =IF(OR(CP15>12,CP15=12),ROUNDDOWN(CP15/12,0),0) -> 0 | CT15: =IF(CQ15>11,ROUNDDOWN(CQ15/12,0),0) -> 0 | CU15: =IF(CR15>11,ROUNDDOWN(CR15/12,0),0) -> 0 | CV15: =IF(CP15=0,0,6000000*1.07^CS15) -> 0 | CW15: =IF(CT15<2,0,6000000+(CT15-1)*500000) -> 0 | CX15: =IF(CU15=0,CV15,IF(CU15<1,0,CV15+CU15*500000)) -> 0 | CY15: =IF(CX15>0,CX15,IF(CW15>0,CW15,6000000)) -> 6000000 | DB15: =CZ15&";"&" "&DA15 -> ; | DE15: =VLOOKUP($D15,'[4]Med Service'!$D$11:$DI$87,110,0) -> #N/A | DF15: =VLOOKUP($D15,'[5]BẢNG LƯƠNG'!$C$3:$AH$102,32,0) -> #N/A
K16: =SUM(K11:K15) -> 140 | L16: =SUM(L11:L15) -> 117 | M16: =SUM(M11:M15) -> 624.04 | N16: =SUM(N11:N15) -> 480.68 | O16: =SUM(O11:O15) -> 0 | P16: =SUM(P11:P15) -> 0 | Q16: =SUM(Q11:Q15) -> 0 | R16: =SUM(R11:R15) -> 0 | ... Z16: =SUM(Z11:Z15) -> 0 | AC16: =SUM(AC11:AC15) -> 33350258 | AD16: =SUM(AD11:AD15) -> 0 | AE16: =SUM(AE11:AE15) -> 0 | AF16: =SUM(AF11:AF15) -> 0 | AG16: =SUM(AG11:AG15) -> 18628187 | AH16: =SUM(AH11:AH15) -> 22074435 | AI16: =SUM(AI11:AI15) -> 0 | AJ16: =SUM(AJ11:AJ15) -> 0 | ... AT16: =SUM(AT11:AT15) -> 0 | AW16: =SUM(AW11:AW15) -> 0 | AX16: =SUM(AX11:AX15) -> 0 | AY16: =SUM(AY11:AY15) -> 0 | AZ16: =SUM(AZ11:AZ15) -> 100000 | BA16: =SUM(BA11:BA15) -> 0 | BB16: =SUM(BB11:BB15) -> 274500 | BC16: =SUM(BC11:BC15) -> 0 | BD16: =SUM(BD11:BD15) -> 0 | ... CI16: =SUM(CI11:CI15) -> 0 | CL16: =SUM(CL11:CL15) -> 13 | DE16: =VLOOKUP($D16,'[4]Med Service'!$D$11:$DI$87,110,0) -> 0
A17: 6 | B17: 6 | C17: Hoang Thanh Thuy | D17: Hoàng Thanh Thủy | E17: =IF(OR(G17="CHT",G17="DSBC"),"HĐLĐ",IF(OR(G17="DSTV",G17="Q.CHT"),"HĐTV","HĐCTV")) -> HĐLĐ | F17: Đỗ Quang Đẩu | G17: DSBC | H17: 27/10/2025 | I17: 615704060127761 | J17: VIB | K17: 28 | L17: =VLOOKUP(D17,CNT!C4:AL67,14,0) -> 28 | M17: =VLOOKUP(D17,CNT!C4:AL67,3,0) -> 224.7 | N17: =VLOOKUP(D17,CNT!C4:AL67,4,0) -> 8.43 | S17: =IF(E17="HĐLĐ",5310000,0) -> 5310000 | T17: =IF(500000/28*L17>500000,500000,500000/28*L17) -> 500000 | AA17: =VLOOKUP(D17,CNT!C4:AL67,20,0) -> 0 | AB17: =VLOOKUP(D17,CNT!C4:AL67,21,0) -> 0 | AC17: =CY17 -> 6000000 | AG17: =AC17/28/8*M17 -> 6018750 | AH17: =AC17/28/8*N17*1.5 -> 338705.36 | AK17: =AC17/28/8*Q17*3 -> 0 | AL17: =VLOOKUP(D17,CNT!C4:AL67,18,0) -> 0 | AM17: =VLOOKUP(D17,CNT!C4:AL68,19,0) -> 0 | AN17: =VLOOKUP(D17,CNT!C4:AL67,24,0) -> 0 | AO17: =VLOOKUP(D17,CNT!C4:AL67,25,0) -> 0 | AP17: =VLOOKUP(D17,CNT!C4:AL67,26,0) -> 1060700 | AQ17: =VLOOKUP(D17,CNT!C4:AL67,27,0) -> 15955 | AR17: =VLOOKUP(D17,CNT!C4:AL67,28,0) -> 0 | AS17: =VLOOKUP(D17,CNT!C4:AL67,29,0) -> 150000 | AU17: =VLOOKUP(D17,CNT!C4:AL67,22,0) -> 0 | AV17: =VLOOKUP(D17,CNT!C4:AL67,23,0) -> 3144860 | BB17: =VLOOKUP(D17,CNT!C4:AL67,31,0) -> 0 | BC17: =VLOOKUP(D17,CNT!C4:AL67,32,0) -> 0 | BD17: =VLOOKUP(D17,CNT!C4:AL67,33,0) -> 0 | BE17: =VLOOKUP(D17,CNT!C4:AL67,34,0) -> 100000 | BF17: =VLOOKUP($D17,CNT!C4:AL67,35,0) -> 0 | BH17: =SUM(AF17:BA17)-SUM(BB17:BG17)+T17 -> 11128970 | BI17: =S17*17.5% -> 929250 | BJ17: =S17*3% -> 159300 | BK17: =S17*1% -> 53100 | BM17: =SUM(BI17:BL17) -> 1141650 | BN17: =S17*8% -> 424800 | BO17: =S17*1.5% -> 79650 | BP17: =S17*1% -> 53100 | BR17: =SUM(BN17:BQ17) -> 557550 | BS17: =T17+U17+V17+W17 -> 500000 | BT17: =BH17-BS17 -> 10628970 | BU17: =IF(E17="HĐLĐ",15500000,0) -> 15500000 | BW17: =BV17*6200000 -> 0 | BX17: =BR17 -> 557550 | BY17: =BU17+BW17+BX17 -> 16057550 | BZ17: =IF(BT17-BY17>0,BT17-BY17,0) -> 0 | CA17: =IF(AND(OR($E17="HĐTV",$E17="HĐCTV"),$BZ17<2000000),0,IF(OR($E17="HĐTV",$E17="HĐCTV"),$BZ17*10%,ROUND(IF($BZ17<=10000000,$BZ17*5%,IF($BZ17<=30000000,$BZ17*10%-500000,IF($BZ17<=60000000,$BZ17*20%-3500000,IF($BZ17<=100000000,$BZ17*30%-9500000,$BZ17*35%-14500000)))),0))) -> 0 | CB17: =ROUND(BH17-BR17-CA17,0) -> 10571420 | CD17: =AW17+AX17 -> 0 | CE17: =CB17+CC17-CD17 -> 10571420 | CF17: =CE17-CG17 -> 0 | CG17: =CE17 -> 10571420 | CI17: =VLOOKUP($C17,[2]Sheet1!$C$5:$K$139,9,0) -> thuy.hoang@medigoapp.com | CJ17: =VLOOKUP(D17,CNT!C4:AL67,36,0) -> Không thực hiện chào kết | CK17: 3 | CL17: =VLOOKUP(D17,CNT!C4:AL67,15,0) -> 2 | CM17: 27 | CN17: 10 | CO17: 2025 | CP17: =IF((($CO$7-CO17)*12)+($CN$7-CN17)>=12,((($CO$7-CO17)*12)+($CN$7-CN17))-1,0) -> 0 | CQ17: =IF(CP17<12,(($CQ$7-CO17)*12)+($CP$7-CN17),0) -> 7 | CR17: =IF(OR(CP17>12,CP17=12),((CP17-(CS17*12))+((($CQ$7-2024)*12)+($CP$7-4)))+1,0) -> 0 | CS17: =IF(OR(CP17>12,CP17=12),ROUNDDOWN(CP17/12,0),0) -> 0 | CT17: =IF(CQ17>11,ROUNDDOWN(CQ17/12,0),0) -> 0 | CU17: =IF(CR17>11,ROUNDDOWN(CR17/12,0),0) -> 0 | CV17: =IF(CP17=0,0,6000000*1.07^CS17) -> 0 | CW17: =IF(CT17<2,0,6000000+(CT17-1)*500000) -> 0 | CX17: =IF(CU17=0,CV17,IF(CU17<1,0,CV17+CU17*500000)) -> 0 | CY17: =IF(CX17>0,CX17,IF(CW17>0,CW17,6000000)) -> 6000000 | DA17: =CJ17 -> Không thực hiện chào kết | DB17: =CZ17&";"&" "&DA17&";"&" "&DF17 -> ; Không thực hiện chào kết; | DE17: =VLOOKUP($D17,'[4]Med Service'!$D$11:$DI$87,110,0) -> 0 | DF17: =VLOOKUP($D17,'[5]BẢNG LƯƠNG'!$C$3:$AH$102,32,0)
