Workbook

Sheet BẢNG CC
A1: BẢNG CHẤM CÔNG
P3: Tháng | R3: 8 | S3: Năm | T3: 2026 | AN3: =SUM(AN8:AN36)
A4: Thông tin nhân viên | D4: Các ngày trong tháng | AI4: Tổng Ngày Công | AM4: Tổng | AN4: Tổng ngày công tính lương | AO4: Ngày nhận việc
A5: STT | B5: Mã NV | C5: Họ và tên | D5: =DATE(T3,R3,1) | E5: =D5+1 | F5: =E5+1 | G5: =F5+1 | H5: =G5+1 | I5: =H5+1 | J5: =I5+1 | K5: =J5+1 | L5: =K5+1 | ... AH5: =AG5+1 | AI5: TT | AJ5: P | AK5: L | AL5: KL
D6: =TEXT(D5,"ddd") | E6: =TEXT(E5,"ddd") | F6: =TEXT(F5,"ddd") | G6: =TEXT(G5,"ddd") | H6: =TEXT(H5,"ddd") | I6: =TEXT(I5,"ddd") | J6: =TEXT(J5,"ddd") | K6: =TEXT(K5,"ddd") | ... AH6: =TEXT(AH5,"ddd")
A7: MEDIGO | AI7: =SUM(AI8:AI36) | AJ7: =SUM(AJ8:AJ36) | AK7: =SUM(AK8:AK36) | AL7: =SUM(AL8:AL36) | AM7: =SUM(AM8:AM36) | AN7: =SUM(AN8:AN36)
A8: 1 | C8: Le Huu Ha | D8: 1 | F8: 1 | G8: 1 | H8: 1 | I8: 1 | J8: 1 | K8: 1 | M8: 1 | N8: 1 | O8: 1 | P8: 1 | Q8: 1 | R8: 1 | T8: 1 | U8: 1 | V8: 1 | W8: 1 | X8: 1 | Y8: 1 | AA8: 1 | AB8: 1 | AC8: 1 | AD8: 1 | AE8: 1 | AF8: 1 | AH8: 1 | AI8: =SUM(D8:AH8)+(COUNTIF(D8:AH8,"0,5KL")/2)+(COUNTIF(D8:AH8,"0,5P")/2)+(COUNTIF(D8:AH8,"0.5L")/2) | AJ8: =(COUNTIF(D8:AH8,"P"))+(COUNTIF(D8:AG8,"P/2")/2)+(COUNTIF(D8:AG8,"0,5P")/2)+(COUNTIF(D8:AG8,"L/P")/2)+(COUNTIF(D8:AG8,"P/KL")/2) | AK8: =COUNTIF(D8:AH8,"L")+(COUNTIF(D8:AG8,"L/2")/2)+(COUNTIF(D8:AG8,"L/P")/2)+(COUNTIF(D8:AG8,"L/KL")/2) | AL8: =COUNTIF(D8:AH8,"KL")+COUNTIF(D8:AG8,"0,5KL")/2+COUNTIF(D8:AG8,"L/KL")/2+COUNTIF(D8:AG8,"KL/2")/2+COUNTIF(D8:AG8,"P/KL")/2+COUNTIF(D8:AG8,"0.5")/2 | AM8: =SUM(AI8:AL8) | AN8: =AI8+AJ8+AK8 | AO8: 2019
A9: 2 | C9: Trần Thị Minh Phượng | D9: 1 | F9: 1 | G9: 1 | H9: 1 | I9: 1 | J9: 1 | K9: 1 | M9: 1 | N9: 1 | O9: 1 | P9: 1 | Q9: 1 | R9: 1 | T9: 1 | U9: 1 | V9: 1 | W9: P | X9: P | Y9: P | AA9: 1 | AB9: 1 | AC9: 1 | AD9: 1 | AE9: 1 | AF9: 1 | AH9: 1 | AI9: =SUM(D9:AH9)+(COUNTIF(D9:AH9,"0,5KL")/2)+(COUNTIF(D9:AH9,"0,5P")/2)+(COUNTIF(D9:AH9,"0.5L")/2) | AJ9: =(COUNTIF(D9:AH9,"P"))+(COUNTIF(D9:AG9,"P/2")/2)+(COUNTIF(D9:AG9,"0,5P")/2)+(COUNTIF(D9:AG9,"L/P")/2)+(COUNTIF(D9:AG9,"P/KL")/2) | AK9: =COUNTIF(D9:AH9,"L")+(COUNTIF(D9:AG9,"L/2")/2)+(COUNTIF(D9:AG9,"L/P")/2)+(COUNTIF(D9:AG9,"L/KL")/2) | AL9: =COUNTIF(D9:AH9,"KL")+COUNTIF(D9:AG9,"0,5KL")/2+COUNTIF(D9:AG9,"L/KL")/2+COUNTIF(D9:AG9,"KL/2")/2+COUNTIF(D9:AG9,"P/KL")/2+COUNTIF(D9:AG9,"0.5")/2 | AM9: =SUM(AI9:AL9) | AN9: =AI9+AJ9+AK9 | AO9: =VLOOKUP(C9,'[7]1. MEDIGO'!$C$4:$BL$100,62,0)
A10: 3 | C10: Nguyễn Thị Thúy Na | D10: 1 | F10: 1 | G10: 1 | H10: 1 | I10: 1 | J10: 1 | K10: 1 | M10: 1 | N10: 1 | O10: 1 | P10: 1 | Q10: 1 | R10: 1 | T10: 1 | U10: 1 | V10: 1 | W10: 1 | X10: P | Y10: 1 | AA10: 1 | AB10: 1 | AC10: 1 | AD10: 1 | AE10: 1 | AF10: P | AH10: P | AI10: =SUM(D10:AH10)+(COUNTIF(D10:AH10,"0,5KL")/2)+(COUNTIF(D10:AH10,"0,5P")/2)+(COUNTIF(D10:AH10,"0.5L")/2) | AJ10: =(COUNTIF(D10:AH10,"P"))+(COUNTIF(D10:AG10,"P/2")/2)+(COUNTIF(D10:AG10,"0,5P")/2)+(COUNTIF(D10:AG10,"L/P")/2)+(COUNTIF(D10:AG10,"P/KL")/2) | AK10: =COUNTIF(D10:AH10,"L")+(COUNTIF(D10:AG10,"L/2")/2)+(COUNTIF(D10:AG10,"L/P")/2)+(COUNTIF(D10:AG10,"L/KL")/2) | AL10: =COUNTIF(D10:AH10,"KL")+COUNTIF(D10:AG10,"0,5KL")/2+COUNTIF(D10:AG10,"L/KL")/2+COUNTIF(D10:AG10,"KL/2")/2+COUNTIF(D10:AG10,"P/KL")/2+COUNTIF(D10:AG10,"0.5")/2 | AM10: =SUM(AI10:AL10) | AN10: =AI10+AJ10+AK10 | AO10: =VLOOKUP(C10,'[7]1. MEDIGO'!$C$4:$BL$100,62,0)
A11: 4 | C11: Nguyễn Thành Tài | D11: 1 | F11: 1 | G11: 1 | H11: 1 | I11: 1 | J11: 1 | K11: 1 | M11: 1 | N11: 1 | O11: 1 | P11: 1 | Q11: 1 | R11: 1 | T11: 1 | U11: 1 | V11: 1 | W11: 1 | X11: 1 | Y11: 1 | AA11: 1 | AB11: 1 | AC11: 1 | AD11: 1 | AE11: 1 | AF11: 1 | AH11: 1 | AI11: =SUM(D11:AH11)+(COUNTIF(D11:AH11,"0,5KL")/2)+(COUNTIF(D11:AH11,"0,5P")/2)+(COUNTIF(D11:AH11,"0.5L")/2) | AJ11: =(COUNTIF(D11:AH11,"P"))+(COUNTIF(D11:AG11,"P/2")/2)+(COUNTIF(D11:AG11,"0,5P")/2)+(COUNTIF(D11:AG11,"L/P")/2)+(COUNTIF(D11:AG11,"P/KL")/2) | AK11: =COUNTIF(D11:AH11,"L")+(COUNTIF(D11:AG11,"L/2")/2)+(COUNTIF(D11:AG11,"L/P")/2)+(COUNTIF(D11:AG11,"L/KL")/2) | AL11: =COUNTIF(D11:AH11,"KL")+COUNTIF(D11:AG11,"0,5KL")/2+COUNTIF(D11:AG11,"L/KL")/2+COUNTIF(D11:AG11,"KL/2")/2+COUNTIF(D11:AG11,"P/KL")/2+COUNTIF(D11:AG11,"0.5")/2 | AM11: =SUM(AI11:AL11) | AN11: =AI11+AJ11+AK11 | AO11: =VLOOKUP(C11,'[7]1. MEDIGO'!$C$4:$BL$100,62,0)
A12: 5 | C12: Tô Ngọc Thiên Phú | D12: 1 | F12: 1 | G12: 1 | H12: 1 | I12: 1 | J12: 1 | K12: 1 | M12: 1 | N12: 1 | O12: 1 | P12: 1 | Q12: P | R12: P | T12: 1 | U12: 1 | V12: 1 | W12: 1 | X12: 1 | Y12: 1 | AA12: 1 | AB12: 1 | AC12: 1 | AD12: 1 | AE12: 1 | AF12: 1 | AH12: P | AI12: =SUM(D12:AH12)+(COUNTIF(D12:AH12,"0,5KL")/2)+(COUNTIF(D12:AH12,"0,5P")/2)+(COUNTIF(D12:AH12,"0.5L")/2) | AJ12: =(COUNTIF(D12:AH12,"P"))+(COUNTIF(D12:AG12,"P/2")/2)+(COUNTIF(D12:AG12,"0,5P")/2)+(COUNTIF(D12:AG12,"L/P")/2)+(COUNTIF(D12:AG12,"P/KL")/2) | AK12: =COUNTIF(D12:AH12,"L")+(COUNTIF(D12:AG12,"L/2")/2)+(COUNTIF(D12:AG12,"L/P")/2)+(COUNTIF(D12:AG12,"L/KL")/2) | AL12: =COUNTIF(D12:AH12,"KL")+COUNTIF(D12:AG12,"0,5KL")/2+COUNTIF(D12:AG12,"L/KL")/2+COUNTIF(D12:AG12,"KL/2")/2+COUNTIF(D12:AG12,"P/KL")/2+COUNTIF(D12:AG12,"0.5")/2 | AM12: =SUM(AI12:AL12) | AN12: =AI12+AJ12+AK12 | AO12: =VLOOKUP(C12,'[7]1. MEDIGO'!$C$4:$BL$100,62,0) | AP12: 46249
A13: 6 | C13: Huỳnh Quang Toàn | D13: 1 | F13: 1 | G13: 1 | H13: 1 | I13: 1 | J13: 1 | K13: 1 | M13: 1 | N13: 1 | O13: 1 | P13: 1 | Q13: 1 | R13: 1 | T13: 1 | U13: 1 | V13: 1 | W13: 1 | X13: 1 | Y13: 1 | AA13: 1 | AB13: 1 | AC13: 1 | AD13: 1 | AE13: 1 | AF13: 1 | AH13: 1 | AI13: =SUM(D13:AH13)+(COUNTIF(D13:AH13,"0,5KL")/2)+(COUNTIF(D13:AH13,"0,5P")/2)+(COUNTIF(D13:AH13,"0.5L")/2) | AJ13: =(COUNTIF(D13:AH13,"P"))+(COUNTIF(D13:AG13,"P/2")/2)+(COUNTIF(D13:AG13,"0,5P")/2)+(COUNTIF(D13:AG13,"L/P")/2)+(COUNTIF(D13:AG13,"P/KL")/2) | AK13: =COUNTIF(D13:AH13,"L")+(COUNTIF(D13:AG13,"L/2")/2)+(COUNTIF(D13:AG13,"L/P")/2)+(COUNTIF(D13:AG13,"L/KL")/2) | AL13: =COUNTIF(D13:AH13,"KL")+COUNTIF(D13:AG13,"0,5KL")/2+COUNTIF(D13:AG13,"L/KL")/2+COUNTIF(D13:AG13,"KL/2")/2+COUNTIF(D13:AG13,"P/KL")/2+COUNTIF(D13:AG13,"0.5")/2 | AM13: =SUM(AI13:AL13) | AN13: =AI13+AJ13+AK13 | AO13: HĐ CÔNG TÁC VIÊN TỪ THÁNG 4/2026
A14: 7 | C14: Nguyễn Tuấn Vinh | D14: 1 | F14: 1 | G14: 1 | H14: 1 | I14: 1 | J14: 1 | K14: 1 | M14: 1 | N14: 1 | O14: 1 | P14: 1 | Q14: 1 | R14: 1 | T14: 1 | U14: 1 | V14: 1 | W14: 1 | X14: 1 | Y14: 1 | AA14: 1 | AB14: 1 | AC14: 1 | AD14: 1 | AE14: 1 | AF14: 1 | AH14: 1 | AI14: =SUM(D14:AH14)+(COUNTIF(D14:AH14,"0,5KL")/2)+(COUNTIF(D14:AH14,"0,5P")/2)+(COUNTIF(D14:AH14,"0.5L")/2) | AJ14: =(COUNTIF(D14:AH14,"P"))+(COUNTIF(D14:AG14,"P/2")/2)+(COUNTIF(D14:AG14,"0,5P")/2)+(COUNTIF(D14:AG14,"L/P")/2)+(COUNTIF(D14:AG14,"P/KL")/2) | AK14: =COUNTIF(D14:AH14,"L")+(COUNTIF(D14:AG14,"L/2")/2)+(COUNTIF(D14:AG14,"L/P")/2)+(COUNTIF(D14:AG14,"L/KL")/2) | AL14: =COUNTIF(D14:AH14,"KL")+COUNTIF(D14:AG14,"0,5KL")/2+COUNTIF(D14:AG14,"L/KL")/2+COUNTIF(D14:AG14,"KL/2")/2+COUNTIF(D14:AG14,"P/KL")/2+COUNTIF(D14:AG14,"0.5")/2 | AM14: =SUM(AI14:AL14) | AN14: =AI14+AJ14+AK14 | AO14: HĐ CÔNG TÁC VIÊN TỪ THÁNG 5/2026
A15: 8 | C15: Hoàng Lê Thanh Vương | D15: 1 | F15: 1 | G15: 1 | H15: 1 | I15: 1 | J15: 1 | K15: 1 | M15: 1 | N15: 1 | O15: 1 | P15: 1 | Q15: 1 | R15: 1 | T15: 1 | U15: 1 | V15: 1 | W15: 1 | X15: 1 | Y15: 1 | AA15: 1 | AB15: 1 | AC15: 1 | AD15: 1 | AE15: 1 | AF15: 1 | AH15: 1 | AI15: =SUM(D15:AH15)+(COUNTIF(D15:AH15,"0,5KL")/2)+(COUNTIF(D15:AH15,"0,5P")/2)+(COUNTIF(D15:AH15,"0.5L")/2) | AJ15: =(COUNTIF(D15:AH15,"P"))+(COUNTIF(D15:AG15,"P/2")/2)+(COUNTIF(D15:AG15,"0,5P")/2)+(COUNTIF(D15:AG15,"L/P")/2)+(COUNTIF(D15:AG15,"P/KL")/2) | AK15: =COUNTIF(D15:AH15,"L")+(COUNTIF(D15:AG15,"L/2")/2)+(COUNTIF(D15:AG15,"L/P")/2)+(COUNTIF(D15:AG15,"L/KL")/2) | AL15: =COUNTIF(D15:AH15,"KL")+COUNTIF(D15:AG15,"0,5KL")/2+COUNTIF(D15:AG15,"L/KL")/2+COUNTIF(D15:AG15,"KL/2")/2+COUNTIF(D15:AG15,"P/KL")/2+COUNTIF(D15:AG15,"0.5")/2 | AM15: =SUM(AI15:AL15) | AN15: =AI15+AJ15+AK15 | AO15: =VLOOKUP(C15,'[7]1. MEDIGO'!$C$4:$BL$100,62,0)
A16: 9 | C16: Nguyễn Hoàng Nguyên Đan | D16: 1 | F16: 1 | G16: 1 | H16: 1 | I16: 1 | J16: 1 | K16: 1 | M16: 1 | N16: 1 | O16: 1 | P16: 1 | Q16: 1 | R16: 1 | T16: 1 | U16: 1 | V16: 1 | W16: 1 | X16: 1 | Y16: 1 | AA16: 1 | AB16: 1 | AC16: 1 | AD16: 1 | AE16: 1 | AF16: 1 | AH16: 1 | AI16: =SUM(D16:AH16)+(COUNTIF(D16:AH16,"0,5KL")/2)+(COUNTIF(D16:AH16,"0,5P")/2)+(COUNTIF(D16:AH16,"0.5L")/2) | AJ16: =(COUNTIF(D16:AH16,"P"))+(COUNTIF(D16:AG16,"P/2")/2)+(COUNTIF(D16:AG16,"0,5P")/2)+(COUNTIF(D16:AG16,"L/P")/2)+(COUNTIF(D16:AG16,"P/KL")/2) | AK16: =COUNTIF(D16:AH16,"L")+(COUNTIF(D16:AG16,"L/2")/2)+(COUNTIF(D16:AG16,"L/P")/2)+(COUNTIF(D16:AG16,"L/KL")/2) | AL16: =COUNTIF(D16:AH16,"KL")+COUNTIF(D16:AG16,"0,5KL")/2+COUNTIF(D16:AG16,"L/KL")/2+COUNTIF(D16:AG16,"KL/2")/2+COUNTIF(D16:AG16,"P/KL")/2+COUNTIF(D16:AG16,"0.5")/2 | AM16: =SUM(AI16:AL16) | AN16: =AI16+AJ16+AK16 | AO16: =VLOOKUP(C16,'[7]1. MEDIGO'!$C$4:$BL$100,62,0)
A17: 10 | C17: Nguyễn Văn Toàn | D17: 1 | F17: 1 | G17: 1 | H17: 1 | I17: 1 | J17: 1 | K17: 1 | M17: 1 | N17: 1 | O17: 1 | P17: 1 | Q17: 1 | R17: 1 | T17: 1 | U17: 1 | V17: 1 | W17: 1 | X17: 1 | Y17: 1 | AA17: 1 | AB17: 1 | AC17: 1 | AD17: 1 | AE17: P | AF17: P | AH17: P | AI17: =SUM(D17:AH17)+(COUNTIF(D17:AH17,"0,5KL")/2)+(COUNTIF(D17:AH17,"0,5P")/2)+(COUNTIF(D17:AH17,"0.5L")/2) | AJ17: =(COUNTIF(D17:AH17,"P"))+(COUNTIF(D17:AG17,"P/2")/2)+(COUNTIF(D17:AG17,"0,5P")/2)+(COUNTIF(D17:AG17,"L/P")/2)+(COUNTIF(D17:AG17,"P/KL")/2) | AK17: =COUNTIF(D17:AH17,"L")+(COUNTIF(D17:AG17,"L/2")/2)+(COUNTIF(D17:AG17,"L/P")/2)+(COUNTIF(D17:AG17,"L/KL")/2) | AL17: =COUNTIF(D17:AH17,"KL")+COUNTIF(D17:AG17,"0,5KL")/2+COUNTIF(D17:AG17,"L/KL")/2+COUNTIF(D17:AG17,"KL/2")/2+COUNTIF(D17:AG17,"P/KL")/2+COUNTIF(D17:AG17,"0.5")/2 | AM17: =SUM(AI17:AL17) | AN17: =AI17+AJ17+AK17 | AO17: =VLOOKUP(C17,'[7]1. MEDIGO'!$C$4:$BL$100,62,0) | AP17: 46263
A18: 11 | C18: Lê Phú Quí | D18: 1 | F18: 1 | G18: 1 | H18: 1 | I18: 1 | J18: 1 | K18: 1 | M18: 1 | N18: 1 | O18: 1 | P18: 1 | Q18: 1 | R18: 1 | T18: 1 | U18: 1 | V18: 1 | W18: 1 | X18: 1 | Y18: 1 | AA18: 1 | AB18: 1 | AC18: 1 | AD18: 1 | AE18: 1 | AF18: 1 | AH18: P | AI18: =SUM(D18:AH18)+(COUNTIF(D18:AH18,"0,5KL")/2)+(COUNTIF(D18:AH18,"0,5P")/2)+(COUNTIF(D18:AH18,"0.5L")/2) | AJ18: =(COUNTIF(D18:AH18,"P"))+(COUNTIF(D18:AG18,"P/2")/2)+(COUNTIF(D18:AG18,"0,5P")/2)+(COUNTIF(D18:AG18,"L/P")/2)+(COUNTIF(D18:AG18,"P/KL")/2) | AK18: =COUNTIF(D18:AH18,"L")+(COUNTIF(D18:AG18,"L/2")/2)+(COUNTIF(D18:AG18,"L/P")/2)+(COUNTIF(D18:AG18,"L/KL")/2) | AL18: =COUNTIF(D18:AH18,"KL")+COUNTIF(D18:AG18,"0,5KL")/2+COUNTIF(D18:AG18,"L/KL")/2+COUNTIF(D18:AG18,"KL/2")/2+COUNTIF(D18:AG18,"P/KL")/2+COUNTIF(D18:AG18,"0.5")/2 | AM18: =SUM(AI18:AL18) | AN18: =AI18+AJ18+AK18 | AO18: =VLOOKUP(C18,'[7]1. MEDIGO'!$C$4:$BL$100,62,0)
A19: 12 | C19: Nguyễn Hồ Phương Anh | D19: 1 | F19: 1 | G19: 1 | H19: 1 | I19: 1 | J19: 1 | K19: 1 | M19: 1 | N19: 1 | O19: 1 | P19: 1 | Q19: 1 | R19: 1 | T19: 1 | U19: 1 | V19: 1 | W19: 1 | X19: 1 | Y19: 1 | AA19: 1 | AB19: 1 | AC19: 1 | AD19: 1 | AE19: 1 | AF19: 1 | AH19: 1 | AI19: =SUM(D19:AH19)+(COUNTIF(D19:AH19,"0,5KL")/2)+(COUNTIF(D19:AH19,"0,5P")/2)+(COUNTIF(D19:AH19,"0.5L")/2) | AJ19: =(COUNTIF(D19:AH19,"P"))+(COUNTIF(D19:AG19,"P/2")/2)+(COUNTIF(D19:AG19,"0,5P")/2)+(COUNTIF(D19:AG19,"L/P")/2)+(COUNTIF(D19:AG19,"P/KL")/2) | AK19: =COUNTIF(D19:AH19,"L")+(COUNTIF(D19:AG19,"L/2")/2)+(COUNTIF(D19:AG19,"L/P")/2)+(COUNTIF(D19:AG19,"L/KL")/2) | AL19: =COUNTIF(D19:AH19,"KL")+COUNTIF(D19:AG19,"0,5KL")/2+COUNTIF(D19:AG19,"L/KL")/2+COUNTIF(D19:AG19,"KL/2")/2+COUNTIF(D19:AG19,"P/KL")/2+COUNTIF(D19:AG19,"0.5")/2 | AM19: =SUM(AI19:AL19) | AN19: =AI19+AJ19+AK19 | AO19: =VLOOKUP(C19,'[7]1. MEDIGO'!$C$4:$BL$100,62,0)
A20: 13 | C20: Nguyễn Thị Ngọc Hân | D20: 1 | F20: 1 | G20: 1 | H20: 1 | I20: 1 | J20: 1 | K20: 1 | M20: 1 | N20: 1 | O20: 1 | P20: 1 | Q20: 1 | R20: 1 | T20: 1 | U20: 1 | V20: 1 | W20: 1 | X20: 1 | Y20: 1 | AA20: 1 | AB20: 1 | AC20: 1 | AD20: 1 | AE20: 1 | AF20: 1 | AH20: 1 | AI20: =SUM(D20:AH20)+(COUNTIF(D20:AH20,"0,5KL")/2)+(COUNTIF(D20:AH20,"0,5P")/2)+(COUNTIF(D20:AH20,"0.5L")/2) | AJ20: =(COUNTIF(D20:AH20,"P"))+(COUNTIF(D20:AG20,"P/2")/2)+(COUNTIF(D20:AG20,"0,5P")/2)+(COUNTIF(D20:AG20,"L/P")/2)+(COUNTIF(D20:AG20,"P/KL")/2) | AK20: =COUNTIF(D20:AH20,"L")+(COUNTIF(D20:AG20,"L/2")/2)+(COUNTIF(D20:AG20,"L/P")/2)+(COUNTIF(D20:AG20,"L/KL")/2) | AL20: =COUNTIF(D20:AH20,"KL")+COUNTIF(D20:AG20,"0,5KL")/2+COUNTIF(D20:AG20,"L/KL")/2+COUNTIF(D20:AG20,"KL/2")/2+COUNTIF(D20:AG20,"P/KL")/2+COUNTIF(D20:AG20,"0.5")/2 | AM20: =SUM(AI20:AL20) | AN20: =AI20+AJ20+AK20 | AO20: =VLOOKUP(C20,'[7]1. MEDIGO'!$C$4:$BL$100,62,0)
A21: 14 | C21: Võ Thị Diệu Hiền | D21: 1 | F21: 1 | G21: 1 | H21: 1 | I21: 1 | J21: 1 | K21: 1 | M21: 1 | N21: 1 | O21: 1 | P21: 1 | Q21: 1 | R21: 1 | T21: 1 | U21: 1 | V21: 1 | W21: 1 | X21: 1 | Y21: 1 | AA21: 1 | AB21: 1 | AC21: 1 | AD21: 1 | AE21: 1 | AF21: 1 | AH21: 1 | AI21: =SUM(D21:AH21)+(COUNTIF(D21:AH21,"0,5KL")/2)+(COUNTIF(D21:AH21,"0,5P")/2)+(COUNTIF(D21:AH21,"0.5L")/2) | AJ21: =(COUNTIF(D21:AH21,"P"))+(COUNTIF(D21:AG21,"P/2")/2)+(COUNTIF(D21:AG21,"0,5P")/2)+(COUNTIF(D21:AG21,"L/P")/2)+(COUNTIF(D21:AG21,"P/KL")/2) | AK21: =COUNTIF(D21:AH21,"L")+(COUNTIF(D21:AG21,"L/2")/2)+(COUNTIF(D21:AG21,"L/P")/2)+(COUNTIF(D21:AG21,"L/KL")/2) | AL21: =COUNTIF(D21:AH21,"KL")+COUNTIF(D21:AG21,"0,5KL")/2+COUNTIF(D21:AG21,"L/KL")/2+COUNTIF(D21:AG21,"KL/2")/2+COUNTIF(D21:AG21,"P/KL")/2+COUNTIF(D21:AG21,"0.5")/2 | AM21: =SUM(AI21:AL21) | AN21: =AI21+AJ21+AK21 | AO21: =VLOOKUP(C21,'[7]1. MEDIGO'!$C$4:$BL$100,62,0)
A22: 15 | C22: Lưu Thanh Tuyền | D22: 1 | F22: 1 | G22: 1 | H22: 1 | I22: 1 | J22: 1 | K22: 1 | M22: 1 | N22: 1 | O22: 1 | P22: 1 | Q22: 1 | R22: 1 | T22: 1 | U22: 1 | V22: 1 | W22: 1 | X22: 1 | Y22: 1 | AA22: 1 | AB22: 1 | AC22: 1 | AD22: 1 | AE22: 1 | AF22: 1 | AH22: 1 | AI22: =SUM(D22:AH22)+(COUNTIF(D22:AH22,"0,5KL")/2)+(COUNTIF(D22:AH22,"0,5P")/2)+(COUNTIF(D22:AH22,"0.5L")/2) | AJ22: =(COUNTIF(D22:AH22,"P"))+(COUNTIF(D22:AG22,"P/2")/2)+(COUNTIF(D22:AG22,"0,5P")/2)+(COUNTIF(D22:AG22,"L/P")/2)+(COUNTIF(D22:AG22,"P/KL")/2) | AK22: =COUNTIF(D22:AH22,"L")+(COUNTIF(D22:AG22,"L/2")/2)+(COUNTIF(D22:AG22,"L/P")/2)+(COUNTIF(D22:AG22,"L/KL")/2) | AL22: =COUNTIF(D22:AH22,"KL")+COUNTIF(D22:AG22,"0,5KL")/2+COUNTIF(D22:AG22,"L/KL")/2+COUNTIF(D22:AG22,"KL/2")/2+COUNTIF(D22:AG22,"P/KL")/2+COUNTIF(D22:AG22,"0.5")/2 | AM22: =SUM(AI22:AL22) | AN22: =AI22+AJ22+AK22 | AO22: =VLOOKUP(C22,'[7]1. MEDIGO'!$C$4:$BL$100,62,0)
A23: 16 | C23: Võ Tấn Trường | D23: P | F23: P | G23: 1 | H23: 1 | I23: 1 | J23: 1 | K23: 1 | M23: 1 | N23: 1 | O23: 1 | P23: 1 | Q23: 1 | R23: 1 | T23: 1 | U23: 1 | V23: 1 | W23: 1 | X23: 1 | Y23: 1 | AA23: 1 | AB23: 1 | AC23: 1 | AD23: 1 | AE23: 1 | AF23: 1 | AH23: 1 | AI23: =SUM(D23:AH23)+(COUNTIF(D23:AH23,"0,5KL")/2)+(COUNTIF(D23:AH23,"0,5P")/2)+(COUNTIF(D23:AH23,"0.5L")/2) | AJ23: =(COUNTIF(D23:AH23,"P"))+(COUNTIF(D23:AG23,"P/2")/2)+(COUNTIF(D23:AG23,"0,5P")/2)+(COUNTIF(D23:AG23,"L/P")/2)+(COUNTIF(D23:AG23,"P/KL")/2) | AK23: =COUNTIF(D23:AH23,"L")+(COUNTIF(D23:AG23,"L/2")/2)+(COUNTIF(D23:AG23,"L/P")/2)+(COUNTIF(D23:AG23,"L/KL")/2) | AL23: =COUNTIF(D23:AH23,"KL")+COUNTIF(D23:AG23,"0,5KL")/2+COUNTIF(D23:AG23,"L/KL")/2+COUNTIF(D23:AG23,"KL/2")/2+COUNTIF(D23:AG23,"P/KL")/2+COUNTIF(D23:AG23,"0.5")/2 | AM23: =SUM(AI23:AL23) | AN23: =AI23+AJ23+AK23 | AO23: =VLOOKUP(C23,'[7]1. MEDIGO'!$C$4:$BL$100,62,0)
A24: 17 | C24: Trần Thị Tâm Nhung | D24: 1 | F24: 1 | G24: 1 | H24: 1 | I24: 1 | J24: 1 | K24: 1 | M24: 1 | N24: 1 | O24: 1 | P24: 1 | Q24: 1 | R24: 1 | T24: 1 | U24: 1 | V24: 1 | W24: 1 | X24: P | Y24: 1 | AA24: 1 | AB24: 1 | AC24: 1 | AD24: 1 | AE24: 1 | AF24: 1 | AH24: 1 | AI24: =SUM(D24:AH24)+(COUNTIF(D24:AH24,"0,5KL")/2)+(COUNTIF(D24:AH24,"0,5P")/2)+(COUNTIF(D24:AH24,"0.5L")/2) | AJ24: =(COUNTIF(D24:AH24,"P"))+(COUNTIF(D24:AG24,"P/2")/2)+(COUNTIF(D24:AG24,"0,5P")/2)+(COUNTIF(D24:AG24,"L/P")/2)+(COUNTIF(D24:AG24,"P/KL")/2) | AK24: =COUNTIF(D24:AH24,"L")+(COUNTIF(D24:AG24,"L/2")/2)+(COUNTIF(D24:AG24,"L/P")/2)+(COUNTIF(D24:AG24,"L/KL")/2) | AL24: =COUNTIF(D24:AH24,"KL")+COUNTIF(D24:AG24,"0,5KL")/2+COUNTIF(D24:AG24,"L/KL")/2+COUNTIF(D24:AG24,"KL/2")/2+COUNTIF(D24:AG24,"P/KL")/2+COUNTIF(D24:AG24,"0.5")/2 | AM24: =SUM(AI24:AL24) | AN24: =AI24+AJ24+AK24 | AO24: =VLOOKUP(C24,'[7]1. MEDIGO'!$C$4:$BL$100,62,0)
A25: 18 | C25: Nguyễn Tuấn Nghĩa | D25: 1 | F25: 1 | G25: 1 | H25: 1 | I25: 1 | J25: 1 | K25: 1 | M25: 1 | N25: 1 | O25: 1 | P25: 1 | Q25: 1 | R25: 1 | T25: 1 | U25: 1 | V25: 1 | W25: 1 | X25: 1 | Y25: 1 | AA25: 1 | AB25: 1 | AC25: 1 | AD25: 1 | AE25: 1 | AF25: 1 | AH25: 1 | AI25: =SUM(D25:AH25)+(COUNTIF(D25:AH25,"0,5KL")/2)+(COUNTIF(D25:AH25,"0,5P")/2)+(COUNTIF(D25:AH25,"0.5L")/2) | AJ25: =(COUNTIF(D25:AH25,"P"))+(COUNTIF(D25:AG25,"P/2")/2)+(COUNTIF(D25:AG25,"0,5P")/2)+(COUNTIF(D25:AG25,"L/P")/2)+(COUNTIF(D25:AG25,"P/KL")/2) | AK25: =COUNTIF(D25:AH25,"L")+(COUNTIF(D25:AG25,"L/2")/2)+(COUNTIF(D25:AG25,"L/P")/2)+(COUNTIF(D25:AG25,"L/KL")/2) | AL25: =COUNTIF(D25:AH25,"KL")+COUNTIF(D25:AG25,"0,5KL")/2+COUNTIF(D25:AG25,"L/KL")/2+COUNTIF(D25:AG25,"KL/2")/2+COUNTIF(D25:AG25,"P/KL")/2+COUNTIF(D25:AG25,"0.5")/2 | AM25: =SUM(AI25:AL25) | AN25: =AI25+AJ25+AK25 | AO25: =VLOOKUP(C25,'[7]1. MEDIGO'!$C$4:$BL$100,62,0)
A26: 19 | C26: Nguyễn Thị Cẩm Bình | D26: 1 | F26: 1 | G26: 1 | H26: 1 | I26: 1 | J26: 1 | K26: 1 | M26: 1 | N26: 1 | O26: 1 | P26: 1 | Q26: 1 | R26: 1 | T26: 1 | U26: 1 | V26: 1 | W26: 1 | X26: 1 | Y26: 1 | AA26: 1 | AB26: 1 | AC26: 1 | AD26: 1 | AE26: 1 | AF26: 1 | AH26: 1 | AI26: =SUM(D26:AH26)+(COUNTIF(D26:AH26,"0,5KL")/2)+(COUNTIF(D26:AH26,"0,5P")/2)+(COUNTIF(D26:AH26,"0.5L")/2) | AJ26: =(COUNTIF(D26:AH26,"P"))+(COUNTIF(D26:AG26,"P/2")/2)+(COUNTIF(D26:AG26,"0,5P")/2)+(COUNTIF(D26:AG26,"L/P")/2)+(COUNTIF(D26:AG26,"P/KL")/2) | AK26: =COUNTIF(D26:AH26,"L")+(COUNTIF(D26:AG26,"L/2")/2)+(COUNTIF(D26:AG26,"L/P")/2)+(COUNTIF(D26:AG26,"L/KL")/2) | AL26: =COUNTIF(D26:AH26,"KL")+COUNTIF(D26:AG26,"0,5KL")/2+COUNTIF(D26:AG26,"L/KL")/2+COUNTIF(D26:AG26,"KL/2")/2+COUNTIF(D26:AG26,"P/KL")/2+COUNTIF(D26:AG26,"0.5")/2 | AM26: =SUM(AI26:AL26) | AN26: =AI26+AJ26+AK26 | AO26: =VLOOKUP(C26,'[7]1. MEDIGO'!$C$4:$BL$100,62,0)
A27: 20 | C27: Nguyễn Cao Nhân | D27: 1 | F27: 1 | G27: 1 | H27: 1 | I27: 1 | J27: 1 | K27: 1 | M27: 1 | N27: 1 | O27: 1 | P27: 1 | Q27: 1 | R27: 1 | T27: 1 | U27: 1 | V27: 1 | W27: 1 | X27: 1 | Y27: 1 | AA27: 1 | AB27: 1 | AC27: 1 | AD27: 1 | AE27: 1 | AF27: 1 | AH27: 1 | AI27: =SUM(D27:AH27)+(COUNTIF(D27:AH27,"0,5KL")/2)+(COUNTIF(D27:AH27,"0,5P")/2)+(COUNTIF(D27:AH27,"0.5L")/2) | AJ27: =(COUNTIF(D27:AH27,"P"))+(COUNTIF(D27:AG27,"P/2")/2)+(COUNTIF(D27:AG27,"0,5P")/2)+(COUNTIF(D27:AG27,"L/P")/2)+(COUNTIF(D27:AG27,"P/KL")/2) | AK27: =COUNTIF(D27:AH27,"L")+(COUNTIF(D27:AG27,"L/2")/2)+(COUNTIF(D27:AG27,"L/P")/2)+(COUNTIF(D27:AG27,"L/KL")/2) | AL27: =COUNTIF(D27:AH27,"KL")+COUNTIF(D27:AG27,"0,5KL")/2+COUNTIF(D27:AG27,"L/KL")/2+COUNTIF(D27:AG27,"KL/2")/2+COUNTIF(D27:AG27,"P/KL")/2+COUNTIF(D27:AG27,"0.5")/2 | AM27: =SUM(AI27:AL27) | AN27: =AI27+AJ27+AK27 | AO27: =VLOOKUP(C27,'[7]1. MEDIGO'!$C$4:$BL$100,62,0)
A28: 21 | C28: Đặng Thị Quế Anh | D28: 1 | F28: 1 | G28: 1 | H28: 1 | I28: 1 | J28: 1 | K28: 1 | M28: 1 | N28: 1 | O28: 1 | P28: 1 | Q28: 1 | R28: 1 | T28: 1 | U28: 1 | V28: 1 | W28: 1 | X28: 1 | Y28: 1 | AA28: P | AB28: 1 | AC28: 1 | AD28: 1 | AE28: 1 | AF28: 1 | AH28: P | AI28: =SUM(D28:AH28)+(COUNTIF(D28:AH28,"0,5KL")/2)+(COUNTIF(D28:AH28,"0,5P")/2)+(COUNTIF(D28:AH28,"0.5L")/2) | AJ28: =(COUNTIF(D28:AH28,"P"))+(COUNTIF(D28:AG28,"P/2")/2)+(COUNTIF(D28:AG28,"0,5P")/2)+(COUNTIF(D28:AG28,"L/P")/2)+(COUNTIF(D28:AG28,"P/KL")/2) | AK28: =COUNTIF(D28:AH28,"L")+(COUNTIF(D28:AG28,"L/2")/2)+(COUNTIF(D28:AG28,"L/P")/2)+(COUNTIF(D28:AG28,"L/KL")/2) | AL28: =COUNTIF(D28:AH28,"KL")+COUNTIF(D28:AG28,"0,5KL")/2+COUNTIF(D28:AG28,"L/KL")/2+COUNTIF(D28:AG28,"KL/2")/2+COUNTIF(D28:AG28,"P/KL")/2+COUNTIF(D28:AG28,"0.5")/2 | AM28: =SUM(AI28:AL28) | AN28: =AI28+AJ28+AK28 | AO28: =VLOOKUP(C28,'[7]1. MEDIGO'!$C$4:$BL$100,62,0)
A29: 22 | C29: Nguyễn Thị Ánh Hồng | D29: 1 | F29: 1 | G29: 1 | H29: 1 | I29: 1 | J29: 1 | K29: 1 | M29: 1 | N29: 1 | O29: 1 | P29: 1 | Q29: 1 | R29: 1 | T29: 1 | U29: 1 | V29: 1 | W29: 1 | X29: 1 | Y29: 1 | AA29: 1 | AB29: 1 | AC29: 1 | AD29: 1 | AE29: 1 | AF29: 1 | AH29: 1 | AI29: =SUM(D29:AH29)+(COUNTIF(D29:AH29,"0,5KL")/2)+(COUNTIF(D29:AH29,"0,5P")/2)+(COUNTIF(D29:AH29,"0.5L")/2) | AJ29: =(COUNTIF(D29:AH29,"P"))+(COUNTIF(D29:AG29,"P/2")/2)+(COUNTIF(D29:AG29,"0,5P")/2)+(COUNTIF(D29:AG29,"L/P")/2)+(COUNTIF(D29:AG29,"P/KL")/2) | AK29: =COUNTIF(D29:AH29,"L")+(COUNTIF(D29:AG29,"L/2")/2)+(COUNTIF(D29:AG29,"L/P")/2)+(COUNTIF(D29:AG29,"L/KL")/2) | AL29: =COUNTIF(D29:AH29,"KL")+COUNTIF(D29:AG29,"0,5KL")/2+COUNTIF(D29:AG29,"L/KL")/2+COUNTIF(D29:AG29,"KL/2")/2+COUNTIF(D29:AG29,"P/KL")/2+COUNTIF(D29:AG29,"0.5")/2 | AM29: =SUM(AI29:AL29) | AN29: =AI29+AJ29+AK29 | AO29: =VLOOKUP(C29,'[7]1. MEDIGO'!$C$4:$BL$100,62,0)
A30: 23 | C30: Phan Thị Kim Hiên | D30: 1 | F30: 1 | G30: 1 | H30: 1 | I30: 1 | J30: 1 | K30: 1 | M30: 1 | N30: 1 | O30: 1 | P30: 1 | Q30: 1 | R30: 1 | T30: 1 | U30: 1 | V30: 1 | W30: 1 | X30: 1 | Y30: 1 | AA30: 1 | AB30: 1 | AC30: 1 | AD30: 1 | AE30: 1 | AF30: 1 | AH30: 1 | AI30: =SUM(D30:AH30)+(COUNTIF(D30:AH30,"0,5KL")/2)+(COUNTIF(D30:AH30,"0,5P")/2)+(COUNTIF(D30:AH30,"0.5L")/2) | AJ30: =(COUNTIF(D30:AH30,"P"))+(COUNTIF(D30:AG30,"P/2")/2)+(COUNTIF(D30:AG30,"0,5P")/2)+(COUNTIF(D30:AG30,"L/P")/2)+(COUNTIF(D30:AG30,"P/KL")/2) | AK30: =COUNTIF(D30:AH30,"L")+(COUNTIF(D30:AG30,"L/2")/2)+(COUNTIF(D30:AG30,"L/P")/2)+(COUNTIF(D30:AG30,"L/KL")/2) | AL30: =COUNTIF(D30:AH30,"KL")+COUNTIF(D30:AG30,"0,5KL")/2+COUNTIF(D30:AG30,"L/KL")/2+COUNTIF(D30:AG30,"KL/2")/2+COUNTIF(D30:AG30,"P/KL")/2+COUNTIF(D30:AG30,"0.5")/2 | AM30: =SUM(AI30:AL30) | AN30: =AI30+AJ30+AK30 | AO30: =VLOOKUP(C30,'[7]1. MEDIGO'!$C$4:$BL$100,62,0)
A31: 24 | C31: Lê Thị Phương Thảo | D31: 1 | F31: 1 | G31: 1 | H31: 1 | I31: 1 | J31: 1 | K31: 1 | M31: 1 | N31: 1 | O31: 1 | P31: 1 | Q31: 1 | R31: 1 | T31: 1 | U31: 1 | V31: 1 | W31: 1 | X31: 1 | Y31: 1 | AA31: 1 | AB31: 1 | AC31: 1 | AD31: 1 | AE31: 1 | AF31: 1 | AH31: 1 | AI31: =SUM(D31:AH31)+(COUNTIF(D31:AH31,"0,5KL")/2)+(COUNTIF(D31:AH31,"0,5P")/2)+(COUNTIF(D31:AH31,"0.5L")/2) | AJ31: =(COUNTIF(D31:AH31,"P"))+(COUNTIF(D31:AG31,"P/2")/2)+(COUNTIF(D31:AG31,"0,5P")/2)+(COUNTIF(D31:AG31,"L/P")/2)+(COUNTIF(D31:AG31,"P/KL")/2) | AK31: =COUNTIF(D31:AH31,"L")+(COUNTIF(D31:AG31,"L/2")/2)+(COUNTIF(D31:AG31,"L/P")/2)+(COUNTIF(D31:AG31,"L/KL")/2) | AL31: =COUNTIF(D31:AH31,"KL")+COUNTIF(D31:AG31,"0,5KL")/2+COUNTIF(D31:AG31,"L/KL")/2+COUNTIF(D31:AG31,"KL/2")/2+COUNTIF(D31:AG31,"P/KL")/2+COUNTIF(D31:AG31,"0.5")/2 | AM31: =SUM(AI31:AL31) | AN31: =AI31+AJ31+AK31 | AO31: =VLOOKUP(C31,'[7]1. MEDIGO'!$C$4:$BL$100,62,0)
A32: 25 | C32: Huỳnh Tấn Nhân | D32: 1 | F32: 1 | G32: 1 | H32: 1 | I32: 1 | J32: 1 | K32: 1 | M32: 1 | N32: 1 | O32: 1 | P32: 1 | Q32: 1 | R32: 1 | T32: 1 | U32: P | V32: P | W32: P | X32: 1 | Y32: 1 | AA32: 1 | AB32: 1 | AC32: 1 | AD32: 1 | AE32: 1 | AF32: 1 | AH32: 1 | AI32: =SUM(D32:AH32)+(COUNTIF(D32:AH32,"0,5KL")/2)+(COUNTIF(D32:AH32,"0,5P")/2)+(COUNTIF(D32:AH32,"0.5L")/2) | AJ32: =(COUNTIF(D32:AH32,"P"))+(COUNTIF(D32:AG32,"P/2")/2)+(COUNTIF(D32:AG32,"0,5P")/2)+(COUNTIF(D32:AG32,"L/P")/2)+(COUNTIF(D32:AG32,"P/KL")/2) | AK32: =COUNTIF(D32:AH32,"L")+(COUNTIF(D32:AG32,"L/2")/2)+(COUNTIF(D32:AG32,"L/P")/2)+(COUNTIF(D32:AG32,"L/KL")/2) | AL32: =COUNTIF(D32:AH32,"KL")+COUNTIF(D32:AG32,"0,5KL")/2+COUNTIF(D32:AG32,"L/KL")/2+COUNTIF(D32:AG32,"KL/2")/2+COUNTIF(D32:AG32,"P/KL")/2+COUNTIF(D32:AG32,"0.5")/2 | AM32: =SUM(AI32:AL32) | AN32: =AI32+AJ32+AK32 | AO32: =VLOOKUP(C32,'[7]1. MEDIGO'!$C$4:$BL$100,62,0)
A33: 26 | C33: Nguyễn Thị Kim Ngọc | D33: 1 | F33: 1 | G33: 1 | H33: 1 | I33: 1 | J33: 1 | K33: 1 | M33: 1 | N33: 1 | O33: 1 | P33: 1 | Q33: 1 | R33: 1 | T33: P | U33: 1 | V33: 1 | W33: 1 | X33: 1 | Y33: 1 | AA33: 1 | AB33: P | AC33: P | AD33: 1 | AE33: 1 | AF33: 1 | AH33: 1 | AI33: =SUM(D33:AH33)+(COUNTIF(D33:AH33,"0,5KL")/2)+(COUNTIF(D33:AH33,"0,5P")/2)+(COUNTIF(D33:AH33,"0.5L")/2) | AJ33: =(COUNTIF(D33:AH33,"P"))+(COUNTIF(D33:AG33,"P/2")/2)+(COUNTIF(D33:AG33,"0,5P")/2)+(COUNTIF(D33:AG33,"L/P")/2)+(COUNTIF(D33:AG33,"P/KL")/2) | AK33: =COUNTIF(D33:AH33,"L")+(COUNTIF(D33:AG33,"L/2")/2)+(COUNTIF(D33:AG33,"L/P")/2)+(COUNTIF(D33:AG33,"L/KL")/2) | AL33: =COUNTIF(D33:AH33,"KL")+COUNTIF(D33:AG33,"0,5KL")/2+COUNTIF(D33:AG33,"L/KL")/2+COUNTIF(D33:AG33,"KL/2")/2+COUNTIF(D33:AG33,"P/KL")/2+COUNTIF(D33:AG33,"0.5")/2 | AM33: =SUM(AI33:AL33) | AN33: =AI33+AJ33+AK33 | AO33: =VLOOKUP(C33,'[7]1. MEDIGO'!$C$4:$BL$100,62,0)
A34: 27 | C34: Lê Thị Phương Anh | D34: 1 | F34: 1 | G34: 1 | H34: 1 | I34: 1 | J34: 1 | K34: 1 | M34: 1 | N34: 1 | O34: 1 | P34: 1 | Q34: 1 | R34: 1 | T34: 1 | U34: 1 | V34: 1 | W34: 1 | X34: 1 | Y34: 1 | AA34: 1 | AB34: 1 | AC34: 1 | AD34: 1 | AE34: 1 | AF34: 1 | AH34: 1 | AI34: =SUM(D34:AH34)+(COUNTIF(D34:AH34,"0,5KL")/2)+(COUNTIF(D34:AH34,"0,5P")/2)+(COUNTIF(D34:AH34,"0.5L")/2) | AJ34: =(COUNTIF(D34:AH34,"P"))+(COUNTIF(D34:AG34,"P/2")/2)+(COUNTIF(D34:AG34,"0,5P")/2)+(COUNTIF(D34:AG34,"L/P")/2)+(COUNTIF(D34:AG34,"P/KL")/2) | AK34: =COUNTIF(D34:AH34,"L")+(COUNTIF(D34:AG34,"L/2")/2)+(COUNTIF(D34:AG34,"L/P")/2)+(COUNTIF(D34:AG34,"L/KL")/2) | AL34: =COUNTIF(D34:AH34,"KL")+COUNTIF(D34:AG34,"0,5KL")/2+COUNTIF(D34:AG34,"L/KL")/2+COUNTIF(D34:AG34,"KL/2")/2+COUNTIF(D34:AG34,"P/KL")/2+COUNTIF(D34:AG34,"0.5")/2 | AM34: =SUM(AI34:AL34) | AN34: =AI34+AJ34+AK34 | AO34: =VLOOKUP(C34,'[7]1. MEDIGO'!$C$4:$BL$100,62,0)
A35: 28 | C35: Nguyễn Vũ Khôi | D35: 1 | F35: 1 | G35: 1 | H35: 1 | I35: 1 | J35: 1 | K35: 1 | M35: 1 | N35: 1 | O35: 1 | P35: 1 | Q35: 1 | R35: 1 | T35: 1 | U35: 1 | V35: 1 | W35: 1 | X35: 1 | Y35: 1 | AA35: 1 | AB35: 1 | AC35: 1 | AD35: 1 | AE35: 1 | AF35: 1 | AH35: 1 | AI35: =SUM(D35:AH35)+(COUNTIF(D35:AH35,"0,5KL")/2)+(COUNTIF(D35:AH35,"0,5P")/2)+(COUNTIF(D35:AH35,"0.5L")/2) | AJ35: =(COUNTIF(D35:AH35,"P"))+(COUNTIF(D35:AG35,"P/2")/2)+(COUNTIF(D35:AG35,"0,5P")/2)+(COUNTIF(D35:AG35,"L/P")/2)+(COUNTIF(D35:AG35,"P/KL")/2) | AK35: =COUNTIF(D35:AH35,"L")+(COUNTIF(D35:AG35,"L/2")/2)+(COUNTIF(D35:AG35,"L/P")/2)+(COUNTIF(D35:AG35,"L/KL")/2) | AL35: =COUNTIF(D35:AH35,"KL")+COUNTIF(D35:AG35,"0,5KL")/2+COUNTIF(D35:AG35,"L/KL")/2+COUNTIF(D35:AG35,"KL/2")/2+COUNTIF(D35:AG35,"P/KL")/2+COUNTIF(D35:AG35,"0.5")/2 | AM35: =SUM(AI35:AL35) | AN35: =AI35+AJ35+AK35 | AO35: =VLOOKUP(C35,'[7]1. MEDIGO'!$C$4:$BL$100,62,0)
A36: 29 | C36: Lai Thị Bích Châu | D36: 1 | F36: 1 | G36: 1 | H36: 1 | I36: 1 | J36: 1 | K36: 1 | M36: 1 | N36: 1 | O36: 1 | P36: 1 | Q36: 1 | R36: 1 | T36: 1 | U36: 1 | V36: 1 | W36: 1 | X36: 1 | Y36: 1 | AA36: 1 | AB36: 1 | AC36: 1 | AD36: 1 | AE36: 1 | AF36: 1 | AH36: 1 | AI36: =SUM(D36:AH36)+(COUNTIF(D36:AH36,"0,5KL")/2)+(COUNTIF(D36:AH36,"0,5P")/2)+(COUNTIF(D36:AH36,"0.5L")/2) | AJ36: =(COUNTIF(D36:AH36,"P"))+(COUNTIF(D36:AG36,"P/2")/2)+(COUNTIF(D36:AG36,"0,5P")/2)+(COUNTIF(D36:AG36,"L/P")/2)+(COUNTIF(D36:AG36,"P/KL")/2) | AK36: =COUNTIF(D36:AH36,"L")+(COUNTIF(D36:AG36,"L/2")/2)+(COUNTIF(D36:AG36,"L/P")/2)+(COUNTIF(D36:AG36,"L/KL")/2) | AL36: =COUNTIF(D36:AH36,"KL")+COUNTIF(D36:AG36,"0,5KL")/2+COUNTIF(D36:AG36,"L/KL")/2+COUNTIF(D36:AG36,"KL/2")/2+COUNTIF(D36:AG36,"P/KL")/2+COUNTIF(D36:AG36,"0.5")/2 | AM36: =SUM(AI36:AL36) | AN36: =AI36+AJ36+AK36 | AO36: =VLOOKUP(C36,'[7]1. MEDIGO'!$C$4:$BL$100,62,0)
B37: MED | D37: 1 | F37: 1 | G37: 1 | H37: 1 | I37: 1 | J37: 1 | K37: 1 | M37: 1 | N37: 1 | O37: 1 | P37: 1 | Q37: 1 | R37: 1 | T37: 1 | U37: 1 | V37: 1 | W37: 1 | X37: 1 | Y37: 1 | AA37: 1 | AB37: 1 | AC37: 1 | AD37: 1 | AE37: 1 | AF37: 1 | AH37: 1 | AI37: =SUM(D37:AH37)+(COUNTIF(D37:AH37,"0,5KL")/2)+(COUNTIF(D37:AH37,"0,5P")/2)+(COUNTIF(D37:AH37,"0.5L")/2) | AJ37: =(COUNTIF(D37:AH37,"P"))+(COUNTIF(D37:AG37,"P/2")/2)+(COUNTIF(D37:AG37,"0,5P")/2)+(COUNTIF(D37:AG37,"L/P")/2)+(COUNTIF(D37:AG37,"P/KL")/2) | AK37: =COUNTIF(D37:AH37,"L")+(COUNTIF(D37:AG37,"L/2")/2)+(COUNTIF(D37:AG37,"L/P")/2)+(COUNTIF(D37:AG37,"L/KL")/2) | AL37: =COUNTIF(D37:AH37,"KL")+COUNTIF(D37:AG37,"0,5KL")/2+COUNTIF(D37:AG37,"L/KL")/2+COUNTIF(D37:AG37,"KL/2")/2+COUNTIF(D37:AG37,"P/KL")/2+COUNTIF(D37:AG37,"0.5")/2 | AM37: =SUM(AI37:AL37) | AN37: =AI37+AJ37+AK37
A38: =A36+1 | C38: Le Huu Ha | D38: 1 | F38: 1 | G38: 1 | H38: 1 | I38: 1 | J38: 1 | K38: 1 | M38: 1 | N38: 1 | O38: 1 | P38: 1 | Q38: 1 | R38: 1 | T38: 1 | U38: 1 | V38: 1 | W38: 1 | X38: 1 | Y38: 1 | AA38: 1 | AB38: 1 | AC38: 1 | AD38: 1 | AE38: 1 | AF38: 1 | AH38: 1 | AI38: =SUM(D38:AH38)+(COUNTIF(D38:AH38,"0,5KL")/2)+(COUNTIF(D38:AH38,"0,5P")/2)+(COUNTIF(D38:AH38,"0.5L")/2) | AJ38: =(COUNTIF(D38:AH38,"P"))+(COUNTIF(D38:AG38,"P/2")/2)+(COUNTIF(D38:AG38,"0,5P")/2)+(COUNTIF(D38:AG38,"L/P")/2)+(COUNTIF(D38:AG38,"P/KL")/2) | AK38: =COUNTIF(D38:AH38,"L")+(COUNTIF(D38:AG38,"L/2")/2)+(COUNTIF(D38:AG38,"L/P")/2)+(COUNTIF(D38:AG38,"L/KL")/2) | AL38: =COUNTIF(D38:AH38,"KL")+COUNTIF(D38:AG38,"0,5KL")/2+COUNTIF(D38:AG38,"L/KL")/2+COUNTIF(D38:AG38,"KL/2")/2+COUNTIF(D38:AG38,"P/KL")/2+COUNTIF(D38:AG38,"0.5")/2 | AM38: =SUM(AI38:AL38) | AN38: =AI38+AJ38+AK38 | AO38: 10/8/2021
A39: 31 | C39: Đoàn Hữu Luận | D39: 1 | F39: 1 | G39: 1 | H39: 1 | I39: 1 | J39: 1 | K39: 1 | M39: 1 | N39: 1 | O39: 1 | P39: 1 | Q39: 1 | R39: 1 | T39: 1 | U39: 1 | V39: 1 | W39: 1 | X39: 1 | Y39: 1 | AA39: 1 | AB39: 1 | AC39: 1 | AD39: 1 | AE39: 1 | AF39: 1 | AH39: 1 | AI39: =SUM(D39:AH39)+(COUNTIF(D39:AH39,"0,5KL")/2)+(COUNTIF(D39:AH39,"0,5P")/2)+(COUNTIF(D39:AH39,"0.5L")/2) | AJ39: =(COUNTIF(D39:AH39,"P"))+(COUNTIF(D39:AG39,"P/2")/2)+(COUNTIF(D39:AG39,"0,5P")/2)+(COUNTIF(D39:AG39,"L/P")/2)+(COUNTIF(D39:AG39,"P/KL")/2) | AK39: =COUNTIF(D39:AH39,"L")+(COUNTIF(D39:AG39,"L/2")/2)+(COUNTIF(D39:AG39,"L/P")/2)+(COUNTIF(D39:AG39,"L/KL")/2) | AL39: =COUNTIF(D39:AH39,"KL")+COUNTIF(D39:AG39,"0,5KL")/2+COUNTIF(D39:AG39,"L/KL")/2+COUNTIF(D39:AG39,"KL/2")/2+COUNTIF(D39:AG39,"P/KL")/2+COUNTIF(D39:AG39,"0.5")/2 | AM39: =SUM(AI39:AL39) | AN39: =AI39+AJ39+AK39 | AO39: 10/8/2022
A40: 32 | C40: Lê Thị Quý Ngọc | D40: 1 | F40: 1 | G40: 1 | H40: 1 | I40: 1 | J40: 1 | K40: 1 | M40: 1 | N40: 1 | O40: 1 | P40: 1 | Q40: 1 | R40: 1 | T40: 1 | U40: 1 | V40: 1 | W40: 1 | X40: 1 | Y40: 1 | AA40: 1 | AB40: 1 | AC40: 1 | AD40: 1 | AE40: 1 | AF40: 1 | AH40: 1 | AI40: =SUM(D40:AH40)+(COUNTIF(D40:AH40,"0,5KL")/2)+(COUNTIF(D40:AH40,"0,5P")/2)+(COUNTIF(D40:AH40,"0.5L")/2) | AJ40: =(COUNTIF(D40:AH40,"P"))+(COUNTIF(D40:AG40,"P/2")/2)+(COUNTIF(D40:AG40,"0,5P")/2)+(COUNTIF(D40:AG40,"L/P")/2)+(COUNTIF(D40:AG40,"P/KL")/2) | AK40: =COUNTIF(D40:AH40,"L")+(COUNTIF(D40:AG40,"L/2")/2)+(COUNTIF(D40:AG40,"L/P")/2)+(COUNTIF(D40:AG40,"L/KL")/2) | AL40: =COUNTIF(D40:AH40,"KL")+COUNTIF(D40:AG40,"0,5KL")/2+COUNTIF(D40:AG40,"L/KL")/2+COUNTIF(D40:AG40,"KL/2")/2+COUNTIF(D40:AG40,"P/KL")/2+COUNTIF(D40:AG40,"0.5")/2 | AM40: =SUM(AI40:AL40) | AN40: =AI40+AJ40+AK40 | AO40: 24/4/2023
A41: 33 | C41: Lê Thu Hà | D41: 1 | F41: 1 | G41: 1 | H41: 1 | I41: 1 | J41: 1 | K41: 1 | M41: 1 | N41: 1 | O41: 1 | P41: 1 | Q41: 1 | R41: 1 | T41: 1 | U41: 1 | V41: 1 | W41: 1 | X41: 1 | Y41: 1 | AA41: 1 | AB41: 1 | AC41: 1 | AD41: 1 | AE41: P | AF41: 1 | AH41: 1 | AI41: =SUM(D41:AH41)+(COUNTIF(D41:AH41,"0,5KL")/2)+(COUNTIF(D41:AH41,"0,5P")/2)+(COUNTIF(D41:AH41,"0.5L")/2) | AJ41: =(COUNTIF(D41:AH41,"P"))+(COUNTIF(D41:AG41,"P/2")/2)+(COUNTIF(D41:AG41,"0,5P")/2)+(COUNTIF(D41:AG41,"L/P")/2)+(COUNTIF(D41:AG41,"P/KL")/2) | AK41: =COUNTIF(D41:AH41,"L")+(COUNTIF(D41:AG41,"L/2")/2)+(COUNTIF(D41:AG41,"L/P")/2)+(COUNTIF(D41:AG41,"L/KL")/2) | AL41: =COUNTIF(D41:AH41,"KL")+COUNTIF(D41:AG41,"0,5KL")/2+COUNTIF(D41:AG41,"L/KL")/2+COUNTIF(D41:AG41,"KL/2")/2+COUNTIF(D41:AG41,"P/KL")/2+COUNTIF(D41:AG41,"0.5")/2 | AM41: =SUM(AI41:AL41) | AN41: =AI41+AJ41+AK41 | AO41: 1/9/2020
...

Sheet Med Service
H1: BẢNG LƯƠNG THÁNG 6
D2: BẢNG LƯƠNG THÁNG 8/2026 | G2: Ngày bắt đầu | H2: 46174 | I2: Ngày kết thúc | J2: 46203
CM7: 1 | CN7: 4 | CO7: 2024 | CP7: 5 | CQ7: 2026 | DA7: 05/2026 | DB7: 05/2026
A8: STT | B8: Tháng | C8: Mã NV | D8: Họ tên | E8: Loại Hợp đồng | F8: Bộ phận | G8: Chức vụ | H8: Ngày vào công ty | I8: Số tài khoản | J8: CN Ngân hàng | K8: Ngày công chuẩn | L8: Ngày công thực tế | M8: CNT ca ngày (giờ) | N8: CNT ca đêm (giờ) | O8: Số giờ TC ngày thường | P8: Số giờ TC ngày CN (*2) | Q8: Số giờ TC ngày Lễ, tết (*3) | R8: HT hiệu quả làm việc | S8: Lương cơ bản (đóng BHXH) | T8: Hỗ trợ tiền ăn | U8: Hỗ trợ đồng phục | V8: Hỗ trợ điện thoại, xăng xe | W8: Hỗ trợ tiền gởi xe | X8: Hỗ trợ nhà ở | Y8: Hỗ trợ nuôi con nhỏ | Z8: Hỗ trợ phụ trách dự án/ sáng kiến | AA8: CNT - Phụ cấp lưu động | AB8: CNT - Phụ cấp tăng cường vận hành | AC8: Lương thỏa thuận | AD8: Lương chính thức | AE8: Lương thử việc | AF8: Lương thực tế | AG8: CNT- Lương ca ngày | AH8: CNT- Lương ca đêm | AI8: Lương tăng ca ngày thường | AJ8: Lương TC ngày CN (*2) | AK8: Lương TC ngày lễ, tết (*3) | AL8: CNT- Tiền HT trách nhiệm | AM8: CNT-Tiền HT cửa hàng mới | AN8: CNT- Tiền HT quy trình/dự án | AO8: CNT- Tiền hỗ trợ đạt KPI | AP8: CNT- tiền HT hàng điểm + Cắt liều | AQ8: CNT- Tiền HT hàng cận date | AR8: CNT- Tiền hỗ trợ chương trình Maps | AS8: CNT- HT Thưởng khác | AT8: Bổ sung lương tính thiếu tháng trước | AU8: CNT - Thưởng dự án Mini | AV8: CNT - Thường Whatsapp | AW8: Hỗ trợ đạt KPI Quý | AX8: HT lễ, tết / thưởng khác | AY8: HT đi CT tỉnh/ gởi xe | AZ8: HT sinh nhật | BA8: HT khấu hao máy tính/ kiêm nhiệm/ hỗ trợ đứng bằng | BB8: CNT trừ hết date | BC8: CNT trừ quy chế, quy trình | BD8: CNT trừ App- Kiot | BE8: CNT trừ Ecom | BF8: CNT các khoản trừ khác | BG8: Khoản trừ KPI, trừ khác | BH8: Tổng thu nhập thực tế | BI8: BHXH Cty (17.5%) | BJ8: BHYT Cty (3%) | BK8: BHTN CTy 1% | BL8: KPCĐ Cty (2%) | BM8: Cộng Cty 23,5% | BN8: BHXH NV (8%) | BO8: BHYT NV (1,5%) | BP8: BHTN NV (1%) | BQ8: ĐP NV (1%) | BR8: BHXH, BHYT, BHTN của NV (11,5%) | BS8: Tổng miễn giảm thuế TNCN (gởi xe, PC điện thoại, tiền ăn, đồng phục) | BT8: Thu nhập chịu thuế | BU8: Giảm trừ TTNCN Bản thân | BV8: Số người phụ thuộc | BW8: Giảm trừ TTNCN Người PT | BX8: Giảm trừ TTNCN 10.5% BHXH, BHYT, BHTN | BY8: Tổng các khoản giảm trừ | BZ8: Thu nhập tính thuế | CA8: Thuế TNCN phải nộp | CB8: Tổng thực nhận sau khi trừ TTNCN, BHXH | CC8: Trả lại lương Cty tính sai/thiếu | CD8: Trừ tạm ứng/ mượn/ bồi thường/ khác | CE8: Tổng thu nhập còn lại | CF8: CK TM | CG8: CK TK | CH8: ESHOP | CI8: Email | CJ8: Lý do bổ sung lương/ trừ lương | CK8: Tháng sinh | CL8: Giờ công đào tạo | CM8: Ngày nhận việc | CN8: Tháng nhận việc | CO8: Năm nhận việc | CP8: thâm niên trước tháng 04/2024 đến 01/4/2024 | CQ8: thâm niên cho NV chưa đủ 12 tháng trong CSTN cũ -> hưởng theo CSTN mới | CR8: Thâm niên cho NV vừa theo chính sách cũ vừa theo chính sách mới | CS8: Số năm TN làm tròn xuống theo CS cũ | CT8: Số năm TN làm tròn xuống theo CS mới | CU8: Số năm TN làm tròn xuống NV hưởng CS mới+ cũ | CV8: Lương thâm niên theo chính sách cũ trước tháng 04/2024 | CW8: Lương thâm niên theo chính sách mới từ 01/04/2024 | CX8: Lương thâm niên cho NV vừa theo chính sách mới + cũ | CY8: Lương Thâm niên của NV | CZ8: Lý do cộng trừ của HC-NS | DA8: Lý do cộng trừ của nhà thuốc | DB8: Lý do chung
A9: 1 | B9: =1+A9 | C9: 3 | D9: 4 | E9: 5 | F9: 6 | G9: 7 | H9: 8 | I9: 9 | J9: 10 | K9: 11 | L9: 12 | M9: 13 | N9: 14 | O9: 15 | P9: 16 | Q9: 17 | R9: 18 | S9: 19 | T9: 20 | U9: 21 | V9: 22 | W9: 23 | X9: 24 | Y9: 25 | Z9: 26 | AA9: 44 | AB9: 44 | AC9: 27 | AD9: 28 | AE9: 29 | AF9: 30 | AG9: 31 | AH9: 32 | AI9: 33 | AJ9: 34 | AK9: 35 | AL9: 36 | AM9: 37 | AN9: 38 | AO9: 39 | AP9: 40 | AQ9: 41 | AR9: 42 | AS9: 43 | AT9: 44 | AU9: 44 | AV9: 44 | AW9: 46 | AX9: 47 | AY9: 48 | AZ9: 49 | BA9: 50 | BB9: 51 | BC9: 52 | BD9: 53 | BE9: 54 | BF9: 55 | BG9: 56 | BH9: 57 | BI9: 58 | BJ9: 59 | BK9: 60 | BL9: 61 | BM9: 62 | BN9: 63 | BO9: 64 | BP9: 65 | BQ9: 66 | BR9: 67 | BS9: 68 | BT9: 69 | BU9: 70 | BV9: 71 | BW9: 72 | BX9: 73 | BY9: 74 | BZ9: 75 | CA9: 76 | CB9: 77 | CC9: 78 | CD9: 79 | CE9: 80 | CF9: 81 | CG9: 82 | CH9: 83 | CI9: 84 | CJ9: 85 | CK9: 86 | CL9: 87 | CM9: 88 | CN9: 89 | CO9: 90 | CP9: 91 | CQ9: 92 | CR9: 93 | CS9: 94 | CT9: 95 | CU9: 96 | CV9: 97 | CW9: 98 | CX9: 99 | CY9: 100 | CZ9: 102 | DA9: 103 | DB9: 104 | DC9: 105
A10: V. | B10: CHUỖI NHÀ THUỐC | K10: =K18+K26+K32+K41+K49+K56+K65+K70+K77+K83+K89 | L10: =L18+L26+L32+L41+L49+L56+L65+L70+L77+L83+L89 | M10: =M18+M26+M32+M41+M49+M56+M65+M70+M77+M83+M89 | N10: =N18+N26+N32+N41+N49+N56+N65+N70+N77+N83+N89 | O10: =O18+O26+O32+O41+O49+O56+O65+O70+O77+O83+O89 | P10: =P18+P26+P32+P41+P49+P56+P65+P70+P77+P83+P89 | Q10: =Q18+Q26+Q32+Q41+Q49+Q56+Q65+Q70+Q77+Q83+Q89 | R10: =R16+R24+R29+R35+R45+R52+R58+R64+R70+R76 | S10: =S18+S26+S32+S41+S49+S56+S65+S70+S77+S83+S89 | T10: =T18+T26+T32+T41+T49+T56+T65+T70+T77+T83+T89 | U10: =U18+U26+U32+U41+U49+U56+U65+U70+U77+U83+U89 | V10: =V18+V26+V32+V41+V49+V56+V65+V70+V77+V83+V89 | W10: =W18+W26+W32+W41+W49+W56+W65+W70+W77+W83+W89 | X10: =X18+X26+X32+X41+X49+X56+X65+X70+X77+X83+X89 | Y10: =Y18+Y26+Y32+Y41+Y49+Y56+Y65+Y70+Y77+Y83+Y89 | Z10: =Z18+Z26+Z32+Z41+Z49+Z56+Z65+Z70+Z77+Z83+Z89 | ... CG10: =CG18+CG26+CG32+CG41+CG49+CG56+CG65+CG70+CG77+CG83+CG89 | CH10: =CH16+CH24+CH29+CH35+CH45+CH52+CH58+CH64+CH70+CH76 | CL10: =CL18+CL26+CL32+CL41+CL49+CL56+CL65+CL70+CL77+CL83+CL89
A11: 1 | B11: 8 | C11: Ho Thi Minh Hoa | D11: Hồ Thị Minh Hòa | E11: =IF(OR(G11="CHT",G11="DSBC",G11="DSXC"),"HĐLĐ",IF(OR(G11="DSTV",G11="Q.CHT"),"HĐTV","HĐCTV")) | F11: 24H | G11: DSBC | H11: 45352 | I11: 0051000542226 | J11: Vietcombank | K11: 26 | L11: 2 | M11: 31.69 | N11: 0 | O11: 16 | S11: =IF(E11="HĐLĐ",5310000,0) | AA11: 0 | AB11: 0 | AC11: 6500000 | AG11: =IF(E11="HĐTV",AE11/28/8*M11,AC11/28/8*M11) | AH11: =IF(E11="HĐTV",AE11/28/8*N11*1.5,AC11/28/8*N11*1.5) | AI11: 0 | AJ11: 0 | AK11: 0 | AL11: 0 | AM11: 0 | AN11: 0 | AO11: 0 | AP11: 0 | AQ11: 0 | AR11: 0 | AS11: 0 | AT11: 0 | AU11: 0 | AV11: 0 | AW11: 0 | AX11: 0 | AY11: 0 | AZ11: 0 | BA11: 0 | BB11: 0 | BC11: 0 | BD11: 0 | BE11: 0 | BF11: 0 | BG11: 0 | BH11: =SUM(T11:AB11)+SUM(AF11:BA11)-SUM(BB11:BG11) | BI11: =S11*17.5% | BJ11: =S11*3% | BK11: =S11*1% | BM11: =SUM(BI11:BL11) | BN11: =S11*8% | BO11: =S11*1.5% | BP11: =S11*1% | BR11: =SUM(BN11:BQ11) | BS11: =T11+U11+V11+W11 | BT11: =BH11-BS11-AH11 | BU11: =IF(E11="HĐLĐ",15500000,0) | BV11: 0 | BW11: =BV11*6200000 | BX11: =BR11 | BY11: =BU11+BW11+BX11 | BZ11: =IF(BT11-BY11>0,BT11-BY11,0) | CA11: =IF(AND(OR($E11="HĐTV",$E11="HĐCTV"),$BZ11<2000000),0,IF(OR($E11="HĐTV",$E11="HĐCTV"),$BZ11*10%,ROUND(IF($BZ11<=10000000,$BZ11*5%,IF($BZ11<=30000000,$BZ11*10%-500000,IF($BZ11<=60000000,$BZ11*20%-3500000,IF($BZ11<=100000000,$BZ11*30%-9500000,$BZ11*35%-14500000)))),0))) | CB11: =ROUND(BH11-BR11-CA11,0) | CD11: 0 | CE11: =CB11+CC11-CD11 | CF11: =CE11-CG11 | CG11: =CE11 | CI11: hoa.ho@medigoapp.com | CJ11: 0 | CK11: 11 | CM11: 1 | CN11: 3 | CO11: 2024 | CP11: =IF((($CO$7-CO11)*12)+($CN$7-CN11)>=12,((($CO$7-CO11)*12)+($CN$7-CN11))-1,0) | CQ11: =IF(CP11<12,(($CQ$7-CO11)*12)+($CP$7-CN11),0) | CR11: =IF(OR(CP11>12,CP11=12),((CP11-(CS11*12))+((($CQ$7-2024)*12)+($CP$7-4)))+1,0) | CS11: =IF(OR(CP11>12,CP11=12),ROUNDDOWN(CP11/12,0),0) | CT11: =IF(CQ11>11,ROUNDDOWN(CQ11/12,0),0) | CU11: =IF(CR11>11,ROUNDDOWN(CR11/12,0),0) | CV11: =IF(CP11=0,0,6000000*1.07^CS11) | CW11: =IF(CT11<2,0,6000000+(CT11-1)*500000) | CX11: =IF(CU11=0,CV11,IF(CU11<1,0,CV11+CU11*500000)) | CY11: =IF(CX11>0,CX11,IF(CW11>0,CW11,6000000))
A12: 2 | B12: 8 | C12: Nguyen Tran Ngoc Phuong | D12: Nguyễn Trần Ngọc Phương | E12: =IF(OR(G12="CHT",G12="DSBC",G12="DSXC"),"HĐLĐ",IF(OR(G12="DSTV",G12="Q.CHT"),"HĐTV","HĐCTV")) | F12: 24H | G12: Q.CHT | H12: 46196 | I12: 0721000550950 | J12: Vietcombank | K12: 28 | L12: 26 | M12: 186.64 | N12: 28.38 | O12: 0 | S12: =IF(E12="HĐLĐ",5310000,0) | T12: 464285.71 | AA12: 0 | AB12: 0 | AC12: 6000000 | AE12: 6000000 | AG12: =IF(E12="HĐTV",AE12/28/8*M12,AC12/28/8*M12) | AH12: =IF(E12="HĐTV",AE12/28/8*N12*1.5,AC12/28/8*N12*1.5) | AI12: 0 | AJ12: 0 | AK12: 0 | AL12: 1,500,000 | AM12: 0 | AN12: 1000000 | AO12: 0 | AP12: 1280200 | AQ12: 6601 | AR12: 0 | AS12: 0 | AT12: 0 | AU12: 300000 | AV12: 0 | AW12: 0 | AX12: 0 | AY12: 0 | AZ12: 0 | BA12: 0 | BB12: 0 | BC12: 0 | BD12: 0 | BE12: 0 | BF12: 0 | BG12: 0 | BH12: =SUM(T12:AB12)+SUM(AF12:BA12)-SUM(BB12:BG12) | BI12: =S12*17.5% | BJ12: =S12*3% | BK12: =S12*1% | BM12: =SUM(BI12:BL12) | BN12: =S12*8% | BO12: =S12*1.5% | BP12: =S12*1% | BR12: =SUM(BN12:BQ12) | BS12: =T12+U12+V12+W12 | BT12: =BH12-BS12-AH12 | BU12: =IF(E12="HĐLĐ",15500000,0) | BV12: 0 | BW12: =BV12*6200000 | BX12: =BR12 | BY12: =BU12+BW12+BX12 | BZ12: =IF(BT12-BY12>0,BT12-BY12,0) | CA12: =IF(AND(OR($E12="HĐTV",$E12="HĐCTV"),$BZ12<2000000),0,IF(OR($E12="HĐTV",$E12="HĐCTV"),$BZ12*10%,ROUND(IF($BZ12<=10000000,$BZ12*5%,IF($BZ12<=30000000,$BZ12*10%-500000,IF($BZ12<=60000000,$BZ12*20%-3500000,IF($BZ12<=100000000,$BZ12*30%-9500000,$BZ12*35%-14500000)))),0))) | CB12: =ROUND(BH12-BR12-CA12,0) | CD12: 0 | CE12: =CB12+CC12-CD12 | CF12: =CE12-CG12 | CG12: =CE12 | CI12: phuong.nguyen@medigoapp.com | CK12: 9 | CL12: 0 | CM12: 23 | CN12: 6 | CO12: 2026 | CP12: =IF((($CO$7-CO12)*12)+($CN$7-CN12)>=12,((($CO$7-CO12)*12)+($CN$7-CN12))-1,0) | CQ12: =IF(CP12<12,(($CQ$7-CO12)*12)+($CP$7-CN12),0) | CR12: =IF(OR(CP12>12,CP12=12),((CP12-(CS12*12))+((($CQ$7-2024)*12)+($CP$7-4)))+1,0) | CS12: =IF(OR(CP12>12,CP12=12),ROUNDDOWN(CP12/12,0),0) | CT12: =IF(CQ12>11,ROUNDDOWN(CQ12/12,0),0) | CU12: =IF(CR12>11,ROUNDDOWN(CR12/12,0),0) | CV12: =IF(CP12=0,0,6000000*1.07^CS12) | CW12: =IF(CT12<2,0,6000000+(CT12-1)*500000) | CX12: =IF(CU12=0,CV12,IF(CU12<1,0,CV12+CU12*500000)) | CY12: =IF(CX12>0,CX12,IF(CW12>0,CW12,6000000))
A13: 3 | B13: 8 | C13: Nguyen Ngoc Anh Thu | D13: Nguyễn Ngọc Anh Thư | E13: =IF(OR(G13="CHT",G13="DSBC",G13="DSXC"),"HĐLĐ",IF(OR(G13="DSTV",G13="Q.CHT"),"HĐTV","HĐCTV")) | F13: 24H | G13: DSTV | H13: 14/07/2026 | I13: 7500664184 | J13: BIDV | K13: 28 | L13: 29 | M13: 26.98 | N13: 219.5 | O13: 8 | S13: =IF(E13="HĐLĐ",5310000,0) | T13: 500000 | AA13: 0 | AB13: 0 | AC13: 6000000 | AD13: =AC13 | AE13: 6000000 | AF13: =IF(E13="HĐTV",AE13/K13*L13,AD13/K13*L13) | AG13: =IF(E13="HĐTV",AE13/28/8*M13,AC13/28/8*M13) | AH13: =IF(E13="HĐTV",AE13/28/8*N13*1.5,AC13/28/8*N13*1.5) | AI13: 1446429 | AJ13: 0 | AK13: 0 | AL13: 0 | AM13: 0 | AN13: 933333 | AO13: 0 | AP13: 579960 | AQ13: 7700 | AR13: 0 | AS13: 0 | AT13: 0 | AU13: 0 | AV13: 0 | AW13: 0 | AX13: 0 | AY13: 0 | AZ13: 0 | BA13: 0 | BB13: 0 | BC13: 0 | BD13: 0 | BE13: 0 | BF13: 0 | BG13: 0 | BH13: =SUM(T13:AB13)+SUM(AF13:BA13)-SUM(BB13:BG13) | BI13: =S13*17.5% | BJ13: =S13*3% | BK13: =S13*1% | BM13: =SUM(BI13:BL13) | BN13: =S13*8% | BO13: =S13*1.5% | BP13: =S13*1% | BR13: =SUM(BN13:BQ13) | BS13: =T13+U13+V13+W13 | BT13: =BH13-BS13-AH13 | BU13: =IF(E13="HĐLĐ",15500000,0) | BV13: 0 | BW13: =BV13*6200000 | BX13: =BR13 | BY13: =BU13+BW13+BX13 | BZ13: =IF(BT13-BY13>0,BT13-BY13,0) | CA13: =IF(AND(OR($E13="HĐTV",$E13="HĐCTV"),$BZ13<2000000),0,IF(OR($E13="HĐTV",$E13="HĐCTV"),$BZ13*10%,ROUND(IF($BZ13<=10000000,$BZ13*5%,IF($BZ13<=30000000,$BZ13*10%-500000,IF($BZ13<=60000000,$BZ13*20%-3500000,IF($BZ13<=100000000,$BZ13*30%-9500000,$BZ13*35%-14500000)))),0))) | CB13: =ROUND(BH13-BR13-CA13,0) | CD13: 0 | CE13: =CB13+CC13-CD13 | CF13: =CE13-CG13 | CG13: =CE13 | CI13: thu.nguyen@medigoapp.com | CK13: 1 | CY13: =IF(CX13>0,CX13,IF(CW13>0,CW13,6000000))
A14: 4 | B14: 8 | C14: Trinh Thi Phuong | D14: Trịnh Thị Phượng | E14: =IF(OR(G14="CHT",G14="DSBC",G14="DSXC"),"HĐLĐ",IF(OR(G14="DSTV",G14="Q.CHT"),"HĐTV","HĐCTV")) | F14: 24H | G14: DSBC | H14: 45096 | I14: 10200014211025 | J14: Đông Nam Á (Seabank) | K14: 26 | L14: 21 | M14: 0.38 | N14: 164.21 | O14: 0 | S14: =IF(E14="HĐLĐ",5310000,0) | T14: 375000 | AA14: 0 | AB14: 0 | AC14: 6500000 | AD14: =AC14 | AE14: 0 | AF14: =IF(E14="HĐTV",AE14/K14*L14,AD14/K14*L14) | AG14: =IF(E14="HĐTV",AE14/28/8*M14,AC14/28/8*M14) | AH14: =IF(E14="HĐTV",AE14/28/8*N14*1.5,AC14/28/8*N14*1.5) | AI14: 1125000 | AJ14: 0 | AK14: 0 | AL14: 0 | AM14: 0 | AN14: 2200000 | AO14: 0 | AP14: 3537750 | AQ14: 11205 | AR14: 0 | AS14: 0 | AT14: 0 | AU14: 0 | AV14: 0 | AW14: 0 | AX14: 0 | AY14: 0 | AZ14: 0 | BA14: 0 | BB14: 0 | BC14: 0 | BD14: 0 | BE14: 0 | BF14: 0 | BG14: 0 | BH14: =SUM(T14:AB14)+SUM(AF14:BA14)-SUM(BB14:BG14) | BI14: =S14*17.5% | BJ14: =S14*3% | BK14: =S14*1% | BM14: =SUM(BI14:BL14) | BN14: =S14*8% | BO14: =S14*1.5% | BP14: =S14*1% | BR14: =SUM(BN14:BQ14) | BS14: =T14+U14+V14+W14 | BT14: =BH14-BS14-AH14 | BU14: =IF(E14="HĐLĐ",15500000,0) | BV14: 0 | BW14: =BV14*6200000 | BX14: =BR14 | BY14: =BU14+BW14+BX14 | BZ14: =IF(BT14-BY14>0,BT14-BY14,0) | CA14: =IF(AND(OR($E14="HĐTV",$E14="HĐCTV"),$BZ14<2000000),0,IF(OR($E14="HĐTV",$E14="HĐCTV"),$BZ14*10%,ROUND(IF($BZ14<=10000000,$BZ14*5%,IF($BZ14<=30000000,$BZ14*10%-500000,IF($BZ14<=60000000,$BZ14*20%-3500000,IF($BZ14<=100000000,$BZ14*30%-9500000,$BZ14*35%-14500000)))),0))) | CB14: =ROUND(BH14-BR14-CA14,0) | CD14: 0 | CE14: =CB14+CC14-CD14 | CF14: =CE14-CG14 | CG14: =CE14 | CK14: 2 | CY14: =IF(CX14>0,CX14,IF(CW14>0,CW14,6000000))
A15: 5 | B15: 8 | C15: Ngo Tran Tuyet Vy | D15: Ngô Trần Tuyết Vy | E15: =IF(OR(G15="CHT",G15="DSBC",G15="DSXC"),"HĐLĐ",IF(OR(G15="DSTV",G15="Q.CHT"),"HĐTV","HĐCTV")) | F15: 24H | G15: DSBC | H15: 44743 | I15: 060260188766 | J15: Sacombank | K15: 28 | L15: 11 | M15: 66.26 | N15: 23.12 | O15: 0 | S15: =IF(E15="HĐLĐ",5310000,0) | T15: 196428.57 | AA15: 0 | AB15: 0 | AC15: 8350258 | AG15: =IF(E15="HĐTV",AE15/28/8*M15,AC15/28/8*M15) | AH15: =IF(E15="HĐTV",AE15/28/8*N15*1.5,AC15/28/8*N15*1.5) | AI15: 0 | AJ15: 0 | AK15: 0 | AL15: 0 | AM15: 0 | AN15: 0 | AO15: 0 | AP15: 1011600 | AQ15: 0 | AR15: 0 | AS15: 0 | AT15: 0 | AU15: 0 | AV15: 0 | AW15: 0 | AX15: 0 | AY15: 0 | AZ15: 0 | BA15: 0 | BB15: 0 | BC15: 0 | BD15: 0 | BE15: 0 | BF15: 0 | BG15: 0 | BH15: =SUM(T15:AB15)+SUM(AF15:BA15)-SUM(BB15:BG15) | BI15: =S15*17.5% | BJ15: =S15*3% | BK15: =S15*1% | BM15: =SUM(BI15:BL15) | BN15: =S15*8% | BO15: =S15*1.5% | BP15: =S15*1% | BR15: =SUM(BN15:BQ15) | BS15: =T15+U15+V15+W15 | BT15: =BH15-BS15-AH15 | BU15: =IF(E15="HĐLĐ",15500000,0) | BV15: 0 | BW15: =BV15*6200000 | BX15: =BR15 | BY15: =BU15+BW15+BX15 | BZ15: =IF(BT15-BY15>0,BT15-BY15,0) | CA15: =IF(AND(OR($E15="HĐTV",$E15="HĐCTV"),$BZ15<2000000),0,IF(OR($E15="HĐTV",$E15="HĐCTV"),$BZ15*10%,ROUND(IF($BZ15<=10000000,$BZ15*5%,IF($BZ15<=30000000,$BZ15*10%-500000,IF($BZ15<=60000000,$BZ15*20%-3500000,IF($BZ15<=100000000,$BZ15*30%-9500000,$BZ15*35%-14500000)))),0))) | CB15: =ROUND(BH15-BR15-CA15,0) | CD15: 0 | CE15: =CB15+CC15-CD15 | CF15: =CE15-CG15 | CG15: =CE15 | CI15: =VLOOKUP($C19,[5]Sheet1!$C$5:$K$139,9,0) | CJ15: 0 | CK15: 3 | CL15: 0 | CM15: 14 | CN15: 2 | CO15: 2021 | CP15: =IF((($CO$7-CO15)*12)+($CN$7-CN15)>=12,((($CO$7-CO15)*12)+($CN$7-CN15))-1,0) | CQ15: =IF(CP15<12,(($CQ$7-CO15)*12)+($CP$7-CN15),0) | CR15: =IF(OR(CP15>12,CP15=12),((CP15-(CS15*12))+((($CQ$7-2024)*12)+($CP$7-4)))+1,0) | CS15: =IF(OR(CP15>12,CP15=12),ROUNDDOWN(CP15/12,0),0) | CT15: =IF(CQ15>11,ROUNDDOWN(CQ15/12,0),0) | CU15: =IF(CR15>11,ROUNDDOWN(CR15/12,0),0) | CV15: =IF(CP15=0,0,6000000*1.07^CS15) | CW15: =IF(CT15<2,0,6000000+(CT15-1)*500000) | CX15: =IF(CU15=0,CV15,IF(CU15<1,0,CV15+CU15*500000)) | CY15: =IF(CX15>0,CX15,IF(CW15>0,CW15,6000000))
A16: 6 | B16: 8 | C16: Pham Nguyen Ngoc Quy | D16: Phạm Nguyễn Ngọc Quý | E16: =IF(OR(G16="CHT",G16="DSBC",G16="DSXC"),"HĐLĐ",IF(OR(G16="DSTV",G16="Q.CHT"),"HĐTV","HĐCTV")) | F16: 24H | G16: DSBC | H16: 01/11/2024 | I16: 1026764251 | J16: Vietcombank | K16: 28 | L16: 23 | M16: 164.33 | N16: 24.07 | O16: 0 | S16: =IF(E16="HĐLĐ",5310000,0) | T16: 410714.29 | AA16: 0 | AB16: 0 | AC16: 6000000 | AG16: =IF(E16="HĐTV",AE16/28/8*M16,AC16/28/8*M16) | AH16: =IF(E16="HĐTV",AE16/28/8*N16*1.5,AC16/28/8*N16*1.5) | AI16: 0 | AJ16: 0 | AK16: 0 | AL16: 0 | AM16: 0 | AN16: 0 | AO16: 0 | AP16: 1686900 | AQ16: 18300 | AR16: 0 | AS16: 0 | AT16: 0 | AU16: 0 | AV16: 0 | AW16: 0 | AX16: 0 | AY16: 0 | AZ16: 0 | BA16: 0 | BB16: 0 | BC16: 0 | BD16: 0 | BE16: 0 | BF16: 0 | BG16: 0 | BH16: =SUM(T16:AB16)+SUM(AF16:BA16)-SUM(BB16:BG16) | BI16: =S16*17.5% | BJ16: =S16*3% | BK16: =S16*1% | BM16: =SUM(BI16:BL16) | BN16: =S16*8% | BO16: =S16*1.5% | BP16: =S16*1% | BR16: =SUM(BN16:BQ16) | BS16: =T16+U16+V16+W16 | BT16: =BH16-BS16-AH16 | BU16: =IF(E16="HĐLĐ",15500000,0) | BV16: 0 | BW16: =BV16*6200000 | BX16: =BR16 | BY16: =BU16+BW16+BX16 | BZ16: =IF(BT16-BY16>0,BT16-BY16,0) | CA16: =IF(AND(OR($E16="HĐTV",$E16="HĐCTV"),$BZ16<2000000),0,IF(OR($E16="HĐTV",$E16="HĐCTV"),$BZ16*10%,ROUND(IF($BZ16<=10000000,$BZ16*5%,IF($BZ16<=30000000,$BZ16*10%-500000,IF($BZ16<=60000000,$BZ16*20%-3500000,IF($BZ16<=100000000,$BZ16*30%-9500000,$BZ16*35%-14500000)))),0))) | CB16: =ROUND(BH16-BR16-CA16,0) | CD16: 0 | CE16: =CB16+CC16-CD16 | CF16: =CE16-CG16 | CG16: =CE16 | CI16: quy.pham@medigoapp.com | CJ16: 0 | CK16: 6 | CL16: 0 | CM16: 1 | CN16: 11 | CO16: 2024 | CP16: =IF((($CO$7-CO16)*12)+($CN$7-CN16)>=12,((($CO$7-CO16)*12)+($CN$7-CN16))-1,0) | CQ16: =IF(CP16<12,(($CQ$7-CO16)*12)+($CP$7-CN16),0) | CR16: =IF(OR(CP16>12,CP16=12),((CP16-(CS16*12))+((($CQ$7-1624)*12)+($CP$7-4)))+1,0) | CS16: =IF(OR(CP16>12,CP16=12),ROUNDDOWN(CP16/12,0),0) | CT16: =IF(CQ16>11,ROUNDDOWN(CQ16/12,0),0) | CU16: =IF(CR16>11,ROUNDDOWN(CR16/12,0),0) | CV16: =IF(CP16=0,0,6000000*1.07^CS16) | CW16: =IF(CT16<2,0,6000000+(CT16-1)*500000) | CX16: =IF(CU16=0,CV16,IF(CU16<1,0,CV16+CU16*500000)) | CY16: =IF(CX16>0,CX16,IF(CW16>0,CW16,6000000))
A17: 7 | B17: 8 | C17: Tran Thi Kim Khanh | D17: Trần Thị Kim Khánh | E17: =IF(OR(G17="CHT",G17="DSBC",G17="DSXC"),"HĐLĐ",IF(OR(G17="DSTV",G17="Q.CHT"),"HĐTV","HĐCTV")) | F17: 24H | G17: DSBC | H17: 45099 | I17: 69110000565904 | J17: BIDV | K17: 26 | L17: 29 | M17: 253.43 | N17: 31.43 | O17: 8 | S17: =IF(E17="HĐLĐ",5310000,0) | T17: 500000 | AA17: 0 | AB17: 0 | AC17: 6500000 | AD17: =AC17 | AE17: 0 | AF17: =IF(E17="HĐTV",AE17/K17*L17,AD17/K17*L17) | AG17: =IF(E17="HĐTV",AE17/28/8*M17,AC17/28/8*M17) | AH17: =IF(E17="HĐTV",AE17/28/8*N17*1.5,AC17/28/8*N17*1.5) | AI17: 0 | AJ17: 0 | AK17: 0 | AL17: 0 | AM17: 0 | AN17: 2800000 | AO17: 2472797 | AP17: 3808150 | AQ17: 46851 | AR17: 0 | AS17: 0 | AT17: 0 | AU17: 0 | AV17: 0 | AW17: 0 | AX17: 0 | AY17: 0 | AZ17: 0 | BA17: 0 | BB17: 0 | BC17: 0 | BD17: 0 | BE17: 0 | BF17: 0 | BG17: 0 | BH17: =SUM(T17:AB17)+SUM(AF17:BA17)-SUM(BB17:BG17) | BI17: =S17*17.5% | BJ17: =S17*3% | BK17: =S17*1% | BM17: =SUM(BI17:BL17) | BN17: =S17*8% | BO17: =S17*1.5% | BP17: =S17*1% | BR17: =SUM(BN17:BQ17) | BS17: =T17+U17+V17+W17 | BT17: =BH17-BS17-AH17 | BU17: =IF(E17="HĐLĐ",15500000,0) | BV17: 0 | BW17: =BV17*6200000 | BX17: =BR17 | BY17: =BU17+BW17+BX17 | BZ17: =IF(BT17-BY17>0,BT17-BY17,0) | CA17: =IF(AND(OR($E17="HĐTV",$E17="HĐCTV"),$BZ17<2000000),0,IF(OR($E17="HĐTV",$E17="HĐCTV"),$BZ17*10%,ROUND(IF($BZ17<=10000000,$BZ17*5%,IF($BZ17<=30000000,$BZ17*10%-500000,IF($BZ17<=60000000,$BZ17*20%-3500000,IF($BZ17<=100000000,$BZ17*30%-9500000,$BZ17*35%-14500000)))),0))) | CB17: =ROUND(BH17-BR17-CA17,0) | CD17: 0 | CE17: =CB17+CC17-CD17 | CF17: =CE17-CG17 | CG17: =CE17 | CY17: =IF(CX17>0,CX17,IF(CW17>0,CW17,6000000))
F18: =SUM(F11:F17) | K18: =SUM(K11:K17) | L18: =SUM(L11:L17) | M18: =SUM(M11:M17) | N18: =SUM(N11:N17) | O18: =SUM(O11:O17) | P18: =SUM(P11:P17) | Q18: =SUM(Q11:Q17) | S18: =SUM(S11:S17) | T18: =SUM(T11:T17) | U18: =SUM(U11:U17) | V18: =SUM(V11:V17) | W18: =SUM(W11:W17) | X18: =SUM(X11:X17) | Y18: =SUM(Y11:Y17) | Z18: =SUM(Z11:Z17) | ... CG18: =SUM(CG11:CG17) | CL18: =SUM(CL11:CL17)
A19: 8 | B19: 8 | C19: Ngo Thi Thanh Tham | D19: Ngô Thị Thanh Thắm | E19: =IF(OR(G19="CHT",G19="DSBC",G19="DSXC"),"HĐLĐ",IF(OR(G19="DSTV",G19="Q.CHT"),"HĐTV","HĐCTV")) | F19: Đỗ Quang Đẩu | G19: CHT | H19: 45524 | I19: 0431000219840 | J19: Vietcombank | K19: 28 | L19: 23 | M19: 183.01 | N19: 0 | O19: 0 | S19: =IF(E19="HĐLĐ",5310000,0) | T19: 410714.29 | AA19: 0 | AB19: 0 | AC19: 6000000 | AG19: =IF(E19="HĐTV",AE19/28/8*M19,AC19/28/8*M19) | AH19: =IF(E19="HĐTV",AE19/28/8*N19*1.5,AC19/28/8*N19*1.5) | AI19: 0 | AJ19: 0 | AK19: 0 | AL19: 2,000,000 | AM19: 0 | AN19: 0 | AO19: 0 | AP19: 688400 | AQ19: 14067 | AR19: 0 | AS19: 1000000 | AT19: 0 | AU19: 0 | AV19: 2681852 | AW19: 0 | AX19: 0 | AY19: 0 | AZ19: 0 | BA19: 0 | BB19: 0 | BC19: 0 | BD19: 0 | BE19: 0 | BF19: 0 | BG19: 0 | BH19: =SUM(T19:AB19)+SUM(AF19:BA19)-SUM(BB19:BG19) | BI19: =S19*17.5% | BJ19: =S19*3% | BK19: =S19*1% | BM19: =SUM(BI19:BL19) | BN19: =S19*8% | BO19: =S19*1.5% | BP19: =S19*1% | BR19: =SUM(BN19:BQ19) | BS19: =T19+U19+V19+W19 | BT19: =BH19-BS19-AH19 | BU19: =IF(E19="HĐLĐ",15500000,0) | BV19: 0 | BW19: =BV19*6200000 | BX19: =BR19 | BY19: =BU19+BW19+BX19 | BZ19: =IF(BT19-BY19>0,BT19-BY19,0) | CA19: =IF(AND(OR($E19="HĐTV",$E19="HĐCTV"),$BZ19<2000000),0,IF(OR($E19="HĐTV",$E19="HĐCTV"),$BZ19*10%,ROUND(IF($BZ19<=10000000,$BZ19*5%,IF($BZ19<=30000000,$BZ19*10%-500000,IF($BZ19<=60000000,$BZ19*20%-3500000,IF($BZ19<=100000000,$BZ19*30%-9500000,$BZ19*35%-14500000)))),0))) | CB19: =ROUND(BH19-BR19-CA19,0) | CD19: 0 | CE19: =CB19+CC19-CD19 | CF19: =CE19-CG19 | CG19: =CE19 | CI19: tham.ngo@medigoapp.com | CJ19: 0 | CK19: 12 | CL19: 0 | CM19: 20 | CN19: 8 | CO19: 2024 | CP19: =IF((($CO$7-CO19)*12)+($CN$7-CN19)>=12,((($CO$7-CO19)*12)+($CN$7-CN19))-1,0) | CQ19: =IF(CP19<12,(($CQ$7-CO19)*12)+($CP$7-CN19),0) | CR19: =IF(OR(CP19>12,CP19=12),((CP19-(CS19*12))+((($CQ$7-2024)*12)+($CP$7-4)))+1,0) | CS19: =IF(OR(CP19>12,CP19=12),ROUNDDOWN(CP19/12,0),0) | CT19: =IF(CQ19>11,ROUNDDOWN(CQ19/12,0),0) | CU19: =IF(CR19>11,ROUNDDOWN(CR19/12,0),0) | CV19: =IF(CP19=0,0,6000000*1.07^CS19) | CW19: =IF(CT19<2,0,6000000+(CT19-1)*500000) | CX19: =IF(CU19=0,CV19,IF(CU19<1,0,CV19+CU19*500000)) | CY19: =IF(CX19>0,CX19,IF(CW19>0,CW19,6000000))
A20: 9 | B20: 8 | C20: Duong Thi Huynh Nhu | D20: Dương Thị Huỳnh Như | E20: =IF(OR(G20="CHT",G20="DSBC",G20="DSXC"),"HĐLĐ",IF(OR(G20="DSTV",G20="Q.CHT"),"HĐTV","HĐCTV")) | F20: Đỗ Quang Đẩu | G20: DSTV | H20: 28/07/2026 | I20: 023704070008223 | J20: HD Bank | K20: 28 | L20: 4 | M20: 32.49 | N20: 0 | O20: 0 | S20: =IF(E20="HĐLĐ",5310000,0) | T20: 71428.571 | AA20: 0 | AB20: 0 | AC20: 6000000 | AD20: =AC20 | AE20: 6000000 | AF20: =IF(E20="HĐTV",AE20/K20*L20,AD20/K20*L20) | AG20: =IF(E20="HĐTV",AE20/28/8*M20,AC20/28/8*M20) | AH20: =IF(E20="HĐTV",AE20/28/8*N20*1.5,AC20/28/8*N20*1.5) | AI20: 0 | AJ20: 0 | AK20: 0 | AL20: 0 | AM20: 0 | AN20: 0 | AO20: 0 | AP20: 0 | AQ20: 0 | AR20: 0 | AS20: 0 | AT20: 0 | AU20: 0 | AV20: 0 | AW20: 0 | AX20: 0 | AY20: 0 | AZ20: 0 | BA20: 0 | BB20: 0 | BC20: 0 | BD20: 0 | BE20: 0 | BF20: 0 | BG20: 0 | BH20: =SUM(T20:AB20)+SUM(AF20:BA20)-SUM(BB20:BG20) | BI20: =S20*17.5% | BJ20: =S20*3% | BK20: =S20*1% | BM20: =SUM(BI20:BL20) | BN20: =S20*8% | BO20: =S20*1.5% | BP20: =S20*1% | BR20: =SUM(BN20:BQ20) | BS20: =T20+U20+V20+W20 | BT20: =BH20-BS20-AH20 | BU20: =IF(E20="HĐLĐ",15500000,0) | BV20: 0 | BW20: =BV20*6200000 | BX20: =BR20 | BY20: =BU20+BW20+BX20 | BZ20: =IF(BT20-BY20>0,BT20-BY20,0) | CA20: =IF(AND(OR($E20="HĐTV",$E20="HĐCTV"),$BZ20<2000000),0,IF(OR($E20="HĐTV",$E20="HĐCTV"),$BZ20*10%,ROUND(IF($BZ20<=10000000,$BZ20*5%,IF($BZ20<=30000000,$BZ20*10%-500000,IF($BZ20<=60000000,$BZ20*20%-3500000,IF($BZ20<=100000000,$BZ20*30%-9500000,$BZ20*35%-14500000)))),0))) | CB20: =ROUND(BH20-BR20-CA20,0) | CD20: 0 | CE20: =CB20+CC20-CD20 | CF20: =CE20-CG20 | CG20: =CE20 | CI20: nhu.duong@medigoapp.com | CK20: 9 | CY20: =IF(CX20>0,CX20,IF(CW20>0,CW20,6000000))
A21: 10 | B21: 8 | C21: Pham Thi Nghia Huong | D21: Phạm Thị Nghĩa Hương | E21: =IF(OR(G21="CHT",G21="DSBC",G21="DSXC"),"HĐLĐ",IF(OR(G21="DSTV",G21="Q.CHT"),"HĐTV","HĐCTV")) | F21: Đỗ Quang Đẩu | G21: DSBC | H21: 45575 | I21: 0968249073 | J21: Mb bank | K21: 28 | L21: 29 | M21: 11.02 | N21: 230.26 | O21: 8 | S21: =IF(E21="HĐLĐ",5310000,0) | T21: 500000 | AA21: 0 | AB21: 0 | AC21: 6000000 | AG21: =IF(E21="HĐTV",AE21/28/8*M21,AC21/28/8*M21) | AH21: =IF(E21="HĐTV",AE21/28/8*N21*1.5,AC21/28/8*N21*1.5) | AI21: 1500000 | AJ21: 0 | AK21: 0 | AL21: 0 | AM21: 0 | AN21: 0 | AO21: 0 | AP21: 629100 | AQ21: 7550 | AR21: 0 | AS21: 0 | AT21: 0 | AU21: 0 | AV21: 340044 | AW21: 0 | AX21: 0 | AY21: 0 | AZ21: 0 | BA21: 0 | BB21: 0 | BC21: 0 | BD21: 100000 | BE21: 0 | BF21: 0 | BG21: 0 | BH21: =SUM(T21:AB21)+SUM(AF21:BA21)-SUM(BB21:BG21) | BI21: =S21*17.5% | BJ21: =S21*3% | BK21: =S21*1% | BM21: =SUM(BI21:BL21) | BN21: =S21*8% | BO21: =S21*1.5% | BP21: =S21*1% | BR21: =SUM(BN21:BQ21) | BS21: =T21+U21+V21+W21 | BT21: =BH21-BS21-AH21 | BU21: =IF(E21="HĐLĐ",15500000,0) | BV21: 0 | BW21: =BV21*6200000 | BX21: =BR21 | BY21: =BU21+BW21+BX21 | BZ21: =IF(BT21-BY21>0,BT21-BY21,0) | CA21: =IF(AND(OR($E21="HĐTV",$E21="HĐCTV"),$BZ21<2000000),0,IF(OR($E21="HĐTV",$E21="HĐCTV"),$BZ21*10%,ROUND(IF($BZ21<=10000000,$BZ21*5%,IF($BZ21<=30000000,$BZ21*10%-500000,IF($BZ21<=60000000,$BZ21*20%-3500000,IF($BZ21<=100000000,$BZ21*30%-9500000,$BZ21*35%-14500000)))),0))) | CB21: =ROUND(BH21-BR21-CA21,0) | CD21: 0 | CE21: =CB21+CC21-CD21 | CF21: =CE21-CG21 | CG21: =CE21 | CI21: huong.pham@medigoapp.com | CJ21: 0 | CK21: 10 | CL21: 0 | CM21: 10 | CN21: 10 | CO21: 2024 | CP21: 0 | CQ21: 17 | CR21: =IF(OR(CP21>12,CP21=12),((CP21-(CS21*12))+((($CQ$7-2024)*12)+($CP$7-4)))+1,0) | CS21: 0 | CT21: 1 | CU21: 0 | CV21: 0 | CW21: 0 | CX21: 0 | CY21: =IF(CX21>0,CX21,IF(CW21>0,CW21,6000000))
A22: 11 | B22: 8 | C22: Tran Thien Phat | D22: Trần Thiên Phát | E22: =IF(OR(G22="CHT",G22="DSBC",G22="DSXC"),"HĐLĐ",IF(OR(G22="DSTV",G22="Q.CHT"),"HĐTV","HĐCTV")) | F22: Đỗ Quang Đẩu | G22: DSBC | H22: 21/07/2025 | I22: 0345611564 | J22: Mbbank | K22: 28 | L22: 31 | M22: 16 | N22: 245.44 | O22: 16 | S22: =IF(E22="HĐLĐ",5310000,0) | T22: 500000 | AA22: 0 | AB22: 0 | AC22: 6000000 | AG22: =IF(E22="HĐTV",AE22/28/8*M22,AC22/28/8*M22) | AH22: =IF(E22="HĐTV",AE22/28/8*N22*1.5,AC22/28/8*N22*1.5) | AI22: 1500000 | AJ22: 0 | AK22: 0 | AL22: 0 | AM22: 0 | AN22: 0 | AO22: 0 | AP22: 867600 | AQ22: 4035 | AR22: 0 | AS22: 0 | AT22: 0 | AU22: 0 | AV22: 375112 | AW22: 0 | AX22: 0 | AY22: 0 | AZ22: 100000 | BA22: 100000 | BB22: 0 | BC22: 0 | BD22: 0 | BE22: 0 | BF22: 0 | BG22: 0 | BH22: =SUM(T22:AB22)+SUM(AF22:BA22)-SUM(BB22:BG22) | BI22: =S22*17.5% | BJ22: =S22*3% | BK22: =S22*1% | BM22: =SUM(BI22:BL22) | BN22: =S22*8% | BO22: =S22*1.5% | BP22: =S22*1% | BR22: =SUM(BN22:BQ22) | BS22: =T22+U22+V22+W22 | BT22: =BH22-BS22-AH22 | BU22: =IF(E22="HĐLĐ",15500000,0) | BV22: 0 | BW22: =BV22*6200000 | BX22: =BR22 | BY22: =BU22+BW22+BX22 | BZ22: =IF(BT22-BY22>0,BT22-BY22,0) | CA22: =IF(AND(OR($E22="HĐTV",$E22="HĐCTV"),$BZ22<2000000),0,IF(OR($E22="HĐTV",$E22="HĐCTV"),$BZ22*10%,ROUND(IF($BZ22<=10000000,$BZ22*5%,IF($BZ22<=30000000,$BZ22*10%-500000,IF($BZ22<=60000000,$BZ22*20%-3500000,IF($BZ22<=100000000,$BZ22*30%-9500000,$BZ22*35%-14500000)))),0))) | CB22: =ROUND(BH22-BR22-CA22,0) | CD22: 0 | CE22: =CB22+CC22-CD22 | CF22: =CE22-CG22 | CG22: =CE22 | CI22: phat.tran@medigoapp.com | CJ22: 0 | CK22: 8 | CL22: 0 | CM22: 21 | CN22: 7 | CO22: 2025 | CP22: =IF((($CO$7-CO22)*12)+($CN$7-CN22)>=12,((($CO$7-CO22)*12)+($CN$7-CN22))-1,0) | CQ22: =IF(CP22<12,(($CQ$7-CO22)*12)+($CP$7-CN22),0) | CR22: =IF(OR(CP22>12,CP22=12),((CP22-(CS22*12))+((($CQ$7-2024)*12)+($CP$7-4)))+1,0) | CS22: =IF(OR(CP22>12,CP22=12),ROUNDDOWN(CP22/12,0),0) | CT22: =IF(CQ22>11,ROUNDDOWN(CQ22/12,0),0) | CU22: =IF(CR22>11,ROUNDDOWN(CR22/12,0),0) | CV22: =IF(CP22=0,0,6000000*1.07^CS22) | CW22: =IF(CT22<2,0,6000000+(CT22-1)*500000) | CX22: =IF(CU22=0,CV22,IF(CU22<1,0,CV22+CU22*500000)) | CY22: =IF(CX22>0,CX22,IF(CW22>0,CW22,6000000))
