Workbook

Sheet Bảng đánh giá
A1: Chi nhánh | B1: Doanh thu | C1: Chi phí | D1: Lợi nhuận | F1: Thành tích | G1: Lương | H1: Mặt bằng | I1: Ds chuyên môn | J1: Điện + nước | K1: Linh tinh | L1: SL đơn ONl | M1: Platform software (8k/1hd) | N1: Ebitda | O1: Ebitda - Team CNT (160M) | P1: Ebitda - Comp (300M)
A2: 24H | D2: =B2-C2 -> 0 | E2: =D2/B2 -> #DIV/0! | F2: Không đạt | G2: 72000000 | H2: 17000000 | I2: 3500000 | J2: 3400000 | K2: 6000000 | L2: 1238 | M2: =L2*8000 -> 9904000 | N2: =D2-G2-H2-I2-J2-K2-M2 -> -111804000 | O2: =N2-16000000 -> -127804000 | P2: =O2-30000000 -> -157804000
A3: Đỗ Quang Đẩu | D3: =B3-C3 -> 0 | E3: =D3/B3 -> #DIV/0! | F3: Không đạt | G3: 82000000 | H3: 55000000 | I3: 3500000 | J3: 8300000 | K3: 6000000 | L3: 920 | M3: =L3*8000 -> 7360000 | N3: =D3-G3-H3-I3-J3-K3-M3 -> -162160000 | O3: =N3-16000000 -> -178160000 | P3: =O3-30000000 -> -208160000
A4: Minh Châu | D4: =B4-C4 -> 0 | E4: =D4/B4 -> #DIV/0! | F4: Không đạt | G4: 50000000 | H4: 15000000 | I4: 3500000 | J4: 5000000 | K4: 6000000 | L4: 471 | M4: =L4*8000 -> 3768000 | N4: =D4-G4-H4-I4-J4-K4-M4 -> -83268000 | O4: =N4-16000000 -> -99268000 | P4: =O4-30000000 -> -129268000
A5: Nam Hòa | D5: =B5-C5 -> 0 | E5: =D5/B5 -> #DIV/0! | F5: Không đạt | G5: 44000000 | H5: 22000000 | I5: 2500000 | J5: 6500000 | K5: 6000000 | L5: 384 | M5: =L5*8000 -> 3072000 | N5: =D5-G5-H5-I5-J5-K5-M5 -> -84072000 | O5: =N5-16000000 -> -100072000 | P5: =O5-30000000 -> -130072000
A6: Nguyễn Chí Thanh | D6: =B6-C6 -> 0 | E6: =D6/B6 -> #DIV/0! | F6: Không đạt | G6: 60000000 | H6: 30000000 | I6: 3500000 | J6: 8000000 | K6: 6000000 | L6: 556 | M6: =L6*8000 -> 4448000 | N6: =D6-G6-H6-I6-J6-K6-M6 -> -111948000 | O6: =N6-16000000 -> -127948000 | P6: =O6-30000000 -> -157948000
A7: Nguyễn Thị Thập | D7: =B7-C7 -> 0 | E7: =D7/B7 -> #DIV/0! | F7: Không đạt | G7: 44000000 | H7: 35000000 | I7: 2500000 | J7: 5000000 | K7: 6000000 | L7: 810 | M7: =L7*8000 -> 6480000 | N7: =D7-G7-H7-I7-J7-K7-M7 -> -98980000 | O7: =N7-16000000 -> -114980000 | P7: =O7-30000000 -> -144980000
A8: Nguyễn Văn Quá | D8: =B8-C8 -> 0 | E8: =D8/B8 -> #DIV/0! | F8: Không đạt | G8: 50000000 | H8: 24000000 | I8: 4000000 | J8: 6800000 | K8: 6000000 | L8: 448 | M8: =L8*8000 -> 3584000 | N8: =D8-G8-H8-I8-J8-K8-M8 -> -94384000 | O8: =N8-16000000 -> -110384000 | P8: =O8-30000000 -> -140384000
A9: Rạch Bùng Binh | D9: =B9-C9 -> 0 | E9: =D9/B9 -> #DIV/0! | F9: Không đạt | G9: 66000000 | H9: 30000000 | I9: 2500000 | J9: 8000000 | K9: 6000000 | L9: 841 | M9: =L9*8000 -> 6728000 | N9: =D9-G9-H9-I9-J9-K9-M9 -> -119228000 | O9: =N9-16000000 -> -135228000 | P9: =O9-30000000 -> -165228000
A10: Đường Láng | D10: =B10-C10 -> 0 | E10: =D10/B10 -> #DIV/0! | F10: Không đạt | G10: 72000000 | H10: 10000000 | I10: 3000000 | J10: 3500000 | K10: 6000000 | L10: 1322 | M10: =L10*8000 -> 10576000 | N10: =D10-G10-H10-I10-J10-K10-M10 -> -105076000 | O10: =N10-16000000 -> -121076000 | P10: =O10-30000000 -> -151076000
A11: Hàng Bông | D11: =B11-C11 -> 0 | E11: =D11/B11 -> #DIV/0! | F11: Không đạt | G11: 60000000 | H11: 45000000 | I11: 0 | J11: 5500000 | K11: 6000000 | L11: 708 | M11: =L11*8000 -> 5664000 | N11: =D11-G11-H11-I11-J11-K11-M11 -> -122164000 | O11: =N11-16000000 -> -138164000 | P11: =O11-30000000 -> -168164000
B12: =SUM(B2:B11) -> 0 | D12: =SUM(D2:D11) -> 0 | E12: =D12/B12 -> #DIV/0!

Sheet BẢNG LƯƠNG
E1: Tổng thời gian làm việc | G1: Quản lý và cửa hàng trưởng ghi nhận vào đây - công thức tổng tự động không cần chỉnh | R1: Quản lý ghi nhận | AK1: KPI trừ
A2: STT | B2: Chi nhánh | C2: Tên | D2: Hình thức | E2: Số giờ ca ngày | F2: Số giờ ca đêm | G2: Số giờ ca ngày | H2: Số giờ ca đêm ( chưa x 1.5 ) | I2: Số giờ tăng ca ngày ( x 1 ) | J2: Số ngày thực làm | K2: Số ngày làm đêm | L2: Ngày lễ hưởng lương ( x 1 ) | M2: Ghi ngày cụ thể | N2: Số ngày lễ vẫn đi làm | O2: Số giờ lễ ca ngày ( Đã x 3 ) | P2: Số giờ lễ ca đêm ( Đã x 3 ) | Q2: Ngày lễ vẫn đi làm (ghi ngày cụ thể) | R2: Số ngày công thực tế | S2: Số giờ tham gia đào tạo | T2: Số giờ nghỉ phép năm | U2: Ngày phép năm (ghi ngày cụ thể) | V2: Phụ cấp trách nhiệm (áp dụng CHT) | W2: Phụ cấp cửa hàng mới | X2: Phụ cấp sức khỏe ca đêm | Y2: Phụ cấp lưu động | Z2: Phụ cấp tăng cường vận hành | AA2: Thưởng dự án Mini KAT (Dược sĩ) | AB2: Thưởng dự án Mini KAT (Đại diện CHT nhận) | AC2: Thường Whatsapp | AD2: Phụ cấp quy trình/dự án | AE2: Thưởng KPI | AF2: Thưởng hàng điểm + Cắt liều | AG2: Thưởng hàng cận date | AH2: Thưởng chương trình Maps | AI2: Thưởng khác | AJ2: Total | AK2: Hàng hết date | AL2: Quy chế quy trình | AM2: HD App - Kiot | AN2: Ecom | AO2: Khác | AP2: Ghi chú
A3: {=_xludf.SEQUENCE(COUNTA(B3:B111),1)} -> #NAME? | B3: 24H | C3: Hồ Thị Minh Hòa | D3: DSBC | E3: =G3+I3+L3+O3+S3+T3 -> #NAME? | F3: =H3+P3 -> 48.4 | G3: =SUMIFS('Giờ công'!I:I,'Giờ công'!G:G,B3,'Giờ công'!H:H,C3) -> 118 | H3: =SUMIFS('Giờ công'!J:J,'Giờ công'!G:G,B3,'Giờ công'!H:H,C3) -> 48.4 | I3: =_xludf.ifs(R3>=30,16,R3=29,8,TRUE,"") -> #NAME? | J3: 18 | K3: 6 | N3: =SUMIFS('Tăng ca lễ'!M:M,'Tăng ca lễ'!K:K,B3,'Tăng ca lễ'!L:L,C3) -> 0 | O3: =IF(OR(D3 = "PT",D3 = "DSHV"), SUMIFS('Tăng ca lễ'!O:O,'Tăng ca lễ'!K:K,B3,'Tăng ca lễ'!L:L,C3)*2, SUMIFS('Tăng ca lễ'!O:O,'Tăng ca lễ'!K:K,B3,'Tăng ca lễ'!L:L,C3)*3) -> 0 | P3: =IF(OR(D3 = "PT", D3 = "DSHV"), SUMIFS('Tăng ca lễ'!P:P,'Tăng ca lễ'!K:K,B3,'Tăng ca lễ'!L:L,C3)*2, SUMIFS('Tăng ca lễ'!P:P,'Tăng ca lễ'!K:K,B3,'Tăng ca lễ'!L:L,C3)*3) -> 0 | R3: =SUMIFS('Ngày công'!M:M,'Ngày công'!K:K,B3,'Ngày công'!L:L,C3) -> 18 | S3: =SUMIFS('Công Đào tạo'!G:G,'Công Đào tạo'!E:E,B3,'Công Đào tạo'!F:F,C3) -> 0 | T3: 0 | V3: =500000/30*17 -> 283333.33 | X3: =IFERROR(__xludf.DUMMYFUNCTION("IF($C3="""","""", IF( TRIM($D3)=""DSCD"", MIN( 1500000, ROUND(1500000/28*MIN(N($J3),28),0) ), IF( AND( REGEXMATCH(TRIM($D3),""^(DSXC|DSBC|CHT|DSTV)$""), N($H3)>=160 ), MIN( 1500000, ROUND(1500000/28*MIN(N($K3),28),0"&") ), 0 ) ) )"),0) -> 0 | AA3: {=IF($C3="","", IFERROR( _xludf.LET( cnChinh, _xlfn.XLOOKUP( TRIM($C3), TRIM(KPI!$B$2:$B1043), KPI!$A$2:$A1043, "" ), IF( TRIM($B3)=TRIM(cnChinh), _xlfn.XLOOKUP( TRIM($C3), TRIM('MiniKat - HCM'!$A$2:$A1043), 'MiniKat - HCM'!$J$2:$J1043, "" ), "" ) ), "" ) )} | AC3: {=IFERROR(_xlfn.XLOOKUP(C3, whatsapp!A:A,whatsapp!D:D), " ")} | AD3: {=IF($C3="","", IFERROR( _xludf.LET( cnChinh, _xlfn.XLOOKUP( TRIM($C3), TRIM(KPI!$B$2:$B1043), KPI!$A$2:$A1043, "" ), IF( TRIM($B3)=TRIM(cnChinh), _xlfn.XLOOKUP( TRIM($C3), TRIM('Dự án'!$B$2:$B1043), 'Dự án'!$C$2:$C1043, "" ), "" ) ), "" ) )} | AE3: =SUMIFS(KPI!C:C,KPI!A:A,B3,KPI!B:B,C3) -> 0 | AF3: =SUMIFS('Thưởng CK'!C:C,'Thưởng CK'!A:A,B3,'Thưởng CK'!B:B,C3) -> 0 | AG3: =SUMIFS('Cận date'!C:C,'Cận date'!A:A,B3,'Cận date'!B:B,C3) -> 0 | AH3: =SUMIFS(Map!D:D,Map!B:B,B3,Map!A:A,C3) -> 0 | AJ3: =SUM(AK3:AO3) -> 0 | AK3: =SUMIFS('KPI trừ'!C:C,'KPI trừ'!A:A,B3,'KPI trừ'!B:B,C3) -> 0 | AL3: =SUMIFS('KPI trừ'!D:D,'KPI trừ'!A:A,B3,'KPI trừ'!B:B,C3) -> 0 | AM3: =SUMIFS('KPI trừ'!E:E,'KPI trừ'!A:A,B3,'KPI trừ'!B:B,C3) -> 0 | AN3: =SUMIFS('KPI trừ'!F:F,'KPI trừ'!A:A,B3,'KPI trừ'!B:B,C3) -> 0 | AO3: =SUMIFS('KPI trừ'!G:G,'KPI trừ'!A:A,B3,'KPI trừ'!B:B,C3) -> 0 | AP3: =IFERROR(__xludf.DUMMYFUNCTION("IFERROR(TEXTJOIN("" "", TRUE, FILTER('KPI trừ'!H:H, ('KPI trừ'!A:A=B3) * ('KPI trừ'!B:B=C3))), """")"),"") | AQ3: =IFERROR(__xludf.DUMMYFUNCTION("IFERROR( MAX( QUERY( FILTER( {'Ngày công'!$C$2:$C$5000,'Ngày công'!$F$2:$F$5000}, TRIM('Ngày công'!$B$2:$B$5000)=TRIM($C3) ), ""select sum(Col2) where Col1 is not null group by Col1 label sum(Col2) ''"", 0 ) ), 0 )"),16.65) -> 16.65
A4: #NAME? | B4: 24H | C4: Nguyễn Ngọc Anh Thư | D4: DSTV | E4: =G4+I4+L4+O4+S4+T4 -> #NAME? | F4: =H4+P4 -> 72.316667 | G4: =SUMIFS('Giờ công'!I:I,'Giờ công'!G:G,B4,'Giờ công'!H:H,C4) -> 39.116667 | H4: =SUMIFS('Giờ công'!J:J,'Giờ công'!G:G,B4,'Giờ công'!H:H,C4) -> 72.316667 | I4: =_xludf.ifs(R4>=30,16,R4=29,8,TRUE,"") -> #NAME? | J4: 14 | K4: 9 | N4: =SUMIFS('Tăng ca lễ'!M:M,'Tăng ca lễ'!K:K,B4,'Tăng ca lễ'!L:L,C4) -> 0 | O4: =IF(OR(D4 = "PT",D4 = "DSHV"), SUMIFS('Tăng ca lễ'!O:O,'Tăng ca lễ'!K:K,B4,'Tăng ca lễ'!L:L,C4)*2, SUMIFS('Tăng ca lễ'!O:O,'Tăng ca lễ'!K:K,B4,'Tăng ca lễ'!L:L,C4)*3) -> 0 | P4: =IF(OR(D4 = "PT", D4 = "DSHV"), SUMIFS('Tăng ca lễ'!P:P,'Tăng ca lễ'!K:K,B4,'Tăng ca lễ'!L:L,C4)*2, SUMIFS('Tăng ca lễ'!P:P,'Tăng ca lễ'!K:K,B4,'Tăng ca lễ'!L:L,C4)*3) -> 0 | R4: =SUMIFS('Ngày công'!M:M,'Ngày công'!K:K,B4,'Ngày công'!L:L,C4) -> 14 | S4: =SUMIFS('Công Đào tạo'!G:G,'Công Đào tạo'!E:E,B4,'Công Đào tạo'!F:F,C4) -> 4.5 | T4: 0 | X4: =IFERROR(__xludf.DUMMYFUNCTION("IF($C4="""","""", IF( TRIM($D4)=""DSCD"", MIN( 1500000, ROUND(1500000/28*MIN(N($J4),28),0) ), IF( AND( REGEXMATCH(TRIM($D4),""^(DSXC|DSBC|CHT|DSTV)$""), N($H4)>=160 ), MIN( 1500000, ROUND(1500000/28*MIN(N($K4),28),0"&") ), 0 ) ) )"),0) -> 0 | AA4: {=IF($C4="","", IFERROR( _xludf.LET( cnChinh, _xlfn.XLOOKUP( TRIM($C4), TRIM(KPI!$B$2:$B1043), KPI!$A$2:$A1043, "" ), IF( TRIM($B4)=TRIM(cnChinh), _xlfn.XLOOKUP( TRIM($C4), TRIM('MiniKat - HCM'!$A$2:$A1043), 'MiniKat - HCM'!$J$2:$J1043, "" ), "" ) ), "" ) )} | AC4: {=IFERROR(_xlfn.XLOOKUP(C4, whatsapp!A:A,whatsapp!D:D), " ")} | AD4: {=IF($C4="","", IFERROR( _xludf.LET( cnChinh, _xlfn.XLOOKUP( TRIM($C4), TRIM(KPI!$B$2:$B1043), KPI!$A$2:$A1043, "" ), IF( TRIM($B4)=TRIM(cnChinh), _xlfn.XLOOKUP( TRIM($C4), TRIM('Dự án'!$B$2:$B1043), 'Dự án'!$C$2:$C1043, "" ), "" ) ), "" ) )} | AE4: =SUMIFS(KPI!C:C,KPI!A:A,B4,KPI!B:B,C4) -> 0 | AF4: =SUMIFS('Thưởng CK'!C:C,'Thưởng CK'!A:A,B4,'Thưởng CK'!B:B,C4) -> 0 | AG4: =SUMIFS('Cận date'!C:C,'Cận date'!A:A,B4,'Cận date'!B:B,C4) -> 0 | AH4: =SUMIFS(Map!D:D,Map!B:B,B4,Map!A:A,C4) -> 0 | AJ4: =SUM(AK4:AO4) -> 0 | AK4: =SUMIFS('KPI trừ'!C:C,'KPI trừ'!A:A,B4,'KPI trừ'!B:B,C4) -> 0 | AL4: =SUMIFS('KPI trừ'!D:D,'KPI trừ'!A:A,B4,'KPI trừ'!B:B,C4) -> 0 | AM4: =SUMIFS('KPI trừ'!E:E,'KPI trừ'!A:A,B4,'KPI trừ'!B:B,C4) -> 0 | AN4: =SUMIFS('KPI trừ'!F:F,'KPI trừ'!A:A,B4,'KPI trừ'!B:B,C4) -> 0 | AO4: =SUMIFS('KPI trừ'!G:G,'KPI trừ'!A:A,B4,'KPI trừ'!B:B,C4) -> 0 | AP4: =IFERROR(__xludf.DUMMYFUNCTION("IFERROR(TEXTJOIN("" "", TRUE, FILTER('KPI trừ'!H:H, ('KPI trừ'!A:A=B4) * ('KPI trừ'!B:B=C4))), """")"),"") | AQ4: =IFERROR(__xludf.DUMMYFUNCTION("IFERROR( MAX( QUERY( FILTER( {'Ngày công'!$C$2:$C$5000,'Ngày công'!$F$2:$F$5000}, TRIM('Ngày công'!$B$2:$B$5000)=TRIM($C4) ), ""select sum(Col2) where Col1 is not null group by Col1 label sum(Col2) ''"", 0 ) ), 0 )"),8.91666666666666) -> 8.9166667
A5: #NAME? | B5: 24H | C5: Nguyễn Trần Ngọc Phương | D5: CHT | E5: =G5+I5+L5+O5+S5+T5 -> #NAME? | F5: =H5+P5 -> 70.183333 | G5: =SUMIFS('Giờ công'!I:I,'Giờ công'!G:G,B5,'Giờ công'!H:H,C5) -> 146.11667 | H5: =SUMIFS('Giờ công'!J:J,'Giờ công'!G:G,B5,'Giờ công'!H:H,C5) -> 70.183333 | I5: =_xludf.ifs(R5>=30,16,R5=29,8,TRUE,"") -> #NAME? | J5: 27 | K5: 9 | N5: =SUMIFS('Tăng ca lễ'!M:M,'Tăng ca lễ'!K:K,B5,'Tăng ca lễ'!L:L,C5) -> 0 | O5: =IF(OR(D5 = "PT",D5 = "DSHV"), SUMIFS('Tăng ca lễ'!O:O,'Tăng ca lễ'!K:K,B5,'Tăng ca lễ'!L:L,C5)*2, SUMIFS('Tăng ca lễ'!O:O,'Tăng ca lễ'!K:K,B5,'Tăng ca lễ'!L:L,C5)*3) -> 0 | P5: =IF(OR(D5 = "PT", D5 = "DSHV"), SUMIFS('Tăng ca lễ'!P:P,'Tăng ca lễ'!K:K,B5,'Tăng ca lễ'!L:L,C5)*2, SUMIFS('Tăng ca lễ'!P:P,'Tăng ca lễ'!K:K,B5,'Tăng ca lễ'!L:L,C5)*3) -> 0 | R5: =SUMIFS('Ngày công'!M:M,'Ngày công'!K:K,B5,'Ngày công'!L:L,C5) -> 27 | S5: =SUMIFS('Công Đào tạo'!G:G,'Công Đào tạo'!E:E,B5,'Công Đào tạo'!F:F,C5) -> 0 | T5: 0 | V5: =2000000*0.75 -> 1500000 | X5: =IFERROR(__xludf.DUMMYFUNCTION("IF($C5="""","""", IF( TRIM($D5)=""DSCD"", MIN( 1500000, ROUND(1500000/28*MIN(N($J5),28),0) ), IF( AND( REGEXMATCH(TRIM($D5),""^(DSXC|DSBC|CHT|DSTV)$""), N($H5)>=160 ), MIN( 1500000, ROUND(1500000/28*MIN(N($K5),28),0"&") ), 0 ) ) )"),0) -> 0 | AA5: {=IF($C5="","", IFERROR( _xludf.LET( cnChinh, _xlfn.XLOOKUP( TRIM($C5), TRIM(KPI!$B$2:$B1043), KPI!$A$2:$A1043, "" ), IF( TRIM($B5)=TRIM(cnChinh), _xlfn.XLOOKUP( TRIM($C5), TRIM('MiniKat - HCM'!$A$2:$A1043), 'MiniKat - HCM'!$J$2:$J1043, "" ), "" ) ), "" ) )} | AC5: {=IFERROR(_xlfn.XLOOKUP(C5, whatsapp!A:A,whatsapp!D:D), " ")} | AD5: {=IF($C5="","", IFERROR( _xludf.LET( cnChinh, _xlfn.XLOOKUP( TRIM($C5), TRIM(KPI!$B$2:$B1043), KPI!$A$2:$A1043, "" ), IF( TRIM($B5)=TRIM(cnChinh), _xlfn.XLOOKUP( TRIM($C5), TRIM('Dự án'!$B$2:$B1043), 'Dự án'!$C$2:$C1043, "" ), "" ) ), "" ) )} | AE5: =SUMIFS(KPI!C:C,KPI!A:A,B5,KPI!B:B,C5) -> 0 | AF5: =SUMIFS('Thưởng CK'!C:C,'Thưởng CK'!A:A,B5,'Thưởng CK'!B:B,C5) -> 876500 | AG5: =SUMIFS('Cận date'!C:C,'Cận date'!A:A,B5,'Cận date'!B:B,C5) -> 5680 | AH5: =SUMIFS(Map!D:D,Map!B:B,B5,Map!A:A,C5) -> 0 | AJ5: =SUM(AK5:AO5) -> 500000 | AK5: =SUMIFS('KPI trừ'!C:C,'KPI trừ'!A:A,B5,'KPI trừ'!B:B,C5) -> 0 | AL5: =SUMIFS('KPI trừ'!D:D,'KPI trừ'!A:A,B5,'KPI trừ'!B:B,C5) -> 0 | AM5: =SUMIFS('KPI trừ'!E:E,'KPI trừ'!A:A,B5,'KPI trừ'!B:B,C5) -> 0 | AN5: =SUMIFS('KPI trừ'!F:F,'KPI trừ'!A:A,B5,'KPI trừ'!B:B,C5) -> 0 | AO5: =SUMIFS('KPI trừ'!G:G,'KPI trừ'!A:A,B5,'KPI trừ'!B:B,C5) -> 500000 | AP5: =IFERROR(__xludf.DUMMYFUNCTION("IFERROR(TEXTJOIN("" "", TRUE, FILTER('KPI trừ'!H:H, ('KPI trừ'!A:A=B5) * ('KPI trừ'!B:B=C5))), """")"),"Cấn trừ chi phí đồng phục") -> Cấn trừ chi phí đồng phục | AQ5: =IFERROR(__xludf.DUMMYFUNCTION("IFERROR( MAX( QUERY( FILTER( {'Ngày công'!$C$2:$C$5000,'Ngày công'!$F$2:$F$5000}, TRIM('Ngày công'!$B$2:$B$5000)=TRIM($C5) ), ""select sum(Col2) where Col1 is not null group by Col1 label sum(Col2) ''"", 0 ) ), 0 )"),13.9833333333333) -> 13.983333
A6: #NAME? | B6: 24H | C6: Ngô Trần Tuyết Vy | D6: DSBC | E6: =G6+I6+L6+O6+S6+T6 -> #NAME? | F6: =H6+P6 -> 137.31667 | G6: =SUMIFS('Giờ công'!I:I,'Giờ công'!G:G,B6,'Giờ công'!H:H,C6) -> 128.58333 | H6: =SUMIFS('Giờ công'!J:J,'Giờ công'!G:G,B6,'Giờ công'!H:H,C6) -> 137.31667 | I6: =_xludf.ifs(R6>=30,16,R6=29,8,TRUE,"") -> #NAME? | J6: 31 | K6: 17 | N6: =SUMIFS('Tăng ca lễ'!M:M,'Tăng ca lễ'!K:K,B6,'Tăng ca lễ'!L:L,C6) -> 0 | O6: =IF(OR(D6 = "PT",D6 = "DSHV"), SUMIFS('Tăng ca lễ'!O:O,'Tăng ca lễ'!K:K,B6,'Tăng ca lễ'!L:L,C6)*2, SUMIFS('Tăng ca lễ'!O:O,'Tăng ca lễ'!K:K,B6,'Tăng ca lễ'!L:L,C6)*3) -> 0 | P6: =IF(OR(D6 = "PT", D6 = "DSHV"), SUMIFS('Tăng ca lễ'!P:P,'Tăng ca lễ'!K:K,B6,'Tăng ca lễ'!L:L,C6)*2, SUMIFS('Tăng ca lễ'!P:P,'Tăng ca lễ'!K:K,B6,'Tăng ca lễ'!L:L,C6)*3) -> 0 | R6: =SUMIFS('Ngày công'!M:M,'Ngày công'!K:K,B6,'Ngày công'!L:L,C6) -> 31 | S6: =SUMIFS('Công Đào tạo'!G:G,'Công Đào tạo'!E:E,B6,'Công Đào tạo'!F:F,C6) -> 0 | T6: 0 | X6: =IFERROR(__xludf.DUMMYFUNCTION("IF($C6="""","""", IF( TRIM($D6)=""DSCD"", MIN( 1500000, ROUND(1500000/28*MIN(N($J6),28),0) ), IF( AND( REGEXMATCH(TRIM($D6),""^(DSXC|DSBC|CHT|DSTV)$""), N($H6)>=160 ), MIN( 1500000, ROUND(1500000/28*MIN(N($K6),28),0"&") ), 0 ) ) )"),0) -> 0 | AA6: {=IF($C6="","", IFERROR( _xludf.LET( cnChinh, _xlfn.XLOOKUP( TRIM($C6), TRIM(KPI!$B$2:$B1043), KPI!$A$2:$A1043, "" ), IF( TRIM($B6)=TRIM(cnChinh), _xlfn.XLOOKUP( TRIM($C6), TRIM('MiniKat - HCM'!$A$2:$A1043), 'MiniKat - HCM'!$J$2:$J1043, "" ), "" ) ), "" ) )} | AC6: {=IFERROR(_xlfn.XLOOKUP(C6, whatsapp!A:A,whatsapp!D:D), " ")} | AD6: {=IF($C6="","", IFERROR( _xludf.LET( cnChinh, _xlfn.XLOOKUP( TRIM($C6), TRIM(KPI!$B$2:$B1043), KPI!$A$2:$A1043, "" ), IF( TRIM($B6)=TRIM(cnChinh), _xlfn.XLOOKUP( TRIM($C6), TRIM('Dự án'!$B$2:$B1043), 'Dự án'!$C$2:$C1043, "" ), "" ) ), "" ) )} | AE6: =SUMIFS(KPI!C:C,KPI!A:A,B6,KPI!B:B,C6) -> 1154180 | AF6: =SUMIFS('Thưởng CK'!C:C,'Thưởng CK'!A:A,B6,'Thưởng CK'!B:B,C6) -> 2576900 | AG6: =SUMIFS('Cận date'!C:C,'Cận date'!A:A,B6,'Cận date'!B:B,C6) -> 10408.25 | AH6: =SUMIFS(Map!D:D,Map!B:B,B6,Map!A:A,C6) -> 0 | AJ6: =SUM(AK6:AO6) -> 0 | AK6: =SUMIFS('KPI trừ'!C:C,'KPI trừ'!A:A,B6,'KPI trừ'!B:B,C6) -> 0 | AL6: =SUMIFS('KPI trừ'!D:D,'KPI trừ'!A:A,B6,'KPI trừ'!B:B,C6) -> 0 | AM6: =SUMIFS('KPI trừ'!E:E,'KPI trừ'!A:A,B6,'KPI trừ'!B:B,C6) -> 0 | AN6: =SUMIFS('KPI trừ'!F:F,'KPI trừ'!A:A,B6,'KPI trừ'!B:B,C6) -> 0 | AO6: =SUMIFS('KPI trừ'!G:G,'KPI trừ'!A:A,B6,'KPI trừ'!B:B,C6) -> 0 | AP6: =IFERROR(__xludf.DUMMYFUNCTION("IFERROR(TEXTJOIN("" "", TRUE, FILTER('KPI trừ'!H:H, ('KPI trừ'!A:A=B6) * ('KPI trừ'!B:B=C6))), """")"),"") | AQ6: =IFERROR(__xludf.DUMMYFUNCTION("IFERROR( MAX( QUERY( FILTER( {'Ngày công'!$C$2:$C$5000,'Ngày công'!$F$2:$F$5000}, TRIM('Ngày công'!$B$2:$B$5000)=TRIM($C6) ), ""select sum(Col2) where Col1 is not null group by Col1 label sum(Col2) ''"", 0 ) ), 0 )"),14.3666666666666) -> 14.366667
A7: #NAME? | B7: 24H | C7: Phạm Nguyễn Ngọc Quý | D7: DSBC | E7: =G7+I7+L7+O7+S7+T7 -> #NAME? | F7: =H7+P7 -> 135.95 | G7: =SUMIFS('Giờ công'!I:I,'Giờ công'!G:G,B7,'Giờ công'!H:H,C7) -> 122.41667 | H7: =SUMIFS('Giờ công'!J:J,'Giờ công'!G:G,B7,'Giờ công'!H:H,C7) -> 135.95 | I7: =_xludf.ifs(R7>=30,16,R7=29,8,TRUE,"") -> #NAME? | J7: 31 | K7: 17 | N7: =SUMIFS('Tăng ca lễ'!M:M,'Tăng ca lễ'!K:K,B7,'Tăng ca lễ'!L:L,C7) -> 0 | O7: =IF(OR(D7 = "PT",D7 = "DSHV"), SUMIFS('Tăng ca lễ'!O:O,'Tăng ca lễ'!K:K,B7,'Tăng ca lễ'!L:L,C7)*2, SUMIFS('Tăng ca lễ'!O:O,'Tăng ca lễ'!K:K,B7,'Tăng ca lễ'!L:L,C7)*3) -> 0 | P7: =IF(OR(D7 = "PT", D7 = "DSHV"), SUMIFS('Tăng ca lễ'!P:P,'Tăng ca lễ'!K:K,B7,'Tăng ca lễ'!L:L,C7)*2, SUMIFS('Tăng ca lễ'!P:P,'Tăng ca lễ'!K:K,B7,'Tăng ca lễ'!L:L,C7)*3) -> 0 | R7: =SUMIFS('Ngày công'!M:M,'Ngày công'!K:K,B7,'Ngày công'!L:L,C7) -> 31 | S7: =SUMIFS('Công Đào tạo'!G:G,'Công Đào tạo'!E:E,B7,'Công Đào tạo'!F:F,C7) -> 0 | T7: 0 | X7: =IFERROR(__xludf.DUMMYFUNCTION("IF($C7="""","""", IF( TRIM($D7)=""DSCD"", MIN( 1500000, ROUND(1500000/28*MIN(N($J7),28),0) ), IF( AND( REGEXMATCH(TRIM($D7),""^(DSXC|DSBC|CHT|DSTV)$""), N($H7)>=160 ), MIN( 1500000, ROUND(1500000/28*MIN(N($K7),28),0"&") ), 0 ) ) )"),0) -> 0 | AA7: {=IF($C7="","", IFERROR( _xludf.LET( cnChinh, _xlfn.XLOOKUP( TRIM($C7), TRIM(KPI!$B$2:$B1043), KPI!$A$2:$A1043, "" ), IF( TRIM($B7)=TRIM(cnChinh), _xlfn.XLOOKUP( TRIM($C7), TRIM('MiniKat - HCM'!$A$2:$A1043), 'MiniKat - HCM'!$J$2:$J1043, "" ), "" ) ), "" ) )} | AC7: {=IFERROR(_xlfn.XLOOKUP(C7, whatsapp!A:A,whatsapp!D:D), " ")} | AD7: {=IF($C7="","", IFERROR( _xludf.LET( cnChinh, _xlfn.XLOOKUP( TRIM($C7), TRIM(KPI!$B$2:$B1043), KPI!$A$2:$A1043, "" ), IF( TRIM($B7)=TRIM(cnChinh), _xlfn.XLOOKUP( TRIM($C7), TRIM('Dự án'!$B$2:$B1043), 'Dự án'!$C$2:$C1043, "" ), "" ) ), "" ) )} | AE7: =SUMIFS(KPI!C:C,KPI!A:A,B7,KPI!B:B,C7) -> 0 | AF7: =SUMIFS('Thưởng CK'!C:C,'Thưởng CK'!A:A,B7,'Thưởng CK'!B:B,C7) -> 1968750 | AG7: =SUMIFS('Cận date'!C:C,'Cận date'!A:A,B7,'Cận date'!B:B,C7) -> 1050 | AH7: =SUMIFS(Map!D:D,Map!B:B,B7,Map!A:A,C7) -> 0 | AJ7: =SUM(AK7:AO7) -> 0 | AK7: =SUMIFS('KPI trừ'!C:C,'KPI trừ'!A:A,B7,'KPI trừ'!B:B,C7) -> 0 | AL7: =SUMIFS('KPI trừ'!D:D,'KPI trừ'!A:A,B7,'KPI trừ'!B:B,C7) -> 0 | AM7: =SUMIFS('KPI trừ'!E:E,'KPI trừ'!A:A,B7,'KPI trừ'!B:B,C7) -> 0 | AN7: =SUMIFS('KPI trừ'!F:F,'KPI trừ'!A:A,B7,'KPI trừ'!B:B,C7) -> 0 | AO7: =SUMIFS('KPI trừ'!G:G,'KPI trừ'!A:A,B7,'KPI trừ'!B:B,C7) -> 0 | AP7: =IFERROR(__xludf.DUMMYFUNCTION("IFERROR(TEXTJOIN("" "", TRUE, FILTER('KPI trừ'!H:H, ('KPI trừ'!A:A=B7) * ('KPI trừ'!B:B=C7))), """")"),"") | AQ7: =IFERROR(__xludf.DUMMYFUNCTION("IFERROR( MAX( QUERY( FILTER( {'Ngày công'!$C$2:$C$5000,'Ngày công'!$F$2:$F$5000}, TRIM('Ngày công'!$B$2:$B$5000)=TRIM($C7) ), ""select sum(Col2) where Col1 is not null group by Col1 label sum(Col2) ''"", 0 ) ), 0 )"),13.9166666666666) -> 13.916667
A8: #NAME? | B8: 24H | C8: Trần Thị Kim Khánh | D8: DSBC | E8: =G8+I8+L8+O8+S8+T8 -> #NAME? | F8: =H8+P8 -> 87.216667 | G8: =SUMIFS('Giờ công'!I:I,'Giờ công'!G:G,B8,'Giờ công'!H:H,C8) -> 196.4 | H8: =SUMIFS('Giờ công'!J:J,'Giờ công'!G:G,B8,'Giờ công'!H:H,C8) -> 87.216667 | I8: =_xludf.ifs(R8>=30,16,R8=29,8,TRUE,"") -> #NAME? | J8: 31 | K8: 11 | N8: =SUMIFS('Tăng ca lễ'!M:M,'Tăng ca lễ'!K:K,B8,'Tăng ca lễ'!L:L,C8) -> 0 | O8: =IF(OR(D8 = "PT",D8 = "DSHV"), SUMIFS('Tăng ca lễ'!O:O,'Tăng ca lễ'!K:K,B8,'Tăng ca lễ'!L:L,C8)*2, SUMIFS('Tăng ca lễ'!O:O,'Tăng ca lễ'!K:K,B8,'Tăng ca lễ'!L:L,C8)*3) -> 0 | P8: =IF(OR(D8 = "PT", D8 = "DSHV"), SUMIFS('Tăng ca lễ'!P:P,'Tăng ca lễ'!K:K,B8,'Tăng ca lễ'!L:L,C8)*2, SUMIFS('Tăng ca lễ'!P:P,'Tăng ca lễ'!K:K,B8,'Tăng ca lễ'!L:L,C8)*3) -> 0 | R8: =SUMIFS('Ngày công'!M:M,'Ngày công'!K:K,B8,'Ngày công'!L:L,C8) -> 31 | S8: =SUMIFS('Công Đào tạo'!G:G,'Công Đào tạo'!E:E,B8,'Công Đào tạo'!F:F,C8) -> 0 | T8: 0 | X8: =IFERROR(__xludf.DUMMYFUNCTION("IF($C8="""","""", IF( TRIM($D8)=""DSCD"", MIN( 1500000, ROUND(1500000/28*MIN(N($J8),28),0) ), IF( AND( REGEXMATCH(TRIM($D8),""^(DSXC|DSBC|CHT|DSTV)$""), N($H8)>=160 ), MIN( 1500000, ROUND(1500000/28*MIN(N($K8),28),0"&") ), 0 ) ) )"),0) -> 0 | AA8: {=IF($C8="","", IFERROR( _xludf.LET( cnChinh, _xlfn.XLOOKUP( TRIM($C8), TRIM(KPI!$B$2:$B1043), KPI!$A$2:$A1043, "" ), IF( TRIM($B8)=TRIM(cnChinh), _xlfn.XLOOKUP( TRIM($C8), TRIM('MiniKat - HCM'!$A$2:$A1043), 'MiniKat - HCM'!$J$2:$J1043, "" ), "" ) ), "" ) )} | AC8: {=IFERROR(_xlfn.XLOOKUP(C8, whatsapp!A:A,whatsapp!D:D), " ")} | AD8: {=IF($C8="","", IFERROR( _xludf.LET( cnChinh, _xlfn.XLOOKUP( TRIM($C8), TRIM(KPI!$B$2:$B1043), KPI!$A$2:$A1043, "" ), IF( TRIM($B8)=TRIM(cnChinh), _xlfn.XLOOKUP( TRIM($C8), TRIM('Dự án'!$B$2:$B1043), 'Dự án'!$C$2:$C1043, "" ), "" ) ), "" ) )} | AE8: =SUMIFS(KPI!C:C,KPI!A:A,B8,KPI!B:B,C8) -> 2027888 | AF8: =SUMIFS('Thưởng CK'!C:C,'Thưởng CK'!A:A,B8,'Thưởng CK'!B:B,C8) -> 3969800 | AG8: =SUMIFS('Cận date'!C:C,'Cận date'!A:A,B8,'Cận date'!B:B,C8) -> 6380 | AH8: =SUMIFS(Map!D:D,Map!B:B,B8,Map!A:A,C8) -> 0 | AJ8: =SUM(AK8:AO8) -> 0 | AK8: =SUMIFS('KPI trừ'!C:C,'KPI trừ'!A:A,B8,'KPI trừ'!B:B,C8) -> 0 | AL8: =SUMIFS('KPI trừ'!D:D,'KPI trừ'!A:A,B8,'KPI trừ'!B:B,C8) -> 0 | AM8: =SUMIFS('KPI trừ'!E:E,'KPI trừ'!A:A,B8,'KPI trừ'!B:B,C8) -> 0 | AN8: =SUMIFS('KPI trừ'!F:F,'KPI trừ'!A:A,B8,'KPI trừ'!B:B,C8) -> 0 | AO8: =SUMIFS('KPI trừ'!G:G,'KPI trừ'!A:A,B8,'KPI trừ'!B:B,C8) -> 0 | AP8: =IFERROR(__xludf.DUMMYFUNCTION("IFERROR(TEXTJOIN("" "", TRUE, FILTER('KPI trừ'!H:H, ('KPI trừ'!A:A=B8) * ('KPI trừ'!B:B=C8))), """")"),"") | AQ8: =IFERROR(__xludf.DUMMYFUNCTION("IFERROR( MAX( QUERY( FILTER( {'Ngày công'!$C$2:$C$5000,'Ngày công'!$F$2:$F$5000}, TRIM('Ngày công'!$B$2:$B$5000)=TRIM($C8) ), ""select sum(Col2) where Col1 is not null group by Col1 label sum(Col2) ''"", 0 ) ), 0 )"),16.1333333333333) -> 16.133333
A9: #NAME? | B9: Đỗ Quang Đẩu | C9: Bùi Thị Thanh Thủy | D9: DSBC | E9: =G9+I9+L9+O9+S9+T9 -> #NAME? | F9: =H9+P9 -> 0 | G9: =SUMIFS('Giờ công'!I:I,'Giờ công'!G:G,B9,'Giờ công'!H:H,C9) -> 56.366667 | H9: =SUMIFS('Giờ công'!J:J,'Giờ công'!G:G,B9,'Giờ công'!H:H,C9) -> 0 | I9: =_xludf.ifs(R9>=30,16,R9=29,8,TRUE,"") -> #NAME? | J9: 7 | K9: 0 | N9: =SUMIFS('Tăng ca lễ'!M:M,'Tăng ca lễ'!K:K,B9,'Tăng ca lễ'!L:L,C9) -> 0 | O9: =IF(OR(D9 = "PT",D9 = "DSHV"), SUMIFS('Tăng ca lễ'!O:O,'Tăng ca lễ'!K:K,B9,'Tăng ca lễ'!L:L,C9)*2, SUMIFS('Tăng ca lễ'!O:O,'Tăng ca lễ'!K:K,B9,'Tăng ca lễ'!L:L,C9)*3) -> 0 | P9: =IF(OR(D9 = "PT", D9 = "DSHV"), SUMIFS('Tăng ca lễ'!P:P,'Tăng ca lễ'!K:K,B9,'Tăng ca lễ'!L:L,C9)*2, SUMIFS('Tăng ca lễ'!P:P,'Tăng ca lễ'!K:K,B9,'Tăng ca lễ'!L:L,C9)*3) -> 0 | R9: =SUMIFS('Ngày công'!M:M,'Ngày công'!K:K,B9,'Ngày công'!L:L,C9) -> 7 | S9: =SUMIFS('Công Đào tạo'!G:G,'Công Đào tạo'!E:E,B9,'Công Đào tạo'!F:F,C9) -> 0 | T9: 0 | X9: =IFERROR(__xludf.DUMMYFUNCTION("IF($C9="""","""", IF( TRIM($D9)=""DSCD"", MIN( 1500000, ROUND(1500000/28*MIN(N($J9),28),0) ), IF( AND( REGEXMATCH(TRIM($D9),""^(DSXC|DSBC|CHT|DSTV)$""), N($H9)>=160 ), MIN( 1500000, ROUND(1500000/28*MIN(N($K9),28),0"&") ), 0 ) ) )"),0) -> 0 | AA9: {=IF($C9="","", IFERROR( _xludf.LET( cnChinh, _xlfn.XLOOKUP( TRIM($C9), TRIM(KPI!$B$2:$B1043), KPI!$A$2:$A1043, "" ), IF( TRIM($B9)=TRIM(cnChinh), _xlfn.XLOOKUP( TRIM($C9), TRIM('MiniKat - HCM'!$A$2:$A1043), 'MiniKat - HCM'!$J$2:$J1043, "" ), "" ) ), "" ) )} | AC9: {=IFERROR(_xlfn.XLOOKUP(C9, whatsapp!A:A,whatsapp!D:D), " ")} | AD9: {=IF($C9="","", IFERROR( _xludf.LET( cnChinh, _xlfn.XLOOKUP( TRIM($C9), TRIM(KPI!$B$2:$B1043), KPI!$A$2:$A1043, "" ), IF( TRIM($B9)=TRIM(cnChinh), _xlfn.XLOOKUP( TRIM($C9), TRIM('Dự án'!$B$2:$B1043), 'Dự án'!$C$2:$C1043, "" ), "" ) ), "" ) )} | AE9: =SUMIFS(KPI!C:C,KPI!A:A,B9,KPI!B:B,C9) -> 0 | AF9: =SUMIFS('Thưởng CK'!C:C,'Thưởng CK'!A:A,B9,'Thưởng CK'!B:B,C9) -> 0 | AG9: =SUMIFS('Cận date'!C:C,'Cận date'!A:A,B9,'Cận date'!B:B,C9) -> 0 | AH9: =SUMIFS(Map!D:D,Map!B:B,B9,Map!A:A,C9) -> 0 | AJ9: =SUM(AK9:AO9) -> 0 | AK9: =SUMIFS('KPI trừ'!C:C,'KPI trừ'!A:A,B9,'KPI trừ'!B:B,C9) -> 0 | AL9: =SUMIFS('KPI trừ'!D:D,'KPI trừ'!A:A,B9,'KPI trừ'!B:B,C9) -> 0 | AM9: =SUMIFS('KPI trừ'!E:E,'KPI trừ'!A:A,B9,'KPI trừ'!B:B,C9) -> 0 | AN9: =SUMIFS('KPI trừ'!F:F,'KPI trừ'!A:A,B9,'KPI trừ'!B:B,C9) -> 0 | AO9: =SUMIFS('KPI trừ'!G:G,'KPI trừ'!A:A,B9,'KPI trừ'!B:B,C9) -> 0 | AP9: =IFERROR(__xludf.DUMMYFUNCTION("IFERROR(TEXTJOIN("" "", TRUE, FILTER('KPI trừ'!H:H, ('KPI trừ'!A:A=B9) * ('KPI trừ'!B:B=C9))), """")"),"") | AQ9: =IFERROR(__xludf.DUMMYFUNCTION("IFERROR( MAX( QUERY( FILTER( {'Ngày công'!$C$2:$C$5000,'Ngày công'!$F$2:$F$5000}, TRIM('Ngày công'!$B$2:$B$5000)=TRIM($C9) ), ""select sum(Col2) where Col1 is not null group by Col1 label sum(Col2) ''"", 0 ) ), 0 )"),16.0666666666666) -> 16.066667
A10: #NAME? | B10: Đỗ Quang Đẩu | C10: Dương Thị Huỳnh Như | D10: DSTV | E10: =G10+I10+L10+O10+S10+T10 -> #NAME? | F10: =H10+P10 -> 0 | G10: =SUMIFS('Giờ công'!I:I,'Giờ công'!G:G,B10,'Giờ công'!H:H,C10) -> 24.133333 | H10: =SUMIFS('Giờ công'!J:J,'Giờ công'!G:G,B10,'Giờ công'!H:H,C10) -> 0 | I10: =_xludf.ifs(R10>=30,16,R10=29,8,TRUE,"") -> #NAME? | J10: 3 | K10: 0 | N10: =SUMIFS('Tăng ca lễ'!M:M,'Tăng ca lễ'!K:K,B10,'Tăng ca lễ'!L:L,C10) -> 0 | O10: =IF(OR(D10 = "PT",D10 = "DSHV"), SUMIFS('Tăng ca lễ'!O:O,'Tăng ca lễ'!K:K,B10,'Tăng ca lễ'!L:L,C10)*2, SUMIFS('Tăng ca lễ'!O:O,'Tăng ca lễ'!K:K,B10,'Tăng ca lễ'!L:L,C10)*3) -> 0 | P10: =IF(OR(D10 = "PT", D10 = "DSHV"), SUMIFS('Tăng ca lễ'!P:P,'Tăng ca lễ'!K:K,B10,'Tăng ca lễ'!L:L,C10)*2, SUMIFS('Tăng ca lễ'!P:P,'Tăng ca lễ'!K:K,B10,'Tăng ca lễ'!L:L,C10)*3) -> 0 | R10: =SUMIFS('Ngày công'!M:M,'Ngày công'!K:K,B10,'Ngày công'!L:L,C10) -> 3 | S10: =SUMIFS('Công Đào tạo'!G:G,'Công Đào tạo'!E:E,B10,'Công Đào tạo'!F:F,C10) -> 0 | T10: 0 | X10: =IFERROR(__xludf.DUMMYFUNCTION("IF($C10="""","""", IF( TRIM($D10)=""DSCD"", MIN( 1500000, ROUND(1500000/28*MIN(N($J10),28),0) ), IF( AND( REGEXMATCH(TRIM($D10),""^(DSXC|DSBC|CHT|DSTV)$""), N($H10)>=160 ), MIN( 1500000, ROUND(1500000/28*MIN(N($K10)"&",28),0) ), 0 ) ) )"),0) -> 0 | AA10: {=IF($C10="","", IFERROR( _xludf.LET( cnChinh, _xlfn.XLOOKUP( TRIM($C10), TRIM(KPI!$B$2:$B1043), KPI!$A$2:$A1043, "" ), IF( TRIM($B10)=TRIM(cnChinh), _xlfn.XLOOKUP( TRIM($C10), TRIM('MiniKat - HCM'!$A$2:$A1043), 'MiniKat - HCM'!$J$2:$J1043, "" ), "" ) ), "" ) )} | AC10: {=IFERROR(_xlfn.XLOOKUP(C10, whatsapp!A:A,whatsapp!D:D), " ")} | AD10: {=IF($C10="","", IFERROR( _xludf.LET( cnChinh, _xlfn.XLOOKUP( TRIM($C10), TRIM(KPI!$B$2:$B1043), KPI!$A$2:$A1043, "" ), IF( TRIM($B10)=TRIM(cnChinh), _xlfn.XLOOKUP( TRIM($C10), TRIM('Dự án'!$B$2:$B1043), 'Dự án'!$C$2:$C1043, "" ), "" ) ), "" ) )} | AE10: =SUMIFS(KPI!C:C,KPI!A:A,B10,KPI!B:B,C10) -> 0 | AF10: =SUMIFS('Thưởng CK'!C:C,'Thưởng CK'!A:A,B10,'Thưởng CK'!B:B,C10) -> 0 | AG10: =SUMIFS('Cận date'!C:C,'Cận date'!A:A,B10,'Cận date'!B:B,C10) -> 0 | AH10: =SUMIFS(Map!D:D,Map!B:B,B10,Map!A:A,C10) -> 0 | AJ10: =SUM(AK10:AO10) -> 0 | AK10: =SUMIFS('KPI trừ'!C:C,'KPI trừ'!A:A,B10,'KPI trừ'!B:B,C10) -> 0 | AL10: =SUMIFS('KPI trừ'!D:D,'KPI trừ'!A:A,B10,'KPI trừ'!B:B,C10) -> 0 | AM10: =SUMIFS('KPI trừ'!E:E,'KPI trừ'!A:A,B10,'KPI trừ'!B:B,C10) -> 0 | AN10: =SUMIFS('KPI trừ'!F:F,'KPI trừ'!A:A,B10,'KPI trừ'!B:B,C10) -> 0 | AO10: =SUMIFS('KPI trừ'!G:G,'KPI trừ'!A:A,B10,'KPI trừ'!B:B,C10) -> 0 | AP10: =IFERROR(__xludf.DUMMYFUNCTION("IFERROR(TEXTJOIN("" "", TRUE, FILTER('KPI trừ'!H:H, ('KPI trừ'!A:A=B10) * ('KPI trừ'!B:B=C10))), """")"),"") | AQ10: =IFERROR(__xludf.DUMMYFUNCTION("IFERROR( MAX( QUERY( FILTER( {'Ngày công'!$C$2:$C$5000,'Ngày công'!$F$2:$F$5000}, TRIM('Ngày công'!$B$2:$B$5000)=TRIM($C10) ), ""select sum(Col2) where Col1 is not null group by Col1 label sum(Col2) ''"", 0 ) ), 0 )"),8.08333333333333) -> 8.0833333
A11: #NAME? | B11: Đỗ Quang Đẩu | C11: Hoàng Thanh Thủy | D11: DSBC | E11: =G11+I11+L11+O11+S11+T11 -> #NAME? | F11: =H11+P11 -> 0.6 | G11: =SUMIFS('Giờ công'!I:I,'Giờ công'!G:G,B11,'Giờ công'!H:H,C11) -> 244.6 | H11: =SUMIFS('Giờ công'!J:J,'Giờ công'!G:G,B11,'Giờ công'!H:H,C11) -> 0.6 | I11: =_xludf.ifs(R11>=30,16,R11=29,8,TRUE,"") -> #NAME? | J11: 30 | K11: 0 | N11: =SUMIFS('Tăng ca lễ'!M:M,'Tăng ca lễ'!K:K,B11,'Tăng ca lễ'!L:L,C11) -> 0 | O11: =IF(OR(D11 = "PT",D11 = "DSHV"), SUMIFS('Tăng ca lễ'!O:O,'Tăng ca lễ'!K:K,B11,'Tăng ca lễ'!L:L,C11)*2, SUMIFS('Tăng ca lễ'!O:O,'Tăng ca lễ'!K:K,B11,'Tăng ca lễ'!L:L,C11)*3) -> 0 | P11: =IF(OR(D11 = "PT", D11 = "DSHV"), SUMIFS('Tăng ca lễ'!P:P,'Tăng ca lễ'!K:K,B11,'Tăng ca lễ'!L:L,C11)*2, SUMIFS('Tăng ca lễ'!P:P,'Tăng ca lễ'!K:K,B11,'Tăng ca lễ'!L:L,C11)*3) -> 0 | R11: =SUMIFS('Ngày công'!M:M,'Ngày công'!K:K,B11,'Ngày công'!L:L,C11) -> 30 | S11: =SUMIFS('Công Đào tạo'!G:G,'Công Đào tạo'!E:E,B11,'Công Đào tạo'!F:F,C11) -> 0 | T11: 0 | X11: =IFERROR(__xludf.DUMMYFUNCTION("IF($C11="""","""", IF( TRIM($D11)=""DSCD"", MIN( 1500000, ROUND(1500000/28*MIN(N($J11),28),0) ), IF( AND( REGEXMATCH(TRIM($D11),""^(DSXC|DSBC|CHT|DSTV)$""), N($H11)>=160 ), MIN( 1500000, ROUND(1500000/28*MIN(N($K11)"&",28),0) ), 0 ) ) )"),0) -> 0 | AA11: {=IF($C11="","", IFERROR( _xludf.LET( cnChinh, _xlfn.XLOOKUP( TRIM($C11), TRIM(KPI!$B$2:$B1043), KPI!$A$2:$A1043, "" ), IF( TRIM($B11)=TRIM(cnChinh), _xlfn.XLOOKUP( TRIM($C11), TRIM('MiniKat - HCM'!$A$2:$A1043), 'MiniKat - HCM'!$J$2:$J1043, "" ), "" ) ), "" ) )} | AC11: {=IFERROR(_xlfn.XLOOKUP(C11, whatsapp!A:A,whatsapp!D:D), " ")} -> 3664228 | AD11: {=IF($C11="","", IFERROR( _xludf.LET( cnChinh, _xlfn.XLOOKUP( TRIM($C11), TRIM(KPI!$B$2:$B1043), KPI!$A$2:$A1043, "" ), IF( TRIM($B11)=TRIM(cnChinh), _xlfn.XLOOKUP( TRIM($C11), TRIM('Dự án'!$B$2:$B1043), 'Dự án'!$C$2:$C1043, "" ), "" ) ), "" ) )} | AE11: =SUMIFS(KPI!C:C,KPI!A:A,B11,KPI!B:B,C11) -> 0 | AF11: =SUMIFS('Thưởng CK'!C:C,'Thưởng CK'!A:A,B11,'Thưởng CK'!B:B,C11) -> 1292850 | AG11: =SUMIFS('Cận date'!C:C,'Cận date'!A:A,B11,'Cận date'!B:B,C11) -> 141680 | AH11: =SUMIFS(Map!D:D,Map!B:B,B11,Map!A:A,C11) -> 0 | AI11: 1572430 | AJ11: =SUM(AK11:AO11) -> 100000 | AK11: =SUMIFS('KPI trừ'!C:C,'KPI trừ'!A:A,B11,'KPI trừ'!B:B,C11) -> 0 | AL11: =SUMIFS('KPI trừ'!D:D,'KPI trừ'!A:A,B11,'KPI trừ'!B:B,C11) -> 0 | AM11: =SUMIFS('KPI trừ'!E:E,'KPI trừ'!A:A,B11,'KPI trừ'!B:B,C11) -> 100000 | AN11: =SUMIFS('KPI trừ'!F:F,'KPI trừ'!A:A,B11,'KPI trừ'!B:B,C11) -> 0 | AO11: =SUMIFS('KPI trừ'!G:G,'KPI trừ'!A:A,B11,'KPI trừ'!B:B,C11) -> 0 | AP11: =IFERROR(__xludf.DUMMYFUNCTION("IFERROR(TEXTJOIN("" "", TRUE, FILTER('KPI trừ'!H:H, ('KPI trừ'!A:A=B11) * ('KPI trừ'!B:B=C11))), """")"),"Sai kênh bán HD1155007 : 100.000đ ") -> Sai kênh bán HD1155007 : 100.000đ | AQ11: =IFERROR(__xludf.DUMMYFUNCTION("IFERROR( MAX( QUERY( FILTER( {'Ngày công'!$C$2:$C$5000,'Ngày công'!$F$2:$F$5000}, TRIM('Ngày công'!$B$2:$B$5000)=TRIM($C11) ), ""select sum(Col2) where Col1 is not null group by Col1 label sum(Col2) ''"", 0 ) ), 0 )"),8.81666666666666) -> 8.8166667
A12: #NAME? | B12: Đỗ Quang Đẩu | C12: Lê Thị Huyền Trân | D12: DSBC | E12: =G12+I12+L12+O12+S12+T12 -> #NAME? | F12: =H12+P12 -> 8.0833333 | G12: =SUMIFS('Giờ công'!I:I,'Giờ công'!G:G,B12,'Giờ công'!H:H,C12) -> 232.83333 | H12: =SUMIFS('Giờ công'!J:J,'Giờ công'!G:G,B12,'Giờ công'!H:H,C12) -> 8.0833333 | I12: =_xludf.ifs(R12>=30,16,R12=29,8,TRUE,"") -> #NAME? | J12: 30 | K12: 1 | N12: =SUMIFS('Tăng ca lễ'!M:M,'Tăng ca lễ'!K:K,B12,'Tăng ca lễ'!L:L,C12) -> 0 | O12: =IF(OR(D12 = "PT",D12 = "DSHV"), SUMIFS('Tăng ca lễ'!O:O,'Tăng ca lễ'!K:K,B12,'Tăng ca lễ'!L:L,C12)*2, SUMIFS('Tăng ca lễ'!O:O,'Tăng ca lễ'!K:K,B12,'Tăng ca lễ'!L:L,C12)*3) -> 0 | P12: =IF(OR(D12 = "PT", D12 = "DSHV"), SUMIFS('Tăng ca lễ'!P:P,'Tăng ca lễ'!K:K,B12,'Tăng ca lễ'!L:L,C12)*2, SUMIFS('Tăng ca lễ'!P:P,'Tăng ca lễ'!K:K,B12,'Tăng ca lễ'!L:L,C12)*3) -> 0 | R12: =SUMIFS('Ngày công'!M:M,'Ngày công'!K:K,B12,'Ngày công'!L:L,C12) -> 30 | S12: =SUMIFS('Công Đào tạo'!G:G,'Công Đào tạo'!E:E,B12,'Công Đào tạo'!F:F,C12) -> 0 | T12: 0 | X12: =IFERROR(__xludf.DUMMYFUNCTION("IF($C12="""","""", IF( TRIM($D12)=""DSCD"", MIN( 1500000, ROUND(1500000/28*MIN(N($J12),28),0) ), IF( AND( REGEXMATCH(TRIM($D12),""^(DSXC|DSBC|CHT|DSTV)$""), N($H12)>=160 ), MIN( 1500000, ROUND(1500000/28*MIN(N($K12)"&",28),0) ), 0 ) ) )"),0) -> 0 | AA12: {=IF($C12="","", IFERROR( _xludf.LET( cnChinh, _xlfn.XLOOKUP( TRIM($C12), TRIM(KPI!$B$2:$B1043), KPI!$A$2:$A1043, "" ), IF( TRIM($B12)=TRIM(cnChinh), _xlfn.XLOOKUP( TRIM($C12), TRIM('MiniKat - HCM'!$A$2:$A1043), 'MiniKat - HCM'!$J$2:$J1043, "" ), "" ) ), "" ) )} | AC12: {=IFERROR(_xlfn.XLOOKUP(C12, whatsapp!A:A,whatsapp!D:D), " ")} -> 2317896 | AD12: {=IF($C12="","", IFERROR( _xludf.LET( cnChinh, _xlfn.XLOOKUP( TRIM($C12), TRIM(KPI!$B$2:$B1043), KPI!$A$2:$A1043, "" ), IF( TRIM($B12)=TRIM(cnChinh), _xlfn.XLOOKUP( TRIM($C12), TRIM('Dự án'!$B$2:$B1043), 'Dự án'!$C$2:$C1043, "" ), "" ) ), "" ) )} | AE12: =SUMIFS(KPI!C:C,KPI!A:A,B12,KPI!B:B,C12) -> 0 | AF12: =SUMIFS('Thưởng CK'!C:C,'Thưởng CK'!A:A,B12,'Thưởng CK'!B:B,C12) -> 1022400 | AG12: =SUMIFS('Cận date'!C:C,'Cận date'!A:A,B12,'Cận date'!B:B,C12) -> 43495 | AH12: =SUMIFS(Map!D:D,Map!B:B,B12,Map!A:A,C12) -> 0 | AI12: 1119186 | AJ12: =SUM(AK12:AO12) -> 0 | AK12: =SUMIFS('KPI trừ'!C:C,'KPI trừ'!A:A,B12,'KPI trừ'!B:B,C12) -> 0 | AL12: =SUMIFS('KPI trừ'!D:D,'KPI trừ'!A:A,B12,'KPI trừ'!B:B,C12) -> 0 | AM12: =SUMIFS('KPI trừ'!E:E,'KPI trừ'!A:A,B12,'KPI trừ'!B:B,C12) -> 0 | AN12: =SUMIFS('KPI trừ'!F:F,'KPI trừ'!A:A,B12,'KPI trừ'!B:B,C12) -> 0 | AO12: =SUMIFS('KPI trừ'!G:G,'KPI trừ'!A:A,B12,'KPI trừ'!B:B,C12) -> 0 | AP12: =IFERROR(__xludf.DUMMYFUNCTION("IFERROR(TEXTJOIN("" "", TRUE, FILTER('KPI trừ'!H:H, ('KPI trừ'!A:A=B12) * ('KPI trừ'!B:B=C12))), """")"),"") | AQ12: =IFERROR(__xludf.DUMMYFUNCTION("IFERROR( MAX( QUERY( FILTER( {'Ngày công'!$C$2:$C$5000,'Ngày công'!$F$2:$F$5000}, TRIM('Ngày công'!$B$2:$B$5000)=TRIM($C12) ), ""select sum(Col2) where Col1 is not null group by Col1 label sum(Col2) ''"", 0 ) ), 0 )"),8.56666666666666) -> 8.5666667
A13: #NAME? | B13: Đỗ Quang Đẩu | C13: Nguyễn Thị Huyền Trang | D13: DSTV | E13: =G13+I13+L13+O13+S13+T13 -> #NAME? | F13: =H13+P13 -> 0 | G13: =SUMIFS('Giờ công'!I:I,'Giờ công'!G:G,B13,'Giờ công'!H:H,C13) -> 57 | H13: =SUMIFS('Giờ công'!J:J,'Giờ công'!G:G,B13,'Giờ công'!H:H,C13) -> 0 | I13: =_xludf.ifs(R14>=30,16,R14=29,8,TRUE,"") -> #NAME? | J13: 7 | K13: 0 | N13: =SUMIFS('Tăng ca lễ'!M:M,'Tăng ca lễ'!K:K,B13,'Tăng ca lễ'!L:L,C13) -> 0 | O13: =IF(OR(D13 = "PT",D13 = "DSHV"), SUMIFS('Tăng ca lễ'!O:O,'Tăng ca lễ'!K:K,B13,'Tăng ca lễ'!L:L,C13)*2, SUMIFS('Tăng ca lễ'!O:O,'Tăng ca lễ'!K:K,B13,'Tăng ca lễ'!L:L,C13)*3) -> 0 | P13: =IF(OR(D13 = "PT", D13 = "DSHV"), SUMIFS('Tăng ca lễ'!P:P,'Tăng ca lễ'!K:K,B13,'Tăng ca lễ'!L:L,C13)*2, SUMIFS('Tăng ca lễ'!P:P,'Tăng ca lễ'!K:K,B13,'Tăng ca lễ'!L:L,C13)*3) -> 0 | R13: =SUMIFS('Ngày công'!M:M,'Ngày công'!K:K,B13,'Ngày công'!L:L,C13) -> 7 | S13: =SUMIFS('Công Đào tạo'!G:G,'Công Đào tạo'!E:E,B13,'Công Đào tạo'!F:F,C13) -> 0 | T13: 0 | X13: =IFERROR(__xludf.DUMMYFUNCTION("IF($C13="""","""", IF( TRIM($D13)=""DSCD"", MIN( 1500000, ROUND(1500000/28*MIN(N($J13),28),0) ), IF( AND( REGEXMATCH(TRIM($D13),""^(DSXC|DSBC|CHT|DSTV)$""), N($H13)>=160 ), MIN( 1500000, ROUND(1500000/28*MIN(N($K13)"&",28),0) ), 0 ) ) )"),0) -> 0 | AA13: {=IF($C13="","", IFERROR( _xludf.LET( cnChinh, _xlfn.XLOOKUP( TRIM($C13), TRIM(KPI!$B$2:$B1043), KPI!$A$2:$A1043, "" ), IF( TRIM($B13)=TRIM(cnChinh), _xlfn.XLOOKUP( TRIM($C13), TRIM('MiniKat - HCM'!$A$2:$A1043), 'MiniKat - HCM'!$J$2:$J1043, "" ), "" ) ), "" ) )} | AC13: {=IFERROR(_xlfn.XLOOKUP(C13, whatsapp!A:A,whatsapp!D:D), " ")} | AD13: {=IF($C13="","", IFERROR( _xludf.LET( cnChinh, _xlfn.XLOOKUP( TRIM($C13), TRIM(KPI!$B$2:$B1043), KPI!$A$2:$A1043, "" ), IF( TRIM($B13)=TRIM(cnChinh), _xlfn.XLOOKUP( TRIM($C13), TRIM('Dự án'!$B$2:$B1043), 'Dự án'!$C$2:$C1043, "" ), "" ) ), "" ) )} | AE13: =SUMIFS(KPI!C:C,KPI!A:A,B13,KPI!B:B,C13) -> 0 | AF13: =SUMIFS('Thưởng CK'!C:C,'Thưởng CK'!A:A,B13,'Thưởng CK'!B:B,C13) -> 0 | AG13: =SUMIFS('Cận date'!C:C,'Cận date'!A:A,B13,'Cận date'!B:B,C13) -> 0 | AH13: =SUMIFS(Map!D:D,Map!B:B,B13,Map!A:A,C13) -> 0 | AJ13: =SUM(AK13:AO13) -> 0 | AK13: =SUMIFS('KPI trừ'!C:C,'KPI trừ'!A:A,B13,'KPI trừ'!B:B,C13) -> 0 | AL13: =SUMIFS('KPI trừ'!D:D,'KPI trừ'!A:A,B13,'KPI trừ'!B:B,C13) -> 0 | AM13: =SUMIFS('KPI trừ'!E:E,'KPI trừ'!A:A,B13,'KPI trừ'!B:B,C13) -> 0 | AN13: =SUMIFS('KPI trừ'!F:F,'KPI trừ'!A:A,B13,'KPI trừ'!B:B,C13) -> 0 | AO13: =SUMIFS('KPI trừ'!G:G,'KPI trừ'!A:A,B13,'KPI trừ'!B:B,C13) -> 0 | AP13: =IFERROR(__xludf.DUMMYFUNCTION("IFERROR(TEXTJOIN("" "", TRUE, FILTER('KPI trừ'!H:H, ('KPI trừ'!A:A=B13) * ('KPI trừ'!B:B=C13))), """")"),"") | AQ13: =IFERROR(__xludf.DUMMYFUNCTION("IFERROR( MAX( QUERY( FILTER( {'Ngày công'!$C$2:$C$5000,'Ngày công'!$F$2:$F$5000}, TRIM('Ngày công'!$B$2:$B$5000)=TRIM($C13) ), ""select sum(Col2) where Col1 is not null group by Col1 label sum(Col2) ''"", 0 ) ), 0 )"),16) -> 16
A14: #NAME? | B14: Đỗ Quang Đẩu | C14: Ngô Thị Ngọc Thủy | D14: DSTV | E14: =G14+I13+L14+O14+S14+T14 -> #NAME? | F14: =H14+P14 -> 0 | G14: =SUMIFS('Giờ công'!I:I,'Giờ công'!G:G,B14,'Giờ công'!H:H,C14) -> 64.616667 | H14: =SUMIFS('Giờ công'!J:J,'Giờ công'!G:G,B14,'Giờ công'!H:H,C14) -> 0 | J14: 8 | K14: 0 | N14: =SUMIFS('Tăng ca lễ'!M:M,'Tăng ca lễ'!K:K,B14,'Tăng ca lễ'!L:L,C14) -> 0 | O14: =IF(OR(D14 = "PT",D14 = "DSHV"), SUMIFS('Tăng ca lễ'!O:O,'Tăng ca lễ'!K:K,B14,'Tăng ca lễ'!L:L,C14)*2, SUMIFS('Tăng ca lễ'!O:O,'Tăng ca lễ'!K:K,B14,'Tăng ca lễ'!L:L,C14)*3) -> 0 | P14: =IF(OR(D14 = "PT", D14 = "DSHV"), SUMIFS('Tăng ca lễ'!P:P,'Tăng ca lễ'!K:K,B14,'Tăng ca lễ'!L:L,C14)*2, SUMIFS('Tăng ca lễ'!P:P,'Tăng ca lễ'!K:K,B14,'Tăng ca lễ'!L:L,C14)*3) -> 0 | R14: =SUMIFS('Ngày công'!M:M,'Ngày công'!K:K,B14,'Ngày công'!L:L,C14) -> 8 | S14: =SUMIFS('Công Đào tạo'!G:G,'Công Đào tạo'!E:E,B14,'Công Đào tạo'!F:F,C14) -> 0 | T14: 0 | X14: =IFERROR(__xludf.DUMMYFUNCTION("IF($C14="""","""", IF( TRIM($D14)=""DSCD"", MIN( 1500000, ROUND(1500000/28*MIN(N($J14),28),0) ), IF( AND( REGEXMATCH(TRIM($D14),""^(DSXC|DSBC|CHT|DSTV)$""), N($H14)>=160 ), MIN( 1500000, ROUND(1500000/28*MIN(N($K14)"&",28),0) ), 0 ) ) )"),0) -> 0 | AA14: {=IF($C14="","", IFERROR( _xludf.LET( cnChinh, _xlfn.XLOOKUP( TRIM($C14), TRIM(KPI!$B$2:$B1043), KPI!$A$2:$A1043, "" ), IF( TRIM($B14)=TRIM(cnChinh), _xlfn.XLOOKUP( TRIM($C14), TRIM('MiniKat - HCM'!$A$2:$A1043), 'MiniKat - HCM'!$J$2:$J1043, "" ), "" ) ), "" ) )} | AC14: {=IFERROR(_xlfn.XLOOKUP(C14, whatsapp!A:A,whatsapp!D:D), " ")} | AD14: {=IF($C14="","", IFERROR( _xludf.LET( cnChinh, _xlfn.XLOOKUP( TRIM($C14), TRIM(KPI!$B$2:$B1043), KPI!$A$2:$A1043, "" ), IF( TRIM($B14)=TRIM(cnChinh), _xlfn.XLOOKUP( TRIM($C14), TRIM('Dự án'!$B$2:$B1043), 'Dự án'!$C$2:$C1043, "" ), "" ) ), "" ) )} | AE14: =SUMIFS(KPI!C:C,KPI!A:A,B14,KPI!B:B,C14) -> 0 | AF14: =SUMIFS('Thưởng CK'!C:C,'Thưởng CK'!A:A,B14,'Thưởng CK'!B:B,C14) -> 0 | AG14: =SUMIFS('Cận date'!C:C,'Cận date'!A:A,B14,'Cận date'!B:B,C14) -> 0 | AH14: =SUMIFS(Map!D:D,Map!B:B,B14,Map!A:A,C14) -> 0 | AJ14: =SUM(AK14:AO14) -> 0 | AK14: =SUMIFS('KPI trừ'!C:C,'KPI trừ'!A:A,B14,'KPI trừ'!B:B,C14) -> 0 | AL14: =SUMIFS('KPI trừ'!D:D,'KPI trừ'!A:A,B14,'KPI trừ'!B:B,C14) -> 0 | AM14: =SUMIFS('KPI trừ'!E:E,'KPI trừ'!A:A,B14,'KPI trừ'!B:B,C14) -> 0 | AN14: =SUMIFS('KPI trừ'!F:F,'KPI trừ'!A:A,B14,'KPI trừ'!B:B,C14) -> 0 | AO14: =SUMIFS('KPI trừ'!G:G,'KPI trừ'!A:A,B14,'KPI trừ'!B:B,C14) -> 0 | AP14: =IFERROR(__xludf.DUMMYFUNCTION("IFERROR(TEXTJOIN("" "", TRUE, FILTER('KPI trừ'!H:H, ('KPI trừ'!A:A=B14) * ('KPI trừ'!B:B=C14))), """")"),"") | AQ14: =IFERROR(__xludf.DUMMYFUNCTION("IFERROR( MAX( QUERY( FILTER( {'Ngày công'!$C$2:$C$5000,'Ngày công'!$F$2:$F$5000}, TRIM('Ngày công'!$B$2:$B$5000)=TRIM($C14) ), ""select sum(Col2) where Col1 is not null group by Col1 label sum(Col2) ''"", 0 ) ), 0 )"),11.5833333333333) -> 11.583333
A15: #NAME? | B15: Đỗ Quang Đẩu | C15: Ngô Thị Thanh Thắm | D15: CHT | E15: =G15+I15+L15+O15+S15+T15 -> #NAME? | F15: =H15+P15 -> 0 | G15: =SUMIFS('Giờ công'!I:I,'Giờ công'!G:G,B15,'Giờ công'!H:H,C15) -> 201.31667 | H15: =SUMIFS('Giờ công'!J:J,'Giờ công'!G:G,B15,'Giờ công'!H:H,C15) -> 0 | I15: =_xludf.ifs(R15>=30,16,R15=29,8,TRUE,"") -> #NAME? | J15: 25 | K15: 0 | N15: =SUMIFS('Tăng ca lễ'!M:M,'Tăng ca lễ'!K:K,B15,'Tăng ca lễ'!L:L,C15) -> 0 | O15: =IF(OR(D15 = "PT",D15 = "DSHV"), SUMIFS('Tăng ca lễ'!O:O,'Tăng ca lễ'!K:K,B15,'Tăng ca lễ'!L:L,C15)*2, SUMIFS('Tăng ca lễ'!O:O,'Tăng ca lễ'!K:K,B15,'Tăng ca lễ'!L:L,C15)*3) -> 0 | P15: =IF(OR(D15 = "PT", D15 = "DSHV"), SUMIFS('Tăng ca lễ'!P:P,'Tăng ca lễ'!K:K,B15,'Tăng ca lễ'!L:L,C15)*2, SUMIFS('Tăng ca lễ'!P:P,'Tăng ca lễ'!K:K,B15,'Tăng ca lễ'!L:L,C15)*3) -> 0 | R15: =SUMIFS('Ngày công'!M:M,'Ngày công'!K:K,B15,'Ngày công'!L:L,C15) -> 25 | S15: =SUMIFS('Công Đào tạo'!G:G,'Công Đào tạo'!E:E,B15,'Công Đào tạo'!F:F,C15) -> 0 | T15: 0 | V15: =2000000*0.75 -> 1500000 | X15: =IFERROR(__xludf.DUMMYFUNCTION("IF($C15="""","""", IF( TRIM($D15)=""DSCD"", MIN( 1500000, ROUND(1500000/28*MIN(N($J15),28),0) ), IF( AND( REGEXMATCH(TRIM($D15),""^(DSXC|DSBC|CHT|DSTV)$""), N($H15)>=160 ), MIN( 1500000, ROUND(1500000/28*MIN(N($K15)"&",28),0) ), 0 ) ) )"),0) -> 0 | AA15: {=IF($C15="","", IFERROR( _xludf.LET( cnChinh, _xlfn.XLOOKUP( TRIM($C15), TRIM(KPI!$B$2:$B1043), KPI!$A$2:$A1043, "" ), IF( TRIM($B15)=TRIM(cnChinh), _xlfn.XLOOKUP( TRIM($C15), TRIM('MiniKat - HCM'!$A$2:$A1043), 'MiniKat - HCM'!$J$2:$J1043, "" ), "" ) ), "" ) )} | AC15: {=IFERROR(_xlfn.XLOOKUP(C15, whatsapp!A:A,whatsapp!D:D), " ")} -> 2673092 | AD15: {=IF($C15="","", IFERROR( _xludf.LET( cnChinh, _xlfn.XLOOKUP( TRIM($C15), TRIM(KPI!$B$2:$B1043), KPI!$A$2:$A1043, "" ), IF( TRIM($B15)=TRIM(cnChinh), _xlfn.XLOOKUP( TRIM($C15), TRIM('Dự án'!$B$2:$B1043), 'Dự án'!$C$2:$C1043, "" ), "" ) ), "" ) )} | AE15: =SUMIFS(KPI!C:C,KPI!A:A,B15,KPI!B:B,C15) -> 0 | AF15: =SUMIFS('Thưởng CK'!C:C,'Thưởng CK'!A:A,B15,'Thưởng CK'!B:B,C15) -> 435350 | AG15: =SUMIFS('Cận date'!C:C,'Cận date'!A:A,B15,'Cận date'!B:B,C15) -> 9545 | AH15: =SUMIFS(Map!D:D,Map!B:B,B15,Map!A:A,C15) -> 0 | AI15: 2893430 | AJ15: =SUM(AK15:AO15) -> 0 | AK15: =SUMIFS('KPI trừ'!C:C,'KPI trừ'!A:A,B15,'KPI trừ'!B:B,C15) -> 0 | AL15: =SUMIFS('KPI trừ'!D:D,'KPI trừ'!A:A,B15,'KPI trừ'!B:B,C15) -> 0 | AM15: =SUMIFS('KPI trừ'!E:E,'KPI trừ'!A:A,B15,'KPI trừ'!B:B,C15) -> 0 | AN15: =SUMIFS('KPI trừ'!F:F,'KPI trừ'!A:A,B15,'KPI trừ'!B:B,C15) -> 0 | AO15: =SUMIFS('KPI trừ'!G:G,'KPI trừ'!A:A,B15,'KPI trừ'!B:B,C15) -> 0 | AP15: =IFERROR(__xludf.DUMMYFUNCTION("IFERROR(TEXTJOIN("" "", TRUE, FILTER('KPI trừ'!H:H, ('KPI trừ'!A:A=B15) * ('KPI trừ'!B:B=C15))), """")"),"") | AQ15: =IFERROR(__xludf.DUMMYFUNCTION("IFERROR( MAX( QUERY( FILTER( {'Ngày công'!$C$2:$C$5000,'Ngày công'!$F$2:$F$5000}, TRIM('Ngày công'!$B$2:$B$5000)=TRIM($C15) ), ""select sum(Col2) where Col1 is not null group by Col1 label sum(Col2) ''"", 0 ) ), 0 )"),9.41666666666666) -> 9.4166667
A16: #NAME? | B16: Đỗ Quang Đẩu | C16: Phạm Thị Diên | D16: DSTV | E16: =G16+I16+L16+O16+S16+T16 -> #NAME? | F16: =H16+P16 -> 0 | G16: =SUMIFS('Giờ công'!I:I,'Giờ công'!G:G,B16,'Giờ công'!H:H,C16) -> 16.466667 | H16: =SUMIFS('Giờ công'!J:J,'Giờ công'!G:G,B16,'Giờ công'!H:H,C16) -> 0 | I16: =_xludf.ifs(R16>=30,16,R16=29,8,TRUE,"") -> #NAME? | J16: 2 | K16: 0 | N16: =SUMIFS('Tăng ca lễ'!M:M,'Tăng ca lễ'!K:K,B16,'Tăng ca lễ'!L:L,C16) -> 0 | O16: =IF(OR(D16 = "PT",D16 = "DSHV"), SUMIFS('Tăng ca lễ'!O:O,'Tăng ca lễ'!K:K,B16,'Tăng ca lễ'!L:L,C16)*2, SUMIFS('Tăng ca lễ'!O:O,'Tăng ca lễ'!K:K,B16,'Tăng ca lễ'!L:L,C16)*3) -> 0 | P16: =IF(OR(D16 = "PT", D16 = "DSHV"), SUMIFS('Tăng ca lễ'!P:P,'Tăng ca lễ'!K:K,B16,'Tăng ca lễ'!L:L,C16)*2, SUMIFS('Tăng ca lễ'!P:P,'Tăng ca lễ'!K:K,B16,'Tăng ca lễ'!L:L,C16)*3) -> 0 | R16: =SUMIFS('Ngày công'!M:M,'Ngày công'!K:K,B16,'Ngày công'!L:L,C16) -> 2 | S16: =SUMIFS('Công Đào tạo'!G:G,'Công Đào tạo'!E:E,B16,'Công Đào tạo'!F:F,C16) -> 0 | T16: 0 | X16: =IFERROR(__xludf.DUMMYFUNCTION("IF($C16="""","""", IF( TRIM($D16)=""DSCD"", MIN( 1500000, ROUND(1500000/28*MIN(N($J16),28),0) ), IF( AND( REGEXMATCH(TRIM($D16),""^(DSXC|DSBC|CHT|DSTV)$""), N($H16)>=160 ), MIN( 1500000, ROUND(1500000/28*MIN(N($K16)"&",28),0) ), 0 ) ) )"),0) -> 0 | AA16: {=IF($C16="","", IFERROR( _xludf.LET( cnChinh, _xlfn.XLOOKUP( TRIM($C16), TRIM(KPI!$B$2:$B1043), KPI!$A$2:$A1043, "" ), IF( TRIM($B16)=TRIM(cnChinh), _xlfn.XLOOKUP( TRIM($C16), TRIM('MiniKat - HCM'!$A$2:$A1043), 'MiniKat - HCM'!$J$2:$J1043, "" ), "" ) ), "" ) )} | AC16: {=IFERROR(_xlfn.XLOOKUP(C16, whatsapp!A:A,whatsapp!D:D), " ")} | AD16: {=IF($C16="","", IFERROR( _xludf.LET( cnChinh, _xlfn.XLOOKUP( TRIM($C16), TRIM(KPI!$B$2:$B1043), KPI!$A$2:$A1043, "" ), IF( TRIM($B16)=TRIM(cnChinh), _xlfn.XLOOKUP( TRIM($C16), TRIM('Dự án'!$B$2:$B1043), 'Dự án'!$C$2:$C1043, "" ), "" ) ), "" ) )} | AE16: =SUMIFS(KPI!C:C,KPI!A:A,B16,KPI!B:B,C16) -> 0 | AF16: =SUMIFS('Thưởng CK'!C:C,'Thưởng CK'!A:A,B16,'Thưởng CK'!B:B,C16) -> 0 | AG16: =SUMIFS('Cận date'!C:C,'Cận date'!A:A,B16,'Cận date'!B:B,C16) -> 0 | AH16: =SUMIFS(Map!D:D,Map!B:B,B16,Map!A:A,C16) -> 0 | AJ16: =SUM(AK16:AO16) -> 0 | AK16: =SUMIFS('KPI trừ'!C:C,'KPI trừ'!A:A,B16,'KPI trừ'!B:B,C16) -> 0 | AL16: =SUMIFS('KPI trừ'!D:D,'KPI trừ'!A:A,B16,'KPI trừ'!B:B,C16) -> 0 | AM16: =SUMIFS('KPI trừ'!E:E,'KPI trừ'!A:A,B16,'KPI trừ'!B:B,C16) -> 0 | AN16: =SUMIFS('KPI trừ'!F:F,'KPI trừ'!A:A,B16,'KPI trừ'!B:B,C16) -> 0 | AO16: =SUMIFS('KPI trừ'!G:G,'KPI trừ'!A:A,B16,'KPI trừ'!B:B,C16) -> 0 | AP16: =IFERROR(__xludf.DUMMYFUNCTION("IFERROR(TEXTJOIN("" "", TRUE, FILTER('KPI trừ'!H:H, ('KPI trừ'!A:A=B16) * ('KPI trừ'!B:B=C16))), """")"),"") | AQ16: =IFERROR(__xludf.DUMMYFUNCTION("IFERROR( MAX( QUERY( FILTER( {'Ngày công'!$C$2:$C$5000,'Ngày công'!$F$2:$F$5000}, TRIM('Ngày công'!$B$2:$B$5000)=TRIM($C16) ), ""select sum(Col2) where Col1 is not null group by Col1 label sum(Col2) ''"", 0 ) ), 0 )"),8.43333333333333) -> 8.4333333
A17: #NAME? | B17: Đỗ Quang Đẩu | C17: Phạm Thị Nghĩa Hương | D17: DSCD | E17: =G17+I17+L17+O17+S17+T17 -> #NAME? | F17: =H17+P17 -> 237.83333 | G17: =SUMIFS('Giờ công'!I:I,'Giờ công'!G:G,B17,'Giờ công'!H:H,C17) -> 0 | H17: =SUMIFS('Giờ công'!J:J,'Giờ công'!G:G,B17,'Giờ công'!H:H,C17) -> 237.83333 | I17: =_xludf.ifs(R17>=30,16,R17=29,8,TRUE,"") -> #NAME? | J17: 30 | K17: 30 | N17: =SUMIFS('Tăng ca lễ'!M:M,'Tăng ca lễ'!K:K,B17,'Tăng ca lễ'!L:L,C17) -> 0 | O17: =IF(OR(D17 = "PT",D17 = "DSHV"), SUMIFS('Tăng ca lễ'!O:O,'Tăng ca lễ'!K:K,B17,'Tăng ca lễ'!L:L,C17)*2, SUMIFS('Tăng ca lễ'!O:O,'Tăng ca lễ'!K:K,B17,'Tăng ca lễ'!L:L,C17)*3) -> 0 | P17: =IF(OR(D17 = "PT", D17 = "DSHV"), SUMIFS('Tăng ca lễ'!P:P,'Tăng ca lễ'!K:K,B17,'Tăng ca lễ'!L:L,C17)*2, SUMIFS('Tăng ca lễ'!P:P,'Tăng ca lễ'!K:K,B17,'Tăng ca lễ'!L:L,C17)*3) -> 0 | R17: =SUMIFS('Ngày công'!M:M,'Ngày công'!K:K,B17,'Ngày công'!L:L,C17) -> 30 | S17: =SUMIFS('Công Đào tạo'!G:G,'Công Đào tạo'!E:E,B17,'Công Đào tạo'!F:F,C17) -> 0 | T17: 0 | X17: =IFERROR(__xludf.DUMMYFUNCTION("IF($C17="""","""", IF( TRIM($D17)=""DSCD"", MIN( 1500000, ROUND(1500000/28*MIN(N($J17),28),0) ), IF( AND( REGEXMATCH(TRIM($D17),""^(DSXC|DSBC|CHT|DSTV)$""), N($H17)>=160 ), MIN( 1500000, ROUND(1500000/28*MIN(N($K17)"&",28),0) ), 0 ) ) )"),1500000) -> 1500000 | AA17: {=IF($C17="","", IFERROR( _xludf.LET( cnChinh, _xlfn.XLOOKUP( TRIM($C17), TRIM(KPI!$B$2:$B1043), KPI!$A$2:$A1043, "" ), IF( TRIM($B17)=TRIM(cnChinh), _xlfn.XLOOKUP( TRIM($C17), TRIM('MiniKat - HCM'!$A$2:$A1043), 'MiniKat - HCM'!$J$2:$J1043, "" ), "" ) ), "" ) )} | AC17: {=IFERROR(_xlfn.XLOOKUP(C17, whatsapp!A:A,whatsapp!D:D), " ")} -> 333844 | AD17: {=IF($C17="","", IFERROR( _xludf.LET( cnChinh, _xlfn.XLOOKUP( TRIM($C17), TRIM(KPI!$B$2:$B1043), KPI!$A$2:$A1043, "" ), IF( TRIM($B17)=TRIM(cnChinh), _xlfn.XLOOKUP( TRIM($C17), TRIM('Dự án'!$B$2:$B1043), 'Dự án'!$C$2:$C1043, "" ), "" ) ), "" ) )} | AE17: =SUMIFS(KPI!C:C,KPI!A:A,B17,KPI!B:B,C17) -> 0 | AF17: =SUMIFS('Thưởng CK'!C:C,'Thưởng CK'!A:A,B17,'Thưởng CK'!B:B,C17) -> 509500 | AG17: =SUMIFS('Cận date'!C:C,'Cận date'!A:A,B17,'Cận date'!B:B,C17) -> 7535 | AH17: =SUMIFS(Map!D:D,Map!B:B,B17,Map!A:A,C17) -> 0 | AI17: =29*10000 -> 290000 | AJ17: =SUM(AK17:AO17) -> 0 | AK17: =SUMIFS('KPI trừ'!C:C,'KPI trừ'!A:A,B17,'KPI trừ'!B:B,C17) -> 0 | AL17: =SUMIFS('KPI trừ'!D:D,'KPI trừ'!A:A,B17,'KPI trừ'!B:B,C17) -> 0 | AM17: =SUMIFS('KPI trừ'!E:E,'KPI trừ'!A:A,B17,'KPI trừ'!B:B,C17) -> 0 | AN17: =SUMIFS('KPI trừ'!F:F,'KPI trừ'!A:A,B17,'KPI trừ'!B:B,C17) -> 0 | AO17: =SUMIFS('KPI trừ'!G:G,'KPI trừ'!A:A,B17,'KPI trừ'!B:B,C17) -> 0 | AP17: =IFERROR(__xludf.DUMMYFUNCTION("IFERROR(TEXTJOIN("" "", TRUE, FILTER('KPI trừ'!H:H, ('KPI trừ'!A:A=B17) * ('KPI trừ'!B:B=C17))), """")"),"") | AQ17: =IFERROR(__xludf.DUMMYFUNCTION("IFERROR( MAX( QUERY( FILTER( {'Ngày công'!$C$2:$C$5000,'Ngày công'!$F$2:$F$5000}, TRIM('Ngày công'!$B$2:$B$5000)=TRIM($C17) ), ""select sum(Col2) where Col1 is not null group by Col1 label sum(Col2) ''"", 0 ) ), 0 )"),8.11666666666666) -> 8.1166667
A18: #NAME? | B18: Đỗ Quang Đẩu | C18: Trần Thiên Phát | D18: DSCD | E18: =G18+I18+L18+O18+S18+T18 -> #NAME? | F18: =H18+P18 -> 230.66667 | G18: =SUMIFS('Giờ công'!I:I,'Giờ công'!G:G,B18,'Giờ công'!H:H,C18) -> 0 | H18: =SUMIFS('Giờ công'!J:J,'Giờ công'!G:G,B18,'Giờ công'!H:H,C18) -> 230.66667 | I18: =_xludf.ifs(R18>=30,16,R18=29,8,TRUE,"") -> #NAME? | J18: 30 | K18: 30 | N18: =SUMIFS('Tăng ca lễ'!M:M,'Tăng ca lễ'!K:K,B18,'Tăng ca lễ'!L:L,C18) -> 0 | O18: =IF(OR(D18 = "PT",D18 = "DSHV"), SUMIFS('Tăng ca lễ'!O:O,'Tăng ca lễ'!K:K,B18,'Tăng ca lễ'!L:L,C18)*2, SUMIFS('Tăng ca lễ'!O:O,'Tăng ca lễ'!K:K,B18,'Tăng ca lễ'!L:L,C18)*3) -> 0 | P18: =IF(OR(D18 = "PT", D18 = "DSHV"), SUMIFS('Tăng ca lễ'!P:P,'Tăng ca lễ'!K:K,B18,'Tăng ca lễ'!L:L,C18)*2, SUMIFS('Tăng ca lễ'!P:P,'Tăng ca lễ'!K:K,B18,'Tăng ca lễ'!L:L,C18)*3) -> 0 | R18: =SUMIFS('Ngày công'!M:M,'Ngày công'!K:K,B18,'Ngày công'!L:L,C18) -> 30 | S18: =SUMIFS('Công Đào tạo'!G:G,'Công Đào tạo'!E:E,B18,'Công Đào tạo'!F:F,C18) -> 0 | T18: 0 | X18: =IFERROR(__xludf.DUMMYFUNCTION("IF($C18="""","""", IF( TRIM($D18)=""DSCD"", MIN( 1500000, ROUND(1500000/28*MIN(N($J18),28),0) ), IF( AND( REGEXMATCH(TRIM($D18),""^(DSXC|DSBC|CHT|DSTV)$""), N($H18)>=160 ), MIN( 1500000, ROUND(1500000/28*MIN(N($K18)"&",28),0) ), 0 ) ) )"),1500000) -> 1500000 | AA18: {=IF($C18="","", IFERROR( _xludf.LET( cnChinh, _xlfn.XLOOKUP( TRIM($C18), TRIM(KPI!$B$2:$B1043), KPI!$A$2:$A1043, "" ), IF( TRIM($B18)=TRIM(cnChinh), _xlfn.XLOOKUP( TRIM($C18), TRIM('MiniKat - HCM'!$A$2:$A1043), 'MiniKat - HCM'!$J$2:$J1043, "" ), "" ) ), "" ) )} | AC18: {=IFERROR(_xlfn.XLOOKUP(C18, whatsapp!A:A,whatsapp!D:D), " ")} -> 354632 | AD18: {=IF($C18="","", IFERROR( _xludf.LET( cnChinh, _xlfn.XLOOKUP( TRIM($C18), TRIM(KPI!$B$2:$B1043), KPI!$A$2:$A1043, "" ), IF( TRIM($B18)=TRIM(cnChinh), _xlfn.XLOOKUP( TRIM($C18), TRIM('Dự án'!$B$2:$B1043), 'Dự án'!$C$2:$C1043, "" ), "" ) ), "" ) )} | AE18: =SUMIFS(KPI!C:C,KPI!A:A,B18,KPI!B:B,C18) -> 0 | AF18: =SUMIFS('Thưởng CK'!C:C,'Thưởng CK'!A:A,B18,'Thưởng CK'!B:B,C18) -> 579300 | AG18: =SUMIFS('Cận date'!C:C,'Cận date'!A:A,B18,'Cận date'!B:B,C18) -> 5485 | AH18: =SUMIFS(Map!D:D,Map!B:B,B18,Map!A:A,C18) -> 0 | AI18: 114300 | AJ18: =SUM(AK18:AO18) -> 0 | AK18: =SUMIFS('KPI trừ'!C:C,'KPI trừ'!A:A,B18,'KPI trừ'!B:B,C18) -> 0 | AL18: =SUMIFS('KPI trừ'!D:D,'KPI trừ'!A:A,B18,'KPI trừ'!B:B,C18) -> 0 | AM18: =SUMIFS('KPI trừ'!E:E,'KPI trừ'!A:A,B18,'KPI trừ'!B:B,C18) -> 0 | AN18: =SUMIFS('KPI trừ'!F:F,'KPI trừ'!A:A,B18,'KPI trừ'!B:B,C18) -> 0 | AO18: =SUMIFS('KPI trừ'!G:G,'KPI trừ'!A:A,B18,'KPI trừ'!B:B,C18) -> 0 | AP18: =IFERROR(__xludf.DUMMYFUNCTION("IFERROR(TEXTJOIN("" "", TRUE, FILTER('KPI trừ'!H:H, ('KPI trừ'!A:A=B18) * ('KPI trừ'!B:B=C18))), """")"),"") | AQ18: =IFERROR(__xludf.DUMMYFUNCTION("IFERROR( MAX( QUERY( FILTER( {'Ngày công'!$C$2:$C$5000,'Ngày công'!$F$2:$F$5000}, TRIM('Ngày công'!$B$2:$B$5000)=TRIM($C18) ), ""select sum(Col2) where Col1 is not null group by Col1 label sum(Col2) ''"", 0 ) ), 0 )"),8.11666666666666) -> 8.1166667
A19: #NAME? | B19: Đỗ Quang Đẩu | C19: Đinh Hoài Bảo | D19: DSTV | E19: =G19+I19+L19+O19+S19+T19 -> #NAME? | F19: =H19+P19 -> 0 | G19: =SUMIFS('Giờ công'!I:I,'Giờ công'!G:G,B19,'Giờ công'!H:H,C19) -> 73.066667 | H19: =SUMIFS('Giờ công'!J:J,'Giờ công'!G:G,B19,'Giờ công'!H:H,C19) -> 0 | I19: =_xludf.ifs(R19>=30,16,R19=29,8,TRUE,"") -> #NAME? | J19: 9 | K19: 0 | N19: =SUMIFS('Tăng ca lễ'!M:M,'Tăng ca lễ'!K:K,B19,'Tăng ca lễ'!L:L,C19) -> 0 | O19: =IF(OR(D19 = "PT",D19 = "DSHV"), SUMIFS('Tăng ca lễ'!O:O,'Tăng ca lễ'!K:K,B19,'Tăng ca lễ'!L:L,C19)*2, SUMIFS('Tăng ca lễ'!O:O,'Tăng ca lễ'!K:K,B19,'Tăng ca lễ'!L:L,C19)*3) -> 0 | P19: =IF(OR(D19 = "PT", D19 = "DSHV"), SUMIFS('Tăng ca lễ'!P:P,'Tăng ca lễ'!K:K,B19,'Tăng ca lễ'!L:L,C19)*2, SUMIFS('Tăng ca lễ'!P:P,'Tăng ca lễ'!K:K,B19,'Tăng ca lễ'!L:L,C19)*3) -> 0 | R19: =SUMIFS('Ngày công'!M:M,'Ngày công'!K:K,B19,'Ngày công'!L:L,C19) -> 9 | S19: =SUMIFS('Công Đào tạo'!G:G,'Công Đào tạo'!E:E,B19,'Công Đào tạo'!F:F,C19) -> 0 | T19: 0 | X19: =IFERROR(__xludf.DUMMYFUNCTION("IF($C19="""","""", IF( TRIM($D19)=""DSCD"", MIN( 1500000, ROUND(1500000/28*MIN(N($J19),28),0) ), IF( AND( REGEXMATCH(TRIM($D19),""^(DSXC|DSBC|CHT|DSTV)$""), N($H19)>=160 ), MIN( 1500000, ROUND(1500000/28*MIN(N($K19)"&",28),0) ), 0 ) ) )"),0) -> 0 | AA19: {=IF($C19="","", IFERROR( _xludf.LET( cnChinh, _xlfn.XLOOKUP( TRIM($C19), TRIM(KPI!$B$2:$B1043), KPI!$A$2:$A1043, "" ), IF( TRIM($B19)=TRIM(cnChinh), _xlfn.XLOOKUP( TRIM($C19), TRIM('MiniKat - HCM'!$A$2:$A1043), 'MiniKat - HCM'!$J$2:$J1043, "" ), "" ) ), "" ) )} | AC19: {=IFERROR(_xlfn.XLOOKUP(C19, whatsapp!A:A,whatsapp!D:D), " ")} | AD19: {=IF($C19="","", IFERROR( _xludf.LET( cnChinh, _xlfn.XLOOKUP( TRIM($C19), TRIM(KPI!$B$2:$B1043), KPI!$A$2:$A1043, "" ), IF( TRIM($B19)=TRIM(cnChinh), _xlfn.XLOOKUP( TRIM($C19), TRIM('Dự án'!$B$2:$B1043), 'Dự án'!$C$2:$C1043, "" ), "" ) ), "" ) )} | AE19: =SUMIFS(KPI!C:C,KPI!A:A,B19,KPI!B:B,C19) -> 0 | AF19: =SUMIFS('Thưởng CK'!C:C,'Thưởng CK'!A:A,B19,'Thưởng CK'!B:B,C19) -> 0 | AG19: =SUMIFS('Cận date'!C:C,'Cận date'!A:A,B19,'Cận date'!B:B,C19) -> 0 | AH19: =SUMIFS(Map!D:D,Map!B:B,B19,Map!A:A,C19) -> 0 | AI19: =20*5000 -> 100000 | AJ19: =SUM(AK19:AO19) -> 0 | AK19: =SUMIFS('KPI trừ'!C:C,'KPI trừ'!A:A,B19,'KPI trừ'!B:B,C19) -> 0 | AL19: =SUMIFS('KPI trừ'!D:D,'KPI trừ'!A:A,B19,'KPI trừ'!B:B,C19) -> 0 | AM19: =SUMIFS('KPI trừ'!E:E,'KPI trừ'!A:A,B19,'KPI trừ'!B:B,C19) -> 0 | AN19: =SUMIFS('KPI trừ'!F:F,'KPI trừ'!A:A,B19,'KPI trừ'!B:B,C19) -> 0 | AO19: =SUMIFS('KPI trừ'!G:G,'KPI trừ'!A:A,B19,'KPI trừ'!B:B,C19) -> 0 | AP19: =IFERROR(__xludf.DUMMYFUNCTION("IFERROR(TEXTJOIN("" "", TRUE, FILTER('KPI trừ'!H:H, ('KPI trừ'!A:A=B19) * ('KPI trừ'!B:B=C19))), """")"),"") | AQ19: =IFERROR(__xludf.DUMMYFUNCTION("IFERROR( MAX( QUERY( FILTER( {'Ngày công'!$C$2:$C$5000,'Ngày công'!$F$2:$F$5000}, TRIM('Ngày công'!$B$2:$B$5000)=TRIM($C19) ), ""select sum(Col2) where Col1 is not null group by Col1 label sum(Col2) ''"", 0 ) ), 0 )"),12) -> 12
A20: #NAME? | B20: Nam Hòa | C20: Bùi Thị Thanh Thủy | D20: DSTV | E20: =G20+I20+L20+O20+S20+T20 -> #NAME? | F20: =H20+P20 -> 0 | G20: =SUMIFS('Giờ công'!I:I,'Giờ công'!G:G,B20,'Giờ công'!H:H,C20) -> 211.51667 | H20: =SUMIFS('Giờ công'!J:J,'Giờ công'!G:G,B20,'Giờ công'!H:H,C20) -> 0 | I20: =_xludf.ifs(R20>=30,16,R20=29,8,TRUE,"") -> #NAME? | J20: 22 | K20: 0 | N20: =SUMIFS('Tăng ca lễ'!M:M,'Tăng ca lễ'!K:K,B20,'Tăng ca lễ'!L:L,C20) -> 0 | O20: =IF(OR(D20 = "PT",D20 = "DSHV"), SUMIFS('Tăng ca lễ'!O:O,'Tăng ca lễ'!K:K,B20,'Tăng ca lễ'!L:L,C20)*2, SUMIFS('Tăng ca lễ'!O:O,'Tăng ca lễ'!K:K,B20,'Tăng ca lễ'!L:L,C20)*3) -> 0 | P20: =IF(OR(D20 = "PT", D20 = "DSHV"), SUMIFS('Tăng ca lễ'!P:P,'Tăng ca lễ'!K:K,B20,'Tăng ca lễ'!L:L,C20)*2, SUMIFS('Tăng ca lễ'!P:P,'Tăng ca lễ'!K:K,B20,'Tăng ca lễ'!L:L,C20)*3) -> 0 | R20: =SUMIFS('Ngày công'!M:M,'Ngày công'!K:K,B20,'Ngày công'!L:L,C20) -> 22 | S20: =SUMIFS('Công Đào tạo'!G:G,'Công Đào tạo'!E:E,B20,'Công Đào tạo'!F:F,C20) -> 7 | T20: 0 | X20: =IFERROR(__xludf.DUMMYFUNCTION("IF($C20="""","""", IF( TRIM($D20)=""DSCD"", MIN( 1500000, ROUND(1500000/28*MIN(N($J20),28),0) ), IF( AND( REGEXMATCH(TRIM($D20),""^(DSXC|DSBC|CHT|DSTV)$""), N($H20)>=160 ), MIN( 1500000, ROUND(1500000/28*MIN(N($K20)"&",28),0) ), 0 ) ) )"),0) -> 0 | AA20: {=IF($C20="","", IFERROR( _xludf.LET( cnChinh, _xlfn.XLOOKUP( TRIM($C20), TRIM(KPI!$B$2:$B1043), KPI!$A$2:$A1043, "" ), IF( TRIM($B20)=TRIM(cnChinh), _xlfn.XLOOKUP( TRIM($C20), TRIM('MiniKat - HCM'!$A$2:$A1043), 'MiniKat - HCM'!$J$2:$J1043, "" ), "" ) ), "" ) )} | AC20: {=IFERROR(_xlfn.XLOOKUP(C20, whatsapp!A:A,whatsapp!D:D), " ")} | AD20: {=IF($C20="","", IFERROR( _xludf.LET( cnChinh, _xlfn.XLOOKUP( TRIM($C20), TRIM(KPI!$B$2:$B1043), KPI!$A$2:$A1043, "" ), IF( TRIM($B20)=TRIM(cnChinh), _xlfn.XLOOKUP( TRIM($C20), TRIM('Dự án'!$B$2:$B1043), 'Dự án'!$C$2:$C1043, "" ), "" ) ), "" ) )} | AE20: =SUMIFS(KPI!C:C,KPI!A:A,B20,KPI!B:B,C20) -> 0 | AF20: =SUMIFS('Thưởng CK'!C:C,'Thưởng CK'!A:A,B20,'Thưởng CK'!B:B,C20) -> 210200 | AG20: =SUMIFS('Cận date'!C:C,'Cận date'!A:A,B20,'Cận date'!B:B,C20) -> 1037.5 | AH20: =SUMIFS(Map!D:D,Map!B:B,B20,Map!A:A,C20) -> 0 | AJ20: =SUM(AK20:AO20) -> 500000 | AK20: =SUMIFS('KPI trừ'!C:C,'KPI trừ'!A:A,B20,'KPI trừ'!B:B,C20) -> 0 | AL20: =SUMIFS('KPI trừ'!D:D,'KPI trừ'!A:A,B20,'KPI trừ'!B:B,C20) -> 0 | AM20: =SUMIFS('KPI trừ'!E:E,'KPI trừ'!A:A,B20,'KPI trừ'!B:B,C20) -> 0 | AN20: =SUMIFS('KPI trừ'!F:F,'KPI trừ'!A:A,B20,'KPI trừ'!B:B,C20) -> 0 | AO20: =SUMIFS('KPI trừ'!G:G,'KPI trừ'!A:A,B20,'KPI trừ'!B:B,C20) -> 500000 | AP20: =IFERROR(__xludf.DUMMYFUNCTION("IFERROR(TEXTJOIN("" "", TRUE, FILTER('KPI trừ'!H:H, ('KPI trừ'!A:A=B20) * ('KPI trừ'!B:B=C20))), """")"),"Cấn trừ chi phí đồng phục") -> Cấn trừ chi phí đồng phục | AQ20: =IFERROR(__xludf.DUMMYFUNCTION("IFERROR( MAX( QUERY( FILTER( {'Ngày công'!$C$2:$C$5000,'Ngày công'!$F$2:$F$5000}, TRIM('Ngày công'!$B$2:$B$5000)=TRIM($C20) ), ""select sum(Col2) where Col1 is not null group by Col1 label sum(Col2) ''"", 0 ) ), 0 )"),16.0666666666666) -> 16.066667
