Workbook

Sheet Med
D1: 1 | E1: 2 | F1: 3 | G1: 4 | H1: 5 | I1: 6 | J1: 7 | K1: 8 | L1: 9 | M1: 10 | N1: 11 | O1: 12 | P1: 13 | Q1: 14 | R1: 15 | S1: 16 | T1: 17 | U1: 18 | V1: 19 | W1: 20 | X1: 21 | Y1: 22 | Z1: 23 | AA1: 26 | AB1: 27 | AC1: 28 | AD1: 29 | AE1: 30 | AF1: 31 | AG1: 35 | AH1: 36 | AI1: 37 | AL1: 38 | AM1: 39 | AN1: 40 | AO1: 41 | AP1: 42 | AQ1: 43 | AR1: 44 | AS1: 45 | AT1: 46 | AU1: 47 | AV1: 48 | AW1: 49 | AX1: 50 | AY1: 51 | AZ1: 52 | BA1: 53 | BB1: 54 | BC1: 55 | BD1: 56 | BE1: 57 | BF1: 58 | BG1: 59 | BH1: 60 | BI1: 61 | BJ1: 62 | BK1: 63 | BL1: 64 | BM1: 65 | BN1: 66 | BO1: 67 | BP1: 68 | BQ1: 69 | BS1: 70 | BT1: 71 | BU1: 72 | BV1: 73 | BW1: 74 | BX1: 75 | BY1: 76 | BZ1: 77 | CA1: 78 | CB1: 79 | CC1: 80 | CD1: 81 | CE1: 82 | CF1: 83 | CG1: 84 | CH1: 85 | CI1: 86 | CJ1: 87 | CK1: 88 | CL1: 89 | CM1: 90 | CN1: 91 | CO1: 92 | CP1: 93 | CQ1: 94 | CR1: 95 | CS1: 96 | CT1: 97 | CU1: 98 | CV1: 99 | CW1: 100 | CX1: 101 | CY1: 102 | CZ1: 103 | DA1: 104
H2: BẢNG LƯƠNG THÁNG 8
G3: Ngày bắt đầu | H3: 46235 | I3: Ngày kết thúc | J3: 46265 | AG3: 20 | AH3: 21 | AI3: 22 | AL3: 28 | AM3: 29 | AN3: 30 | AO3: 31 | AP3: 32 | AQ3: 33 | AS3: 25 | AT3: 26 | AU3: 27 | BA3: 35 | BB3: 36 | BC3: 37 | BD3: 38 | BE3: 39 | CE3: =#REF! -> #REF!
CE6: =BG13-BQ13-CA13-CD13+CC13 -> #REF! | CF6: =CG6-'TTCK VP '!F118 -> #REF! | CG6: =#REF!+#REF!+#REF! -> #REF! | CH6: Chuyển khoản VP
CF7: =CG7-#REF! -> #REF! | CG7: =#REF! -> #REF! | CH7: Chuyển khoản CNT
BG8: =BG93+BG87+BG81+BG74+BG69+BG60+BG53+BG45+BG36+BG30+BG22 -> 6.3348117e+08 | CM8: 1 | CN8: 4 | CO8: 2024 | CP8: 5 | CQ8: 2026 | DA8: 05/2026 | DB8: 05/2026
D9: 1 | E9: 2 | F9: 3 | G9: 4 | H9: 5 | I9: 6 | J9: 7 | K9: 8 | L9: 9 | M9: 10 | N9: 11 | O9: 12 | P9: 13 | Q9: 14 | R9: 15 | S9: 16 | T9: 17 | U9: 18 | V9: 19 | W9: 20 | X9: 21 | Y9: 22 | Z9: 23 | AA9: 26 | AB9: 27 | AC9: 28 | AD9: 29 | AE9: 30 | AF9: 31 | AG9: 35 | AH9: 36 | AI9: 37 | AL9: 38 | AM9: 39 | AN9: 40 | AO9: 41 | AP9: 42 | AQ9: 43 | AR9: 44 | AS9: 45 | AT9: 46 | AU9: 47 | AV9: 48 | AW9: 49 | AX9: 50 | AY9: 51 | AZ9: 52 | BA9: 53 | BB9: 54 | BC9: 55 | BD9: 56 | BE9: 57 | BF9: 58 | BG9: 59 | BH9: 60 | BI9: 61 | BJ9: 62 | BK9: 63 | BL9: 64 | BM9: 65 | BN9: 66 | BO9: 67 | BP9: 68 | BQ9: 69 | BR9: 70 | BS9: 71 | BT9: 72 | BU9: 73 | BV9: 74 | BW9: 75 | BX9: 76 | BY9: 77 | BZ9: 78 | CA9: 79 | CB9: 80 | CC9: 81 | CD9: 82 | CE9: 83 | CF9: 84 | CG9: 85 | CH9: 86 | CI9: 87 | CJ9: 88 | CK9: 89 | CL9: 90 | CM9: 91 | CN9: 92 | CO9: 93 | CP9: 94 | CQ9: 95 | CR9: 96 | CS9: 97 | CT9: 98 | CU9: 99 | CV9: 100 | CW9: 101 | CX9: 102 | CY9: 103 | CZ9: 104 | DA9: 105 | DB9: 106 | DC9: 107 | DD9: 108 | DE9: 109 | DF9: 110 | DG9: 111
L10: 16 | M10: 3 | N10: 4 | AG10: 20 | AH10: 21 | AI10: 22 | AL10: 28 | AM10: 29 | AN10: 30 | AO10: 31 | AP10: 32 | AQ10: 33 | AS10: 25 | AT10: 26 | AU10: 27 | BA10: 35 | BB10: 36 | BC10: 37 | BD10: 38 | BE10: 39 | BF10: 40
A11: STT | B11: Tháng | C11: Mã NV | D11: Họ tên | E11: Loại Hợp đồng | F11: Bộ phận | G11: Chức vụ | H11: Ngày vào công ty | I11: Số tài khoản | J11: CN Ngân hàng | K11: Ngày công chuẩn | L11: Ngày công thực tế | M11: CNT ca ngày (giờ) | N11: CNT ca đêm (giờ) | O11: Số giờ TC ngày thường | P11: Số giờ TC ngày CN (*2) | Q11: Số giờ TC ngày Lễ, tết (*3) | R11: HT hiệu quả làm việc | S11: Lương cơ bản (đóng BHXH) | T11: Hỗ trợ tiền ăn | U11: Hỗ trợ đồng phục | V11: Hỗ trợ điện thoại, xăng xe | W11: Hỗ trợ tiền gởi xe | X11: Hỗ trợ nhà ở | Y11: Hỗ trợ nuôi con nhỏ | Z11: Hỗ trợ phụ trách dự án/ sáng kiến | AA11: Lương thỏa thuận | AB11: Lương chính thức | AC11: Lương thử việc | AD11: Lương thực tế | AE11: CNT- Lương ca ngày | AF11: CNT- Lương ca đêm | AG11: Phụ cấp trách nhiệm (áp dụng CHT) | AH11: CNT-Phụ cấp cửa hàng mới | AI11: CNT-Phụ cấp sức khỏe ca đêm | AJ11: Phụ cấp lưu động | AK11: Phụ cấp tăng cường vận hành | AL11: CNT- TPhụ cấp quy trình/dự án | AM11: CNT- Tiền hỗ trợ đạt KPI | AN11: CNT- tiền HT hàng điểm + Cắt liều | AO11: CNT- Tiền HT hàng cận date | AP11: CNT- Tiền hỗ trợ chương trình Maps | AQ11: CNT- HT Thưởng khác | AR11: Bổ sung lương tính thiếu tháng trước | AS11: CNT - Thưởng dự án Mini | AT11: Thưởng dự án Mini (Đại diện CHT nhận) | AU11: CNT - Thường Whatsapp | AV11: Hỗ trợ đạt KPI Quý | AW11: HT lễ, tết / thưởng khác | AX11: HT đi CT tỉnh/ gởi xe | AY11: HT sinh nhật | AZ11: HT khấu hao máy tính/ kiêm nhiệm/ hỗ trợ đứng bằng | BA11: CNT trừ hết date | BB11: CNT trừ quy chế, quy trình | BC11: CNT trừ App- Kiot | BD11: CNT trừ Ecom | BE11: CNT Đối soát | BF11: CNT các khoản trừ khác | BG11: Tổng thu nhập thực tế | BH11: BHXH Cty (17.5%) | BI11: BHYT Cty (3%) | BJ11: BHTN CTy 1% | BK11: KPCĐ Cty (2%) | BL11: Cộng Cty 23,5% | BM11: BHXH NV (8%) | BN11: BHYT NV (1,5%) | BO11: BHTN NV (1%) | BP11: ĐP NV (1%) | BQ11: BHXH, BHYT, BHTN của NV (11,5%) | BR11: CNT- Ca đêm miễn thuế | BS11: Tổng miễn giảm thuế TNCN (gởi xe, PC điện thoại, tiền ăn, đồng phục) | BT11: Thu nhập chịu thuế | BU11: Giảm trừ TTNCN Bản thân | BV11: Số người phụ thuộc | BW11: Giảm trừ TTNCN Người PT | BX11: Giảm trừ TTNCN 10.5% BHXH, BHYT, BHTN | BY11: Tổng các khoản giảm trừ | BZ11: Thu nhập tính thuế | CA11: Thuế TNCN phải nộp | CB11: Tổng thực nhận sau khi trừ TTNCN, BHXH | CC11: Trả lại lương Cty tính sai/thiếu | CD11: Trừ tạm ứng/ mượn/ bồi thường/ khác | CE11: Tổng thu nhập còn lại | CF11: CK TM | CG11: CK TK | CH11: T7 | CI11: Email | CK11: Tháng sinh | CL11: Giờ công đào tạo | CM11: Ngày nhận việc | CN11: Tháng nhận việc | CO11: Năm nhận việc | CP11: thâm niên trước tháng 04/2024 đến 01/4/2024 | CQ11: thâm niên cho NV chưa đủ 12 tháng trong CSTN cũ -> hưởng theo CSTN mới | CR11: Thâm niên cho NV vừa theo chính sách cũ vừa theo chính sách mới | CS11: Số năm TN làm tròn xuống theo CS cũ | CT11: Số năm TN làm tròn xuống theo CS mới | CU11: Số năm TN làm tròn xuống NV hưởng CS mới+ cũ | CV11: Lương thâm niên theo chính sách cũ trước tháng 04/2024 | CW11: Lương thâm niên theo chính sách mới từ 01/04/2024 | CX11: Lương thâm niên cho NV vừa theo chính sách mới + cũ | CY11: Lương Thâm niên của NV | CZ11: Lý do cộng trừ của HC-NS | DA11: Lý do cộng trừ của nhà thuốc | DB11: Lý do chung
A12: 1 | B12: =1+A12 -> 2 | C12: 3 | D12: 4 | E12: 5 | F12: 6 | G12: 7 | H12: 8 | I12: 9 | J12: 10 | K12: 11 | L12: 12 | M12: 13 | N12: 14 | O12: 15 | P12: 16 | Q12: 17 | R12: 18 | S12: 19 | T12: 20 | U12: 21 | V12: 22 | W12: 23 | X12: 24 | Y12: 25 | Z12: 26 | AA12: 27 | AB12: 28 | AC12: 29 | AD12: 30 | AE12: 31 | AF12: 32 | AG12: 36 | AH12: 37 | AL12: 38 | AM12: 39 | AN12: 40 | AO12: 41 | AP12: 42 | AQ12: 43 | AR12: 44 | AS12: 44 | AU12: 44 | AV12: 46 | AW12: 47 | AX12: 48 | AY12: 49 | AZ12: 50 | BA12: 51 | BB12: 52 | BC12: 53 | BD12: 54 | BE12: 55 | BF12: 56 | BG12: 57 | BH12: 58 | BI12: 59 | BJ12: 60 | BK12: 61 | BL12: 62 | BM12: 63 | BN12: 64 | BO12: 65 | BP12: 66 | BQ12: 67 | BS12: 68 | BT12: 69 | BU12: 70 | BV12: 71 | BW12: 72 | BX12: 73 | BY12: 74 | BZ12: 75 | CA12: 76 | CB12: 77 | CC12: 78 | CD12: 79 | CE12: 80 | CF12: 81 | CG12: 82 | CH12: 83 | CI12: 84 | CJ12: 85 | CK12: 86 | CL12: 87 | CM12: 88 | CN12: 89 | CO12: 90 | CP12: 91 | CQ12: 92 | CR12: 93 | CS12: 94 | CT12: 95 | CU12: 96 | CV12: 97 | CW12: 98 | CX12: 99 | CY12: 100 | CZ12: 102 | DA12: 103 | DB12: 104 | DC12: 105 | DD12: Nhân sự mới/nghỉ việc
A13: MED SERVICE | K13: =#REF!+#REF!+#REF!+#REF!+#REF! -> #REF! | L13: =#REF!+#REF!+#REF!+#REF!+#REF! -> #REF! | M13: =#REF!+#REF!+#REF!+#REF!+#REF! -> #REF! | N13: =#REF!+#REF!+#REF!+#REF!+#REF! -> #REF! | O13: =#REF!+#REF!+#REF!+#REF!+#REF! -> #REF! | P13: =#REF!+#REF!+#REF!+#REF!+#REF! -> #REF! | Q13: =#REF!+#REF!+#REF!+#REF!+#REF! -> #REF! | R13: =#REF!+#REF!+#REF!+#REF!+#REF! -> #REF! | ... AI13: =#REF!+#REF!+#REF!+#REF!+#REF! -> #REF! | AL13: =#REF!+#REF!+#REF!+#REF!+#REF! -> #REF! | AM13: =#REF!+#REF!+#REF!+#REF!+#REF! -> #REF! | AN13: =#REF!+#REF!+#REF!+#REF!+#REF! -> #REF! | AO13: =#REF!+#REF!+#REF!+#REF!+#REF! -> #REF! | AP13: =#REF!+#REF!+#REF!+#REF!+#REF! -> #REF! | AQ13: =#REF!+#REF!+#REF!+#REF!+#REF! -> #REF! | AR13: =#REF!+#REF!+#REF!+#REF!+#REF! -> #REF! | AS13: =#REF!+#REF!+#REF!+#REF!+#REF! -> #REF! | ... CG13: =#REF!+#REF!+#REF!+#REF!+#REF! -> #REF! | CJ13: =#REF!+#REF!+#REF!+#REF!+#REF! -> #REF! | CK13: =#REF!+#REF!+#REF!+#REF!+#REF! -> #REF! | CL13: =#REF!+#REF!+#REF!+#REF!+#REF! -> #REF! | CM13: =#REF!+#REF!+#REF!+#REF!+#REF! -> #REF! | CN13: =#REF!+#REF!+#REF!+#REF!+#REF! -> #REF! | CO13: =#REF!+#REF!+#REF!+#REF!+#REF! -> #REF! | CP13: =#REF!+#REF!+#REF!+#REF!+#REF! -> #REF! | CQ13: =#REF!+#REF!+#REF!+#REF!+#REF! -> #REF! | ... DC13: =#REF!+#REF!+#REF!+#REF!+#REF! -> #REF!
A14: V. | B14: CHUỖI NHÀ THUỐC | L14: =L22+L30+L36+L53+L60+L69+L74+L81+L87+L93+L45 -> 1315 | M14: =M22+M30+M36+M53+M60+M69+M74+M81+M87+M93+M45 -> 7272.86 | N14: =N22+N30+N36+N53+N60+N69+N74+N81+N87+N93+N45 -> 4565.09 | O14: =O22+O30+O36+O53+O60+O69+O74+O81+O87+O93+O45 -> 264 | P14: =P22+P30+P36+P53+P60+P69+P74+P81+P87+P93+P45 -> 0 | Q14: =Q22+Q30+Q36+Q53+Q60+Q69+Q74+Q81+Q87+Q93+Q45 -> 0 | R14: =R22+R30+R36+R53+R60+R69+R74+R81+R87+R93+R45 -> 0 | S14: =S22+S30+S36+S53+S60+S69+S74+S81+S87+S93+S45 -> 207090000 | ... BQ14: =BQ22+BQ30+BQ36+BQ53+BQ60+BQ69+BQ74+BQ81+BQ87+BQ93+BQ45 -> 21744450 | BS14: =BS22+BS30+BS36+BS53+BS60+BS69+BS74+BS81+BS87+BS93+BS45 -> 19511729 | BT14: =BT22+BT30+BT36+BT53+BT60+BT69+BT74+BT81+BT87+BT93+BT45 -> 3.4176678e+08 | BU14: =BU22+BU30+BU36+BU53+BU60+BU69+BU74+BU81+BU87+BU93+BU45 -> 496000000 | BV14: =BV22+BV30+BV36+BV53+BV60+BV69+BV74+BV81+BV87+BV93+BV45 -> 1 | BW14: =BW22+BW30+BW36+BW53+BW60+BW69+BW74+BW81+BW87+BW93+BW45 -> 6200000 | BX14: =BX22+BX30+BX36+BX53+BX60+BX69+BX74+BX81+BX87+BX93+BX45 -> 18956700 | BY14: =BY22+BY30+BY36+BY53+BY60+BY69+BY74+BY81+BY87+BY93+BY45 -> 521156700 | BZ14: =BZ22+BZ30+BZ36+BZ53+BZ60+BZ69+BZ74+BZ81+BZ87+BZ93+BZ45 -> 1.3384598e+08 | ... CG14: =CG22+CG30+CG36+CG53+CG60+CG69+CG74+CG81+CG87+CG93+CG45 -> 562119753 | CH14: =CH22+CH30+CH36+CH53+CH60+CH69+CH74+CH81+CH87+CH93 -> 0 | CL14: =CL22+CL30+CL36+CL53+CL60+CL69+CL74+CL81+CL87+CL93 -> 0
A15: 1 | B15: 8 | C15: Ho Thi Minh Hoa | D15: Hồ Thị Minh Hòa | E15: =IF(OR(G15="CHT",G15="DSBC"),"HĐLĐ",IF(OR(G15="DSTV",G15="Q.CHT"),"HĐTV","HĐCTV")) -> HĐLĐ | F15: 24H | G15: DSBC | H15: 45352 | I15: 0051000542226 | J15: Vietcombank | K15: 26 | L15: 2 | M15: 31.69 | N15: 0 | O15: 16 | S15: =IF(E15="HĐLĐ",5310000,0) -> 5310000 | AA15: =CY15 -> 6500000 | AE15: =IF(E15="HĐTV",AC15/28/8*M15,AA15/28/8*M15) -> 919575.89 | AF15: =IF(E15="HĐTV",AC15/28/8*N15*1.5,AA15/28/8*N15*1.5) -> 0 | AG15: 0 | AH15: 0 | AI15: 0 | AL15: 0 | AM15: 0 | AN15: 0 | AO15: 0 | AP15: 0 | AQ15: 0 | AS15: 0 | AU15: 0 | BA15: 0 | BB15: 0 | BC15: 0 | BD15: 0 | BE15: 0 | BF15: 0 | BG15: =SUM(T15:Z15)+SUM(AD15:AZ15)-SUM(BA15:BF15) -> 919575.89 | BH15: =S15*17.5% -> 929250 | BI15: =S15*3% -> 159300 | BJ15: =S15*1% -> 53100 | BL15: =SUM(BH15:BK15) -> 1141650 | BM15: =S15*8% -> 424800 | BN15: =S15*1.5% -> 79650 | BO15: =S15*1% -> 53100 | BQ15: =SUM(BM15:BP15) -> 557550 | BR15: =AF15 -> 0 | BS15: =T15+U15+V15+W15 -> 0 | BT15: =BG15-BS15-BR15 -> 919575.89 | BU15: =BT15 -> 919575.89 | BW15: =BV15*6200000 -> 0 | BX15: =BQ15 -> 557550 | BY15: =BU15+BW15+BX15 -> 1477125.9 | BZ15: =IF(BT15-BY15>0,BT15-BY15,0) -> 0 | CA15: =IF(AND(OR($E15="HĐTV",$E15="HĐCTV"),$BZ15<2000000),0,IF(OR($E15="HĐTV",$E15="HĐCTV"),$BZ15*10%,ROUND(IF($BZ15<=10000000,$BZ15*5%,IF($BZ15<=30000000,$BZ15*10%-500000,IF($BZ15<=60000000,$BZ15*20%-3500000,IF($BZ15<=100000000,$BZ15*30%-9500000,$BZ15*35%-14500000)))),0))) -> 0 | CB15: =ROUND(BG15-BQ15-CA15,0) -> 362026 | CD15: =AV15+AW15 -> 0 | CE15: =CB15+CC15-CD15 -> 362026 | CF15: =CE15-CG15 -> 0 | CG15: =CE15 -> 362026 | CI15: hoa.ho@medigoapp.com | CJ15: =VLOOKUP(D15,[1]CNT!$C$6:$AP$113,40,0) -> 0 | CK15: 11 | CM15: 1 | CN15: 3 | CO15: 2024 | CP15: =IF((($CO$8-CO15)*12)+($CN$8-CN15)>=12,((($CO$8-CO15)*12)+($CN$8-CN15))-1,0) -> 0 | CQ15: =IF(CP15<12,(($CQ$8-CO15)*12)+($CP$8-CN15),0) -> 26 | CR15: =IF(OR(CP15>12,CP15=12),((CP15-(CS15*12))+((($CQ$8-2024)*12)+($CP$8-4)))+1,0) -> 0 | CS15: =IF(OR(CP15>12,CP15=12),ROUNDDOWN(CP15/12,0),0) -> 0 | CT15: =IF(CQ15>11,ROUNDDOWN(CQ15/12,0),0) -> 2 | CU15: =IF(CR15>11,ROUNDDOWN(CR15/12,0),0) -> 0 | CV15: =IF(CP15=0,0,6000000*1.07^CS15) -> 0 | CW15: =IF(CT15<2,0,6000000+(CT15-1)*500000) -> 6500000 | CX15: =IF(CU15=0,CV15,IF(CU15<1,0,CV15+CU15*500000)) -> 0 | CY15: =IF(CX15>0,CX15,IF(CW15>0,CW15,6000000)) -> 6500000 | DB15: =CZ15&";"&" "&DA15 -> ; | DF15: =VLOOKUP($D15,'[2]Med Service'!$D$11:$DI$87,110,0) -> 1035547 | DG15: =VLOOKUP($D15,'[3]BẢNG LƯƠNG'!$C$3:$AH$102,32,0)
A16: 3 | B16: 8 | C16: Nguyen Tran Ngoc Phuong | D16: Nguyễn Trần Ngọc Phương | E16: =IF(OR(G16="CHT",G16="DSBC"),"HĐLĐ",IF(OR(G16="DSTV",G16="Q.CHT"),"HĐTV","HĐCTV")) -> HĐTV | F16: 24H | G16: Q.CHT | H16: 46196 | I16: 0721000550950 | J16: Vietcombank | K16: 28 | L16: 26 | M16: 186.64 | N16: 28.38 | O16: 0 | S16: =IF(E16="HĐLĐ",5310000,0) -> 0 | T16: =IF(500000/28*L16>500000,500000,500000/28*L16) -> 464285.71 | AA16: =CY16 -> 6000000 | AC16: =AA16 -> 6000000 | AE16: =IF(E16="HĐTV",AC16/28/8*M16,AA16/28/8*M16) -> 4999285.7 | AF16: =IF(E16="HĐTV",AC16/28/8*N16*1.5,AA16/28/8*N16*1.5) -> 1140267.9 | AG16: 1,500,000 | AH16: 0 | AI16: 0 | AL16: 1000000 | AM16: 0 | AN16: 1280200 | AO16: 6601 | AP16: 0 | AQ16: 0 | AS16: 0 | AT16: 300000 | AU16: 0 | BA16: 0 | BB16: 0 | BC16: 0 | BD16: 0 | BE16: 0 | BF16: 0 | BG16: =SUM(T16:Z16)+SUM(AD16:AZ16)-SUM(BA16:BF16) -> 9190640.3 | BH16: =S16*17.5% -> 0 | BI16: =S16*3% -> 0 | BJ16: =S16*1% -> 0 | BL16: =SUM(BH16:BK16) -> 0 | BM16: =S16*8% -> 0 | BN16: =S16*1.5% -> 0 | BO16: =S16*1% -> 0 | BQ16: =SUM(BM16:BP16) -> 0 | BR16: =AF16 -> 1140267.9 | BS16: =T16+U16+V16+W16 -> 464285.71 | BT16: =BG16-BS16-BR16 -> 7586086.7 | BU16: =IF(E16="HĐLĐ",15500000,0) -> 0 | BW16: =BV16*6200000 -> 0 | BX16: =BQ16 -> 0 | BY16: =BU16+BW16+BX16 -> 0 | BZ16: =IF(BT16-BY16>0,BT16-BY16,0) -> 7586086.7 | CA16: =IF(AND(OR($E16="HĐTV",$E16="HĐCTV"),$BZ16<2000000),0,IF(OR($E16="HĐTV",$E16="HĐCTV"),$BZ16*10%,ROUND(IF($BZ16<=10000000,$BZ16*5%,IF($BZ16<=30000000,$BZ16*10%-500000,IF($BZ16<=60000000,$BZ16*20%-3500000,IF($BZ16<=100000000,$BZ16*30%-9500000,$BZ16*35%-14500000)))),0))) -> 758608.67 | CB16: =ROUND(BG16-BQ16-CA16,0) -> 8432032 | CD16: =AV16+AW16 -> 0 | CE16: =CB16+CC16-CD16 -> 8432032 | CF16: =CE16-CG16 -> 0 | CG16: =CE16 -> 8432032 | CI16: phuong.nguyen@medigoapp.com | CK16: 9 | CL16: =VLOOKUP(D16,[1]CNT!C7:AJ70,15,0) -> 0 | CM16: 23 | CN16: 6 | CO16: 2026 | CP16: =IF((($CO$8-CO16)*12)+($CN$8-CN16)>=12,((($CO$8-CO16)*12)+($CN$8-CN16))-1,0) -> 0 | CQ16: =IF(CP16<12,(($CQ$8-CO16)*12)+($CP$8-CN16),0) -> -1 | CR16: =IF(OR(CP16>12,CP16=12),((CP16-(CS16*12))+((($CQ$8-2024)*12)+($CP$8-4)))+1,0) -> 0 | CS16: =IF(OR(CP16>12,CP16=12),ROUNDDOWN(CP16/12,0),0) -> 0 | CT16: =IF(CQ16>11,ROUNDDOWN(CQ16/12,0),0) -> 0 | CU16: =IF(CR16>11,ROUNDDOWN(CR16/12,0),0) -> 0 | CV16: =IF(CP16=0,0,6000000*1.07^CS16) -> 0 | CW16: =IF(CT16<2,0,6000000+(CT16-1)*500000) -> 0 | CX16: =IF(CU16=0,CV16,IF(CU16<1,0,CV16+CU16*500000)) -> 0 | CY16: =IF(CX16>0,CX16,IF(CW16>0,CW16,6000000)) -> 6000000 | DB16: =CZ16&";"&" "&DA16 -> ; | DF16: =VLOOKUP($D16,'[2]Med Service'!$D$11:$DI$87,110,0) -> #N/A | DG16: =VLOOKUP($D16,'[3]BẢNG LƯƠNG'!$C$3:$AH$102,32,0) -> #N/A
A17: 2 | B17: 8 | C17: Nguyen Ngoc Anh Thu | D17: Nguyễn Ngọc Anh Thư | E17: =IF(OR(G17="CHT",G17="DSBC"),"HĐLĐ",IF(OR(G17="DSTV",G17="Q.CHT"),"HĐTV","HĐCTV")) -> HĐTV | F17: 24H | G17: DSTV | H17: 14/07/2026 | I17: 7500664184 | J17: BIDV | K17: 28 | L17: 29 | M17: 26.98 | N17: 219.5 | O17: 8 | S17: =IF(E17="HĐLĐ",5310000,0) -> 0 | T17: =IF(500000/28*L17>500000,500000,500000/28*L17) -> 500000 | AA17: =VLOOKUP(D17,'[4]Med Service'!D$42:AC$140,26,0) -> 6000000 | AB17: =AA17 -> 6000000 | AC17: =AA17 -> 6000000 | AD17: =IF(E17="HĐTV",AC17/K17*L17,AB17/K17*L17) -> 6214285.7 | AE17: =IF(E17="HĐTV",AC17/28/8*M17,AA17/28/8*M17) -> 722678.57 | AF17: =IF(E17="HĐTV",AC17/28/8*N17*1.5,AA17/28/8*N17*1.5) -> 8819196.4 | AG17: 0 | AH17: 0 | AI17: 1446429 | AL17: 933333 | AM17: 0 | AN17: 579960 | AO17: 7700 | AP17: 0 | AQ17: 0 | AS17: 0 | AT17: 0 | AU17: 0 | BA17: 0 | BB17: 0 | BC17: 0 | BD17: 0 | BE17: 0 | BF17: 0 | BG17: =SUM(T17:Z17)+SUM(AD17:AZ17)-SUM(BA17:BF17) -> 19223583 | BH17: =S17*17.5% -> 0 | BI17: =S17*3% -> 0 | BJ17: =S17*1% -> 0 | BL17: =SUM(BH17:BK17) -> 0 | BM17: =S17*8% -> 0 | BN17: =S17*1.5% -> 0 | BO17: =S17*1% -> 0 | BQ17: =SUM(BM17:BP17) -> 0 | BR17: =AF17 -> 8819196.4 | BS17: =T17+U17+V17+W17 -> 500000 | BT17: =BG17-BS17-BR17 -> 9904386.3 | BU17: =IF(E17="HĐLĐ",15500000,0) -> 0 | BX17: =BQ17 -> 0 | BY17: =BU17+BW17+BX17 -> 0 | BZ17: =IF(BT17-BY17>0,BT17-BY17,0) -> 9904386.3 | CA17: =IF(AND(OR($E17="HĐTV",$E17="HĐCTV"),$BZ17<2000000),0,IF(OR($E17="HĐTV",$E17="HĐCTV"),$BZ17*10%,ROUND(IF($BZ17<=10000000,$BZ17*5%,IF($BZ17<=30000000,$BZ17*10%-500000,IF($BZ17<=60000000,$BZ17*20%-3500000,IF($BZ17<=100000000,$BZ17*30%-9500000,$BZ17*35%-14500000)))),0))) -> 990438.63 | CB17: =ROUND(BG17-BQ17-CA17,0) -> 18233144 | CE17: =CB17+CC17-CD17 -> 18233144 | CF17: =CE17-CG17 -> 0 | CG17: =CE17 -> 18233144 | CI17: thu.nguyen@medigoapp.com | CK17: 1 | CY17: =IF(CX17>0,CX17,IF(CW17>0,CW17,6000000)) -> 6000000
B18: 8 | C18: Trinh Thi Phuong | D18: Trịnh Thị Phượng | E18: =IF(OR(G18="CHT",G18="DSBC"),"HĐLĐ",IF(OR(G18="DSTV",G18="Q.CHT"),"HĐTV","HĐCTV")) -> HĐLĐ | F18: 24H | G18: DSBC | H18: 45096 | I18: 10200014211025 | J18: Đông Nam Á (Seabank) | K18: 26 | L18: 21 | M18: 0.38 | N18: 164.21 | O18: 0 | S18: =IF(E18="HĐLĐ",5310000,0) -> 5310000 | T18: =IF(500000/28*L18>500000,500000,500000/28*L18) -> 375000 | AA18: 6500000 | AB18: =AA18 -> 6500000 | AC18: =IF(E18="HĐTV",AB18*85%,0) -> 0 | AD18: =IF(E18="HĐTV",AC18/K18*L18,AB18/K18*L18) -> 5250000 | AE18: =IF(E18="HĐTV",AC18/28/8*M18,AA18/28/8*M18) -> 11026.786 | AF18: =IF(E18="HĐTV",AC18/28/8*N18*1.5,AA18/28/8*N18*1.5) -> 7147533.5 | AG18: 0 | AH18: 0 | AI18: 1125000 | AL18: 2200000 | AM18: 0 | AN18: 3537750 | AO18: 11205 | AP18: 0 | AQ18: 0 | AS18: 0 | AT18: 0 | AU18: 0 | BA18: 0 | BB18: 0 | BC18: 0 | BD18: 0 | BE18: 0 | BF18: 0 | BG18: =SUM(T18:Z18)+SUM(AD18:AZ18)-SUM(BA18:BF18) -> 19657515 | BH18: =S18*17.5% -> 929250 | BI18: =S18*3% -> 159300 | BJ18: =S18*1% -> 53100 | BL18: =SUM(BH18:BK18) -> 1141650 | BM18: =S18*8% -> 424800 | BN18: =S18*1.5% -> 79650 | BO18: =S18*1% -> 53100 | BQ18: =SUM(BM18:BP18) -> 557550 | CE18: =CB18+CC18-CD18 -> 0 | CF18: =CE18-CG18 -> 0 | CG18: =CE18 -> 0 | CK18: 2 | CY18: =IF(CX18>0,CX18,IF(CW18>0,CW18,6000000)) -> 6000000
A19: 4 | B19: 8 | C19: Ngo Tran Tuyet Vy | D19: Ngô Trần Tuyết Vy | E19: =IF(OR(G19="CHT",G19="DSBC"),"HĐLĐ",IF(OR(G19="DSTV",G19="Q.CHT"),"HĐTV","HĐCTV")) -> HĐLĐ | F19: 24H | G19: DSBC | H19: 44743 | I19: 060260188766 | J19: Sacombank | K19: 28 | L19: 11 | M19: 66.26 | N19: 23.12 | O19: 0 | S19: =IF(E19="HĐLĐ",5310000,0) -> 5310000 | T19: =IF(500000/28*L19>500000,500000,500000/28*L19) -> 196428.57 | AA19: =CY19 -> 8350258 | AE19: =IF(E19="HĐTV",AC19/28/8*M19,AA19/28/8*M19) -> 2470036.1 | AF19: =IF(E19="HĐTV",AC19/28/8*N19*1.5,AA19/28/8*N19*1.5) -> 1292798.9 | AG19: 0 | AH19: 0 | AI19: 0 | AL19: 0 | AM19: 0 | AN19: 1011600 | AO19: 0 | AP19: 0 | AQ19: 0 | AS19: 0 | AT19: 0 | AU19: 0 | BA19: 0 | BB19: 0 | BC19: 0 | BD19: 0 | BE19: 0 | BF19: 0 | BG19: =SUM(T19:Z19)+SUM(AD19:AZ19)-SUM(BA19:BF19) -> 4970863.6 | BH19: =S19*17.5% -> 929250 | BI19: =S19*3% -> 159300 | BJ19: =S19*1% -> 53100 | BL19: =SUM(BH19:BK19) -> 1141650 | BM19: =S19*8% -> 424800 | BN19: =S19*1.5% -> 79650 | BO19: =S19*1% -> 53100 | BQ19: =SUM(BM19:BP19) -> 557550 | BR19: =AF19 -> 1292798.9 | BS19: =T19+U19+V19+W19 -> 196428.57 | BT19: =BG19-BS19-BR19 -> 3481636.1 | BU19: =IF(E19="HĐLĐ",15500000,0) -> 15500000 | BW19: =BV19*6200000 -> 0 | BX19: =BQ19 -> 557550 | BY19: =BU19+BW19+BX19 -> 16057550 | BZ19: =IF(BT19-BY19>0,BT19-BY19,0) -> 0 | CA19: =IF(AND(OR($E19="HĐTV",$E19="HĐCTV"),$BZ19<2000000),0,IF(OR($E19="HĐTV",$E19="HĐCTV"),$BZ19*10%,ROUND(IF($BZ19<=10000000,$BZ19*5%,IF($BZ19<=30000000,$BZ19*10%-500000,IF($BZ19<=60000000,$BZ19*20%-3500000,IF($BZ19<=100000000,$BZ19*30%-9500000,$BZ19*35%-14500000)))),0))) -> 0 | CB19: =ROUND(BG19-BQ19-CA19,0) -> 4413314 | CD19: =AV19+AW19 -> 0 | CE19: =CB19+CC19-CD19 -> 4413314 | CF19: =CE19-CG19 -> 0 | CG19: =CE19 -> 4413314 | CI19: =VLOOKUP($C19,[5]Sheet1!$C$5:$K$139,9,0) -> vy.ngo@medigoapp.com | CJ19: =VLOOKUP(D19,[1]CNT!$C$6:$AP$113,40,0) -> 0 | CK19: 3 | CL19: =VLOOKUP(D19,[1]CNT!C7:AJ70,15,0) -> 0 | CM19: 14 | CN19: 2 | CO19: 2021 | CP19: =IF((($CO$8-CO19)*12)+($CN$8-CN19)>=12,((($CO$8-CO19)*12)+($CN$8-CN19))-1,0) -> 37 | CQ19: =IF(CP19<12,(($CQ$8-CO19)*12)+($CP$8-CN19),0) -> 0 | CR19: =IF(OR(CP19>12,CP19=12),((CP19-(CS19*12))+((($CQ$8-2024)*12)+($CP$8-4)))+1,0) -> 27 | CS19: =IF(OR(CP19>12,CP19=12),ROUNDDOWN(CP19/12,0),0) -> 3 | CT19: =IF(CQ19>11,ROUNDDOWN(CQ19/12,0),0) -> 0 | CU19: =IF(CR19>11,ROUNDDOWN(CR19/12,0),0) -> 2 | CV19: =IF(CP19=0,0,6000000*1.07^CS19) -> 7350258 | CW19: =IF(CT19<2,0,6000000+(CT19-1)*500000) -> 0 | CX19: =IF(CU19=0,CV19,IF(CU19<1,0,CV19+CU19*500000)) -> 8350258 | CY19: =IF(CX19>0,CX19,IF(CW19>0,CW19,6000000)) -> 8350258 | DB19: =CZ19&";"&" "&DA19 -> ; | DF19: =VLOOKUP($D19,'[2]Med Service'!$D$11:$DI$87,110,0) -> 0 | DG19: =VLOOKUP($D19,'[3]BẢNG LƯƠNG'!$C$3:$AH$102,32,0)
A20: 5 | B20: 8 | C20: Pham Nguyen Ngoc Quy | D20: Phạm Nguyễn Ngọc Quý | E20: =IF(OR(G20="CHT",G20="DSBC"),"HĐLĐ",IF(OR(G20="DSTV",G20="Q.CHT"),"HĐTV","HĐCTV")) -> HĐLĐ | F20: 24H | G20: DSBC | H20: 01/11/2024 | I20: 1026764251 | J20: Vietcombank | K20: 28 | L20: 23 | M20: 164.33 | N20: 24.07 | O20: 0 | S20: =IF(E20="HĐLĐ",5310000,0) -> 5310000 | T20: =IF(500000/28*L20>500000,500000,500000/28*L20) -> 410714.29 | AA20: =CY20 -> 6000000 | AE20: =IF(E20="HĐTV",AC20/28/8*M20,AA20/28/8*M20) -> 4401696.4 | AF20: =IF(E20="HĐTV",AC20/28/8*N20*1.5,AA20/28/8*N20*1.5) -> 967098.21 | AG20: 0 | AH20: 0 | AI20: 0 | AL20: 0 | AM20: 0 | AN20: 1686900 | AO20: 18300 | AP20: 0 | AQ20: 0 | AS20: 0 | AT20: 0 | AU20: 0 | BA20: 0 | BB20: 0 | BC20: 0 | BD20: 0 | BE20: 0 | BF20: 0 | BG20: =SUM(T20:Z20)+SUM(AD20:AZ20)-SUM(BA20:BF20) -> 7484708.9 | BH20: =S20*17.5% -> 929250 | BI20: =S20*3% -> 159300 | BJ20: =S20*1% -> 53100 | BL20: =SUM(BH20:BK20) -> 1141650 | BM20: =S20*8% -> 424800 | BN20: =S20*1.5% -> 79650 | BO20: =S20*1% -> 53100 | BQ20: =SUM(BM20:BP20) -> 557550 | BR20: =AF20 -> 967098.21 | BS20: =T20+U20+V20+W20 -> 410714.29 | BT20: =BG20-BS20-BR20 -> 6106896.4 | BU20: =IF(E20="HĐLĐ",15500000,0) -> 15500000 | BW20: =BV20*6200000 -> 0 | BX20: =BQ20 -> 557550 | BY20: =BU20+BW20+BX20 -> 16057550 | BZ20: =IF(BT20-BY20>0,BT20-BY20,0) -> 0 | CA20: =IF(AND(OR($E20="HĐTV",$E20="HĐCTV"),$BZ20<2000000),0,IF(OR($E20="HĐTV",$E20="HĐCTV"),$BZ20*10%,ROUND(IF($BZ20<=10000000,$BZ20*5%,IF($BZ20<=30000000,$BZ20*10%-500000,IF($BZ20<=60000000,$BZ20*20%-3500000,IF($BZ20<=100000000,$BZ20*30%-9500000,$BZ20*35%-14500000)))),0))) -> 0 | CB20: =ROUND(BG20-BQ20-CA20,0) -> 6927159 | CD20: =AV20+AW20 -> 0 | CE20: =CB20+CC20-CD20 -> 6927159 | CF20: =CE20-CG20 -> 0 | CG20: =CE20 -> 6927159 | CI20: quy.pham@medigoapp.com | CJ20: =VLOOKUP(D20,[1]CNT!$C$6:$AP$113,40,0) -> 0 | CK20: 6 | CL20: =VLOOKUP(D20,[1]CNT!C7:AJ70,15,0) -> 0 | CM20: 1 | CN20: 11 | CO20: 2024 | CP20: =IF((($CO$8-CO20)*12)+($CN$8-CN20)>=12,((($CO$8-CO20)*12)+($CN$8-CN20))-1,0) -> 0 | CQ20: =IF(CP20<12,(($CQ$8-CO20)*12)+($CP$8-CN20),0) -> 18 | CR20: =IF(OR(CP20>12,CP20=12),((CP20-(CS20*12))+((($CQ$8-2024)*12)+($CP$8-4)))+1,0) -> 0 | CS20: =IF(OR(CP20>12,CP20=12),ROUNDDOWN(CP20/12,0),0) -> 0 | CT20: =IF(CQ20>11,ROUNDDOWN(CQ20/12,0),0) -> 1 | CU20: =IF(CR20>11,ROUNDDOWN(CR20/12,0),0) -> 0 | CV20: =IF(CP20=0,0,6000000*1.07^CS20) -> 0 | CW20: =IF(CT20<2,0,6000000+(CT20-1)*500000) -> 0 | CX20: =IF(CU20=0,CV20,IF(CU20<1,0,CV20+CU20*500000)) -> 0 | CY20: =IF(CX20>0,CX20,IF(CW20>0,CW20,6000000)) -> 6000000 | DB20: =CZ20&";"&" "&DA20 -> ; | DF20: =VLOOKUP($D20,'[2]Med Service'!$D$11:$DI$87,110,0) -> 0 | DG20: =VLOOKUP($D20,'[3]BẢNG LƯƠNG'!$C$3:$AH$102,32,0)
C21: Tran Thi Kim Khanh | D21: Trần Thị Kim Khánh | E21: =IF(OR(G21="CHT",G21="DSBC"),"HĐLĐ",IF(OR(G21="DSTV",G21="Q.CHT"),"HĐTV","HĐCTV")) -> HĐLĐ | F21: 24H | G21: DSBC | H21: 45099 | I21: 69110000565904 | J21: BIDV | K21: 26 | L21: 29 | M21: 253.43 | N21: 31.43 | O21: 8 | S21: =IF(E21="HĐLĐ",5310000,0) -> 5310000 | T21: =IF(500000/28*L21>500000,500000,500000/28*L21) -> 500000 | AA21: 6500000 | AB21: =AA21 -> 6500000 | AC21: =IF(E21="HĐTV",AB21*85%,0) -> 0 | AD21: =IF(E21="HĐTV",AC21/K21*L21,AB21/K21*L21) -> 7250000 | AE21: =IF(E21="HĐTV",AC21/28/8*M21,AA21/28/8*M21) -> 7353995.5 | AF21: =IF(E21="HĐTV",AC21/28/8*N21*1.5,AA21/28/8*N21*1.5) -> 1368046.9 | AG21: 0 | AH21: 0 | AI21: 0 | AL21: 2800000 | AM21: 2472797 | AN21: 3808150 | AO21: 46851 | AP21: 0 | AQ21: 0 | AS21: 0 | AT21: 0 | AU21: 0 | BA21: 0 | BB21: 0 | BC21: 0 | BD21: 0 | BE21: 0 | BF21: 0 | BG21: =SUM(T21:Z21)+SUM(AD21:AZ21)-SUM(BA21:BF21) -> 25599840 | BH21: =S21*17.5% -> 929250 | BI21: =S21*3% -> 159300 | BJ21: =S21*1% -> 53100 | BL21: =SUM(BH21:BK21) -> 1141650 | BM21: =S21*8% -> 424800 | BN21: =S21*1.5% -> 79650 | BO21: =S21*1% -> 53100 | BQ21: =SUM(BM21:BP21) -> 557550 | CE21: =CB21+CC21-CD21 -> 0 | CG21: =CE21 -> 0 | CY21: =IF(CX21>0,CX21,IF(CW21>0,CW21,6000000)) -> 6000000
L22: =SUM(L15:L21) -> 141 | M22: =SUM(M15:M21) -> 729.71 | N22: =SUM(N15:N21) -> 490.71 | O22: =SUM(O15:O21) -> 32 | P22: =SUM(P15:P21) -> 0 | Q22: =SUM(Q15:Q21) -> 0 | R22: =SUM(R15:R21) -> 0 | S22: =SUM(S15:S21) -> 26550000 | U22: =SUM(U15:U21) -> 0 | V22: =SUM(V15:V21) -> 0 | W22: =SUM(W15:W21) -> 0 | X22: =SUM(X15:X21) -> 0 | Y22: =SUM(Y15:Y21) -> 0 | Z22: =SUM(Z15:Z21) -> 0 | AA22: =SUM(AA15:AA21) -> 45850258 | AB22: =SUM(AB15:AB21) -> 19000000 | ... CG22: =SUM(CG15:CG21) -> 38367675 | CH22: =SUM(CH15:CH20) -> 0 | CI22: =SUM(CI15:CI20) -> 0 | CJ22: =SUM(CJ15:CJ20) -> 0 | CK22: =SUM(CK15:CK20) -> 32 | CL22: =SUM(CL15:CL20) -> 0 | CM22: =SUM(CM15:CM20) -> 39 | CN22: =SUM(CN15:CN20) -> 22 | CO22: =SUM(CO15:CO20) -> 8095 | ... DG22: =SUM(DG15:DG20) -> #N/A
A23: 13 | B23: 7 | C23: Ngo Thi Thanh Tham | D23: Ngô Thị Thanh Thắm | E23: =IF(OR(G23="CHT",G23="DSBC"),"HĐLĐ",IF(OR(G23="DSTV",G23="Q.CHT"),"HĐTV","HĐCTV")) -> HĐLĐ | F23: Đỗ Quang Đẩu | G23: CHT | H23: 45524 | I23: 0431000219840 | J23: Vietcombank | K23: 28 | L23: 23 | M23: 183.01 | N23: 0 | O23: 0 | S23: =IF(E23="HĐLĐ",5310000,0) -> 5310000 | T23: =IF(500000/28*L23>500000,500000,500000/28*L23) -> 410714.29 | AA23: =CY23 -> 6000000 | AE23: =IF(E23="HĐTV",AC23/28/8*M23,AA23/28/8*M23) -> 4902053.6 | AF23: =IF(E23="HĐTV",AC23/28/8*N23*1.5,AA23/28/8*N23*1.5) -> 0 | AG23: 2,000,000 | AH23: 0 | AI23: 0 | AL23: 0 | AM23: 0 | AN23: 688400 | AO23: 14067 | AP23: 0 | AQ23: 1000000 | AS23: 0 | AT23: 0 | AU23: 2681852 | BA23: 0 | BB23: 0 | BC23: 0 | BD23: 0 | BE23: 0 | BF23: 0 | BG23: =SUM(T23:Z23)+SUM(AD23:AZ23)-SUM(BA23:BF23) -> 9697086.9 | BH23: =S23*17.5% -> 929250 | BI23: =S23*3% -> 159300 | BJ23: =S23*1% -> 53100 | BL23: =SUM(BH23:BK23) -> 1141650 | BM23: =S23*8% -> 424800 | BN23: =S23*1.5% -> 79650 | BO23: =S23*1% -> 53100 | BQ23: =SUM(BM23:BP23) -> 557550 | BR23: =AF23 -> 0 | BS23: =T23+U23+V23+W23 -> 410714.29 | BT23: =BG23-BS23-BR23 -> 9286372.6 | BU23: =IF(E23="HĐLĐ",15500000,0) -> 15500000 | BW23: =BV23*6200000 -> 0 | BX23: =BQ23 -> 557550 | BY23: =BU23+BW23+BX23 -> 16057550 | BZ23: =IF(BT23-BY23>0,BT23-BY23,0) -> 0 | CA23: =IF(AND(OR($E23="HĐTV",$E23="HĐCTV"),$BZ23<2000000),0,IF(OR($E23="HĐTV",$E23="HĐCTV"),$BZ23*10%,ROUND(IF($BZ23<=10000000,$BZ23*5%,IF($BZ23<=30000000,$BZ23*10%-500000,IF($BZ23<=60000000,$BZ23*20%-3500000,IF($BZ23<=100000000,$BZ23*30%-9500000,$BZ23*35%-14500000)))),0))) -> 0 | CB23: =ROUND(BG23-BQ23-CA23,0) -> 9139537 | CD23: =AV23+AW23 -> 0 | CE23: =CB23+CC23-CD23 -> 9139537 | CF23: =CE23-CG23 -> 0 | CG23: =CE23 -> 9139537 | CI23: tham.ngo@medigoapp.com | CJ23: =VLOOKUP(D23,[1]CNT!$C$6:$AP$113,40,0) -> 0 | CK23: 12 | CL23: =VLOOKUP(D23,[1]CNT!C10:AJ73,15,0) -> 0 | CM23: 20 | CN23: 8 | CO23: 2024 | CP23: =IF((($CO$8-CO23)*12)+($CN$8-CN23)>=12,((($CO$8-CO23)*12)+($CN$8-CN23))-1,0) -> 0 | CQ23: =IF(CP23<12,(($CQ$8-CO23)*12)+($CP$8-CN23),0) -> 21 | CR23: =IF(OR(CP23>12,CP23=12),((CP23-(CS23*12))+((($CQ$8-2024)*12)+($CP$8-4)))+1,0) -> 0 | CS23: =IF(OR(CP23>12,CP23=12),ROUNDDOWN(CP23/12,0),0) -> 0 | CT23: =IF(CQ23>11,ROUNDDOWN(CQ23/12,0),0) -> 1 | CU23: =IF(CR23>11,ROUNDDOWN(CR23/12,0),0) -> 0 | CV23: =IF(CP23=0,0,6000000*1.07^CS23) -> 0 | CW23: =IF(CT23<2,0,6000000+(CT23-1)*500000) -> 0 | CX23: =IF(CU23=0,CV23,IF(CU23<1,0,CV23+CU23*500000)) -> 0 | CY23: =IF(CX23>0,CX23,IF(CW23>0,CW23,6000000)) -> 6000000 | DA23: =CJ23 -> 0 | DE23: =VLOOKUP($D23,'[6]Tong hop'!$B$8:$Q$45,15,0) -> 346622 | DF23: =VLOOKUP($D23,'[2]Med Service'!$D$11:$DI$87,110,0) -> 0 | DG23: =VLOOKUP($D23,'[3]BẢNG LƯƠNG'!$C$3:$AH$102,32,0) -> Vi phạm chấm điểm checklist 28/05/2026: 10.000đ
A24: 8 | B24: 7 | C24: Duong Thi Huynh Nhu | D24: Dương Thị Huỳnh Như | E24: =IF(OR(G24="CHT",G24="DSBC"),"HĐLĐ",IF(OR(G24="DSTV",G24="Q.CHT"),"HĐTV","HĐCTV")) -> HĐTV | F24: Đỗ Quang Đẩu | G24: DSTV | H24: 28/07/2026 | I24: 023704070008223 | J24: HD Bank | K24: 28 | L24: 4 | M24: 32.49 | N24: 0 | O24: 0 | S24: =IF(E24="HĐLĐ",5310000,0) -> 0 | T24: =IF(500000/28*L24>500000,500000,500000/28*L24) -> 71428.571 | AA24: 6000000 | AB24: =AA24 -> 6000000 | AC24: 6000000 | AD24: =IF(E24="HĐTV",AC24/K24*L24,AB24/K24*L24) -> 857142.86 | AE24: =IF(E24="HĐTV",AC24/28/8*M24,AA24/28/8*M24) -> 870267.86 | AF24: =IF(E24="HĐTV",AC24/28/8*N24*1.5,AA24/28/8*N24*1.5) -> 0 | AG24: 0 | AH24: 0 | AI24: 0 | AL24: 0 | AM24: 0 | AN24: 0 | AO24: 0 | AP24: 0 | AQ24: 0 | AS24: 0 | AT24: 0 | AU24: 0 | BA24: 0 | BB24: 0 | BC24: 0 | BD24: 0 | BE24: 0 | BF24: 0 | BG24: =SUM(T24:Z24)+SUM(AD24:AZ24)-SUM(BA24:BF24) -> 1798839.3 | BH24: =S24*17.5% -> 0 | BI24: =S24*3% -> 0 | BJ24: =S24*1% -> 0 | BL24: =SUM(BH24:BK24) -> 0 | BM24: =S24*8% -> 0 | BN24: =S24*1.5% -> 0 | BO24: =S24*1% -> 0 | BQ24: =SUM(BM24:BP24) -> 0 | BR24: =AF24 -> 0 | BS24: =T24+U24+V24+W24 -> 71428.571 | BT24: =BG24-BS24-BR24 -> 1727410.7 | BU24: =IF(E24="HĐLĐ",15500000,0) -> 0 | BX24: =BQ24 -> 0 | BY24: =BU24+BW24+BX24 -> 0 | BZ24: =IF(BT24-BY24>0,BT24-BY24,0) -> 1727410.7 | CA24: =IF(AND(OR($E24="HĐTV",$E24="HĐCTV"),$BZ24<2000000),0,IF(OR($E24="HĐTV",$E24="HĐCTV"),$BZ24*10%,ROUND(IF($BZ24<=10000000,$BZ24*5%,IF($BZ24<=30000000,$BZ24*10%-500000,IF($BZ24<=60000000,$BZ24*20%-3500000,IF($BZ24<=100000000,$BZ24*30%-9500000,$BZ24*35%-14500000)))),0))) -> 0 | CB24: =ROUND(BG24-BQ24-CA24,0) -> 1798839 | CE24: =CB24+CC24-CD24 -> 1798839 | CF24: =CE24-CG24 -> 0 | CG24: =CE24 -> 1798839 | CI24: nhu.duong@medigoapp.com | CK24: 9 | CY24: =IF(CX24>0,CX24,IF(CW24>0,CW24,6000000)) -> 6000000
A25: 15 | B25: 7 | C25: Pham Thi Nghia Huong | D25: Phạm Thị Nghĩa Hương | E25: HĐLĐ | F25: Đỗ Quang Đẩu | G25: DSBC | H25: 45575 | I25: 0968249073 | J25: Mb bank | K25: 28 | L25: 29 | M25: 11.02 | N25: 230.26 | O25: 8 | S25: =IF(E25="HĐLĐ",5310000,0) -> 5310000 | T25: =IF(500000/28*L25>500000,500000,500000/28*L25) -> 500000 | AA25: =CY25 -> 6000000 | AE25: =IF(E25="HĐTV",AC25/28/8*M25,AA25/28/8*M25) -> 295178.57 | AF25: =IF(E25="HĐTV",AC25/28/8*N25*1.5,AA25/28/8*N25*1.5) -> 9251517.9 | AG25: 0 | AH25: 0 | AI25: 1500000 | AL25: 0 | AM25: 0 | AN25: 629100 | AO25: 7550 | AP25: 0 | AQ25: 0 | AS25: 0 | AT25: 0 | AU25: 340044 | BA25: 0 | BB25: 0 | BC25: 100000 | BD25: 0 | BE25: 0 | BF25: 0 | BG25: =SUM(T25:Z25)+SUM(AD25:AZ25)-SUM(BA25:BF25) -> 12423390 | BH25: =S25*17.5% -> 929250 | BI25: =S25*3% -> 159300 | BJ25: =S25*1% -> 53100 | BL25: =SUM(BH25:BK25) -> 1141650 | BM25: =S25*8% -> 424800 | BN25: =S25*1.5% -> 79650 | BO25: =S25*1% -> 53100 | BQ25: =SUM(BM25:BP25) -> 557550 | BR25: =AF25 -> 9251517.9 | BS25: =SUM(BN25:BQ25) -> 690300 | BT25: =BG25-BS25-BR25 -> 2481572.6 | BU25: =IF(E25="HĐLĐ",15500000,0) -> 15500000 | BW25: =BV25*6200000 -> 0 | BX25: =BQ25 -> 557550 | BY25: =BU25+BW25+BX25 -> 16057550 | BZ25: =IF(BT25-BY25>0,BT25-BY25,0) -> 0 | CA25: =IF(AND(OR($E25="HĐTV",$E25="HĐCTV"),$BZ25<2000000),0,IF(OR($E25="HĐTV",$E25="HĐCTV"),$BZ25*10%,ROUND(IF($BZ25<=10000000,$BZ25*5%,IF($BZ25<=30000000,$BZ25*10%-500000,IF($BZ25<=60000000,$BZ25*20%-3500000,IF($BZ25<=100000000,$BZ25*30%-9500000,$BZ25*35%-14500000)))),0))) -> 0 | CB25: =ROUND(BG25-BQ25-CA25,0) -> 11865840 | CD25: =AV25+AW25 -> 0 | CE25: =CB25+CC25-CD25 -> 11865840 | CF25: =CE25-CG25 -> 0 | CG25: =CE25 -> 11865840 | CI25: huong.pham@medigoapp.com | CJ25: =VLOOKUP(D25,[1]CNT!$C$6:$AP$113,40,0) -> 0 | CK25: 10 | CL25: =VLOOKUP(D25,[1]CNT!C12:AJ75,15,0) -> 0 | CM25: 10 | CN25: 10 | CO25: 2024 | CP25: 0 | CQ25: 17 | CR25: =IF(OR(CP25>12,CP25=12),((CP25-(CS25*12))+((($CQ$8-2024)*12)+($CP$8-4)))+1,0) -> 0 | CS25: 0 | CT25: 1 | CU25: 0 | CV25: 0 | CW25: 0 | CX25: 0 | CY25: =IF(CX25>0,CX25,IF(CW25>0,CW25,6000000)) -> 6000000 | DA25: =CJ25 -> 0 | DB25: Sai thao tác (Sai kênh bán HD1180427): 100.000đ | DE25: =VLOOKUP($D25,'[6]Tong hop'!$B$8:$Q$45,15,0) -> 432003 | DF25: =VLOOKUP($D25,'[2]Med Service'!$D$11:$DI$87,110,0) -> 0 | DG25: =VLOOKUP($D25,'[3]BẢNG LƯƠNG'!$C$3:$AH$102,32,0)
A26: 16 | B26: 7 | C26: Tran Thien Phat | D26: Trần Thiên Phát | E26: =IF(OR(G26="CHT",G26="DSBC"),"HĐLĐ",IF(OR(G26="DSTV",G26="Q.CHT"),"HĐTV","HĐCTV")) -> HĐLĐ | F26: Đỗ Quang Đẩu | G26: DSBC | H26: 21/07/2025 | I26: 0345611564 | J26: Mbbank | K26: 28 | L26: 31 | M26: 16 | N26: 245.44 | O26: 16 | S26: =IF(E26="HĐLĐ",5310000,0) -> 5310000 | T26: =IF(500000/28*L26>500000,500000,500000/28*L26) -> 500000 | AA26: =CY26 -> 6000000 | AE26: =IF(E26="HĐTV",AC26/28/8*M26,AA26/28/8*M26) -> 428571.43 | AF26: =IF(E26="HĐTV",AC26/28/8*N26*1.5,AA26/28/8*N26*1.5) -> 9861428.6 | AG26: 0 | AH26: 0 | AI26: 1500000 | AL26: 0 | AM26: 0 | AN26: 867600 | AO26: 4035 | AP26: 0 | AQ26: 0 | AS26: 0 | AT26: 0 | AU26: 375112 | AY26: 100000 | AZ26: 100000 | BA26: 0 | BB26: 0 | BC26: 0 | BD26: 0 | BE26: 0 | BF26: 0 | BG26: =SUM(T26:Z26)+SUM(AD26:AZ26)-SUM(BA26:BF26) -> 13736747 | BH26: =S26*17.5% -> 929250 | BI26: =S26*3% -> 159300 | BJ26: =S26*1% -> 53100 | BL26: =SUM(BH26:BK26) -> 1141650 | BM26: =S26*8% -> 424800 | BN26: =S26*1.5% -> 79650 | BO26: =S26*1% -> 53100 | BQ26: =SUM(BM26:BP26) -> 557550 | BR26: =AF26 -> 9861428.6 | BS26: =T26+U26+V26+W26 -> 500000 | BT26: =BG26-BS26-BR26 -> 3375318.4 | BU26: =IF(E26="HĐLĐ",15500000,0) -> 15500000 | BW26: =BV26*6200000 -> 0 | BX26: =BQ26 -> 557550 | BY26: =BU26+BW26+BX26 -> 16057550 | BZ26: =IF(BT26-BY26>0,BT26-BY26,0) -> 0 | CA26: =IF(AND(OR($E26="HĐTV",$E26="HĐCTV"),$BZ26<2000000),0,IF(OR($E26="HĐTV",$E26="HĐCTV"),$BZ26*10%,ROUND(IF($BZ26<=10000000,$BZ26*5%,IF($BZ26<=30000000,$BZ26*10%-500000,IF($BZ26<=60000000,$BZ26*20%-3500000,IF($BZ26<=100000000,$BZ26*30%-9500000,$BZ26*35%-14500000)))),0))) -> 0 | CB26: =ROUND(BG26-BQ26-CA26,0) -> 13179197 | CD26: =AV26+AW26 -> 0 | CE26: =CB26+CC26-CD26 -> 13179197 | CF26: =CE26-CG26 -> 0 | CG26: =CE26 -> 13179197 | CI26: phat.tran@medigoapp.com | CJ26: =VLOOKUP(D26,[1]CNT!$C$6:$AP$113,40,0) -> 0 | CK26: 8 | CL26: =VLOOKUP(D26,[1]CNT!C13:AJ76,15,0) -> 0 | CM26: 21 | CN26: 7 | CO26: 2025 | CP26: =IF((($CO$8-CO26)*12)+($CN$8-CN26)>=12,((($CO$8-CO26)*12)+($CN$8-CN26))-1,0) -> 0 | CQ26: =IF(CP26<12,(($CQ$8-CO26)*12)+($CP$8-CN26),0) -> 10 | CR26: =IF(OR(CP26>12,CP26=12),((CP26-(CS26*12))+((($CQ$8-2024)*12)+($CP$8-4)))+1,0) -> 0 | CS26: =IF(OR(CP26>12,CP26=12),ROUNDDOWN(CP26/12,0),0) -> 0 | CT26: =IF(CQ26>11,ROUNDDOWN(CQ26/12,0),0) -> 0 | CU26: =IF(CR26>11,ROUNDDOWN(CR26/12,0),0) -> 0 | CV26: =IF(CP26=0,0,6000000*1.07^CS26) -> 0 | CW26: =IF(CT26<2,0,6000000+(CT26-1)*500000) -> 0 | CX26: =IF(CU26=0,CV26,IF(CU26<1,0,CV26+CU26*500000)) -> 0 | CY26: =IF(CX26>0,CX26,IF(CW26>0,CW26,6000000)) -> 6000000 | DA26: =CJ26 -> 0 | DF26: =VLOOKUP($D26,'[2]Med Service'!$D$11:$DI$87,110,0) -> 0 | DG26: =VLOOKUP($D26,'[3]BẢNG LƯƠNG'!$C$3:$AH$102,32,0)
C27: Hoang Lam Gia Bao | D27: Hoàng Lâm Gia Bảo | E27: =IF(OR(G27="CHT",G27="DSBC"),"HĐLĐ",IF(OR(G27="DSTV",G27="Q.CHT"),"HĐTV","HĐCTV")) -> HĐLĐ | F27: Đỗ Quang Đẩu | G27: DSBC | H27: 27/5/2026 | I27: 067106916868 | J27: Sacombank | K27: 28 | L27: 4 | M27: 44.77 | N27: 0.5 | O27: 16 | S27: =IF(E27="HĐLĐ",5310000,0) -> 5310000 | T27: =500000-T41-T65 -> 17857.143 | AA27: =CY27 -> 6000000 | AB27: =AA27 -> 6000000 | AC27: =IF(E27="HĐTV",AB27*85%,0) -> 0 | AD27: =IF(E27="HĐTV",AC27/K27*L27,AB27/K27*L27) -> 857142.86 | AE27: =IF(E27="HĐTV",AC27/28/8*M27,AA27/28/8*M27) -> 1199196.4 | AF27: =IF(E27="HĐTV",AC27/28/8*N27*1.5,AA27/28/8*N27*1.5) -> 20089.286 | AG27: 0 | AH27: 0 | AI27: 0 | AL27: 0 | AM27: 0 | AN27: 0 | AO27: 0 | AP27: 0 | AQ27: 0 | AS27: 0 | AT27: 0 | AU27: 0 | BA27: 0 | BB27: 0 | BC27: 0 | BD27: 0 | BE27: 0 | BF27: 0 | BG27: =SUM(T27:Z27)+SUM(AD27:AZ27)-SUM(BA27:BF27) -> 2094285.7 | BH27: =S27*17.5% -> 929250 | BI27: =S27*3% -> 159300 | BJ27: =S27*1% -> 53100 | BL27: =SUM(BH27:BK27) -> 1141650 | BM27: =S27*8% -> 424800 | BN27: =S27*1.5% -> 79650 | BO27: =S27*1% -> 53100 | BQ27: =SUM(BM27:BP27) -> 557550 | CK27: 11 | CY27: =IF(CX27>0,CX27,IF(CW27>0,CW27,6000000)) -> 6000000
A28: 9 | B28: 7 | C28: Hoang Thanh Thuy | D28: Hoàng Thanh Thủy | E28: =IF(OR(G28="CHT",G28="DSBC"),"HĐLĐ",IF(OR(G28="DSTV",G28="Q.CHT"),"HĐTV","HĐCTV")) -> HĐLĐ | F28: Đỗ Quang Đẩu | G28: DSBC | H28: 27/10/2025 | I28: 615704060127761 | J28: VIB | K28: 28 | L28: 30 | M28: 262.37 | N28: 1.1 | O28: 16 | S28: =IF(E28="HĐLĐ",5310000,0) -> 5310000 | T28: =IF(500000/28*L28>500000,500000,500000/28*L28) -> 500000 | AA28: =CY28 -> 6000000 | AE28: =IF(E28="HĐTV",AC28/28/8*M28,AA28/28/8*M28) -> 7027767.9 | AF28: =IF(E28="HĐTV",AC28/28/8*N28*1.5,AA28/28/8*N28*1.5) -> 44196.429 | AG28: 0 | AH28: 0 | AI28: 0 | AL28: 0 | AM28: 0 | AN28: 1723400 | AO28: 40230 | AP28: 0 | AQ28: 0 | AS28: 0 | AT28: 0 | AU28: 3697588 | BA28: 0 | BB28: 0 | BC28: 100000 | BD28: 0 | BE28: 0 | BF28: 0 | BG28: =SUM(T28:Z28)+SUM(AD28:AZ28)-SUM(BA28:BF28) -> 12933182 | BH28: =S28*17.5% -> 929250 | BI28: =S28*3% -> 159300 | BJ28: =S28*1% -> 53100 | BL28: =SUM(BH28:BK28) -> 1141650 | BM28: =S28*8% -> 424800 | BN28: =S28*1.5% -> 79650 | BO28: =S28*1% -> 53100 | BQ28: =SUM(BM28:BP28) -> 557550 | BR28: =AF28 -> 44196.429 | BS28: =T28+U28+V28+W28 -> 500000 | BT28: =BG28-BS28-BR28 -> 12388986 | BU28: =IF(E28="HĐLĐ",15500000,0) -> 15500000 | BW28: =BV28*6200000 -> 0 | BX28: =BQ28 -> 557550 | BY28: =BU28+BW28+BX28 -> 16057550 | BZ28: =IF(BT28-BY28>0,BT28-BY28,0) -> 0 | CA28: =IF(AND(OR($E28="HĐTV",$E28="HĐCTV"),$BZ28<2000000),0,IF(OR($E28="HĐTV",$E28="HĐCTV"),$BZ28*10%,ROUND(IF($BZ28<=10000000,$BZ28*5%,IF($BZ28<=30000000,$BZ28*10%-500000,IF($BZ28<=60000000,$BZ28*20%-3500000,IF($BZ28<=100000000,$BZ28*30%-9500000,$BZ28*35%-14500000)))),0))) -> 0 | CB28: =ROUND(BG28-BQ28-CA28,0) -> 12375632 | CD28: =AV28+AW28 -> 0 | CE28: =CB28+CC28-CD28 -> 12375632 | CF28: =CE28-CG28 -> 0 | CG28: =CE28 -> 12375632 | CI28: =VLOOKUP($C28,[5]Sheet1!$C$5:$K$139,9,0) -> thuy.hoang@medigoapp.com | CJ28: =VLOOKUP(D28,[1]CNT!$C$6:$AP$113,40,0) -> Sai kênh bán HD1155007 : 100.000đ | CK28: 3 | CL28: =VLOOKUP(D28,[1]CNT!C7:AJ70,15,0) -> 0 | CM28: 27 | CN28: 10 | CO28: 2025 | CP28: =IF((($CO$8-CO28)*12)+($CN$8-CN28)>=12,((($CO$8-CO28)*12)+($CN$8-CN28))-1,0) -> 0 | CQ28: =IF(CP28<12,(($CQ$8-CO28)*12)+($CP$8-CN28),0) -> 7 | CR28: =IF(OR(CP28>12,CP28=12),((CP28-(CS28*12))+((($CQ$8-2024)*12)+($CP$8-4)))+1,0) -> 0 | CS28: =IF(OR(CP28>12,CP28=12),ROUNDDOWN(CP28/12,0),0) -> 0 | CT28: =IF(CQ28>11,ROUNDDOWN(CQ28/12,0),0) -> 0 | CU28: =IF(CR28>11,ROUNDDOWN(CR28/12,0),0) -> 0 | CV28: =IF(CP28=0,0,6000000*1.07^CS28) -> 0 | CW28: =IF(CT28<2,0,6000000+(CT28-1)*500000) -> 0 | CX28: =IF(CU28=0,CV28,IF(CU28<1,0,CV28+CU28*500000)) -> 0 | CY28: =IF(CX28>0,CX28,IF(CW28>0,CW28,6000000)) -> 6000000 | DA28: =CJ28 -> Sai kênh bán HD1155007 : 100.000đ | DB28: Sai thao tác (Sai kênh bán HD1180947): 100.000đ | DF28: =VLOOKUP($D28,'[2]Med Service'!$D$11:$DI$87,110,0) -> 0 | DG28: =VLOOKUP($D28,'[3]BẢNG LƯƠNG'!$C$3:$AH$102,32,0)
A29: 10 | B29: 7 | C29: Le Thi Huyen Tran | D29: Lê Thị Huyền Trân | E29: =IF(OR(G29="CHT",G29="DSBC"),"HĐLĐ",IF(OR(G29="DSTV",G29="Q.CHT"),"HĐTV","HĐCTV")) -> HĐLĐ | F29: Đỗ Quang Đẩu | G29: DSBC | H29: 45510 | I29: 03130767201 | J29: Tiên Phong Bank | K29: 28 | L29: 30 | M29: 252.16 | N29: 8.08 | O29: 16 | S29: =IF(E29="HĐLĐ",5310000,0) -> 5310000 | T29: =IF(500000/28*L29>500000,500000,500000/28*L29) -> 500000 | AA29: =CY29 -> 6000000 | AE29: =IF(E29="HĐTV",AC29/28/8*M29,AA29/28/8*M29) -> 6754285.7 | AF29: =IF(E29="HĐTV",AC29/28/8*N29*1.5,AA29/28/8*N29*1.5) -> 324642.86 | AG29: 0 | AH29: 0 | AI29: 0 | AL29: 0 | AM29: 0 | AN29: 1139700 | AO29: 37807 | AP29: 160 | AQ29: 0 | AS29: 0 | AT29: 0 | AU29: 2352976 | BA29: 0 | BB29: 0 | BC29: 0 | BD29: 0 | BE29: 0 | BF29: 0 | BG29: =SUM(T29:Z29)+SUM(AD29:AZ29)-SUM(BA29:BF29) -> 11109572 | BH29: =S29*17.5% -> 929250 | BI29: =S29*3% -> 159300 | BJ29: =S29*1% -> 53100 | BL29: =SUM(BH29:BK29) -> 1141650 | BM29: =S29*8% -> 424800 | BN29: =S29*1.5% -> 79650 | BO29: =S29*1% -> 53100 | BQ29: =SUM(BM29:BP29) -> 557550 | BR29: =AF29 -> 324642.86 | BS29: =T29+U29+V29+W29 -> 500000 | BT29: =BG29-BS29-BR29 -> 10284929 | BU29: =IF(E29="HĐLĐ",15500000,0) -> 15500000 | BW29: =BV29*6200000 -> 0 | BX29: =BQ29 -> 557550 | BY29: =BU29+BW29+BX29 -> 16057550 | BZ29: =IF(BT29-BY29>0,BT29-BY29,0) -> 0 | CA29: =IF(AND(OR($E29="HĐTV",$E29="HĐCTV"),$BZ29<2000000),0,IF(OR($E29="HĐTV",$E29="HĐCTV"),$BZ29*10%,ROUND(IF($BZ29<=10000000,$BZ29*5%,IF($BZ29<=30000000,$BZ29*10%-500000,IF($BZ29<=60000000,$BZ29*20%-3500000,IF($BZ29<=100000000,$BZ29*30%-9500000,$BZ29*35%-14500000)))),0))) -> 0 | CB29: =ROUND(BG29-BQ29-CA29,0) -> 10552022 | CD29: =AV29+AW29 -> 0 | CE29: =CB29+CC29-CD29 -> 10552022 | CF29: =CE29-CG29 -> 0 | CG29: =CE29 -> 10552022 | CI29: tran.le@medigoapp.com | CJ29: =VLOOKUP(D29,[1]CNT!$C$6:$AP$113,40,0) -> 0 | CK29: 1 | CL29: =VLOOKUP(D29,[1]CNT!C8:AJ71,15,0) -> 0 | CM29: 6 | CN29: 8 | CO29: 2024 | CP29: =IF((($CO$8-CO29)*12)+($CN$8-CN29)>=12,((($CO$8-CO29)*12)+($CN$8-CN29))-1,0) -> 0 | CQ29: =IF(CP29<12,(($CQ$8-CO29)*12)+($CP$8-CN29),0) -> 21 | CR29: =IF(OR(CP29>12,CP29=12),((CP29-(CS29*12))+((($CQ$8-2024)*12)+($CP$8-4)))+1,0) -> 0 | CS29: =IF(OR(CP29>12,CP29=12),ROUNDDOWN(CP29/12,0),0) -> 0 | CT29: =IF(CQ29>11,ROUNDDOWN(CQ29/12,0),0) -> 1 | CU29: =IF(CR29>11,ROUNDDOWN(CR29/12,0),0) -> 0 | CV29: =IF(CP29=0,0,6000000*1.07^CS29) -> 0 | CW29: =IF(CT29<2,0,6000000+(CT29-1)*500000) -> 0 | CX29: =IF(CU29=0,CV29,IF(CU29<1,0,CV29+CU29*500000)) -> 0 | CY29: =IF(CX29>0,CX29,IF(CW29>0,CW29,6000000)) -> 6000000 | DA29: =CJ29 -> 0 | DE29: =VLOOKUP($D29,'[6]Tong hop'!$B$8:$Q$45,15,0) -> 79114 | DF29: =VLOOKUP($D29,'[2]Med Service'!$D$11:$DI$87,110,0) -> 0 | DG29: =VLOOKUP($D29,'[3]BẢNG LƯƠNG'!$C$3:$AH$102,32,0)
G30: =SUM(G23:G92) -> 0 | I30: =SUM(I23:I92) -> 0 | J30: =SUM(J23:J92) -> 0 | L30: =SUM(L23:L29) -> 151 | M30: =SUM(M23:M29) -> 801.82 | N30: =SUM(N23:N29) -> 485.38 | O30: =SUM(O23:O29) -> 72 | P30: =SUM(P23:P29) -> 0 | Q30: =SUM(Q23:Q29) -> 0 | R30: =SUM(R23:R29) -> 0 | S30: =SUM(S23:S29) -> 31860000 | U30: =SUM(U23:U29) -> 0 | V30: =SUM(V23:V29) -> 0 | W30: =SUM(W23:W29) -> 0 | X30: =SUM(X23:X29) -> 0 | Y30: =SUM(Y23:Y29) -> 0 | Z30: =SUM(Z23:Z29) -> 0 | AA30: =SUM(AA23:AA29) -> 42000000 | AB30: =SUM(AB23:AB29) -> 12000000 | ... DC30: =SUM(DC23:DC29) -> 0 | DF30: =VLOOKUP($D30,'[2]Med Service'!$D$11:$DI$87,110,0) -> 0
A31: x | B31: 7 | C31: Thai Thuy Linh | D31: Thái Thùy Linh | E31: =IF(OR(G31="CHT",G31="DSBC"),"HĐLĐ",IF(OR(G31="DSTV",G31="Q.CHT"),"HĐTV","HĐCTV")) -> HĐLĐ | F31: Minh Châu | G31: CHT | H31: 44644 | I31: 070077077837 | J31: Sacombank | K31: 28 | L31: 27 | M31: 202.49 | N31: 49.04 | O31: 0 | S31: =IF(E31="HĐLĐ",5310000,0) -> 5310000 | T31: =IF(500000/28*L31>500000,500000,500000/28*L31) -> 482142.86 | AA31: =CY31 -> 7869400 | AE31: =IF(E31="HĐTV",AC31/28/8*M31,AA31/28/8*M31) -> 7113726.8 | AF31: =IF(E31="HĐTV",AC31/28/8*N31*1.5,AA31/28/8*N31*1.5) -> 2584254.8 | AG31: 1,500,000 | AH31: 0 | AI31: 0 | AL31: 0 | AM31: 0 | AN31: 1446150 | AO31: 107427 | AP31: 0 | AQ31: 500000 | AS31: 0 | AT31: 300000 | AU31: 0 | AZ31: 2017813 | BA31: 0 | BB31: 0 | BC31: 0 | BD31: 0 | BE31: 0 | BF31: 0 | BG31: =SUM(T31:Z31)+SUM(AD31:AZ31)-SUM(BA31:BF31) -> 14551514 | BH31: =S31*17.5% -> 929250 | BI31: =S31*3% -> 159300 | BJ31: =S31*1% -> 53100 | BL31: =SUM(BH31:BK31) -> 1141650 | BM31: =S31*8% -> 424800 | BN31: =S31*1.5% -> 79650 | BO31: =S31*1% -> 53100 | BQ31: =SUM(BM31:BP31) -> 557550 | BR31: =AF31 -> 2584254.8 | BS31: =T31+U31+V31+W31 -> 482142.86 | BT31: =BG31-BS31-BR31 -> 11485117 | BU31: =IF(E31="HĐLĐ",15500000,0) -> 15500000 | BW31: =BV31*6200000 -> 0 | BX31: =BQ31 -> 557550 | BY31: =BU31+BW31+BX31 -> 16057550 | BZ31: =IF(BT31-BY31>0,BT31-BY31,0) -> 0 | CA31: =IF(AND(OR(E31="HĐTV",E31="HĐCTV"),BZ31<2000000),0,IF(OR(E31="HĐTV",E31="HĐCTV"),BZ31*10%,ROUND(+IF(AND(BZ31>=0,BZ31<=5000000),BZ31*0.05,IF(AND(BZ31>5000000,BZ31<=10000000),BZ31*0.1-250000,IF(AND(BZ31>10000000,BZ31<=18000000),BZ31*0.15-750000,IF(AND(BZ31>18000000,BZ31<=32000000),BZ31*0.2-1650000,IF(AND(BZ31>32000000,BZ31<=52000000),BZ31*0.25-3250000,IF(AND(BZ31>52000000,BZ31<=80000000),BZ31*0.3-5850000,BZ31*0.35-9850000)))))),0))) -> 0 | CB31: =ROUND(BG31-BQ31-CA31,0) -> 13993964 | CE31: =CB31+CC31-CD31 -> 13993964 | CF31: =CE31-CG31 -> 0 | CG31: =CE31 -> 13993964 | CI31: linh.thai@medigoapp.com | CJ31: =CG31-CH31 -> 13993964 | CK31: 12 | CL31: =VLOOKUP(D31,[1]CNT!C9:AJ72,15,0) -> 0 | CM31: 24 | CN31: 3 | CO31: 2022 | CP31: =IF((($CO$8-CO31)*12)+($CN$8-CN31)>=12,((($CO$8-CO31)*12)+($CN$8-CN31))-1,0) -> 24 | CQ31: =IF(CP31<12,(($CQ$8-CO31)*12)+($CP$8-CN31),0) -> 0 | CR31: =IF(OR(CP31>12,CP31=12),((CP31-(CS31*12))+((($CQ$8-2024)*12)+($CP$8-4)))+1,0) -> 26 | CS31: =IF(OR(CP31>12,CP31=12),ROUNDDOWN(CP31/12,0),0) -> 2 | CT31: =IF(CQ31>11,ROUNDDOWN(CQ31/12,0),0) -> 0 | CU31: =IF(CR31>11,ROUNDDOWN(CR31/12,0),0) -> 2 | CV31: =IF(CP31=0,0,6000000*1.07^CS31) -> 6869400 | CW31: =IF(CT31<2,0,6000000+(CT31-1)*500000) -> 0 | CX31: =IF(CU31=0,CV31,IF(CU31<1,0,CV31+CU31*500000)) -> 7869400 | CY31: =IF(CX31>0,CX31,IF(CW31>0,CW31,6000000)) -> 7869400 | DA31: =CJ31 -> 13993964 | DE31: =VLOOKUP($D31,'[6]Tong hop'!$B$8:$Q$45,15,0) -> 0 | DF31: =VLOOKUP($D31,'[2]Med Service'!$D$11:$DI$87,110,0) -> 3028734 | DG31: =VLOOKUP($D31,'[3]BẢNG LƯƠNG'!$C$3:$AH$102,32,0) -> Lệch doanh thu HD.BY98NJKV: 60.000đ
A32: 24 | B32: 7 | C32: Trinh Thi Phuong | D32: Trịnh Thị Phượng | E32: =IF(OR(G32="CHT",G32="DSBC"),"HĐLĐ",IF(OR(G32="DSTV",G32="Q.CHT"),"HĐTV","HĐCTV")) -> HĐLĐ | F32: Minh Châu | G32: DSBC | H32: 45096 | I32: 10200014211025 | J32: Đông Nam Á (Seabank) | K32: 28 | L32: 6 | M32: 0 | N32: 46.45 | O32: 0 | S32: =IF(E32="HĐLĐ",5310000,0) -> 5310000 | T32: =IF(500000/28*L32>500000,500000,500000/28*L32) -> 107142.86 | AA32: =CY32 -> 6500000 | AE32: =IF(E32="HĐTV",AC32/28/8*M32,AA32/28/8*M32) -> 0 | AF32: =IF(E32="HĐTV",AC32/28/8*N32*1.5,AA32/28/8*N32*1.5) -> 2021819.2 | AG32: 0 | AH32: 0 | AI32: 321439 | AL32: 0 | AM32: 1301447 | AN32: 0 | AO32: 11205 | AP32: 0 | AQ32: 0 | AS32: 0 | AT32: 0 | AU32: 0 | BA32: 0 | BB32: 0 | BC32: 0 | BD32: 0 | BE32: 0 | BF32: 0 | BG32: =SUM(T32:Z32)+SUM(AD32:AZ32)-SUM(BA32:BF32) -> 3763053.1 | BH32: =S32*17.5% -> 929250 | BI32: =S32*3% -> 159300 | BJ32: =S32*1% -> 53100 | BL32: =SUM(BH32:BK32) -> 1141650 | BM32: =S32*8% -> 424800 | BN32: =S32*1.5% -> 79650 | BO32: =S32*1% -> 53100 | BQ32: =SUM(BM32:BP32) -> 557550 | BR32: =AF32 -> 2021819.2 | BS32: =T32+U32+V32+W32 -> 107142.86 | BT32: =BG32-BS32-BR32 -> 1634091 | BU32: =IF(E32="HĐLĐ",15500000,0) -> 15500000 | BV32: 1 | BW32: =BV32*6200000 -> 6200000 | BX32: =BQ32 -> 557550 | BY32: =BU32+BW32+BX32 -> 22257550 | BZ32: =IF(BT32-BY32>0,BT32-BY32,0) -> 0 | CA32: =IF(AND(OR(E32="HĐTV",E32="HĐCTV"),BZ32<2000000),0,IF(OR(E32="HĐTV",E32="HĐCTV"),BZ32*10%,ROUND(+IF(AND(BZ32>=0,BZ32<=5000000),BZ32*0.05,IF(AND(BZ32>5000000,BZ32<=10000000),BZ32*0.1-250000,IF(AND(BZ32>10000000,BZ32<=18000000),BZ32*0.15-750000,IF(AND(BZ32>18000000,BZ32<=32000000),BZ32*0.2-1650000,IF(AND(BZ32>32000000,BZ32<=52000000),BZ32*0.25-3250000,IF(AND(BZ32>52000000,BZ32<=80000000),BZ32*0.3-5850000,BZ32*0.35-9850000)))))),0))) -> 0 | CB32: =ROUND(BG32-BQ32-CA32,0) -> 3205503 | CD32: =AV32+AW32 -> 0 | CE32: =CB32+CC32-CD32 -> 3205503 | CF32: =CE32-CG32 -> 0 | CG32: =CE32 -> 3205503 | CI32: phuong.trinh@medigoapp.com | CJ32: =VLOOKUP(D32,[1]CNT!$C$6:$AP$113,40,0) -> 0 | CK32: 4 | CL32: =VLOOKUP(D32,[1]CNT!C10:AJ73,15,0) -> 0 | CM32: 19 | CN32: 6 | CO32: 2023 | CP32: =IF((($CO$8-CO32)*12)+($CN$8-CN32)>=12,((($CO$8-CO32)*12)+($CN$8-CN32))-1,0) -> 0 | CQ32: =IF(CP32<12,(($CQ$8-CO32)*12)+($CP$8-CN32),0) -> 35 | CR32: =IF(OR(CP32>12,CP32=12),((CP32-(CS32*12))+((($CQ$8-2024)*12)+($CP$8-4)))+1,0) -> 0 | CS32: =IF(OR(CP32>12,CP32=12),ROUNDDOWN(CP32/12,0),0) -> 0 | CT32: =IF(CQ32>11,ROUNDDOWN(CQ32/12,0),0) -> 2 | CU32: =IF(CR32>11,ROUNDDOWN(CR32/12,0),0) -> 0 | CV32: =IF(CP32=0,0,6000000*1.07^CS32) -> 0 | CW32: =IF(CT32<2,0,6000000+(CT32-1)*500000) -> 6500000 | CX32: =IF(CU32=0,CV32,IF(CU32<1,0,CV32+CU32*500000)) -> 0 | CY32: =IF(CX32>0,CX32,IF(CW32>0,CW32,6000000)) -> 6500000 | DA32: =CJ32 -> 0 | DF32: =VLOOKUP($D32,'[2]Med Service'!$D$11:$DI$87,110,0) -> 0 | DG32: =VLOOKUP($D32,'[3]BẢNG LƯƠNG'!$C$3:$AH$102,32,0)
A33: x | B33: 7 | C33: Phan Cong Vu Tai | D33: Phan Công Vũ Tài | E33: =IF(OR(G33="CHT",G33="DSBC"),"HĐLĐ",IF(OR(G33="DSTV",G33="Q.CHT"),"HĐTV","HĐCTV")) -> HĐLĐ | F33: Minh Châu | G33: DSBC | H33: 26/01/2026 | I33: 02446989901 | J33: Tp Bank | K33: 28 | L33: 28 | M33: 69.75 | N33: 185.25 | O33: 16 | S33: =IF(E33="HĐLĐ",5310000,0) -> 5310000 | T33: =IF(500000/28*L33>500000,500000,500000/28*L33) -> 500000 | AA33: =CY33 -> 6000000 | AE33: =IF(E33="HĐTV",AC33/28/8*M33,AA33/28/8*M33) -> 1868303.6 | AF33: =IF(E33="HĐTV",AC33/28/8*N33*1.5,AA33/28/8*N33*1.5) -> 7443080.4 | AG33: 0 | AH33: 0 | AI33: 1285714 | AL33: 4000000 | AM33: 2145059 | AN33: 4854450 | AO33: 15362 | AP33: 0 | AQ33: 0 | AS33: 0 | AT33: 0 | AU33: 0 | BA33: 0 | BB33: 0 | BC33: 100000 | BD33: 0 | BE33: 90000 | BF33: 0 | BG33: =SUM(T33:Z33)+SUM(AD33:AZ33)-SUM(BA33:BF33) -> 21921969 | BH33: =S33*17.5% -> 929250 | BI33: =S33*3% -> 159300 | BJ33: =S33*1% -> 53100 | BL33: =SUM(BH33:BK33) -> 1141650 | BM33: =S33*8% -> 424800 | BN33: =S33*1.5% -> 79650 | BO33: =S33*1% -> 53100 | BQ33: =SUM(BM33:BP33) -> 557550 | BR33: =AF33 -> 7443080.4 | BS33: =T33+U33+V33+W33 -> 500000 | BT33: =BG33-BS33-BR33 -> 13978889 | BU33: =15500000-BU51 -> 11285087 | BW33: =BV33*6200000 -> 0 | BX33: =BQ33 -> 557550 | BY33: =BU33+BW33+BX33 -> 11842637 | BZ33: =IF(BT33-BY33>0,BT33-BY33,0) -> 2136251.5 | CA33: =IF(AND(OR($E33="HĐTV",$E33="HĐCTV"),$BZ33<2000000),0,IF(OR($E33="HĐTV",$E33="HĐCTV"),$BZ33*10%,ROUND(IF($BZ33<=10000000,$BZ33*5%,IF($BZ33<=30000000,$BZ33*10%-500000,IF($BZ33<=60000000,$BZ33*20%-3500000,IF($BZ33<=100000000,$BZ33*30%-9500000,$BZ33*35%-14500000)))),0))) -> 106813 | CB33: =ROUND(BG33-BQ33-CA33,0) -> 21257606 | CD33: 6000000 | CE33: =CB33+CC33-CD33 -> 15257606 | CF33: =CE33-CG33 -> 0 | CG33: =CE33 -> 15257606 | CI33: =VLOOKUP($C33,[5]Sheet1!$C$5:$K$139,9,0) -> tai.phan@medigoapp.com | CJ33: =CG33-CH33 -> 15257606 | CK33: 4 | CL33: =VLOOKUP(D33,[1]CNT!C8:AJ71,15,0) -> 0 | CM33: 26 | CN33: 1 | CO33: 2026 | CP33: =IF((($CO$8-CO33)*12)+($CN$8-CN33)>=12,((($CO$8-CO33)*12)+($CN$8-CN33))-1,0) -> 0 | CQ33: =IF(CP33<12,(($CQ$8-CO33)*12)+($CP$8-CN33),0) -> 4 | CR33: =IF(OR(CP33>12,CP33=12),((CP33-(CS33*12))+((($CQ$8-2024)*12)+($CP$8-4)))+1,0) -> 0 | CS33: =IF(OR(CP33>12,CP33=12),ROUNDDOWN(CP33/12,0),0) -> 0 | CT33: =IF(CQ33>11,ROUNDDOWN(CQ33/12,0),0) -> 0 | CU33: =IF(CR33>11,ROUNDDOWN(CR33/12,0),0) -> 0 | CV33: =IF(CP33=0,0,6000000*1.07^CS33) -> 0 | CW33: =IF(CT33<2,0,6000000+(CT33-1)*500000) -> 0 | CX33: =IF(CU33=0,CV33,IF(CU33<1,0,CV33+CU33*500000)) -> 0 | CY33: 6000000 | DA33: =CJ33 -> 15257606 | DB33: Sai thao tác - xuất nhầm 2 HD chéo với nhau (HD1194853): 100.000đ Đối soát HD1133288 | DF33: =VLOOKUP($D33,'[2]Med Service'!$D$11:$DI$87,110,0) -> 0 | DG33: =VLOOKUP($D33,'[3]BẢNG LƯƠNG'!$C$3:$AH$102,32,0)
D34: Đoàn Quốc Tâm | E34: =IF(OR(G34="CHT",G34="DSBC"),"HĐLĐ",IF(OR(G34="DSTV",G34="Q.CHT"),"HĐTV","HĐCTV")) -> HĐLĐ | F34: Minh Châu | G34: DSBC | H34: 25/3/2024 | I34: 23241857 | J34: ACB | K34: 28 | L34: 30 | M34: 283.54 | N34: 55.74 | O34: 16 | S34: =IF(E34="HĐLĐ",5310000,0) -> 5310000 | T34: =IF(500000/28*L34>500000,500000,500000/28*L34) -> 500000 | AA34: 6500000 | AB34: =AA34 -> 6500000 | AC34: =IF(E34="HĐTV",AB34*85%,0) -> 0 | AD34: =IF(E34="HĐTV",AC34/K34*L34,AB34/K34*L34) -> 6964285.7 | AE34: =IF(E34="HĐTV",AC34/28/8*M34,AA34/28/8*M34) -> 8227723.2 | AF34: =IF(E34="HĐTV",AC34/28/8*N34*1.5,AA34/28/8*N34*1.5) -> 2426183 | AG34: 0 | AH34: 0 | AL34: 1000000 | AM34: 0 | AN34: 3048900 | AO34: 68625 | AP34: 0 | AQ34: 0 | AS34: 0 | AT34: 0 | AU34: 0 | BA34: 0 | BB34: 0 | BC34: 0 | BD34: 0 | BE34: 0 | BF34: 0 | BG34: =SUM(T34:Z34)+SUM(AD34:AZ34)-SUM(BA34:BF34) -> 22235717 | BH34: =S34*17.5% -> 929250 | BI34: =S34*3% -> 159300 | BJ34: =S34*1% -> 53100 | BL34: =SUM(BH34:BK34) -> 1141650 | BM34: =S34*8% -> 424800 | BN34: =S34*1.5% -> 79650 | BO34: =S34*1% -> 53100 | BQ34: =SUM(BM34:BP34) -> 557550 | CE34: =CB34+CC34-CD34 -> 0 | CY34: =IF(CX34>0,CX34,IF(CW34>0,CW34,6000000)) -> 6000000
A35: 20 | B35: 7 | C35: Nguyen Ngoc Thuy | D35: Nguyễn Ngọc Thùy | E35: =IF(OR(G35="CHT",G35="DSBC"),"HĐLĐ",IF(OR(G35="DSTV",G35="Q.CHT"),"HĐTV","HĐCTV")) -> HĐTV | F35: Minh Châu | G35: DSTV | H35: 14/07/2026 | I35: 0798366668888 | J35: MB Bank | K35: 28 | L35: 28 | M35: 206.43 | N35: 32.22 | O35: 0 | S35: =IF(E35="HĐLĐ",5310000,0) -> 0 | T35: =IF(500000/28*L35>500000,500000,500000/28*L35) -> 500000 | AA35: 6000000 | AB35: =AA35 -> 6000000 | AC35: 6000000 | AD35: =IF(E35="HĐTV",AC35/K35*L35,AB35/K35*L35) -> 6000000 | AE35: =IF(E35="HĐTV",AC35/28/8*M35,AA35/28/8*M35) -> 5529375 | AF35: =IF(E35="HĐTV",AC35/28/8*N35*1.5,AA35/28/8*N35*1.5) -> 1294553.6 | AG35: 0 | AH35: 0 | AL35: 1000000 | AM35: 0 | AN35: 380880 | AO35: 0 | AP35: 0 | AQ35: 0 | AS35: 0 | AT35: 0 | AU35: 0 | BA35: 0 | BB35: 0 | BC35: 0 | BD35: 0 | BE35: 0 | BF35: 500000 | BG35: =SUM(T35:Z35)+SUM(AD35:AZ35)-SUM(BA35:BF35) -> 14204809 | BH35: =S35*17.5% -> 0 | BI35: =S35*3% -> 0 | BJ35: =S35*1% -> 0 | BL35: =SUM(BH35:BK35) -> 0 | BM35: =S35*8% -> 0 | BN35: =S35*1.5% -> 0 | BO35: =S35*1% -> 0 | BQ35: =SUM(BM35:BP35) -> 0 | BR35: =AF35 -> 1294553.6 | BS35: =T35+U35+V35+W35 -> 500000 | BT35: =BG35-BS35-BR35 -> 12410255 | BU35: =IF(E35="HĐLĐ",15500000,0) -> 0 | BX35: =BQ35 -> 0 | BY35: =BU35+BW35+BX35 -> 0 | BZ35: =IF(BT35-BY35>0,BT35-BY35,0) -> 12410255 | CA35: =IF(AND(OR($E35="HĐTV",$E35="HĐCTV"),$BZ35<2000000),0,IF(OR($E35="HĐTV",$E35="HĐCTV"),$BZ35*10%,ROUND(IF($BZ35<=10000000,$BZ35*5%,IF($BZ35<=30000000,$BZ35*10%-500000,IF($BZ35<=60000000,$BZ35*20%-3500000,IF($BZ35<=100000000,$BZ35*30%-9500000,$BZ35*35%-14500000)))),0))) -> 1241025.5 | CB35: =ROUND(BG35-BQ35-CA35,0) -> 12963783 | CE35: =CB35+CC35-CD35 -> 12963783 | CF35: =CE35-CG35 -> 0 | CG35: =CE35 -> 12963783 | CI35: thuy.nguyen@medigoapp.com | CK35: 2 | CY35: =IF(CX35>0,CX35,IF(CW35>0,CW35,6000000)) -> 6000000 | DB35: Khấu hao đồng phục
J36: =SUM(J31:J92) -> 0 | L36: =SUM(L31:L35) -> 119 | M36: =SUM(M31:M35) -> 762.21 | N36: =SUM(N31:N35) -> 368.7 | O36: =SUM(O31:O35) -> 32 | P36: =SUM(P31:P35) -> 0 | Q36: =SUM(Q31:Q35) -> 0 | R36: =SUM(R31:R35) -> 0 | S36: =SUM(S31:S35) -> 21240000 | U36: =SUM(U31:U35) -> 0 | V36: =SUM(V31:V35) -> 0 | W36: =SUM(W31:W35) -> 0 | X36: =SUM(X31:X35) -> 0 | Y36: =SUM(Y31:Y35) -> 0 | Z36: =SUM(Z31:Z35) -> 0 | AA36: =SUM(AA31:AA35) -> 32869400 | AB36: =SUM(AB31:AB35) -> 12500000 | ... AI36: =SUM(AI31:AI35) -> 1607153 | AL36: =SUM(AL31:AL35) -> 6000000 | AM36: =SUM(AM31:AM35) -> 3446506 | AN36: =SUM(AN31:AN35) -> 9730380 | AO36: =SUM(AO31:AO35) -> 202619 | AP36: =SUM(AP31:AP35) -> 0 | AQ36: =SUM(AQ31:AQ35) -> 500000 | AR36: =SUM(AR31:AR35) -> 0 | AS36: =SUM(AS31:AS35) -> 0 | ... DC36: =SUM(DC31:DC35) -> 0 | DF36: =VLOOKUP($D36,'[2]Med Service'!$D$11:$DI$87,110,0) -> 0
A37: 27 | B37: 7 | C37: Ho Thi Minh Hoa | D37: Hồ Thị Minh Hòa | E37: =IF(OR(G37="CHT",G37="DSBC"),"HĐLĐ",IF(OR(G37="DSTV",G37="Q.CHT"),"HĐTV","HĐCTV")) -> HĐLĐ | F37: Lê Bình | G37: CHT | H37: 45352 | I37: 0051000542226 | J37: Vietcombank | K37: 28 | L37: 28 | M37: 272.06 | N37: 6.88 | O37: 0 | S37: =IF(E37="HĐLĐ",5310000,0) -> 5310000 | T37: =IF(500000/28*L37>500000,500000,500000/28*L37) -> 500000 | AA37: =CY37 -> 6500000 | AE37: =IF(E37="HĐTV",AC37/28/8*M37,AA37/28/8*M37) -> 7894598.2 | AF37: =IF(E37="HĐTV",AC37/28/8*N37*1.5,AA37/28/8*N37*1.5) -> 299464.29 | AG37: 1500000 | AH37: 0 | AI37: 0 | AL37: 0 | AM37: 0 | AN37: 1265850 | AO37: 0 | AP37: 60 | AQ37: 0 | AS37: 45000 | AT37: 300000 | AU37: 0 | BA37: 0 | BB37: 0 | BC37: 0 | BD37: 0 | BE37: 0 | BF37: 0 | BG37: =SUM(T37:Z37)+SUM(AD37:AZ37)-SUM(BA37:BF37) -> 11804972 | BH37: =S37*17.5% -> 929250 | BI37: =S37*3% -> 159300 | BJ37: =S37*1% -> 53100 | BL37: =SUM(BH37:BK37) -> 1141650 | BM37: =S37*8% -> 424800 | BN37: =S37*1.5% -> 79650 | BO37: =S37*1% -> 53100 | BQ37: =SUM(BM37:BP37) -> 557550 | BR37: =AF37 -> 299464.29 | BS37: =T37+U37+V37+W37 -> 500000 | BT37: =BG37-BS37-BR37 -> 11005508 | BU37: =15500000-BU15 -> 14580424 | BW37: =BV37*6200000 -> 0 | BX37: =BQ37 -> 557550 | BY37: =BU37+BW37+BX37 -> 15137974 | BZ37: =IF(BT37-BY37>0,BT37-BY37,0) -> 0 | CA37: =IF(AND(OR($E37="HĐTV",$E37="HĐCTV"),$BZ37<2000000),0,IF(OR($E37="HĐTV",$E37="HĐCTV"),$BZ37*10%,ROUND(IF($BZ37<=10000000,$BZ37*5%,IF($BZ37<=30000000,$BZ37*10%-500000,IF($BZ37<=60000000,$BZ37*20%-3500000,IF($BZ37<=100000000,$BZ37*30%-9500000,$BZ37*35%-14500000)))),0))) -> 0 | CB37: =ROUND(BG37-BQ37-CA37,0) -> 11247423 | CD37: =AV37+AW37 -> 0 | CE37: =CB37+CC37-CD37 -> 11247423 | CF37: =CE37-CG37 -> 0 | CG37: =CE37 -> 11247423 | CI37: hoa.ho@medigoapp.com | CJ37: =VLOOKUP(D37,[1]CNT!$C$6:$AP$113,40,0) -> 0 | CK37: 11 | CL37: =VLOOKUP(D37,[1]CNT!C36:AJ99,15,0) -> 0 | CM37: 1 | CN37: 3 | CO37: 2024 | CP37: =IF((($CO$8-CO37)*12)+($CN$8-CN37)>=12,((($CO$8-CO37)*12)+($CN$8-CN37))-1,0) -> 0 | CQ37: =IF(CP37<12,(($CQ$8-CO37)*12)+($CP$8-CN37),0) -> 26 | CR37: =IF(OR(CP37>12,CP37=12),((CP37-(CS37*12))+((($CQ$8-2024)*12)+($CP$8-4)))+1,0) -> 0 | CS37: =IF(OR(CP37>12,CP37=12),ROUNDDOWN(CP37/12,0),0) -> 0 | CT37: =IF(CQ37>11,ROUNDDOWN(CQ37/12,0),0) -> 2 | CU37: =IF(CR37>11,ROUNDDOWN(CR37/12,0),0) -> 0 | CV37: =IF(CP37=0,0,6000000*1.07^CS37) -> 0 | CW37: =IF(CT37<2,0,6000000+(CT37-1)*500000) -> 6500000 | CX37: =IF(CU37=0,CV37,IF(CU37<1,0,CV37+CU37*500000)) -> 0 | CY37: =IF(CX37>0,CX37,IF(CW37>0,CW37,6000000)) -> 6500000 | DF37: =VLOOKUP($D37,'[2]Med Service'!$D$11:$DI$87,110,0) -> 1035547 | DG37: =VLOOKUP($D37,'[3]BẢNG LƯƠNG'!$C$3:$AH$102,32,0)
C38: Nguyen Tran Ngoc Phuong | D38: Nguyễn Trần Ngọc Phương | E38: =IF(OR(G38="CHT",G38="DSBC"),"HĐLĐ",IF(OR(G38="DSTV",G38="Q.CHT"),"HĐTV","HĐCTV")) -> HĐTV | F38: Lê Bình | G38: Q.CHT | H38: 46196 | I38: 0721000550950 | J38: Vietcombank | K38: 26 | L38: 1 | M38: 10 | N38: 0 | O38: 0 | S38: =IF(E38="HĐLĐ",5310000,0) -> 0 | T38: =IF(500000/28*L38>500000,500000,500000/28*L38) -> 17857.143 | AA38: =CY38 -> 6000000 | AB38: =AA38 -> 6000000 | AC38: 6000000 | AD38: =IF(E38="HĐTV",AC38/K38*L38,AB38/K38*L38) -> 230769.23 | AE38: =IF(E38="HĐTV",AC38/28/8*M38,AA38/28/8*M38) -> 267857.14 | AF38: =IF(E38="HĐTV",AC38/28/8*N38*1.5,AA38/28/8*N38*1.5) -> 0 | AG38: 0 | AH38: 0 | AI38: 0 | AL38: 0 | AM38: 0 | AN38: 0 | AO38: 6601 | AP38: 0 | AQ38: 0 | AS38: 0 | AT38: 0 | AU38: 0 | BA38: 0 | BB38: 0 | BC38: 0 | BD38: 0 | BE38: 0 | BF38: 0 | BG38: =SUM(T38:Z38)+SUM(AD38:AZ38)-SUM(BA38:BF38) -> 523084.52 | BH38: =S38*17.5% -> 0 | BI38: =S38*3% -> 0 | BJ38: =S38*1% -> 0 | BL38: =SUM(BH38:BK38) -> 0 | BM38: =S38*8% -> 0 | BN38: =S38*1.5% -> 0 | BO38: =S38*1% -> 0 | BQ38: =SUM(BM38:BP38) -> 0 | CE38: =CB38+CC38-CD38 -> 0 | CK38: 4 | CY38: =IF(CX38>0,CX38,IF(CW38>0,CW38,6000000)) -> 6000000
