Workbook

Sheet data
A1: Nhà thuốc | B1: Tên nhân viên | C1: Số giao dịch off | D1: Doanh thu off | E1: Số giao dịch onl | F1: Doanh thu onl | G1: Tổng giao dịch | H1: Doanh thu tổng | J1: 46244
A2: Hàng Bông | B2: Nguyễn Mạnh Tuấn | C2: 189 | D2: 39636120 | E2: 105 | F2: 19335000 | G2: 294 | H2: 58971120
A3: Hàng Bông | B3: Vũ Thanh Hằng | C3: 291 | D3: 96198960 | E3: 78 | F3: 24633300 | G3: 369 | H3: 120832260
A4: Hàng Bông | B4: Đinh Thị Khánh Ly | C4: 457 | D4: 114122670 | E4: 122 | F4: 29387520 | G4: 579 | H4: 143510190
A5: Hàng Bông | B5: Đinh Thị Lan Anh | C5: 232 | D5: 40092210 | E5: 45 | F5: 9655900 | G5: 277 | H5: 49748110
A6: Lê Bình | B6: Hoàng Lâm Gia Bảo | C6: 98 | D6: 10853100 | E6: 35 | F6: 6323800 | G6: 133 | H6: 17176900
A7: Lê Bình | B7: Hồ Thị Minh Hòa | C7: 82 | D7: 9714300 | E7: 35 | F7: 6755520 | G7: 117 | H7: 16469820
A8: Lê Bình | B8: Đinh Hoài Bảo | C8: 142 | D8: 10502600 | E8: 73 | F8: 11321850 | G8: 215 | H8: 21824450
A9: Minh Châu | B9: Phan Công Vũ Tài | C9: 270 | D9: 24320200 | E9: 45 | F9: 7240600 | G9: 315 | H9: 31560800
A10: Minh Châu | B10: Thái Thùy Linh | C10: 178 | D10: 14565000 | E10: 23 | F10: 4635700 | G10: 201 | H10: 19200700
A11: Minh Châu | B11: Trịnh Thị Phượng | C11: 263 | D11: 21466900 | E11: 28 | F11: 3104300 | G11: 291 | H11: 24571200
A12: Minh Châu | B12: Đoàn Quốc Tâm | C12: 270 | D12: 20899000 | E12: 64 | F12: 8884600 | G12: 334 | H12: 29783600
A13: Nam Hòa | B13: Bùi Thị Thanh Thủy | C13: 84 | D13: 4062300 | E13: 37 | F13: 9341550 | G13: 121 | H13: 13403850
A14: Nam Hòa | B14: Nguyễn Thị Huyền Trang | C14: 81 | D14: 4582400 | E14: 23 | F14: 3041400 | G14: 104 | H14: 7623800
A15: Nam Hòa | B15: Nguyễn Trí Nghĩa | C15: 5 | D15: 451000 | G15: 5 | H15: 451000
A16: Nam Hòa | B16: Phan Công Vũ Tài | C16: 5 | D16: 670000 | G16: 5 | H16: 670000
A17: Nam Hòa | B17: Thanh Thảo | C17: 1 | D17: 28000 | G17: 1 | H17: 28000
A18: Nam Hòa | B18: Trần Thị Ánh Nguyệt | C18: 259 | D18: 19912400 | E18: 71 | F18: 14465500 | G18: 330 | H18: 34377900
A19: Nam Hòa | B19: Đỗ Thị Kim Tiến | C19: 120 | D19: 10038100 | E19: 31 | F19: 4734900 | G19: 151 | H19: 14773000
A20: Nguyễn Chí Thanh | B20: Lê Thị Quỳnh Trâm | C20: 98 | D20: 6196900 | E20: 69 | F20: 15945300 | G20: 167 | H20: 22142200
A21: Nguyễn Chí Thanh | B21: Nguyễn Thị Hồng Hạnh | C21: 214 | D21: 16276800 | E21: 20 | F21: 2583900 | G21: 234 | H21: 18860700
A22: Nguyễn Chí Thanh | B22: Nguyễn Trí Nghĩa | C22: 93 | D22: 4340800 | E22: 14 | F22: 1063100 | G22: 107 | H22: 5403900
A23: Nguyễn Chí Thanh | B23: Trần Hoàng Khánh | C23: 289 | D23: 19347200 | E23: 66 | F23: 6917900 | G23: 355 | H23: 26265100
A24: Nguyễn Chí Thanh | B24: Đỗ Thị Phương Thảo | C24: 116 | D24: 12809525 | E24: 74 | F24: 16090400 | G24: 190 | H24: 28899925
A25: Nguyễn Thị Thập | B25: Cao Trọng Nhân | C25: 222 | D25: 18344100 | E25: 114 | F25: 26551400 | G25: 336 | H25: 44895500
A26: Nguyễn Thị Thập | B26: Nguyễn Trí Nghĩa | C26: 118 | D26: 7306400 | E26: 93 | F26: 15372400 | G26: 211 | H26: 22678800
A27: Nguyễn Thị Thập | B27: Triệu Thị Ngọc Lý | C27: 106 | D27: 7807300 | E27: 106 | F27: 33740100 | G27: 212 | H27: 41547400
A28: Nguyễn Thị Thập | B28: Trần Thành Đạt | C28: 193 | D28: 11607800 | E28: 77 | F28: 30478100 | G28: 270 | H28: 42085900
A29: Nguyễn Văn Quá | B29: Hồ Ngọc Lý | C29: 176 | D29: 13479200 | E29: 23 | F29: 2573200 | G29: 199 | H29: 16052400
... A38: Trường Sa | B38: Hồ Thị Minh Hòa | C38: 20 | D38: 1503600 | E38: 14 | F38: 2401800 | G38: 34 | H38: 3905400
A39: Trường Sa | B39: Medigo | E39: 1 | F39: 40000 | G39: 1 | H39: 40000
A40: Trường Sa | B40: Nguyễn Trần Ngọc Phương | C40: 173 | D40: 13524200 | E40: 89 | F40: 13101600 | G40: 262 | H40: 26625800
A41: Trường Sa | B41: Ngô Trần Tuyết Vy | C41: 255 | D41: 15509600 | E41: 157 | F41: 26477700 | G41: 412 | H41: 41987300
A42: Trường Sa | B42: Phạm Nguyễn Ngọc Quý | C42: 139 | D42: 11180100 | E42: 63 | F42: 8428150 | G42: 202 | H42: 19608250
A43: Trường Sa | B43: Trần Thị Kim Khánh | C43: 168 | D43: 14610900 | E43: 124 | F43: 24086100 | G43: 292 | H43: 38697000
A44: Trường Sa | B44: Trịnh Thị Phượng | C44: 19 | D44: 1535000 | E44: 4 | F44: 689000 | G44: 23 | H44: 2224000
A45: Đường Láng | B45: Hứa Thị Kim Thoa | C45: 64 | D45: 6554300 | E45: 12 | F45: 1017500 | G45: 76 | H45: 7571800
A46: Đường Láng | B46: Lê Thị Soạn | C46: 271 | D46: 33194701 | E46: 198 | F46: 27633600 | G46: 469 | H46: 60828301
A47: Đường Láng | B47: Nguyễn Thị Mai Duyên | C47: 184 | D47: 22172140 | E47: 204 | F47: 48202967 | G47: 388 | H47: 70375107
A48: Đường Láng | B48: Nguyễn Thị Tâm | C48: 216 | D48: 30217000 | E48: 148 | F48: 41141400 | G48: 364 | H48: 71358400
...

Sheet kpi dược sĩ
A1: Dữ liệu cập nhật đến ngày | C1: =data!J1 | O1: Mức hoành thành KPI | R1: Mức hoành thành KPI
A2: Nhà thuốc | B2: Nhân viên | C2: Chức danh | D2: KPI trung bình bill | E2: Trung bình bill | F2: KPI doanh thu CK+Combo+NY3/ngày | G2: CK + Combo + NY3/ngày | H2: KPI Doanh thu/ngày (100%) | I2: Doanh thu thực/ngày | J2: % Hoàn thành KPI | K2: Thưởng KPI | L2: Hệ số * Dự án | M2: Thưởng Dự án | N2: Thưởng Dự án + KPI + HH | O2: 0.8 | P2: 0.9 | Q2: 1 | R2: 0.8 | S2: 0.9 | T2: 1 | U2: KPIs Doanh thu/ngày | V2: KPIs Doanh thu/tháng | W2: Số giao dịch off | X2: Doanh thu off | Y2: Trung bình bill off | Z2: Số giao dịch onl | AA2: Doanh thu onl | AB2: Trung bình bill onl | AC2: Tổng giao dịch | AD2: Doanh thu tổng | AE2: Trung bình Bill
A3: Trường Sa | B3: Nguyễn Trần Ngọc Phương | C3: Q.CHT | D3: 150000 | E3: =AE3 | F3: 21000 | G3: =IFERROR(SUMIF('Dự án T8'!$B:$B, $B3, 'Dự án T8'!$D:$D), 0) | H3: =Q3 | I3: =(AD3/DAY($C$1)) | J3: =I3/H3 | K3: =_xlfn.XLOOKUP(B3, 'kpi nhà thuốc'!$A:$A, 'kpi nhà thuốc'!$G:$G, IF(AND(OR(C3="DSXC", C3="DSCD", C3="DSBC", C3="DSTV", C3="Q.CHT"), G3>=F3), AD3 * _xlfn.IFS(AND(I3>=T3, E3>=D3), 0.015, I3>=T3, 0.013, AND(I3>=S3, E3>=D3), 0.013, I3>=S3, 0.011, AND(I3>=R3, E3>=D3), 0.012, I3>=R3, 0.010, TRUE, 0), 0)) | L3: =IF(C3="DSTV","", IF(J3<0.6, 0.8, 1)) | M3: =IFERROR(SUMIF('Dự án T8'!$B:$B, $B3, 'Dự án T8'!$M:$M)*$L3, 0) | N3: =N(K3)+M3 | O3: =CEILING(R3, 100000) | P3: =CEILING(S3, 100000) | Q3: =CEILING(T3, 100000) | R3: =U3*$R$2 | S3: =U3*$S$2 | T3: =U3*$T$2 | U3: =V3/DAY($C$1) | V3: 110000000 | W3: =IFERROR(SUMIFS(data!$C:$C, data!$A:$A, $A3, data!$B:$B, $B3), 0) | X3: =IFERROR(SUMIF(data!$B:$B, $B3, data!$D:$D), 0) | Y3: =IF(W3>0, X3/W3, 0) | Z3: =IFERROR(SUMIFS(data!$E:$E, data!$A:$A, $A3, data!$B:$B, $B3), 0) | AA3: =IFERROR(SUMIF(data!$B:$B, $B3, data!$F:$F), 0) | AB3: =IF(Z3>0, AA3/Z3, 0) | AC3: =W3+Z3 | AD3: =X3+AA3 | AE3: =IF(AC3>0, AD3/AC3, 0)
A4: Trường Sa | B4: Phạm Nguyễn Ngọc Quý | C4: DSXC | D4: 175000 | E4: =AE4 | F4: 19000 | G4: =IFERROR(SUMIF('Dự án T8'!$B:$B, $B4, 'Dự án T8'!$D:$D), 0) | H4: =Q4 | I4: =(AD4/DAY($C$1)) | J4: =I4/H4 | K4: =_xlfn.XLOOKUP(B4, 'kpi nhà thuốc'!$A:$A, 'kpi nhà thuốc'!$G:$G, IF(AND(OR(C4="DSXC", C4="DSCD", C4="DSBC", C4="DSTV", C4="Q.CHT"), G4>=F4), AD4 * _xlfn.IFS(AND(I4>=T4, E4>=D4), 0.015, I4>=T4, 0.013, AND(I4>=S4, E4>=D4), 0.013, I4>=S4, 0.011, AND(I4>=R4, E4>=D4), 0.012, I4>=R4, 0.010, TRUE, 0), 0)) | L4: =IF(C4="DSTV","", IF(J4<0.6, 0.8, 1)) | M4: =IFERROR(SUMIF('Dự án T8'!$B:$B, $B4, 'Dự án T8'!$M:$M)*$L4, 0) | N4: =N(K4)+M4 | O4: =CEILING(R4, 100000) | P4: =CEILING(S4, 100000) | Q4: =CEILING(T4, 100000) | R4: =U4*$R$2 | S4: =U4*$S$2 | T4: =U4*$T$2 | U4: =V4/DAY($C$1) | V4: 115000000 | W4: =IFERROR(SUMIFS(data!$C:$C, data!$A:$A, $A4, data!$B:$B, $B4), 0) | X4: =IFERROR(SUMIF(data!$B:$B, $B4, data!$D:$D), 0) | Y4: =IF(W4>0, X4/W4, 0) | Z4: =IFERROR(SUMIFS(data!$E:$E, data!$A:$A, $A4, data!$B:$B, $B4), 0) | AA4: =IFERROR(SUMIF(data!$B:$B, $B4, data!$F:$F), 0) | AB4: =IF(Z4>0, AA4/Z4, 0) | AC4: =W4+Z4 | AD4: =X4+AA4 | AE4: =IF(AC4>0, AD4/AC4, 0)
A5: Trường Sa | B5: Nguyễn Ngọc Anh Thư | C5: DSCD (TV) | D5: 150000 | E5: =AE5 | F5: 0 | G5: =IFERROR(SUMIF('Dự án T8'!$B:$B, $B5, 'Dự án T8'!$D:$D), 0) | H5: =Q5 | I5: =(AD5/DAY($C$1)) | J5: =I5/H5 | K5: =_xlfn.XLOOKUP(B5, 'kpi nhà thuốc'!$A:$A, 'kpi nhà thuốc'!$G:$G, IF(AND(OR(C5="DSXC", C5="DSCD", C5="DSBC", C5="DSTV", C5="Q.CHT"), G5>=F5), AD5 * _xlfn.IFS(AND(I5>=T5, E5>=D5), 0.015, I5>=T5, 0.013, AND(I5>=S5, E5>=D5), 0.013, I5>=S5, 0.011, AND(I5>=R5, E5>=D5), 0.012, I5>=R5, 0.010, TRUE, 0), 0)) | L5: =IF(C5="DSTV","", IF(J5<0.6, 0.8, 1)) | M5: =IFERROR(SUMIF('Dự án T8'!$B:$B, $B5, 'Dự án T8'!$M:$M)*$L5, 0) | N5: =N(K5)+M5 | O5: =CEILING(R5, 100000) | P5: =CEILING(S5, 100000) | Q5: =CEILING(T5, 100000) | R5: =U5*$R$2 | S5: =U5*$S$2 | T5: =U5*$T$2 | U5: =V5/DAY($C$1) | V5: 95000000 | W5: =IFERROR(SUMIFS(data!$C:$C, data!$A:$A, $A5, data!$B:$B, $B5), 0) | X5: =IFERROR(SUMIF(data!$B:$B, $B5, data!$D:$D), 0) | Y5: =IF(W5>0, X5/W5, 0) | Z5: =IFERROR(SUMIFS(data!$E:$E, data!$A:$A, $A5, data!$B:$B, $B5), 0) | AA5: =IFERROR(SUMIF(data!$B:$B, $B5, data!$F:$F), 0) | AB5: =IF(Z5>0, AA5/Z5, 0) | AC5: =W5+Z5 | AD5: =X5+AA5 | AE5: =IF(AC5>0, AD5/AC5, 0)
A6: Trường Sa | B6: Trần Thị Kim Khánh | C6: DSXC | D6: 112000 | E6: =AE6 | F6: 34000 | G6: =IFERROR(SUMIF('Dự án T8'!$B:$B, $B6, 'Dự án T8'!$D:$D), 0) | H6: =Q6 | I6: =(AD6/DAY($C$1)) | J6: =I6/H6 | K6: =_xlfn.XLOOKUP(B6, 'kpi nhà thuốc'!$A:$A, 'kpi nhà thuốc'!$G:$G, IF(AND(OR(C6="DSXC", C6="DSCD", C6="DSBC", C6="DSTV", C6="Q.CHT"), G6>=F6), AD6 * _xlfn.IFS(AND(I6>=T6, E6>=D6), 0.015, I6>=T6, 0.013, AND(I6>=S6, E6>=D6), 0.013, I6>=S6, 0.011, AND(I6>=R6, E6>=D6), 0.012, I6>=R6, 0.010, TRUE, 0), 0)) | L6: =IF(C6="DSTV","", IF(J6<0.6, 0.8, 1)) | M6: =IFERROR(SUMIF('Dự án T8'!$B:$B, $B6, 'Dự án T8'!$M:$M)*$L6, 0) | N6: =N(K6)+M6 | O6: =CEILING(R6, 100000) | P6: =CEILING(S6, 100000) | Q6: =CEILING(T6, 100000) | R6: =U6*$R$2 | S6: =U6*$S$2 | T6: =U6*$T$2 | U6: =V6/DAY($C$1) | V6: 115000000 | W6: =IFERROR(SUMIFS(data!$C:$C, data!$A:$A, $A6, data!$B:$B, $B6), 0) | X6: =IFERROR(SUMIF(data!$B:$B, $B6, data!$D:$D), 0) | Y6: =IF(W6>0, X6/W6, 0) | Z6: =IFERROR(SUMIFS(data!$E:$E, data!$A:$A, $A6, data!$B:$B, $B6), 0) | AA6: =IFERROR(SUMIF(data!$B:$B, $B6, data!$F:$F), 0) | AB6: =IF(Z6>0, AA6/Z6, 0) | AC6: =W6+Z6 | AD6: =X6+AA6 | AE6: =IF(AC6>0, AD6/AC6, 0)
A7: Trường Sa | B7: Ngô Trần Tuyết Vy | C7: DSXC | D7: 130000 | E7: =AE7 | F7: 33000 | G7: =IFERROR(SUMIF('Dự án T8'!$B:$B, $B7, 'Dự án T8'!$D:$D), 0) | H7: =Q7 | I7: =(AD7/DAY($C$1)) | J7: =I7/H7 | K7: =_xlfn.XLOOKUP(B7, 'kpi nhà thuốc'!$A:$A, 'kpi nhà thuốc'!$G:$G, IF(AND(OR(C7="DSXC", C7="DSCD", C7="DSBC", C7="DSTV", C7="Q.CHT"), G7>=F7), AD7 * _xlfn.IFS(AND(I7>=T7, E7>=D7), 0.015, I7>=T7, 0.013, AND(I7>=S7, E7>=D7), 0.013, I7>=S7, 0.011, AND(I7>=R7, E7>=D7), 0.012, I7>=R7, 0.010, TRUE, 0), 0)) | L7: =IF(C7="DSTV","", IF(J7<0.6, 0.8, 1)) | M7: =IFERROR(SUMIF('Dự án T8'!$B:$B, $B7, 'Dự án T8'!$M:$M)*$L7, 0) | N7: =N(K7)+M7 | O7: =CEILING(R7, 100000) | P7: =CEILING(S7, 100000) | Q7: =CEILING(T7, 100000) | R7: =U7*$R$2 | S7: =U7*$S$2 | T7: =U7*$T$2 | U7: =V7/DAY($C$1) | V7: 100000000 | W7: =IFERROR(SUMIFS(data!$C:$C, data!$A:$A, $A7, data!$B:$B, $B7), 0) | X7: =IFERROR(SUMIF(data!$B:$B, $B7, data!$D:$D), 0) | Y7: =IF(W7>0, X7/W7, 0) | Z7: =IFERROR(SUMIFS(data!$E:$E, data!$A:$A, $A7, data!$B:$B, $B7), 0) | AA7: =IFERROR(SUMIF(data!$B:$B, $B7, data!$F:$F), 0) | AB7: =IF(Z7>0, AA7/Z7, 0) | AC7: =W7+Z7 | AD7: =X7+AA7 | AE7: =IF(AC7>0, AD7/AC7, 0)
A8: Đỗ Quang Đẩu | B8: Phạm Thị Nghĩa Hương | C8: DSCD | D8: 232000 | E8: =AE8 | F8: 28000 | G8: =IFERROR(SUMIF('Dự án T8'!$B:$B, $B8, 'Dự án T8'!$D:$D), 0) | H8: =Q8 | I8: =(AD8/DAY($C$1)) | J8: =I8/H8 | K8: =_xlfn.XLOOKUP(B8, 'kpi nhà thuốc'!$A:$A, 'kpi nhà thuốc'!$G:$G, IF(AND(OR(C8="DSXC", C8="DSCD", C8="DSBC", C8="DSTV", C8="Q.CHT"), G8>=F8), AD8 * _xlfn.IFS(AND(I8>=T8, E8>=D8), 0.015, I8>=T8, 0.013, AND(I8>=S8, E8>=D8), 0.013, I8>=S8, 0.011, AND(I8>=R8, E8>=D8), 0.012, I8>=R8, 0.010, TRUE, 0), 0)) | L8: =IF(C8="DSTV","", IF(J8<0.6, 0.8, 1)) | M8: =IFERROR(SUMIF('Dự án T8'!$B:$B, $B8, 'Dự án T8'!$M:$M)*$L8, 0) | N8: =N(K8)+M8 | O8: =CEILING(R8, 100000) | P8: =CEILING(S8, 100000) | Q8: =CEILING(T8, 100000) | R8: =U8*$R$2 | S8: =U8*$S$2 | T8: =U8*$T$2 | U8: =V8/DAY($C$1) | V8: 200000000 | W8: =IFERROR(SUMIFS(data!$C:$C, data!$A:$A, $A8, data!$B:$B, $B8), 0) | X8: =IFERROR(SUMIF(data!$B:$B, $B8, data!$D:$D), 0) | Y8: =IF(W8>0, X8/W8, 0) | Z8: =IFERROR(SUMIFS(data!$E:$E, data!$A:$A, $A8, data!$B:$B, $B8), 0) | AA8: =IFERROR(SUMIF(data!$B:$B, $B8, data!$F:$F), 0) | AB8: =IF(Z8>0, AA8/Z8, 0) | AC8: =W8+Z8 | AD8: =X8+AA8 | AE8: =IF(AC8>0, AD8/AC8, 0)
A9: Đỗ Quang Đẩu | B9: Trần Thiên Phát | C9: DSCD | D9: 132000 | E9: =AE9 | F9: 51000 | G9: =IFERROR(SUMIF('Dự án T8'!$B:$B, $B9, 'Dự án T8'!$D:$D), 0) | H9: =Q9 | I9: =(AD9/DAY($C$1)) | J9: =I9/H9 | K9: =_xlfn.XLOOKUP(B9, 'kpi nhà thuốc'!$A:$A, 'kpi nhà thuốc'!$G:$G, IF(AND(OR(C9="DSXC", C9="DSCD", C9="DSBC", C9="DSTV", C9="Q.CHT"), G9>=F9), AD9 * _xlfn.IFS(AND(I9>=T9, E9>=D9), 0.015, I9>=T9, 0.013, AND(I9>=S9, E9>=D9), 0.013, I9>=S9, 0.011, AND(I9>=R9, E9>=D9), 0.012, I9>=R9, 0.010, TRUE, 0), 0)) | L9: =IF(C9="DSTV","", IF(J9<0.6, 0.8, 1)) | M9: =IFERROR(SUMIF('Dự án T8'!$B:$B, $B9, 'Dự án T8'!$M:$M)*$L9, 0) | N9: =N(K9)+M9 | O9: =CEILING(R9, 100000) | P9: =CEILING(S9, 100000) | Q9: =CEILING(T9, 100000) | R9: =U9*$R$2 | S9: =U9*$S$2 | T9: =U9*$T$2 | U9: =V9/DAY($C$1) | V9: 200000000 | W9: =IFERROR(SUMIFS(data!$C:$C, data!$A:$A, $A9, data!$B:$B, $B9), 0) | X9: =IFERROR(SUMIF(data!$B:$B, $B9, data!$D:$D), 0) | Y9: =IF(W9>0, X9/W9, 0) | Z9: =IFERROR(SUMIFS(data!$E:$E, data!$A:$A, $A9, data!$B:$B, $B9), 0) | AA9: =IFERROR(SUMIF(data!$B:$B, $B9, data!$F:$F), 0) | AB9: =IF(Z9>0, AA9/Z9, 0) | AC9: =W9+Z9 | AD9: =X9+AA9 | AE9: =IF(AC9>0, AD9/AC9, 0)
A10: Đỗ Quang Đẩu | B10: Ngô Thị Thanh Thắm | C10: CHT | D10: 159000 | E10: =AE10 | F10: 31000 | G10: =IFERROR(SUMIF('Dự án T8'!$B:$B, $B10, 'Dự án T8'!$D:$D), 0) | H10: =Q10 | I10: =(AD10/DAY($C$1)) | J10: =I10/H10 | K10: =_xlfn.XLOOKUP(B10, 'kpi nhà thuốc'!$A:$A, 'kpi nhà thuốc'!$G:$G, IF(AND(OR(C10="DSXC", C10="DSCD", C10="DSBC", C10="DSTV", C10="Q.CHT"), G10>=F10), AD10 * _xlfn.IFS(AND(I10>=T10, E10>=D10), 0.015, I10>=T10, 0.013, AND(I10>=S10, E10>=D10), 0.013, I10>=S10, 0.011, AND(I10>=R10, E10>=D10), 0.012, I10>=R10, 0.010, TRUE, 0), 0)) | L10: =IF(C10="DSTV","", IF(J10<0.6, 0.8, 1)) | M10: =IFERROR(SUMIF('Dự án T8'!$B:$B, $B10, 'Dự án T8'!$M:$M)*$L10, 0) | N10: =N(K10)+M10 | O10: =CEILING(R10, 100000) | P10: =CEILING(S10, 100000) | Q10: =CEILING(T10, 100000) | R10: =U10*$R$2 | S10: =U10*$S$2 | T10: =U10*$T$2 | U10: =V10/DAY($C$1) | V10: 240000000 | W10: =IFERROR(SUMIFS(data!$C:$C, data!$A:$A, $A10, data!$B:$B, $B10), 0) | X10: =IFERROR(SUMIF(data!$B:$B, $B10, data!$D:$D), 0) | Y10: =IF(W10>0, X10/W10, 0) | Z10: =IFERROR(SUMIFS(data!$E:$E, data!$A:$A, $A10, data!$B:$B, $B10), 0) | AA10: =IFERROR(SUMIF(data!$B:$B, $B10, data!$F:$F), 0) | AB10: =IF(Z10>0, AA10/Z10, 0) | AC10: =W10+Z10 | AD10: =X10+AA10 | AE10: =IF(AC10>0, AD10/AC10, 0)
A11: Đỗ Quang Đẩu | B11: Hoàng Thanh Thủy | C11: DSXC | D11: 207000 | E11: =AE11 | F11: 39000 | G11: =IFERROR(SUMIF('Dự án T8'!$B:$B, $B11, 'Dự án T8'!$D:$D), 0) | H11: =Q11 | I11: =(AD11/DAY($C$1)) | J11: =I11/H11 | K11: =_xlfn.XLOOKUP(B11, 'kpi nhà thuốc'!$A:$A, 'kpi nhà thuốc'!$G:$G, IF(AND(OR(C11="DSXC", C11="DSCD", C11="DSBC", C11="DSTV", C11="Q.CHT"), G11>=F11), AD11 * _xlfn.IFS(AND(I11>=T11, E11>=D11), 0.015, I11>=T11, 0.013, AND(I11>=S11, E11>=D11), 0.013, I11>=S11, 0.011, AND(I11>=R11, E11>=D11), 0.012, I11>=R11, 0.010, TRUE, 0), 0)) | L11: =IF(C11="DSTV","", IF(J11<0.6, 0.8, 1)) | M11: =IFERROR(SUMIF('Dự án T8'!$B:$B, $B11, 'Dự án T8'!$M:$M)*$L11, 0) | N11: =N(K11)+M11 | O11: =CEILING(R11, 100000) | P11: =CEILING(S11, 100000) | Q11: =CEILING(T11, 100000) | R11: =U11*$R$2 | S11: =U11*$S$2 | T11: =U11*$T$2 | U11: =V11/DAY($C$1) | V11: 230000000 | W11: =IFERROR(SUMIFS(data!$C:$C, data!$A:$A, $A11, data!$B:$B, $B11), 0) | X11: =IFERROR(SUMIF(data!$B:$B, $B11, data!$D:$D), 0) | Y11: =IF(W11>0, X11/W11, 0) | Z11: =IFERROR(SUMIFS(data!$E:$E, data!$A:$A, $A11, data!$B:$B, $B11), 0) | AA11: =IFERROR(SUMIF(data!$B:$B, $B11, data!$F:$F), 0) | AB11: =IF(Z11>0, AA11/Z11, 0) | AC11: =W11+Z11 | AD11: =X11+AA11 | AE11: =IF(AC11>0, AD11/AC11, 0)
A12: Đỗ Quang Đẩu | B12: Lê Thị Huyền Trân | C12: DSXC | D12: 250000 | E12: =AE12 | F12: 40000 | G12: =IFERROR(SUMIF('Dự án T8'!$B:$B, $B12, 'Dự án T8'!$D:$D), 0) | H12: =Q12 | I12: =(AD12/DAY($C$1)) | J12: =I12/H12 | K12: =_xlfn.XLOOKUP(B12, 'kpi nhà thuốc'!$A:$A, 'kpi nhà thuốc'!$G:$G, IF(AND(OR(C12="DSXC", C12="DSCD", C12="DSBC", C12="DSTV", C12="Q.CHT"), G12>=F12), AD12 * _xlfn.IFS(AND(I12>=T12, E12>=D12), 0.015, I12>=T12, 0.013, AND(I12>=S12, E12>=D12), 0.013, I12>=S12, 0.011, AND(I12>=R12, E12>=D12), 0.012, I12>=R12, 0.010, TRUE, 0), 0)) | L12: =IF(C12="DSTV","", IF(J12<0.6, 0.8, 1)) | M12: =IFERROR(SUMIF('Dự án T8'!$B:$B, $B12, 'Dự án T8'!$M:$M)*$L12, 0) | N12: =N(K12)+M12 | O12: =CEILING(R12, 100000) | P12: =CEILING(S12, 100000) | Q12: =CEILING(T12, 100000) | R12: =U12*$R$2 | S12: =U12*$S$2 | T12: =U12*$T$2 | U12: =V12/DAY($C$1) | V12: 230000000 | W12: =IFERROR(SUMIFS(data!$C:$C, data!$A:$A, $A12, data!$B:$B, $B12), 0) | X12: =IFERROR(SUMIF(data!$B:$B, $B12, data!$D:$D), 0) | Y12: =IF(W12>0, X12/W12, 0) | Z12: =IFERROR(SUMIFS(data!$E:$E, data!$A:$A, $A12, data!$B:$B, $B12), 0) | AA12: =IFERROR(SUMIF(data!$B:$B, $B12, data!$F:$F), 0) | AB12: =IF(Z12>0, AA12/Z12, 0) | AC12: =W12+Z12 | AD12: =X12+AA12 | AE12: =IF(AC12>0, AD12/AC12, 0)
A13: Minh Châu | B13: Thái Thùy Linh | C13: CHT | D13: 112000 | E13: =AE13 | F13: 2000 | G13: =IFERROR(SUMIF('Dự án T8'!$B:$B, $B13, 'Dự án T8'!$D:$D), 0) | H13: =Q13 | I13: =(AD13/DAY($C$1)) | J13: =I13/H13 | K13: =_xlfn.XLOOKUP(B13, 'kpi nhà thuốc'!$A:$A, 'kpi nhà thuốc'!$G:$G, IF(AND(OR(C13="DSXC", C13="DSCD", C13="DSBC", C13="DSTV", C13="Q.CHT"), G13>=F13), AD13 * _xlfn.IFS(AND(I13>=T13, E13>=D13), 0.015, I13>=T13, 0.013, AND(I13>=S13, E13>=D13), 0.013, I13>=S13, 0.011, AND(I13>=R13, E13>=D13), 0.012, I13>=R13, 0.010, TRUE, 0), 0)) | L13: =IF(C13="DSTV","", IF(J13<0.6, 0.8, 1)) | M13: =IFERROR(SUMIF('Dự án T8'!$B:$B, $B13, 'Dự án T8'!$M:$M)*$L13, 0) | N13: =N(K13)+M13 | O13: =CEILING(R13, 100000) | P13: =CEILING(S13, 100000) | Q13: =CEILING(T13, 100000) | R13: =U13*$R$2 | S13: =U13*$S$2 | T13: =U13*$T$2 | U13: =V13/DAY($C$1) | V13: 120000000 | W13: =IFERROR(SUMIFS(data!$C:$C, data!$A:$A, $A13, data!$B:$B, $B13), 0) | X13: =IFERROR(SUMIF(data!$B:$B, $B13, data!$D:$D), 0) | Y13: =IF(W13>0, X13/W13, 0) | Z13: =IFERROR(SUMIFS(data!$E:$E, data!$A:$A, $A13, data!$B:$B, $B13), 0) | AA13: =IFERROR(SUMIF(data!$B:$B, $B13, data!$F:$F), 0) | AB13: =IF(Z13>0, AA13/Z13, 0) | AC13: =W13+Z13 | AD13: =X13+AA13 | AE13: =IF(AC13>0, AD13/AC13, 0)
A14: Minh Châu | B14: Đoàn Quốc Tâm | C14: DSXC | D14: 103000 | E14: =AE14 | F14: 3000 | G14: =IFERROR(SUMIF('Dự án T8'!$B:$B, $B14, 'Dự án T8'!$D:$D), 0) | H14: =Q14 | I14: =(AD14/DAY($C$1)) | J14: =I14/H14 | K14: =_xlfn.XLOOKUP(B14, 'kpi nhà thuốc'!$A:$A, 'kpi nhà thuốc'!$G:$G, IF(AND(OR(C14="DSXC", C14="DSCD", C14="DSBC", C14="DSTV", C14="Q.CHT"), G14>=F14), AD14 * _xlfn.IFS(AND(I14>=T14, E14>=D14), 0.015, I14>=T14, 0.013, AND(I14>=S14, E14>=D14), 0.013, I14>=S14, 0.011, AND(I14>=R14, E14>=D14), 0.012, I14>=R14, 0.010, TRUE, 0), 0)) | L14: =IF(C14="DSTV","", IF(J14<0.6, 0.8, 1)) | M14: =IFERROR(SUMIF('Dự án T8'!$B:$B, $B14, 'Dự án T8'!$M:$M)*$L14, 0) | N14: =N(K14)+M14 | O14: =CEILING(R14, 100000) | P14: =CEILING(S14, 100000) | Q14: =CEILING(T14, 100000) | R14: =U14*$R$2 | S14: =U14*$S$2 | T14: =U14*$T$2 | U14: =V14/DAY($C$1) | V14: 120000000 | W14: =IFERROR(SUMIFS(data!$C:$C, data!$A:$A, $A14, data!$B:$B, $B14), 0) | X14: =IFERROR(SUMIF(data!$B:$B, $B14, data!$D:$D), 0) | Y14: =IF(W14>0, X14/W14, 0) | Z14: =IFERROR(SUMIFS(data!$E:$E, data!$A:$A, $A14, data!$B:$B, $B14), 0) | AA14: =IFERROR(SUMIF(data!$B:$B, $B14, data!$F:$F), 0) | AB14: =IF(Z14>0, AA14/Z14, 0) | AC14: =W14+Z14 | AD14: =X14+AA14 | AE14: =IF(AC14>0, AD14/AC14, 0)
... A57: Trường Sa | B57: Medigo | C57: DSBC | D57: 150000 | E57: =AE57 | F57: 0 | G57: =IFERROR(SUMIF('Dự án T8'!$B:$B, $B57, 'Dự án T8'!$D:$D), 0) | H57: =Q57 | I57: =(AD57/DAY($C$1)) | J57: =I57/H57 | K57: =_xlfn.XLOOKUP(B57, 'kpi nhà thuốc'!$A:$A, 'kpi nhà thuốc'!$G:$G, IF(AND(OR(C57="DSXC", C57="DSCD", C57="DSBC", C57="DSTV", C57="Q.CHT"), G57>=F57), AD57 * _xlfn.IFS(AND(I57>=T57, E57>=D57), 0.015, I57>=T57, 0.013, AND(I57>=S57, E57>=D57), 0.013, I57>=S57, 0.011, AND(I57>=R57, E57>=D57), 0.012, I57>=R57, 0.010, TRUE, 0), 0)) | L57: =IF(C57="DSTV","", IF(J57<0.6, 0.8, 1)) | M57: =IFERROR(SUMIF('Dự án T8'!$B:$B, $B57, 'Dự án T8'!$M:$M)*$L57, 0) | N57: =N(K57)+M57 | O57: =CEILING(R57, 100000) | P57: =CEILING(S57, 100000) | Q57: =CEILING(T57, 100000) | R57: =U57*$R$2 | S57: =U57*$S$2 | T57: =U57*$T$2 | U57: =V57/DAY($C$1) | V57: 270000000 | W57: =IFERROR(SUMIFS(data!$C:$C, data!$A:$A, $A57, data!$B:$B, $B57), 0) | X57: =IFERROR(SUMIF(data!$B:$B, $B57, data!$D:$D), 0) | Y57: =IF(W57>0, X57/W57, 0) | Z57: =IFERROR(SUMIFS(data!$E:$E, data!$A:$A, $A57, data!$B:$B, $B57), 0) | AA57: =IFERROR(SUMIF(data!$B:$B, $B57, data!$F:$F), 0) | AB57: =IF(Z57>0, AA57/Z57, 0) | AC57: =W57+Z57 | AD57: =X57+AA57 | AE57: =IF(AC57>0, AD57/AC57, 0)

Sheet kpi nhà thuốc
D1: Dữ liệu cập nhật đến ngày | F1: ='kpi dược sĩ'!$C$1 | T1: ='kpi dược sĩ'!$C$1
A2: Cửa hàng trưởng | B2: Nhà thuốc | C2: KPI doanh thu (tháng) | D2: Doanh thu thực tế (tháng) | E2: Doanh thu thực tế (ngày) | F2: Tỷ lệ đạt KPIs | G2: Thưởng CHT | H2: KPIs mức 1 | I2: KPIs hàng điểm mức 1 | J2: KPIs mức 1/tháng | K2: KPIs mức 1/ngày | L2: KPIs mức 1/ngày | M2: KPIs mức 2 | N2: KPIs hàng điểm mức 2 | O2: KPIs mức 2/tháng | P2: KPIs mức 2/ngày | Q2: KPIs mức 3 | R2: KPIs hàng điểm mức 3 | S2: KPIs mức 3/tháng | T2: KPIs mức 3/ngày | U2: Doanh thu hàng điểm | V2: Hàng điểm/ Doanh thu tổng | W2: Xét Đạt KPI | X2: Số giao dịch off | Y2: Doanh thu off | Z2: Tbbill off | AA2: Số giao dịch onl | AB2: Doanh thu onl | AC2: Tbbill onl | AD2: Tổng giao dịch | AE2: Doanh thu tổng | AF2: Trung bình Bill
A3: Đinh Thị Lan Anh | B3: Hàng Bông | C3: 574089563 | D3: =AE3 | E3: =D3/DAY('kpi dược sĩ'!$C$1) | F3: =E3/T3 | G3: =IF(W3<>"Đạt", 0, IF(E3>=T3, D3*0.5%+1000000, IF(E3>=P3, D3*0.4%+700000, IF(E3>=K3, D3*0.35%+500000, 0)))) | H3: 0.8 | I3: =J3*0.25 | J3: =C3*H3 | K3: =T3*H3 | L3: =CEILING(K3, 100000) | M3: 0.9 | N3: =O3*0.25 | O3: =C3*M3 | P3: =T3*M3 | Q3: 1 | R3: =S3*0.25 | S3: =C3*Q3 | T3: =C3/DAY($T$1) | U3: =SUMIF('Dự án T8'!$A:$A, B3, 'Dự án T8'!$D:$D)*DAY($F$1) | V3: =U3/D3 | W3: =IF(OR(F3="", V3=""), "", IF(AND(F3>=80%, V3>=25%), "Đạt", "Không đạt")) | X3: =SUMIF(data!$A:$A, B3, data!$C:$C) | Y3: =SUMIF(data!$A:$A, B3, data!$D:$D) | Z3: =IF(X3>0, Y3/X3, 0) | AA3: =SUMIF(data!$A:$A, B3, data!$E:$E) | AB3: =SUMIF(data!$A:$A, B3, data!$F:$F) | AC3: =IF(AA3>0, AB3/AA3, 0) | AD3: =X3+AA3 | AE3: =Y3+AB3 | AF3: =IF(AD3>0, AE3/AD3, 0)
A4: Hứa Thị Kim Thoa | B4: Đường Láng | C4: 492042962 | D4: =AE4 | E4: =D4/DAY('kpi dược sĩ'!$C$1) | F4: =E4/T4 | G4: =IF(W4<>"Đạt", 0, IF(E4>=T4, D4*0.5%+1000000, IF(E4>=P4, D4*0.4%+700000, IF(E4>=K4, D4*0.35%+500000, 0)))) | H4: 0.8 | I4: =J4*0.25 | J4: =C4*H4 | K4: =T4*H4 | L4: =CEILING(K4, 100000) | M4: 0.9 | N4: =O4*0.25 | O4: =C4*M4 | P4: =T4*M4 | Q4: 1 | R4: =S4*0.25 | S4: =C4*Q4 | T4: =C4/DAY($T$1) | U4: =SUMIF('Dự án T8'!$A:$A, B4, 'Dự án T8'!$D:$D)*DAY($F$1) | V4: =U4/D4 | W4: =IF(OR(F4="", V4=""), "", IF(AND(F4>=80%, V4>=25%), "Đạt", "Không đạt")) | X4: =SUMIF(data!$A:$A, B4, data!$C:$C) | Y4: =SUMIF(data!$A:$A, B4, data!$D:$D) | Z4: =IF(X4>0, Y4/X4, 0) | AA4: =SUMIF(data!$A:$A, B4, data!$E:$E) | AB4: =SUMIF(data!$A:$A, B4, data!$F:$F) | AC4: =IF(AA4>0, AB4/AA4, 0) | AD4: =X4+AA4 | AE4: =Y4+AB4 | AF4: =IF(AD4>0, AE4/AD4, 0)
A5: Nguyễn Trần Ngọc Phương | B5: Trường Sa | C5: 640000000 | D5: =AE5 | E5: =D5/DAY('kpi dược sĩ'!$C$1) | F5: =E5/T5 | G5: =IF(W5<>"Đạt", 0, IF(E5>=T5, D5*0.5%+1000000, IF(E5>=P5, D5*0.4%+700000, IF(E5>=K5, D5*0.35%+500000, 0)))) | H5: 0.8 | I5: =J5*0.25 | J5: =C5*H5 | K5: =T5*H5 | L5: =CEILING(K5, 100000) | M5: 0.9 | N5: =O5*0.25 | O5: =C5*M5 | P5: =T5*M5 | Q5: 1 | R5: =S5*0.25 | S5: =C5*Q5 | T5: =C5/DAY($T$1) | U5: =SUMIF('Dự án T8'!$A:$A, B5, 'Dự án T8'!$D:$D)*DAY($F$1) | V5: =U5/D5 | W5: =IF(OR(F5="", V5=""), "", IF(AND(F5>=80%, V5>=25%), "Đạt", "Không đạt")) | X5: =SUMIF(data!$A:$A, B5, data!$C:$C) | Y5: =SUMIF(data!$A:$A, B5, data!$D:$D) | Z5: =IF(X5>0, Y5/X5, 0) | AA5: =SUMIF(data!$A:$A, B5, data!$E:$E) | AB5: =SUMIF(data!$A:$A, B5, data!$F:$F) | AC5: =IF(AA5>0, AB5/AA5, 0) | AD5: =X5+AA5 | AE5: =Y5+AB5 | AF5: =IF(AD5>0, AE5/AD5, 0)
A6: Ngô Thị Thanh Thắm | B6: Đỗ Quang Đẩu | C6: 1100000000 | D6: =AE6 | E6: =D6/DAY('kpi dược sĩ'!$C$1) | F6: =E6/T6 | G6: =IF(W6<>"Đạt", 0, IF(E6>=T6, D6*0.5%+1000000, IF(E6>=P6, D6*0.4%+700000, IF(E6>=K6, D6*0.35%+500000, 0)))) | H6: 0.8 | I6: =J6*0.25 | J6: =C6*H6 | K6: =T6*H6 | L6: =CEILING(K6, 100000) | M6: 0.9 | N6: =O6*0.25 | O6: =C6*M6 | P6: =T6*M6 | Q6: 1 | R6: =S6*0.25 | S6: =C6*Q6 | T6: =C6/DAY($T$1) | U6: =SUMIF('Dự án T8'!$A:$A, B6, 'Dự án T8'!$D:$D)*DAY($F$1) | V6: =U6/D6 | W6: =IF(OR(F6="", V6=""), "", IF(AND(F6>=80%, V6>=25%), "Đạt", "Không đạt")) | X6: =SUMIF(data!$A:$A, B6, data!$C:$C) | Y6: =SUMIF(data!$A:$A, B6, data!$D:$D) | Z6: =IF(X6>0, Y6/X6, 0) | AA6: =SUMIF(data!$A:$A, B6, data!$E:$E) | AB6: =SUMIF(data!$A:$A, B6, data!$F:$F) | AC6: =IF(AA6>0, AB6/AA6, 0) | AD6: =X6+AA6 | AE6: =Y6+AB6 | AF6: =IF(AD6>0, AE6/AD6, 0)
A7: Thái Thùy Linh | B7: Minh Châu | C7: 460000000 | D7: =AE7 | E7: =D7/DAY('kpi dược sĩ'!$C$1) | F7: =E7/T7 | G7: =IF(W7<>"Đạt", 0, IF(E7>=T7, D7*0.5%+1000000, IF(E7>=P7, D7*0.4%+700000, IF(E7>=K7, D7*0.35%+500000, 0)))) | H7: 0.8 | I7: =J7*0.25 | J7: =C7*H7 | K7: =T7*H7 | L7: =CEILING(K7, 100000) | M7: 0.9 | N7: =O7*0.25 | O7: =C7*M7 | P7: =T7*M7 | Q7: 1 | R7: =S7*0.25 | S7: =C7*Q7 | T7: =C7/DAY($T$1) | U7: =SUMIF('Dự án T8'!$A:$A, B7, 'Dự án T8'!$D:$D)*DAY($F$1) | V7: =U7/D7 | W7: =IF(OR(F7="", V7=""), "", IF(AND(F7>=80%, V7>=25%), "Đạt", "Không đạt")) | X7: =SUMIF(data!$A:$A, B7, data!$C:$C) | Y7: =SUMIF(data!$A:$A, B7, data!$D:$D) | Z7: =IF(X7>0, Y7/X7, 0) | AA7: =SUMIF(data!$A:$A, B7, data!$E:$E) | AB7: =SUMIF(data!$A:$A, B7, data!$F:$F) | AC7: =IF(AA7>0, AB7/AA7, 0) | AD7: =X7+AA7 | AE7: =Y7+AB7 | AF7: =IF(AD7>0, AE7/AD7, 0)
A8: Vũ Ngọc Thanh Thảo | B8: Nam Hòa | C8: 330000000 | D8: =AE8 | E8: =D8/DAY('kpi dược sĩ'!$C$1) | F8: =E8/T8 | G8: =IF(W8<>"Đạt", 0, IF(E8>=T8, D8*0.5%+1000000, IF(E8>=P8, D8*0.4%+700000, IF(E8>=K8, D8*0.35%+500000, 0)))) | H8: 0.8 | I8: =J8*0.25 | J8: =C8*H8 | K8: =T8*H8 | L8: =CEILING(K8, 100000) | M8: 0.9 | N8: =O8*0.25 | O8: =C8*M8 | P8: =T8*M8 | Q8: 1 | R8: =S8*0.25 | S8: =C8*Q8 | T8: =C8/DAY($T$1) | U8: =SUMIF('Dự án T8'!$A:$A, B8, 'Dự án T8'!$D:$D)*DAY($F$1) | V8: =U8/D8 | W8: =IF(OR(F8="", V8=""), "", IF(AND(F8>=80%, V8>=25%), "Đạt", "Không đạt")) | X8: =SUMIF(data!$A:$A, B8, data!$C:$C) | Y8: =SUMIF(data!$A:$A, B8, data!$D:$D) | Z8: =IF(X8>0, Y8/X8, 0) | AA8: =SUMIF(data!$A:$A, B8, data!$E:$E) | AB8: =SUMIF(data!$A:$A, B8, data!$F:$F) | AC8: =IF(AA8>0, AB8/AA8, 0) | AD8: =X8+AA8 | AE8: =Y8+AB8 | AF8: =IF(AD8>0, AE8/AD8, 0)
A9: Lê Thị Quỳnh Trâm | B9: Nguyễn Chí Thanh | C9: 550000000 | D9: =AE9 | E9: =D9/DAY('kpi dược sĩ'!$C$1) | F9: =E9/T9 | G9: =IF(W9<>"Đạt", 0, IF(E9>=T9, D9*0.5%+1000000, IF(E9>=P9, D9*0.4%+700000, IF(E9>=K9, D9*0.35%+500000, 0)))) | H9: 0.8 | I9: =J9*0.25 | J9: =C9*H9 | K9: =T9*H9 | L9: =CEILING(K9, 100000) | M9: 0.9 | N9: =O9*0.25 | O9: =C9*M9 | P9: =T9*M9 | Q9: 1 | R9: =S9*0.25 | S9: =C9*Q9 | T9: =C9/DAY($T$1) | U9: =SUMIF('Dự án T8'!$A:$A, B9, 'Dự án T8'!$D:$D)*DAY($F$1) | V9: =U9/D9 | W9: =IF(OR(F9="", V9=""), "", IF(AND(F9>=80%, V9>=25%), "Đạt", "Không đạt")) | X9: =SUMIF(data!$A:$A, B9, data!$C:$C) | Y9: =SUMIF(data!$A:$A, B9, data!$D:$D) | Z9: =IF(X9>0, Y9/X9, 0) | AA9: =SUMIF(data!$A:$A, B9, data!$E:$E) | AB9: =SUMIF(data!$A:$A, B9, data!$F:$F) | AC9: =IF(AA9>0, AB9/AA9, 0) | AD9: =X9+AA9 | AE9: =Y9+AB9 | AF9: =IF(AD9>0, AE9/AD9, 0)
A10: Triệu Thị Ngọc Lý | B10: Nguyễn Thị Thập | C10: 545000000 | D10: =AE10 | E10: =D10/DAY('kpi dược sĩ'!$C$1) | F10: =E10/T10 | G10: =IF(W10<>"Đạt", 0, IF(E10>=T10, D10*0.5%+1000000, IF(E10>=P10, D10*0.4%+700000, IF(E10>=K10, D10*0.35%+500000, 0)))) | H10: 0.8 | I10: =J10*0.25 | J10: =C10*H10 | K10: =T10*H10 | L10: =CEILING(K10, 100000) | M10: 0.9 | N10: =O10*0.25 | O10: =C10*M10 | P10: =T10*M10 | Q10: 1 | R10: =S10*0.25 | S10: =C10*Q10 | T10: =C10/DAY($T$1) | U10: =SUMIF('Dự án T8'!$A:$A, B10, 'Dự án T8'!$D:$D)*DAY($F$1) | V10: =U10/D10 | W10: =IF(OR(F10="", V10=""), "", IF(AND(F10>=80%, V10>=25%), "Đạt", "Không đạt")) | X10: =SUMIF(data!$A:$A, B10, data!$C:$C) | Y10: =SUMIF(data!$A:$A, B10, data!$D:$D) | Z10: =IF(X10>0, Y10/X10, 0) | AA10: =SUMIF(data!$A:$A, B10, data!$E:$E) | AB10: =SUMIF(data!$A:$A, B10, data!$F:$F) | AC10: =IF(AA10>0, AB10/AA10, 0) | AD10: =X10+AA10 | AE10: =Y10+AB10 | AF10: =IF(AD10>0, AE10/AD10, 0)
A11: Võ Ngọc Giàu Sang | B11: Nguyễn Văn Quá | C11: 400000000 | D11: =AE11 | E11: =D11/DAY('kpi dược sĩ'!$C$1) | F11: =E11/T11 | G11: =IF(W11<>"Đạt", 0, IF(E11>=T11, D11*0.5%+1000000, IF(E11>=P11, D11*0.4%+700000, IF(E11>=K11, D11*0.35%+500000, 0)))) | H11: 0.8 | I11: =J11*0.25 | J11: =C11*H11 | K11: =T11*H11 | L11: =CEILING(K11, 100000) | M11: 0.9 | N11: =O11*0.25 | O11: =C11*M11 | P11: =T11*M11 | Q11: 1 | R11: =S11*0.25 | S11: =C11*Q11 | T11: =C11/DAY($T$1) | U11: =SUMIF('Dự án T8'!$A:$A, B11, 'Dự án T8'!$D:$D)*DAY($F$1) | V11: =U11/D11 | W11: =IF(OR(F11="", V11=""), "", IF(AND(F11>=80%, V11>=25%), "Đạt", "Không đạt")) | X11: =SUMIF(data!$A:$A, B11, data!$C:$C) | Y11: =SUMIF(data!$A:$A, B11, data!$D:$D) | Z11: =IF(X11>0, Y11/X11, 0) | AA11: =SUMIF(data!$A:$A, B11, data!$E:$E) | AB11: =SUMIF(data!$A:$A, B11, data!$F:$F) | AC11: =IF(AA11>0, AB11/AA11, 0) | AD11: =X11+AA11 | AE11: =Y11+AB11 | AF11: =IF(AD11>0, AE11/AD11, 0)
A12: Cù Thị Tường Vy | B12: Rạch Bùng Binh | C12: 475000000 | D12: =AE12 | E12: =D12/DAY('kpi dược sĩ'!$C$1) | F12: =E12/T12 | G12: =IF(W12<>"Đạt", 0, IF(E12>=T12, D12*0.5%+1000000, IF(E12>=P12, D12*0.4%+700000, IF(E12>=K12, D12*0.35%+500000, 0)))) | H12: 0.8 | I12: =J12*0.25 | J12: =C12*H12 | K12: =T12*H12 | L12: =CEILING(K12, 100000) | M12: 0.9 | N12: =O12*0.25 | O12: =C12*M12 | P12: =T12*M12 | Q12: 1 | R12: =S12*0.25 | S12: =C12*Q12 | T12: =C12/DAY($T$1) | U12: =SUMIF('Dự án T8'!$A:$A, B12, 'Dự án T8'!$D:$D)*DAY($F$1) | V12: =U12/D12 | W12: =IF(OR(F12="", V12=""), "", IF(AND(F12>=80%, V12>=25%), "Đạt", "Không đạt")) | X12: =SUMIF(data!$A:$A, B12, data!$C:$C) | Y12: =SUMIF(data!$A:$A, B12, data!$D:$D) | Z12: =IF(X12>0, Y12/X12, 0) | AA12: =SUMIF(data!$A:$A, B12, data!$E:$E) | AB12: =SUMIF(data!$A:$A, B12, data!$F:$F) | AC12: =IF(AA12>0, AB12/AA12, 0) | AD12: =X12+AA12 | AE12: =Y12+AB12 | AF12: =IF(AD12>0, AE12/AD12, 0)
A13: Hồ Thị Minh Hòa | B13: Lê Bình | C13: 550000000 | D13: =AE13 | E13: =D13/DAY('kpi dược sĩ'!$C$1) | F13: =E13/T13 | G13: =IF(W13<>"Đạt", 0, IF(E13>=T13, D13*0.5%+1000000, IF(E13>=P13, D13*0.4%+700000, IF(E13>=K13, D13*0.35%+500000, 0)))) | H13: 0.8 | I13: =J13*0.25 | J13: =C13*H13 | K13: =T13*H13 | L13: =CEILING(K13, 100000) | M13: 0.9 | N13: =O13*0.25 | O13: =C13*M13 | P13: =T13*M13 | Q13: 1 | R13: =S13*0.25 | S13: =C13*Q13 | T13: =C13/DAY($T$1) | U13: =SUMIF('Dự án T8'!$A:$A, B13, 'Dự án T8'!$D:$D)*DAY($F$1) | V13: =U13/D13 | W13: =IF(OR(F13="", V13=""), "", IF(AND(F13>=80%, V13>=25%), "Đạt", "Không đạt")) | X13: =SUMIF(data!$A:$A, B13, data!$C:$C) | Y13: =SUMIF(data!$A:$A, B13, data!$D:$D) | Z13: =IF(X13>0, Y13/X13, 0) | AA13: =SUMIF(data!$A:$A, B13, data!$E:$E) | AB13: =SUMIF(data!$A:$A, B13, data!$F:$F) | AC13: =IF(AA13>0, AB13/AA13, 0) | AD13: =X13+AA13 | AE13: =Y13+AB13 | AF13: =IF(AD13>0, AE13/AD13, 0)

Sheet Dự án T8
A1: 46244
A2: Nhà thuốc | B2: Nhân viên | C2: Chức danh | D2: CK + Combo + NY3/ngày | E2: NY3 | F2: Chiết khấu | G2: Combo Liều | H2: Chiết khấu/ngày | I2: Combo Liều/ngày | J2: Thưởng dự án | K2: Thưởng thêm | L2: Thưởng dự án Hot Bill HN | M2: Total dự án
A3: Trường Sa | B3: Nguyễn Trần Ngọc Phương | C3: Q.CHT | D3: =SUM(E3:G3)/DAY($A$1) | E3: 720500 | F3: 6890696 | G3: 3926990 | H3: =F3/DAY($A$1) | I3: =G3/DAY($A$1) | J3: =IFERROR(IF(OR($A3="Hàng Bông",$A3="Đường Láng"),_xlfn.IFS(AND($H3>=2200000.0,$I3>=450000.0),1000000.0,AND($H3>=2500000.0,$I3>=520000.0),1600000.0,AND($H3>=2800000.0,$I3>=650000.0),2200000.0,AND($H3>=3200000.0,$I3>=750000.0),2800000.0,AND($H3>=3400000.0,$I3>=900000.0),4000000.0,TRUE,0),_xlfn.IFS(AND($H3>=630000.0,$I3>=350000.0),1000000.0,AND($H3>=850000.0,$I3>=480000.0),1600000.0,AND($H3>=1000000.0,$I3>=580000.0),2200000.0,AND($H3>=1200000.0,$I3>=650000.0),2800000.0,AND($H3>=1500000.0,$I3>=700000.0),4000000.0,TRUE,0)),0) | K3: =IFERROR(IF(AND($J3=0, IF(OR($A3="Hàng Bông",$A3="Đường Láng"),$D3>=2000000,$D3>=950000)), 500000, 0), 0) | L3: =IFERROR(SUMIFS('Hot Bill HN'!$G:$G, 'Hot Bill HN'!$C:$C, $A3, 'Hot Bill HN'!$D:$D, $B3), 0) | M3: =IFERROR($J3+$K3+$L3, 0)
A4: Trường Sa | B4: Phạm Nguyễn Ngọc Quý | C4: DSXC | D4: =SUM(E4:G4)/DAY($A$1) | E4: 281500 | F4: 6791156 | G4: 3508802 | H4: =F4/DAY($A$1) | I4: =G4/DAY($A$1) | J4: =IFERROR(IF(OR($A4="Hàng Bông",$A4="Đường Láng"),_xlfn.IFS(AND($H4>=2200000.0,$I4>=450000.0),1000000.0,AND($H4>=2500000.0,$I4>=520000.0),1600000.0,AND($H4>=2800000.0,$I4>=650000.0),2200000.0,AND($H4>=3200000.0,$I4>=750000.0),2800000.0,AND($H4>=3400000.0,$I4>=900000.0),4000000.0,TRUE,0),_xlfn.IFS(AND($H4>=630000.0,$I4>=350000.0),1000000.0,AND($H4>=850000.0,$I4>=480000.0),1600000.0,AND($H4>=1000000.0,$I4>=580000.0),2200000.0,AND($H4>=1200000.0,$I4>=650000.0),2800000.0,AND($H4>=1500000.0,$I4>=700000.0),4000000.0,TRUE,0)),0) | K4: =IFERROR(IF(AND($J4=0, IF(OR($A4="Hàng Bông",$A4="Đường Láng"),$D4>=2000000,$D4>=950000)), 500000, 0), 0) | L4: =IFERROR(SUMIFS('Hot Bill HN'!$G:$G, 'Hot Bill HN'!$C:$C, $A4, 'Hot Bill HN'!$D:$D, $B4), 0) | M4: =IFERROR($J4+$K4+$L4, 0)
A5: Trường Sa | B5: Nguyễn Ngọc Anh Thư | C5: DSCD (TV) | D5: =SUM(E5:G5)/DAY($A$1) | E5: 0 | F5: 0 | G5: 0 | H5: =F5/DAY($A$1) | I5: =G5/DAY($A$1) | J5: =IFERROR(IF(OR($A5="Hàng Bông",$A5="Đường Láng"),_xlfn.IFS(AND($H5>=2200000.0,$I5>=450000.0),1000000.0,AND($H5>=2500000.0,$I5>=520000.0),1600000.0,AND($H5>=2800000.0,$I5>=650000.0),2200000.0,AND($H5>=3200000.0,$I5>=750000.0),2800000.0,AND($H5>=3400000.0,$I5>=900000.0),4000000.0,TRUE,0),_xlfn.IFS(AND($H5>=630000.0,$I5>=350000.0),1000000.0,AND($H5>=850000.0,$I5>=480000.0),1600000.0,AND($H5>=1000000.0,$I5>=580000.0),2200000.0,AND($H5>=1200000.0,$I5>=650000.0),2800000.0,AND($H5>=1500000.0,$I5>=700000.0),4000000.0,TRUE,0)),0) | K5: =IFERROR(IF(AND($J5=0, IF(OR($A5="Hàng Bông",$A5="Đường Láng"),$D5>=2000000,$D5>=950000)), 500000, 0), 0) | L5: =IFERROR(SUMIFS('Hot Bill HN'!$G:$G, 'Hot Bill HN'!$C:$C, $A5, 'Hot Bill HN'!$D:$D, $B5), 0) | M5: =IFERROR($J5+$K5+$L5, 0)
A6: Trường Sa | B6: Trần Thị Kim Khánh | C6: DSXC | D6: =SUM(E6:G6)/DAY($A$1) | E6: 1663030 | F6: 10800138 | G6: 6473755 | H6: =F6/DAY($A$1) | I6: =G6/DAY($A$1) | J6: =IFERROR(IF(OR($A6="Hàng Bông",$A6="Đường Láng"),_xlfn.IFS(AND($H6>=2200000.0,$I6>=450000.0),1000000.0,AND($H6>=2500000.0,$I6>=520000.0),1600000.0,AND($H6>=2800000.0,$I6>=650000.0),2200000.0,AND($H6>=3200000.0,$I6>=750000.0),2800000.0,AND($H6>=3400000.0,$I6>=900000.0),4000000.0,TRUE,0),_xlfn.IFS(AND($H6>=630000.0,$I6>=350000.0),1000000.0,AND($H6>=850000.0,$I6>=480000.0),1600000.0,AND($H6>=1000000.0,$I6>=580000.0),2200000.0,AND($H6>=1200000.0,$I6>=650000.0),2800000.0,AND($H6>=1500000.0,$I6>=700000.0),4000000.0,TRUE,0)),0) | K6: =IFERROR(IF(AND($J6=0, IF(OR($A6="Hàng Bông",$A6="Đường Láng"),$D6>=2000000,$D6>=950000)), 500000, 0), 0) | L6: =IFERROR(SUMIFS('Hot Bill HN'!$G:$G, 'Hot Bill HN'!$C:$C, $A6, 'Hot Bill HN'!$D:$D, $B6), 0) | M6: =IFERROR($J6+$K6+$L6, 0)
A7: Trường Sa | B7: Ngô Trần Tuyết Vy | C7: DSXC | D7: =SUM(E7:G7)/DAY($A$1) | E7: 126879 | F7: 10798824 | G7: 7371263 | H7: =F7/DAY($A$1) | I7: =G7/DAY($A$1) | J7: =IFERROR(IF(OR($A7="Hàng Bông",$A7="Đường Láng"),_xlfn.IFS(AND($H7>=2200000.0,$I7>=450000.0),1000000.0,AND($H7>=2500000.0,$I7>=520000.0),1600000.0,AND($H7>=2800000.0,$I7>=650000.0),2200000.0,AND($H7>=3200000.0,$I7>=750000.0),2800000.0,AND($H7>=3400000.0,$I7>=900000.0),4000000.0,TRUE,0),_xlfn.IFS(AND($H7>=630000.0,$I7>=350000.0),1000000.0,AND($H7>=850000.0,$I7>=480000.0),1600000.0,AND($H7>=1000000.0,$I7>=580000.0),2200000.0,AND($H7>=1200000.0,$I7>=650000.0),2800000.0,AND($H7>=1500000.0,$I7>=700000.0),4000000.0,TRUE,0)),0) | K7: =IFERROR(IF(AND($J7=0, IF(OR($A7="Hàng Bông",$A7="Đường Láng"),$D7>=2000000,$D7>=950000)), 500000, 0), 0) | L7: =IFERROR(SUMIFS('Hot Bill HN'!$G:$G, 'Hot Bill HN'!$C:$C, $A7, 'Hot Bill HN'!$D:$D, $B7), 0) | M7: =IFERROR($J7+$K7+$L7, 0)
A8: Đỗ Quang Đẩu | B8: Phạm Thị Nghĩa Hương | C8: DSCD | D8: =SUM(E8:G8)/DAY($A$1) | E8: 1005500 | F8: 3251619 | G8: 561911 | H8: =F8/DAY($A$1) | I8: =G8/DAY($A$1) | J8: =IFERROR(IF(OR($A8="Hàng Bông",$A8="Đường Láng"),_xlfn.IFS(AND($H8>=2200000.0,$I8>=450000.0),1000000.0,AND($H8>=2500000.0,$I8>=520000.0),1600000.0,AND($H8>=2800000.0,$I8>=650000.0),2200000.0,AND($H8>=3200000.0,$I8>=750000.0),2800000.0,AND($H8>=3400000.0,$I8>=900000.0),4000000.0,TRUE,0),_xlfn.IFS(AND($H8>=630000.0,$I8>=350000.0),1000000.0,AND($H8>=850000.0,$I8>=480000.0),1600000.0,AND($H8>=1000000.0,$I8>=580000.0),2200000.0,AND($H8>=1200000.0,$I8>=650000.0),2800000.0,AND($H8>=1500000.0,$I8>=700000.0),4000000.0,TRUE,0)),0) | K8: =IFERROR(IF(AND($J8=0, IF(OR($A8="Hàng Bông",$A8="Đường Láng"),$D8>=2000000,$D8>=950000)), 500000, 0), 0) | L8: =IFERROR(SUMIFS('Hot Bill HN'!$G:$G, 'Hot Bill HN'!$C:$C, $A8, 'Hot Bill HN'!$D:$D, $B8), 0) | M8: =IFERROR($J8+$K8+$L8, 0)
A9: Đỗ Quang Đẩu | B9: Trần Thiên Phát | C9: DSCD | D9: =SUM(E9:G9)/DAY($A$1) | E9: 3294500 | F9: 3793503 | G9: 1518200 | H9: =F9/DAY($A$1) | I9: =G9/DAY($A$1) | J9: =IFERROR(IF(OR($A9="Hàng Bông",$A9="Đường Láng"),_xlfn.IFS(AND($H9>=2200000.0,$I9>=450000.0),1000000.0,AND($H9>=2500000.0,$I9>=520000.0),1600000.0,AND($H9>=2800000.0,$I9>=650000.0),2200000.0,AND($H9>=3200000.0,$I9>=750000.0),2800000.0,AND($H9>=3400000.0,$I9>=900000.0),4000000.0,TRUE,0),_xlfn.IFS(AND($H9>=630000.0,$I9>=350000.0),1000000.0,AND($H9>=850000.0,$I9>=480000.0),1600000.0,AND($H9>=1000000.0,$I9>=580000.0),2200000.0,AND($H9>=1200000.0,$I9>=650000.0),2800000.0,AND($H9>=1500000.0,$I9>=700000.0),4000000.0,TRUE,0)),0) | K9: =IFERROR(IF(AND($J9=0, IF(OR($A9="Hàng Bông",$A9="Đường Láng"),$D9>=2000000,$D9>=950000)), 500000, 0), 0) | L9: =IFERROR(SUMIFS('Hot Bill HN'!$G:$G, 'Hot Bill HN'!$C:$C, $A9, 'Hot Bill HN'!$D:$D, $B9), 0) | M9: =IFERROR($J9+$K9+$L9, 0)
A10: Đỗ Quang Đẩu | B10: Ngô Thị Thanh Thắm | C10: CHT | D10: =SUM(E10:G10)/DAY($A$1) | E10: 1543000 | F10: 2348700 | G10: 1283401 | H10: =F10/DAY($A$1) | I10: =G10/DAY($A$1) | J10: =IFERROR(IF(OR($A10="Hàng Bông",$A10="Đường Láng"),_xlfn.IFS(AND($H10>=2200000.0,$I10>=450000.0),1000000.0,AND($H10>=2500000.0,$I10>=520000.0),1600000.0,AND($H10>=2800000.0,$I10>=650000.0),2200000.0,AND($H10>=3200000.0,$I10>=750000.0),2800000.0,AND($H10>=3400000.0,$I10>=900000.0),4000000.0,TRUE,0),_xlfn.IFS(AND($H10>=630000.0,$I10>=350000.0),1000000.0,AND($H10>=850000.0,$I10>=480000.0),1600000.0,AND($H10>=1000000.0,$I10>=580000.0),2200000.0,AND($H10>=1200000.0,$I10>=650000.0),2800000.0,AND($H10>=1500000.0,$I10>=700000.0),4000000.0,TRUE,0)),0) | K10: =IFERROR(IF(AND($J10=0, IF(OR($A10="Hàng Bông",$A10="Đường Láng"),$D10>=2000000,$D10>=950000)), 500000, 0), 0) | L10: =IFERROR(SUMIFS('Hot Bill HN'!$G:$G, 'Hot Bill HN'!$C:$C, $A10, 'Hot Bill HN'!$D:$D, $B10), 0) | M10: =IFERROR($J10+$K10+$L10, 0)
A11: Đỗ Quang Đẩu | B11: Hoàng Thanh Thủy | C11: DSXC | D11: =SUM(E11:G11)/DAY($A$1) | E11: 397542 | F11: 3924462 | G11: 2236537 | H11: =F11/DAY($A$1) | I11: =G11/DAY($A$1) | J11: =IFERROR(IF(OR($A11="Hàng Bông",$A11="Đường Láng"),_xlfn.IFS(AND($H11>=2200000.0,$I11>=450000.0),1000000.0,AND($H11>=2500000.0,$I11>=520000.0),1600000.0,AND($H11>=2800000.0,$I11>=650000.0),2200000.0,AND($H11>=3200000.0,$I11>=750000.0),2800000.0,AND($H11>=3400000.0,$I11>=900000.0),4000000.0,TRUE,0),_xlfn.IFS(AND($H11>=630000.0,$I11>=350000.0),1000000.0,AND($H11>=850000.0,$I11>=480000.0),1600000.0,AND($H11>=1000000.0,$I11>=580000.0),2200000.0,AND($H11>=1200000.0,$I11>=650000.0),2800000.0,AND($H11>=1500000.0,$I11>=700000.0),4000000.0,TRUE,0)),0) | K11: =IFERROR(IF(AND($J11=0, IF(OR($A11="Hàng Bông",$A11="Đường Láng"),$D11>=2000000,$D11>=950000)), 500000, 0), 0) | L11: =IFERROR(SUMIFS('Hot Bill HN'!$G:$G, 'Hot Bill HN'!$C:$C, $A11, 'Hot Bill HN'!$D:$D, $B11), 0) | M11: =IFERROR($J11+$K11+$L11, 0)
A12: Đỗ Quang Đẩu | B12: Lê Thị Huyền Trân | C12: DSXC | D12: =SUM(E12:G12)/DAY($A$1) | E12: 1162000 | F12: 4079192 | G12: 1505502 | H12: =F12/DAY($A$1) | I12: =G12/DAY($A$1) | J12: =IFERROR(IF(OR($A12="Hàng Bông",$A12="Đường Láng"),_xlfn.IFS(AND($H12>=2200000.0,$I12>=450000.0),1000000.0,AND($H12>=2500000.0,$I12>=520000.0),1600000.0,AND($H12>=2800000.0,$I12>=650000.0),2200000.0,AND($H12>=3200000.0,$I12>=750000.0),2800000.0,AND($H12>=3400000.0,$I12>=900000.0),4000000.0,TRUE,0),_xlfn.IFS(AND($H12>=630000.0,$I12>=350000.0),1000000.0,AND($H12>=850000.0,$I12>=480000.0),1600000.0,AND($H12>=1000000.0,$I12>=580000.0),2200000.0,AND($H12>=1200000.0,$I12>=650000.0),2800000.0,AND($H12>=1500000.0,$I12>=700000.0),4000000.0,TRUE,0)),0) | K12: =IFERROR(IF(AND($J12=0, IF(OR($A12="Hàng Bông",$A12="Đường Láng"),$D12>=2000000,$D12>=950000)), 500000, 0), 0) | L12: =IFERROR(SUMIFS('Hot Bill HN'!$G:$G, 'Hot Bill HN'!$C:$C, $A12, 'Hot Bill HN'!$D:$D, $B12), 0) | M12: =IFERROR($J12+$K12+$L12, 0)
A13: Minh Châu | B13: Thái Thùy Linh | C13: CHT | D13: =SUM(E13:G13)/DAY($A$1) | E13: 100000 | F13: 4397666 | G13: 2822347 | H13: =F13/DAY($A$1) | I13: =G13/DAY($A$1) | J13: =IFERROR(IF(OR($A13="Hàng Bông",$A13="Đường Láng"),_xlfn.IFS(AND($H13>=2200000.0,$I13>=450000.0),1000000.0,AND($H13>=2500000.0,$I13>=520000.0),1600000.0,AND($H13>=2800000.0,$I13>=650000.0),2200000.0,AND($H13>=3200000.0,$I13>=750000.0),2800000.0,AND($H13>=3400000.0,$I13>=900000.0),4000000.0,TRUE,0),_xlfn.IFS(AND($H13>=630000.0,$I13>=350000.0),1000000.0,AND($H13>=850000.0,$I13>=480000.0),1600000.0,AND($H13>=1000000.0,$I13>=580000.0),2200000.0,AND($H13>=1200000.0,$I13>=650000.0),2800000.0,AND($H13>=1500000.0,$I13>=700000.0),4000000.0,TRUE,0)),0) | K13: =IFERROR(IF(AND($J13=0, IF(OR($A13="Hàng Bông",$A13="Đường Láng"),$D13>=2000000,$D13>=950000)), 500000, 0), 0) | L13: =IFERROR(SUMIFS('Hot Bill HN'!$G:$G, 'Hot Bill HN'!$C:$C, $A13, 'Hot Bill HN'!$D:$D, $B13), 0) | M13: =IFERROR($J13+$K13+$L13, 0)
A14: Minh Châu | B14: Đoàn Quốc Tâm | C14: DSXC | D14: =SUM(E14:G14)/DAY($A$1) | E14: 263000 | F14: 5969931 | G14: 5178640 | H14: =F14/DAY($A$1) | I14: =G14/DAY($A$1) | J14: =IFERROR(IF(OR($A14="Hàng Bông",$A14="Đường Láng"),_xlfn.IFS(AND($H14>=2200000.0,$I14>=450000.0),1000000.0,AND($H14>=2500000.0,$I14>=520000.0),1600000.0,AND($H14>=2800000.0,$I14>=650000.0),2200000.0,AND($H14>=3200000.0,$I14>=750000.0),2800000.0,AND($H14>=3400000.0,$I14>=900000.0),4000000.0,TRUE,0),_xlfn.IFS(AND($H14>=630000.0,$I14>=350000.0),1000000.0,AND($H14>=850000.0,$I14>=480000.0),1600000.0,AND($H14>=1000000.0,$I14>=580000.0),2200000.0,AND($H14>=1200000.0,$I14>=650000.0),2800000.0,AND($H14>=1500000.0,$I14>=700000.0),4000000.0,TRUE,0)),0) | K14: =IFERROR(IF(AND($J14=0, IF(OR($A14="Hàng Bông",$A14="Đường Láng"),$D14>=2000000,$D14>=950000)), 500000, 0), 0) | L14: =IFERROR(SUMIFS('Hot Bill HN'!$G:$G, 'Hot Bill HN'!$C:$C, $A14, 'Hot Bill HN'!$D:$D, $B14), 0) | M14: =IFERROR($J14+$K14+$L14, 0)
... A64: Đỗ Quang Đẩu | B64: Hoàng Lâm Gia Bảo | C64: DSBC | D64: =SUM(E64:G64)/DAY($A$1) | E64: 0 | F64: 0 | G64: 0 | H64: =F64/DAY($A$1) | I64: =G64/DAY($A$1) | J64: =IFERROR(IF(OR($A64="Hàng Bông",$A64="Đường Láng"),_xlfn.IFS(AND($H64>=2200000.0,$I64>=450000.0),1000000.0,AND($H64>=2500000.0,$I64>=520000.0),1600000.0,AND($H64>=2800000.0,$I64>=650000.0),2200000.0,AND($H64>=3200000.0,$I64>=750000.0),2800000.0,AND($H64>=3400000.0,$I64>=900000.0),4000000.0,TRUE,0),_xlfn.IFS(AND($H64>=630000.0,$I64>=350000.0),1000000.0,AND($H64>=850000.0,$I64>=480000.0),1600000.0,AND($H64>=1000000.0,$I64>=580000.0),2200000.0,AND($H64>=1200000.0,$I64>=650000.0),2800000.0,AND($H64>=1500000.0,$I64>=700000.0),4000000.0,TRUE,0)),0) | K64: =IFERROR(IF(AND($J64=0, IF(OR($A64="Hàng Bông",$A64="Đường Láng"),$D64>=2000000,$D64>=950000)), 500000, 0), 0) | L64: =IFERROR(SUMIFS('Hot Bill HN'!$G:$G, 'Hot Bill HN'!$C:$C, $A64, 'Hot Bill HN'!$D:$D, $B64), 0) | M64: =IFERROR($J64+$K64+$L64, 0)

Sheet Hot Bill HN
A1: Mã hóa đơn | B1: Thời gian | C1: Chi nhánh | D1: Tên Dược Sĩ | E1: Số lượng SP CK | F1: Doanh thu nhóm CK+CKHN | G1: Tiền Thưởng (VNĐ) | H1: Chi tiết sản phẩm
A2: HD1177499 | B2: 46244.899 | C2: Hàng Bông | D2: Vũ Thanh Hằng | E2: 4 | F2: 1545000 | G2: 50000 | H2: CK Advance white glutathion viên uống trắng sáng da lustrel laboratoires (h/60v) (SL: 1, TT: 1,080,000đ) | CK Xịt họng keo ong anphapolis (h/30ml) (SL: 1, TT: 125,000đ) | CKHN Manukan (h/16v) (SL: 2, TT: 340,000đ)
A3: HD1177072 | B3: 46244.474 | C3: Hàng Bông | D3: Đinh Thị Khánh Ly | E3: 2 | F3: 1145000 | G3: 50000 | H3: CKHN Chai xịt bạc ghimas powder spray (c/125ml) (SL: 1, TT: 695,000đ) | CKHN Vistra evening primrose oil 1000mg (h/45v) (SL: 1, TT: 450,000đ)
A4: HD1176145 | B4: 46243.736 | C4: Hàng Bông | D4: Vũ Thanh Hằng | E4: 4 | F4: 1172000 | G4: 50000 | H4: CKHN Manukan (h/16v) (SL: 2, TT: 340,000đ) | CK Probioboost confort gastrique fleurance nature (h/15v) (SL: 2, TT: 832,000đ)
A5: HD1175989 | B5: 46243.503 | C5: Hàng Bông | D5: Đinh Thị Khánh Ly | E5: 2 | F5: 1315000 | G5: 50000 | H5: CK Probioboost confort gastrique fleurance nature (h/15v) (SL: 1, TT: 416,000đ) | CK Cys-Control family Canneberge Arkopharma (h/20g) (SL: 1, TT: 899,000đ)
A6: HD1175970 | B6: 46243.482 | C6: Hàng Bông | D6: Đinh Thị Khánh Ly | E6: 2 | F6: 1390000 | G6: 50000 | H6: CKHN Chai xịt bạc ghimas powder spray (c/125ml) (SL: 2, TT: 1,390,000đ)
A7: HD1174981 | B7: 46242.752 | C7: Hàng Bông | D7: Đinh Thị Lan Anh | E7: 2 | F7: 1111000 | G7: 50000 | H7: CK Radis noir artichaut bio fleurance nature (h/30v) (SL: 1, TT: 416,000đ) | CKHN Chai xịt bạc ghimas powder spray (c/125ml) (SL: 1, TT: 695,000đ)
A8: HD1174848 | B8: 46242.582 | C8: Hàng Bông | D8: Vũ Thanh Hằng | E8: 1 | F8: 1080000 | G8: 50000 | H8: CK Advance white glutathion viên uống trắng sáng da lustrel laboratoires (h/60v) (SL: 1, TT: 1,080,000đ)
A9: HD1173977 | B9: 46241.931 | C9: Hàng Bông | D9: Đinh Thị Khánh Ly | E9: 2 | F9: 1315000 | G9: 50000 | H9: CK Radis noir artichaut bio fleurance nature (h/30v) (SL: 1, TT: 416,000đ) | CK Cys-Control family Canneberge Arkopharma (h/20g) (SL: 1, TT: 899,000đ)
A10: HD1168139 | B10: 46236.962 | C10: Đường Láng | D10: Nguyễn Thị Mai Duyên | E10: 2 | F10: 1309000 | G10: 50000 | H10: CK Puissance+ viên uống tăng cường sinh lực fleurance nature (h/30v) (SL: 1, TT: 649,000đ) | CK Maca #6 old truths nature's supplements (h/60v) (SL: 1, TT: 660,000đ)
A11: HD1167793 | B11: 46236.645 | C11: Hàng Bông | D11: Đinh Thị Khánh Ly | E11: 6 | F11: 2917000 | G11: 50000 | H11: CK Calcium 600 eurho vital (h/30v) (SL: 1, TT: 325,000đ) | CK Omega 3 viên uống bổ sung omega 3 arkopharma (h/60v) (SL: 2, TT: 754,000đ) | CK All in one vitality viên uống chống oxy hóa sante + (h/60v) (SL: 2, TT: 1,178,000đ) | CK Maca #6 old truths nature's supplements (h/60v) (SL: 1, TT: 660,000đ)
A12: HD1167533 | B12: 46236.269 | C12: Hàng Bông | D12: Vũ Thanh Hằng | E12: 2 | F12: 1105000 | G12: 50000 | H12: CK Advance white glutathion viên uống trắng sáng da lustrel laboratoires (h/60v) (SL: 1, TT: 980,000đ) | CK Xịt họng keo ong anphapolis (h/30ml) (SL: 1, TT: 125,000đ)
A13: HD1166478 | B13: 46235.551 | C13: Hàng Bông | D13: Vũ Thanh Hằng | E13: 4 | F13: 1035000 | G13: 50000 | H13: CK Bách địa khang usvip (h/30v) (SL: 1, TT: 130,000đ) | CKHN Mason Natural Daily Multiple Vitamins with Minerals (h/60v) (SL: 1, TT: 620,000đ) | CKHN Manukan (h/16v) (SL: 1, TT: 160,000đ) | CK Xịt họng keo ong anphapolis (h/30ml) (SL: 1, TT: 125,000đ)
A14: HD1166155 | B14: 46235.177 | C14: Đường Láng | D14: Nguyễn Thị Tâm | E14: 10 | F14: 1235000 | G14: 50000 | H14: CKHN Orezul bù nước điện giải hương cam yalla (h/20g) (SL: 5, TT: 600,000đ) | CK Sodmex plus cream (h/15g) (SL: 5, TT: 635,000đ)
