Workbook

Sheet data
A1: Nhà thuốc | B1: Tên nhân viên | C1: Số giao dịch off | D1: Doanh thu off | E1: Số giao dịch onl | F1: Doanh thu onl | G1: Tổng giao dịch | H1: Doanh thu tổng | J1: 46275
A2: Hàng Bông | B2: Nguyễn Mạnh Tuấn | C2: 253 | D2: 44005321 | E2: 139 | F2: 18588246 | G2: 392 | H2: 62593567
A3: Hàng Bông | B3: Vũ Thanh Hằng | C3: 205 | D3: 69518430 | E3: 47 | F3: 10051633 | G3: 252 | H3: 79570063
A4: Hàng Bông | B4: Đinh Thị Khánh Ly | C4: 287 | D4: 81207691 | E4: 66 | F4: 19890500 | G4: 353 | H4: 101098191
A5: Hàng Bông | B5: Đinh Thị Lan Anh | C5: 180 | D5: 37379380 | E5: 34 | F5: 6845600 | G5: 214 | H5: 44224980
A6: Hàng Bông | B6: Đỗ Thu Huệ | C6: 64 | D6: 8535200 | E6: 28 | F6: 4803400 | G6: 92 | H6: 13338600
A7: Lê Bình | B7: Hoàng Lâm Gia Bảo | C7: 86 | D7: 11634400 | E7: 62 | F7: 15452800 | G7: 148 | H7: 27087200
A8: Lê Bình | B8: Hồ Thị Minh Hòa | C8: 97 | D8: 7905900 | E8: 49 | F8: 9217850 | G8: 146 | H8: 17123750
A9: Lê Bình | B9: Lê Thị Xuyến | C9: 119 | D9: 9274600 | E9: 47 | F9: 7668800 | G9: 166 | H9: 16943400
A10: Lê Bình | B10: Ngô Thị Thanh Thắm | C10: 7 | D10: 1087900 | E10: 3 | F10: 521000 | G10: 10 | H10: 1608900
A11: Lê Bình | B11: Phạm Nguyễn Ngọc Quý | C11: 7 | D11: 324400 | G11: 7 | H11: 324400
A12: Lê Bình | B12: Đinh Hoài Bảo | C12: 71 | D12: 5564400 | E12: 43 | F12: 5346600 | G12: 114 | H12: 10911000
A13: Minh Châu | B13: Nguyễn Ngọc Thùy | C13: 185 | D13: 13887900 | E13: 39 | F13: 5532350 | G13: 224 | H13: 19420250
A14: Minh Châu | B14: Phan Công Vũ Tài | C14: 175 | D14: 14620500 | E14: 25 | F14: 3383300 | G14: 200 | H14: 18003800
A15: Minh Châu | B15: Thái Thùy Linh | C15: 419 | D15: 28832400 | E15: 54 | F15: 6278500 | G15: 473 | H15: 35110900
A16: Minh Châu | B16: Đoàn Quốc Tâm | C16: 202 | D16: 15436450 | E16: 78 | F16: 23292200 | G16: 280 | H16: 38728650
A17: Nam Hòa | B17: Bùi Thị Thanh Thủy | C17: 73 | D17: 5574000 | E17: 46 | F17: 40265400 | G17: 119 | H17: 45839400
A18: Nam Hòa | B18: Dương Thị Huỳnh Như | C18: 158 | D18: 14719600 | E18: 42 | F18: 5573900 | G18: 200 | H18: 20293500
A19: Nam Hòa | B19: Nguyễn Thị Huyền Trang | C19: 118 | D19: 7125900 | E19: 41 | F19: 9565800 | G19: 159 | H19: 16691700
A20: Nam Hòa | B20: Phan Công Vũ Tài | C20: 1 | D20: 36000 | G20: 1 | H20: 36000
A21: Nam Hòa | B21: Trần Thị Ánh Nguyệt | C21: 155 | D21: 11020900 | E21: 48 | F21: 7310700 | G21: 203 | H21: 18331600
A22: Nguyễn Chí Thanh | B22: Lê Thị Quỳnh Trâm | C22: 107 | D22: 9742400 | E22: 64 | F22: 12443800 | G22: 171 | H22: 22186200
A23: Nguyễn Chí Thanh | B23: Lý Thục Mi | C23: 27 | D23: 2376900 | E23: 6 | F23: 2046000 | G23: 33 | H23: 4422900
A24: Nguyễn Chí Thanh | B24: Nguyễn Thị Hồng Hạnh | C24: 274 | D24: 20877200 | E24: 31 | F24: 4339800 | G24: 305 | H24: 25217000
A25: Nguyễn Chí Thanh | B25: Trần Hoàng Khánh | C25: 276 | D25: 20646600 | E25: 71 | F25: 10980300 | G25: 347 | H25: 31626900
A26: Nguyễn Chí Thanh | B26: Đỗ Thị Phương Thảo | C26: 115 | D26: 8534200 | E26: 55 | F26: 16299500 | G26: 170 | H26: 24833700
A27: Nguyễn Thị Thập | B27: Cao Trọng Nhân | C27: 309 | D27: 21778500 | E27: 131 | F27: 27676720 | G27: 440 | H27: 49455220
A28: Nguyễn Thị Thập | B28: Ngô Thị Ngọc Thủy | C28: 10 | D28: 444300 | E28: 11 | F28: 1183900 | G28: 21 | H28: 1628200
A29: Nguyễn Thị Thập | B29: Triệu Thị Ngọc Lý | C29: 197 | D29: 11996100 | E29: 142 | F29: 28962102 | G29: 339 | H29: 40958202
A30: Nguyễn Thị Thập | B30: Trần Thành Đạt | C30: 229 | D30: 17795600 | E30: 87 | F30: 17598800 | G30: 316 | H30: 35394400
A31: Nguyễn Văn Quá | B31: Hoàng Lâm Gia Bảo | C31: 33 | D31: 3408800 | E31: 10 | F31: 888500 | G31: 43 | H31: 4297300
A32: Nguyễn Văn Quá | B32: Hồ Ngọc Lý | C32: 519 | D32: 34232000 | E32: 67 | F32: 6909450 | G32: 586 | H32: 41141450
... A50: Đường Láng | B50: Lê Thị Soạn | C50: 349 | D50: 42297896 | E50: 180 | F50: 32587800 | G50: 529 | H50: 74885696
A51: Đường Láng | B51: Medigo | E51: 2 | F51: 76000 | G51: 2 | H51: 76000
A52: Đường Láng | B52: Nguyễn Thị Mai Duyên | C52: 329 | D52: 46024248 | E52: 202 | F52: 43058000 | G52: 531 | H52: 89082248
A53: Đường Láng | B53: Nguyễn Thị Tâm | C53: 105 | D53: 12257500 | E53: 149 | F53: 42853200 | G53: 254 | H53: 55110700
A54: Đường Láng | B54: Trần Ngọc Dung | C54: 72 | D54: 7029800 | E54: 105 | F54: 26080850 | G54: 177 | H54: 33110650
A55: Đỗ Quang Đẩu | B55: Hoàng Lâm Gia Bảo | C55: 3 | D55: 765500 | E55: 5 | F55: 870000 | G55: 8 | H55: 1635500
A56: Đỗ Quang Đẩu | B56: Hoàng Thanh Thủy | C56: 155 | D56: 38890420 | E56: 67 | F56: 16244200 | G56: 222 | H56: 55134620
A57: Đỗ Quang Đẩu | B57: Lê Thị Huyền Trân | C57: 212 | D57: 39740900 | E57: 77 | F57: 14954800 | G57: 289 | H57: 54695700
...

Sheet kpi dược sĩ
A1: Dữ liệu cập nhật đến ngày | C1: 46275 | O1: Mức hoành thành KPI | R1: Mức hoành thành KPI
A2: Nhà thuốc | B2: Nhân viên | C2: Chức danh | D2: KPI trung bình bill | E2: Trung bình bill | F2: KPI doanh thu CK+Combo+NY3/ngày | G2: CK + Combo + NY3/ngày | H2: KPI Doanh thu/ngày (100%) | I2: Doanh thu thực/ngày | J2: % Hoàn thành KPI | K2: Thưởng KPI | L2: Hệ số * Dự án | M2: Thưởng Dự án | N2: Thưởng Dự án + KPI + HH | O2: 0.8 | P2: 0.9 | Q2: 1 | R2: 0.8 | S2: 0.9 | T2: 1 | U2: KPIs Doanh thu/ngày | V2: KPIs Doanh thu/tháng | W2: Số giao dịch off | X2: Doanh thu off | Y2: Trung bình bill off | Z2: Số giao dịch onl | AA2: Doanh thu onl | AB2: Trung bình bill onl | AC2: Tổng giao dịch | AD2: Doanh thu tổng | AE2: Trung bình Bill
A3: Trường Sa | B3: Nguyễn Trần Ngọc Phương | C3: Q.CHT | D3: 150000 | E3: =AE3 -> 88098.81 | F3: =IFERROR(ROUND(_xludf.LET(nt,$A3,nv,$B3,songay,DAY(EOMONTH($C$1,0)),doanhthungay,$I3,duan_nv,SUMIFS('Dự án T9'!$D:$D,'Dự án T9'!$A:$A,nt,'Dự án T9'!$B:$B,nv),duan_nt,SUMIFS('Dự án T9'!$D:$D,'Dự án T9'!$A:$A,nt),tyle,duan_nv/duan_nt,muc2_ngay,_xlfn.XLOOKUP(nt,'kpi nhà thuốc'!$B:$B,'kpi nhà thuốc'!$P:$P),muc3_ngay,_xlfn.XLOOKUP(nt,'kpi nhà thuốc'!$B:$B,'kpi nhà thuốc'!$T:$T),hangdiem1,_xlfn.XLOOKUP(nt,'kpi nhà thuốc'!$B:$B,'kpi nhà thuốc'!$I:$I),hangdiem2,_xlfn.XLOOKUP(nt,'kpi nhà thuốc'!$B:$B,'kpi nhà thuốc'!$N:$N),hangdiem3,_xlfn.XLOOKUP(nt,'kpi nhà thuốc'!$B:$B,'kpi nhà thuốc'!$R:$R),_xludf.SWITCH(TRUE,doanhthungay>=muc3_ngay,hangdiem3,doanhthungay>=muc2_ngay,hangdiem2,TRUE,hangdiem1)/songay*tyle),-3),0) -> 0 | G3: =IFERROR(SUMIF('Dự án T9'!$B:$B, $B3, 'Dự án T9'!$D:$D), 0) -> 699788.4 | H3: =Q3 -> 12800000 | I3: =(AD3/DAY($C$1)) -> 1480060 | J3: =_xlfn.XLOOKUP(B3, 'kpi nhà thuốc'!A:A, 'kpi nhà thuốc'!F:F, (AD3/DAY($C$1))/U3) -> 0.20039975 | K3: =_xlfn.XLOOKUP(B3, 'kpi nhà thuốc'!$A:$A, 'kpi nhà thuốc'!$G:$G, IF(AND(OR(C3="DSXC", C3="DSCD", C3="DSBC", C3="DSTV", C3="Q.CHT", C3="BC", C3="DSHV"), G3>=F3), AD3 * _xlfn.IFS(AND(I3>=T3, E3>=D3), 0.015, I3>=T3, 0.013, AND(I3>=S3, E3>=D3), 0.013, I3>=S3, 0.011, AND(I3>=R3, E3>=D3), 0.012, I3>=R3, 0.01, TRUE, 0), 0)) -> 0 | L3: =IF(C3="DSTV","", IF(J3<0.6, 0.8, 1)) -> 0.8 | M3: =IFERROR(SUMIF('Dự án T9'!$B:$B, $B3, 'Dự án T9'!$M:$M)*$L3, 0) -> 0 | N3: =N(K3)+M3 -> 0 | O3: =CEILING(R3, 100000) -> 10300000 | P3: =CEILING(S3, 100000) -> 11600000 | Q3: =CEILING(T3, 100000) -> 12800000 | R3: =U3*$R$2 -> 10240000 | S3: =U3*$S$2 -> 11520000 | T3: =U3*$T$2 -> 12800000 | U3: =V3/DAY($C$1) -> 12800000 | V3: 128000000 | W3: =IFERROR(SUMIFS(data!$C:$C, data!$A:$A, $A3, data!$B:$B, $B3), 0) -> 110 | X3: =IFERROR(SUMIF(data!$B:$B, $B3, data!$D:$D), 0) -> 5766100 | Y3: =IF(W3>0, X3/W3, 0) -> 52419.091 | Z3: =IFERROR(SUMIFS(data!$E:$E, data!$A:$A, $A3, data!$B:$B, $B3), 0) -> 58 | AA3: =IFERROR(SUMIF(data!$B:$B, $B3, data!$F:$F), 0) -> 9034500 | AB3: =IF(Z3>0, AA3/Z3, 0) -> 155767.24 | AC3: =W3+Z3 -> 168 | AD3: =X3+AA3 -> 14800600 | AE3: =IF(AC3>0, AD3/AC3, 0) -> 88098.81
A4: Trường Sa | B4: Phạm Nguyễn Ngọc Quý | C4: DSXC | D4: 130000 | E4: =AE4 -> 131181.21 | F4: =IFERROR(ROUND(_xludf.LET(nt,$A4,nv,$B4,songay,DAY(EOMONTH($C$1,0)),doanhthungay,$I4,duan_nv,SUMIFS('Dự án T9'!$D:$D,'Dự án T9'!$A:$A,nt,'Dự án T9'!$B:$B,nv),duan_nt,SUMIFS('Dự án T9'!$D:$D,'Dự án T9'!$A:$A,nt),tyle,duan_nv/duan_nt,muc2_ngay,_xlfn.XLOOKUP(nt,'kpi nhà thuốc'!$B:$B,'kpi nhà thuốc'!$P:$P),muc3_ngay,_xlfn.XLOOKUP(nt,'kpi nhà thuốc'!$B:$B,'kpi nhà thuốc'!$T:$T),hangdiem1,_xlfn.XLOOKUP(nt,'kpi nhà thuốc'!$B:$B,'kpi nhà thuốc'!$I:$I),hangdiem2,_xlfn.XLOOKUP(nt,'kpi nhà thuốc'!$B:$B,'kpi nhà thuốc'!$N:$N),hangdiem3,_xlfn.XLOOKUP(nt,'kpi nhà thuốc'!$B:$B,'kpi nhà thuốc'!$R:$R),_xludf.SWITCH(TRUE,doanhthungay>=muc3_ngay,hangdiem3,doanhthungay>=muc2_ngay,hangdiem2,TRUE,hangdiem1)/songay*tyle),-3),0) -> 0 | G4: =IFERROR(SUMIF('Dự án T9'!$B:$B, $B4, 'Dự án T9'!$D:$D), 0) -> 1067866.5 | H4: =Q4 -> 12800000 | I4: =(AD4/DAY($C$1)) -> 3043404 | J4: =_xlfn.XLOOKUP(B4, 'kpi nhà thuốc'!A:A, 'kpi nhà thuốc'!F:F, (AD4/DAY($C$1))/U4) -> 0.23776594 | K4: =_xlfn.XLOOKUP(B4, 'kpi nhà thuốc'!$A:$A, 'kpi nhà thuốc'!$G:$G, IF(AND(OR(C4="DSXC", C4="DSCD", C4="DSBC", C4="DSTV", C4="Q.CHT", C4="BC", C4="DSHV"), G4>=F4), AD4 * _xlfn.IFS(AND(I4>=T4, E4>=D4), 0.015, I4>=T4, 0.013, AND(I4>=S4, E4>=D4), 0.013, I4>=S4, 0.011, AND(I4>=R4, E4>=D4), 0.012, I4>=R4, 0.01, TRUE, 0), 0)) -> 0 | L4: =IF(C4="DSTV","", IF(J4<0.6, 0.8, 1)) -> 0.8 | M4: =IFERROR(SUMIF('Dự án T9'!$B:$B, $B4, 'Dự án T9'!$M:$M)*$L4, 0) -> 800000 | N4: =N(K4)+M4 -> 800000 | O4: =CEILING(R4, 100000) -> 10300000 | P4: =CEILING(S4, 100000) -> 11600000 | Q4: =CEILING(T4, 100000) -> 12800000 | R4: =U4*$R$2 -> 10240000 | S4: =U4*$S$2 -> 11520000 | T4: =U4*$T$2 -> 12800000 | U4: =V4/DAY($C$1) -> 12800000 | V4: 128000000 | W4: =IFERROR(SUMIFS(data!$C:$C, data!$A:$A, $A4, data!$B:$B, $B4), 0) -> 161 | X4: =IFERROR(SUMIF(data!$B:$B, $B4, data!$D:$D), 0) -> 12039900 | Y4: =IF(W4>0, X4/W4, 0) -> 74781.988 | Z4: =IFERROR(SUMIFS(data!$E:$E, data!$A:$A, $A4, data!$B:$B, $B4), 0) -> 71 | AA4: =IFERROR(SUMIF(data!$B:$B, $B4, data!$F:$F), 0) -> 18394140 | AB4: =IF(Z4>0, AA4/Z4, 0) -> 259072.39 | AC4: =W4+Z4 -> 232 | AD4: =X4+AA4 -> 30434040 | AE4: =IF(AC4>0, AD4/AC4, 0) -> 131181.21
A5: Trường Sa | B5: Nguyễn Ngọc Anh Thư | C5: DSHV | D5: 100000 | E5: =AE5 -> 99062.981 | F5: =IFERROR(ROUND(_xludf.LET(nt,$A5,nv,$B5,songay,DAY(EOMONTH($C$1,0)),doanhthungay,$I5,duan_nv,SUMIFS('Dự án T9'!$D:$D,'Dự án T9'!$A:$A,nt,'Dự án T9'!$B:$B,nv),duan_nt,SUMIFS('Dự án T9'!$D:$D,'Dự án T9'!$A:$A,nt),tyle,duan_nv/duan_nt,muc2_ngay,_xlfn.XLOOKUP(nt,'kpi nhà thuốc'!$B:$B,'kpi nhà thuốc'!$P:$P),muc3_ngay,_xlfn.XLOOKUP(nt,'kpi nhà thuốc'!$B:$B,'kpi nhà thuốc'!$T:$T),hangdiem1,_xlfn.XLOOKUP(nt,'kpi nhà thuốc'!$B:$B,'kpi nhà thuốc'!$I:$I),hangdiem2,_xlfn.XLOOKUP(nt,'kpi nhà thuốc'!$B:$B,'kpi nhà thuốc'!$N:$N),hangdiem3,_xlfn.XLOOKUP(nt,'kpi nhà thuốc'!$B:$B,'kpi nhà thuốc'!$R:$R),_xludf.SWITCH(TRUE,doanhthungay>=muc3_ngay,hangdiem3,doanhthungay>=muc2_ngay,hangdiem2,TRUE,hangdiem1)/songay*tyle),-3),0) -> 0 | G5: =IFERROR(SUMIF('Dự án T9'!$B:$B, $B5, 'Dự án T9'!$D:$D), 0) -> 819035.3 | H5: =Q5 -> 12800000 | I5: =(AD5/DAY($C$1)) -> 2060510 | J5: =_xlfn.XLOOKUP(B5, 'kpi nhà thuốc'!A:A, 'kpi nhà thuốc'!F:F, (AD5/DAY($C$1))/U5) -> 0.16097734 | K5: =_xlfn.XLOOKUP(B5, 'kpi nhà thuốc'!$A:$A, 'kpi nhà thuốc'!$G:$G, IF(AND(OR(C5="DSXC", C5="DSCD", C5="DSBC", C5="DSTV", C5="Q.CHT", C5="BC", C5="DSHV"), G5>=F5), AD5 * _xlfn.IFS(AND(I5>=T5, E5>=D5), 0.015, I5>=T5, 0.013, AND(I5>=S5, E5>=D5), 0.013, I5>=S5, 0.011, AND(I5>=R5, E5>=D5), 0.012, I5>=R5, 0.01, TRUE, 0), 0)) -> 0 | L5: =IF(C5="DSTV","", IF(J5<0.6, 0.8, 1)) -> 0.8 | M5: =IFERROR(SUMIF('Dự án T9'!$B:$B, $B5, 'Dự án T9'!$M:$M)*$L5, 0) -> 0 | N5: =N(K5)+M5 -> 0 | O5: =CEILING(R5, 100000) -> 10300000 | P5: =CEILING(S5, 100000) -> 11600000 | Q5: =CEILING(T5, 100000) -> 12800000 | R5: =U5*$R$2 -> 10240000 | S5: =U5*$S$2 -> 11520000 | T5: =U5*$T$2 -> 12800000 | U5: =V5/DAY($C$1) -> 12800000 | V5: 128000000 | W5: =IFERROR(SUMIFS(data!$C:$C, data!$A:$A, $A5, data!$B:$B, $B5), 0) -> 121 | X5: =IFERROR(SUMIF(data!$B:$B, $B5, data!$D:$D), 0) -> 6675600 | Y5: =IF(W5>0, X5/W5, 0) -> 55170.248 | Z5: =IFERROR(SUMIFS(data!$E:$E, data!$A:$A, $A5, data!$B:$B, $B5), 0) -> 87 | AA5: =IFERROR(SUMIF(data!$B:$B, $B5, data!$F:$F), 0) -> 13929500 | AB5: =IF(Z5>0, AA5/Z5, 0) -> 160109.2 | AC5: =W5+Z5 -> 208 | AD5: =X5+AA5 -> 20605100 | AE5: =IF(AC5>0, AD5/AC5, 0) -> 99062.981
A6: Trường Sa | B6: Trần Thị Kim Khánh | C6: DSCD | D6: 175000 | E6: =AE6 -> 109174.73 | F6: =IFERROR(ROUND(_xludf.LET(nt,$A6,nv,$B6,songay,DAY(EOMONTH($C$1,0)),doanhthungay,$I6,duan_nv,SUMIFS('Dự án T9'!$D:$D,'Dự án T9'!$A:$A,nt,'Dự án T9'!$B:$B,nv),duan_nt,SUMIFS('Dự án T9'!$D:$D,'Dự án T9'!$A:$A,nt),tyle,duan_nv/duan_nt,muc2_ngay,_xlfn.XLOOKUP(nt,'kpi nhà thuốc'!$B:$B,'kpi nhà thuốc'!$P:$P),muc3_ngay,_xlfn.XLOOKUP(nt,'kpi nhà thuốc'!$B:$B,'kpi nhà thuốc'!$T:$T),hangdiem1,_xlfn.XLOOKUP(nt,'kpi nhà thuốc'!$B:$B,'kpi nhà thuốc'!$I:$I),hangdiem2,_xlfn.XLOOKUP(nt,'kpi nhà thuốc'!$B:$B,'kpi nhà thuốc'!$N:$N),hangdiem3,_xlfn.XLOOKUP(nt,'kpi nhà thuốc'!$B:$B,'kpi nhà thuốc'!$R:$R),_xludf.SWITCH(TRUE,doanhthungay>=muc3_ngay,hangdiem3,doanhthungay>=muc2_ngay,hangdiem2,TRUE,hangdiem1)/songay*tyle),-3),0) -> 0 | G6: =IFERROR(SUMIF('Dự án T9'!$B:$B, $B6, 'Dự án T9'!$D:$D), 0) -> 1058477.8 | H6: =Q6 -> 12800000 | I6: =(AD6/DAY($C$1)) -> 1986980 | J6: =_xlfn.XLOOKUP(B6, 'kpi nhà thuốc'!A:A, 'kpi nhà thuốc'!F:F, (AD6/DAY($C$1))/U6) -> 0.15523281 | K6: =_xlfn.XLOOKUP(B6, 'kpi nhà thuốc'!$A:$A, 'kpi nhà thuốc'!$G:$G, IF(AND(OR(C6="DSXC", C6="DSCD", C6="DSBC", C6="DSTV", C6="Q.CHT", C6="BC", C6="DSHV"), G6>=F6), AD6 * _xlfn.IFS(AND(I6>=T6, E6>=D6), 0.015, I6>=T6, 0.013, AND(I6>=S6, E6>=D6), 0.013, I6>=S6, 0.011, AND(I6>=R6, E6>=D6), 0.012, I6>=R6, 0.01, TRUE, 0), 0)) -> 0 | L6: =IF(C6="DSTV","", IF(J6<0.6, 0.8, 1)) -> 0.8 | M6: =IFERROR(SUMIF('Dự án T9'!$B:$B, $B6, 'Dự án T9'!$M:$M)*$L6, 0) -> 400000 | N6: =N(K6)+M6 -> 400000 | O6: =CEILING(R6, 100000) -> 10300000 | P6: =CEILING(S6, 100000) -> 11600000 | Q6: =CEILING(T6, 100000) -> 12800000 | R6: =U6*$R$2 -> 10240000 | S6: =U6*$S$2 -> 11520000 | T6: =U6*$T$2 -> 12800000 | U6: =V6/DAY($C$1) -> 12800000 | V6: 128000000 | W6: =IFERROR(SUMIFS(data!$C:$C, data!$A:$A, $A6, data!$B:$B, $B6), 0) -> 118 | X6: =IFERROR(SUMIF(data!$B:$B, $B6, data!$D:$D), 0) -> 9708400 | Y6: =IF(W6>0, X6/W6, 0) -> 82274.576 | Z6: =IFERROR(SUMIFS(data!$E:$E, data!$A:$A, $A6, data!$B:$B, $B6), 0) -> 64 | AA6: =IFERROR(SUMIF(data!$B:$B, $B6, data!$F:$F), 0) -> 10161400 | AB6: =IF(Z6>0, AA6/Z6, 0) -> 158771.88 | AC6: =W6+Z6 -> 182 | AD6: =X6+AA6 -> 19869800 | AE6: =IF(AC6>0, AD6/AC6, 0) -> 109174.73
A7: Trường Sa | B7: Trịnh Thị Phượng | C7: DSCD | D7: 175000 | E7: =AE7 -> 106850.62 | F7: =IFERROR(ROUND(_xludf.LET(nt,$A7,nv,$B7,songay,DAY(EOMONTH($C$1,0)),doanhthungay,$I7,duan_nv,SUMIFS('Dự án T9'!$D:$D,'Dự án T9'!$A:$A,nt,'Dự án T9'!$B:$B,nv),duan_nt,SUMIFS('Dự án T9'!$D:$D,'Dự án T9'!$A:$A,nt),tyle,duan_nv/duan_nt,muc2_ngay,_xlfn.XLOOKUP(nt,'kpi nhà thuốc'!$B:$B,'kpi nhà thuốc'!$P:$P),muc3_ngay,_xlfn.XLOOKUP(nt,'kpi nhà thuốc'!$B:$B,'kpi nhà thuốc'!$T:$T),hangdiem1,_xlfn.XLOOKUP(nt,'kpi nhà thuốc'!$B:$B,'kpi nhà thuốc'!$I:$I),hangdiem2,_xlfn.XLOOKUP(nt,'kpi nhà thuốc'!$B:$B,'kpi nhà thuốc'!$N:$N),hangdiem3,_xlfn.XLOOKUP(nt,'kpi nhà thuốc'!$B:$B,'kpi nhà thuốc'!$R:$R),_xludf.SWITCH(TRUE,doanhthungay>=muc3_ngay,hangdiem3,doanhthungay>=muc2_ngay,hangdiem2,TRUE,hangdiem1)/songay*tyle),-3),0) -> 0 | G7: =IFERROR(SUMIF('Dự án T9'!$B:$B, $B7, 'Dự án T9'!$D:$D), 0) -> 0 | H7: =Q7 -> 12800000 | I7: =(AD7/DAY($C$1)) -> 3440590 | J7: =_xlfn.XLOOKUP(B7, 'kpi nhà thuốc'!A:A, 'kpi nhà thuốc'!F:F, (AD7/DAY($C$1))/U7) -> 0.26879609 | K7: =_xlfn.XLOOKUP(B7, 'kpi nhà thuốc'!$A:$A, 'kpi nhà thuốc'!$G:$G, IF(AND(OR(C7="DSXC", C7="DSCD", C7="DSBC", C7="DSTV", C7="Q.CHT", C7="BC", C7="DSHV"), G7>=F7), AD7 * _xlfn.IFS(AND(I7>=T7, E7>=D7), 0.015, I7>=T7, 0.013, AND(I7>=S7, E7>=D7), 0.013, I7>=S7, 0.011, AND(I7>=R7, E7>=D7), 0.012, I7>=R7, 0.01, TRUE, 0), 0)) -> 0 | L7: =IF(C7="DSTV","", IF(J7<0.6, 0.8, 1)) -> 0.8 | M7: =IFERROR(SUMIF('Dự án T9'!$B:$B, $B7, 'Dự án T9'!$M:$M)*$L7, 0) -> 0 | N7: =N(K7)+M7 -> 0 | O7: =CEILING(R7, 100000) -> 10300000 | P7: =CEILING(S7, 100000) -> 11600000 | Q7: =CEILING(T7, 100000) -> 12800000 | R7: =U7*$R$2 -> 10240000 | S7: =U7*$S$2 -> 11520000 | T7: =U7*$T$2 -> 12800000 | U7: =V7/DAY($C$1) -> 12800000 | V7: 128000000 | W7: =IFERROR(SUMIFS(data!$C:$C, data!$A:$A, $A7, data!$B:$B, $B7), 0) -> 236 | X7: =IFERROR(SUMIF(data!$B:$B, $B7, data!$D:$D), 0) -> 22440900 | Y7: =IF(W7>0, X7/W7, 0) -> 95088.559 | Z7: =IFERROR(SUMIFS(data!$E:$E, data!$A:$A, $A7, data!$B:$B, $B7), 0) -> 86 | AA7: =IFERROR(SUMIF(data!$B:$B, $B7, data!$F:$F), 0) -> 11965000 | AB7: =IF(Z7>0, AA7/Z7, 0) -> 139127.91 | AC7: =W7+Z7 -> 322 | AD7: =X7+AA7 -> 34405900 | AE7: =IF(AC7>0, AD7/AC7, 0) -> 106850.62
A8: Đỗ Quang Đẩu | B8: Phạm Thị Nghĩa Hương | C8: DSCD | D8: 187974 | E8: =AE8 -> 199475.42 | F8: =IFERROR(ROUND(_xludf.LET(nt,$A8,nv,$B8,songay,DAY(EOMONTH($C$1,0)),doanhthungay,$I8,duan_nv,SUMIFS('Dự án T9'!$D:$D,'Dự án T9'!$A:$A,nt,'Dự án T9'!$B:$B,nv),duan_nt,SUMIFS('Dự án T9'!$D:$D,'Dự án T9'!$A:$A,nt),tyle,duan_nv/duan_nt,muc2_ngay,_xlfn.XLOOKUP(nt,'kpi nhà thuốc'!$B:$B,'kpi nhà thuốc'!$P:$P),muc3_ngay,_xlfn.XLOOKUP(nt,'kpi nhà thuốc'!$B:$B,'kpi nhà thuốc'!$T:$T),hangdiem1,_xlfn.XLOOKUP(nt,'kpi nhà thuốc'!$B:$B,'kpi nhà thuốc'!$I:$I),hangdiem2,_xlfn.XLOOKUP(nt,'kpi nhà thuốc'!$B:$B,'kpi nhà thuốc'!$N:$N),hangdiem3,_xlfn.XLOOKUP(nt,'kpi nhà thuốc'!$B:$B,'kpi nhà thuốc'!$R:$R),_xludf.SWITCH(TRUE,doanhthungay>=muc3_ngay,hangdiem3,doanhthungay>=muc2_ngay,hangdiem2,TRUE,hangdiem1)/songay*tyle),-3),0) -> 0 | G8: =IFERROR(SUMIF('Dự án T9'!$B:$B, $B8, 'Dự án T9'!$D:$D), 0) -> 381832.4 | H8: =Q8 -> 24000000 | I8: =(AD8/DAY($C$1)) -> 3570610 | J8: =_xlfn.XLOOKUP(B8, 'kpi nhà thuốc'!A:A, 'kpi nhà thuốc'!F:F, (AD8/DAY($C$1))/U8) -> 0.14877542 | K8: =_xlfn.XLOOKUP(B8, 'kpi nhà thuốc'!$A:$A, 'kpi nhà thuốc'!$G:$G, IF(AND(OR(C8="DSXC", C8="DSCD", C8="DSBC", C8="DSTV", C8="Q.CHT", C8="BC", C8="DSHV"), G8>=F8), AD8 * _xlfn.IFS(AND(I8>=T8, E8>=D8), 0.015, I8>=T8, 0.013, AND(I8>=S8, E8>=D8), 0.013, I8>=S8, 0.011, AND(I8>=R8, E8>=D8), 0.012, I8>=R8, 0.01, TRUE, 0), 0)) -> 0 | L8: =IF(C8="DSTV","", IF(J8<0.6, 0.8, 1)) -> 0.8 | M8: =IFERROR(SUMIF('Dự án T9'!$B:$B, $B8, 'Dự án T9'!$M:$M)*$L8, 0) -> 0 | N8: =N(K8)+M8 -> 0 | O8: =CEILING(R8, 100000) -> 19200000 | P8: =CEILING(S8, 100000) -> 21600000 | Q8: =CEILING(T8, 100000) -> 24000000 | R8: =U8*$R$2 -> 19200000 | S8: =U8*$S$2 -> 21600000 | T8: =U8*$T$2 -> 24000000 | U8: =V8/DAY($C$1) -> 24000000 | V8: 240000000 | W8: =IFERROR(SUMIFS(data!$C:$C, data!$A:$A, $A8, data!$B:$B, $B8), 0) -> 135 | X8: =IFERROR(SUMIF(data!$B:$B, $B8, data!$D:$D), 0) -> 30834300 | Y8: =IF(W8>0, X8/W8, 0) -> 228402.22 | Z8: =IFERROR(SUMIFS(data!$E:$E, data!$A:$A, $A8, data!$B:$B, $B8), 0) -> 44 | AA8: =IFERROR(SUMIF(data!$B:$B, $B8, data!$F:$F), 0) -> 4871800 | AB8: =IF(Z8>0, AA8/Z8, 0) -> 110722.73 | AC8: =W8+Z8 -> 179 | AD8: =X8+AA8 -> 35706100 | AE8: =IF(AC8>0, AD8/AC8, 0) -> 199475.42
A9: Đỗ Quang Đẩu | B9: Trần Thiên Phát | C9: DSXC | D9: 204503 | E9: =AE9 -> 153570.11 | F9: =IFERROR(ROUND(_xludf.LET(nt,$A9,nv,$B9,songay,DAY(EOMONTH($C$1,0)),doanhthungay,$I9,duan_nv,SUMIFS('Dự án T9'!$D:$D,'Dự án T9'!$A:$A,nt,'Dự án T9'!$B:$B,nv),duan_nt,SUMIFS('Dự án T9'!$D:$D,'Dự án T9'!$A:$A,nt),tyle,duan_nv/duan_nt,muc2_ngay,_xlfn.XLOOKUP(nt,'kpi nhà thuốc'!$B:$B,'kpi nhà thuốc'!$P:$P),muc3_ngay,_xlfn.XLOOKUP(nt,'kpi nhà thuốc'!$B:$B,'kpi nhà thuốc'!$T:$T),hangdiem1,_xlfn.XLOOKUP(nt,'kpi nhà thuốc'!$B:$B,'kpi nhà thuốc'!$I:$I),hangdiem2,_xlfn.XLOOKUP(nt,'kpi nhà thuốc'!$B:$B,'kpi nhà thuốc'!$N:$N),hangdiem3,_xlfn.XLOOKUP(nt,'kpi nhà thuốc'!$B:$B,'kpi nhà thuốc'!$R:$R),_xludf.SWITCH(TRUE,doanhthungay>=muc3_ngay,hangdiem3,doanhthungay>=muc2_ngay,hangdiem2,TRUE,hangdiem1)/songay*tyle),-3),0) -> 0 | G9: =IFERROR(SUMIF('Dự án T9'!$B:$B, $B9, 'Dự án T9'!$D:$D), 0) -> 516686.5 | H9: =Q9 -> 24000000 | I9: =(AD9/DAY($C$1)) -> 2672120 | J9: =_xlfn.XLOOKUP(B9, 'kpi nhà thuốc'!A:A, 'kpi nhà thuốc'!F:F, (AD9/DAY($C$1))/U9) -> 0.11133833 | K9: =_xlfn.XLOOKUP(B9, 'kpi nhà thuốc'!$A:$A, 'kpi nhà thuốc'!$G:$G, IF(AND(OR(C9="DSXC", C9="DSCD", C9="DSBC", C9="DSTV", C9="Q.CHT", C9="BC", C9="DSHV"), G9>=F9), AD9 * _xlfn.IFS(AND(I9>=T9, E9>=D9), 0.015, I9>=T9, 0.013, AND(I9>=S9, E9>=D9), 0.013, I9>=S9, 0.011, AND(I9>=R9, E9>=D9), 0.012, I9>=R9, 0.01, TRUE, 0), 0)) -> 0 | L9: =IF(C9="DSTV","", IF(J9<0.6, 0.8, 1)) -> 0.8 | M9: =IFERROR(SUMIF('Dự án T9'!$B:$B, $B9, 'Dự án T9'!$M:$M)*$L9, 0) -> 0 | N9: =N(K9)+M9 -> 0 | O9: =CEILING(R9, 100000) -> 19200000 | P9: =CEILING(S9, 100000) -> 21600000 | Q9: =CEILING(T9, 100000) -> 24000000 | R9: =U9*$R$2 -> 19200000 | S9: =U9*$S$2 -> 21600000 | T9: =U9*$T$2 -> 24000000 | U9: =V9/DAY($C$1) -> 24000000 | V9: 240000000 | W9: =IFERROR(SUMIFS(data!$C:$C, data!$A:$A, $A9, data!$B:$B, $B9), 0) -> 116 | X9: =IFERROR(SUMIF(data!$B:$B, $B9, data!$D:$D), 0) -> 20710600 | Y9: =IF(W9>0, X9/W9, 0) -> 178539.66 | Z9: =IFERROR(SUMIFS(data!$E:$E, data!$A:$A, $A9, data!$B:$B, $B9), 0) -> 58 | AA9: =IFERROR(SUMIF(data!$B:$B, $B9, data!$F:$F), 0) -> 6010600 | AB9: =IF(Z9>0, AA9/Z9, 0) -> 103631.03 | AC9: =W9+Z9 -> 174 | AD9: =X9+AA9 -> 26721200 | AE9: =IF(AC9>0, AD9/AC9, 0) -> 153570.11
A10: Đỗ Quang Đẩu | B10: Ngô Thị Thanh Thắm | C10: CHT | D10: 346495 | E10: =AE10 -> 332241.51 | F10: =IFERROR(ROUND(_xludf.LET(nt,$A10,nv,$B10,songay,DAY(EOMONTH($C$1,0)),doanhthungay,$I10,duan_nv,SUMIFS('Dự án T9'!$D:$D,'Dự án T9'!$A:$A,nt,'Dự án T9'!$B:$B,nv),duan_nt,SUMIFS('Dự án T9'!$D:$D,'Dự án T9'!$A:$A,nt),tyle,duan_nv/duan_nt,muc2_ngay,_xlfn.XLOOKUP(nt,'kpi nhà thuốc'!$B:$B,'kpi nhà thuốc'!$P:$P),muc3_ngay,_xlfn.XLOOKUP(nt,'kpi nhà thuốc'!$B:$B,'kpi nhà thuốc'!$T:$T),hangdiem1,_xlfn.XLOOKUP(nt,'kpi nhà thuốc'!$B:$B,'kpi nhà thuốc'!$I:$I),hangdiem2,_xlfn.XLOOKUP(nt,'kpi nhà thuốc'!$B:$B,'kpi nhà thuốc'!$N:$N),hangdiem3,_xlfn.XLOOKUP(nt,'kpi nhà thuốc'!$B:$B,'kpi nhà thuốc'!$R:$R),_xludf.SWITCH(TRUE,doanhthungay>=muc3_ngay,hangdiem3,doanhthungay>=muc2_ngay,hangdiem2,TRUE,hangdiem1)/songay*tyle),-3),0) -> 0 | G10: =IFERROR(SUMIF('Dự án T9'!$B:$B, $B10, 'Dự án T9'!$D:$D), 0) -> 404545.9 | H10: =Q10 -> 24000000 | I10: =(AD10/DAY($C$1)) -> 5282640 | J10: =_xlfn.XLOOKUP(B10, 'kpi nhà thuốc'!A:A, 'kpi nhà thuốc'!F:F, (AD10/DAY($C$1))/U10) -> 0.18759218 | K10: =_xlfn.XLOOKUP(B10, 'kpi nhà thuốc'!$A:$A, 'kpi nhà thuốc'!$G:$G, IF(AND(OR(C10="DSXC", C10="DSCD", C10="DSBC", C10="DSTV", C10="Q.CHT", C10="BC", C10="DSHV"), G10>=F10), AD10 * _xlfn.IFS(AND(I10>=T10, E10>=D10), 0.015, I10>=T10, 0.013, AND(I10>=S10, E10>=D10), 0.013, I10>=S10, 0.011, AND(I10>=R10, E10>=D10), 0.012, I10>=R10, 0.01, TRUE, 0), 0)) -> 0 | L10: =IF(C10="DSTV","", IF(J10<0.6, 0.8, 1)) -> 0.8 | M10: =IFERROR(SUMIF('Dự án T9'!$B:$B, $B10, 'Dự án T9'!$M:$M)*$L10, 0) -> 0 | N10: =N(K10)+M10 -> 0 | O10: =CEILING(R10, 100000) -> 19200000 | P10: =CEILING(S10, 100000) -> 21600000 | Q10: =CEILING(T10, 100000) -> 24000000 | R10: =U10*$R$2 -> 19200000 | S10: =U10*$S$2 -> 21600000 | T10: =U10*$T$2 -> 24000000 | U10: =V10/DAY($C$1) -> 24000000 | V10: 240000000 | W10: =IFERROR(SUMIFS(data!$C:$C, data!$A:$A, $A10, data!$B:$B, $B10), 0) -> 105 | X10: =IFERROR(SUMIF(data!$B:$B, $B10, data!$D:$D), 0) -> 31479500 | Y10: =IF(W10>0, X10/W10, 0) -> 299804.76 | Z10: =IFERROR(SUMIFS(data!$E:$E, data!$A:$A, $A10, data!$B:$B, $B10), 0) -> 54 | AA10: =IFERROR(SUMIF(data!$B:$B, $B10, data!$F:$F), 0) -> 21346900 | AB10: =IF(Z10>0, AA10/Z10, 0) -> 395312.96 | AC10: =W10+Z10 -> 159 | AD10: =X10+AA10 -> 52826400 | AE10: =IF(AC10>0, AD10/AC10, 0) -> 332241.51
A11: Đỗ Quang Đẩu | B11: Hoàng Thanh Thủy | C11: DSXC | D11: 335470 | E11: =AE11 -> 248354.14 | F11: =IFERROR(ROUND(_xludf.LET(nt,$A11,nv,$B11,songay,DAY(EOMONTH($C$1,0)),doanhthungay,$I11,duan_nv,SUMIFS('Dự án T9'!$D:$D,'Dự án T9'!$A:$A,nt,'Dự án T9'!$B:$B,nv),duan_nt,SUMIFS('Dự án T9'!$D:$D,'Dự án T9'!$A:$A,nt),tyle,duan_nv/duan_nt,muc2_ngay,_xlfn.XLOOKUP(nt,'kpi nhà thuốc'!$B:$B,'kpi nhà thuốc'!$P:$P),muc3_ngay,_xlfn.XLOOKUP(nt,'kpi nhà thuốc'!$B:$B,'kpi nhà thuốc'!$T:$T),hangdiem1,_xlfn.XLOOKUP(nt,'kpi nhà thuốc'!$B:$B,'kpi nhà thuốc'!$I:$I),hangdiem2,_xlfn.XLOOKUP(nt,'kpi nhà thuốc'!$B:$B,'kpi nhà thuốc'!$N:$N),hangdiem3,_xlfn.XLOOKUP(nt,'kpi nhà thuốc'!$B:$B,'kpi nhà thuốc'!$R:$R),_xludf.SWITCH(TRUE,doanhthungay>=muc3_ngay,hangdiem3,doanhthungay>=muc2_ngay,hangdiem2,TRUE,hangdiem1)/songay*tyle),-3),0) -> 0 | G11: =IFERROR(SUMIF('Dự án T9'!$B:$B, $B11, 'Dự án T9'!$D:$D), 0) -> 1322051.9 | H11: =Q11 -> 24000000 | I11: =(AD11/DAY($C$1)) -> 5513462 | J11: =_xlfn.XLOOKUP(B11, 'kpi nhà thuốc'!A:A, 'kpi nhà thuốc'!F:F, (AD11/DAY($C$1))/U11) -> 0.22972758 | K11: =_xlfn.XLOOKUP(B11, 'kpi nhà thuốc'!$A:$A, 'kpi nhà thuốc'!$G:$G, IF(AND(OR(C11="DSXC", C11="DSCD", C11="DSBC", C11="DSTV", C11="Q.CHT", C11="BC", C11="DSHV"), G11>=F11), AD11 * _xlfn.IFS(AND(I11>=T11, E11>=D11), 0.015, I11>=T11, 0.013, AND(I11>=S11, E11>=D11), 0.013, I11>=S11, 0.011, AND(I11>=R11, E11>=D11), 0.012, I11>=R11, 0.01, TRUE, 0), 0)) -> 0 | L11: =IF(C11="DSTV","", IF(J11<0.6, 0.8, 1)) -> 0.8 | M11: =IFERROR(SUMIF('Dự án T9'!$B:$B, $B11, 'Dự án T9'!$M:$M)*$L11, 0) -> 400000 | N11: =N(K11)+M11 -> 400000 | O11: =CEILING(R11, 100000) -> 19200000 | P11: =CEILING(S11, 100000) -> 21600000 | Q11: =CEILING(T11, 100000) -> 24000000 | R11: =U11*$R$2 -> 19200000 | S11: =U11*$S$2 -> 21600000 | T11: =U11*$T$2 -> 24000000 | U11: =V11/DAY($C$1) -> 24000000 | V11: 240000000 | W11: =IFERROR(SUMIFS(data!$C:$C, data!$A:$A, $A11, data!$B:$B, $B11), 0) -> 155 | X11: =IFERROR(SUMIF(data!$B:$B, $B11, data!$D:$D), 0) -> 38890420 | Y11: =IF(W11>0, X11/W11, 0) -> 250905.94 | Z11: =IFERROR(SUMIFS(data!$E:$E, data!$A:$A, $A11, data!$B:$B, $B11), 0) -> 67 | AA11: =IFERROR(SUMIF(data!$B:$B, $B11, data!$F:$F), 0) -> 16244200 | AB11: =IF(Z11>0, AA11/Z11, 0) -> 242450.75 | AC11: =W11+Z11 -> 222 | AD11: =X11+AA11 -> 55134620 | AE11: =IF(AC11>0, AD11/AC11, 0) -> 248354.14
A12: Đỗ Quang Đẩu | B12: Lê Thị Huyền Trân | C12: DSXC | D12: 187847 | E12: =AE12 -> 189258.48 | F12: =IFERROR(ROUND(_xludf.LET(nt,$A12,nv,$B12,songay,DAY(EOMONTH($C$1,0)),doanhthungay,$I12,duan_nv,SUMIFS('Dự án T9'!$D:$D,'Dự án T9'!$A:$A,nt,'Dự án T9'!$B:$B,nv),duan_nt,SUMIFS('Dự án T9'!$D:$D,'Dự án T9'!$A:$A,nt),tyle,duan_nv/duan_nt,muc2_ngay,_xlfn.XLOOKUP(nt,'kpi nhà thuốc'!$B:$B,'kpi nhà thuốc'!$P:$P),muc3_ngay,_xlfn.XLOOKUP(nt,'kpi nhà thuốc'!$B:$B,'kpi nhà thuốc'!$T:$T),hangdiem1,_xlfn.XLOOKUP(nt,'kpi nhà thuốc'!$B:$B,'kpi nhà thuốc'!$I:$I),hangdiem2,_xlfn.XLOOKUP(nt,'kpi nhà thuốc'!$B:$B,'kpi nhà thuốc'!$N:$N),hangdiem3,_xlfn.XLOOKUP(nt,'kpi nhà thuốc'!$B:$B,'kpi nhà thuốc'!$R:$R),_xludf.SWITCH(TRUE,doanhthungay>=muc3_ngay,hangdiem3,doanhthungay>=muc2_ngay,hangdiem2,TRUE,hangdiem1)/songay*tyle),-3),0) -> 0 | G12: =IFERROR(SUMIF('Dự án T9'!$B:$B, $B12, 'Dự án T9'!$D:$D), 0) -> 724108.8 | H12: =Q12 -> 24000000 | I12: =(AD12/DAY($C$1)) -> 5469570 | J12: =_xlfn.XLOOKUP(B12, 'kpi nhà thuốc'!A:A, 'kpi nhà thuốc'!F:F, (AD12/DAY($C$1))/U12) -> 0.22789875 | K12: =_xlfn.XLOOKUP(B12, 'kpi nhà thuốc'!$A:$A, 'kpi nhà thuốc'!$G:$G, IF(AND(OR(C12="DSXC", C12="DSCD", C12="DSBC", C12="DSTV", C12="Q.CHT", C12="BC", C12="DSHV"), G12>=F12), AD12 * _xlfn.IFS(AND(I12>=T12, E12>=D12), 0.015, I12>=T12, 0.013, AND(I12>=S12, E12>=D12), 0.013, I12>=S12, 0.011, AND(I12>=R12, E12>=D12), 0.012, I12>=R12, 0.01, TRUE, 0), 0)) -> 0 | L12: =IF(C12="DSTV","", IF(J12<0.6, 0.8, 1)) -> 0.8 | M12: =IFERROR(SUMIF('Dự án T9'!$B:$B, $B12, 'Dự án T9'!$M:$M)*$L12, 0) -> 0 | N12: =N(K12)+M12 -> 0 | O12: =CEILING(R12, 100000) -> 19200000 | P12: =CEILING(S12, 100000) -> 21600000 | Q12: =CEILING(T12, 100000) -> 24000000 | R12: =U12*$R$2 -> 19200000 | S12: =U12*$S$2 -> 21600000 | T12: =U12*$T$2 -> 24000000 | U12: =V12/DAY($C$1) -> 24000000 | V12: 240000000 | W12: =IFERROR(SUMIFS(data!$C:$C, data!$A:$A, $A12, data!$B:$B, $B12), 0) -> 212 | X12: =IFERROR(SUMIF(data!$B:$B, $B12, data!$D:$D), 0) -> 39740900 | Y12: =IF(W12>0, X12/W12, 0) -> 187457.08 | Z12: =IFERROR(SUMIFS(data!$E:$E, data!$A:$A, $A12, data!$B:$B, $B12), 0) -> 77 | AA12: =IFERROR(SUMIF(data!$B:$B, $B12, data!$F:$F), 0) -> 14954800 | AB12: =IF(Z12>0, AA12/Z12, 0) -> 194218.18 | AC12: =W12+Z12 -> 289 | AD12: =X12+AA12 -> 54695700 | AE12: =IF(AC12>0, AD12/AC12, 0) -> 189258.48
A13: Minh Châu | B13: Thái Thùy Linh | C13: CHT | D13: 100080 | E13: =AE13 -> 74230.233 | F13: =IFERROR(ROUND(_xludf.LET(nt,$A13,nv,$B13,songay,DAY(EOMONTH($C$1,0)),doanhthungay,$I13,duan_nv,SUMIFS('Dự án T9'!$D:$D,'Dự án T9'!$A:$A,nt,'Dự án T9'!$B:$B,nv),duan_nt,SUMIFS('Dự án T9'!$D:$D,'Dự án T9'!$A:$A,nt),tyle,duan_nv/duan_nt,muc2_ngay,_xlfn.XLOOKUP(nt,'kpi nhà thuốc'!$B:$B,'kpi nhà thuốc'!$P:$P),muc3_ngay,_xlfn.XLOOKUP(nt,'kpi nhà thuốc'!$B:$B,'kpi nhà thuốc'!$T:$T),hangdiem1,_xlfn.XLOOKUP(nt,'kpi nhà thuốc'!$B:$B,'kpi nhà thuốc'!$I:$I),hangdiem2,_xlfn.XLOOKUP(nt,'kpi nhà thuốc'!$B:$B,'kpi nhà thuốc'!$N:$N),hangdiem3,_xlfn.XLOOKUP(nt,'kpi nhà thuốc'!$B:$B,'kpi nhà thuốc'!$R:$R),_xludf.SWITCH(TRUE,doanhthungay>=muc3_ngay,hangdiem3,doanhthungay>=muc2_ngay,hangdiem2,TRUE,hangdiem1)/songay*tyle),-3),0) -> 0 | G13: =IFERROR(SUMIF('Dự án T9'!$B:$B, $B13, 'Dự án T9'!$D:$D), 0) -> 1562186 | H13: =Q13 -> 12000000 | I13: =(AD13/DAY($C$1)) -> 3511090 | J13: =_xlfn.XLOOKUP(B13, 'kpi nhà thuốc'!A:A, 'kpi nhà thuốc'!F:F, (AD13/DAY($C$1))/U13) -> 0.24187739 | K13: =_xlfn.XLOOKUP(B13, 'kpi nhà thuốc'!$A:$A, 'kpi nhà thuốc'!$G:$G, IF(AND(OR(C13="DSXC", C13="DSCD", C13="DSBC", C13="DSTV", C13="Q.CHT", C13="BC", C13="DSHV"), G13>=F13), AD13 * _xlfn.IFS(AND(I13>=T13, E13>=D13), 0.015, I13>=T13, 0.013, AND(I13>=S13, E13>=D13), 0.013, I13>=S13, 0.011, AND(I13>=R13, E13>=D13), 0.012, I13>=R13, 0.01, TRUE, 0), 0)) -> 0 | L13: =IF(C13="DSTV","", IF(J13<0.6, 0.8, 1)) -> 0.8 | M13: =IFERROR(SUMIF('Dự án T9'!$B:$B, $B13, 'Dự án T9'!$M:$M)*$L13, 0) -> 800000 | N13: =N(K13)+M13 -> 800000 | O13: =CEILING(R13, 100000) -> 9600000 | P13: =CEILING(S13, 100000) -> 10800000 | Q13: =CEILING(T13, 100000) -> 12000000 | R13: =U13*$R$2 -> 9600000 | S13: =U13*$S$2 -> 10800000 | T13: =U13*$T$2 -> 12000000 | U13: =V13/DAY($C$1) -> 12000000 | V13: 120000000 | W13: =IFERROR(SUMIFS(data!$C:$C, data!$A:$A, $A13, data!$B:$B, $B13), 0) -> 419 | X13: =IFERROR(SUMIF(data!$B:$B, $B13, data!$D:$D), 0) -> 28832400 | Y13: =IF(W13>0, X13/W13, 0) -> 68812.411 | Z13: =IFERROR(SUMIFS(data!$E:$E, data!$A:$A, $A13, data!$B:$B, $B13), 0) -> 54 | AA13: =IFERROR(SUMIF(data!$B:$B, $B13, data!$F:$F), 0) -> 6278500 | AB13: =IF(Z13>0, AA13/Z13, 0) -> 116268.52 | AC13: =W13+Z13 -> 473 | AD13: =X13+AA13 -> 35110900 | AE13: =IF(AC13>0, AD13/AC13, 0) -> 74230.233
A14: Minh Châu | B14: Đoàn Quốc Tâm | C14: DSXC | D14: 99702 | E14: =AE14 -> 138316.61 | F14: =IFERROR(ROUND(_xludf.LET(nt,$A14,nv,$B14,songay,DAY(EOMONTH($C$1,0)),doanhthungay,$I14,duan_nv,SUMIFS('Dự án T9'!$D:$D,'Dự án T9'!$A:$A,nt,'Dự án T9'!$B:$B,nv),duan_nt,SUMIFS('Dự án T9'!$D:$D,'Dự án T9'!$A:$A,nt),tyle,duan_nv/duan_nt,muc2_ngay,_xlfn.XLOOKUP(nt,'kpi nhà thuốc'!$B:$B,'kpi nhà thuốc'!$P:$P),muc3_ngay,_xlfn.XLOOKUP(nt,'kpi nhà thuốc'!$B:$B,'kpi nhà thuốc'!$T:$T),hangdiem1,_xlfn.XLOOKUP(nt,'kpi nhà thuốc'!$B:$B,'kpi nhà thuốc'!$I:$I),hangdiem2,_xlfn.XLOOKUP(nt,'kpi nhà thuốc'!$B:$B,'kpi nhà thuốc'!$N:$N),hangdiem3,_xlfn.XLOOKUP(nt,'kpi nhà thuốc'!$B:$B,'kpi nhà thuốc'!$R:$R),_xludf.SWITCH(TRUE,doanhthungay>=muc3_ngay,hangdiem3,doanhthungay>=muc2_ngay,hangdiem2,TRUE,hangdiem1)/songay*tyle),-3),0) -> 0 | G14: =IFERROR(SUMIF('Dự án T9'!$B:$B, $B14, 'Dự án T9'!$D:$D), 0) -> 1116017.6 | H14: =Q14 -> 12000000 | I14: =(AD14/DAY($C$1)) -> 3872865 | J14: =_xlfn.XLOOKUP(B14, 'kpi nhà thuốc'!A:A, 'kpi nhà thuốc'!F:F, (AD14/DAY($C$1))/U14) -> 0.32273875 | K14: =_xlfn.XLOOKUP(B14, 'kpi nhà thuốc'!$A:$A, 'kpi nhà thuốc'!$G:$G, IF(AND(OR(C14="DSXC", C14="DSCD", C14="DSBC", C14="DSTV", C14="Q.CHT", C14="BC", C14="DSHV"), G14>=F14), AD14 * _xlfn.IFS(AND(I14>=T14, E14>=D14), 0.015, I14>=T14, 0.013, AND(I14>=S14, E14>=D14), 0.013, I14>=S14, 0.011, AND(I14>=R14, E14>=D14), 0.012, I14>=R14, 0.01, TRUE, 0), 0)) -> 0 | L14: =IF(C14="DSTV","", IF(J14<0.6, 0.8, 1)) -> 0.8 | M14: =IFERROR(SUMIF('Dự án T9'!$B:$B, $B14, 'Dự án T9'!$M:$M)*$L14, 0) -> 400000 | N14: =N(K14)+M14 -> 400000 | O14: =CEILING(R14, 100000) -> 9600000 | P14: =CEILING(S14, 100000) -> 10800000 | Q14: =CEILING(T14, 100000) -> 12000000 | R14: =U14*$R$2 -> 9600000 | S14: =U14*$S$2 -> 10800000 | T14: =U14*$T$2 -> 12000000 | U14: =V14/DAY($C$1) -> 12000000 | V14: 120000000 | W14: =IFERROR(SUMIFS(data!$C:$C, data!$A:$A, $A14, data!$B:$B, $B14), 0) -> 202 | X14: =IFERROR(SUMIF(data!$B:$B, $B14, data!$D:$D), 0) -> 15436450 | Y14: =IF(W14>0, X14/W14, 0) -> 76418.069 | Z14: =IFERROR(SUMIFS(data!$E:$E, data!$A:$A, $A14, data!$B:$B, $B14), 0) -> 78 | AA14: =IFERROR(SUMIF(data!$B:$B, $B14, data!$F:$F), 0) -> 23292200 | AB14: =IF(Z14>0, AA14/Z14, 0) -> 298617.95 | AC14: =W14+Z14 -> 280 | AD14: =X14+AA14 -> 38728650 | AE14: =IF(AC14>0, AD14/AC14, 0) -> 138316.61
... A54: Đường Láng | B54: Medigo | C54: DSBC | D54: 150000 | E54: =AE54 -> 38000 | F54: =IFERROR(ROUND(_xludf.LET(nt,$A54,nv,$B54,songay,DAY(EOMONTH($C$1,0)),doanhthungay,$I54,duan_nv,SUMIFS('Dự án T9'!$D:$D,'Dự án T9'!$A:$A,nt,'Dự án T9'!$B:$B,nv),duan_nt,SUMIFS('Dự án T9'!$D:$D,'Dự án T9'!$A:$A,nt),tyle,duan_nv/duan_nt,muc2_ngay,_xlfn.XLOOKUP(nt,'kpi nhà thuốc'!$B:$B,'kpi nhà thuốc'!$P:$P),muc3_ngay,_xlfn.XLOOKUP(nt,'kpi nhà thuốc'!$B:$B,'kpi nhà thuốc'!$T:$T),hangdiem1,_xlfn.XLOOKUP(nt,'kpi nhà thuốc'!$B:$B,'kpi nhà thuốc'!$I:$I),hangdiem2,_xlfn.XLOOKUP(nt,'kpi nhà thuốc'!$B:$B,'kpi nhà thuốc'!$N:$N),hangdiem3,_xlfn.XLOOKUP(nt,'kpi nhà thuốc'!$B:$B,'kpi nhà thuốc'!$R:$R),_xludf.SWITCH(TRUE,doanhthungay>=muc3_ngay,hangdiem3,doanhthungay>=muc2_ngay,hangdiem2,TRUE,hangdiem1)/songay*tyle),-3),0) -> 0 | G54: =IFERROR(SUMIF('Dự án T9'!$B:$B, $B54, 'Dự án T9'!$D:$D), 0) -> 0 | H54: =Q54 -> 27000000 | I54: =(AD54/DAY($C$1)) -> 7600 | J54: =_xlfn.XLOOKUP(B54, 'kpi nhà thuốc'!A:A, 'kpi nhà thuốc'!F:F, (AD54/DAY($C$1))/U54) -> 0.00028148148 | K54: =_xlfn.XLOOKUP(B54, 'kpi nhà thuốc'!$A:$A, 'kpi nhà thuốc'!$G:$G, IF(AND(OR(C54="DSXC", C54="DSCD", C54="DSBC", C54="DSTV", C54="Q.CHT", C54="BC", C54="DSHV"), G54>=F54), AD54 * _xlfn.IFS(AND(I54>=T54, E54>=D54), 0.015, I54>=T54, 0.013, AND(I54>=S54, E54>=D54), 0.013, I54>=S54, 0.011, AND(I54>=R54, E54>=D54), 0.012, I54>=R54, 0.01, TRUE, 0), 0)) -> 0 | L54: =IF(C54="DSTV","", IF(J54<0.6, 0.8, 1)) -> 0.8 | M54: =IFERROR(SUMIF('Dự án T9'!$B:$B, $B54, 'Dự án T9'!$M:$M)*$L54, 0) -> 0 | N54: =N(K54)+M54 -> 0 | O54: =CEILING(R54, 100000) -> 21600000 | P54: =CEILING(S54, 100000) -> 24300000 | Q54: =CEILING(T54, 100000) -> 27000000 | R54: =U54*$R$2 -> 21600000 | S54: =U54*$S$2 -> 24300000 | T54: =U54*$T$2 -> 27000000 | U54: =V54/DAY($C$1) -> 27000000 | V54: 270000000 | W54: =IFERROR(SUMIFS(data!$C:$C, data!$A:$A, $A54, data!$B:$B, $B54), 0) -> 0 | X54: =IFERROR(SUMIF(data!$B:$B, $B54, data!$D:$D), 0) -> 0 | Y54: =IF(W54>0, X54/W54, 0) -> 0 | Z54: =IFERROR(SUMIFS(data!$E:$E, data!$A:$A, $A54, data!$B:$B, $B54), 0) -> 2 | AA54: =IFERROR(SUMIF(data!$B:$B, $B54, data!$F:$F), 0) -> 76000 | AB54: =IF(Z54>0, AA54/Z54, 0) -> 38000 | AC54: =W54+Z54 -> 2 | AD54: =X54+AA54 -> 76000 | AE54: =IF(AC54>0, AD54/AC54, 0) -> 38000

Sheet kpi nhà thuốc
D1: Dữ liệu cập nhật đến ngày | F1: 46275 | T1: ='kpi dược sĩ'!$C$1 -> 46275
A2: Cửa hàng trưởng | B2: Nhà thuốc | C2: KPI doanh thu (tháng) | D2: Doanh thu thực tế (tháng) | E2: Doanh thu thực tế (ngày) | F2: Tỷ lệ đạt KPIs | G2: Thưởng CHT | H2: KPIs mức 1 | I2: KPIs hàng điểm mức 1 | J2: KPIs mức 1/tháng | K2: KPIs mức 1/ngày | L2: KPIs mức 1/ngày | M2: KPIs mức 2 | N2: KPIs hàng điểm mức 2 | O2: KPIs mức 2/tháng | P2: KPIs mức 2/ngày | Q2: KPIs mức 3 | R2: KPIs hàng điểm mức 3 | S2: KPIs mức 3/tháng | T2: KPIs mức 3/ngày | U2: Doanh thu hàng điểm | V2: Hàng điểm/ Doanh thu tổng | W2: Xét Đạt KPI | X2: Số giao dịch off | Y2: Doanh thu off | Z2: Tbbill off | AA2: Số giao dịch onl | AB2: Doanh thu onl | AC2: Tbbill onl | AD2: Tổng giao dịch | AE2: Doanh thu tổng | AF2: Trung bình Bill
A3: Nguyễn Trần Ngọc Phương | B3: Trường Sa | C3: 640000000 | D3: =AE3 -> 128255840 | E3: =D3/DAY('kpi dược sĩ'!$C$1) -> 12825584 | F3: =E3/T3 -> 0.20039975 | G3: =IF(W3<>"Đạt", 0, IF(E3>=T3, D3*0.5%+1000000, IF(E3>=P3, D3*0.4%+700000, IF(E3>=K3, D3*0.35%+500000, 0)))) -> 0 | H3: 0.8 | I3: =J3*0.25 -> 128000000 | J3: =C3*H3 -> 512000000 | K3: =T3*H3 -> 51200000 | L3: =CEILING(K3, 100000) -> 51200000 | M3: 0.9 | N3: =O3*0.25 -> 144000000 | O3: =C3*M3 -> 576000000 | P3: =T3*M3 -> 57600000 | Q3: 1 | R3: =S3*0.25 -> 160000000 | S3: =C3*Q3 -> 640000000 | T3: =C3/DAY('kpi dược sĩ'!$C$1) -> 64000000 | U3: =SUMIF('Dự án T9'!$A:$A, B3, 'Dự án T9'!$D:$D)*DAY($F$1) -> 36451680 | V3: =U3/D3 -> 0.28421068 | W3: =IF(OR(F3="", V3=""), "", IF(AND(F3>=80%, V3>=25%), "Đạt", "Không đạt")) -> Không đạt | X3: =SUMIF(data!$A:$A, B3, data!$C:$C) -> 805 | Y3: =SUMIF(data!$A:$A, B3, data!$D:$D) -> 59985100 | Z3: =IF(X3>0, Y3/X3, 0) -> 74515.652 | AA3: =SUMIF(data!$A:$A, B3, data!$E:$E) -> 390 | AB3: =SUMIF(data!$A:$A, B3, data!$F:$F) -> 68270740 | AC3: =IF(AA3>0, AB3/AA3, 0) -> 175053.18 | AD3: =X3+AA3 -> 1195 | AE3: =Y3+AB3 -> 128255840 | AF3: =IF(AD3>0, AE3/AD3, 0) -> 107327.06
A4: Ngô Thị Thanh Thắm | B4: Đỗ Quang Đẩu | C4: 1200000000 | D4: =AE4 -> 225110620 | E4: =D4/DAY('kpi dược sĩ'!$C$1) -> 22511062 | F4: =E4/T4 -> 0.18759218 | G4: =IF(W4<>"Đạt", 0, IF(E4>=T4, D4*0.5%+1000000, IF(E4>=P4, D4*0.4%+700000, IF(E4>=K4, D4*0.35%+500000, 0)))) -> 0 | H4: 0.8 | I4: =J4*0.25 -> 240000000 | J4: =C4*H4 -> 960000000 | K4: =T4*H4 -> 96000000 | L4: =CEILING(K4, 100000) -> 96000000 | M4: 0.9 | N4: =O4*0.25 -> 270000000 | O4: =C4*M4 -> 1080000000 | P4: =T4*M4 -> 108000000 | Q4: 1 | R4: =S4*0.25 -> 300000000 | S4: =C4*Q4 -> 1200000000 | T4: =C4/DAY('kpi dược sĩ'!$C$1) -> 120000000 | U4: =SUMIF('Dự án T9'!$A:$A, B4, 'Dự án T9'!$D:$D)*DAY($F$1) -> 32717555 | V4: =U4/D4 -> 0.1453399 | W4: =IF(OR(F4="", V4=""), "", IF(AND(F4>=80%, V4>=25%), "Đạt", "Không đạt")) -> Không đạt | X4: =SUMIF(data!$A:$A, B4, data!$C:$C) -> 726 | Y4: =SUMIF(data!$A:$A, B4, data!$D:$D) -> 161333320 | Z4: =IF(X4>0, Y4/X4, 0) -> 222222.2 | AA4: =SUMIF(data!$A:$A, B4, data!$E:$E) -> 305 | AB4: =SUMIF(data!$A:$A, B4, data!$F:$F) -> 63777300 | AC4: =IF(AA4>0, AB4/AA4, 0) -> 209105.9 | AD4: =X4+AA4 -> 1031 | AE4: =Y4+AB4 -> 225110620 | AF4: =IF(AD4>0, AE4/AD4, 0) -> 218342.02
A5: Thái Thùy Linh | B5: Minh Châu | C5: 460000000 | D5: =AE5 -> 111263600 | E5: =D5/DAY('kpi dược sĩ'!$C$1) -> 11126360 | F5: =E5/T5 -> 0.24187739 | G5: =IF(W5<>"Đạt", 0, IF(E5>=T5, D5*0.5%+1000000, IF(E5>=P5, D5*0.4%+700000, IF(E5>=K5, D5*0.35%+500000, 0)))) -> 0 | H5: 0.8 | I5: =J5*0.25 -> 92000000 | J5: =C5*H5 -> 368000000 | K5: =T5*H5 -> 36800000 | L5: =CEILING(K5, 100000) -> 36800000 | M5: 0.9 | N5: =O5*0.25 -> 103500000 | O5: =C5*M5 -> 414000000 | P5: =T5*M5 -> 41400000 | Q5: 1 | R5: =S5*0.25 -> 115000000 | S5: =C5*Q5 -> 460000000 | T5: =C5/DAY('kpi dược sĩ'!$C$1) -> 46000000 | U5: =SUMIF('Dự án T9'!$A:$A, B5, 'Dự án T9'!$D:$D)*DAY($F$1) -> 46460485 | V5: =U5/D5 -> 0.41757129 | W5: =IF(OR(F5="", V5=""), "", IF(AND(F5>=80%, V5>=25%), "Đạt", "Không đạt")) -> Không đạt | X5: =SUMIF(data!$A:$A, B5, data!$C:$C) -> 981 | Y5: =SUMIF(data!$A:$A, B5, data!$D:$D) -> 72777250 | Z5: =IF(X5>0, Y5/X5, 0) -> 74186.799 | AA5: =SUMIF(data!$A:$A, B5, data!$E:$E) -> 196 | AB5: =SUMIF(data!$A:$A, B5, data!$F:$F) -> 38486350 | AC5: =IF(AA5>0, AB5/AA5, 0) -> 196358.93 | AD5: =X5+AA5 -> 1177 | AE5: =Y5+AB5 -> 111263600 | AF5: =IF(AD5>0, AE5/AD5, 0) -> 94531.521
A6: Vũ Ngọc Thanh Thảo | B6: Nam Hòa | C6: 300000000 | D6: =AE6 -> 101192200 | E6: =D6/DAY('kpi dược sĩ'!$C$1) -> 10119220 | F6: =E6/T6 -> 0.33730733 | G6: =IF(W6<>"Đạt", 0, IF(E6>=T6, D6*0.5%+1000000, IF(E6>=P6, D6*0.4%+700000, IF(E6>=K6, D6*0.35%+500000, 0)))) -> 0 | H6: 0.8 | I6: =J6*0.25 -> 60000000 | J6: =C6*H6 -> 240000000 | K6: =T6*H6 -> 24000000 | L6: =CEILING(K6, 100000) -> 24000000 | M6: 0.9 | N6: =O6*0.25 -> 67500000 | O6: =C6*M6 -> 270000000 | P6: =T6*M6 -> 27000000 | Q6: 1 | R6: =S6*0.25 -> 75000000 | S6: =C6*Q6 -> 300000000 | T6: =C6/DAY('kpi dược sĩ'!$C$1) -> 30000000 | U6: =SUMIF('Dự án T9'!$A:$A, B6, 'Dự án T9'!$D:$D)*DAY($F$1) -> 26287780 | V6: =U6/D6 -> 0.25978069 | W6: =IF(OR(F6="", V6=""), "", IF(AND(F6>=80%, V6>=25%), "Đạt", "Không đạt")) -> Không đạt | X6: =SUMIF(data!$A:$A, B6, data!$C:$C) -> 505 | Y6: =SUMIF(data!$A:$A, B6, data!$D:$D) -> 38476400 | Z6: =IF(X6>0, Y6/X6, 0) -> 76190.891 | AA6: =SUMIF(data!$A:$A, B6, data!$E:$E) -> 177 | AB6: =SUMIF(data!$A:$A, B6, data!$F:$F) -> 62715800 | AC6: =IF(AA6>0, AB6/AA6, 0) -> 354326.55 | AD6: =X6+AA6 -> 682 | AE6: =Y6+AB6 -> 101192200 | AF6: =IF(AD6>0, AE6/AD6, 0) -> 148375.66
A7: Lê Thị Quỳnh Trâm | B7: Nguyễn Chí Thanh | C7: 520000000 | D7: =AE7 -> 108286700 | E7: =D7/DAY('kpi dược sĩ'!$C$1) -> 10828670 | F7: =E7/T7 -> 0.20824365 | G7: =IF(W7<>"Đạt", 0, IF(E7>=T7, D7*0.5%+1000000, IF(E7>=P7, D7*0.4%+700000, IF(E7>=K7, D7*0.35%+500000, 0)))) -> 0 | H7: 0.8 | I7: =J7*0.25 -> 104000000 | J7: =C7*H7 -> 416000000 | K7: =T7*H7 -> 41600000 | L7: =CEILING(K7, 100000) -> 41600000 | M7: 0.9 | N7: =O7*0.25 -> 117000000 | O7: =C7*M7 -> 468000000 | P7: =T7*M7 -> 46800000 | Q7: 1 | R7: =S7*0.25 -> 130000000 | S7: =C7*Q7 -> 520000000 | T7: =C7/DAY('kpi dược sĩ'!$C$1) -> 52000000 | U7: =SUMIF('Dự án T9'!$A:$A, B7, 'Dự án T9'!$D:$D)*DAY($F$1) -> 27755143 | V7: =U7/D7 -> 0.25631165 | W7: =IF(OR(F7="", V7=""), "", IF(AND(F7>=80%, V7>=25%), "Đạt", "Không đạt")) -> Không đạt | X7: =SUMIF(data!$A:$A, B7, data!$C:$C) -> 799 | Y7: =SUMIF(data!$A:$A, B7, data!$D:$D) -> 62177300 | Z7: =IF(X7>0, Y7/X7, 0) -> 77818.899 | AA7: =SUMIF(data!$A:$A, B7, data!$E:$E) -> 227 | AB7: =SUMIF(data!$A:$A, B7, data!$F:$F) -> 46109400 | AC7: =IF(AA7>0, AB7/AA7, 0) -> 203125.11 | AD7: =X7+AA7 -> 1026 | AE7: =Y7+AB7 -> 108286700 | AF7: =IF(AD7>0, AE7/AD7, 0) -> 105542.59
A8: Triệu Thị Ngọc Lý | B8: Nguyễn Thị Thập | C8: 545000000 | D8: =AE8 -> 127436022 | E8: =D8/DAY('kpi dược sĩ'!$C$1) -> 12743602 | F8: =E8/T8 -> 0.23382756 | G8: =IF(W8<>"Đạt", 0, IF(E8>=T8, D8*0.5%+1000000, IF(E8>=P8, D8*0.4%+700000, IF(E8>=K8, D8*0.35%+500000, 0)))) -> 0 | H8: 0.8 | I8: =J8*0.25 -> 109000000 | J8: =C8*H8 -> 436000000 | K8: =T8*H8 -> 43600000 | L8: =CEILING(K8, 100000) -> 43600000 | M8: 0.9 | N8: =O8*0.25 -> 122625000 | O8: =C8*M8 -> 490500000 | P8: =T8*M8 -> 49050000 | Q8: 1 | R8: =S8*0.25 -> 136250000 | S8: =C8*Q8 -> 545000000 | T8: =C8/DAY('kpi dược sĩ'!$C$1) -> 54500000 | U8: =SUMIF('Dự án T9'!$A:$A, B8, 'Dự án T9'!$D:$D)*DAY($F$1) -> 32923410 | V8: =U8/D8 -> 0.25835246 | W8: =IF(OR(F8="", V8=""), "", IF(AND(F8>=80%, V8>=25%), "Đạt", "Không đạt")) -> Không đạt | X8: =SUMIF(data!$A:$A, B8, data!$C:$C) -> 745 | Y8: =SUMIF(data!$A:$A, B8, data!$D:$D) -> 52014500 | Z8: =IF(X8>0, Y8/X8, 0) -> 69818.121 | AA8: =SUMIF(data!$A:$A, B8, data!$E:$E) -> 371 | AB8: =SUMIF(data!$A:$A, B8, data!$F:$F) -> 75421522 | AC8: =IF(AA8>0, AB8/AA8, 0) -> 203292.51 | AD8: =X8+AA8 -> 1116 | AE8: =Y8+AB8 -> 127436022 | AF8: =IF(AD8>0, AE8/AD8, 0) -> 114189.98
A9: Nguyễn Thị Hương Giang | B9: Nguyễn Văn Quá | C9: 350000000 | D9: =AE9 -> 109363550 | E9: =D9/DAY('kpi dược sĩ'!$C$1) -> 10936355 | F9: =E9/T9 -> 0.31246729 | G9: =IF(W9<>"Đạt", 0, IF(E9>=T9, D9*0.5%+1000000, IF(E9>=P9, D9*0.4%+700000, IF(E9>=K9, D9*0.35%+500000, 0)))) -> 0 | H9: 0.8 | I9: =J9*0.25 -> 70000000 | J9: =C9*H9 -> 280000000 | K9: =T9*H9 -> 28000000 | L9: =CEILING(K9, 100000) -> 28000000 | M9: 0.9 | N9: =O9*0.25 -> 78750000 | O9: =C9*M9 -> 315000000 | P9: =T9*M9 -> 31500000 | Q9: 1 | R9: =S9*0.25 -> 87500000 | S9: =C9*Q9 -> 350000000 | T9: =C9/DAY('kpi dược sĩ'!$C$1) -> 35000000 | U9: =SUMIF('Dự án T9'!$A:$A, B9, 'Dự án T9'!$D:$D)*DAY($F$1) -> 44265206 | V9: =U9/D9 -> 0.40475283 | W9: =IF(OR(F9="", V9=""), "", IF(AND(F9>=80%, V9>=25%), "Đạt", "Không đạt")) -> Không đạt | X9: =SUMIF(data!$A:$A, B9, data!$C:$C) -> 1036 | Y9: =SUMIF(data!$A:$A, B9, data!$D:$D) -> 75347400 | Z9: =IF(X9>0, Y9/X9, 0) -> 72729.151 | AA9: =SUMIF(data!$A:$A, B9, data!$E:$E) -> 165 | AB9: =SUMIF(data!$A:$A, B9, data!$F:$F) -> 34016150 | AC9: =IF(AA9>0, AB9/AA9, 0) -> 206158.48 | AD9: =X9+AA9 -> 1201 | AE9: =Y9+AB9 -> 109363550 | AF9: =IF(AD9>0, AE9/AD9, 0) -> 91060.408
A10: Ngô Thị Ngọc Thủy | B10: Rạch Bùng Binh | C10: 430000000 | D10: =AE10 -> 91087600 | E10: =D10/DAY('kpi dược sĩ'!$C$1) -> 9108760 | F10: =E10/T10 -> 0.21183163 | G10: =IF(W10<>"Đạt", 0, IF(E10>=T10, D10*0.5%+1000000, IF(E10>=P10, D10*0.4%+700000, IF(E10>=K10, D10*0.35%+500000, 0)))) -> 0 | H10: 0.8 | I10: =J10*0.25 -> 86000000 | J10: =C10*H10 -> 344000000 | K10: =T10*H10 -> 34400000 | L10: =CEILING(K10, 100000) -> 34400000 | M10: 0.9 | N10: =O10*0.25 -> 96750000 | O10: =C10*M10 -> 387000000 | P10: =T10*M10 -> 38700000 | Q10: 1 | R10: =S10*0.25 -> 107500000 | S10: =C10*Q10 -> 430000000 | T10: =C10/DAY('kpi dược sĩ'!$C$1) -> 43000000 | U10: =SUMIF('Dự án T9'!$A:$A, B10, 'Dự án T9'!$D:$D)*DAY($F$1) -> 30725449 | V10: =U10/D10 -> 0.33731758 | W10: =IF(OR(F10="", V10=""), "", IF(AND(F10>=80%, V10>=25%), "Đạt", "Không đạt")) -> Không đạt | X10: =SUMIF(data!$A:$A, B10, data!$C:$C) -> 595 | Y10: =SUMIF(data!$A:$A, B10, data!$D:$D) -> 49018800 | Z10: =IF(X10>0, Y10/X10, 0) -> 82384.538 | AA10: =SUMIF(data!$A:$A, B10, data!$E:$E) -> 239 | AB10: =SUMIF(data!$A:$A, B10, data!$F:$F) -> 42068800 | AC10: =IF(AA10>0, AB10/AA10, 0) -> 176020.08 | AD10: =X10+AA10 -> 834 | AE10: =Y10+AB10 -> 91087600 | AF10: =IF(AD10>0, AE10/AD10, 0) -> 109217.75
A11: Hồ Thị Minh Hòa | B11: Lê Bình | C11: 325500000 | D11: =AE11 -> 73998650 | E11: =D11/DAY('kpi dược sĩ'!$C$1) -> 7399865 | F11: =E11/T11 -> 0.2273384 | G11: =IF(W11<>"Đạt", 0, IF(E11>=T11, D11*0.5%+1000000, IF(E11>=P11, D11*0.4%+700000, IF(E11>=K11, D11*0.35%+500000, 0)))) -> 0 | H11: 0.8 | I11: =J11*0.25 -> 65100000 | J11: =C11*H11 -> 260400000 | K11: =T11*H11 -> 26040000 | L11: =CEILING(K11, 100000) -> 26100000 | M11: 0.9 | N11: =O11*0.25 -> 73237500 | O11: =C11*M11 -> 292950000 | P11: =T11*M11 -> 29295000 | Q11: 1 | R11: =S11*0.25 -> 81375000 | S11: =C11*Q11 -> 325500000 | T11: =C11/DAY('kpi dược sĩ'!$C$1) -> 32550000 | U11: =SUMIF('Dự án T9'!$A:$A, B11, 'Dự án T9'!$D:$D)*DAY($F$1) -> 37348339 | V11: =U11/D11 -> 0.50471649 | W11: =IF(OR(F11="", V11=""), "", IF(AND(F11>=80%, V11>=25%), "Đạt", "Không đạt")) -> Không đạt | X11: =SUMIF(data!$A:$A, B11, data!$C:$C) -> 387 | Y11: =SUMIF(data!$A:$A, B11, data!$D:$D) -> 35791600 | Z11: =IF(X11>0, Y11/X11, 0) -> 92484.755 | AA11: =SUMIF(data!$A:$A, B11, data!$E:$E) -> 204 | AB11: =SUMIF(data!$A:$A, B11, data!$F:$F) -> 38207050 | AC11: =IF(AA11>0, AB11/AA11, 0) -> 187289.46 | AD11: =X11+AA11 -> 591 | AE11: =Y11+AB11 -> 73998650 | AF11: =IF(AD11>0, AE11/AD11, 0) -> 125209.22
A12: Đinh Thị Lan Anh | B12: Hàng Bông | C12: 1350000000 | D12: =AE12 -> 300825401 | E12: =D12/DAY('kpi dược sĩ'!$C$1) -> 30082540 | F12: =E12/T12 -> 0.22283363 | G12: =IF(W12<>"Đạt", 0, IF(E12>=T12, D12*0.5%+1000000, IF(E12>=P12, D12*0.4%+700000, IF(E12>=K12, D12*0.35%+500000, 0)))) -> 0 | H12: 0.8 | I12: =J12*0.25 -> 270000000 | J12: =C12*H12 -> 1080000000 | K12: =T12*H12 -> 108000000 | L12: =CEILING(K12, 100000) -> 108000000 | M12: 0.9 | N12: =O12*0.25 -> 303750000 | O12: =C12*M12 -> 1215000000 | P12: =T12*M12 -> 121500000 | Q12: 1 | R12: =S12*0.25 -> 337500000 | S12: =C12*Q12 -> 1350000000 | T12: =C12/DAY('kpi dược sĩ'!$C$1) -> 135000000 | U12: =SUMIF('Dự án T9'!$A:$A, B12, 'Dự án T9'!$D:$D)*DAY($F$1) -> 128448345 | V12: =U12/D12 -> 0.42698637 | W12: =IF(OR(F12="", V12=""), "", IF(AND(F12>=80%, V12>=25%), "Đạt", "Không đạt")) -> Không đạt | X12: =SUMIF(data!$A:$A, B12, data!$C:$C) -> 989 | Y12: =SUMIF(data!$A:$A, B12, data!$D:$D) -> 240646022 | Z12: =IF(X12>0, Y12/X12, 0) -> 243322.57 | AA12: =SUMIF(data!$A:$A, B12, data!$E:$E) -> 314 | AB12: =SUMIF(data!$A:$A, B12, data!$F:$F) -> 60179379 | AC12: =IF(AA12>0, AB12/AA12, 0) -> 191654.07 | AD12: =X12+AA12 -> 1303 | AE12: =Y12+AB12 -> 300825401 | AF12: =IF(AD12>0, AE12/AD12, 0) -> 230871.37
A13: Hứa Thị Kim Thoa | B13: Đường Láng | C13: 1100000000 | D13: =AE13 -> 258317094 | E13: =D13/DAY('kpi dược sĩ'!$C$1) -> 25831709 | F13: =E13/T13 -> 0.23483372 | G13: =IF(W13<>"Đạt", 0, IF(E13>=T13, D13*0.5%+1000000, IF(E13>=P13, D13*0.4%+700000, IF(E13>=K13, D13*0.35%+500000, 0)))) -> 0 | H13: 0.8 | I13: =J13*0.25 -> 220000000 | J13: =C13*H13 -> 880000000 | K13: =T13*H13 -> 88000000 | L13: =CEILING(K13, 100000) -> 88000000 | M13: 0.9 | N13: =O13*0.25 -> 247500000 | O13: =C13*M13 -> 990000000 | P13: =T13*M13 -> 99000000 | Q13: 1 | R13: =S13*0.25 -> 275000000 | S13: =C13*Q13 -> 1100000000 | T13: =C13/DAY('kpi dược sĩ'!$C$1) -> 110000000 | U13: =SUMIF('Dự án T9'!$A:$A, B13, 'Dự án T9'!$D:$D)*DAY($F$1) -> 1.3057694e+08 | V13: =U13/D13 -> 0.50549091 | W13: =IF(OR(F13="", V13=""), "", IF(AND(F13>=80%, V13>=25%), "Đạt", "Không đạt")) -> Không đạt | X13: =SUMIF(data!$A:$A, B13, data!$C:$C) -> 894 | Y13: =SUMIF(data!$A:$A, B13, data!$D:$D) -> 111525944 | Z13: =IF(X13>0, Y13/X13, 0) -> 124749.38 | AA13: =SUMIF(data!$A:$A, B13, data!$E:$E) -> 655 | AB13: =SUMIF(data!$A:$A, B13, data!$F:$F) -> 146791150 | AC13: =IF(AA13>0, AB13/AA13, 0) -> 224108.63 | AD13: =X13+AA13 -> 1549 | AE13: =Y13+AB13 -> 258317094 | AF13: =IF(AD13>0, AE13/AD13, 0) -> 166763.78

Sheet Dự án T9
A1: 46275
A2: Nhà thuốc | B2: Nhân viên | C2: Chức danh | D2: CK + Combo + NY3/ngày | E2: NY3 | F2: Chiết khấu | G2: Combo Liều | H2: Chiết khấu/ngày | I2: Combo Liều/ngày | J2: Thưởng dự án | K2: Thưởng thêm | L2: Thưởng dự án Hot Bill HN | M2: Total dự án
A3: Trường Sa | B3: Nguyễn Trần Ngọc Phương | C3: Q.CHT | D3: =SUM(E3:G3)/DAY($A$1) -> 699788.4 | E3: 103943 | F3: 3490284 | G3: 3403657 | H3: =F3/DAY($A$1) -> 349028.4 | I3: =G3/DAY($A$1) -> 340365.7 | J3: =IFERROR(IF(OR($A3="Hàng Bông",$A3="Đường Láng"),_xlfn.IFS(AND($H3>=2200000,$I3>=450000),1000000,AND($H3>=2500000,$I3>=520000),1600000,AND($H3>=2800000,$I3>=650000),2200000,AND($H3>=3200000,$I3>=750000),2800000,AND($H3>=3400000,$I3>=900000),4000000,TRUE,0),_xlfn.IFS(AND($H3>=630000,$I3>=350000),1000000,AND($H3>=850000,$I3>=480000),1600000,AND($H3>=1000000,$I3>=580000),2200000,AND($H3>=1200000,$I3>=650000),2800000,AND($H3>=1500000,$I3>=700000),4000000,TRUE,0)),0) -> 0 | K3: =IFERROR(IF(AND($J3=0, IF(OR($A3="Hàng Bông",$A3="Đường Láng"),$D3>=2000000,$D3>=950000)), 500000, 0), 0) -> 0 | L3: =IFERROR(SUMIFS('Hot Bill HN'!$G:$G, 'Hot Bill HN'!$C:$C, $A3, 'Hot Bill HN'!$D:$D, $B3), 0) -> 0 | M3: =IFERROR($J3+$K3+$L3, 0) -> 0
A4: Trường Sa | B4: Phạm Nguyễn Ngọc Quý | C4: DSXC | D4: =SUM(E4:G4)/DAY($A$1) -> 1067866.5 | E4: 299429 | F4: 6595324 | G4: 3783912 | H4: =F4/DAY($A$1) -> 659532.4 | I4: =G4/DAY($A$1) -> 378391.2 | J4: =IFERROR(IF(OR($A4="Hàng Bông",$A4="Đường Láng"),_xlfn.IFS(AND($H4>=2200000,$I4>=450000),1000000,AND($H4>=2500000,$I4>=520000),1600000,AND($H4>=2800000,$I4>=650000),2200000,AND($H4>=3200000,$I4>=750000),2800000,AND($H4>=3400000,$I4>=900000),4000000,TRUE,0),_xlfn.IFS(AND($H4>=630000,$I4>=350000),1000000,AND($H4>=850000,$I4>=480000),1600000,AND($H4>=1000000,$I4>=580000),2200000,AND($H4>=1200000,$I4>=650000),2800000,AND($H4>=1500000,$I4>=700000),4000000,TRUE,0)),0) -> 1000000 | K4: =IFERROR(IF(AND($J4=0, IF(OR($A4="Hàng Bông",$A4="Đường Láng"),$D4>=2000000,$D4>=950000)), 500000, 0), 0) -> 0 | L4: =IFERROR(SUMIFS('Hot Bill HN'!$G:$G, 'Hot Bill HN'!$C:$C, $A4, 'Hot Bill HN'!$D:$D, $B4), 0) -> 0 | M4: =IFERROR($J4+$K4+$L4, 0) -> 1000000
A5: Trường Sa | B5: Nguyễn Ngọc Anh Thư | C5: DSHV | D5: =SUM(E5:G5)/DAY($A$1) -> 819035.3 | E5: 95960 | F5: 4449942 | G5: 3644451 | H5: =F5/DAY($A$1) -> 444994.2 | I5: =G5/DAY($A$1) -> 364445.1 | J5: =IFERROR(IF(OR($A5="Hàng Bông",$A5="Đường Láng"),_xlfn.IFS(AND($H5>=2200000,$I5>=450000),1000000,AND($H5>=2500000,$I5>=520000),1600000,AND($H5>=2800000,$I5>=650000),2200000,AND($H5>=3200000,$I5>=750000),2800000,AND($H5>=3400000,$I5>=900000),4000000,TRUE,0),_xlfn.IFS(AND($H5>=630000,$I5>=350000),1000000,AND($H5>=850000,$I5>=480000),1600000,AND($H5>=1000000,$I5>=580000),2200000,AND($H5>=1200000,$I5>=650000),2800000,AND($H5>=1500000,$I5>=700000),4000000,TRUE,0)),0) -> 0 | K5: =IFERROR(IF(AND($J5=0, IF(OR($A5="Hàng Bông",$A5="Đường Láng"),$D5>=2000000,$D5>=950000)), 500000, 0), 0) -> 0 | L5: =IFERROR(SUMIFS('Hot Bill HN'!$G:$G, 'Hot Bill HN'!$C:$C, $A5, 'Hot Bill HN'!$D:$D, $B5), 0) -> 0 | M5: =IFERROR($J5+$K5+$L5, 0) -> 0
A6: Trường Sa | B6: Trần Thị Kim Khánh | C6: DSCD | D6: =SUM(E6:G6)/DAY($A$1) -> 1058477.8 | E6: 972463 | F6: 5475158 | G6: 4137157 | H6: =F6/DAY($A$1) -> 547515.8 | I6: =G6/DAY($A$1) -> 413715.7 | J6: =IFERROR(IF(OR($A6="Hàng Bông",$A6="Đường Láng"),_xlfn.IFS(AND($H6>=2200000,$I6>=450000),1000000,AND($H6>=2500000,$I6>=520000),1600000,AND($H6>=2800000,$I6>=650000),2200000,AND($H6>=3200000,$I6>=750000),2800000,AND($H6>=3400000,$I6>=900000),4000000,TRUE,0),_xlfn.IFS(AND($H6>=630000,$I6>=350000),1000000,AND($H6>=850000,$I6>=480000),1600000,AND($H6>=1000000,$I6>=580000),2200000,AND($H6>=1200000,$I6>=650000),2800000,AND($H6>=1500000,$I6>=700000),4000000,TRUE,0)),0) -> 0 | K6: =IFERROR(IF(AND($J6=0, IF(OR($A6="Hàng Bông",$A6="Đường Láng"),$D6>=2000000,$D6>=950000)), 500000, 0), 0) -> 500000 | L6: =IFERROR(SUMIFS('Hot Bill HN'!$G:$G, 'Hot Bill HN'!$C:$C, $A6, 'Hot Bill HN'!$D:$D, $B6), 0) -> 0 | M6: =IFERROR($J6+$K6+$L6, 0) -> 500000
A7: Trường Sa | B7: Trịnh Thị Phượng | C7: DSCD | D7: =SUM(E7:G7)/DAY($A$1) -> 0 | E7: 0 | F7: 0 | G7: 0 | H7: =F7/DAY($A$1) -> 0 | I7: =G7/DAY($A$1) -> 0 | J7: =IFERROR(IF(OR($A7="Hàng Bông",$A7="Đường Láng"),_xlfn.IFS(AND($H7>=2200000,$I7>=450000),1000000,AND($H7>=2500000,$I7>=520000),1600000,AND($H7>=2800000,$I7>=650000),2200000,AND($H7>=3200000,$I7>=750000),2800000,AND($H7>=3400000,$I7>=900000),4000000,TRUE,0),_xlfn.IFS(AND($H7>=630000,$I7>=350000),1000000,AND($H7>=850000,$I7>=480000),1600000,AND($H7>=1000000,$I7>=580000),2200000,AND($H7>=1200000,$I7>=650000),2800000,AND($H7>=1500000,$I7>=700000),4000000,TRUE,0)),0) -> 0 | K7: =IFERROR(IF(AND($J7=0, IF(OR($A7="Hàng Bông",$A7="Đường Láng"),$D7>=2000000,$D7>=950000)), 500000, 0), 0) -> 0 | L7: =IFERROR(SUMIFS('Hot Bill HN'!$G:$G, 'Hot Bill HN'!$C:$C, $A7, 'Hot Bill HN'!$D:$D, $B7), 0) -> 0 | M7: =IFERROR($J7+$K7+$L7, 0) -> 0
A8: Đỗ Quang Đẩu | B8: Phạm Thị Nghĩa Hương | C8: DSCD | D8: =SUM(E8:G8)/DAY($A$1) -> 381832.4 | E8: 1374955 | F8: 1727155 | G8: 716214 | H8: =F8/DAY($A$1) -> 172715.5 | I8: =G8/DAY($A$1) -> 71621.4 | J8: =IFERROR(IF(OR($A8="Hàng Bông",$A8="Đường Láng"),_xlfn.IFS(AND($H8>=2200000,$I8>=450000),1000000,AND($H8>=2500000,$I8>=520000),1600000,AND($H8>=2800000,$I8>=650000),2200000,AND($H8>=3200000,$I8>=750000),2800000,AND($H8>=3400000,$I8>=900000),4000000,TRUE,0),_xlfn.IFS(AND($H8>=630000,$I8>=350000),1000000,AND($H8>=850000,$I8>=480000),1600000,AND($H8>=1000000,$I8>=580000),2200000,AND($H8>=1200000,$I8>=650000),2800000,AND($H8>=1500000,$I8>=700000),4000000,TRUE,0)),0) -> 0 | K8: =IFERROR(IF(AND($J8=0, IF(OR($A8="Hàng Bông",$A8="Đường Láng"),$D8>=2000000,$D8>=950000)), 500000, 0), 0) -> 0 | L8: =IFERROR(SUMIFS('Hot Bill HN'!$G:$G, 'Hot Bill HN'!$C:$C, $A8, 'Hot Bill HN'!$D:$D, $B8), 0) -> 0 | M8: =IFERROR($J8+$K8+$L8, 0) -> 0
A9: Đỗ Quang Đẩu | B9: Trần Thiên Phát | C9: DSXC | D9: =SUM(E9:G9)/DAY($A$1) -> 516686.5 | E9: 2315200 | F9: 1877270 | G9: 974395 | H9: =F9/DAY($A$1) -> 187727 | I9: =G9/DAY($A$1) -> 97439.5 | J9: =IFERROR(IF(OR($A9="Hàng Bông",$A9="Đường Láng"),_xlfn.IFS(AND($H9>=2200000,$I9>=450000),1000000,AND($H9>=2500000,$I9>=520000),1600000,AND($H9>=2800000,$I9>=650000),2200000,AND($H9>=3200000,$I9>=750000),2800000,AND($H9>=3400000,$I9>=900000),4000000,TRUE,0),_xlfn.IFS(AND($H9>=630000,$I9>=350000),1000000,AND($H9>=850000,$I9>=480000),1600000,AND($H9>=1000000,$I9>=580000),2200000,AND($H9>=1200000,$I9>=650000),2800000,AND($H9>=1500000,$I9>=700000),4000000,TRUE,0)),0) -> 0 | K9: =IFERROR(IF(AND($J9=0, IF(OR($A9="Hàng Bông",$A9="Đường Láng"),$D9>=2000000,$D9>=950000)), 500000, 0), 0) -> 0 | L9: =IFERROR(SUMIFS('Hot Bill HN'!$G:$G, 'Hot Bill HN'!$C:$C, $A9, 'Hot Bill HN'!$D:$D, $B9), 0) -> 0 | M9: =IFERROR($J9+$K9+$L9, 0) -> 0
A10: Đỗ Quang Đẩu | B10: Ngô Thị Thanh Thắm | C10: CHT | D10: =SUM(E10:G10)/DAY($A$1) -> 327075.9 | E10: 179907 | F10: 1659048 | G10: 1431804 | H10: =F10/DAY($A$1) -> 165904.8 | I10: =G10/DAY($A$1) -> 143180.4 | J10: =IFERROR(IF(OR($A10="Hàng Bông",$A10="Đường Láng"),_xlfn.IFS(AND($H10>=2200000,$I10>=450000),1000000,AND($H10>=2500000,$I10>=520000),1600000,AND($H10>=2800000,$I10>=650000),2200000,AND($H10>=3200000,$I10>=750000),2800000,AND($H10>=3400000,$I10>=900000),4000000,TRUE,0),_xlfn.IFS(AND($H10>=630000,$I10>=350000),1000000,AND($H10>=850000,$I10>=480000),1600000,AND($H10>=1000000,$I10>=580000),2200000,AND($H10>=1200000,$I10>=650000),2800000,AND($H10>=1500000,$I10>=700000),4000000,TRUE,0)),0) -> 0 | K10: =IFERROR(IF(AND($J10=0, IF(OR($A10="Hàng Bông",$A10="Đường Láng"),$D10>=2000000,$D10>=950000)), 500000, 0), 0) -> 0 | L10: =IFERROR(SUMIFS('Hot Bill HN'!$G:$G, 'Hot Bill HN'!$C:$C, $A10, 'Hot Bill HN'!$D:$D, $B10), 0) -> 0 | M10: =IFERROR($J10+$K10+$L10, 0) -> 0
A11: Đỗ Quang Đẩu | B11: Hoàng Thanh Thủy | C11: DSXC | D11: =SUM(E11:G11)/DAY($A$1) -> 1322051.9 | E11: 5193759 | F11: 5576977 | G11: 2449783 | H11: =F11/DAY($A$1) -> 557697.7 | I11: =G11/DAY($A$1) -> 244978.3 | J11: =IFERROR(IF(OR($A11="Hàng Bông",$A11="Đường Láng"),_xlfn.IFS(AND($H11>=2200000,$I11>=450000),1000000,AND($H11>=2500000,$I11>=520000),1600000,AND($H11>=2800000,$I11>=650000),2200000,AND($H11>=3200000,$I11>=750000),2800000,AND($H11>=3400000,$I11>=900000),4000000,TRUE,0),_xlfn.IFS(AND($H11>=630000,$I11>=350000),1000000,AND($H11>=850000,$I11>=480000),1600000,AND($H11>=1000000,$I11>=580000),2200000,AND($H11>=1200000,$I11>=650000),2800000,AND($H11>=1500000,$I11>=700000),4000000,TRUE,0)),0) -> 0 | K11: =IFERROR(IF(AND($J11=0, IF(OR($A11="Hàng Bông",$A11="Đường Láng"),$D11>=2000000,$D11>=950000)), 500000, 0), 0) -> 500000 | L11: =IFERROR(SUMIFS('Hot Bill HN'!$G:$G, 'Hot Bill HN'!$C:$C, $A11, 'Hot Bill HN'!$D:$D, $B11), 0) -> 0 | M11: =IFERROR($J11+$K11+$L11, 0) -> 500000
A12: Đỗ Quang Đẩu | B12: Lê Thị Huyền Trân | C12: DSXC | D12: =SUM(E12:G12)/DAY($A$1) -> 724108.8 | E12: 1783067 | F12: 3125482 | G12: 2332539 | H12: =F12/DAY($A$1) -> 312548.2 | I12: =G12/DAY($A$1) -> 233253.9 | J12: =IFERROR(IF(OR($A12="Hàng Bông",$A12="Đường Láng"),_xlfn.IFS(AND($H12>=2200000,$I12>=450000),1000000,AND($H12>=2500000,$I12>=520000),1600000,AND($H12>=2800000,$I12>=650000),2200000,AND($H12>=3200000,$I12>=750000),2800000,AND($H12>=3400000,$I12>=900000),4000000,TRUE,0),_xlfn.IFS(AND($H12>=630000,$I12>=350000),1000000,AND($H12>=850000,$I12>=480000),1600000,AND($H12>=1000000,$I12>=580000),2200000,AND($H12>=1200000,$I12>=650000),2800000,AND($H12>=1500000,$I12>=700000),4000000,TRUE,0)),0) -> 0 | K12: =IFERROR(IF(AND($J12=0, IF(OR($A12="Hàng Bông",$A12="Đường Láng"),$D12>=2000000,$D12>=950000)), 500000, 0), 0) -> 0 | L12: =IFERROR(SUMIFS('Hot Bill HN'!$G:$G, 'Hot Bill HN'!$C:$C, $A12, 'Hot Bill HN'!$D:$D, $B12), 0) -> 0 | M12: =IFERROR($J12+$K12+$L12, 0) -> 0
A13: Minh Châu | B13: Thái Thùy Linh | C13: CHT | D13: =SUM(E13:G13)/DAY($A$1) -> 1562186 | E13: 391000 | F13: 7566325 | G13: 7664535 | H13: =F13/DAY($A$1) -> 756632.5 | I13: =G13/DAY($A$1) -> 766453.5 | J13: =IFERROR(IF(OR($A13="Hàng Bông",$A13="Đường Láng"),_xlfn.IFS(AND($H13>=2200000,$I13>=450000),1000000,AND($H13>=2500000,$I13>=520000),1600000,AND($H13>=2800000,$I13>=650000),2200000,AND($H13>=3200000,$I13>=750000),2800000,AND($H13>=3400000,$I13>=900000),4000000,TRUE,0),_xlfn.IFS(AND($H13>=630000,$I13>=350000),1000000,AND($H13>=850000,$I13>=480000),1600000,AND($H13>=1000000,$I13>=580000),2200000,AND($H13>=1200000,$I13>=650000),2800000,AND($H13>=1500000,$I13>=700000),4000000,TRUE,0)),0) -> 1000000 | K13: =IFERROR(IF(AND($J13=0, IF(OR($A13="Hàng Bông",$A13="Đường Láng"),$D13>=2000000,$D13>=950000)), 500000, 0), 0) -> 0 | L13: =IFERROR(SUMIFS('Hot Bill HN'!$G:$G, 'Hot Bill HN'!$C:$C, $A13, 'Hot Bill HN'!$D:$D, $B13), 0) -> 0 | M13: =IFERROR($J13+$K13+$L13, 0) -> 1000000
