Workbook

Sheet data
A1: Nhà thuốc | B1: Tên nhân viên | C1: Số giao dịch off | D1: Doanh thu off | E1: Số giao dịch onl | F1: Doanh thu onl | G1: Tổng giao dịch | H1: Doanh thu tổng | J1: 46266
A2: Hàng Bông | B2: Nguyễn Mạnh Tuấn | C2: 782 | D2: 140105271 | E2: 435 | F2: 72375400 | G2: 1217 | H2: 212480671
A3: Hàng Bông | B3: Vũ Thanh Hằng | C3: 874 | D3: 284965450 | E3: 204 | F3: 58354497 | G3: 1078 | H3: 343319947
A4: Hàng Bông | B4: Đinh Thị Khánh Ly | C4: 1076 | D4: 264598985 | E4: 273 | F4: 61819627 | G4: 1349 | H4: 326418612
A5: Hàng Bông | B5: Đinh Thị Lan Anh | C5: 584 | D5: 107357032 | E5: 134 | F5: 26695101 | G5: 718 | H5: 134052133
A6: Lê Bình | B6: Hoàng Lâm Gia Bảo | C6: 251 | D6: 28489900 | E6: 111 | F6: 24047500 | G6: 362 | H6: 52537400
A7: Lê Bình | B7: Hồ Thị Minh Hòa | C7: 334 | D7: 31282300 | E7: 119 | F7: 24332420 | G7: 453 | H7: 55614720
A8: Lê Bình | B8: Lê Thị Xuyến | C8: 216 | D8: 16821200 | E8: 93 | F8: 11894900 | G8: 309 | H8: 28716100
A9: Lê Bình | B9: Nguyễn Thị Huyền Trang | C9: 15 | D9: 1259000 | E9: 2 | F9: 555000 | G9: 17 | H9: 1814000
A10: Lê Bình | B10: Phạm Nguyễn Ngọc Quý | C10: 10 | D10: 640500 | E10: 3 | F10: 527100 | G10: 13 | H10: 1167600
A11: Lê Bình | B11: Đinh Hoài Bảo | C11: 295 | D11: 24509200 | E11: 147 | F11: 22229750 | G11: 442 | H11: 46738950
A12: Minh Châu | B12: Nguyễn Ngọc Thùy | C12: 142 | D12: 10203800 | E12: 17 | F12: 1715850 | G12: 159 | H12: 11919650
A13: Minh Châu | B13: Phan Công Vũ Tài | C13: 1201 | D13: 98186094 | E13: 164 | F13: 24466350 | G13: 1365 | H13: 122652444
... A48: Trường Sa | B48: Hồ Thị Minh Hòa | C48: 20 | D48: 1503600 | E48: 14 | F48: 2401800 | G48: 34 | H48: 3905400
A49: Trường Sa | B49: Medigo | E49: 2 | F49: 773000 | G49: 2 | H49: 773000
A50: Trường Sa | B50: Nguyễn Ngọc Anh Thư | C50: 160 | D50: 10020901 | E50: 143 | F50: 18528950 | G50: 303 | H50: 28549851
A51: Trường Sa | B51: Nguyễn Trần Ngọc Phương | C51: 391 | D51: 26034702 | E51: 237 | F51: 36920401 | G51: 628 | H51: 62955103
A52: Trường Sa | B52: Ngô Trần Tuyết Vy | C52: 273 | D52: 16360400 | E52: 168 | F52: 28002100 | G52: 441 | H52: 44362500
A53: Trường Sa | B53: Phạm Nguyễn Ngọc Quý | C53: 392 | D53: 27728200 | E53: 222 | F53: 43587850 | G53: 614 | H53: 71316050
A54: Trường Sa | B54: Trần Thị Kim Khánh | C54: 511 | D54: 47529800 | E54: 432 | F54: 117323300 | G54: 943 | H54: 164853100
A55: Trường Sa | B55: Trịnh Thị Phượng | C55: 655 | D55: 58374052 | E55: 180 | F55: 25508640 | G55: 835 | H55: 83882692
A56: Đường Láng | B56: Hứa Thị Kim Thoa | C56: 140 | D56: 13436700 | E56: 44 | F56: 17580300 | G56: 184 | H56: 31017000
A57: Đường Láng | B57: Lê Thị Soạn | C57: 841 | D57: 96897085 | E57: 602 | F57: 95732950 | G57: 1443 | H57: 192630035
A58: Đường Láng | B58: Medigo | E58: 1 | F58: 49000 | G58: 1 | H58: 49000
A59: Đường Láng | B59: Nguyễn Thị Mai Duyên | C59: 417 | D59: 52907633 | E59: 519 | F59: 155622967 | G59: 936 | H59: 208530600
A60: Đường Láng | B60: Nguyễn Thị Tâm | C60: 663 | D60: 79617694 | E60: 454 | F60: 109454692 | G60: 1117 | H60: 189072386
A61: Đường Láng | B61: Trần Ngọc Dung | C61: 298 | D61: 30730280 | E61: 435 | F61: 134236200 | G61: 733 | H61: 164966480
A62: Đỗ Quang Đẩu | B62: Hoàng Lâm Gia Bảo | C62: 22 | D62: 11025100 | E62: 3 | F62: 533000 | G62: 25 | H62: 11558100
A63: Đỗ Quang Đẩu | B63: Hoàng Thanh Thủy | C63: 643 | D63: 221293840 | E63: 226 | F63: 70229849 | G63: 869 | H63: 291523689
A64: Đỗ Quang Đẩu | B64: Lê Thị Huyền Trân | C64: 728 | D64: 131993700 | E64: 237 | F64: 49278600 | G64: 965 | H64: 181272300
A65: Đỗ Quang Đẩu | B65: Ngô Thị Thanh Thắm | C65: 440 | D65: 170736200 | E65: 156 | F65: 35774901 | G65: 596 | H65: 206511101
A66: Đỗ Quang Đẩu | B66: Phạm Thị Nghĩa Hương | C66: 553 | D66: 109865100 | E66: 145 | F66: 21340500 | G66: 698 | H66: 131205600
A67: Đỗ Quang Đẩu | B67: Trần Thiên Phát | C67: 558 | D67: 124498570 | E67: 138 | F67: 17835300 | G67: 696 | H67: 142333870

Sheet kpi dược sĩ
A1: Dữ liệu cập nhật đến ngày | C1: 46265 | O1: Mức hoành thành KPI doanh thu/ngày | R1: Mức hoành thành KPI doanh thu/ngày
A2: Nhà thuốc | B2: Nhân viên | C2: Chức danh | D2: KPI trung bình bill | E2: Trung bình bill | F2: KPI doanh thu CK+Combo+NY3/ngày | G2: CK + Combo + NY3/ngày | H2: KPI Doanh thu/ngày (100%) | I2: Doanh thu thực/ngày | J2: % Hoàn thành KPI | K2: Thưởng KPI | L2: Hệ số * Dự án | M2: Thưởng Dự án | N2: Thưởng Dự án + KPI + HH | O2: 0.8 | P2: 0.9 | Q2: 1 | R2: 0.8 | S2: 0.9 | T2: 1 | U2: KPIs Doanh thu/ngày | V2: KPIs Doanh thu/tháng | W2: Số giao dịch off | X2: Doanh thu off | Y2: Trung bình bill off | Z2: Số giao dịch onl | AA2: Doanh thu onl | AB2: Trung bình bill onl | AC2: Tổng giao dịch | AD2: Doanh thu tổng | AE2: Trung bình Bill
A3: Hàng Bông | B3: Đinh Thị Lan Anh | C3: CHT | D3: 150000 | E3: =AE3 -> 186702.14 | F3: {=IFERROR( ROUND( _xludf.LET( nt,$A3, nv,$B3, songay,DAY(EOMONTH($C$1,0)), doanhthungay,$I3, duan_nv,SUM_xlfn.IFS('Dự án T8'!$D:$D,'Dự án T8'!$A:$A,nt,'Dự án T8'!$B:$B,nv), duan_nt,SUM_xlfn.IFS('Dự án T8'!$D:$D,'Dự án T8'!$A:$A,nt), tyle,duan_nv/duan_nt, muc2_ngay,_xlfn.XLOOKUP(nt,'kpi nhà thuốc'!$B:$B,'kpi nhà thuốc'!$P:$P), muc3_ngay,_xlfn.XLOOKUP(nt,'kpi nhà thuốc'!$B:$B,'kpi nhà thuốc'!$T:$T), hangdiem1,_xlfn.XLOOKUP(nt,'kpi nhà thuốc'!$B:$B,'kpi nhà thuốc'!$I:$I), hangdiem2,_xlfn.XLOOKUP(nt,'kpi nhà thuốc'!$B:$B,'kpi nhà thuốc'!$N:$N), hangdiem3,_xlfn.XLOOKUP(nt,'kpi nhà thuốc'!$B:$B,'kpi nhà thuốc'!$R:$R), _xludf.SWITCH(TRUE, doanhthungay>=muc3_ngay,hangdiem3, doanhthungay>=muc2_ngay,hangdiem2, TRUE,hangdiem1 )/songay*tyle ), -3), 0)} -> 0 | G3: =IFERROR(SUMIF('Dự án T8'!$B:$B, $B3, 'Dự án T8'!$D:$D), 0) -> 2314111.2 | H3: =Q3 -> 8800000 | I3: =(AD3/DAY($C$1)) -> 4324262.4 | J3: {=_xlfn.XLOOKUP(B3,'kpi nhà thuốc'!A:A,'kpi nhà thuốc'!F:F,(AD3/DAY($C$1))/U3)} -> 0.80021367 | K3: {=IFERROR( _xlfn.XLOOKUP(B6, 'kpi nhà thuốc'!A:A, 'kpi nhà thuốc'!G:G), IF( AND(OR(C6="DSXC", C6="DSCD", C6="DSBC", C6="DSTV"), G6>=F6), AD6 * IFS( AND(I6>=T6, E6>=D6), 1.5%, I6>=T6, 1.3%, AND(I6>=S6, E6>=D6), 1.3%, I6>=S6, 1.1%, AND(I6>=R6, E6>=D6), 1.2%, I6>=R6, 1%, TRUE, 0 ), 0 ) )} -> 4243442 | L3: =IF(C3="DSTV","", IF(J3<0.6, 0.8, 1)) -> 1 | M3: =IFERROR(SUMIF('Dự án T8'!$B:$B, $B3, 'Dự án T8'!$M:$M)*$L3, 0) -> 600000 | N3: =N(K3)+M3 -> 4843442 | O3: =CEILING(R3,100000) -> 7000000 | P3: =CEILING(S3,100000) -> 7900000 | Q3: =CEILING(T3,100000) -> 8800000 | R3: =U3*$R$2 -> 6967741.9 | S3: =U3*$S$2 -> 7838709.7 | T3: =U3*$T$2 -> 8709677.4 | U3: =V3/DAY($C$1) -> 8709677.4 | V3: 270000000 | W3: =IFERROR(SUMIFS(data!$C:$C, data!$A:$A, $A3, data!$B:$B, $B3), 0) -> 584 | X3: =IFERROR(SUMIF(data!$B:$B, $B3, data!$D:$D), 0) -> 107357032 | Y3: =IF(W3>0,X3/W3,0) -> 183830.53 | Z3: =IFERROR(SUMIFS(data!$E:$E, data!$A:$A, $A3, data!$B:$B, $B3), 0) -> 134 | AA3: =IFERROR(SUMIF(data!$B:$B, $B3, data!$F:$F), 0) -> 26695101 | AB3: =IF(Z3>0,AA3/Z3,0) -> 199217.17 | AC3: =W3+Z3 -> 718 | AD3: =X3+AA3 -> 134052133 | AE3: =IF(AC3>0,AD3/AC3,0) -> 186702.14
A4: Hàng Bông | B4: Vũ Thanh Hằng | C4: DSXC | D4: 245000 | E4: =AE4 -> 318478.61 | F4: {=IFERROR( ROUND( _xludf.LET( nt,$A4, nv,$B4, songay,DAY(EOMONTH($C$1,0)), doanhthungay,$I4, duan_nv,SUM_xlfn.IFS('Dự án T8'!$D:$D,'Dự án T8'!$A:$A,nt,'Dự án T8'!$B:$B,nv), duan_nt,SUM_xlfn.IFS('Dự án T8'!$D:$D,'Dự án T8'!$A:$A,nt), tyle,duan_nv/duan_nt, muc2_ngay,_xlfn.XLOOKUP(nt,'kpi nhà thuốc'!$B:$B,'kpi nhà thuốc'!$P:$P), muc3_ngay,_xlfn.XLOOKUP(nt,'kpi nhà thuốc'!$B:$B,'kpi nhà thuốc'!$T:$T), hangdiem1,_xlfn.XLOOKUP(nt,'kpi nhà thuốc'!$B:$B,'kpi nhà thuốc'!$I:$I), hangdiem2,_xlfn.XLOOKUP(nt,'kpi nhà thuốc'!$B:$B,'kpi nhà thuốc'!$N:$N), hangdiem3,_xlfn.XLOOKUP(nt,'kpi nhà thuốc'!$B:$B,'kpi nhà thuốc'!$R:$R), _xludf.SWITCH(TRUE, doanhthungay>=muc3_ngay,hangdiem3, doanhthungay>=muc2_ngay,hangdiem2, TRUE,hangdiem1 )/songay*tyle ), -3), 0)} -> 0 | G4: =IFERROR(SUMIF('Dự án T8'!$B:$B, $B4, 'Dự án T8'!$D:$D), 0) -> 4156945.4 | H4: =Q4 -> 11300000 | I4: =(AD4/DAY($C$1)) -> 11074837 | J4: {=_xlfn.XLOOKUP(B4,'kpi nhà thuốc'!A:A,'kpi nhà thuốc'!F:F,(AD4/DAY($C$1))/U4)} -> 0.98091413 | K4: {=_xlfn.XLOOKUP( B4, 'kpi nhà thuốc'!A:A, 'kpi nhà thuốc'!G:G, IF( AND( OR(C4="DSXC",C4="DSCD"), G4>=F4),IF(AND(I4>=T4,E4>=D4),AD4*1.5%,IF(AND(I4>=T4,E4<D4),AD4*1.3%,IF(AND(I4>=S4,E4>=D4),AD4*1.3%,IF(AND(I4>=S4,E4<D4),AD4*1.1%,IF(AND(I4>=R4,E4>=D4),AD4*1.2%,IF(AND(I4>=R4,E4<D4),AD4*1%,"")))))),"" ) )} -> 4463159.3 | L4: =IF(C4="DSTV","", IF(J4<0.6, 0.8, 1)) -> 1 | M4: =IFERROR(SUMIF('Dự án T8'!$B:$B, $B4, 'Dự án T8'!$M:$M)*$L4, 0) -> 1800000 | N4: =N(K4)+M4 -> 6263159.3 | O4: =CEILING(R4,100000) -> 9100000 | P4: =CEILING(S4,100000) -> 10200000 | Q4: =CEILING(T4,100000) -> 11300000 | R4: =U4*$R$2 -> 9032258.1 | S4: =U4*$S$2 -> 10161290 | T4: =U4*$T$2 -> 11290323 | U4: =V4/DAY($C$1) -> 11290323 | V4: 350000000 | W4: =IFERROR(SUMIFS(data!$C:$C, data!$A:$A, $A4, data!$B:$B, $B4), 0) -> 874 | X4: =IFERROR(SUMIF(data!$B:$B, $B4, data!$D:$D), 0) -> 284965450 | Y4: =IF(W4>0,X4/W4,0) -> 326047.43 | Z4: =IFERROR(SUMIFS(data!$E:$E, data!$A:$A, $A4, data!$B:$B, $B4), 0) -> 204 | AA4: =IFERROR(SUMIF(data!$B:$B, $B4, data!$F:$F), 0) -> 58354497 | AB4: =IF(Z4>0,AA4/Z4,0) -> 286051.46 | AC4: =W4+Z4 -> 1078 | AD4: =X4+AA4 -> 343319947 | AE4: =IF(AC4>0,AD4/AC4,0) -> 318478.61
A5: Hàng Bông | B5: Nguyễn Mạnh Tuấn | C5: DSCD | D5: 250000 | E5: =AE5 -> 174593.81 | F5: {=IFERROR( ROUND( _xludf.LET( nt,$A5, nv,$B5, songay,DAY(EOMONTH($C$1,0)), doanhthungay,$I5, duan_nv,SUM_xlfn.IFS('Dự án T8'!$D:$D,'Dự án T8'!$A:$A,nt,'Dự án T8'!$B:$B,nv), duan_nt,SUM_xlfn.IFS('Dự án T8'!$D:$D,'Dự án T8'!$A:$A,nt), tyle,duan_nv/duan_nt, muc2_ngay,_xlfn.XLOOKUP(nt,'kpi nhà thuốc'!$B:$B,'kpi nhà thuốc'!$P:$P), muc3_ngay,_xlfn.XLOOKUP(nt,'kpi nhà thuốc'!$B:$B,'kpi nhà thuốc'!$T:$T), hangdiem1,_xlfn.XLOOKUP(nt,'kpi nhà thuốc'!$B:$B,'kpi nhà thuốc'!$I:$I), hangdiem2,_xlfn.XLOOKUP(nt,'kpi nhà thuốc'!$B:$B,'kpi nhà thuốc'!$N:$N), hangdiem3,_xlfn.XLOOKUP(nt,'kpi nhà thuốc'!$B:$B,'kpi nhà thuốc'!$R:$R), _xludf.SWITCH(TRUE, doanhthungay>=muc3_ngay,hangdiem3, doanhthungay>=muc2_ngay,hangdiem2, TRUE,hangdiem1 )/songay*tyle ), -3), 0)} -> 0 | G5: =IFERROR(SUMIF('Dự án T8'!$B:$B, $B5, 'Dự án T8'!$D:$D), 0) -> 1913967 | H5: =Q5 -> 9700000 | I5: =(AD5/DAY($C$1)) -> 6854215.2 | J5: {=_xlfn.XLOOKUP(B5,'kpi nhà thuốc'!A:A,'kpi nhà thuốc'!F:F,(AD5/DAY($C$1))/U5)} -> 0.7082689 | K5: {=_xlfn.XLOOKUP( B5, 'kpi nhà thuốc'!A:A, 'kpi nhà thuốc'!G:G, IF( AND( OR(C5="DSXC",C5="DSCD"), G5>=F5),IF(AND(I5>=T5,E5>=D5),AD5*1.5%,IF(AND(I5>=T5,E5<D5),AD5*1.3%,IF(AND(I5>=S5,E5>=D5),AD5*1.3%,IF(AND(I5>=S5,E5<D5),AD5*1.1%,IF(AND(I5>=R5,E5>=D5),AD5*1.2%,IF(AND(I5>=R5,E5<D5),AD5*1%,"")))))),"" ) )} | L5: =IF(C5="DSTV","", IF(J5<0.6, 0.8, 1)) -> 1 | M5: =IFERROR(SUMIF('Dự án T8'!$B:$B, $B5, 'Dự án T8'!$M:$M)*$L5, 0) -> 100000 | N5: =N(K5)+M5 -> 100000 | O5: =CEILING(R5,100000) -> 7800000 | P5: =CEILING(S5,100000) -> 8800000 | Q5: =CEILING(T5,100000) -> 9700000 | R5: =U5*$R$2 -> 7741935.5 | S5: =U5*$S$2 -> 8709677.4 | T5: =U5*$T$2 -> 9677419.4 | U5: =V5/DAY($C$1) -> 9677419.4 | V5: 300000000 | W5: =IFERROR(SUMIFS(data!$C:$C, data!$A:$A, $A5, data!$B:$B, $B5), 0) -> 782 | X5: =IFERROR(SUMIF(data!$B:$B, $B5, data!$D:$D), 0) -> 140105271 | Y5: =IF(W5>0,X5/W5,0) -> 179162.75 | Z5: =IFERROR(SUMIFS(data!$E:$E, data!$A:$A, $A5, data!$B:$B, $B5), 0) -> 435 | AA5: =IFERROR(SUMIF(data!$B:$B, $B5, data!$F:$F), 0) -> 72375400 | AB5: =IF(Z5>0,AA5/Z5,0) -> 166380.23 | AC5: =W5+Z5 -> 1217 | AD5: =X5+AA5 -> 212480671 | AE5: =IF(AC5>0,AD5/AC5,0) -> 174593.81
A6: Hàng Bông | B6: Đinh Thị Khánh Ly | C6: DSXC | D6: 204000 | E6: =AE6 -> 241970.8 | F6: {=IFERROR( ROUND( _xludf.LET( nt,$A6, nv,$B6, songay,DAY(EOMONTH($C$1,0)), doanhthungay,$I6, duan_nv,SUM_xlfn.IFS('Dự án T8'!$D:$D,'Dự án T8'!$A:$A,nt,'Dự án T8'!$B:$B,nv), duan_nt,SUM_xlfn.IFS('Dự án T8'!$D:$D,'Dự án T8'!$A:$A,nt), tyle,duan_nv/duan_nt, muc2_ngay,_xlfn.XLOOKUP(nt,'kpi nhà thuốc'!$B:$B,'kpi nhà thuốc'!$P:$P), muc3_ngay,_xlfn.XLOOKUP(nt,'kpi nhà thuốc'!$B:$B,'kpi nhà thuốc'!$T:$T), hangdiem1,_xlfn.XLOOKUP(nt,'kpi nhà thuốc'!$B:$B,'kpi nhà thuốc'!$I:$I), hangdiem2,_xlfn.XLOOKUP(nt,'kpi nhà thuốc'!$B:$B,'kpi nhà thuốc'!$N:$N), hangdiem3,_xlfn.XLOOKUP(nt,'kpi nhà thuốc'!$B:$B,'kpi nhà thuốc'!$R:$R), _xludf.SWITCH(TRUE, doanhthungay>=muc3_ngay,hangdiem3, doanhthungay>=muc2_ngay,hangdiem2, TRUE,hangdiem1 )/songay*tyle ), -3), 0)} -> 0 | G6: =IFERROR(SUMIF('Dự án T8'!$B:$B, $B6, 'Dự án T8'!$D:$D), 0) -> 3533822.9 | H6: =Q6 -> 11300000 | I6: =(AD6/DAY($C$1)) -> 10529633 | J6: {=_xlfn.XLOOKUP(B6,'kpi nhà thuốc'!A:A,'kpi nhà thuốc'!F:F,(AD6/DAY($C$1))/U6)} -> 0.93262461 | K6: =ARRAY_CONSTRAIN(ARRAYFORMULA(_xlfn.XLOOKUP( B6, 'kpi nhà thuốc'!A:A,K40 'kpi nhà thuốc'!G:G, IF( AND( OR(C6="DSXC",C6="DSCD"), G6>=F6),IF(AND(I6>=T6,E6>=D6),AD6*1.5%,IF(AND(I6>=T6,E6<D6),AD6*1.3%,IF(AND(I6>=S6,E6>=D6),AD6*1.3%,IF(AND(I6>=S6,E6<D6),AD6*1.1%,IF(AND(I6>=R6,E6>=D6),AD6*1.2%,IF(AND(I6>=R6,E6<D6),AD6*1%,"")))))),"" ) )), 1, 1) -> #ERROR! | L6: =IF(C6="DSTV","", IF(J6<0.6, 0.8, 1)) -> 1 | M6: =IFERROR(SUMIF('Dự án T8'!$B:$B, $B6, 'Dự án T8'!$M:$M)*$L6, 0) -> 650000 | N6: =N(K6)+M6 -> #ERROR! | O6: =CEILING(R6,100000) -> 9100000 | P6: =CEILING(S6,100000) -> 10200000 | Q6: =CEILING(T6,100000) -> 11300000 | R6: =U6*$R$2 -> 9032258.1 | S6: =U6*$S$2 -> 10161290 | T6: =U6*$T$2 -> 11290323 | U6: =V6/DAY($C$1) -> 11290323 | V6: 350000000 | W6: =IFERROR(SUMIFS(data!$C:$C, data!$A:$A, $A6, data!$B:$B, $B6), 0) -> 1076 | X6: =IFERROR(SUMIF(data!$B:$B, $B6, data!$D:$D), 0) -> 264598985 | Y6: =IF(W6>0,X6/W6,0) -> 245909.84 | Z6: =IFERROR(SUMIFS(data!$E:$E, data!$A:$A, $A6, data!$B:$B, $B6), 0) -> 273 | AA6: =IFERROR(SUMIF(data!$B:$B, $B6, data!$F:$F), 0) -> 61819627 | AB6: =IF(Z6>0,AA6/Z6,0) -> 226445.52 | AC6: =W6+Z6 -> 1349 | AD6: =X6+AA6 -> 326418612 | AE6: =IF(AC6>0,AD6/AC6,0) -> 241970.8
A7: Đường Láng | B7: Hứa Thị Kim Thoa | C7: CHT | D7: 150000 | E7: =AE7 -> 168570.65 | F7: {=IFERROR( ROUND( _xludf.LET( nt,$A7, nv,$B7, songay,DAY(EOMONTH($C$1,0)), doanhthungay,$I7, duan_nv,SUM_xlfn.IFS('Dự án T8'!$D:$D,'Dự án T8'!$A:$A,nt,'Dự án T8'!$B:$B,nv), duan_nt,SUM_xlfn.IFS('Dự án T8'!$D:$D,'Dự án T8'!$A:$A,nt), tyle,duan_nv/duan_nt, muc2_ngay,_xlfn.XLOOKUP(nt,'kpi nhà thuốc'!$B:$B,'kpi nhà thuốc'!$P:$P), muc3_ngay,_xlfn.XLOOKUP(nt,'kpi nhà thuốc'!$B:$B,'kpi nhà thuốc'!$T:$T), hangdiem1,_xlfn.XLOOKUP(nt,'kpi nhà thuốc'!$B:$B,'kpi nhà thuốc'!$I:$I), hangdiem2,_xlfn.XLOOKUP(nt,'kpi nhà thuốc'!$B:$B,'kpi nhà thuốc'!$N:$N), hangdiem3,_xlfn.XLOOKUP(nt,'kpi nhà thuốc'!$B:$B,'kpi nhà thuốc'!$R:$R), _xludf.SWITCH(TRUE, doanhthungay>=muc3_ngay,hangdiem3, doanhthungay>=muc2_ngay,hangdiem2, TRUE,hangdiem1 )/songay*tyle ), -3), 0)} -> 0 | G7: =IFERROR(SUMIF('Dự án T8'!$B:$B, $B7, 'Dự án T8'!$D:$D), 0) -> 240027.55 | H7: =Q7 -> 3900000 | I7: =(AD7/DAY($C$1)) -> 1000548.4 | J7: {=_xlfn.XLOOKUP(B7,'kpi nhà thuốc'!A:A,'kpi nhà thuốc'!F:F,(AD7/DAY($C$1))/U7)} -> 0.80231174 | K7: {=_xlfn.XLOOKUP( B7, 'kpi nhà thuốc'!A:A, 'kpi nhà thuốc'!G:G, IF( AND( OR(C7="DSXC",C7="DSCD"), G7>=F7),IF(AND(I7>=T7,E7>=D7),AD7*1.5%,IF(AND(I7>=T7,E7<D7),AD7*1.3%,IF(AND(I7>=S7,E7>=D7),AD7*1.3%,IF(AND(I7>=S7,E7<D7),AD7*1.1%,IF(AND(I7>=R7,E7>=D7),AD7*1.2%,IF(AND(I7>=R7,E7<D7),AD7*1%,"")))))),"" ) )} -> 2751929.3 | L7: =IF(C7="DSTV","", IF(J7<0.6, 0.8, 1)) -> 1 | M7: =IFERROR(SUMIF('Dự án T8'!$B:$B, $B7, 'Dự án T8'!$M:$M)*$L7, 0) -> 0 | N7: =N(K7)+M7 -> 2751929.3 | O7: =CEILING(R7,100000) -> 3100000 | P7: =CEILING(S7,100000) -> 3500000 | Q7: =CEILING(T7,100000) -> 3900000 | R7: =U7*$R$2 -> 3096774.2 | S7: =U7*$S$2 -> 3483871 | T7: =U7*$T$2 -> 3870967.7 | U7: =V7/DAY($C$1) -> 3870967.7 | V7: 120000000 | W7: =IFERROR(SUMIFS(data!$C:$C, data!$A:$A, $A7, data!$B:$B, $B7), 0) -> 140 | X7: =IFERROR(SUMIF(data!$B:$B, $B7, data!$D:$D), 0) -> 13436700 | Y7: =IF(W7>0,X7/W7,0) -> 95976.429 | Z7: =IFERROR(SUMIFS(data!$E:$E, data!$A:$A, $A7, data!$B:$B, $B7), 0) -> 44 | AA7: =IFERROR(SUMIF(data!$B:$B, $B7, data!$F:$F), 0) -> 17580300 | AB7: =IF(Z7>0,AA7/Z7,0) -> 399552.27 | AC7: =W7+Z7 -> 184 | AD7: =X7+AA7 -> 31017000 | AE7: =IF(AC7>0,AD7/AC7,0) -> 168570.65
A8: Đường Láng | B8: Lê Thị Soạn | C8: DSCD | D8: 183000 | E8: =AE8 -> 133492.75 | F8: {=IFERROR( ROUND( _xludf.LET( nt,$A8, nv,$B8, songay,DAY(EOMONTH($C$1,0)), doanhthungay,$I8, duan_nv,SUM_xlfn.IFS('Dự án T8'!$D:$D,'Dự án T8'!$A:$A,nt,'Dự án T8'!$B:$B,nv), duan_nt,SUM_xlfn.IFS('Dự án T8'!$D:$D,'Dự án T8'!$A:$A,nt), tyle,duan_nv/duan_nt, muc2_ngay,_xlfn.XLOOKUP(nt,'kpi nhà thuốc'!$B:$B,'kpi nhà thuốc'!$P:$P), muc3_ngay,_xlfn.XLOOKUP(nt,'kpi nhà thuốc'!$B:$B,'kpi nhà thuốc'!$T:$T), hangdiem1,_xlfn.XLOOKUP(nt,'kpi nhà thuốc'!$B:$B,'kpi nhà thuốc'!$I:$I), hangdiem2,_xlfn.XLOOKUP(nt,'kpi nhà thuốc'!$B:$B,'kpi nhà thuốc'!$N:$N), hangdiem3,_xlfn.XLOOKUP(nt,'kpi nhà thuốc'!$B:$B,'kpi nhà thuốc'!$R:$R), _xludf.SWITCH(TRUE, doanhthungay>=muc3_ngay,hangdiem3, doanhthungay>=muc2_ngay,hangdiem2, TRUE,hangdiem1 )/songay*tyle ), -3), 0)} -> 0 | G8: =IFERROR(SUMIF('Dự án T8'!$B:$B, $B8, 'Dự án T8'!$D:$D), 0) -> 3249223.3 | H8: =Q8 -> 7500000 | I8: =(AD8/DAY($C$1)) -> 6213872.1 | J8: {=_xlfn.XLOOKUP(B8,'kpi nhà thuốc'!A:A,'kpi nhà thuốc'!F:F,(AD8/DAY($C$1))/U8)} -> 0.83752189 | K8: {=_xlfn.XLOOKUP( B8, 'kpi nhà thuốc'!A:A, 'kpi nhà thuốc'!G:G, IF( AND( OR(C8="DSXC",C8="DSCD"), G8>=F8),IF(AND(I8>=T8,E8>=D8),AD8*1.5%,IF(AND(I8>=T8,E8<D8),AD8*1.3%,IF(AND(I8>=S8,E8>=D8),AD8*1.3%,IF(AND(I8>=S8,E8<D8),AD8*1.1%,IF(AND(I8>=R8,E8>=D8),AD8*1.2%,IF(AND(I8>=R8,E8<D8),AD8*1%,"")))))),"" ) )} -> 1926300.4 | L8: =IF(C8="DSTV","", IF(J8<0.6, 0.8, 1)) -> 1 | M8: =IFERROR(SUMIF('Dự án T8'!$B:$B, $B8, 'Dự án T8'!$M:$M)*$L8, 0) -> 1650000 | N8: =N(K8)+M8 -> 3576300.4 | O8: =CEILING(R8,100000) -> 6000000 | P8: =CEILING(S8,100000) -> 6700000 | Q8: =CEILING(T8,100000) -> 7500000 | R8: =U8*$R$2 -> 5935483.9 | S8: =U8*$S$2 -> 6677419.4 | T8: =U8*$T$2 -> 7419354.8 | U8: =V8/DAY($C$1) -> 7419354.8 | V8: 230000000 | W8: =IFERROR(SUMIFS(data!$C:$C, data!$A:$A, $A8, data!$B:$B, $B8), 0) -> 841 | X8: =IFERROR(SUMIF(data!$B:$B, $B8, data!$D:$D), 0) -> 96897085 | Y8: =IF(W8>0,X8/W8,0) -> 115216.51 | Z8: =IFERROR(SUMIFS(data!$E:$E, data!$A:$A, $A8, data!$B:$B, $B8), 0) -> 602 | AA8: =IFERROR(SUMIF(data!$B:$B, $B8, data!$F:$F), 0) -> 95732950 | AB8: =IF(Z8>0,AA8/Z8,0) -> 159024.83 | AC8: =W8+Z8 -> 1443 | AD8: =X8+AA8 -> 192630035 | AE8: =IF(AC8>0,AD8/AC8,0) -> 133492.75
A9: Đường Láng | B9: Nguyễn Thị Tâm | C9: DSXC | D9: 178000 | E9: =AE9 -> 169268.03 | F9: {=IFERROR( ROUND( _xludf.LET( nt,$A9, nv,$B9, songay,DAY(EOMONTH($C$1,0)), doanhthungay,$I9, duan_nv,SUM_xlfn.IFS('Dự án T8'!$D:$D,'Dự án T8'!$A:$A,nt,'Dự án T8'!$B:$B,nv), duan_nt,SUM_xlfn.IFS('Dự án T8'!$D:$D,'Dự án T8'!$A:$A,nt), tyle,duan_nv/duan_nt, muc2_ngay,_xlfn.XLOOKUP(nt,'kpi nhà thuốc'!$B:$B,'kpi nhà thuốc'!$P:$P), muc3_ngay,_xlfn.XLOOKUP(nt,'kpi nhà thuốc'!$B:$B,'kpi nhà thuốc'!$T:$T), hangdiem1,_xlfn.XLOOKUP(nt,'kpi nhà thuốc'!$B:$B,'kpi nhà thuốc'!$I:$I), hangdiem2,_xlfn.XLOOKUP(nt,'kpi nhà thuốc'!$B:$B,'kpi nhà thuốc'!$N:$N), hangdiem3,_xlfn.XLOOKUP(nt,'kpi nhà thuốc'!$B:$B,'kpi nhà thuốc'!$R:$R), _xludf.SWITCH(TRUE, doanhthungay>=muc3_ngay,hangdiem3, doanhthungay>=muc2_ngay,hangdiem2, TRUE,hangdiem1 )/songay*tyle ), -3), 0)} -> 0 | G9: =IFERROR(SUMIF('Dự án T8'!$B:$B, $B9, 'Dự án T8'!$D:$D), 0) -> 2992485.3 | H9: =Q9 -> 6500000 | I9: =(AD9/DAY($C$1)) -> 6099109.2 | J9: {=_xlfn.XLOOKUP(B9,'kpi nhà thuốc'!A:A,'kpi nhà thuốc'!F:F,(AD9/DAY($C$1))/U9)} -> 0.94536193 | K9: {=_xlfn.XLOOKUP( B9, 'kpi nhà thuốc'!A:A, 'kpi nhà thuốc'!G:G, IF( AND( OR(C9="DSXC",C9="DSCD"), G9>=F9),IF(AND(I9>=T9,E9>=D9),AD9*1.5%,IF(AND(I9>=T9,E9<D9),AD9*1.3%,IF(AND(I9>=S9,E9>=D9),AD9*1.3%,IF(AND(I9>=S9,E9<D9),AD9*1.1%,IF(AND(I9>=R9,E9>=D9),AD9*1.2%,IF(AND(I9>=R9,E9<D9),AD9*1%,"")))))),"" ) )} -> 2079796.2 | L9: =IF(C9="DSTV","", IF(J9<0.6, 0.8, 1)) -> 1 | M9: =IFERROR(SUMIF('Dự án T8'!$B:$B, $B9, 'Dự án T8'!$M:$M)*$L9, 0) -> 1050000 | N9: =N(K9)+M9 -> 3129796.2 | O9: =CEILING(R9,100000) -> 5200000 | P9: =CEILING(S9,100000) -> 5900000 | Q9: =CEILING(T9,100000) -> 6500000 | R9: =U9*$R$2 -> 5161290.3 | S9: =U9*$S$2 -> 5806451.6 | T9: =U9*$T$2 -> 6451612.9 | U9: =V9/DAY($C$1) -> 6451612.9 | V9: 200000000 | W9: =IFERROR(SUMIFS(data!$C:$C, data!$A:$A, $A9, data!$B:$B, $B9), 0) -> 663 | X9: =IFERROR(SUMIF(data!$B:$B, $B9, data!$D:$D), 0) -> 79617694 | Y9: =IF(W9>0,X9/W9,0) -> 120087.02 | Z9: =IFERROR(SUMIFS(data!$E:$E, data!$A:$A, $A9, data!$B:$B, $B9), 0) -> 454 | AA9: =IFERROR(SUMIF(data!$B:$B, $B9, data!$F:$F), 0) -> 109454692 | AB9: =IF(Z9>0,AA9/Z9,0) -> 241089.63 | AC9: =W9+Z9 -> 1117 | AD9: =X9+AA9 -> 189072386 | AE9: =IF(AC9>0,AD9/AC9,0) -> 169268.03
A10: Đường Láng | B10: Nguyễn Thị Mai Duyên | C10: DSXC | D10: 241000 | E10: =AE10 -> 222789.1 | F10: {=IFERROR( ROUND( _xludf.LET( nt,$A10, nv,$B10, songay,DAY(EOMONTH($C$1,0)), doanhthungay,$I10, duan_nv,SUM_xlfn.IFS('Dự án T8'!$D:$D,'Dự án T8'!$A:$A,nt,'Dự án T8'!$B:$B,nv), duan_nt,SUM_xlfn.IFS('Dự án T8'!$D:$D,'Dự án T8'!$A:$A,nt), tyle,duan_nv/duan_nt, muc2_ngay,_xlfn.XLOOKUP(nt,'kpi nhà thuốc'!$B:$B,'kpi nhà thuốc'!$P:$P), muc3_ngay,_xlfn.XLOOKUP(nt,'kpi nhà thuốc'!$B:$B,'kpi nhà thuốc'!$T:$T), hangdiem1,_xlfn.XLOOKUP(nt,'kpi nhà thuốc'!$B:$B,'kpi nhà thuốc'!$I:$I), hangdiem2,_xlfn.XLOOKUP(nt,'kpi nhà thuốc'!$B:$B,'kpi nhà thuốc'!$N:$N), hangdiem3,_xlfn.XLOOKUP(nt,'kpi nhà thuốc'!$B:$B,'kpi nhà thuốc'!$R:$R), _xludf.SWITCH(TRUE, doanhthungay>=muc3_ngay,hangdiem3, doanhthungay>=muc2_ngay,hangdiem2, TRUE,hangdiem1 )/songay*tyle ), -3), 0)} -> 0 | G10: =IFERROR(SUMIF('Dự án T8'!$B:$B, $B10, 'Dự án T8'!$D:$D), 0) -> 2869824.4 | H10: =Q10 -> 7500000 | I10: =(AD10/DAY($C$1)) -> 6726793.5 | J10: {=_xlfn.XLOOKUP(B10,'kpi nhà thuốc'!A:A,'kpi nhà thuốc'!F:F,(AD10/DAY($C$1))/U10)} -> 0.90665478 | K10: {=_xlfn.XLOOKUP( B10, 'kpi nhà thuốc'!A:A, 'kpi nhà thuốc'!G:G, IF( AND( OR(C10="DSXC",C10="DSCD"), G10>=F10),IF(AND(I10>=T10,E10>=D10),AD10*1.5%,IF(AND(I10>=T10,E10<D10),AD10*1.3%,IF(AND(I10>=S10,E10>=D10),AD10*1.3%,IF(AND(I10>=S10,E10<D10),AD10*1.1%,IF(AND(I10>=R10,E10>=D10),AD10*1.2%,IF(AND(I10>=R10,E10<D10),AD10*1%,"")))))),"" ) )} -> 2293836.6 | L10: =IF(C10="DSTV","", IF(J10<0.6, 0.8, 1)) -> 1 | M10: =IFERROR(SUMIF('Dự án T8'!$B:$B, $B10, 'Dự án T8'!$M:$M)*$L10, 0) -> 1350000 | N10: =N(K10)+M10 -> 3643836.6 | O10: =CEILING(R10,100000) -> 6000000 | P10: =CEILING(S10,100000) -> 6700000 | Q10: =CEILING(T10,100000) -> 7500000 | R10: =U10*$R$2 -> 5935483.9 | S10: =U10*$S$2 -> 6677419.4 | T10: =U10*$T$2 -> 7419354.8 | U10: =V10/DAY($C$1) -> 7419354.8 | V10: 230000000 | W10: =IFERROR(SUMIFS(data!$C:$C, data!$A:$A, $A10, data!$B:$B, $B10), 0) -> 417 | X10: =IFERROR(SUMIF(data!$B:$B, $B10, data!$D:$D), 0) -> 52907633 | Y10: =IF(W10>0,X10/W10,0) -> 126876.82 | Z10: =IFERROR(SUMIFS(data!$E:$E, data!$A:$A, $A10, data!$B:$B, $B10), 0) -> 519 | AA10: =IFERROR(SUMIF(data!$B:$B, $B10, data!$F:$F), 0) -> 155622967 | AB10: =IF(Z10>0,AA10/Z10,0) -> 299851.57 | AC10: =W10+Z10 -> 936 | AD10: =X10+AA10 -> 208530600 | AE10: =IF(AC10>0,AD10/AC10,0) -> 222789.1
A11: Đường Láng | B11: Trần Ngọc Dung | C11: DSXC | D11: 150000 | E11: =AE11 -> 225056.59 | F11: {=IFERROR( ROUND( _xludf.LET( nt,$A11, nv,$B11, songay,DAY(EOMONTH($C$1,0)), doanhthungay,$I11, duan_nv,SUM_xlfn.IFS('Dự án T8'!$D:$D,'Dự án T8'!$A:$A,nt,'Dự án T8'!$B:$B,nv), duan_nt,SUM_xlfn.IFS('Dự án T8'!$D:$D,'Dự án T8'!$A:$A,nt), tyle,duan_nv/duan_nt, muc2_ngay,_xlfn.XLOOKUP(nt,'kpi nhà thuốc'!$B:$B,'kpi nhà thuốc'!$P:$P), muc3_ngay,_xlfn.XLOOKUP(nt,'kpi nhà thuốc'!$B:$B,'kpi nhà thuốc'!$T:$T), hangdiem1,_xlfn.XLOOKUP(nt,'kpi nhà thuốc'!$B:$B,'kpi nhà thuốc'!$I:$I), hangdiem2,_xlfn.XLOOKUP(nt,'kpi nhà thuốc'!$B:$B,'kpi nhà thuốc'!$N:$N), hangdiem3,_xlfn.XLOOKUP(nt,'kpi nhà thuốc'!$B:$B,'kpi nhà thuốc'!$R:$R), _xludf.SWITCH(TRUE, doanhthungay>=muc3_ngay,hangdiem3, doanhthungay>=muc2_ngay,hangdiem2, TRUE,hangdiem1 )/songay*tyle ), -3), 0)} -> 0 | G11: =IFERROR(SUMIF('Dự án T8'!$B:$B, $B11, 'Dự án T8'!$D:$D), 0) -> 773680.55 | H11: =Q11 -> 6500000 | I11: =(AD11/DAY($C$1)) -> 5321499.4 | J11: {=_xlfn.XLOOKUP(B11,'kpi nhà thuốc'!A:A,'kpi nhà thuốc'!F:F,(AD11/DAY($C$1))/U11)} -> 0.8248324 | K11: {=_xlfn.XLOOKUP( B11, 'kpi nhà thuốc'!A:A, 'kpi nhà thuốc'!G:G, IF( AND( OR(C11="DSXC",C11="DSCD"), G11>=F11),IF(AND(I11>=T11,E11>=D11),AD11*1.5%,IF(AND(I11>=T11,E11<D11),AD11*1.3%,IF(AND(I11>=S11,E11>=D11),AD11*1.3%,IF(AND(I11>=S11,E11<D11),AD11*1.1%,IF(AND(I11>=R11,E11>=D11),AD11*1.2%,IF(AND(I11>=R11,E11<D11),AD11*1%,"")))))),"" ) )} -> 1979597.8 | L11: =IF(C11="DSTV","", IF(J11<0.6, 0.8, 1)) -> 1 | M11: =IFERROR(SUMIF('Dự án T8'!$B:$B, $B11, 'Dự án T8'!$M:$M)*$L11, 0) -> 0 | N11: =N(K11)+M11 -> 1979597.8 | O11: =CEILING(R11,100000) -> 5200000 | P11: =CEILING(S11,100000) -> 5900000 | Q11: =CEILING(T11,100000) -> 6500000 | R11: =U11*$R$2 -> 5161290.3 | S11: =U11*$S$2 -> 5806451.6 | T11: =U11*$T$2 -> 6451612.9 | U11: =V11/DAY($C$1) -> 6451612.9 | V11: 200000000 | W11: =IFERROR(SUMIFS(data!$C:$C, data!$A:$A, $A11, data!$B:$B, $B11), 0) -> 298 | X11: =IFERROR(SUMIF(data!$B:$B, $B11, data!$D:$D), 0) -> 30730280 | Y11: =IF(W11>0,X11/W11,0) -> 103121.74 | Z11: =IFERROR(SUMIFS(data!$E:$E, data!$A:$A, $A11, data!$B:$B, $B11), 0) -> 435 | AA11: =IFERROR(SUMIF(data!$B:$B, $B11, data!$F:$F), 0) -> 134236200 | AB11: =IF(Z11>0,AA11/Z11,0) -> 308588.97 | AC11: =W11+Z11 -> 733 | AD11: =X11+AA11 -> 164966480 | AE11: =IF(AC11>0,AD11/AC11,0) -> 225056.59
A12: Trường Sa | B12: Nguyễn Trần Ngọc Phương | C12: Q.CHT | D12: 150000 | E12: =AE12 -> 100246.98 | F12: {=IFERROR( ROUND( _xludf.LET( nt,$A12, nv,$B12, songay,DAY(EOMONTH($C$1,0)), doanhthungay,$I12, duan_nv,SUM_xlfn.IFS('Dự án T8'!$D:$D,'Dự án T8'!$A:$A,nt,'Dự án T8'!$B:$B,nv), duan_nt,SUM_xlfn.IFS('Dự án T8'!$D:$D,'Dự án T8'!$A:$A,nt), tyle,duan_nv/duan_nt, muc2_ngay,_xlfn.XLOOKUP(nt,'kpi nhà thuốc'!$B:$B,'kpi nhà thuốc'!$P:$P), muc3_ngay,_xlfn.XLOOKUP(nt,'kpi nhà thuốc'!$B:$B,'kpi nhà thuốc'!$T:$T), hangdiem1,_xlfn.XLOOKUP(nt,'kpi nhà thuốc'!$B:$B,'kpi nhà thuốc'!$I:$I), hangdiem2,_xlfn.XLOOKUP(nt,'kpi nhà thuốc'!$B:$B,'kpi nhà thuốc'!$N:$N), hangdiem3,_xlfn.XLOOKUP(nt,'kpi nhà thuốc'!$B:$B,'kpi nhà thuốc'!$R:$R), _xludf.SWITCH(TRUE, doanhthungay>=muc3_ngay,hangdiem3, doanhthungay>=muc2_ngay,hangdiem2, TRUE,hangdiem1 )/songay*tyle ), -3), 0)} -> 0 | G12: =IFERROR(SUMIF('Dự án T8'!$B:$B, $B12, 'Dự án T8'!$D:$D), 0) -> 783980 | H12: =Q12 -> 3600000 | I12: =(AD12/DAY($C$1)) -> 2030809.8 | J12: {=_xlfn.XLOOKUP(B12,'kpi nhà thuốc'!A:A,'kpi nhà thuốc'!F:F,(AD12/DAY($C$1))/U12)} -> 0.7196839 | K12: {=_xlfn.XLOOKUP( B12, 'kpi nhà thuốc'!A:A, 'kpi nhà thuốc'!G:G, IF( AND( OR(C12="DSXC",C12="DSCD"), G12>=F12),IF(AND(I12>=T12,E12>=D12),AD12*1.5%,IF(AND(I12>=T12,E12<D12),AD12*1.3%,IF(AND(I12>=S12,E12>=D12),AD12*1.3%,IF(AND(I12>=S12,E12<D12),AD12*1.1%,IF(AND(I12>=R12,E12>=D12),AD12*1.2%,IF(AND(I12>=R12,E12<D12),AD12*1%,"")))))),"" ) )} -> 0 | L12: =IF(C12="DSTV","", IF(J12<0.6, 0.8, 1)) -> 1 | M12: =IFERROR(SUMIF('Dự án T8'!$B:$B, $B12, 'Dự án T8'!$M:$M)*$L12, 0) -> 0 | N12: =N(K12)+M12 -> 0 | O12: =CEILING(R12,100000) -> 2900000 | P12: =CEILING(S12,100000) -> 3200000 | Q12: =CEILING(T12,100000) -> 3600000 | R12: =U12*$R$2 -> 2838709.7 | S12: =U12*$S$2 -> 3193548.4 | T12: =U12*$T$2 -> 3548387.1 | U12: =V12/DAY($C$1) -> 3548387.1 | V12: 110000000 | W12: =IFERROR(SUMIFS(data!$C:$C, data!$A:$A, $A12, data!$B:$B, $B12), 0) -> 391 | X12: =IFERROR(SUMIF(data!$B:$B, $B12, data!$D:$D), 0) -> 26034702 | Y12: =IF(W12>0,X12/W12,0) -> 66584.916 | Z12: =IFERROR(SUMIFS(data!$E:$E, data!$A:$A, $A12, data!$B:$B, $B12), 0) -> 237 | AA12: =IFERROR(SUMIF(data!$B:$B, $B12, data!$F:$F), 0) -> 36920401 | AB12: =IF(Z12>0,AA12/Z12,0) -> 155782.28 | AC12: =W12+Z12 -> 628 | AD12: =X12+AA12 -> 62955103 | AE12: =IF(AC12>0,AD12/AC12,0) -> 100246.98
A13: Trường Sa | B13: Phạm Nguyễn Ngọc Quý | C13: DSXC | D13: 175000 | E13: =AE13 -> 118051.55 | F13: {=IFERROR( ROUND( _xludf.LET( nt,$A13, nv,$B13, songay,DAY(EOMONTH($C$1,0)), doanhthungay,$I13, duan_nv,SUM_xlfn.IFS('Dự án T8'!$D:$D,'Dự án T8'!$A:$A,nt,'Dự án T8'!$B:$B,nv), duan_nt,SUM_xlfn.IFS('Dự án T8'!$D:$D,'Dự án T8'!$A:$A,nt), tyle,duan_nv/duan_nt, muc2_ngay,_xlfn.XLOOKUP(nt,'kpi nhà thuốc'!$B:$B,'kpi nhà thuốc'!$P:$P), muc3_ngay,_xlfn.XLOOKUP(nt,'kpi nhà thuốc'!$B:$B,'kpi nhà thuốc'!$T:$T), hangdiem1,_xlfn.XLOOKUP(nt,'kpi nhà thuốc'!$B:$B,'kpi nhà thuốc'!$I:$I), hangdiem2,_xlfn.XLOOKUP(nt,'kpi nhà thuốc'!$B:$B,'kpi nhà thuốc'!$N:$N), hangdiem3,_xlfn.XLOOKUP(nt,'kpi nhà thuốc'!$B:$B,'kpi nhà thuốc'!$R:$R), _xludf.SWITCH(TRUE, doanhthungay>=muc3_ngay,hangdiem3, doanhthungay>=muc2_ngay,hangdiem2, TRUE,hangdiem1 )/songay*tyle ), -3), 0)} -> 0 | G13: =IFERROR(SUMIF('Dự án T8'!$B:$B, $B13, 'Dự án T8'!$D:$D), 0) -> 905201.29 | H13: =Q13 -> 3800000 | I13: =(AD13/DAY($C$1)) -> 2338182.3 | J13: {=_xlfn.XLOOKUP(B13,'kpi nhà thuốc'!A:A,'kpi nhà thuốc'!F:F,(AD13/DAY($C$1))/U13)} -> 0.63029261 | K13: {=_xlfn.XLOOKUP( B13, 'kpi nhà thuốc'!A:A, 'kpi nhà thuốc'!G:G, IF( AND( OR(C13="DSXC",C13="DSCD"), G13>=F13),IF(AND(I13>=T13,E13>=D13),AD13*1.5%,IF(AND(I13>=T13,E13<D13),AD13*1.3%,IF(AND(I13>=S13,E13>=D13),AD13*1.3%,IF(AND(I13>=S13,E13<D13),AD13*1.1%,IF(AND(I13>=R13,E13>=D13),AD13*1.2%,IF(AND(I13>=R13,E13<D13),AD13*1%,"")))))),"" ) )} | L13: =IF(C13="DSTV","", IF(J13<0.6, 0.8, 1)) -> 1 | M13: =IFERROR(SUMIF('Dự án T8'!$B:$B, $B13, 'Dự án T8'!$M:$M)*$L13, 0) -> 0 | N13: =N(K13)+M13 -> 0 | O13: =CEILING(R13,100000) -> 3000000 | P13: =CEILING(S13,100000) -> 3400000 | Q13: =CEILING(T13,100000) -> 3800000 | R13: =U13*$R$2 -> 2967741.9 | S13: =U13*$S$2 -> 3338709.7 | T13: =U13*$T$2 -> 3709677.4 | U13: =V13/DAY($C$1) -> 3709677.4 | V13: 115000000 | W13: =IFERROR(SUMIFS(data!$C:$C, data!$A:$A, $A13, data!$B:$B, $B13), 0) -> 392 | X13: =IFERROR(SUMIF(data!$B:$B, $B13, data!$D:$D), 0) -> 28368700 | Y13: =IF(W13>0,X13/W13,0) -> 72369.133 | Z13: =IFERROR(SUMIFS(data!$E:$E, data!$A:$A, $A13, data!$B:$B, $B13), 0) -> 222 | AA13: =IFERROR(SUMIF(data!$B:$B, $B13, data!$F:$F), 0) -> 44114950 | AB13: =IF(Z13>0,AA13/Z13,0) -> 198715.99 | AC13: =W13+Z13 -> 614 | AD13: =X13+AA13 -> 72483650 | AE13: =IF(AC13>0,AD13/AC13,0) -> 118051.55
A14: Trường Sa | B14: Nguyễn Ngọc Anh Thư | C14: DSCD (TV) | D14: 150000 | E14: =AE14 -> 94223.931 | F14: {=IFERROR( ROUND( _xludf.LET( nt,$A14, nv,$B14, songay,DAY(EOMONTH($C$1,0)), doanhthungay,$I14, duan_nv,SUM_xlfn.IFS('Dự án T8'!$D:$D,'Dự án T8'!$A:$A,nt,'Dự án T8'!$B:$B,nv), duan_nt,SUM_xlfn.IFS('Dự án T8'!$D:$D,'Dự án T8'!$A:$A,nt), tyle,duan_nv/duan_nt, muc2_ngay,_xlfn.XLOOKUP(nt,'kpi nhà thuốc'!$B:$B,'kpi nhà thuốc'!$P:$P), muc3_ngay,_xlfn.XLOOKUP(nt,'kpi nhà thuốc'!$B:$B,'kpi nhà thuốc'!$T:$T), hangdiem1,_xlfn.XLOOKUP(nt,'kpi nhà thuốc'!$B:$B,'kpi nhà thuốc'!$I:$I), hangdiem2,_xlfn.XLOOKUP(nt,'kpi nhà thuốc'!$B:$B,'kpi nhà thuốc'!$N:$N), hangdiem3,_xlfn.XLOOKUP(nt,'kpi nhà thuốc'!$B:$B,'kpi nhà thuốc'!$R:$R), _xludf.SWITCH(TRUE, doanhthungay>=muc3_ngay,hangdiem3, doanhthungay>=muc2_ngay,hangdiem2, TRUE,hangdiem1 )/songay*tyle ), -3), 0)} -> 0 | G14: =IFERROR(SUMIF('Dự án T8'!$B:$B, $B14, 'Dự án T8'!$D:$D), 0) -> 438028.87 | H14: =Q14 -> 3100000 | I14: =(AD14/DAY($C$1)) -> 920962.94 | J14: {=_xlfn.XLOOKUP(B14,'kpi nhà thuốc'!A:A,'kpi nhà thuốc'!F:F,(AD14/DAY($C$1))/U14)} -> 0.30052475 | K14: {=_xlfn.XLOOKUP( B14, 'kpi nhà thuốc'!A:A, 'kpi nhà thuốc'!G:G, IF( AND( OR(C14="DSXC",C14="DSCD"), G14>=F14),IF(AND(I14>=T14,E14>=D14),AD14*1.5%,IF(AND(I14>=T14,E14<D14),AD14*1.3%,IF(AND(I14>=S14,E14>=D14),AD14*1.3%,IF(AND(I14>=S14,E14<D14),AD14*1.1%,IF(AND(I14>=R14,E14>=D14),AD14*1.2%,IF(AND(I14>=R14,E14<D14),AD14*1%,"")))))),"" ) )} | L14: =IF(C14="DSTV","", IF(J14<0.6, 0.8, 1)) -> 0.8 | M14: =IFERROR(SUMIF('Dự án T8'!$B:$B, $B14, 'Dự án T8'!$M:$M)*$L14, 0) -> 0 | N14: =N(K14)+M14 -> 0 | O14: =CEILING(R14,100000) -> 2500000 | P14: =CEILING(S14,100000) -> 2800000 | Q14: =CEILING(T14,100000) -> 3100000 | R14: =U14*$R$2 -> 2451612.9 | S14: =U14*$S$2 -> 2758064.5 | T14: =U14*$T$2 -> 3064516.1 | U14: =V14/DAY($C$1) -> 3064516.1 | V14: 95000000 | W14: =IFERROR(SUMIFS(data!$C:$C, data!$A:$A, $A14, data!$B:$B, $B14), 0) -> 160 | X14: =IFERROR(SUMIF(data!$B:$B, $B14, data!$D:$D), 0) -> 10020901 | Y14: =IF(W14>0,X14/W14,0) -> 62630.631 | Z14: =IFERROR(SUMIFS(data!$E:$E, data!$A:$A, $A14, data!$B:$B, $B14), 0) -> 143 | AA14: =IFERROR(SUMIF(data!$B:$B, $B14, data!$F:$F), 0) -> 18528950 | AB14: =IF(Z14>0,AA14/Z14,0) -> 129573.08 | AC14: =W14+Z14 -> 303 | AD14: =X14+AA14 -> 28549851 | AE14: =IF(AC14>0,AD14/AC14,0) -> 94223.931
A15: Trường Sa | B15: Trần Thị Kim Khánh | C15: DSXC | D15: 112000 | E15: =AE15 -> 174817.71 | F15: {=IFERROR( ROUND( _xludf.LET( nt,$A15, nv,$B15, songay,DAY(EOMONTH($C$1,0)), doanhthungay,$I15, duan_nv,SUM_xlfn.IFS('Dự án T8'!$D:$D,'Dự án T8'!$A:$A,nt,'Dự án T8'!$B:$B,nv), duan_nt,SUM_xlfn.IFS('Dự án T8'!$D:$D,'Dự án T8'!$A:$A,nt), tyle,duan_nv/duan_nt, muc2_ngay,_xlfn.XLOOKUP(nt,'kpi nhà thuốc'!$B:$B,'kpi nhà thuốc'!$P:$P), muc3_ngay,_xlfn.XLOOKUP(nt,'kpi nhà thuốc'!$B:$B,'kpi nhà thuốc'!$T:$T), hangdiem1,_xlfn.XLOOKUP(nt,'kpi nhà thuốc'!$B:$B,'kpi nhà thuốc'!$I:$I), hangdiem2,_xlfn.XLOOKUP(nt,'kpi nhà thuốc'!$B:$B,'kpi nhà thuốc'!$N:$N), hangdiem3,_xlfn.XLOOKUP(nt,'kpi nhà thuốc'!$B:$B,'kpi nhà thuốc'!$R:$R), _xludf.SWITCH(TRUE, doanhthungay>=muc3_ngay,hangdiem3, doanhthungay>=muc2_ngay,hangdiem2, TRUE,hangdiem1 )/songay*tyle ), -3), 0)} -> 0 | G15: =IFERROR(SUMIF('Dự án T8'!$B:$B, $B15, 'Dự án T8'!$D:$D), 0) -> 1995953.3 | H15: =Q15 -> 3800000 | I15: =(AD15/DAY($C$1)) -> 5317841.9 | J15: {=_xlfn.XLOOKUP(B15,'kpi nhà thuốc'!A:A,'kpi nhà thuốc'!F:F,(AD15/DAY($C$1))/U15)} -> 1.4335052 | K15: {=_xlfn.XLOOKUP( B15, 'kpi nhà thuốc'!A:A, 'kpi nhà thuốc'!G:G, IF( AND( OR(C15="DSXC",C15="DSCD"), G15>=F15),IF(AND(I15>=T15,E15>=D15),AD15*1.5%,IF(AND(I15>=T15,E15<D15),AD15*1.3%,IF(AND(I15>=S15,E15>=D15),AD15*1.3%,IF(AND(I15>=S15,E15<D15),AD15*1.1%,IF(AND(I15>=R15,E15>=D15),AD15*1.2%,IF(AND(I15>=R15,E15<D15),AD15*1%,"")))))),"" ) )} -> 2472796.5 | L15: =IF(C15="DSTV","", IF(J15<0.6, 0.8, 1)) -> 1 | M15: =IFERROR(SUMIF('Dự án T8'!$B:$B, $B15, 'Dự án T8'!$M:$M)*$L15, 0) -> 2800000 | N15: =N(K15)+M15 -> 5272796.5 | O15: =CEILING(R15,100000) -> 3000000 | P15: =CEILING(S15,100000) -> 3400000 | Q15: =CEILING(T15,100000) -> 3800000 | R15: =U15*$R$2 -> 2967741.9 | S15: =U15*$S$2 -> 3338709.7 | T15: =U15*$T$2 -> 3709677.4 | U15: =V15/DAY($C$1) -> 3709677.4 | V15: 115000000 | W15: =IFERROR(SUMIFS(data!$C:$C, data!$A:$A, $A15, data!$B:$B, $B15), 0) -> 511 | X15: =IFERROR(SUMIF(data!$B:$B, $B15, data!$D:$D), 0) -> 47529800 | Y15: =IF(W15>0,X15/W15,0) -> 93013.307 | Z15: =IFERROR(SUMIFS(data!$E:$E, data!$A:$A, $A15, data!$B:$B, $B15), 0) -> 432 | AA15: =IFERROR(SUMIF(data!$B:$B, $B15, data!$F:$F), 0) -> 117323300 | AB15: =IF(Z15>0,AA15/Z15,0) -> 271581.71 | AC15: =W15+Z15 -> 943 | AD15: =X15+AA15 -> 164853100 | AE15: =IF(AC15>0,AD15/AC15,0) -> 174817.71
A16: Trường Sa | B16: Ngô Trần Tuyết Vy | C16: DSXC | D16: 130000 | E16: =AE16 -> 100595.24 | F16: {=IFERROR( ROUND( _xludf.LET( nt,$A16, nv,$B16, songay,DAY(EOMONTH($C$1,0)), doanhthungay,$I16, duan_nv,SUM_xlfn.IFS('Dự án T8'!$D:$D,'Dự án T8'!$A:$A,nt,'Dự án T8'!$B:$B,nv), duan_nt,SUM_xlfn.IFS('Dự án T8'!$D:$D,'Dự án T8'!$A:$A,nt), tyle,duan_nv/duan_nt, muc2_ngay,_xlfn.XLOOKUP(nt,'kpi nhà thuốc'!$B:$B,'kpi nhà thuốc'!$P:$P), muc3_ngay,_xlfn.XLOOKUP(nt,'kpi nhà thuốc'!$B:$B,'kpi nhà thuốc'!$T:$T), hangdiem1,_xlfn.XLOOKUP(nt,'kpi nhà thuốc'!$B:$B,'kpi nhà thuốc'!$I:$I), hangdiem2,_xlfn.XLOOKUP(nt,'kpi nhà thuốc'!$B:$B,'kpi nhà thuốc'!$N:$N), hangdiem3,_xlfn.XLOOKUP(nt,'kpi nhà thuốc'!$B:$B,'kpi nhà thuốc'!$R:$R), _xludf.SWITCH(TRUE, doanhthungay>=muc3_ngay,hangdiem3, doanhthungay>=muc2_ngay,hangdiem2, TRUE,hangdiem1 )/songay*tyle ), -3), 0)} -> 0 | G16: =IFERROR(SUMIF('Dự án T8'!$B:$B, $B16, 'Dự án T8'!$D:$D), 0) -> 624747.58 | H16: =Q16 -> 3300000 | I16: =(AD16/DAY($C$1)) -> 1431048.4 | J16: {=_xlfn.XLOOKUP(B16,'kpi nhà thuốc'!A:A,'kpi nhà thuốc'!F:F,(AD16/DAY($C$1))/U16)} -> 0.443625 | K16: {=_xlfn.XLOOKUP( B16, 'kpi nhà thuốc'!A:A, 'kpi nhà thuốc'!G:G, IF( AND( OR(C16="DSXC",C16="DSCD"), G16>=F16),IF(AND(I16>=T16,E16>=D16),AD16*1.5%,IF(AND(I16>=T16,E16<D16),AD16*1.3%,IF(AND(I16>=S16,E16>=D16),AD16*1.3%,IF(AND(I16>=S16,E16<D16),AD16*1.1%,IF(AND(I16>=R16,E16>=D16),AD16*1.2%,IF(AND(I16>=R16,E16<D16),AD16*1%,"")))))),"" ) )} | L16: =IF(C16="DSTV","", IF(J16<0.6, 0.8, 1)) -> 0.8 | M16: =IFERROR(SUMIF('Dự án T8'!$B:$B, $B16, 'Dự án T8'!$M:$M)*$L16, 0) -> 0 | N16: =N(K16)+M16 -> 0 | O16: =CEILING(R16,100000) -> 2600000 | P16: =CEILING(S16,100000) -> 3000000 | Q16: =CEILING(T16,100000) -> 3300000 | R16: =U16*$R$2 -> 2580645.2 | S16: =U16*$S$2 -> 2903225.8 | T16: =U16*$T$2 -> 3225806.5 | U16: =V16/DAY($C$1) -> 3225806.5 | V16: 100000000 | W16: =IFERROR(SUMIFS(data!$C:$C, data!$A:$A, $A16, data!$B:$B, $B16), 0) -> 273 | X16: =IFERROR(SUMIF(data!$B:$B, $B16, data!$D:$D), 0) -> 16360400 | Y16: =IF(W16>0,X16/W16,0) -> 59928.205 | Z16: =IFERROR(SUMIFS(data!$E:$E, data!$A:$A, $A16, data!$B:$B, $B16), 0) -> 168 | AA16: =IFERROR(SUMIF(data!$B:$B, $B16, data!$F:$F), 0) -> 28002100 | AB16: =IF(Z16>0,AA16/Z16,0) -> 166679.17 | AC16: =W16+Z16 -> 441 | AD16: =X16+AA16 -> 44362500 | AE16: =IF(AC16>0,AD16/AC16,0) -> 100595.24
A17: Đỗ Quang Đẩu | B17: Phạm Thị Nghĩa Hương | C17: DSCD | D17: 232000 | E17: =AE17 -> 187973.64 | F17: {=IFERROR( ROUND( _xludf.LET( nt,$A17, nv,$B17, songay,DAY(EOMONTH($C$1,0)), doanhthungay,$I17, duan_nv,SUM_xlfn.IFS('Dự án T8'!$D:$D,'Dự án T8'!$A:$A,nt,'Dự án T8'!$B:$B,nv), duan_nt,SUM_xlfn.IFS('Dự án T8'!$D:$D,'Dự án T8'!$A:$A,nt), tyle,duan_nv/duan_nt, muc2_ngay,_xlfn.XLOOKUP(nt,'kpi nhà thuốc'!$B:$B,'kpi nhà thuốc'!$P:$P), muc3_ngay,_xlfn.XLOOKUP(nt,'kpi nhà thuốc'!$B:$B,'kpi nhà thuốc'!$T:$T), hangdiem1,_xlfn.XLOOKUP(nt,'kpi nhà thuốc'!$B:$B,'kpi nhà thuốc'!$I:$I), hangdiem2,_xlfn.XLOOKUP(nt,'kpi nhà thuốc'!$B:$B,'kpi nhà thuốc'!$N:$N), hangdiem3,_xlfn.XLOOKUP(nt,'kpi nhà thuốc'!$B:$B,'kpi nhà thuốc'!$R:$R), _xludf.SWITCH(TRUE, doanhthungay>=muc3_ngay,hangdiem3, doanhthungay>=muc2_ngay,hangdiem2, TRUE,hangdiem1 )/songay*tyle ), -3), 0)} -> 0 | G17: =IFERROR(SUMIF('Dự án T8'!$B:$B, $B17, 'Dự án T8'!$D:$D), 0) -> 367421.61 | H17: =Q17 -> 6500000 | I17: =(AD17/DAY($C$1)) -> 4232438.7 | J17: {=_xlfn.XLOOKUP(B17,'kpi nhà thuốc'!A:A,'kpi nhà thuốc'!F:F,(AD17/DAY($C$1))/U17)} -> 0.656028 | K17: {=_xlfn.XLOOKUP( B17, 'kpi nhà thuốc'!A:A, 'kpi nhà thuốc'!G:G, IF( AND( OR(C17="DSXC",C17="DSCD"), G17>=F17),IF(AND(I17>=T17,E17>=D17),AD17*1.5%,IF(AND(I17>=T17,E17<D17),AD17*1.3%,IF(AND(I17>=S17,E17>=D17),AD17*1.3%,IF(AND(I17>=S17,E17<D17),AD17*1.1%,IF(AND(I17>=R17,E17>=D17),AD17*1.2%,IF(AND(I17>=R17,E17<D17),AD17*1%,"")))))),"" ) )} | L17: =IF(C17="DSTV","", IF(J17<0.6, 0.8, 1)) -> 1 | M17: =IFERROR(SUMIF('Dự án T8'!$B:$B, $B17, 'Dự án T8'!$M:$M)*$L17, 0) -> 0 | N17: =N(K17)+M17 -> 0 | O17: =CEILING(R17,100000) -> 5200000 | P17: =CEILING(S17,100000) -> 5900000 | Q17: =CEILING(T17,100000) -> 6500000 | R17: =U17*$R$2 -> 5161290.3 | S17: =U17*$S$2 -> 5806451.6 | T17: =U17*$T$2 -> 6451612.9 | U17: =V17/DAY($C$1) -> 6451612.9 | V17: 200000000 | W17: =IFERROR(SUMIFS(data!$C:$C, data!$A:$A, $A17, data!$B:$B, $B17), 0) -> 553 | X17: =IFERROR(SUMIF(data!$B:$B, $B17, data!$D:$D), 0) -> 109865100 | Y17: =IF(W17>0,X17/W17,0) -> 198671.07 | Z17: =IFERROR(SUMIFS(data!$E:$E, data!$A:$A, $A17, data!$B:$B, $B17), 0) -> 145 | AA17: =IFERROR(SUMIF(data!$B:$B, $B17, data!$F:$F), 0) -> 21340500 | AB17: =IF(Z17>0,AA17/Z17,0) -> 147175.86 | AC17: =W17+Z17 -> 698 | AD17: =X17+AA17 -> 131205600 | AE17: =IF(AC17>0,AD17/AC17,0) -> 187973.64
A18: Đỗ Quang Đẩu | B18: Trần Thiên Phát | C18: DSCD | D18: 132000 | E18: =AE18 -> 204502.69 | F18: {=IFERROR( ROUND( _xludf.LET( nt,$A18, nv,$B18, songay,DAY(EOMONTH($C$1,0)), doanhthungay,$I18, duan_nv,SUM_xlfn.IFS('Dự án T8'!$D:$D,'Dự án T8'!$A:$A,nt,'Dự án T8'!$B:$B,nv), duan_nt,SUM_xlfn.IFS('Dự án T8'!$D:$D,'Dự án T8'!$A:$A,nt), tyle,duan_nv/duan_nt, muc2_ngay,_xlfn.XLOOKUP(nt,'kpi nhà thuốc'!$B:$B,'kpi nhà thuốc'!$P:$P), muc3_ngay,_xlfn.XLOOKUP(nt,'kpi nhà thuốc'!$B:$B,'kpi nhà thuốc'!$T:$T), hangdiem1,_xlfn.XLOOKUP(nt,'kpi nhà thuốc'!$B:$B,'kpi nhà thuốc'!$I:$I), hangdiem2,_xlfn.XLOOKUP(nt,'kpi nhà thuốc'!$B:$B,'kpi nhà thuốc'!$N:$N), hangdiem3,_xlfn.XLOOKUP(nt,'kpi nhà thuốc'!$B:$B,'kpi nhà thuốc'!$R:$R), _xludf.SWITCH(TRUE, doanhthungay>=muc3_ngay,hangdiem3, doanhthungay>=muc2_ngay,hangdiem2, TRUE,hangdiem1 )/songay*tyle ), -3), 0)} -> 0 | G18: =IFERROR(SUMIF('Dự án T8'!$B:$B, $B18, 'Dự án T8'!$D:$D), 0) -> 495122.84 | H18: =Q18 -> 6500000 | I18: =(AD18/DAY($C$1)) -> 4591415.2 | J18: {=_xlfn.XLOOKUP(B18,'kpi nhà thuốc'!A:A,'kpi nhà thuốc'!F:F,(AD18/DAY($C$1))/U18)} -> 0.71166935 | K18: {=_xlfn.XLOOKUP( B18, 'kpi nhà thuốc'!A:A, 'kpi nhà thuốc'!G:G, IF( AND( OR(C18="DSXC",C18="DSCD"), G18>=F18),IF(AND(I18>=T18,E18>=D18),AD18*1.5%,IF(AND(I18>=T18,E18<D18),AD18*1.3%,IF(AND(I18>=S18,E18>=D18),AD18*1.3%,IF(AND(I18>=S18,E18<D18),AD18*1.1%,IF(AND(I18>=R18,E18>=D18),AD18*1.2%,IF(AND(I18>=R18,E18<D18),AD18*1%,"")))))),"" ) )} | L18: =IF(C18="DSTV","", IF(J18<0.6, 0.8, 1)) -> 1 | M18: =IFERROR(SUMIF('Dự án T8'!$B:$B, $B18, 'Dự án T8'!$M:$M)*$L18, 0) -> 0 | N18: =N(K18)+M18 -> 0 | O18: =CEILING(R18,100000) -> 5200000 | P18: =CEILING(S18,100000) -> 5900000 | Q18: =CEILING(T18,100000) -> 6500000 | R18: =U18*$R$2 -> 5161290.3 | S18: =U18*$S$2 -> 5806451.6 | T18: =U18*$T$2 -> 6451612.9 | U18: =V18/DAY($C$1) -> 6451612.9 | V18: 200000000 | W18: =IFERROR(SUMIFS(data!$C:$C, data!$A:$A, $A18, data!$B:$B, $B18), 0) -> 558 | X18: =IFERROR(SUMIF(data!$B:$B, $B18, data!$D:$D), 0) -> 124498570 | Y18: =IF(W18>0,X18/W18,0) -> 223115.72 | Z18: =IFERROR(SUMIFS(data!$E:$E, data!$A:$A, $A18, data!$B:$B, $B18), 0) -> 138 | AA18: =IFERROR(SUMIF(data!$B:$B, $B18, data!$F:$F), 0) -> 17835300 | AB18: =IF(Z18>0,AA18/Z18,0) -> 129241.3 | AC18: =W18+Z18 -> 696 | AD18: =X18+AA18 -> 142333870 | AE18: =IF(AC18>0,AD18/AC18,0) -> 204502.69
... A25: Minh Châu | B25: Nguyễn Ngọc Thùy | C25: DSHV | D25: 100000 | E25: =AE25 -> 74966.352 | F25: {=IFERROR( ROUND( _xludf.LET( nt,$A25, nv,$B25, songay,DAY(EOMONTH($C$1,0)), doanhthungay,$I25, duan_nv,SUM_xlfn.IFS('Dự án T8'!$D:$D,'Dự án T8'!$A:$A,nt,'Dự án T8'!$B:$B,nv), duan_nt,SUM_xlfn.IFS('Dự án T8'!$D:$D,'Dự án T8'!$A:$A,nt), tyle,duan_nv/duan_nt, muc2_ngay,_xlfn.XLOOKUP(nt,'kpi nhà thuốc'!$B:$B,'kpi nhà thuốc'!$P:$P), muc3_ngay,_xlfn.XLOOKUP(nt,'kpi nhà thuốc'!$B:$B,'kpi nhà thuốc'!$T:$T), hangdiem1,_xlfn.XLOOKUP(nt,'kpi nhà thuốc'!$B:$B,'kpi nhà thuốc'!$I:$I), hangdiem2,_xlfn.XLOOKUP(nt,'kpi nhà thuốc'!$B:$B,'kpi nhà thuốc'!$N:$N), hangdiem3,_xlfn.XLOOKUP(nt,'kpi nhà thuốc'!$B:$B,'kpi nhà thuốc'!$R:$R), _xludf.SWITCH(TRUE, doanhthungay>=muc3_ngay,hangdiem3, doanhthungay>=muc2_ngay,hangdiem2, TRUE,hangdiem1 )/songay*tyle ), -3), 0)} -> 0 | G25: =IFERROR(SUMIF('Dự án T8'!$B:$B, $B25, 'Dự án T8'!$D:$D), 0) -> 168526.19 | H25: =Q25 -> 3300000 | I25: =(AD25/DAY($C$1)) -> 384504.84 | J25: {=_xlfn.XLOOKUP(B25,'kpi nhà thuốc'!A:A,'kpi nhà thuốc'!F:F,(AD25/DAY($C$1))/U25)} -> 0.1191965 | K25: {=_xlfn.XLOOKUP( B25, 'kpi nhà thuốc'!A:A, 'kpi nhà thuốc'!G:G, IF( AND( OR(C25="DSXC",C25="DSCD"), G25>=F25),IF(AND(I25>=T25,E25>=D25),AD25*1.5%,IF(AND(I25>=T25,E25<D25),AD25*1.3%,IF(AND(I25>=S25,E25>=D25),AD25*1.3%,IF(AND(I25>=S25,E25<D25),AD25*1.1%,IF(AND(I25>=R25,E25>=D25),AD25*1.2%,IF(AND(I25>=R25,E25<D25),AD25*1%,"")))))),"" ) )} | L25: =IF(C25="DSTV","", IF(J25<0.6, 0.8, 1)) -> 0.8 | M25: =IFERROR(SUMIF('Dự án T8'!$B:$B, $B25, 'Dự án T8'!$M:$M)*$L25, 0) -> 0 | N25: =N(K25)+M25 -> 0 | O25: =CEILING(R25,100000) -> 2600000 | P25: =CEILING(S25,100000) -> 3000000 | Q25: =CEILING(T25,100000) -> 3300000 | R25: =U25*$R$2 -> 2580645.2 | S25: =U25*$S$2 -> 2903225.8 | T25: =U25*$T$2 -> 3225806.5 | U25: =V25/DAY($C$1) -> 3225806.5 | V25: 100000000 | W25: =IFERROR(SUMIFS(data!$C:$C, data!$A:$A, $A25, data!$B:$B, $B25), 0) -> 142 | X25: =IFERROR(SUMIF(data!$B:$B, $B25, data!$D:$D), 0) -> 10203800 | Y25: =IF(W25>0,X25/W25,0) -> 71857.746 | Z25: =IFERROR(SUMIFS(data!$E:$E, data!$A:$A, $A25, data!$B:$B, $B25), 0) -> 17 | AA25: =IFERROR(SUMIF(data!$B:$B, $B25, data!$F:$F), 0) -> 1715850 | AB25: =IF(Z25>0,AA25/Z25,0) -> 100932.35 | AC25: =W25+Z25 -> 159 | AD25: =X25+AA25 -> 11919650 | AE25: =IF(AC25>0,AD25/AC25,0) -> 74966.352
A26: Minh Châu | B26: Trịnh Thị Phượng | C26: DSCD | E26: =AE26 -> 372693.79 | F26: {=IFERROR( ROUND( _xludf.LET( nt,$A26, nv,$B26, songay,DAY(EOMONTH($C$1,0)), doanhthungay,$I26, duan_nv,SUM_xlfn.IFS('Dự án T8'!$D:$D,'Dự án T8'!$A:$A,nt,'Dự án T8'!$B:$B,nv), duan_nt,SUM_xlfn.IFS('Dự án T8'!$D:$D,'Dự án T8'!$A:$A,nt), tyle,duan_nv/duan_nt, muc2_ngay,_xlfn.XLOOKUP(nt,'kpi nhà thuốc'!$B:$B,'kpi nhà thuốc'!$P:$P), muc3_ngay,_xlfn.XLOOKUP(nt,'kpi nhà thuốc'!$B:$B,'kpi nhà thuốc'!$T:$T), hangdiem1,_xlfn.XLOOKUP(nt,'kpi nhà thuốc'!$B:$B,'kpi nhà thuốc'!$I:$I), hangdiem2,_xlfn.XLOOKUP(nt,'kpi nhà thuốc'!$B:$B,'kpi nhà thuốc'!$N:$N), hangdiem3,_xlfn.XLOOKUP(nt,'kpi nhà thuốc'!$B:$B,'kpi nhà thuốc'!$R:$R), _xludf.SWITCH(TRUE, doanhthungay>=muc3_ngay,hangdiem3, doanhthungay>=muc2_ngay,hangdiem2, TRUE,hangdiem1 )/songay*tyle ), -3), 0)} -> 0 | G26: =IFERROR(SUMIF('Dự án T8'!$B:$B, $B26, 'Dự án T8'!$D:$D), 0) -> 1901524.1 | H26: =Q26 -> 3800000 | I26: =(AD26/DAY($C$1)) -> 3498512.6 | J26: {=_xlfn.XLOOKUP(B26,'kpi nhà thuốc'!A:A,'kpi nhà thuốc'!F:F,(AD26/DAY($C$1))/U26)} -> 0.94307732 | K26: {=_xlfn.XLOOKUP( B26, 'kpi nhà thuốc'!A:A, 'kpi nhà thuốc'!G:G, IF( AND( OR(C26="DSXC",C26="DSCD"), G26>=F26),IF(AND(I26>=T26,E26>=D26),AD26*1.5%,IF(AND(I26>=T26,E26<D26),AD26*1.3%,IF(AND(I26>=S26,E26>=D26),AD26*1.3%,IF(AND(I26>=S26,E26<D26),AD26*1.1%,IF(AND(I26>=R26,E26>=D26),AD26*1.2%,IF(AND(I26>=R26,E26<D26),AD26*1%,"")))))),"" ) )} -> 1409900.6 | L26: =IF(C26="DSTV","", IF(J26<0.6, 0.8, 1)) -> 1 | M26: =IFERROR(SUMIF('Dự án T8'!$B:$B, $B26, 'Dự án T8'!$M:$M)*$L26, 0) -> 2200000 | N26: =N(K26)+M26 -> 3609900.6 | O26: =CEILING(R26,100000) -> 3000000 | P26: =CEILING(S26,100000) -> 3400000 | Q26: =CEILING(T26,100000) -> 3800000 | R26: =U26*$R$2 -> 2967741.9 | S26: =U26*$S$2 -> 3338709.7 | T26: =U26*$T$2 -> 3709677.4 | U26: =V26/DAY($C$1) -> 3709677.4 | V26: 115000000 | W26: =IFERROR(SUMIFS(data!$C:$C, data!$A:$A, $A26, data!$B:$B, $B26), 0) -> 263 | X26: =IFERROR(SUMIF(data!$B:$B, $B26, data!$D:$D), 0) -> 79840952 | Y26: =IF(W26>0,X26/W26,0) -> 303577.76 | Z26: =IFERROR(SUMIFS(data!$E:$E, data!$A:$A, $A26, data!$B:$B, $B26), 0) -> 28 | AA26: =IFERROR(SUMIF(data!$B:$B, $B26, data!$F:$F), 0) -> 28612940 | AB26: =IF(Z26>0,AA26/Z26,0) -> 1021890.7 | AC26: =W26+Z26 -> 291 | AD26: =X26+AA26 -> 108453892 | AE26: =IF(AC26>0,AD26/AC26,0) -> 372693.79
A27: Nam Hòa | B27: Trần Thị Ánh Nguyệt | C27: DSCD | D27: 120000 | E27: =AE27 -> 105336.82 | F27: {=IFERROR( ROUND( _xludf.LET( nt,$A27, nv,$B27, songay,DAY(EOMONTH($C$1,0)), doanhthungay,$I27, duan_nv,SUM_xlfn.IFS('Dự án T8'!$D:$D,'Dự án T8'!$A:$A,nt,'Dự án T8'!$B:$B,nv), duan_nt,SUM_xlfn.IFS('Dự án T8'!$D:$D,'Dự án T8'!$A:$A,nt), tyle,duan_nv/duan_nt, muc2_ngay,_xlfn.XLOOKUP(nt,'kpi nhà thuốc'!$B:$B,'kpi nhà thuốc'!$P:$P), muc3_ngay,_xlfn.XLOOKUP(nt,'kpi nhà thuốc'!$B:$B,'kpi nhà thuốc'!$T:$T), hangdiem1,_xlfn.XLOOKUP(nt,'kpi nhà thuốc'!$B:$B,'kpi nhà thuốc'!$I:$I), hangdiem2,_xlfn.XLOOKUP(nt,'kpi nhà thuốc'!$B:$B,'kpi nhà thuốc'!$N:$N), hangdiem3,_xlfn.XLOOKUP(nt,'kpi nhà thuốc'!$B:$B,'kpi nhà thuốc'!$R:$R), _xludf.SWITCH(TRUE, doanhthungay>=muc3_ngay,hangdiem3, doanhthungay>=muc2_ngay,hangdiem2, TRUE,hangdiem1 )/songay*tyle ), -3), 0)} -> 0 | G27: =IFERROR(SUMIF('Dự án T8'!$B:$B, $B27, 'Dự án T8'!$D:$D), 0) -> 1377500.4 | H27: =Q27 -> 3300000 | I27: =(AD27/DAY($C$1)) -> 2823706.5 | J27: {=_xlfn.XLOOKUP(B27,'kpi nhà thuốc'!A:A,'kpi nhà thuốc'!F:F,(AD27/DAY($C$1))/U27)} -> 0.875349 | K27: {=_xlfn.XLOOKUP( B27, 'kpi nhà thuốc'!A:A, 'kpi nhà thuốc'!G:G, IF( AND( OR(C27="DSXC",C27="DSCD"), G27>=F27),IF(AND(I27>=T27,E27>=D27),AD27*1.5%,IF(AND(I27>=T27,E27<D27),AD27*1.3%,IF(AND(I27>=S27,E27>=D27),AD27*1.3%,IF(AND(I27>=S27,E27<D27),AD27*1.1%,IF(AND(I27>=R27,E27>=D27),AD27*1.2%,IF(AND(I27>=R27,E27<D27),AD27*1%,"")))))),"" ) )} -> 875349 | L27: =IF(C27="DSTV","", IF(J27<0.6, 0.8, 1)) -> 1 | M27: =IFERROR(SUMIF('Dự án T8'!$B:$B, $B27, 'Dự án T8'!$M:$M)*$L27, 0) -> 1600000 | N27: =N(K27)+M27 -> 2475349 | O27: =CEILING(R27,100000) -> 2600000 | P27: =CEILING(S27,100000) -> 3000000 | Q27: =CEILING(T27,100000) -> 3300000 | R27: =U27*$R$2 -> 2580645.2 | S27: =U27*$S$2 -> 2903225.8 | T27: =U27*$T$2 -> 3225806.5 | U27: =V27/DAY($C$1) -> 3225806.5 | V27: 100000000 | W27: =IFERROR(SUMIFS(data!$C:$C, data!$A:$A, $A27, data!$B:$B, $B27), 0) -> 637 | X27: =IFERROR(SUMIF(data!$B:$B, $B27, data!$D:$D), 0) -> 49451800 | Y27: =IF(W27>0,X27/W27,0) -> 77632.339 | Z27: =IFERROR(SUMIFS(data!$E:$E, data!$A:$A, $A27, data!$B:$B, $B27), 0) -> 194 | AA27: =IFERROR(SUMIF(data!$B:$B, $B27, data!$F:$F), 0) -> 38083100 | AB27: =IF(Z27>0,AA27/Z27,0) -> 196304.64 | AC27: =W27+Z27 -> 831 | AD27: =X27+AA27 -> 87534900 | AE27: =IF(AC27>0,AD27/AC27,0) -> 105336.82
A28: Nam Hòa | B28: Nguyễn Thị Huyền Trang | C28: DSXC (TV) | E28: =AE28 -> 125861.89 | F28: {=IFERROR( ROUND( _xludf.LET( nt,$A28, nv,$B28, songay,DAY(EOMONTH($C$1,0)), doanhthungay,$I28, duan_nv,SUM_xlfn.IFS('Dự án T8'!$D:$D,'Dự án T8'!$A:$A,nt,'Dự án T8'!$B:$B,nv), duan_nt,SUM_xlfn.IFS('Dự án T8'!$D:$D,'Dự án T8'!$A:$A,nt), tyle,duan_nv/duan_nt, muc2_ngay,_xlfn.XLOOKUP(nt,'kpi nhà thuốc'!$B:$B,'kpi nhà thuốc'!$P:$P), muc3_ngay,_xlfn.XLOOKUP(nt,'kpi nhà thuốc'!$B:$B,'kpi nhà thuốc'!$T:$T), hangdiem1,_xlfn.XLOOKUP(nt,'kpi nhà thuốc'!$B:$B,'kpi nhà thuốc'!$I:$I), hangdiem2,_xlfn.XLOOKUP(nt,'kpi nhà thuốc'!$B:$B,'kpi nhà thuốc'!$N:$N), hangdiem3,_xlfn.XLOOKUP(nt,'kpi nhà thuốc'!$B:$B,'kpi nhà thuốc'!$R:$R), _xludf.SWITCH(TRUE, doanhthungay>=muc3_ngay,hangdiem3, doanhthungay>=muc2_ngay,hangdiem2, TRUE,hangdiem1 )/songay*tyle ), -3), 0)} -> 0 | G28: =IFERROR(SUMIF('Dự án T8'!$B:$B, $B28, 'Dự án T8'!$D:$D), 0) -> 374797.45 | H28: =Q28 -> 2000000 | I28: =(AD28/DAY($C$1)) -> 1502222.6 | J28: {=_xlfn.XLOOKUP(B28,'kpi nhà thuốc'!A:A,'kpi nhà thuốc'!F:F,(AD28/DAY($C$1))/U28)} -> 0.77614833 | K28: {=_xlfn.XLOOKUP( B28, 'kpi nhà thuốc'!A:A, 'kpi nhà thuốc'!G:G, IF( AND( OR(C28="DSXC",C28="DSCD"), G28>=F28),IF(AND(I28>=T28,E28>=D28),AD28*1.5%,IF(AND(I28>=T28,E28<D28),AD28*1.3%,IF(AND(I28>=S28,E28>=D28),AD28*1.3%,IF(AND(I28>=S28,E28<D28),AD28*1.1%,IF(AND(I28>=R28,E28>=D28),AD28*1.2%,IF(AND(I28>=R28,E28<D28),AD28*1%,"")))))),"" ) )} | L28: =IF(C28="DSTV","", IF(J28<0.6, 0.8, 1)) -> 1 | M28: =IFERROR(SUMIF('Dự án T8'!$B:$B, $B28, 'Dự án T8'!$M:$M)*$L28, 0) -> 0 | N28: =N(K28)+M28 -> 0 | O28: =CEILING(R28,100000) -> 1600000 | P28: =CEILING(S28,100000) -> 1800000 | Q28: =CEILING(T28,100000) -> 2000000 | R28: =U28*$R$2 -> 1548387.1 | S28: =U28*$S$2 -> 1741935.5 | T28: =U28*$T$2 -> 1935483.9 | U28: =V28/DAY($C$1) -> 1935483.9 | V28: 60000000 | W28: =IFERROR(SUMIFS(data!$C:$C, data!$A:$A, $A28, data!$B:$B, $B28), 0) -> 254 | X28: =IFERROR(SUMIF(data!$B:$B, $B28, data!$D:$D), 0) -> 17434800 | Y28: =IF(W28>0,X28/W28,0) -> 68640.945 | Z28: =IFERROR(SUMIFS(data!$E:$E, data!$A:$A, $A28, data!$B:$B, $B28), 0) -> 116 | AA28: =IFERROR(SUMIF(data!$B:$B, $B28, data!$F:$F), 0) -> 29134100 | AB28: =IF(Z28>0,AA28/Z28,0) -> 251156.03 | AC28: =W28+Z28 -> 370 | AD28: =X28+AA28 -> 46568900 | AE28: =IF(AC28>0,AD28/AC28,0) -> 125861.89
A29: Nam Hòa | B29: Đỗ Thị Kim Tiến | C29: DSCD (TV) | E29: =AE29 -> 98967.105 | F29: {=IFERROR( ROUND( _xludf.LET( nt,$A29, nv,$B29, songay,DAY(EOMONTH($C$1,0)), doanhthungay,$I29, duan_nv,SUM_xlfn.IFS('Dự án T8'!$D:$D,'Dự án T8'!$A:$A,nt,'Dự án T8'!$B:$B,nv), duan_nt,SUM_xlfn.IFS('Dự án T8'!$D:$D,'Dự án T8'!$A:$A,nt), tyle,duan_nv/duan_nt, muc2_ngay,_xlfn.XLOOKUP(nt,'kpi nhà thuốc'!$B:$B,'kpi nhà thuốc'!$P:$P), muc3_ngay,_xlfn.XLOOKUP(nt,'kpi nhà thuốc'!$B:$B,'kpi nhà thuốc'!$T:$T), hangdiem1,_xlfn.XLOOKUP(nt,'kpi nhà thuốc'!$B:$B,'kpi nhà thuốc'!$I:$I), hangdiem2,_xlfn.XLOOKUP(nt,'kpi nhà thuốc'!$B:$B,'kpi nhà thuốc'!$N:$N), hangdiem3,_xlfn.XLOOKUP(nt,'kpi nhà thuốc'!$B:$B,'kpi nhà thuốc'!$R:$R), _xludf.SWITCH(TRUE, doanhthungay>=muc3_ngay,hangdiem3, doanhthungay>=muc2_ngay,hangdiem2, TRUE,hangdiem1 )/songay*tyle ), -3), 0)} -> 0 | G29: =IFERROR(SUMIF('Dự án T8'!$B:$B, $B29, 'Dự án T8'!$D:$D), 0) -> 236991.71 | H29: =Q29 -> 2000000 | I29: =(AD29/DAY($C$1)) -> 485258.06 | J29: {=_xlfn.XLOOKUP(B29,'kpi nhà thuốc'!A:A,'kpi nhà thuốc'!F:F,(AD29/DAY($C$1))/U29)} -> 0.25071667 | K29: {=_xlfn.XLOOKUP( B29, 'kpi nhà thuốc'!A:A, 'kpi nhà thuốc'!G:G, IF( AND( OR(C29="DSXC",C29="DSCD"), G29>=F29),IF(AND(I29>=T29,E29>=D29),AD29*1.5%,IF(AND(I29>=T29,E29<D29),AD29*1.3%,IF(AND(I29>=S29,E29>=D29),AD29*1.3%,IF(AND(I29>=S29,E29<D29),AD29*1.1%,IF(AND(I29>=R29,E29>=D29),AD29*1.2%,IF(AND(I29>=R29,E29<D29),AD29*1%,"")))))),"" ) )} | L29: =IF(C29="DSTV","", IF(J29<0.6, 0.8, 1)) -> 0.8 | M29: =IFERROR(SUMIF('Dự án T8'!$B:$B, $B29, 'Dự án T8'!$M:$M)*$L29, 0) -> 0 | N29: =N(K29)+M29 -> 0 | O29: =CEILING(R29,100000) -> 1600000 | P29: =CEILING(S29,100000) -> 1800000 | Q29: =CEILING(T29,100000) -> 2000000 | R29: =U29*$R$2 -> 1548387.1 | S29: =U29*$S$2 -> 1741935.5 | T29: =U29*$T$2 -> 1935483.9 | U29: =V29/DAY($C$1) -> 1935483.9 | V29: 60000000 | W29: =IFERROR(SUMIFS(data!$C:$C, data!$A:$A, $A29, data!$B:$B, $B29), 0) -> 120 | X29: =IFERROR(SUMIF(data!$B:$B, $B29, data!$D:$D), 0) -> 10038100 | Y29: =IF(W29>0,X29/W29,0) -> 83650.833 | Z29: =IFERROR(SUMIFS(data!$E:$E, data!$A:$A, $A29, data!$B:$B, $B29), 0) -> 32 | AA29: =IFERROR(SUMIF(data!$B:$B, $B29, data!$F:$F), 0) -> 5004900 | AB29: =IF(Z29>0,AA29/Z29,0) -> 156403.12 | AC29: =W29+Z29 -> 152 | AD29: =X29+AA29 -> 15043000 | AE29: =IF(AC29>0,AD29/AC29,0) -> 98967.105
A30: Nam Hòa | B30: Dương Thị Huỳnh Như | C30: DSCD (TV) | E30: =AE30 -> 84379.221 | F30: {=IFERROR( ROUND( _xludf.LET( nt,$A30, nv,$B30, songay,DAY(EOMONTH($C$1,0)), doanhthungay,$I30, duan_nv,SUM_xlfn.IFS('Dự án T8'!$D:$D,'Dự án T8'!$A:$A,nt,'Dự án T8'!$B:$B,nv), duan_nt,SUM_xlfn.IFS('Dự án T8'!$D:$D,'Dự án T8'!$A:$A,nt), tyle,duan_nv/duan_nt, muc2_ngay,_xlfn.XLOOKUP(nt,'kpi nhà thuốc'!$B:$B,'kpi nhà thuốc'!$P:$P), muc3_ngay,_xlfn.XLOOKUP(nt,'kpi nhà thuốc'!$B:$B,'kpi nhà thuốc'!$T:$T), hangdiem1,_xlfn.XLOOKUP(nt,'kpi nhà thuốc'!$B:$B,'kpi nhà thuốc'!$I:$I), hangdiem2,_xlfn.XLOOKUP(nt,'kpi nhà thuốc'!$B:$B,'kpi nhà thuốc'!$N:$N), hangdiem3,_xlfn.XLOOKUP(nt,'kpi nhà thuốc'!$B:$B,'kpi nhà thuốc'!$R:$R), _xludf.SWITCH(TRUE, doanhthungay>=muc3_ngay,hangdiem3, doanhthungay>=muc2_ngay,hangdiem2, TRUE,hangdiem1 )/songay*tyle ), -3), 0)} -> 0 | G30: =IFERROR(SUMIF('Dự án T8'!$B:$B, $B30, 'Dự án T8'!$D:$D), 0) -> 162390.39 | H30: =Q30 -> 1700000 | I30: =(AD30/DAY($C$1)) -> 419174.19 | J30: {=_xlfn.XLOOKUP(B30,'kpi nhà thuốc'!A:A,'kpi nhà thuốc'!F:F,(AD30/DAY($C$1))/U30)} -> 0.259888 | K30: {=_xlfn.XLOOKUP( B30, 'kpi nhà thuốc'!A:A, 'kpi nhà thuốc'!G:G, IF( AND( OR(C30="DSXC",C30="DSCD"), G30>=F30),IF(AND(I30>=T30,E30>=D30),AD30*1.5%,IF(AND(I30>=T30,E30<D30),AD30*1.3%,IF(AND(I30>=S30,E30>=D30),AD30*1.3%,IF(AND(I30>=S30,E30<D30),AD30*1.1%,IF(AND(I30>=R30,E30>=D30),AD30*1.2%,IF(AND(I30>=R30,E30<D30),AD30*1%,"")))))),"" ) )} | L30: =IF(C30="DSTV","", IF(J30<0.6, 0.8, 1)) -> 0.8 | M30: =IFERROR(SUMIF('Dự án T8'!$B:$B, $B30, 'Dự án T8'!$M:$M)*$L30, 0) -> 0 | N30: =N(K30)+M30 -> 0 | O30: =CEILING(R30,100000) -> 1300000 | P30: =CEILING(S30,100000) -> 1500000 | Q30: =CEILING(T30,100000) -> 1700000 | R30: =U30*$R$2 -> 1290322.6 | S30: =U30*$S$2 -> 1451612.9 | T30: =U30*$T$2 -> 1612903.2 | U30: =V30/DAY($C$1) -> 1612903.2 | V30: 50000000 | W30: =IFERROR(SUMIFS(data!$C:$C, data!$A:$A, $A30, data!$B:$B, $B30), 0) -> 126 | X30: =IFERROR(SUMIF(data!$B:$B, $B30, data!$D:$D), 0) -> 9970700 | Y30: =IF(W30>0,X30/W30,0) -> 79132.54 | Z30: =IFERROR(SUMIFS(data!$E:$E, data!$A:$A, $A30, data!$B:$B, $B30), 0) -> 28 | AA30: =IFERROR(SUMIF(data!$B:$B, $B30, data!$F:$F), 0) -> 3023700 | AB30: =IF(Z30>0,AA30/Z30,0) -> 107989.29 | AC30: =W30+Z30 -> 154 | AD30: =X30+AA30 -> 12994400 | AE30: =IF(AC30>0,AD30/AC30,0) -> 84379.221
A31: Nam Hòa | B31: Bùi Thị Thanh Thủy | C31: DSXC (TV) | E31: =AE31 -> 124619.89 | F31: {=IFERROR( ROUND( _xludf.LET( nt,$A31, nv,$B31, songay,DAY(EOMONTH($C$1,0)), doanhthungay,$I31, duan_nv,SUM_xlfn.IFS('Dự án T8'!$D:$D,'Dự án T8'!$A:$A,nt,'Dự án T8'!$B:$B,nv), duan_nt,SUM_xlfn.IFS('Dự án T8'!$D:$D,'Dự án T8'!$A:$A,nt), tyle,duan_nv/duan_nt, muc2_ngay,_xlfn.XLOOKUP(nt,'kpi nhà thuốc'!$B:$B,'kpi nhà thuốc'!$P:$P), muc3_ngay,_xlfn.XLOOKUP(nt,'kpi nhà thuốc'!$B:$B,'kpi nhà thuốc'!$T:$T), hangdiem1,_xlfn.XLOOKUP(nt,'kpi nhà thuốc'!$B:$B,'kpi nhà thuốc'!$I:$I), hangdiem2,_xlfn.XLOOKUP(nt,'kpi nhà thuốc'!$B:$B,'kpi nhà thuốc'!$N:$N), hangdiem3,_xlfn.XLOOKUP(nt,'kpi nhà thuốc'!$B:$B,'kpi nhà thuốc'!$R:$R), _xludf.SWITCH(TRUE, doanhthungay>=muc3_ngay,hangdiem3, doanhthungay>=muc2_ngay,hangdiem2, TRUE,hangdiem1 )/songay*tyle ), -3), 0)} -> 0 | G31: =IFERROR(SUMIF('Dự án T8'!$B:$B, $B31, 'Dự án T8'!$D:$D), 0) -> 548968.03 | H31: =Q31 -> 2000000 | I31: =(AD31/DAY($C$1)) -> 1591918.6 | J31: {=_xlfn.XLOOKUP(B31,'kpi nhà thuốc'!A:A,'kpi nhà thuốc'!F:F,(AD31/DAY($C$1))/U31)} -> 0.8224913 | K31: {=_xlfn.XLOOKUP( B31, 'kpi nhà thuốc'!A:A, 'kpi nhà thuốc'!G:G, IF( AND( OR(C31="DSXC",C31="DSCD"), G31>=F31),IF(AND(I31>=T31,E31>=D31),AD31*1.5%,IF(AND(I31>=T31,E31<D31),AD31*1.3%,IF(AND(I31>=S31,E31>=D31),AD31*1.3%,IF(AND(I31>=S31,E31<D31),AD31*1.1%,IF(AND(I31>=R31,E31>=D31),AD31*1.2%,IF(AND(I31>=R31,E31<D31),AD31*1%,"")))))),"" ) )} | L31: =IF(C31="DSTV","", IF(J31<0.6, 0.8, 1)) -> 1 | M31: =IFERROR(SUMIF('Dự án T8'!$B:$B, $B31, 'Dự án T8'!$M:$M)*$L31, 0) -> 0 | N31: =N(K31)+M31 -> 0 | O31: =CEILING(R31,100000) -> 1600000 | P31: =CEILING(S31,100000) -> 1800000 | Q31: =CEILING(T31,100000) -> 2000000 | R31: =U31*$R$2 -> 1548387.1 | S31: =U31*$S$2 -> 1741935.5 | T31: =U31*$T$2 -> 1935483.9 | U31: =V31/DAY($C$1) -> 1935483.9 | V31: 60000000 | W31: =IFERROR(SUMIFS(data!$C:$C, data!$A:$A, $A31, data!$B:$B, $B31), 0) -> 268 | X31: =IFERROR(SUMIF(data!$B:$B, $B31, data!$D:$D), 0) -> 18636328 | Y31: =IF(W31>0,X31/W31,0) -> 69538.537 | Z31: =IFERROR(SUMIFS(data!$E:$E, data!$A:$A, $A31, data!$B:$B, $B31), 0) -> 128 | AA31: =IFERROR(SUMIF(data!$B:$B, $B31, data!$F:$F), 0) -> 30713150 | AB31: =IF(Z31>0,AA31/Z31,0) -> 239946.48 | AC31: =W31+Z31 -> 396 | AD31: =X31+AA31 -> 49349478 | AE31: =IF(AC31>0,AD31/AC31,0) -> 124619.89
