Workbook

Sheet Bảng đánh giá
A1: Chi nhánh | B1: Doanh thu | C1: Chi phí | D1: Lợi nhuận | F1: Thành tích | G1: Lương | H1: Mặt bằng | I1: Ds chuyên môn | J1: Điện + nước | K1: Linh tinh | L1: SL đơn ONl | M1: Platform software (8k/1hd) | N1: Ebitda | O1: Ebitda - Team CNT (160M) | P1: Ebitda - Comp (300M)
A2: Trường Sa | D2: =B2-C2 -> 0 | E2: =IF(B2>0, D2/B2, 0) -> 0 | F2: Không đạt
A3: Đỗ Quang Đẩu | D3: =B3-C3 -> 0 | E3: =IF(B3>0, D3/B3, 0) -> 0 | F3: Không đạt
A4: Minh Châu | D4: =B4-C4 -> 0 | E4: =IF(B4>0, D4/B4, 0) -> 0 | F4: Không đạt
A5: Nam Hòa | D5: =B5-C5 -> 0 | E5: =IF(B5>0, D5/B5, 0) -> 0 | F5: Không đạt
A6: Nguyễn Chí Thanh | D6: =B6-C6 -> 0 | E6: =IF(B6>0, D6/B6, 0) -> 0 | F6: Không đạt
A7: Nguyễn Thị Thập | D7: =B7-C7 -> 0 | E7: =IF(B7>0, D7/B7, 0) -> 0 | F7: Không đạt
A8: Nguyễn Văn Quá | D8: =B8-C8 -> 0 | E8: =IF(B8>0, D8/B8, 0) -> 0 | F8: Không đạt
A9: Rạch Bùng Binh | D9: =B9-C9 -> 0 | E9: =IF(B9>0, D9/B9, 0) -> 0 | F9: Không đạt
A10: Lê Bình | D10: =B10-C10 -> 0 | E10: =IF(B10>0, D10/B10, 0) -> 0 | F10: Không đạt
A11: Đường Láng | D11: =B11-C11 -> 0 | E11: =IF(B11>0, D11/B11, 0) -> 0 | F11: Không đạt
A12: Hàng Bông | D12: =B12-C12 -> 0 | E12: =IF(B12>0, D12/B12, 0) -> 0 | F12: Không đạt
B13: =SUM(B2:B12) -> 0 | D13: =SUM(D2:D12) -> 0 | E13: =IF(B13>0, D13/B13, 0) -> 0

Sheet BẢNG LƯƠNG
E1: Tổng thời gian làm việc | G1: Quản lý và cửa hàng trưởng ghi nhận vào đây - công thức tổng tự động không cần chỉnh | R1: Quản lý ghi nhận | AK1: KPI trừ
A2: STT | B2: Chi nhánh | C2: Tên | D2: Hình thức | E2: Số giờ ca ngày | F2: Số giờ ca đêm | G2: Số giờ ca ngày | H2: Số giờ ca đêm ( chưa x 1.5 ) | I2: Số giờ tăng ca ngày ( x 1 ) | J2: Số ngày làm ngày | K2: Số ca làm đêm | L2: Ngày lễ hưởng lương ( x 1 ) | M2: Ghi ngày cụ thể | N2: Số ngày lễ vẫn đi làm | O2: Số giờ lễ ca ngày ( Đã x 3 ) | P2: Số giờ lễ ca đêm ( Đã x 3 ) | Q2: Ngày lễ vẫn đi làm (ghi ngày cụ thể) | R2: Số ngày công thực tế | S2: Số giờ tham gia đào tạo | T2: Số giờ nghỉ phép năm | U2: Ngày phép năm (ghi ngày cụ thể) | V2: Phụ cấp trách nhiệm (áp dụng CHT) | W2: Phụ cấp cửa hàng mới | X2: Phụ cấp sức khỏe ca đêm | Y2: Phụ cấp lưu động | Z2: Phụ cấp tăng cường vận hành | AA2: Thưởng dự án Mini KAT (Dược sĩ) | AB2: Thưởng dự án Mini KAT (Đại diện CHT nhận) | AC2: Thường Whatsapp | AD2: Phụ cấp quy trình/dự án | AE2: Thưởng KPI | AF2: Thưởng hàng điểm + Cắt liều | AG2: Thưởng hàng cận date | AH2: Thưởng chương trình Maps | AI2: Thưởng khác | AJ2: Total | AK2: Hàng hết date | AL2: Quy chế quy trình | AM2: HD App - Kiot | AN2: Ecom | AO2: Khác | AP2: Ghi chú
A3: 1 | B3: Trường Sa | C3: Hồ Thị Minh Hòa | D3: CHT | E3: =SUM(G3, I3, L3, O3, S3, T3) -> 31.69 | F3: =SUM(H3, P3) -> 0 | G3: =SUMIFS('Giờ công'!I:I, 'Giờ công'!G:G, B3, 'Giờ công'!H:H, C3) -> 15.69 | H3: =SUMIFS('Giờ công'!J:J, 'Giờ công'!G:G, B3, 'Giờ công'!H:H, C3) -> 0 | I3: =IF(ROW()=MATCH(C3, $C$1:$C$72, 0), IF(SUMIF($C$3:$C$72, C3, $R$3:$R$72)>=30, 16, IF(SUMIF($C$3:$C$72, C3, $R$3:$R$72)>=29, 8, "")), "") -> 16 | J3: =ROUND(G3/24, 1) -> 0.7 | K3: =SUMIFS('Ngày công'!I:I, 'Ngày công'!A:A, B3, 'Ngày công'!B:B, C3) -> 0 | N3: =SUMIFS('Tăng ca lễ'!M:M, 'Tăng ca lễ'!K:K, B3, 'Tăng ca lễ'!L:L, C3) -> 0 | O3: =IF(OR(D3="PT", D3="DSHV"), SUMIFS('Tăng ca lễ'!O:O, 'Tăng ca lễ'!K:K, B3, 'Tăng ca lễ'!L:L, C3)*2, SUMIFS('Tăng ca lễ'!O:O, 'Tăng ca lễ'!K:K, B3, 'Tăng ca lễ'!L:L, C3)*3) -> 0 | P3: =IF(OR(D3="PT", D3="DSHV"), SUMIFS('Tăng ca lễ'!P:P, 'Tăng ca lễ'!K:K, B3, 'Tăng ca lễ'!L:L, C3)*2, SUMIFS('Tăng ca lễ'!P:P, 'Tăng ca lễ'!K:K, B3, 'Tăng ca lễ'!L:L, C3)*3) -> 0 | R3: =SUMIFS('Ngày công'!M:M, 'Ngày công'!K:K, B3, 'Ngày công'!L:L, C3) -> 2 | S3: =SUMIFS('Công Đào tạo'!G:G, 'Công Đào tạo'!E:E, B3, 'Công Đào tạo'!F:F, C3) -> 0 | T3: 0 | V3: =IF(AND(ROW()=MATCH(C3, $C$1:$C$72, 0), OR(TRIM(D3)="CHT", TRIM(D3)="Q.CHT")), 500000/31*SUMIF($C$3:$C$72, C3, $R$3:$R$72), 0) -> 483870.97 | X3: =IF(C3="","", IF(TRIM(D3)="DSCD", MIN(1500000, ROUND(1500000/28*MIN(N(J3),28),0)), IF(AND(OR(TRIM(D3)="DSXC", TRIM(D3)="DSBC", TRIM(D3)="CHT", TRIM(D3)="DSTV", TRIM(D3)="Q.CHT"), N(H3)>=160), MIN(1500000, ROUND(1500000/28*MIN(N(K3),28),0)), 0))) -> 0 | AA3: =IF(ROW()=MATCH(C3, $C$1:$C$72, 0), IFERROR(VLOOKUP(C3, 'MiniKat - HN'!$A:$L, 12, FALSE), 0) + IFERROR(VLOOKUP(C3, 'MiniKat - HCM'!$A:$J, 10, FALSE), 0), 0) -> 225000 | AB3: =IF(OR(TRIM(D3)="CHT", TRIM(D3)="Q.CHT"), SUMIFS('MiniKat - HN'!$Y:$Y, 'MiniKat - HN'!$N:$N, B3) + SUMIFS('MiniKat - HCM'!$U:$U, 'MiniKat - HCM'!$M:$M, B3), 0) -> 300000 | AC3: =IF(ROW()=MATCH(C3, $C$1:$C$72, 0), SUMIFS(whatsapp!$D:$D, whatsapp!$A:$A, C3), 0) -> 0 | AD3: =SUMIFS('Dự án'!$C:$C, 'Dự án'!$A:$A, B3, 'Dự án'!$B:$B, C3) -> 0 | AE3: =SUMIFS(KPI!$C:$C, KPI!$A:$A, B3, KPI!$B:$B, C3) -> 0 | AF3: =SUMIFS('Thưởng CK'!$C:$C, 'Thưởng CK'!$A:$A, B3, 'Thưởng CK'!$B:$B, C3) -> 0 | AG3: =SUMIFS('Cận date'!$C:$C, 'Cận date'!$A:$A, B3, 'Cận date'!$B:$B, C3) -> 0 | AH3: =SUMIFS(Map!$D:$D, Map!$B:$B, B3, Map!$A:$A, C3) -> 0 | AI3: 0 | AJ3: =SUM(AK3:AO3) -> 0 | AK3: =SUMIFS('KPI trừ'!$C:$C, 'KPI trừ'!$A:$A, B3, 'KPI trừ'!$B:$B, C3) -> 0 | AL3: =SUMIFS('KPI trừ'!$D:$D, 'KPI trừ'!$A:$A, B3, 'KPI trừ'!$B:$B, C3) -> 0 | AM3: =SUMIFS('KPI trừ'!$E:$E, 'KPI trừ'!$A:$A, B3, 'KPI trừ'!$B:$B, C3) -> 0 | AN3: =SUMIFS('KPI trừ'!$F:$F, 'KPI trừ'!$A:$A, B3, 'KPI trừ'!$B:$B, C3) -> 0 | AO3: =SUMIFS('KPI trừ'!$G:$G, 'KPI trừ'!$A:$A, B3, 'KPI trừ'!$B:$B, C3) -> 0 | AP3: =IFERROR(INDEX('KPI trừ'!$H:$H, MATCH(1, ('KPI trừ'!$A:$A=B3)*('KPI trừ'!$B:$B=C3), 0)), "")
A4: 2 | B4: Trường Sa | C4: Nguyễn Trần Ngọc Phương | D4: Q.CHT | E4: =SUM(G4, I4, L4, O4, S4, T4) -> 186.64 | F4: =SUM(H4, P4) -> 28.38 | G4: =SUMIFS('Giờ công'!I:I, 'Giờ công'!G:G, B4, 'Giờ công'!H:H, C4) -> 186.64 | H4: =SUMIFS('Giờ công'!J:J, 'Giờ công'!G:G, B4, 'Giờ công'!H:H, C4) -> 28.38 | I4: =IF(ROW()=MATCH(C4, $C$1:$C$72, 0), IF(SUMIF($C$3:$C$72, C4, $R$3:$R$72)>=30, 16, IF(SUMIF($C$3:$C$72, C4, $R$3:$R$72)>=29, 8, "")), "") | J4: =ROUND(G4/24, 1) -> 7.8 | K4: =SUMIFS('Ngày công'!I:I, 'Ngày công'!A:A, B4, 'Ngày công'!B:B, C4) -> 3 | N4: =SUMIFS('Tăng ca lễ'!M:M, 'Tăng ca lễ'!K:K, B4, 'Tăng ca lễ'!L:L, C4) -> 0 | O4: =IF(OR(D4="PT", D4="DSHV"), SUMIFS('Tăng ca lễ'!O:O, 'Tăng ca lễ'!K:K, B4, 'Tăng ca lễ'!L:L, C4)*2, SUMIFS('Tăng ca lễ'!O:O, 'Tăng ca lễ'!K:K, B4, 'Tăng ca lễ'!L:L, C4)*3) -> 0 | P4: =IF(OR(D4="PT", D4="DSHV"), SUMIFS('Tăng ca lễ'!P:P, 'Tăng ca lễ'!K:K, B4, 'Tăng ca lễ'!L:L, C4)*2, SUMIFS('Tăng ca lễ'!P:P, 'Tăng ca lễ'!K:K, B4, 'Tăng ca lễ'!L:L, C4)*3) -> 0 | R4: =SUMIFS('Ngày công'!M:M, 'Ngày công'!K:K, B4, 'Ngày công'!L:L, C4) -> 26 | S4: =SUMIFS('Công Đào tạo'!G:G, 'Công Đào tạo'!E:E, B4, 'Công Đào tạo'!F:F, C4) -> 0 | T4: 0 | V4: =IF(AND(ROW()=MATCH(C4, $C$1:$C$72, 0), OR(TRIM(D4)="CHT", TRIM(D4)="Q.CHT")), 500000/31*SUMIF($C$3:$C$72, C4, $R$3:$R$72), 0) -> 435483.87 | X4: =IF(C4="","", IF(TRIM(D4)="DSCD", MIN(1500000, ROUND(1500000/28*MIN(N(J4),28),0)), IF(AND(OR(TRIM(D4)="DSXC", TRIM(D4)="DSBC", TRIM(D4)="CHT", TRIM(D4)="DSTV", TRIM(D4)="Q.CHT"), N(H4)>=160), MIN(1500000, ROUND(1500000/28*MIN(N(K4),28),0)), 0))) -> 0 | AA4: =IF(ROW()=MATCH(C4, $C$1:$C$72, 0), IFERROR(VLOOKUP(C4, 'MiniKat - HN'!$A:$L, 12, FALSE), 0) + IFERROR(VLOOKUP(C4, 'MiniKat - HCM'!$A:$J, 10, FALSE), 0), 0) -> 0 | AB4: =IF(OR(TRIM(D4)="CHT", TRIM(D4)="Q.CHT"), SUMIFS('MiniKat - HN'!$Y:$Y, 'MiniKat - HN'!$N:$N, B4) + SUMIFS('MiniKat - HCM'!$U:$U, 'MiniKat - HCM'!$M:$M, B4), 0) -> 300000 | AC4: =IF(ROW()=MATCH(C4, $C$1:$C$72, 0), SUMIFS(whatsapp!$D:$D, whatsapp!$A:$A, C4), 0) -> 0 | AD4: =SUMIFS('Dự án'!$C:$C, 'Dự án'!$A:$A, B4, 'Dự án'!$B:$B, C4) -> 0 | AE4: =SUMIFS(KPI!$C:$C, KPI!$A:$A, B4, KPI!$B:$B, C4) -> 0 | AF4: =SUMIFS('Thưởng CK'!$C:$C, 'Thưởng CK'!$A:$A, B4, 'Thưởng CK'!$B:$B, C4) -> 1280200 | AG4: =SUMIFS('Cận date'!$C:$C, 'Cận date'!$A:$A, B4, 'Cận date'!$B:$B, C4) -> 6601 | AH4: =SUMIFS(Map!$D:$D, Map!$B:$B, B4, Map!$A:$A, C4) -> 0 | AI4: 0 | AJ4: =SUM(AK4:AO4) -> 500000 | AK4: =SUMIFS('KPI trừ'!$C:$C, 'KPI trừ'!$A:$A, B4, 'KPI trừ'!$B:$B, C4) -> 0 | AL4: =SUMIFS('KPI trừ'!$D:$D, 'KPI trừ'!$A:$A, B4, 'KPI trừ'!$B:$B, C4) -> 0 | AM4: =SUMIFS('KPI trừ'!$E:$E, 'KPI trừ'!$A:$A, B4, 'KPI trừ'!$B:$B, C4) -> 0 | AN4: =SUMIFS('KPI trừ'!$F:$F, 'KPI trừ'!$A:$A, B4, 'KPI trừ'!$B:$B, C4) -> 0 | AO4: =SUMIFS('KPI trừ'!$G:$G, 'KPI trừ'!$A:$A, B4, 'KPI trừ'!$B:$B, C4) -> 500000 | AP4: =IFERROR(INDEX('KPI trừ'!$H:$H, MATCH(1, ('KPI trừ'!$A:$A=B4)*('KPI trừ'!$B:$B=C4), 0)), "")
A5: 3 | B5: Trường Sa | C5: Nguyễn Ngọc Anh Thư | D5: DSCD (TV) | E5: =SUM(G5, I5, L5, O5, S5, T5) -> 26.98 | F5: =SUM(H5, P5) -> 219.5 | G5: =SUMIFS('Giờ công'!I:I, 'Giờ công'!G:G, B5, 'Giờ công'!H:H, C5) -> 18.98 | H5: =SUMIFS('Giờ công'!J:J, 'Giờ công'!G:G, B5, 'Giờ công'!H:H, C5) -> 219.5 | I5: =IF(ROW()=MATCH(C5, $C$1:$C$72, 0), IF(SUMIF($C$3:$C$72, C5, $R$3:$R$72)>=30, 16, IF(SUMIF($C$3:$C$72, C5, $R$3:$R$72)>=29, 8, "")), "") -> 8 | J5: =ROUND(G5/24, 1) -> 0.8 | K5: =SUMIFS('Ngày công'!I:I, 'Ngày công'!A:A, B5, 'Ngày công'!B:B, C5) -> 27 | N5: =SUMIFS('Tăng ca lễ'!M:M, 'Tăng ca lễ'!K:K, B5, 'Tăng ca lễ'!L:L, C5) -> 0 | O5: =IF(OR(D5="PT", D5="DSHV"), SUMIFS('Tăng ca lễ'!O:O, 'Tăng ca lễ'!K:K, B5, 'Tăng ca lễ'!L:L, C5)*2, SUMIFS('Tăng ca lễ'!O:O, 'Tăng ca lễ'!K:K, B5, 'Tăng ca lễ'!L:L, C5)*3) -> 0 | P5: =IF(OR(D5="PT", D5="DSHV"), SUMIFS('Tăng ca lễ'!P:P, 'Tăng ca lễ'!K:K, B5, 'Tăng ca lễ'!L:L, C5)*2, SUMIFS('Tăng ca lễ'!P:P, 'Tăng ca lễ'!K:K, B5, 'Tăng ca lễ'!L:L, C5)*3) -> 0 | R5: =SUMIFS('Ngày công'!M:M, 'Ngày công'!K:K, B5, 'Ngày công'!L:L, C5) -> 29 | S5: =SUMIFS('Công Đào tạo'!G:G, 'Công Đào tạo'!E:E, B5, 'Công Đào tạo'!F:F, C5) -> 0 | T5: 0 | V5: =IF(AND(ROW()=MATCH(C5, $C$1:$C$72, 0), OR(TRIM(D5)="CHT", TRIM(D5)="Q.CHT")), 500000/31*SUMIF($C$3:$C$72, C5, $R$3:$R$72), 0) -> 0 | X5: =IF(C5="","", IF(TRIM(D5)="DSCD", MIN(1500000, ROUND(1500000/28*MIN(N(J5),28),0)), IF(AND(OR(TRIM(D5)="DSXC", TRIM(D5)="DSBC", TRIM(D5)="CHT", TRIM(D5)="DSTV", TRIM(D5)="Q.CHT"), N(H5)>=160), MIN(1500000, ROUND(1500000/28*MIN(N(K5),28),0)), 0))) -> 0 | AA5: =IF(ROW()=MATCH(C5, $C$1:$C$72, 0), IFERROR(VLOOKUP(C5, 'MiniKat - HN'!$A:$L, 12, FALSE), 0) + IFERROR(VLOOKUP(C5, 'MiniKat - HCM'!$A:$J, 10, FALSE), 0), 0) -> 0 | AB5: =IF(OR(TRIM(D5)="CHT", TRIM(D5)="Q.CHT"), SUMIFS('MiniKat - HN'!$Y:$Y, 'MiniKat - HN'!$N:$N, B5) + SUMIFS('MiniKat - HCM'!$U:$U, 'MiniKat - HCM'!$M:$M, B5), 0) -> 0 | AC5: =IF(ROW()=MATCH(C5, $C$1:$C$72, 0), SUMIFS(whatsapp!$D:$D, whatsapp!$A:$A, C5), 0) -> 0 | AD5: =SUMIFS('Dự án'!$C:$C, 'Dự án'!$A:$A, B5, 'Dự án'!$B:$B, C5) -> 0 | AE5: =SUMIFS(KPI!$C:$C, KPI!$A:$A, B5, KPI!$B:$B, C5) -> 0 | AF5: =SUMIFS('Thưởng CK'!$C:$C, 'Thưởng CK'!$A:$A, B5, 'Thưởng CK'!$B:$B, C5) -> 579960 | AG5: =SUMIFS('Cận date'!$C:$C, 'Cận date'!$A:$A, B5, 'Cận date'!$B:$B, C5) -> 7700 | AH5: =SUMIFS(Map!$D:$D, Map!$B:$B, B5, Map!$A:$A, C5) -> 0 | AI5: 0 | AJ5: =SUM(AK5:AO5) -> 0 | AK5: =SUMIFS('KPI trừ'!$C:$C, 'KPI trừ'!$A:$A, B5, 'KPI trừ'!$B:$B, C5) -> 0 | AL5: =SUMIFS('KPI trừ'!$D:$D, 'KPI trừ'!$A:$A, B5, 'KPI trừ'!$B:$B, C5) -> 0 | AM5: =SUMIFS('KPI trừ'!$E:$E, 'KPI trừ'!$A:$A, B5, 'KPI trừ'!$B:$B, C5) -> 0 | AN5: =SUMIFS('KPI trừ'!$F:$F, 'KPI trừ'!$A:$A, B5, 'KPI trừ'!$B:$B, C5) -> 0 | AO5: =SUMIFS('KPI trừ'!$G:$G, 'KPI trừ'!$A:$A, B5, 'KPI trừ'!$B:$B, C5) -> 0 | AP5: =IFERROR(INDEX('KPI trừ'!$H:$H, MATCH(1, ('KPI trừ'!$A:$A=B5)*('KPI trừ'!$B:$B=C5), 0)), "")
A6: 4 | B6: Trường Sa | C6: Trịnh Thị Phượng | D6: DSCD | E6: =SUM(G6, I6, L6, O6, S6, T6) -> 0.38 | F6: =SUM(H6, P6) -> 164.21 | G6: =SUMIFS('Giờ công'!I:I, 'Giờ công'!G:G, B6, 'Giờ công'!H:H, C6) -> 0.38 | H6: =SUMIFS('Giờ công'!J:J, 'Giờ công'!G:G, B6, 'Giờ công'!H:H, C6) -> 164.21 | I6: =IF(ROW()=MATCH(C6, $C$1:$C$72, 0), IF(SUMIF($C$3:$C$72, C6, $R$3:$R$72)>=30, 16, IF(SUMIF($C$3:$C$72, C6, $R$3:$R$72)>=29, 8, "")), "") | J6: =ROUND(G6/24, 1) -> 0 | K6: =SUMIFS('Ngày công'!I:I, 'Ngày công'!A:A, B6, 'Ngày công'!B:B, C6) -> 21 | N6: =SUMIFS('Tăng ca lễ'!M:M, 'Tăng ca lễ'!K:K, B6, 'Tăng ca lễ'!L:L, C6) -> 0 | O6: =IF(OR(D6="PT", D6="DSHV"), SUMIFS('Tăng ca lễ'!O:O, 'Tăng ca lễ'!K:K, B6, 'Tăng ca lễ'!L:L, C6)*2, SUMIFS('Tăng ca lễ'!O:O, 'Tăng ca lễ'!K:K, B6, 'Tăng ca lễ'!L:L, C6)*3) -> 0 | P6: =IF(OR(D6="PT", D6="DSHV"), SUMIFS('Tăng ca lễ'!P:P, 'Tăng ca lễ'!K:K, B6, 'Tăng ca lễ'!L:L, C6)*2, SUMIFS('Tăng ca lễ'!P:P, 'Tăng ca lễ'!K:K, B6, 'Tăng ca lễ'!L:L, C6)*3) -> 0 | R6: =SUMIFS('Ngày công'!M:M, 'Ngày công'!K:K, B6, 'Ngày công'!L:L, C6) -> 21 | S6: =SUMIFS('Công Đào tạo'!G:G, 'Công Đào tạo'!E:E, B6, 'Công Đào tạo'!F:F, C6) -> 0 | T6: 0 | V6: =IF(AND(ROW()=MATCH(C6, $C$1:$C$72, 0), OR(TRIM(D6)="CHT", TRIM(D6)="Q.CHT")), 500000/31*SUMIF($C$3:$C$72, C6, $R$3:$R$72), 0) -> 0 | X6: =IF(C6="","", IF(TRIM(D6)="DSCD", MIN(1500000, ROUND(1500000/28*MIN(N(J6),28),0)), IF(AND(OR(TRIM(D6)="DSXC", TRIM(D6)="DSBC", TRIM(D6)="CHT", TRIM(D6)="DSTV", TRIM(D6)="Q.CHT"), N(H6)>=160), MIN(1500000, ROUND(1500000/28*MIN(N(K6),28),0)), 0))) -> 0 | AA6: =IF(ROW()=MATCH(C6, $C$1:$C$72, 0), IFERROR(VLOOKUP(C6, 'MiniKat - HN'!$A:$L, 12, FALSE), 0) + IFERROR(VLOOKUP(C6, 'MiniKat - HCM'!$A:$J, 10, FALSE), 0), 0) -> 0 | AB6: =IF(OR(TRIM(D6)="CHT", TRIM(D6)="Q.CHT"), SUMIFS('MiniKat - HN'!$Y:$Y, 'MiniKat - HN'!$N:$N, B6) + SUMIFS('MiniKat - HCM'!$U:$U, 'MiniKat - HCM'!$M:$M, B6), 0) -> 0 | AC6: =IF(ROW()=MATCH(C6, $C$1:$C$72, 0), SUMIFS(whatsapp!$D:$D, whatsapp!$A:$A, C6), 0) -> 0 | AD6: =SUMIFS('Dự án'!$C:$C, 'Dự án'!$A:$A, B6, 'Dự án'!$B:$B, C6) -> 2200000 | AE6: =SUMIFS(KPI!$C:$C, KPI!$A:$A, B6, KPI!$B:$B, C6) -> 0 | AF6: =SUMIFS('Thưởng CK'!$C:$C, 'Thưởng CK'!$A:$A, B6, 'Thưởng CK'!$B:$B, C6) -> 3537750 | AG6: =SUMIFS('Cận date'!$C:$C, 'Cận date'!$A:$A, B6, 'Cận date'!$B:$B, C6) -> 11205 | AH6: =SUMIFS(Map!$D:$D, Map!$B:$B, B6, Map!$A:$A, C6) -> 0 | AI6: 0 | AJ6: =SUM(AK6:AO6) -> 0 | AK6: =SUMIFS('KPI trừ'!$C:$C, 'KPI trừ'!$A:$A, B6, 'KPI trừ'!$B:$B, C6) -> 0 | AL6: =SUMIFS('KPI trừ'!$D:$D, 'KPI trừ'!$A:$A, B6, 'KPI trừ'!$B:$B, C6) -> 0 | AM6: =SUMIFS('KPI trừ'!$E:$E, 'KPI trừ'!$A:$A, B6, 'KPI trừ'!$B:$B, C6) -> 0 | AN6: =SUMIFS('KPI trừ'!$F:$F, 'KPI trừ'!$A:$A, B6, 'KPI trừ'!$B:$B, C6) -> 0 | AO6: =SUMIFS('KPI trừ'!$G:$G, 'KPI trừ'!$A:$A, B6, 'KPI trừ'!$B:$B, C6) -> 0 | AP6: =IFERROR(INDEX('KPI trừ'!$H:$H, MATCH(1, ('KPI trừ'!$A:$A=B6)*('KPI trừ'!$B:$B=C6), 0)), "")
A7: 5 | B7: Trường Sa | C7: Ngô Trần Tuyết Vy | D7: DSXC | E7: =SUM(G7, I7, L7, O7, S7, T7) -> 66.26 | F7: =SUM(H7, P7) -> 23.12 | G7: =SUMIFS('Giờ công'!I:I, 'Giờ công'!G:G, B7, 'Giờ công'!H:H, C7) -> 66.26 | H7: =SUMIFS('Giờ công'!J:J, 'Giờ công'!G:G, B7, 'Giờ công'!H:H, C7) -> 23.12 | I7: =IF(ROW()=MATCH(C7, $C$1:$C$72, 0), IF(SUMIF($C$3:$C$72, C7, $R$3:$R$72)>=30, 16, IF(SUMIF($C$3:$C$72, C7, $R$3:$R$72)>=29, 8, "")), "") | J7: =ROUND(G7/24, 1) -> 2.8 | K7: =SUMIFS('Ngày công'!I:I, 'Ngày công'!A:A, B7, 'Ngày công'!B:B, C7) -> 3 | N7: =SUMIFS('Tăng ca lễ'!M:M, 'Tăng ca lễ'!K:K, B7, 'Tăng ca lễ'!L:L, C7) -> 0 | O7: =IF(OR(D7="PT", D7="DSHV"), SUMIFS('Tăng ca lễ'!O:O, 'Tăng ca lễ'!K:K, B7, 'Tăng ca lễ'!L:L, C7)*2, SUMIFS('Tăng ca lễ'!O:O, 'Tăng ca lễ'!K:K, B7, 'Tăng ca lễ'!L:L, C7)*3) -> 0 | P7: =IF(OR(D7="PT", D7="DSHV"), SUMIFS('Tăng ca lễ'!P:P, 'Tăng ca lễ'!K:K, B7, 'Tăng ca lễ'!L:L, C7)*2, SUMIFS('Tăng ca lễ'!P:P, 'Tăng ca lễ'!K:K, B7, 'Tăng ca lễ'!L:L, C7)*3) -> 0 | R7: =SUMIFS('Ngày công'!M:M, 'Ngày công'!K:K, B7, 'Ngày công'!L:L, C7) -> 11 | S7: =SUMIFS('Công Đào tạo'!G:G, 'Công Đào tạo'!E:E, B7, 'Công Đào tạo'!F:F, C7) -> 0 | T7: 0 | V7: =IF(AND(ROW()=MATCH(C7, $C$1:$C$72, 0), OR(TRIM(D7)="CHT", TRIM(D7)="Q.CHT")), 500000/31*SUMIF($C$3:$C$72, C7, $R$3:$R$72), 0) -> 0 | X7: =IF(C7="","", IF(TRIM(D7)="DSCD", MIN(1500000, ROUND(1500000/28*MIN(N(J7),28),0)), IF(AND(OR(TRIM(D7)="DSXC", TRIM(D7)="DSBC", TRIM(D7)="CHT", TRIM(D7)="DSTV", TRIM(D7)="Q.CHT"), N(H7)>=160), MIN(1500000, ROUND(1500000/28*MIN(N(K7),28),0)), 0))) -> 0 | AA7: =IF(ROW()=MATCH(C7, $C$1:$C$72, 0), IFERROR(VLOOKUP(C7, 'MiniKat - HN'!$A:$L, 12, FALSE), 0) + IFERROR(VLOOKUP(C7, 'MiniKat - HCM'!$A:$J, 10, FALSE), 0), 0) -> 0 | AB7: =IF(OR(TRIM(D7)="CHT", TRIM(D7)="Q.CHT"), SUMIFS('MiniKat - HN'!$Y:$Y, 'MiniKat - HN'!$N:$N, B7) + SUMIFS('MiniKat - HCM'!$U:$U, 'MiniKat - HCM'!$M:$M, B7), 0) -> 0 | AC7: =IF(ROW()=MATCH(C7, $C$1:$C$72, 0), SUMIFS(whatsapp!$D:$D, whatsapp!$A:$A, C7), 0) -> 0 | AD7: =SUMIFS('Dự án'!$C:$C, 'Dự án'!$A:$A, B7, 'Dự án'!$B:$B, C7) -> 0 | AE7: =SUMIFS(KPI!$C:$C, KPI!$A:$A, B7, KPI!$B:$B, C7) -> 0 | AF7: =SUMIFS('Thưởng CK'!$C:$C, 'Thưởng CK'!$A:$A, B7, 'Thưởng CK'!$B:$B, C7) -> 1011600 | AG7: =SUMIFS('Cận date'!$C:$C, 'Cận date'!$A:$A, B7, 'Cận date'!$B:$B, C7) -> 0 | AH7: =SUMIFS(Map!$D:$D, Map!$B:$B, B7, Map!$A:$A, C7) -> 0 | AI7: 0 | AJ7: =SUM(AK7:AO7) -> 0 | AK7: =SUMIFS('KPI trừ'!$C:$C, 'KPI trừ'!$A:$A, B7, 'KPI trừ'!$B:$B, C7) -> 0 | AL7: =SUMIFS('KPI trừ'!$D:$D, 'KPI trừ'!$A:$A, B7, 'KPI trừ'!$B:$B, C7) -> 0 | AM7: =SUMIFS('KPI trừ'!$E:$E, 'KPI trừ'!$A:$A, B7, 'KPI trừ'!$B:$B, C7) -> 0 | AN7: =SUMIFS('KPI trừ'!$F:$F, 'KPI trừ'!$A:$A, B7, 'KPI trừ'!$B:$B, C7) -> 0 | AO7: =SUMIFS('KPI trừ'!$G:$G, 'KPI trừ'!$A:$A, B7, 'KPI trừ'!$B:$B, C7) -> 0 | AP7: =IFERROR(INDEX('KPI trừ'!$H:$H, MATCH(1, ('KPI trừ'!$A:$A=B7)*('KPI trừ'!$B:$B=C7), 0)), "")
A8: 6 | B8: Trường Sa | C8: Phạm Nguyễn Ngọc Quý | D8: DSXC | E8: =SUM(G8, I8, L8, O8, S8, T8) -> 164.33 | F8: =SUM(H8, P8) -> 24.07 | G8: =SUMIFS('Giờ công'!I:I, 'Giờ công'!G:G, B8, 'Giờ công'!H:H, C8) -> 164.33 | H8: =SUMIFS('Giờ công'!J:J, 'Giờ công'!G:G, B8, 'Giờ công'!H:H, C8) -> 24.07 | I8: =IF(ROW()=MATCH(C8, $C$1:$C$72, 0), IF(SUMIF($C$3:$C$72, C8, $R$3:$R$72)>=30, 16, IF(SUMIF($C$3:$C$72, C8, $R$3:$R$72)>=29, 8, "")), "") | J8: =ROUND(G8/24, 1) -> 6.8 | K8: =SUMIFS('Ngày công'!I:I, 'Ngày công'!A:A, B8, 'Ngày công'!B:B, C8) -> 3 | N8: =SUMIFS('Tăng ca lễ'!M:M, 'Tăng ca lễ'!K:K, B8, 'Tăng ca lễ'!L:L, C8) -> 0 | O8: =IF(OR(D8="PT", D8="DSHV"), SUMIFS('Tăng ca lễ'!O:O, 'Tăng ca lễ'!K:K, B8, 'Tăng ca lễ'!L:L, C8)*2, SUMIFS('Tăng ca lễ'!O:O, 'Tăng ca lễ'!K:K, B8, 'Tăng ca lễ'!L:L, C8)*3) -> 0 | P8: =IF(OR(D8="PT", D8="DSHV"), SUMIFS('Tăng ca lễ'!P:P, 'Tăng ca lễ'!K:K, B8, 'Tăng ca lễ'!L:L, C8)*2, SUMIFS('Tăng ca lễ'!P:P, 'Tăng ca lễ'!K:K, B8, 'Tăng ca lễ'!L:L, C8)*3) -> 0 | R8: =SUMIFS('Ngày công'!M:M, 'Ngày công'!K:K, B8, 'Ngày công'!L:L, C8) -> 23 | S8: =SUMIFS('Công Đào tạo'!G:G, 'Công Đào tạo'!E:E, B8, 'Công Đào tạo'!F:F, C8) -> 0 | T8: 0 | V8: =IF(AND(ROW()=MATCH(C8, $C$1:$C$72, 0), OR(TRIM(D8)="CHT", TRIM(D8)="Q.CHT")), 500000/31*SUMIF($C$3:$C$72, C8, $R$3:$R$72), 0) -> 0 | X8: =IF(C8="","", IF(TRIM(D8)="DSCD", MIN(1500000, ROUND(1500000/28*MIN(N(J8),28),0)), IF(AND(OR(TRIM(D8)="DSXC", TRIM(D8)="DSBC", TRIM(D8)="CHT", TRIM(D8)="DSTV", TRIM(D8)="Q.CHT"), N(H8)>=160), MIN(1500000, ROUND(1500000/28*MIN(N(K8),28),0)), 0))) -> 0 | AA8: =IF(ROW()=MATCH(C8, $C$1:$C$72, 0), IFERROR(VLOOKUP(C8, 'MiniKat - HN'!$A:$L, 12, FALSE), 0) + IFERROR(VLOOKUP(C8, 'MiniKat - HCM'!$A:$J, 10, FALSE), 0), 0) -> 0 | AB8: =IF(OR(TRIM(D8)="CHT", TRIM(D8)="Q.CHT"), SUMIFS('MiniKat - HN'!$Y:$Y, 'MiniKat - HN'!$N:$N, B8) + SUMIFS('MiniKat - HCM'!$U:$U, 'MiniKat - HCM'!$M:$M, B8), 0) -> 0 | AC8: =IF(ROW()=MATCH(C8, $C$1:$C$72, 0), SUMIFS(whatsapp!$D:$D, whatsapp!$A:$A, C8), 0) -> 0 | AD8: =SUMIFS('Dự án'!$C:$C, 'Dự án'!$A:$A, B8, 'Dự án'!$B:$B, C8) -> 0 | AE8: =SUMIFS(KPI!$C:$C, KPI!$A:$A, B8, KPI!$B:$B, C8) -> 0 | AF8: =SUMIFS('Thưởng CK'!$C:$C, 'Thưởng CK'!$A:$A, B8, 'Thưởng CK'!$B:$B, C8) -> 1686900 | AG8: =SUMIFS('Cận date'!$C:$C, 'Cận date'!$A:$A, B8, 'Cận date'!$B:$B, C8) -> 18300 | AH8: =SUMIFS(Map!$D:$D, Map!$B:$B, B8, Map!$A:$A, C8) -> 0 | AI8: 0 | AJ8: =SUM(AK8:AO8) -> 0 | AK8: =SUMIFS('KPI trừ'!$C:$C, 'KPI trừ'!$A:$A, B8, 'KPI trừ'!$B:$B, C8) -> 0 | AL8: =SUMIFS('KPI trừ'!$D:$D, 'KPI trừ'!$A:$A, B8, 'KPI trừ'!$B:$B, C8) -> 0 | AM8: =SUMIFS('KPI trừ'!$E:$E, 'KPI trừ'!$A:$A, B8, 'KPI trừ'!$B:$B, C8) -> 0 | AN8: =SUMIFS('KPI trừ'!$F:$F, 'KPI trừ'!$A:$A, B8, 'KPI trừ'!$B:$B, C8) -> 0 | AO8: =SUMIFS('KPI trừ'!$G:$G, 'KPI trừ'!$A:$A, B8, 'KPI trừ'!$B:$B, C8) -> 0 | AP8: =IFERROR(INDEX('KPI trừ'!$H:$H, MATCH(1, ('KPI trừ'!$A:$A=B8)*('KPI trừ'!$B:$B=C8), 0)), "")
A9: 7 | B9: Trường Sa | C9: Trần Thị Kim Khánh | D9: DSXC | E9: =SUM(G9, I9, L9, O9, S9, T9) -> 253.43 | F9: =SUM(H9, P9) -> 31.43 | G9: =SUMIFS('Giờ công'!I:I, 'Giờ công'!G:G, B9, 'Giờ công'!H:H, C9) -> 245.43 | H9: =SUMIFS('Giờ công'!J:J, 'Giờ công'!G:G, B9, 'Giờ công'!H:H, C9) -> 31.43 | I9: =IF(ROW()=MATCH(C9, $C$1:$C$72, 0), IF(SUMIF($C$3:$C$72, C9, $R$3:$R$72)>=30, 16, IF(SUMIF($C$3:$C$72, C9, $R$3:$R$72)>=29, 8, "")), "") -> 8 | J9: =ROUND(G9/24, 1) -> 10.2 | K9: =SUMIFS('Ngày công'!I:I, 'Ngày công'!A:A, B9, 'Ngày công'!B:B, C9) -> 4 | N9: =SUMIFS('Tăng ca lễ'!M:M, 'Tăng ca lễ'!K:K, B9, 'Tăng ca lễ'!L:L, C9) -> 0 | O9: =IF(OR(D9="PT", D9="DSHV"), SUMIFS('Tăng ca lễ'!O:O, 'Tăng ca lễ'!K:K, B9, 'Tăng ca lễ'!L:L, C9)*2, SUMIFS('Tăng ca lễ'!O:O, 'Tăng ca lễ'!K:K, B9, 'Tăng ca lễ'!L:L, C9)*3) -> 0 | P9: =IF(OR(D9="PT", D9="DSHV"), SUMIFS('Tăng ca lễ'!P:P, 'Tăng ca lễ'!K:K, B9, 'Tăng ca lễ'!L:L, C9)*2, SUMIFS('Tăng ca lễ'!P:P, 'Tăng ca lễ'!K:K, B9, 'Tăng ca lễ'!L:L, C9)*3) -> 0 | R9: =SUMIFS('Ngày công'!M:M, 'Ngày công'!K:K, B9, 'Ngày công'!L:L, C9) -> 29 | S9: =SUMIFS('Công Đào tạo'!G:G, 'Công Đào tạo'!E:E, B9, 'Công Đào tạo'!F:F, C9) -> 0 | T9: 0 | V9: =IF(AND(ROW()=MATCH(C9, $C$1:$C$72, 0), OR(TRIM(D9)="CHT", TRIM(D9)="Q.CHT")), 500000/31*SUMIF($C$3:$C$72, C9, $R$3:$R$72), 0) -> 0 | X9: =IF(C9="","", IF(TRIM(D9)="DSCD", MIN(1500000, ROUND(1500000/28*MIN(N(J9),28),0)), IF(AND(OR(TRIM(D9)="DSXC", TRIM(D9)="DSBC", TRIM(D9)="CHT", TRIM(D9)="DSTV", TRIM(D9)="Q.CHT"), N(H9)>=160), MIN(1500000, ROUND(1500000/28*MIN(N(K9),28),0)), 0))) -> 0 | AA9: =IF(ROW()=MATCH(C9, $C$1:$C$72, 0), IFERROR(VLOOKUP(C9, 'MiniKat - HN'!$A:$L, 12, FALSE), 0) + IFERROR(VLOOKUP(C9, 'MiniKat - HCM'!$A:$J, 10, FALSE), 0), 0) -> 0 | AB9: =IF(OR(TRIM(D9)="CHT", TRIM(D9)="Q.CHT"), SUMIFS('MiniKat - HN'!$Y:$Y, 'MiniKat - HN'!$N:$N, B9) + SUMIFS('MiniKat - HCM'!$U:$U, 'MiniKat - HCM'!$M:$M, B9), 0) -> 0 | AC9: =IF(ROW()=MATCH(C9, $C$1:$C$72, 0), SUMIFS(whatsapp!$D:$D, whatsapp!$A:$A, C9), 0) -> 0 | AD9: =SUMIFS('Dự án'!$C:$C, 'Dự án'!$A:$A, B9, 'Dự án'!$B:$B, C9) -> 2800000 | AE9: =SUMIFS(KPI!$C:$C, KPI!$A:$A, B9, KPI!$B:$B, C9) -> 2472796 | AF9: =SUMIFS('Thưởng CK'!$C:$C, 'Thưởng CK'!$A:$A, B9, 'Thưởng CK'!$B:$B, C9) -> 3808150 | AG9: =SUMIFS('Cận date'!$C:$C, 'Cận date'!$A:$A, B9, 'Cận date'!$B:$B, C9) -> 46851 | AH9: =SUMIFS(Map!$D:$D, Map!$B:$B, B9, Map!$A:$A, C9) -> 0 | AI9: 0 | AJ9: =SUM(AK9:AO9) -> 0 | AK9: =SUMIFS('KPI trừ'!$C:$C, 'KPI trừ'!$A:$A, B9, 'KPI trừ'!$B:$B, C9) -> 0 | AL9: =SUMIFS('KPI trừ'!$D:$D, 'KPI trừ'!$A:$A, B9, 'KPI trừ'!$B:$B, C9) -> 0 | AM9: =SUMIFS('KPI trừ'!$E:$E, 'KPI trừ'!$A:$A, B9, 'KPI trừ'!$B:$B, C9) -> 0 | AN9: =SUMIFS('KPI trừ'!$F:$F, 'KPI trừ'!$A:$A, B9, 'KPI trừ'!$B:$B, C9) -> 0 | AO9: =SUMIFS('KPI trừ'!$G:$G, 'KPI trừ'!$A:$A, B9, 'KPI trừ'!$B:$B, C9) -> 0 | AP9: =IFERROR(INDEX('KPI trừ'!$H:$H, MATCH(1, ('KPI trừ'!$A:$A=B9)*('KPI trừ'!$B:$B=C9), 0)), "")
A10: 8 | B10: Đỗ Quang Đẩu | C10: Ngô Thị Thanh Thắm | D10: CHT | E10: =SUM(G10, I10, L10, O10, S10, T10) -> 183.01 | F10: =SUM(H10, P10) -> 0 | G10: =SUMIFS('Giờ công'!I:I, 'Giờ công'!G:G, B10, 'Giờ công'!H:H, C10) -> 183.01 | H10: =SUMIFS('Giờ công'!J:J, 'Giờ công'!G:G, B10, 'Giờ công'!H:H, C10) -> 0 | I10: =IF(ROW()=MATCH(C10, $C$1:$C$72, 0), IF(SUMIF($C$3:$C$72, C10, $R$3:$R$72)>=30, 16, IF(SUMIF($C$3:$C$72, C10, $R$3:$R$72)>=29, 8, "")), "") | J10: =ROUND(G10/24, 1) -> 7.6 | K10: =SUMIFS('Ngày công'!I:I, 'Ngày công'!A:A, B10, 'Ngày công'!B:B, C10) -> 0 | N10: =SUMIFS('Tăng ca lễ'!M:M, 'Tăng ca lễ'!K:K, B10, 'Tăng ca lễ'!L:L, C10) -> 0 | O10: =IF(OR(D10="PT", D10="DSHV"), SUMIFS('Tăng ca lễ'!O:O, 'Tăng ca lễ'!K:K, B10, 'Tăng ca lễ'!L:L, C10)*2, SUMIFS('Tăng ca lễ'!O:O, 'Tăng ca lễ'!K:K, B10, 'Tăng ca lễ'!L:L, C10)*3) -> 0 | P10: =IF(OR(D10="PT", D10="DSHV"), SUMIFS('Tăng ca lễ'!P:P, 'Tăng ca lễ'!K:K, B10, 'Tăng ca lễ'!L:L, C10)*2, SUMIFS('Tăng ca lễ'!P:P, 'Tăng ca lễ'!K:K, B10, 'Tăng ca lễ'!L:L, C10)*3) -> 0 | R10: =SUMIFS('Ngày công'!M:M, 'Ngày công'!K:K, B10, 'Ngày công'!L:L, C10) -> 23 | S10: =SUMIFS('Công Đào tạo'!G:G, 'Công Đào tạo'!E:E, B10, 'Công Đào tạo'!F:F, C10) -> 0 | T10: 0 | V10: =IF(AND(ROW()=MATCH(C10, $C$1:$C$72, 0), OR(TRIM(D10)="CHT", TRIM(D10)="Q.CHT")), 500000/31*SUMIF($C$3:$C$72, C10, $R$3:$R$72), 0) -> 370967.74 | X10: =IF(C10="","", IF(TRIM(D10)="DSCD", MIN(1500000, ROUND(1500000/28*MIN(N(J10),28),0)), IF(AND(OR(TRIM(D10)="DSXC", TRIM(D10)="DSBC", TRIM(D10)="CHT", TRIM(D10)="DSTV", TRIM(D10)="Q.CHT"), N(H10)>=160), MIN(1500000, ROUND(1500000/28*MIN(N(K10),28),0)), 0))) -> 0 | AA10: =IF(ROW()=MATCH(C10, $C$1:$C$72, 0), IFERROR(VLOOKUP(C10, 'MiniKat - HN'!$A:$L, 12, FALSE), 0) + IFERROR(VLOOKUP(C10, 'MiniKat - HCM'!$A:$J, 10, FALSE), 0), 0) -> 0 | AB10: =IF(OR(TRIM(D10)="CHT", TRIM(D10)="Q.CHT"), SUMIFS('MiniKat - HN'!$Y:$Y, 'MiniKat - HN'!$N:$N, B10) + SUMIFS('MiniKat - HCM'!$U:$U, 'MiniKat - HCM'!$M:$M, B10), 0) -> 0 | AC10: =IF(ROW()=MATCH(C10, $C$1:$C$72, 0), SUMIFS(whatsapp!$D:$D, whatsapp!$A:$A, C10), 0) -> 2681852 | AD10: =SUMIFS('Dự án'!$C:$C, 'Dự án'!$A:$A, B10, 'Dự án'!$B:$B, C10) -> 0 | AE10: =SUMIFS(KPI!$C:$C, KPI!$A:$A, B10, KPI!$B:$B, C10) -> 0 | AF10: =SUMIFS('Thưởng CK'!$C:$C, 'Thưởng CK'!$A:$A, B10, 'Thưởng CK'!$B:$B, C10) -> 688400 | AG10: =SUMIFS('Cận date'!$C:$C, 'Cận date'!$A:$A, B10, 'Cận date'!$B:$B, C10) -> 14067 | AH10: =SUMIFS(Map!$D:$D, Map!$B:$B, B10, Map!$A:$A, C10) -> 0 | AI10: 0 | AJ10: =SUM(AK10:AO10) -> 0 | AK10: =SUMIFS('KPI trừ'!$C:$C, 'KPI trừ'!$A:$A, B10, 'KPI trừ'!$B:$B, C10) -> 0 | AL10: =SUMIFS('KPI trừ'!$D:$D, 'KPI trừ'!$A:$A, B10, 'KPI trừ'!$B:$B, C10) -> 0 | AM10: =SUMIFS('KPI trừ'!$E:$E, 'KPI trừ'!$A:$A, B10, 'KPI trừ'!$B:$B, C10) -> 0 | AN10: =SUMIFS('KPI trừ'!$F:$F, 'KPI trừ'!$A:$A, B10, 'KPI trừ'!$B:$B, C10) -> 0 | AO10: =SUMIFS('KPI trừ'!$G:$G, 'KPI trừ'!$A:$A, B10, 'KPI trừ'!$B:$B, C10) -> 0 | AP10: =IFERROR(INDEX('KPI trừ'!$H:$H, MATCH(1, ('KPI trừ'!$A:$A=B10)*('KPI trừ'!$B:$B=C10), 0)), "")
A11: 9 | B11: Đỗ Quang Đẩu | C11: Dương Thị Huỳnh Như | D11: DSCD (TV) | E11: =SUM(G11, I11, L11, O11, S11, T11) -> 32.49 | F11: =SUM(H11, P11) -> 0 | G11: =SUMIFS('Giờ công'!I:I, 'Giờ công'!G:G, B11, 'Giờ công'!H:H, C11) -> 32.49 | H11: =SUMIFS('Giờ công'!J:J, 'Giờ công'!G:G, B11, 'Giờ công'!H:H, C11) -> 0 | I11: =IF(ROW()=MATCH(C11, $C$1:$C$72, 0), IF(SUMIF($C$3:$C$72, C11, $R$3:$R$72)>=30, 16, IF(SUMIF($C$3:$C$72, C11, $R$3:$R$72)>=29, 8, "")), "") | J11: =ROUND(G11/24, 1) -> 1.4 | K11: =SUMIFS('Ngày công'!I:I, 'Ngày công'!A:A, B11, 'Ngày công'!B:B, C11) -> 0 | N11: =SUMIFS('Tăng ca lễ'!M:M, 'Tăng ca lễ'!K:K, B11, 'Tăng ca lễ'!L:L, C11) -> 0 | O11: =IF(OR(D11="PT", D11="DSHV"), SUMIFS('Tăng ca lễ'!O:O, 'Tăng ca lễ'!K:K, B11, 'Tăng ca lễ'!L:L, C11)*2, SUMIFS('Tăng ca lễ'!O:O, 'Tăng ca lễ'!K:K, B11, 'Tăng ca lễ'!L:L, C11)*3) -> 0 | P11: =IF(OR(D11="PT", D11="DSHV"), SUMIFS('Tăng ca lễ'!P:P, 'Tăng ca lễ'!K:K, B11, 'Tăng ca lễ'!L:L, C11)*2, SUMIFS('Tăng ca lễ'!P:P, 'Tăng ca lễ'!K:K, B11, 'Tăng ca lễ'!L:L, C11)*3) -> 0 | R11: =SUMIFS('Ngày công'!M:M, 'Ngày công'!K:K, B11, 'Ngày công'!L:L, C11) -> 4 | S11: =SUMIFS('Công Đào tạo'!G:G, 'Công Đào tạo'!E:E, B11, 'Công Đào tạo'!F:F, C11) -> 0 | T11: 0 | V11: =IF(AND(ROW()=MATCH(C11, $C$1:$C$72, 0), OR(TRIM(D11)="CHT", TRIM(D11)="Q.CHT")), 500000/31*SUMIF($C$3:$C$72, C11, $R$3:$R$72), 0) -> 0 | X11: =IF(C11="","", IF(TRIM(D11)="DSCD", MIN(1500000, ROUND(1500000/28*MIN(N(J11),28),0)), IF(AND(OR(TRIM(D11)="DSXC", TRIM(D11)="DSBC", TRIM(D11)="CHT", TRIM(D11)="DSTV", TRIM(D11)="Q.CHT"), N(H11)>=160), MIN(1500000, ROUND(1500000/28*MIN(N(K11),28),0)), 0))) -> 0 | AA11: =IF(ROW()=MATCH(C11, $C$1:$C$72, 0), IFERROR(VLOOKUP(C11, 'MiniKat - HN'!$A:$L, 12, FALSE), 0) + IFERROR(VLOOKUP(C11, 'MiniKat - HCM'!$A:$J, 10, FALSE), 0), 0) -> 0 | AB11: =IF(OR(TRIM(D11)="CHT", TRIM(D11)="Q.CHT"), SUMIFS('MiniKat - HN'!$Y:$Y, 'MiniKat - HN'!$N:$N, B11) + SUMIFS('MiniKat - HCM'!$U:$U, 'MiniKat - HCM'!$M:$M, B11), 0) -> 0 | AC11: =IF(ROW()=MATCH(C11, $C$1:$C$72, 0), SUMIFS(whatsapp!$D:$D, whatsapp!$A:$A, C11), 0) -> 0 | AD11: =SUMIFS('Dự án'!$C:$C, 'Dự án'!$A:$A, B11, 'Dự án'!$B:$B, C11) -> 0 | AE11: =SUMIFS(KPI!$C:$C, KPI!$A:$A, B11, KPI!$B:$B, C11) -> 0 | AF11: =SUMIFS('Thưởng CK'!$C:$C, 'Thưởng CK'!$A:$A, B11, 'Thưởng CK'!$B:$B, C11) -> 0 | AG11: =SUMIFS('Cận date'!$C:$C, 'Cận date'!$A:$A, B11, 'Cận date'!$B:$B, C11) -> 0 | AH11: =SUMIFS(Map!$D:$D, Map!$B:$B, B11, Map!$A:$A, C11) -> 0 | AI11: 0 | AJ11: =SUM(AK11:AO11) -> 0 | AK11: =SUMIFS('KPI trừ'!$C:$C, 'KPI trừ'!$A:$A, B11, 'KPI trừ'!$B:$B, C11) -> 0 | AL11: =SUMIFS('KPI trừ'!$D:$D, 'KPI trừ'!$A:$A, B11, 'KPI trừ'!$B:$B, C11) -> 0 | AM11: =SUMIFS('KPI trừ'!$E:$E, 'KPI trừ'!$A:$A, B11, 'KPI trừ'!$B:$B, C11) -> 0 | AN11: =SUMIFS('KPI trừ'!$F:$F, 'KPI trừ'!$A:$A, B11, 'KPI trừ'!$B:$B, C11) -> 0 | AO11: =SUMIFS('KPI trừ'!$G:$G, 'KPI trừ'!$A:$A, B11, 'KPI trừ'!$B:$B, C11) -> 0 | AP11: =IFERROR(INDEX('KPI trừ'!$H:$H, MATCH(1, ('KPI trừ'!$A:$A=B11)*('KPI trừ'!$B:$B=C11), 0)), "")
A12: 10 | B12: Đỗ Quang Đẩu | C12: Phạm Thị Nghĩa Hương | D12: DSCD | E12: =SUM(G12, I12, L12, O12, S12, T12) -> 11.02 | F12: =SUM(H12, P12) -> 230.26 | G12: =SUMIFS('Giờ công'!I:I, 'Giờ công'!G:G, B12, 'Giờ công'!H:H, C12) -> 3.02 | H12: =SUMIFS('Giờ công'!J:J, 'Giờ công'!G:G, B12, 'Giờ công'!H:H, C12) -> 230.26 | I12: =IF(ROW()=MATCH(C12, $C$1:$C$72, 0), IF(SUMIF($C$3:$C$72, C12, $R$3:$R$72)>=30, 16, IF(SUMIF($C$3:$C$72, C12, $R$3:$R$72)>=29, 8, "")), "") -> 8 | J12: =ROUND(G12/24, 1) -> 0.1 | K12: =SUMIFS('Ngày công'!I:I, 'Ngày công'!A:A, B12, 'Ngày công'!B:B, C12) -> 29 | N12: =SUMIFS('Tăng ca lễ'!M:M, 'Tăng ca lễ'!K:K, B12, 'Tăng ca lễ'!L:L, C12) -> 0 | O12: =IF(OR(D12="PT", D12="DSHV"), SUMIFS('Tăng ca lễ'!O:O, 'Tăng ca lễ'!K:K, B12, 'Tăng ca lễ'!L:L, C12)*2, SUMIFS('Tăng ca lễ'!O:O, 'Tăng ca lễ'!K:K, B12, 'Tăng ca lễ'!L:L, C12)*3) -> 0 | P12: =IF(OR(D12="PT", D12="DSHV"), SUMIFS('Tăng ca lễ'!P:P, 'Tăng ca lễ'!K:K, B12, 'Tăng ca lễ'!L:L, C12)*2, SUMIFS('Tăng ca lễ'!P:P, 'Tăng ca lễ'!K:K, B12, 'Tăng ca lễ'!L:L, C12)*3) -> 0 | R12: =SUMIFS('Ngày công'!M:M, 'Ngày công'!K:K, B12, 'Ngày công'!L:L, C12) -> 29 | S12: =SUMIFS('Công Đào tạo'!G:G, 'Công Đào tạo'!E:E, B12, 'Công Đào tạo'!F:F, C12) -> 0 | T12: 0 | V12: =IF(AND(ROW()=MATCH(C12, $C$1:$C$72, 0), OR(TRIM(D12)="CHT", TRIM(D12)="Q.CHT")), 500000/31*SUMIF($C$3:$C$72, C12, $R$3:$R$72), 0) -> 0 | X12: =IF(C12="","", IF(TRIM(D12)="DSCD", MIN(1500000, ROUND(1500000/28*MIN(N(J12),28),0)), IF(AND(OR(TRIM(D12)="DSXC", TRIM(D12)="DSBC", TRIM(D12)="CHT", TRIM(D12)="DSTV", TRIM(D12)="Q.CHT"), N(H12)>=160), MIN(1500000, ROUND(1500000/28*MIN(N(K12),28),0)), 0))) -> 5357 | AA12: =IF(ROW()=MATCH(C12, $C$1:$C$72, 0), IFERROR(VLOOKUP(C12, 'MiniKat - HN'!$A:$L, 12, FALSE), 0) + IFERROR(VLOOKUP(C12, 'MiniKat - HCM'!$A:$J, 10, FALSE), 0), 0) -> 0 | AB12: =IF(OR(TRIM(D12)="CHT", TRIM(D12)="Q.CHT"), SUMIFS('MiniKat - HN'!$Y:$Y, 'MiniKat - HN'!$N:$N, B12) + SUMIFS('MiniKat - HCM'!$U:$U, 'MiniKat - HCM'!$M:$M, B12), 0) -> 0 | AC12: =IF(ROW()=MATCH(C12, $C$1:$C$72, 0), SUMIFS(whatsapp!$D:$D, whatsapp!$A:$A, C12), 0) -> 340044 | AD12: =SUMIFS('Dự án'!$C:$C, 'Dự án'!$A:$A, B12, 'Dự án'!$B:$B, C12) -> 0 | AE12: =SUMIFS(KPI!$C:$C, KPI!$A:$A, B12, KPI!$B:$B, C12) -> 0 | AF12: =SUMIFS('Thưởng CK'!$C:$C, 'Thưởng CK'!$A:$A, B12, 'Thưởng CK'!$B:$B, C12) -> 629100 | AG12: =SUMIFS('Cận date'!$C:$C, 'Cận date'!$A:$A, B12, 'Cận date'!$B:$B, C12) -> 7550 | AH12: =SUMIFS(Map!$D:$D, Map!$B:$B, B12, Map!$A:$A, C12) -> 0 | AI12: 0 | AJ12: =SUM(AK12:AO12) -> 0 | AK12: =SUMIFS('KPI trừ'!$C:$C, 'KPI trừ'!$A:$A, B12, 'KPI trừ'!$B:$B, C12) -> 0 | AL12: =SUMIFS('KPI trừ'!$D:$D, 'KPI trừ'!$A:$A, B12, 'KPI trừ'!$B:$B, C12) -> 0 | AM12: =SUMIFS('KPI trừ'!$E:$E, 'KPI trừ'!$A:$A, B12, 'KPI trừ'!$B:$B, C12) -> 0 | AN12: =SUMIFS('KPI trừ'!$F:$F, 'KPI trừ'!$A:$A, B12, 'KPI trừ'!$B:$B, C12) -> 0 | AO12: =SUMIFS('KPI trừ'!$G:$G, 'KPI trừ'!$A:$A, B12, 'KPI trừ'!$B:$B, C12) -> 0 | AP12: =IFERROR(INDEX('KPI trừ'!$H:$H, MATCH(1, ('KPI trừ'!$A:$A=B12)*('KPI trừ'!$B:$B=C12), 0)), "")
A13: 11 | B13: Đỗ Quang Đẩu | C13: Trần Thiên Phát | D13: DSCD | E13: =SUM(G13, I13, L13, O13, S13, T13) -> 16 | F13: =SUM(H13, P13) -> 245.44 | G13: =SUMIFS('Giờ công'!I:I, 'Giờ công'!G:G, B13, 'Giờ công'!H:H, C13) -> 0 | H13: =SUMIFS('Giờ công'!J:J, 'Giờ công'!G:G, B13, 'Giờ công'!H:H, C13) -> 245.44 | I13: =IF(ROW()=MATCH(C13, $C$1:$C$72, 0), IF(SUMIF($C$3:$C$72, C13, $R$3:$R$72)>=30, 16, IF(SUMIF($C$3:$C$72, C13, $R$3:$R$72)>=29, 8, "")), "") -> 16 | J13: =ROUND(G13/24, 1) -> 0 | K13: =SUMIFS('Ngày công'!I:I, 'Ngày công'!A:A, B13, 'Ngày công'!B:B, C13) -> 31 | N13: =SUMIFS('Tăng ca lễ'!M:M, 'Tăng ca lễ'!K:K, B13, 'Tăng ca lễ'!L:L, C13) -> 0 | O13: =IF(OR(D13="PT", D13="DSHV"), SUMIFS('Tăng ca lễ'!O:O, 'Tăng ca lễ'!K:K, B13, 'Tăng ca lễ'!L:L, C13)*2, SUMIFS('Tăng ca lễ'!O:O, 'Tăng ca lễ'!K:K, B13, 'Tăng ca lễ'!L:L, C13)*3) -> 0 | P13: =IF(OR(D13="PT", D13="DSHV"), SUMIFS('Tăng ca lễ'!P:P, 'Tăng ca lễ'!K:K, B13, 'Tăng ca lễ'!L:L, C13)*2, SUMIFS('Tăng ca lễ'!P:P, 'Tăng ca lễ'!K:K, B13, 'Tăng ca lễ'!L:L, C13)*3) -> 0 | R13: =SUMIFS('Ngày công'!M:M, 'Ngày công'!K:K, B13, 'Ngày công'!L:L, C13) -> 31 | S13: =SUMIFS('Công Đào tạo'!G:G, 'Công Đào tạo'!E:E, B13, 'Công Đào tạo'!F:F, C13) -> 0 | T13: 0 | V13: =IF(AND(ROW()=MATCH(C13, $C$1:$C$72, 0), OR(TRIM(D13)="CHT", TRIM(D13)="Q.CHT")), 500000/31*SUMIF($C$3:$C$72, C13, $R$3:$R$72), 0) -> 0 | X13: =IF(C13="","", IF(TRIM(D13)="DSCD", MIN(1500000, ROUND(1500000/28*MIN(N(J13),28),0)), IF(AND(OR(TRIM(D13)="DSXC", TRIM(D13)="DSBC", TRIM(D13)="CHT", TRIM(D13)="DSTV", TRIM(D13)="Q.CHT"), N(H13)>=160), MIN(1500000, ROUND(1500000/28*MIN(N(K13),28),0)), 0))) -> 0 | AA13: =IF(ROW()=MATCH(C13, $C$1:$C$72, 0), IFERROR(VLOOKUP(C13, 'MiniKat - HN'!$A:$L, 12, FALSE), 0) + IFERROR(VLOOKUP(C13, 'MiniKat - HCM'!$A:$J, 10, FALSE), 0), 0) -> 0 | AB13: =IF(OR(TRIM(D13)="CHT", TRIM(D13)="Q.CHT"), SUMIFS('MiniKat - HN'!$Y:$Y, 'MiniKat - HN'!$N:$N, B13) + SUMIFS('MiniKat - HCM'!$U:$U, 'MiniKat - HCM'!$M:$M, B13), 0) -> 0 | AC13: =IF(ROW()=MATCH(C13, $C$1:$C$72, 0), SUMIFS(whatsapp!$D:$D, whatsapp!$A:$A, C13), 0) -> 375112 | AD13: =SUMIFS('Dự án'!$C:$C, 'Dự án'!$A:$A, B13, 'Dự án'!$B:$B, C13) -> 0 | AE13: =SUMIFS(KPI!$C:$C, KPI!$A:$A, B13, KPI!$B:$B, C13) -> 0 | AF13: =SUMIFS('Thưởng CK'!$C:$C, 'Thưởng CK'!$A:$A, B13, 'Thưởng CK'!$B:$B, C13) -> 867600 | AG13: =SUMIFS('Cận date'!$C:$C, 'Cận date'!$A:$A, B13, 'Cận date'!$B:$B, C13) -> 4035 | AH13: =SUMIFS(Map!$D:$D, Map!$B:$B, B13, Map!$A:$A, C13) -> 0 | AI13: 0 | AJ13: =SUM(AK13:AO13) -> 0 | AK13: =SUMIFS('KPI trừ'!$C:$C, 'KPI trừ'!$A:$A, B13, 'KPI trừ'!$B:$B, C13) -> 0 | AL13: =SUMIFS('KPI trừ'!$D:$D, 'KPI trừ'!$A:$A, B13, 'KPI trừ'!$B:$B, C13) -> 0 | AM13: =SUMIFS('KPI trừ'!$E:$E, 'KPI trừ'!$A:$A, B13, 'KPI trừ'!$B:$B, C13) -> 0 | AN13: =SUMIFS('KPI trừ'!$F:$F, 'KPI trừ'!$A:$A, B13, 'KPI trừ'!$B:$B, C13) -> 0 | AO13: =SUMIFS('KPI trừ'!$G:$G, 'KPI trừ'!$A:$A, B13, 'KPI trừ'!$B:$B, C13) -> 0 | AP13: =IFERROR(INDEX('KPI trừ'!$H:$H, MATCH(1, ('KPI trừ'!$A:$A=B13)*('KPI trừ'!$B:$B=C13), 0)), "")
A14: 12 | B14: Đỗ Quang Đẩu | C14: Hoàng Lâm Gia Bảo | D14: DSXC | E14: =SUM(G14, I14, L14, O14, S14, T14) -> 44.77 | F14: =SUM(H14, P14) -> 0.5 | G14: =SUMIFS('Giờ công'!I:I, 'Giờ công'!G:G, B14, 'Giờ công'!H:H, C14) -> 28.77 | H14: =SUMIFS('Giờ công'!J:J, 'Giờ công'!G:G, B14, 'Giờ công'!H:H, C14) -> 0.5 | I14: =IF(ROW()=MATCH(C14, $C$1:$C$72, 0), IF(SUMIF($C$3:$C$72, C14, $R$3:$R$72)>=30, 16, IF(SUMIF($C$3:$C$72, C14, $R$3:$R$72)>=29, 8, "")), "") -> 16 | J14: =ROUND(G14/24, 1) -> 1.2 | K14: =SUMIFS('Ngày công'!I:I, 'Ngày công'!A:A, B14, 'Ngày công'!B:B, C14) -> 0 | N14: =SUMIFS('Tăng ca lễ'!M:M, 'Tăng ca lễ'!K:K, B14, 'Tăng ca lễ'!L:L, C14) -> 0 | O14: =IF(OR(D14="PT", D14="DSHV"), SUMIFS('Tăng ca lễ'!O:O, 'Tăng ca lễ'!K:K, B14, 'Tăng ca lễ'!L:L, C14)*2, SUMIFS('Tăng ca lễ'!O:O, 'Tăng ca lễ'!K:K, B14, 'Tăng ca lễ'!L:L, C14)*3) -> 0 | P14: =IF(OR(D14="PT", D14="DSHV"), SUMIFS('Tăng ca lễ'!P:P, 'Tăng ca lễ'!K:K, B14, 'Tăng ca lễ'!L:L, C14)*2, SUMIFS('Tăng ca lễ'!P:P, 'Tăng ca lễ'!K:K, B14, 'Tăng ca lễ'!L:L, C14)*3) -> 0 | R14: =SUMIFS('Ngày công'!M:M, 'Ngày công'!K:K, B14, 'Ngày công'!L:L, C14) -> 4 | S14: =SUMIFS('Công Đào tạo'!G:G, 'Công Đào tạo'!E:E, B14, 'Công Đào tạo'!F:F, C14) -> 0 | T14: 0 | V14: =IF(AND(ROW()=MATCH(C14, $C$1:$C$72, 0), OR(TRIM(D14)="CHT", TRIM(D14)="Q.CHT")), 500000/31*SUMIF($C$3:$C$72, C14, $R$3:$R$72), 0) -> 0 | X14: =IF(C14="","", IF(TRIM(D14)="DSCD", MIN(1500000, ROUND(1500000/28*MIN(N(J14),28),0)), IF(AND(OR(TRIM(D14)="DSXC", TRIM(D14)="DSBC", TRIM(D14)="CHT", TRIM(D14)="DSTV", TRIM(D14)="Q.CHT"), N(H14)>=160), MIN(1500000, ROUND(1500000/28*MIN(N(K14),28),0)), 0))) -> 0 | AA14: =IF(ROW()=MATCH(C14, $C$1:$C$72, 0), IFERROR(VLOOKUP(C14, 'MiniKat - HN'!$A:$L, 12, FALSE), 0) + IFERROR(VLOOKUP(C14, 'MiniKat - HCM'!$A:$J, 10, FALSE), 0), 0) -> 0 | AB14: =IF(OR(TRIM(D14)="CHT", TRIM(D14)="Q.CHT"), SUMIFS('MiniKat - HN'!$Y:$Y, 'MiniKat - HN'!$N:$N, B14) + SUMIFS('MiniKat - HCM'!$U:$U, 'MiniKat - HCM'!$M:$M, B14), 0) -> 0 | AC14: =IF(ROW()=MATCH(C14, $C$1:$C$72, 0), SUMIFS(whatsapp!$D:$D, whatsapp!$A:$A, C14), 0) -> 0 | AD14: =SUMIFS('Dự án'!$C:$C, 'Dự án'!$A:$A, B14, 'Dự án'!$B:$B, C14) -> 0 | AE14: =SUMIFS(KPI!$C:$C, KPI!$A:$A, B14, KPI!$B:$B, C14) -> 0 | AF14: =SUMIFS('Thưởng CK'!$C:$C, 'Thưởng CK'!$A:$A, B14, 'Thưởng CK'!$B:$B, C14) -> 0 | AG14: =SUMIFS('Cận date'!$C:$C, 'Cận date'!$A:$A, B14, 'Cận date'!$B:$B, C14) -> 0 | AH14: =SUMIFS(Map!$D:$D, Map!$B:$B, B14, Map!$A:$A, C14) -> 0 | AI14: 0 | AJ14: =SUM(AK14:AO14) -> 0 | AK14: =SUMIFS('KPI trừ'!$C:$C, 'KPI trừ'!$A:$A, B14, 'KPI trừ'!$B:$B, C14) -> 0 | AL14: =SUMIFS('KPI trừ'!$D:$D, 'KPI trừ'!$A:$A, B14, 'KPI trừ'!$B:$B, C14) -> 0 | AM14: =SUMIFS('KPI trừ'!$E:$E, 'KPI trừ'!$A:$A, B14, 'KPI trừ'!$B:$B, C14) -> 0 | AN14: =SUMIFS('KPI trừ'!$F:$F, 'KPI trừ'!$A:$A, B14, 'KPI trừ'!$B:$B, C14) -> 0 | AO14: =SUMIFS('KPI trừ'!$G:$G, 'KPI trừ'!$A:$A, B14, 'KPI trừ'!$B:$B, C14) -> 0 | AP14: =IFERROR(INDEX('KPI trừ'!$H:$H, MATCH(1, ('KPI trừ'!$A:$A=B14)*('KPI trừ'!$B:$B=C14), 0)), "")
... A72: 70 | B72: Hàng Bông | C72: Đỗ Thu Huệ | D72: DSBC | E72: =SUM(G72, I72, L72, O72, S72, T72) -> 112.03 | F72: =SUM(H72, P72) -> 0 | G72: =SUMIFS('Giờ công'!I:I, 'Giờ công'!G:G, B72, 'Giờ công'!H:H, C72) -> 112.03 | H72: =SUMIFS('Giờ công'!J:J, 'Giờ công'!G:G, B72, 'Giờ công'!H:H, C72) -> 0 | I72: =IF(ROW()=MATCH(C72, $C$1:$C$72, 0), IF(SUMIF($C$3:$C$72, C72, $R$3:$R$72)>=30, 16, IF(SUMIF($C$3:$C$72, C72, $R$3:$R$72)>=29, 8, "")), "") | J72: =ROUND(G72/24, 1) -> 4.7 | K72: =SUMIFS('Ngày công'!I:I, 'Ngày công'!A:A, B72, 'Ngày công'!B:B, C72) -> 0 | N72: =SUMIFS('Tăng ca lễ'!M:M, 'Tăng ca lễ'!K:K, B72, 'Tăng ca lễ'!L:L, C72) -> 0 | O72: =IF(OR(D72="PT", D72="DSHV"), SUMIFS('Tăng ca lễ'!O:O, 'Tăng ca lễ'!K:K, B72, 'Tăng ca lễ'!L:L, C72)*2, SUMIFS('Tăng ca lễ'!O:O, 'Tăng ca lễ'!K:K, B72, 'Tăng ca lễ'!L:L, C72)*3) -> 0 | P72: =IF(OR(D72="PT", D72="DSHV"), SUMIFS('Tăng ca lễ'!P:P, 'Tăng ca lễ'!K:K, B72, 'Tăng ca lễ'!L:L, C72)*2, SUMIFS('Tăng ca lễ'!P:P, 'Tăng ca lễ'!K:K, B72, 'Tăng ca lễ'!L:L, C72)*3) -> 0 | R72: =SUMIFS('Ngày công'!M:M, 'Ngày công'!K:K, B72, 'Ngày công'!L:L, C72) -> 14 | S72: =SUMIFS('Công Đào tạo'!G:G, 'Công Đào tạo'!E:E, B72, 'Công Đào tạo'!F:F, C72) -> 0 | T72: 0 | V72: =IF(AND(ROW()=MATCH(C72, $C$1:$C$72, 0), OR(TRIM(D72)="CHT", TRIM(D72)="Q.CHT")), 500000/31*SUMIF($C$3:$C$72, C72, $R$3:$R$72), 0) -> 0 | X72: =IF(C72="","", IF(TRIM(D72)="DSCD", MIN(1500000, ROUND(1500000/28*MIN(N(J72),28),0)), IF(AND(OR(TRIM(D72)="DSXC", TRIM(D72)="DSBC", TRIM(D72)="CHT", TRIM(D72)="DSTV", TRIM(D72)="Q.CHT"), N(H72)>=160), MIN(1500000, ROUND(1500000/28*MIN(N(K72),28),0)), 0))) -> 0 | AA72: =IF(ROW()=MATCH(C72, $C$1:$C$72, 0), IFERROR(VLOOKUP(C72, 'MiniKat - HN'!$A:$L, 12, FALSE), 0) + IFERROR(VLOOKUP(C72, 'MiniKat - HCM'!$A:$J, 10, FALSE), 0), 0) -> 0 | AB72: =IF(OR(TRIM(D72)="CHT", TRIM(D72)="Q.CHT"), SUMIFS('MiniKat - HN'!$Y:$Y, 'MiniKat - HN'!$N:$N, B72) + SUMIFS('MiniKat - HCM'!$U:$U, 'MiniKat - HCM'!$M:$M, B72), 0) -> 0 | AC72: =IF(ROW()=MATCH(C72, $C$1:$C$72, 0), SUMIFS(whatsapp!$D:$D, whatsapp!$A:$A, C72), 0) -> 0 | AD72: =SUMIFS('Dự án'!$C:$C, 'Dự án'!$A:$A, B72, 'Dự án'!$B:$B, C72) -> 0 | AE72: =SUMIFS(KPI!$C:$C, KPI!$A:$A, B72, KPI!$B:$B, C72) -> 0 | AF72: =SUMIFS('Thưởng CK'!$C:$C, 'Thưởng CK'!$A:$A, B72, 'Thưởng CK'!$B:$B, C72) -> 0 | AG72: =SUMIFS('Cận date'!$C:$C, 'Cận date'!$A:$A, B72, 'Cận date'!$B:$B, C72) -> 0 | AH72: =SUMIFS(Map!$D:$D, Map!$B:$B, B72, Map!$A:$A, C72) -> 0 | AI72: 0 | AJ72: =SUM(AK72:AO72) -> 0 | AK72: =SUMIFS('KPI trừ'!$C:$C, 'KPI trừ'!$A:$A, B72, 'KPI trừ'!$B:$B, C72) -> 0 | AL72: =SUMIFS('KPI trừ'!$D:$D, 'KPI trừ'!$A:$A, B72, 'KPI trừ'!$B:$B, C72) -> 0 | AM72: =SUMIFS('KPI trừ'!$E:$E, 'KPI trừ'!$A:$A, B72, 'KPI trừ'!$B:$B, C72) -> 0 | AN72: =SUMIFS('KPI trừ'!$F:$F, 'KPI trừ'!$A:$A, B72, 'KPI trừ'!$B:$B, C72) -> 0 | AO72: =SUMIFS('KPI trừ'!$G:$G, 'KPI trừ'!$A:$A, B72, 'KPI trừ'!$B:$B, C72) -> 0 | AP72: =IFERROR(INDEX('KPI trừ'!$H:$H, MATCH(1, ('KPI trừ'!$A:$A=B72)*('KPI trừ'!$B:$B=C72), 0)), "")
D74: Tổng | E74: =SUM(E3:E72) -> 8041.69 | F74: =SUM(F3:F72) -> 5123.39 | G74: =SUM(G3:G72) -> 7745.69 | H74: =SUM(H3:H72) -> 5123.39 | I74: =SUM(I3:I72) -> 296 | J74: =SUM(J3:J72) -> 322.8 | K74: =SUM(K3:K72) -> 628 | L74: =SUM(L3:L72) -> 0 | ... AO74: =SUM(AO3:AO72) -> 1000000
E76: Chi nhánh | G76: Số giờ ca ngày | H76: Số giờ ca đêm ( chưa x 1.5 ) | I76: Tổng số giờ
E77: Trường Sa | G77: =SUMIF(B:B, E77, G:G) -> 697.71 | H77: =SUMIF(B:B, E77, H:H) -> 490.71 | I77: =SUM(G77:H77) -> 1188.42
E78: Đỗ Quang Đẩu | G78: =SUMIF(B:B, E78, G:G) -> 729.82 | H78: =SUMIF(B:B, E78, H:H) -> 485.38 | I78: =SUM(G78:H78) -> 1215.2
E79: Nam Hòa | G79: =SUMIF(B:B, E79, G:G) -> 717.81 | H79: =SUMIF(B:B, E79, H:H) -> 483.44 | I79: =SUM(G79:H79) -> 1201.25
E80: Minh Châu | G80: =SUMIF(B:B, E80, G:G) -> 715.21 | H80: =SUMIF(B:B, E80, H:H) -> 368.7 | I80: =SUM(G80:H80) -> 1083.91
E81: Lê Bình | G81: =SUMIF(B:B, E81, G:G) -> 725.71 | H81: =SUMIF(B:B, E81, H:H) -> 486.55 | I81: =SUM(G81:H81) -> 1212.26
E82: Nguyễn Chí Thanh | G82: =SUMIF(B:B, E82, G:G) -> 755.71 | H82: =SUMIF(B:B, E82, H:H) -> 463.44 | I82: =SUM(G82:H82) -> 1219.15
E83: Nguyễn Thị Thập | G83: =SUMIF(B:B, E83, G:G) -> 740.65 | H83: =SUMIF(B:B, E83, H:H) -> 545.32 | I83: =SUM(G83:H83) -> 1285.97
E84: Nguyễn Văn Quá | G84: =SUMIF(B:B, E84, G:G) -> 490.05 | H84: =SUMIF(B:B, E84, H:H) -> 420.28 | I84: =SUM(G84:H84) -> 910.33
E85: Rạch Bùng Binh | G85: =SUMIF(B:B, E85, G:G) -> 722.9 | H85: =SUMIF(B:B, E85, H:H) -> 479.56 | I85: =SUM(G85:H85) -> 1202.46
E86: Đường Láng | G86: =SUMIF(B:B, E86, G:G) -> 701.19 | H86: =SUMIF(B:B, E86, H:H) -> 589.66 | I86: =SUM(G86:H86) -> 1290.85
E87: Hàng Bông | G87: =SUMIF(B:B, E87, G:G) -> 748.93 | H87: =SUMIF(B:B, E87, H:H) -> 310.35 | I87: =SUM(G87:H87) -> 1059.28
E88: Tổng cộng | G88: =SUM(G77:G87) -> 7745.69 | H88: =SUM(H77:H87) -> 5123.39 | I88: =SUM(I77:I87) -> 12869.08

Sheet MiniKat - HN
A1: Người bán | B1: SL Party Smart | C1: SL KAT bán | D1: SL LadyCare bán | E1: SL AVC bán | F1: Doanh thu LadyCare | G1: Doanh thu AVC | H1: Thưởng KAT | I1: Thưởng Party | J1: Thưởng LadyCare | K1: Thưởng AVC | L1: Tổng Thưởng | N1: Chi nhánh | O1: SL KAT bán | P1: SL PARTY SMART bán | Q1: SL AVC bán | R1: Doanh thu LadyCare | S1: Doanh thu AVC | T1: Thưởng KAT Tổng | U1: Thưởng PS 180 hộp | V1: PS đầu 150 hộp | W1: Thưởng LadyCare | X1: Thưởng AVC | Y1: Tổng thưởng
A2: Hứa Thị Kim Thoa | B2: 4 | C2: 0 | D2: 1 | E2: 3 | F2: 179000 | G2: 485000 | H2: =IF(C2>=17, C2*30000, IF(C2>=15, C2*25000, 0)) -> 0 | I2: =IF(B2>=80, B2*6000, 0) -> 0 | J2: =IF(F2>7000000, F2*0.06, IF(F2>5000000, F2*0.04, 0)) -> 0 | K2: =IF(G2>9000000, E2*6000, IF(G2>7000000, E2*4000, 0)) -> 0 | L2: =H2+I2+J2+K2 -> 0 | N2: Đường Láng | O2: 7 | P2: 114 | Q2: 115 | R2: 4626000 | S2: 19647000 | T2: =IF(O2>=17, 300000, 0) -> 0 | U2: =IF(P2>=180, 300000, 0) -> 0 | V2: =IF(P2>=150, 150000, 0) -> 0 | W2: =IF(R2>30000000, 700000, IF(R2>22000000, 500000, 0)) -> 0 | X2: 0 | Y2: =T2+U2+V2+W2+X2 -> 0
A3: Lê Thị Soạn | B3: 60 | C3: 3 | D3: 9 | E3: 54 | F3: 1791000 | G3: 9127000 | H3: =IF(C3>=17, C3*30000, IF(C3>=15, C3*25000, 0)) -> 0 | I3: =IF(B3>=80, B3*6000, 0) -> 0 | J3: =IF(F3>7000000, F3*0.06, IF(F3>5000000, F3*0.04, 0)) -> 0 | K3: =IF(G3>9000000, E3*6000, IF(G3>7000000, E3*4000, 0)) -> 324000 | L3: =H3+I3+J3+K3 -> 324000 | N3: Hàng Bông | O3: 8 | P3: 18 | Q3: 23 | R3: 1194000 | S3: 3941500 | T3: =IF(O3>=17, 300000, 0) -> 0 | U3: =IF(P3>=180, 300000, 0) -> 0 | V3: =IF(P3>=150, 150000, 0) -> 0 | W3: =IF(R3>30000000, 700000, IF(R3>22000000, 500000, 0)) -> 0 | X3: 0 | Y3: =T3+U3+V3+W3+X3 -> 0
A4: Nguyễn Thị Mai Duyên | B4: 15 | C4: 4 | D4: 4 | E4: 6 | F4: 776000 | G4: 1020000 | H4: =IF(C4>=17, C4*30000, IF(C4>=15, C4*25000, 0)) -> 0 | I4: =IF(B4>=80, B4*6000, 0) -> 0 | J4: =IF(F4>7000000, F4*0.06, IF(F4>5000000, F4*0.04, 0)) -> 0 | K4: =IF(G4>9000000, E4*6000, IF(G4>7000000, E4*4000, 0)) -> 0 | L4: =H4+I4+J4+K4 -> 0
A5: Nguyễn Thị Tâm | B5: 24 | C5: 0 | D5: 8 | E5: 46 | F5: 1522000 | G5: 7745000 | H5: =IF(C5>=17, C5*30000, IF(C5>=15, C5*25000, 0)) -> 0 | I5: =IF(B5>=80, B5*6000, 0) -> 0 | J5: =IF(F5>7000000, F5*0.06, IF(F5>5000000, F5*0.04, 0)) -> 0 | K5: =IF(G5>9000000, E5*6000, IF(G5>7000000, E5*4000, 0)) -> 184000 | L5: =H5+I5+J5+K5 -> 184000
A6: Trần Ngọc Dung | B6: 11 | C6: 0 | D6: 2 | E6: 6 | F6: 358000 | G6: 1270000 | H6: =IF(C6>=17, C6*30000, IF(C6>=15, C6*25000, 0)) -> 0 | I6: =IF(B6>=80, B6*6000, 0) -> 0 | J6: =IF(F6>7000000, F6*0.06, IF(F6>5000000, F6*0.04, 0)) -> 0 | K6: =IF(G6>9000000, E6*6000, IF(G6>7000000, E6*4000, 0)) -> 0 | L6: =H6+I6+J6+K6 -> 0
A7: Đinh Thị Lan Anh | B7: 0 | C7: 2 | D7: 1 | E7: 6 | F7: 179000 | G7: 1020000 | H7: =IF(C7>=17, C7*30000, IF(C7>=15, C7*25000, 0)) -> 0 | I7: =IF(B7>=80, B7*6000, 0) -> 0 | J7: =IF(F7>7000000, F7*0.06, IF(F7>5000000, F7*0.04, 0)) -> 0 | K7: =IF(G7>9000000, E7*6000, IF(G7>7000000, E7*4000, 0)) -> 0 | L7: =H7+I7+J7+K7 -> 0
A8: Nguyễn Mạnh Tuấn | B8: 5 | C8: 0 | D8: 0 | E8: 8 | F8: 0 | G8: 1360000 | H8: =IF(C8>=17, C8*30000, IF(C8>=15, C8*25000, 0)) -> 0 | I8: =IF(B8>=80, B8*6000, 0) -> 0 | J8: =IF(F8>7000000, F8*0.06, IF(F8>5000000, F8*0.04, 0)) -> 0 | K8: =IF(G8>9000000, E8*6000, IF(G8>7000000, E8*4000, 0)) -> 0 | L8: =H8+I8+J8+K8 -> 0
A9: Vũ Thanh Hằng | B9: 3 | C9: 3 | D9: 3 | E9: 3 | F9: 597000 | G9: 535000 | H9: =IF(C9>=17, C9*30000, IF(C9>=15, C9*25000, 0)) -> 0 | I9: =IF(B9>=80, B9*6000, 0) -> 0 | J9: =IF(F9>7000000, F9*0.06, IF(F9>5000000, F9*0.04, 0)) -> 0 | K9: =IF(G9>9000000, E9*6000, IF(G9>7000000, E9*4000, 0)) -> 0 | L9: =H9+I9+J9+K9 -> 0
A10: Đinh Thị Khánh Ly | B10: 10 | C10: 3 | D10: 2 | E10: 6 | F10: 418000 | G10: 1026500 | H10: =IF(C10>=17, C10*30000, IF(C10>=15, C10*25000, 0)) -> 0 | I10: =IF(B10>=80, B10*6000, 0) -> 0 | J10: =IF(F10>7000000, F10*0.06, IF(F10>5000000, F10*0.04, 0)) -> 0 | K10: =IF(G10>9000000, E10*6000, IF(G10>7000000, E10*4000, 0)) -> 0 | L10: =H10+I10+J10+K10 -> 0
A11: Đỗ Thu Huệ | B11: 0 | C11: 0 | D11: 0 | E11: 0 | F11: 0 | G11: 0 | H11: =IF(C11>=17, C11*30000, IF(C11>=15, C11*25000, 0)) -> 0 | I11: =IF(B11>=80, B11*6000, 0) -> 0 | J11: =IF(F11>7000000, F11*0.06, IF(F11>5000000, F11*0.04, 0)) -> 0 | K11: =IF(G11>9000000, E11*6000, IF(G11>7000000, E11*4000, 0)) -> 0 | L11: =H11+I11+J11+K11 -> 0

Sheet MiniKat - HCM
A1: Người bán | B1: SL Party Smart | C1: SL KAT bán | D1: SL LadyCare bán | E1: Doanh thu LadyCare | F1: Doanh Thu KAT | G1: Thưởng KAT | H1: Thưởng Party | I1: Thưởng LadyCare | J1: Tổng Thưởng | M1: Chi nhánh | N1: SL KAT bán | O1: SL PARTY SMART bán | P1: Thưởng KAT Tổng | Q1: Thưởng PS 180 hộp | R1: PS đầu 150 hộp | S1: Doanh thu LadyCare | T1: Thưởng LadyCare | U1: Tổng thưởng
A2: Hồ Thị Minh Hòa | B2: 8 | C2: 9 | D2: 1 | E2: 179000 | F2: 547000 | G2: =IF(C2>=10, C2*30000, IF(C2>=7, C2*25000, 0)) -> 225000 | H2: =IF(B2>=80, B2*6000, 0) -> 0 | I2: =IF(E2>7000000, E2*0.06, IF(E2>5000000, E2*0.04, IF(E2>3000000, E2*0.03, 0))) -> 0 | J2: =G2+H2+I2 -> 225000 | M2: Trường Sa | N2: =SUM(C2:C8) -> 19 | O2: =SUM(B2:B8) -> 67 | P2: =IF(N2>=17, 300000, 0) -> 300000 | Q2: =IF(O2>=180, 300000, 0) -> 0 | R2: =IF(O2>=150, 150000, 0) -> 0 | S2: =SUM(E2:E8) -> 4714800 | T2: =IF(S2>30000000, 700000, IF(S2>22000000, 500000, IF(S2>15000000, 200000, 0))) -> 0 | U2: =P2+Q2+R2+T2 -> 300000
A3: Nguyễn Trần Ngọc Phương | B3: 8 | C3: 0 | D3: 6 | E3: 1044000 | F3: 0 | G3: =IF(C3>=10, C3*30000, IF(C3>=7, C3*25000, 0)) -> 0 | H3: =IF(B3>=80, B3*6000, 0) -> 0 | I3: =IF(E3>7000000, E3*0.06, IF(E3>5000000, E3*0.04, IF(E3>3000000, E3*0.03, 0))) -> 0 | J3: =G3+H3+I3 -> 0 | M3: Đỗ Quang Đẩu | N3: =SUM(C9:C15) -> 5 | O3: =SUM(B9:B15) -> 42 | P3: =IF(N3>=17, 300000, 0) -> 0 | Q3: =IF(O3>=180, 300000, 0) -> 0 | R3: =IF(O3>=150, 150000, 0) -> 0 | S3: =SUM(E9:E15) -> 686000 | T3: =IF(S3>30000000, 700000, IF(S3>22000000, 500000, IF(S3>15000000, 200000, 0))) -> 0 | U3: =P3+Q3+R3+T3 -> 0
A4: Nguyễn Ngọc Anh Thư | B4: 3 | C4: 2 | D4: 1 | E4: 149000 | F4: 960000 | G4: =IF(C4>=10, C4*30000, IF(C4>=7, C4*25000, 0)) -> 0 | H4: =IF(B4>=80, B4*6000, 0) -> 0 | I4: =IF(E4>7000000, E4*0.06, IF(E4>5000000, E4*0.04, IF(E4>3000000, E4*0.03, 0))) -> 0 | J4: =G4+H4+I4 -> 0 | M4: Minh Châu | N4: =SUM(C16:C21) -> 17 | O4: =SUM(B16:B21) -> 27 | P4: =IF(N4>=17, 300000, 0) -> 300000 | Q4: =IF(O4>=180, 300000, 0) -> 0 | R4: =IF(O4>=150, 150000, 0) -> 0 | S4: =SUM(E16:E21) -> 4954000 | T4: =IF(S4>30000000, 700000, IF(S4>22000000, 500000, IF(S4>15000000, 200000, 0))) -> 0 | U4: =P4+Q4+R4+T4 -> 300000
A5: Trịnh Thị Phượng | B5: 6 | C5: 6 | D5: 6 | E5: 984000 | F5: 2880000 | G5: =IF(C5>=10, C5*30000, IF(C5>=7, C5*25000, 0)) -> 0 | H5: =IF(B5>=80, B5*6000, 0) -> 0 | I5: =IF(E5>7000000, E5*0.06, IF(E5>5000000, E5*0.04, IF(E5>3000000, E5*0.03, 0))) -> 0 | J5: =G5+H5+I5 -> 0 | M5: Nam Hòa | N5: =SUM(C22:C28) -> 10 | O5: =SUM(B22:B28) -> 40 | P5: =IF(N5>=17, 300000, 0) -> 0 | Q5: =IF(O5>=180, 300000, 0) -> 0 | R5: =IF(O5>=150, 150000, 0) -> 0 | S5: =SUM(E22:E28) -> 3313000 | T5: =IF(S5>30000000, 700000, IF(S5>22000000, 500000, IF(S5>15000000, 200000, 0))) -> 0 | U5: =P5+Q5+R5+T5 -> 0
A6: Ngô Trần Tuyết Vy | B6: 8 | C6: 1 | D6: 1 | E6: 179000 | F6: 480000 | G6: =IF(C6>=10, C6*30000, IF(C6>=7, C6*25000, 0)) -> 0 | H6: =IF(B6>=80, B6*6000, 0) -> 0 | I6: =IF(E6>7000000, E6*0.06, IF(E6>5000000, E6*0.04, IF(E6>3000000, E6*0.03, 0))) -> 0 | J6: =G6+H6+I6 -> 0 | M6: Nguyễn Chí Thanh | N6: =SUM(C29:C34) -> 4 | O6: =SUM(B29:B34) -> 24 | P6: =IF(N6>=17, 300000, 0) -> 0 | Q6: =IF(O6>=180, 300000, 0) -> 0 | R6: =IF(O6>=150, 150000, 0) -> 0 | S6: =SUM(E29:E34) -> 1521000 | T6: =IF(S6>30000000, 700000, IF(S6>22000000, 500000, IF(S6>15000000, 200000, 0))) -> 0 | U6: =P6+Q6+R6+T6 -> 0
A7: Phạm Nguyễn Ngọc Quý | B7: 24 | C7: 0 | D7: 3 | E7: 537000 | F7: 0 | G7: =IF(C7>=10, C7*30000, IF(C7>=7, C7*25000, 0)) -> 0 | H7: =IF(B7>=80, B7*6000, 0) -> 0 | I7: =IF(E7>7000000, E7*0.06, IF(E7>5000000, E7*0.04, IF(E7>3000000, E7*0.03, 0))) -> 0 | J7: =G7+H7+I7 -> 0 | M7: Nguyễn Thị Thập | N7: =SUM(C35:C43) -> 27 | O7: =SUM(B35:B43) -> 106 | P7: =IF(N7>=17, 300000, 0) -> 300000 | Q7: =IF(O7>=180, 300000, 0) -> 0 | R7: =IF(O7>=150, 150000, 0) -> 0 | S7: =SUM(E35:E43) -> 3701000 | T7: =IF(S7>30000000, 700000, IF(S7>22000000, 500000, IF(S7>15000000, 200000, 0))) -> 0 | U7: =P7+Q7+R7+T7 -> 300000
A8: Trần Thị Kim Khánh | B8: 10 | C8: 1 | D8: 10 | E8: 1642800 | F8: 480000 | G8: =IF(C8>=10, C8*30000, IF(C8>=7, C8*25000, 0)) -> 0 | H8: =IF(B8>=80, B8*6000, 0) -> 0 | I8: =IF(E8>7000000, E8*0.06, IF(E8>5000000, E8*0.04, IF(E8>3000000, E8*0.03, 0))) -> 0 | J8: =G8+H8+I8 -> 0 | M8: Nguyễn Văn Quá | N8: =SUM(C44:C47) -> 9 | O8: =SUM(B44:B47) -> 73 | P8: =IF(N8>=17, 300000, 0) -> 0 | Q8: =IF(O8>=180, 300000, 0) -> 0 | R8: =IF(O8>=150, 150000, 0) -> 0 | S8: =SUM(E44:E47) -> 627000 | T8: =IF(S8>30000000, 700000, IF(S8>22000000, 500000, IF(S8>15000000, 200000, 0))) -> 0 | U8: =P8+Q8+R8+T8 -> 0
A9: Ngô Thị Thanh Thắm | B9: 7 | C9: 1 | D9: 1 | E9: 149000 | F9: 480000 | G9: =IF(C9>=10, C9*30000, IF(C9>=7, C9*25000, 0)) -> 0 | H9: =IF(B9>=80, B9*6000, 0) -> 0 | I9: =IF(E9>7000000, E9*0.06, IF(E9>5000000, E9*0.04, IF(E9>3000000, E9*0.03, 0))) -> 0 | J9: =G9+H9+I9 -> 0 | M9: Rạch Bùng Binh | N9: =SUM(C48:C53) -> 10 | O9: =SUM(B48:B53) -> 166 | P9: =IF(N9>=17, 300000, 0) -> 0 | Q9: =IF(O9>=180, 300000, 0) -> 0 | R9: =IF(O9>=150, 150000, 0) -> 150000 | S9: =SUM(E48:E53) -> 3432000 | T9: =IF(S9>30000000, 700000, IF(S9>22000000, 500000, IF(S9>15000000, 200000, 0))) -> 0 | U9: =P9+Q9+R9+T9 -> 150000
A10: Dương Thị Huỳnh Như | B10: 0 | C10: 0 | D10: 0 | E10: 0 | F10: 0 | G10: =IF(C10>=10, C10*30000, IF(C10>=7, C10*25000, 0)) -> 0 | H10: =IF(B10>=80, B10*6000, 0) -> 0 | I10: =IF(E10>7000000, E10*0.06, IF(E10>5000000, E10*0.04, IF(E10>3000000, E10*0.03, 0))) -> 0 | J10: =G10+H10+I10 -> 0 | M10: Lê Bình | N10: =SUM(C54:C61) -> 16 | O10: =SUM(B54:B61) -> 53 | P10: =IF(N10>=17, 300000, 0) -> 0 | Q10: =IF(O10>=180, 300000, 0) -> 0 | R10: =IF(O10>=150, 150000, 0) -> 0 | S10: =SUM(E54:E61) -> 2237000 | T10: =IF(S10>30000000, 700000, IF(S10>22000000, 500000, IF(S10>15000000, 200000, 0))) -> 0 | U10: =P10+Q10+R10+T10 -> 0
A11: Phạm Thị Nghĩa Hương | B11: 3 | C11: 0 | D11: 1 | E11: 179000 | F11: 0 | G11: =IF(C11>=10, C11*30000, IF(C11>=7, C11*25000, 0)) -> 0 | H11: =IF(B11>=80, B11*6000, 0) -> 0 | I11: =IF(E11>7000000, E11*0.06, IF(E11>5000000, E11*0.04, IF(E11>3000000, E11*0.03, 0))) -> 0 | J11: =G11+H11+I11 -> 0 | M11: Tổng cộng | N11: =SUM(N2:N10) -> 117 | O11: =SUM(O2:O10) -> 598 | P11: =SUM(P2:P10) -> 900000 | Q11: =SUM(Q2:Q10) -> 0 | R11: =SUM(R2:R10) -> 150000 | S11: =SUM(S2:S10) -> 25185800 | T11: =SUM(T2:T10) -> 0 | U11: =SUM(U2:U10) -> 1050000
A12: Trần Thiên Phát | B12: 8 | C12: 0 | D12: 0 | E12: 0 | F12: 0 | G12: =IF(C12>=10, C12*30000, IF(C12>=7, C12*25000, 0)) -> 0 | H12: =IF(B12>=80, B12*6000, 0) -> 0 | I12: =IF(E12>7000000, E12*0.06, IF(E12>5000000, E12*0.04, IF(E12>3000000, E12*0.03, 0))) -> 0 | J12: =G12+H12+I12 -> 0
A13: Hoàng Lâm Gia Bảo | B13: 6 | C13: 4 | D13: 1 | E13: 179000 | F13: 1920000 | G13: =IF(C13>=10, C13*30000, IF(C13>=7, C13*25000, 0)) -> 0 | H13: =IF(B13>=80, B13*6000, 0) -> 0 | I13: =IF(E13>7000000, E13*0.06, IF(E13>5000000, E13*0.04, IF(E13>3000000, E13*0.03, 0))) -> 0 | J13: =G13+H13+I13 -> 0
A14: Hoàng Thanh Thủy | B14: 7 | C14: 0 | D14: 1 | E14: 179000 | F14: 0 | G14: =IF(C14>=10, C14*30000, IF(C14>=7, C14*25000, 0)) -> 0 | H14: =IF(B14>=80, B14*6000, 0) -> 0 | I14: =IF(E14>7000000, E14*0.06, IF(E14>5000000, E14*0.04, IF(E14>3000000, E14*0.03, 0))) -> 0 | J14: =G14+H14+I14 -> 0
A15: Lê Thị Huyền Trân | B15: 11 | C15: 0 | D15: 0 | E15: 0 | F15: 0 | G15: =IF(C15>=10, C15*30000, IF(C15>=7, C15*25000, 0)) -> 0 | H15: =IF(B15>=80, B15*6000, 0) -> 0 | I15: =IF(E15>7000000, E15*0.06, IF(E15>5000000, E15*0.04, IF(E15>3000000, E15*0.03, 0))) -> 0 | J15: =G15+H15+I15 -> 0
A16: Thái Thùy Linh | B16: 3 | C16: 2 | D16: 3 | E16: 567000 | F16: 960000 | G16: =IF(C16>=10, C16*30000, IF(C16>=7, C16*25000, 0)) -> 0 | H16: =IF(B16>=80, B16*6000, 0) -> 0 | I16: =IF(E16>7000000, E16*0.06, IF(E16>5000000, E16*0.04, IF(E16>3000000, E16*0.03, 0))) -> 0 | J16: =G16+H16+I16 -> 0
A17: Trịnh Thị Phượng | B17: 6 | C17: 6 | D17: 6 | E17: 984000 | F17: 2880000 | G17: =IF(C17>=10, C17*30000, IF(C17>=7, C17*25000, 0)) -> 0 | H17: =IF(B17>=80, B17*6000, 0) -> 0 | I17: =IF(E17>7000000, E17*0.06, IF(E17>5000000, E17*0.04, IF(E17>3000000, E17*0.03, 0))) -> 0 | J17: =G17+H17+I17 -> 0
A18: Phan Công Vũ Tài | B18: 11 | C18: 4 | D18: 11 | E18: 2179000 | F18: 1920000 | G18: =IF(C18>=10, C18*30000, IF(C18>=7, C18*25000, 0)) -> 0 | H18: =IF(B18>=80, B18*6000, 0) -> 0 | I18: =IF(E18>7000000, E18*0.06, IF(E18>5000000, E18*0.04, IF(E18>3000000, E18*0.03, 0))) -> 0 | J18: =G18+H18+I18 -> 0
A19: Đoàn Quốc Tâm | B19: 6 | C19: 5 | D19: 5 | E19: 1015000 | F19: 2400000 | G19: =IF(C19>=10, C19*30000, IF(C19>=7, C19*25000, 0)) -> 0 | H19: =IF(B19>=80, B19*6000, 0) -> 0 | I19: =IF(E19>7000000, E19*0.06, IF(E19>5000000, E19*0.04, IF(E19>3000000, E19*0.03, 0))) -> 0 | J19: =G19+H19+I19 -> 0
A20: Nguyễn Ngọc Thùy | B20: 1 | C20: 0 | D20: 1 | E20: 209000 | F20: 0 | G20: =IF(C20>=10, C20*30000, IF(C20>=7, C20*25000, 0)) -> 0 | H20: =IF(B20>=80, B20*6000, 0) -> 0 | I20: =IF(E20>7000000, E20*0.06, IF(E20>5000000, E20*0.04, IF(E20>3000000, E20*0.03, 0))) -> 0 | J20: =G20+H20+I20 -> 0
A21: Dương Thị Huỳnh Như | B21: 0 | C21: 0 | D21: 0 | E21: 0 | F21: 0 | G21: =IF(C21>=10, C21*30000, IF(C21>=7, C21*25000, 0)) -> 0 | H21: =IF(B21>=80, B21*6000, 0) -> 0 | I21: =IF(E21>7000000, E21*0.06, IF(E21>5000000, E21*0.04, IF(E21>3000000, E21*0.03, 0))) -> 0 | J21: =G21+H21+I21 -> 0
A22: Trần Thị Ánh Nguyệt | B22: 12 | C22: 1 | D22: 4 | E22: 746000 | F22: 480000 | G22: =IF(C22>=10, C22*30000, IF(C22>=7, C22*25000, 0)) -> 0 | H22: =IF(B22>=80, B22*6000, 0) -> 0 | I22: =IF(E22>7000000, E22*0.06, IF(E22>5000000, E22*0.04, IF(E22>3000000, E22*0.03, 0))) -> 0 | J22: =G22+H22+I22 -> 0
A23: Đỗ Thị Kim Tiến | B23: 8 | C23: 0 | D23: 1 | E23: 209000 | F23: 0 | G23: =IF(C23>=10, C23*30000, IF(C23>=7, C23*25000, 0)) -> 0 | H23: =IF(B23>=80, B23*6000, 0) -> 0 | I23: =IF(E23>7000000, E23*0.06, IF(E23>5000000, E23*0.04, IF(E23>3000000, E23*0.03, 0))) -> 0 | J23: =G23+H23+I23 -> 0
... A61: Trần Thị Phương Thùy | B61: 0 | C61: 0 | D61: 0 | E61: 0 | F61: 0 | G61: =IF(C61>=10, C61*30000, IF(C61>=7, C61*25000, 0)) -> 0 | H61: =IF(B61>=80, B61*6000, 0) -> 0 | I61: =IF(E61>7000000, E61*0.06, IF(E61>5000000, E61*0.04, IF(E61>3000000, E61*0.03, 0))) -> 0 | J61: =G61+H61+I61 -> 0

Sheet whatsapp
A1: Whatsapp - Người bán | B1: Doanh thu | C1: Hệ số thưởng | D1: Thưởng | F1: Ứng dụng nhắn tin Whatsapp
A2: Hồ Thị Minh Hòa | B2: 0 | C2: 0.015 | D2: =B2*C2 -> 0
A3: Nguyễn Trần Ngọc Phương | B3: 0 | C3: 0.015 | D3: =B3*C3 -> 0
A4: Nguyễn Ngọc Anh Thư | B4: 0 | C4: 0.015 | D4: =B4*C4 -> 0
A5: Trịnh Thị Phượng | B5: 0 | C5: 0.015 | D5: =B5*C5 -> 0
A6: Ngô Trần Tuyết Vy | B6: 0 | C6: 0.015 | D6: =B6*C6 -> 0
A7: Phạm Nguyễn Ngọc Quý | B7: 0 | C7: 0.015 | D7: =B7*C7 -> 0
A8: Trần Thị Kim Khánh | B8: 0 | C8: 0.015 | D8: =B8*C8 -> 0
A9: Ngô Thị Thanh Thắm | B9: 67046300 | C9: 0.04 | D9: =B9*C9 -> 2681852
A10: Dương Thị Huỳnh Như | B10: 0 | C10: 0.015 | D10: =B10*C10 -> 0
A11: Phạm Thị Nghĩa Hương | B11: 8501100 | C11: 0.04 | D11: =B11*C11 -> 340044
A12: Trần Thiên Phát | B12: 9377800 | C12: 0.04 | D12: =B12*C12 -> 375112
A13: Hoàng Lâm Gia Bảo | B13: 0 | C13: 0.015 | D13: =B13*C13 -> 0
... A71: Đỗ Thu Huệ | B71: 0 | C71: 0.015 | D71: =B71*C71 -> 0

Sheet Cận date
A1: Chi nhánh | B1: Tên nhân viên | C1: Thưởng cận Date | H1: Tên nhân viên | I1: Doanh thu cận date | J1: Thưởng cận date
A2: Trường Sa | B2: Hồ Thị Minh Hòa | C2: =IFERROR(INDEX(J:J, MATCH(B2, H:H, 0)), 0) -> 0 | H2: Hồ Thị Minh Hòa | I2: 0 | J2: =ROUND(I2*5%, 0) -> 0
A3: Trường Sa | B3: Nguyễn Trần Ngọc Phương | C3: =IFERROR(INDEX(J:J, MATCH(B3, H:H, 0)), 0) -> 6601 | H3: Nguyễn Trần Ngọc Phương | I3: 132013 | J3: =ROUND(I3*5%, 0) -> 6601
A4: Trường Sa | B4: Nguyễn Ngọc Anh Thư | C4: =IFERROR(INDEX(J:J, MATCH(B4, H:H, 0)), 0) -> 7700 | H4: Nguyễn Ngọc Anh Thư | I4: 154000 | J4: =ROUND(I4*5%, 0) -> 7700
A5: Trường Sa | B5: Trịnh Thị Phượng | C5: =IFERROR(INDEX(J:J, MATCH(B5, H:H, 0)), 0) -> 11205 | H5: Trịnh Thị Phượng | I5: 224100 | J5: =ROUND(I5*5%, 0) -> 11205
A6: Trường Sa | B6: Ngô Trần Tuyết Vy | C6: =IFERROR(INDEX(J:J, MATCH(B6, H:H, 0)), 0) -> 0 | H6: Ngô Trần Tuyết Vy | I6: 0 | J6: =ROUND(I6*5%, 0) -> 0
A7: Trường Sa | B7: Phạm Nguyễn Ngọc Quý | C7: =IFERROR(INDEX(J:J, MATCH(B7, H:H, 0)), 0) -> 18300 | H7: Phạm Nguyễn Ngọc Quý | I7: 366000 | J7: =ROUND(I7*5%, 0) -> 18300
A8: Trường Sa | B8: Trần Thị Kim Khánh | C8: =IFERROR(INDEX(J:J, MATCH(B8, H:H, 0)), 0) -> 46851 | H8: Trần Thị Kim Khánh | I8: 937027 | J8: =ROUND(I8*5%, 0) -> 46851
A9: Đỗ Quang Đẩu | B9: Ngô Thị Thanh Thắm | C9: =IFERROR(INDEX(J:J, MATCH(B9, H:H, 0)), 0) -> 14067 | H9: Ngô Thị Thanh Thắm | I9: 281343 | J9: =ROUND(I9*5%, 0) -> 14067
A10: Đỗ Quang Đẩu | B10: Dương Thị Huỳnh Như | C10: =IFERROR(INDEX(J:J, MATCH(B10, H:H, 0)), 0) -> 0 | H10: Dương Thị Huỳnh Như | I10: 0 | J10: =ROUND(I10*5%, 0) -> 0
