Workbook

Sheet data
A1: Nhà thuốc | B1: Tên nhân viên | C1: Số giao dịch off | D1: Doanh thu off | E1: Số giao dịch onl | F1: Doanh thu onl | G1: Tổng giao dịch | H1: Doanh thu tổng | J1: 46262
A2: Trường Sa | B2: Hồ Thị Minh Hòa | C2: 20 | D2: 1503600 | E2: 14 | F2: 2401800 | G2: 34 | H2: 3905400
A3: Trường Sa | B3: Medigo | E3: 2 | F3: 773000 | G3: 2 | H3: 773000
A4: Trường Sa | B4: Ngô Trần Tuyết Vy | C4: 273 | D4: 16360400 | E4: 168 | F4: 28002100 | G4: 441 | H4: 44362500
A5: Trường Sa | B5: Nguyễn Ngọc Anh Thư | C5: 124 | D5: 7987200 | E5: 111 | F5: 14358250 | G5: 235 | H5: 22345450
A6: Trường Sa | B6: Nguyễn Trần Ngọc Phương | C6: 359 | D6: 24147102 | E6: 222 | F6: 33293301 | G6: 581 | H6: 57440403
A7: Trường Sa | B7: Phạm Nguyễn Ngọc Quý | C7: 357 | D7: 25728300 | E7: 203 | F7: 39161850 | G7: 560 | H7: 64890150
A8: Trường Sa | B8: Trần Thị Kim Khánh | C8: 465 | D8: 43483900 | E8: 393 | F8: 111327600 | G8: 858 | H8: 154811500
A9: Trường Sa | B9: Trịnh Thị Phượng | C9: 578 | D9: 52334100 | E9: 152 | F9: 21958640 | G9: 730 | H9: 74292740
A10: Trường Sa
A12: Đỗ Quang Đẩu | B12: Hoàng Lâm Gia Bảo | C12: 22 | D12: 11025100 | E12: 3 | F12: 533000 | G12: 25 | H12: 11558100
A13: Đỗ Quang Đẩu | B13: Hoàng Thanh Thủy | C13: 570 | D13: 196157840 | E13: 205 | F13: 65403549 | G13: 775 | H13: 261561389
A14: Đỗ Quang Đẩu | B14: Lê Thị Huyền Trân | C14: 659 | D14: 125219600 | E14: 215 | F14: 45027700 | G14: 874 | H14: 170247300
A15: Đỗ Quang Đẩu | B15: Ngô Thị Thanh Thắm | C15: 381 | D15: 160380300 | E15: 135 | F15: 31240001 | G15: 516 | H15: 191620301
A16: Đỗ Quang Đẩu | B16: Phạm Thị Nghĩa Hương | C16: 485 | D16: 97146800 | E16: 132 | F16: 19113000 | G16: 617 | H16: 116259800
A17: Đỗ Quang Đẩu | B17: Trần Thiên Phát | C17: 508 | D17: 115542670 | E17: 125 | F17: 16581400 | G17: 633 | H17: 132124070
A18: Đỗ Quang Đẩu
A19: Đỗ Quang Đẩu
A21: Lê Bình | B21: Đinh Hoài Bảo | C21: 295 | D21: 24509200 | E21: 147 | F21: 22229750 | G21: 442 | H21: 46738950
A22: Lê Bình | B22: Hồ Thị Minh Hòa | C22: 298 | D22: 27340300 | E22: 103 | F22: 20564220 | G22: 401 | H22: 47904520
A23: Lê Bình | B23: Hoàng Lâm Gia Bảo | C23: 238 | D23: 27427500 | E23: 105 | F23: 21293500 | G23: 343 | H23: 48721000
A24: Lê Bình | B24: Lê Thị Xuyến | C24: 177 | D24: 13537000 | E24: 76 | F24: 10291300 | G24: 253 | H24: 23828300
A25: Lê Bình | B25: Nguyễn Thị Huyền Trang | C25: 15 | D25: 1259000 | E25: 1 | F25: 105000 | G25: 16 | H25: 1364000
A27: Minh Châu | B27: Đoàn Quốc Tâm | C27: 696 | D27: 59336500 | E27: 191 | F27: 29599100 | G27: 887 | H27: 88935600
A28: Minh Châu | B28: Nguyễn Ngọc Thùy | C28: 118 | D28: 8323800 | E28: 15 | F28: 1540850 | G28: 133 | H28: 9864650
A29: Minh Châu | B29: Phan Công Vũ Tài | C29: 1028 | D29: 84409594 | E29: 138 | F29: 20035250 | G29: 1166 | H29: 104444844
A30: Minh Châu | B30: Thái Thùy Linh | C30: 505 | D30: 41868700 | E30: 117 | F30: 18342950 | G30: 622 | H30: 60211650
A31: Minh Châu | B31: Trịnh Thị Phượng | C31: 264 | D31: 21942900 | E31: 28 | F31: 3104300 | G31: 292 | H31: 25047200
A34: Nam Hòa | B34: Bùi Thị Thanh Thủy | C34: 248 | D34: 17563028 | E34: 113 | F34: 27843550 | G34: 361 | H34: 45406578
A35: Nam Hòa | B35: Đỗ Thị Kim Tiến | C35: 120 | D35: 10080700 | E35: 35 | F35: 7887900 | G35: 155 | H35: 17968600
... A41: Nam Hòa | B41: Trần Thị Ánh Nguyệt | C41: 593 | D41: 45493300 | E41: 178 | F41: 27598600 | G41: 771 | H41: 73091900
A42: Nam Hòa
A43: Nam Hòa
A45: Nguyễn Chí Thanh | B45: Đỗ Thị Phương Thảo | C45: 346 | D45: 41488625 | E45: 219 | F45: 40219500 | G45: 565 | H45: 81708125
A46: Nguyễn Chí Thanh | B46: Lê Thị Quỳnh Trâm | C46: 290 | D46: 25411600 | E46: 206 | F46: 104707300 | G46: 496 | H46: 130118900
A47: Nguyễn Chí Thanh | B47: Nguyễn Thị Hồng Hạnh | C47: 725 | D47: 59614300 | E47: 94 | F47: 11636605 | G47: 819 | H47: 71250905
A48: Nguyễn Chí Thanh | B48: Nguyễn Trí Nghĩa | C48: 93 | D48: 4340800 | E48: 14 | F48: 1063100 | G48: 107 | H48: 5403900
A49: Nguyễn Chí Thanh | B49: Trần Hoàng Khánh | C49: 737 | D49: 52913400 | E49: 181 | F49: 28349070 | G49: 918 | H49: 81262470
A50: Nguyễn Chí Thanh
A51: Nguyễn Chí Thanh
...

Sheet kpi dược sĩ
A1: Dữ liệu cập nhật đến ngày | C1: =data!J1 -> 46262 | O1: Mức hoành thành KPI doanh thu/ngày | R1: Mức hoành thành KPI doanh thu/ngày
A2: Nhà thuốc | B2: Nhân viên | C2: Chức danh | D2: KPI trung bình bill | E2: Trung bình bill | F2: KPI doanh thu CK+Combo+NY3/ngày | G2: CK + Combo + NY3/ngày | H2: KPI Doanh thu/ngày (100%) | I2: Doanh thu thực/ngày | J2: % Hoàn thành KPI | K2: Thưởng KPI | L2: Hệ số * Dự án | M2: Thưởng Dự án | N2: Thưởng Dự án + KPI + HH | O2: 0.8 | P2: 0.9 | Q2: 1 | R2: 0.8 | S2: 0.9 | T2: 1 | U2: KPIs Doanh thu/ngày | V2: KPIs Doanh thu/tháng | W2: Số giao dịch off | X2: Doanh thu off | Y2: Trung bình bill off | Z2: Số giao dịch onl | AA2: Doanh thu onl | AB2: Trung bình bill onl | AC2: Tổng giao dịch | AD2: Doanh thu tổng | AE2: Trung bình Bill
A3: Hàng Bông | B3: Đinh Thị Lan Anh | C3: CHT | D3: 150000 | E3: =AE3 -> 187790.06 | F3: {=IFERROR( ROUND( _xludf.LET( nt,$A3, nv,$B3, songay,DAY(EOMONTH($C$1,0)), doanhthungay,$I3, duan_nv,SUM_xlfn.IFS('Dự án T8'!$D:$D,'Dự án T8'!$A:$A,nt,'Dự án T8'!$B:$B,nv), duan_nt,SUM_xlfn.IFS('Dự án T8'!$D:$D,'Dự án T8'!$A:$A,nt), tyle,duan_nv/duan_nt, muc2_ngay,_xlfn.XLOOKUP(nt,'kpi nhà thuốc'!$B:$B,'kpi nhà thuốc'!$P:$P), muc3_ngay,_xlfn.XLOOKUP(nt,'kpi nhà thuốc'!$B:$B,'kpi nhà thuốc'!$T:$T), hangdiem1,_xlfn.XLOOKUP(nt,'kpi nhà thuốc'!$B:$B,'kpi nhà thuốc'!$I:$I), hangdiem2,_xlfn.XLOOKUP(nt,'kpi nhà thuốc'!$B:$B,'kpi nhà thuốc'!$N:$N), hangdiem3,_xlfn.XLOOKUP(nt,'kpi nhà thuốc'!$B:$B,'kpi nhà thuốc'!$R:$R), _xludf.SWITCH(TRUE, doanhthungay>=muc3_ngay,hangdiem3, doanhthungay>=muc2_ngay,hangdiem2, TRUE,hangdiem1 )/songay*tyle ), -3), 0)} -> 0 | G3: {=_xlfn.XLOOKUP(B3,'Dự án T8'!B:B,'Dự án T8'!D:D,0)} -> 2758480.5 | H3: =Q3 -> 8800000 | I3: =(AD3/DAY($C$1)) -> 4560615.8 | J3: {=_xlfn.XLOOKUP(B3,'kpi nhà thuốc'!A:A,'kpi nhà thuốc'!F:F,(AD3/DAY($C$1))/U3)} -> 0.8070668 | K3: {=_xlfn.XLOOKUP( B3, 'kpi nhà thuốc'!A:A, 'kpi nhà thuốc'!G:G, IF( AND( OR(C3="DSXC",C3="DSCD"), G3>=F3),IF(AND(I3>=T3,E3>=D3),AD3*1.5%,IF(AND(I3>=T3,E3<D3),AD3*1.3%,IF(AND(I3>=S3,E3>=D3),AD3*1.3%,IF(AND(I3>=S3,E3<D3),AD3*1.1%,IF(AND(I3>=R3,E3>=D3),AD3*1.2%,IF(AND(I3>=R3,E3<D3),AD3*1%,"")))))),"" ) )} -> #NAME? | L3: =IF(C3="DSTV","", IF(J3<0.6, 0.8, 1)) -> 1 | M3: {=IFERROR( _xlfn.XLOOKUP( $A3&$B3, 'Dự án T8'!$A:$A&'Dự án T8'!$B:$B, 'Dự án T8'!$M:$M, 0 )*$L3, 0)} -> 600000 | N3: =K3+M3*L3 -> #NAME? | O3: =CEILING(R3,100000) -> 7000000 | P3: =CEILING(S3,100000) -> 7900000 | Q3: =CEILING(T3,100000) -> 8800000 | R3: =U3*$R$2 -> 6967741.9 | S3: =U3*$S$2 -> 7838709.7 | T3: =U3*$T$2 -> 8709677.4 | U3: =V3/DAY('kpi nhà thuốc'!$T$1) -> 8709677.4 | V3: 270000000 | W3: =SUMIF(data!$B:$B,B3,data!$C:$C) -> 554 | X3: =SUMIF(data!$B:$B,B3,data!$D:$D) -> 103518742 | Y3: =IF(W3>0,X3/W3,0) -> 186856.94 | Z3: =SUMIF(data!$B:$B,B3,data!$E:$E) -> 126 | AA3: =SUMIF(data!$B:$B,B3,data!$F:$F) -> 24178501 | AB3: =IF(Z3>0,AA3/Z3,0) -> 191892.87 | AC3: =W3+Z3 -> 680 | AD3: =X3+AA3 -> 127697243 | AE3: =IF(AC3>0,AD3/AC3,0) -> 187790.06
A4: Hàng Bông | B4: Vũ Thanh Hằng | C4: DSXC | D4: 245000 | E4: =AE4 -> 326285.32 | F4: {=IFERROR( ROUND( _xludf.LET( nt,$A4, nv,$B4, songay,DAY(EOMONTH($C$1,0)), doanhthungay,$I4, duan_nv,SUM_xlfn.IFS('Dự án T8'!$D:$D,'Dự án T8'!$A:$A,nt,'Dự án T8'!$B:$B,nv), duan_nt,SUM_xlfn.IFS('Dự án T8'!$D:$D,'Dự án T8'!$A:$A,nt), tyle,duan_nv/duan_nt, muc2_ngay,_xlfn.XLOOKUP(nt,'kpi nhà thuốc'!$B:$B,'kpi nhà thuốc'!$P:$P), muc3_ngay,_xlfn.XLOOKUP(nt,'kpi nhà thuốc'!$B:$B,'kpi nhà thuốc'!$T:$T), hangdiem1,_xlfn.XLOOKUP(nt,'kpi nhà thuốc'!$B:$B,'kpi nhà thuốc'!$I:$I), hangdiem2,_xlfn.XLOOKUP(nt,'kpi nhà thuốc'!$B:$B,'kpi nhà thuốc'!$N:$N), hangdiem3,_xlfn.XLOOKUP(nt,'kpi nhà thuốc'!$B:$B,'kpi nhà thuốc'!$R:$R), _xludf.SWITCH(TRUE, doanhthungay>=muc3_ngay,hangdiem3, doanhthungay>=muc2_ngay,hangdiem2, TRUE,hangdiem1 )/songay*tyle ), -3), 0)} -> 0 | G4: {=_xlfn.XLOOKUP(B4,'Dự án T8'!B:B,'Dự án T8'!D:D,0)} -> 8078076.9 | H4: =Q4 -> 11300000 | I4: =(AD4/DAY($C$1)) -> 11466598 | J4: {=_xlfn.XLOOKUP(B4,'kpi nhà thuốc'!A:A,'kpi nhà thuốc'!F:F,(AD4/DAY($C$1))/U4)} -> 1.015613 | K4: {=_xlfn.XLOOKUP( B4, 'kpi nhà thuốc'!A:A, 'kpi nhà thuốc'!G:G, IF( AND( OR(C4="DSXC",C4="DSCD"), G4>=F4),IF(AND(I4>=T4,E4>=D4),AD4*1.5%,IF(AND(I4>=T4,E4<D4),AD4*1.3%,IF(AND(I4>=S4,E4>=D4),AD4*1.3%,IF(AND(I4>=S4,E4<D4),AD4*1.1%,IF(AND(I4>=R4,E4>=D4),AD4*1.2%,IF(AND(I4>=R4,E4<D4),AD4*1%,"")))))),"" ) )} -> #NAME? | L4: =IF(C4="DSTV","", IF(J4<0.6, 0.8, 1)) -> 1 | M4: {=IFERROR( _xlfn.XLOOKUP( $A4&$B4, 'Dự án T8'!$A:$A&'Dự án T8'!$B:$B, 'Dự án T8'!$M:$M, 0 )*$L4, 0)} -> 1400000 | N4: =K4+M4*L4 -> #NAME? | O4: =CEILING(R4,100000) -> 9100000 | P4: =CEILING(S4,100000) -> 10200000 | Q4: =CEILING(T4,100000) -> 11300000 | R4: =U4*$R$2 -> 9032258.1 | S4: =U4*$S$2 -> 10161290 | T4: =U4*$T$2 -> 11290323 | U4: =V4/DAY('kpi nhà thuốc'!$T$1) -> 11290323 | V4: 350000000 | W4: =SUMIF(data!$B:$B,B4,data!$C:$C) -> 794 | X4: =SUMIF(data!$B:$B,B4,data!$D:$D) -> 267188160 | Y4: =IF(W4>0,X4/W4,0) -> 336509.02 | Z4: =SUMIF(data!$B:$B,B4,data!$E:$E) -> 190 | AA4: =SUMIF(data!$B:$B,B4,data!$F:$F) -> 53876597 | AB4: =IF(Z4>0,AA4/Z4,0) -> 283561.04 | AC4: =W4+Z4 -> 984 | AD4: =X4+AA4 -> 321064757 | AE4: =IF(AC4>0,AD4/AC4,0) -> 326285.32
A5: Hàng Bông | B5: Nguyễn Mạnh Tuấn | C5: DSCD | D5: 250000 | E5: =AE5 -> 173037.08 | F5: {=IFERROR( ROUND( _xludf.LET( nt,$A5, nv,$B5, songay,DAY(EOMONTH($C$1,0)), doanhthungay,$I5, duan_nv,SUM_xlfn.IFS('Dự án T8'!$D:$D,'Dự án T8'!$A:$A,nt,'Dự án T8'!$B:$B,nv), duan_nt,SUM_xlfn.IFS('Dự án T8'!$D:$D,'Dự án T8'!$A:$A,nt), tyle,duan_nv/duan_nt, muc2_ngay,_xlfn.XLOOKUP(nt,'kpi nhà thuốc'!$B:$B,'kpi nhà thuốc'!$P:$P), muc3_ngay,_xlfn.XLOOKUP(nt,'kpi nhà thuốc'!$B:$B,'kpi nhà thuốc'!$T:$T), hangdiem1,_xlfn.XLOOKUP(nt,'kpi nhà thuốc'!$B:$B,'kpi nhà thuốc'!$I:$I), hangdiem2,_xlfn.XLOOKUP(nt,'kpi nhà thuốc'!$B:$B,'kpi nhà thuốc'!$N:$N), hangdiem3,_xlfn.XLOOKUP(nt,'kpi nhà thuốc'!$B:$B,'kpi nhà thuốc'!$R:$R), _xludf.SWITCH(TRUE, doanhthungay>=muc3_ngay,hangdiem3, doanhthungay>=muc2_ngay,hangdiem2, TRUE,hangdiem1 )/songay*tyle ), -3), 0)} -> 0 | G5: {=_xlfn.XLOOKUP(B5,'Dự án T8'!B:B,'Dự án T8'!D:D,0)} -> 2185630.4 | H5: =Q5 -> 9700000 | I5: =(AD5/DAY($C$1)) -> 6890583.6 | J5: {=_xlfn.XLOOKUP(B5,'kpi nhà thuốc'!A:A,'kpi nhà thuốc'!F:F,(AD5/DAY($C$1))/U5)} -> 0.71202697 | K5: {=_xlfn.XLOOKUP( B5, 'kpi nhà thuốc'!A:A, 'kpi nhà thuốc'!G:G, IF( AND( OR(C5="DSXC",C5="DSCD"), G5>=F5),IF(AND(I5>=T5,E5>=D5),AD5*1.5%,IF(AND(I5>=T5,E5<D5),AD5*1.3%,IF(AND(I5>=S5,E5>=D5),AD5*1.3%,IF(AND(I5>=S5,E5<D5),AD5*1.1%,IF(AND(I5>=R5,E5>=D5),AD5*1.2%,IF(AND(I5>=R5,E5<D5),AD5*1%,"")))))),"" ) )} -> #NAME? | L5: =IF(C5="DSTV","", IF(J5<0.6, 0.8, 1)) -> 1 | M5: {=IFERROR( _xlfn.XLOOKUP( $A5&$B5, 'Dự án T8'!$A:$A&'Dự án T8'!$B:$B, 'Dự án T8'!$M:$M, 0 )*$L5, 0)} -> 600000 | N5: =K5+M5*L5 -> #NAME? | O5: =CEILING(R5,100000) -> 7800000 | P5: =CEILING(S5,100000) -> 8800000 | Q5: =CEILING(T5,100000) -> 9700000 | R5: =U5*$R$2 -> 7741935.5 | S5: =U5*$S$2 -> 8709677.4 | T5: =U5*$T$2 -> 9677419.4 | U5: =V5/DAY('kpi nhà thuốc'!$T$1) -> 9677419.4 | V5: 300000000 | W5: =SUMIF(data!$B:$B,B5,data!$C:$C) -> 715 | X5: =SUMIF(data!$B:$B,B5,data!$D:$D) -> 127357340 | Y5: =IF(W5>0,X5/W5,0) -> 178122.15 | Z5: =SUMIF(data!$B:$B,B5,data!$E:$E) -> 400 | AA5: =SUMIF(data!$B:$B,B5,data!$F:$F) -> 65579000 | AB5: =IF(Z5>0,AA5/Z5,0) -> 163947.5 | AC5: =W5+Z5 -> 1115 | AD5: =X5+AA5 -> 192936340 | AE5: =IF(AC5>0,AD5/AC5,0) -> 173037.08
A6: Hàng Bông | B6: Đinh Thị Khánh Ly | C6: DSXC | D6: 204000 | E6: =AE6 -> 245748.6 | F6: {=IFERROR( ROUND( _xludf.LET( nt,$A6, nv,$B6, songay,DAY(EOMONTH($C$1,0)), doanhthungay,$I6, duan_nv,SUM_xlfn.IFS('Dự án T8'!$D:$D,'Dự án T8'!$A:$A,nt,'Dự án T8'!$B:$B,nv), duan_nt,SUM_xlfn.IFS('Dự án T8'!$D:$D,'Dự án T8'!$A:$A,nt), tyle,duan_nv/duan_nt, muc2_ngay,_xlfn.XLOOKUP(nt,'kpi nhà thuốc'!$B:$B,'kpi nhà thuốc'!$P:$P), muc3_ngay,_xlfn.XLOOKUP(nt,'kpi nhà thuốc'!$B:$B,'kpi nhà thuốc'!$T:$T), hangdiem1,_xlfn.XLOOKUP(nt,'kpi nhà thuốc'!$B:$B,'kpi nhà thuốc'!$I:$I), hangdiem2,_xlfn.XLOOKUP(nt,'kpi nhà thuốc'!$B:$B,'kpi nhà thuốc'!$N:$N), hangdiem3,_xlfn.XLOOKUP(nt,'kpi nhà thuốc'!$B:$B,'kpi nhà thuốc'!$R:$R), _xludf.SWITCH(TRUE, doanhthungay>=muc3_ngay,hangdiem3, doanhthungay>=muc2_ngay,hangdiem2, TRUE,hangdiem1 )/songay*tyle ), -3), 0)} -> 0 | G6: {=_xlfn.XLOOKUP(B6,'Dự án T8'!B:B,'Dự án T8'!D:D,0)} -> 3697575.1 | H6: =Q6 -> 11300000 | I6: =(AD6/DAY($C$1)) -> 10145907 | J6: {=_xlfn.XLOOKUP(B6,'kpi nhà thuốc'!A:A,'kpi nhà thuốc'!F:F,(AD6/DAY($C$1))/U6)} -> 0.89863744 | K6: {=_xlfn.XLOOKUP( B6, 'kpi nhà thuốc'!A:A, 'kpi nhà thuốc'!G:G, IF( AND( OR(C6="DSXC",C6="DSCD"), G6>=F6),IF(AND(I6>=T6,E6>=D6),AD6*1.5%,IF(AND(I6>=T6,E6<D6),AD6*1.3%,IF(AND(I6>=S6,E6>=D6),AD6*1.3%,IF(AND(I6>=S6,E6<D6),AD6*1.1%,IF(AND(I6>=R6,E6>=D6),AD6*1.2%,IF(AND(I6>=R6,E6<D6),AD6*1%,"")))))),"" ) )} -> #NAME? | L6: =IF(C6="DSTV","", IF(J6<0.6, 0.8, 1)) -> 1 | M6: {=IFERROR( _xlfn.XLOOKUP( $A6&$B6, 'Dự án T8'!$A:$A&'Dự án T8'!$B:$B, 'Dự án T8'!$M:$M, 0 )*$L6, 0)} -> 850000 | N6: =K6+M6*L6 -> #NAME? | O6: =CEILING(R6,100000) -> 9100000 | P6: =CEILING(S6,100000) -> 10200000 | Q6: =CEILING(T6,100000) -> 11300000 | R6: =U6*$R$2 -> 9032258.1 | S6: =U6*$S$2 -> 10161290 | T6: =U6*$T$2 -> 11290323 | U6: =V6/DAY('kpi nhà thuốc'!$T$1) -> 11290323 | V6: 350000000 | W6: =SUMIF(data!$B:$B,B6,data!$C:$C) -> 909 | X6: =SUMIF(data!$B:$B,B6,data!$D:$D) -> 227340258 | Y6: =IF(W6>0,X6/W6,0) -> 250099.29 | Z6: =SUMIF(data!$B:$B,B6,data!$E:$E) -> 247 | AA6: =SUMIF(data!$B:$B,B6,data!$F:$F) -> 56745127 | AB6: =IF(Z6>0,AA6/Z6,0) -> 229737.36 | AC6: =W6+Z6 -> 1156 | AD6: =X6+AA6 -> 284085385 | AE6: =IF(AC6>0,AD6/AC6,0) -> 245748.6
A7: Đường Láng | B7: Hứa Thị Kim Thoa | C7: CHT | D7: 150000 | E7: =AE7 -> 166213.64 | F7: {=IFERROR( ROUND( _xludf.LET( nt,$A7, nv,$B7, songay,DAY(EOMONTH($C$1,0)), doanhthungay,$I7, duan_nv,SUM_xlfn.IFS('Dự án T8'!$D:$D,'Dự án T8'!$A:$A,nt,'Dự án T8'!$B:$B,nv), duan_nt,SUM_xlfn.IFS('Dự án T8'!$D:$D,'Dự án T8'!$A:$A,nt), tyle,duan_nv/duan_nt, muc2_ngay,_xlfn.XLOOKUP(nt,'kpi nhà thuốc'!$B:$B,'kpi nhà thuốc'!$P:$P), muc3_ngay,_xlfn.XLOOKUP(nt,'kpi nhà thuốc'!$B:$B,'kpi nhà thuốc'!$T:$T), hangdiem1,_xlfn.XLOOKUP(nt,'kpi nhà thuốc'!$B:$B,'kpi nhà thuốc'!$I:$I), hangdiem2,_xlfn.XLOOKUP(nt,'kpi nhà thuốc'!$B:$B,'kpi nhà thuốc'!$N:$N), hangdiem3,_xlfn.XLOOKUP(nt,'kpi nhà thuốc'!$B:$B,'kpi nhà thuốc'!$R:$R), _xludf.SWITCH(TRUE, doanhthungay>=muc3_ngay,hangdiem3, doanhthungay>=muc2_ngay,hangdiem2, TRUE,hangdiem1 )/songay*tyle ), -3), 0)} -> 0 | G7: {=_xlfn.XLOOKUP(B7,'Dự án T8'!B:B,'Dự án T8'!D:D,0)} -> 268285.64 | H7: =Q7 -> 3900000 | I7: =(AD7/DAY($C$1)) -> 1044771.4 | J7: {=_xlfn.XLOOKUP(B7,'kpi nhà thuốc'!A:A,'kpi nhà thuốc'!F:F,(AD7/DAY($C$1))/U7)} -> 0.79120316 | K7: {=_xlfn.XLOOKUP( B7, 'kpi nhà thuốc'!A:A, 'kpi nhà thuốc'!G:G, IF( AND( OR(C7="DSXC",C7="DSCD"), G7>=F7),IF(AND(I7>=T7,E7>=D7),AD7*1.5%,IF(AND(I7>=T7,E7<D7),AD7*1.3%,IF(AND(I7>=S7,E7>=D7),AD7*1.3%,IF(AND(I7>=S7,E7<D7),AD7*1.1%,IF(AND(I7>=R7,E7>=D7),AD7*1.2%,IF(AND(I7>=R7,E7<D7),AD7*1%,"")))))),"" ) )} -> 0 | L7: =IF(C7="DSTV","", IF(J7<0.6, 0.8, 1)) -> 1 | M7: {=IFERROR( _xlfn.XLOOKUP( $A7&$B7, 'Dự án T8'!$A:$A&'Dự án T8'!$B:$B, 'Dự án T8'!$M:$M, 0 )*$L7, 0)} -> 0 | N7: =K7+M7*L7 -> 0 | O7: =CEILING(R7,100000) -> 3100000 | P7: =CEILING(S7,100000) -> 3500000 | Q7: =CEILING(T7,100000) -> 3900000 | R7: =U7*$R$2 -> 3096774.2 | S7: =U7*$S$2 -> 3483871 | T7: =U7*$T$2 -> 3870967.7 | U7: =V7/DAY('kpi nhà thuốc'!$T$1) -> 3870967.7 | V7: 120000000 | W7: =SUMIF(data!$B:$B,B7,data!$C:$C) -> 134 | X7: =SUMIF(data!$B:$B,B7,data!$D:$D) -> 11932300 | Y7: =IF(W7>0,X7/W7,0) -> 89047.015 | Z7: =SUMIF(data!$B:$B,B7,data!$E:$E) -> 42 | AA7: =SUMIF(data!$B:$B,B7,data!$F:$F) -> 17321300 | AB7: =IF(Z7>0,AA7/Z7,0) -> 412411.9 | AC7: =W7+Z7 -> 176 | AD7: =X7+AA7 -> 29253600 | AE7: =IF(AC7>0,AD7/AC7,0) -> 166213.64
A8: Đường Láng | B8: Lê Thị Soạn | C8: DSCD | D8: 183000 | E8: =AE8 -> 130638.68 | F8: {=IFERROR( ROUND( _xludf.LET( nt,$A8, nv,$B8, songay,DAY(EOMONTH($C$1,0)), doanhthungay,$I8, duan_nv,SUM_xlfn.IFS('Dự án T8'!$D:$D,'Dự án T8'!$A:$A,nt,'Dự án T8'!$B:$B,nv), duan_nt,SUM_xlfn.IFS('Dự án T8'!$D:$D,'Dự án T8'!$A:$A,nt), tyle,duan_nv/duan_nt, muc2_ngay,_xlfn.XLOOKUP(nt,'kpi nhà thuốc'!$B:$B,'kpi nhà thuốc'!$P:$P), muc3_ngay,_xlfn.XLOOKUP(nt,'kpi nhà thuốc'!$B:$B,'kpi nhà thuốc'!$T:$T), hangdiem1,_xlfn.XLOOKUP(nt,'kpi nhà thuốc'!$B:$B,'kpi nhà thuốc'!$I:$I), hangdiem2,_xlfn.XLOOKUP(nt,'kpi nhà thuốc'!$B:$B,'kpi nhà thuốc'!$N:$N), hangdiem3,_xlfn.XLOOKUP(nt,'kpi nhà thuốc'!$B:$B,'kpi nhà thuốc'!$R:$R), _xludf.SWITCH(TRUE, doanhthungay>=muc3_ngay,hangdiem3, doanhthungay>=muc2_ngay,hangdiem2, TRUE,hangdiem1 )/songay*tyle ), -3), 0)} -> 0 | G8: {=_xlfn.XLOOKUP(B8,'Dự án T8'!B:B,'Dự án T8'!D:D,0)} -> 3421012 | H8: =Q8 -> 7500000 | I8: =(AD8/DAY($C$1)) -> 6032707.7 | J8: {=_xlfn.XLOOKUP(B8,'kpi nhà thuốc'!A:A,'kpi nhà thuốc'!F:F,(AD8/DAY($C$1))/U8)} -> 0.81310408 | K8: {=_xlfn.XLOOKUP( B8, 'kpi nhà thuốc'!A:A, 'kpi nhà thuốc'!G:G, IF( AND( OR(C8="DSXC",C8="DSCD"), G8>=F8),IF(AND(I8>=T8,E8>=D8),AD8*1.5%,IF(AND(I8>=T8,E8<D8),AD8*1.3%,IF(AND(I8>=S8,E8>=D8),AD8*1.3%,IF(AND(I8>=S8,E8<D8),AD8*1.1%,IF(AND(I8>=R8,E8>=D8),AD8*1.2%,IF(AND(I8>=R8,E8<D8),AD8*1%,"")))))),"" ) )} -> #NAME? | L8: =IF(C8="DSTV","", IF(J8<0.6, 0.8, 1)) -> 1 | M8: {=IFERROR( _xlfn.XLOOKUP( $A8&$B8, 'Dự án T8'!$A:$A&'Dự án T8'!$B:$B, 'Dự án T8'!$M:$M, 0 )*$L8, 0)} -> 550000 | N8: =K8+M8*L8 -> #NAME? | O8: =CEILING(R8,100000) -> 6000000 | P8: =CEILING(S8,100000) -> 6700000 | Q8: =CEILING(T8,100000) -> 7500000 | R8: =U8*$R$2 -> 5935483.9 | S8: =U8*$S$2 -> 6677419.4 | T8: =U8*$T$2 -> 7419354.8 | U8: =V8/DAY('kpi nhà thuốc'!$T$1) -> 7419354.8 | V8: 230000000 | W8: =SUMIF(data!$B:$B,B8,data!$C:$C) -> 745 | X8: =SUMIF(data!$B:$B,B8,data!$D:$D) -> 84823161 | Y8: =IF(W8>0,X8/W8,0) -> 113856.59 | Z8: =SUMIF(data!$B:$B,B8,data!$E:$E) -> 548 | AA8: =SUMIF(data!$B:$B,B8,data!$F:$F) -> 84092655 | AB8: =IF(Z8>0,AA8/Z8,0) -> 153453.75 | AC8: =W8+Z8 -> 1293 | AD8: =X8+AA8 -> 168915816 | AE8: =IF(AC8>0,AD8/AC8,0) -> 130638.68
A9: Đường Láng | B9: Nguyễn Thị Tâm | C9: DSXC | D9: 178000 | E9: =AE9 -> 171563.8 | F9: {=IFERROR( ROUND( _xludf.LET( nt,$A9, nv,$B9, songay,DAY(EOMONTH($C$1,0)), doanhthungay,$I9, duan_nv,SUM_xlfn.IFS('Dự án T8'!$D:$D,'Dự án T8'!$A:$A,nt,'Dự án T8'!$B:$B,nv), duan_nt,SUM_xlfn.IFS('Dự án T8'!$D:$D,'Dự án T8'!$A:$A,nt), tyle,duan_nv/duan_nt, muc2_ngay,_xlfn.XLOOKUP(nt,'kpi nhà thuốc'!$B:$B,'kpi nhà thuốc'!$P:$P), muc3_ngay,_xlfn.XLOOKUP(nt,'kpi nhà thuốc'!$B:$B,'kpi nhà thuốc'!$T:$T), hangdiem1,_xlfn.XLOOKUP(nt,'kpi nhà thuốc'!$B:$B,'kpi nhà thuốc'!$I:$I), hangdiem2,_xlfn.XLOOKUP(nt,'kpi nhà thuốc'!$B:$B,'kpi nhà thuốc'!$N:$N), hangdiem3,_xlfn.XLOOKUP(nt,'kpi nhà thuốc'!$B:$B,'kpi nhà thuốc'!$R:$R), _xludf.SWITCH(TRUE, doanhthungay>=muc3_ngay,hangdiem3, doanhthungay>=muc2_ngay,hangdiem2, TRUE,hangdiem1 )/songay*tyle ), -3), 0)} -> 0 | G9: {=_xlfn.XLOOKUP(B9,'Dự án T8'!B:B,'Dự án T8'!D:D,0)} -> 2881220.8 | H9: =Q9 -> 6500000 | I9: =(AD9/DAY($C$1)) -> 5943460.2 | J9: {=_xlfn.XLOOKUP(B9,'kpi nhà thuốc'!A:A,'kpi nhà thuốc'!F:F,(AD9/DAY($C$1))/U9)} -> 0.92123633 | K9: {=_xlfn.XLOOKUP( B9, 'kpi nhà thuốc'!A:A, 'kpi nhà thuốc'!G:G, IF( AND( OR(C9="DSXC",C9="DSCD"), G9>=F9),IF(AND(I9>=T9,E9>=D9),AD9*1.5%,IF(AND(I9>=T9,E9<D9),AD9*1.3%,IF(AND(I9>=S9,E9>=D9),AD9*1.3%,IF(AND(I9>=S9,E9<D9),AD9*1.1%,IF(AND(I9>=R9,E9>=D9),AD9*1.2%,IF(AND(I9>=R9,E9<D9),AD9*1%,"")))))),"" ) )} -> #NAME? | L9: =IF(C9="DSTV","", IF(J9<0.6, 0.8, 1)) -> 1 | M9: {=IFERROR( _xlfn.XLOOKUP( $A9&$B9, 'Dự án T8'!$A:$A&'Dự án T8'!$B:$B, 'Dự án T8'!$M:$M, 0 )*$L9, 0)} -> 600000 | N9: =K9+M9*L9 -> #NAME? | O9: =CEILING(R9,100000) -> 5200000 | P9: =CEILING(S9,100000) -> 5900000 | Q9: =CEILING(T9,100000) -> 6500000 | R9: =U9*$R$2 -> 5161290.3 | S9: =U9*$S$2 -> 5806451.6 | T9: =U9*$T$2 -> 6451612.9 | U9: =V9/DAY('kpi nhà thuốc'!$T$1) -> 6451612.9 | V9: 200000000 | W9: =SUMIF(data!$B:$B,B9,data!$C:$C) -> 572 | X9: =SUMIF(data!$B:$B,B9,data!$D:$D) -> 69209294 | Y9: =IF(W9>0,X9/W9,0) -> 120995.27 | Z9: =SUMIF(data!$B:$B,B9,data!$E:$E) -> 398 | AA9: =SUMIF(data!$B:$B,B9,data!$F:$F) -> 97207592 | AB9: =IF(Z9>0,AA9/Z9,0) -> 244240.18 | AC9: =W9+Z9 -> 970 | AD9: =X9+AA9 -> 166416886 | AE9: =IF(AC9>0,AD9/AC9,0) -> 171563.8
A10: Đường Láng | B10: Nguyễn Thị Mai Duyên | C10: DSXC | D10: 241000 | E10: =AE10 -> 220068.96 | F10: {=IFERROR( ROUND( _xludf.LET( nt,$A10, nv,$B10, songay,DAY(EOMONTH($C$1,0)), doanhthungay,$I10, duan_nv,SUM_xlfn.IFS('Dự án T8'!$D:$D,'Dự án T8'!$A:$A,nt,'Dự án T8'!$B:$B,nv), duan_nt,SUM_xlfn.IFS('Dự án T8'!$D:$D,'Dự án T8'!$A:$A,nt), tyle,duan_nv/duan_nt, muc2_ngay,_xlfn.XLOOKUP(nt,'kpi nhà thuốc'!$B:$B,'kpi nhà thuốc'!$P:$P), muc3_ngay,_xlfn.XLOOKUP(nt,'kpi nhà thuốc'!$B:$B,'kpi nhà thuốc'!$T:$T), hangdiem1,_xlfn.XLOOKUP(nt,'kpi nhà thuốc'!$B:$B,'kpi nhà thuốc'!$I:$I), hangdiem2,_xlfn.XLOOKUP(nt,'kpi nhà thuốc'!$B:$B,'kpi nhà thuốc'!$N:$N), hangdiem3,_xlfn.XLOOKUP(nt,'kpi nhà thuốc'!$B:$B,'kpi nhà thuốc'!$R:$R), _xludf.SWITCH(TRUE, doanhthungay>=muc3_ngay,hangdiem3, doanhthungay>=muc2_ngay,hangdiem2, TRUE,hangdiem1 )/songay*tyle ), -3), 0)} -> 0 | G10: {=_xlfn.XLOOKUP(B10,'Dự án T8'!B:B,'Dự án T8'!D:D,0)} -> 3368580.7 | H10: =Q10 -> 7500000 | I10: =(AD10/DAY($C$1)) -> 7285854.5 | J10: {=_xlfn.XLOOKUP(B10,'kpi nhà thuốc'!A:A,'kpi nhà thuốc'!F:F,(AD10/DAY($C$1))/U10)} -> 0.98200648 | K10: {=_xlfn.XLOOKUP( B10, 'kpi nhà thuốc'!A:A, 'kpi nhà thuốc'!G:G, IF( AND( OR(C10="DSXC",C10="DSCD"), G10>=F10),IF(AND(I10>=T10,E10>=D10),AD10*1.5%,IF(AND(I10>=T10,E10<D10),AD10*1.3%,IF(AND(I10>=S10,E10>=D10),AD10*1.3%,IF(AND(I10>=S10,E10<D10),AD10*1.1%,IF(AND(I10>=R10,E10>=D10),AD10*1.2%,IF(AND(I10>=R10,E10<D10),AD10*1%,"")))))),"" ) )} -> #NAME? | L10: =IF(C10="DSTV","", IF(J10<0.6, 0.8, 1)) -> 1 | M10: {=IFERROR( _xlfn.XLOOKUP( $A10&$B10, 'Dự án T8'!$A:$A&'Dự án T8'!$B:$B, 'Dự án T8'!$M:$M, 0 )*$L10, 0)} -> 700000 | N10: =K10+M10*L10 -> #NAME? | O10: =CEILING(R10,100000) -> 6000000 | P10: =CEILING(S10,100000) -> 6700000 | Q10: =CEILING(T10,100000) -> 7500000 | R10: =U10*$R$2 -> 5935483.9 | S10: =U10*$S$2 -> 6677419.4 | T10: =U10*$T$2 -> 7419354.8 | U10: =V10/DAY('kpi nhà thuốc'!$T$1) -> 7419354.8 | V10: 230000000 | W10: =SUMIF(data!$B:$B,B10,data!$C:$C) -> 411 | X10: =SUMIF(data!$B:$B,B10,data!$D:$D) -> 52500960 | Y10: =IF(W10>0,X10/W10,0) -> 127739.56 | Z10: =SUMIF(data!$B:$B,B10,data!$E:$E) -> 516 | AA10: =SUMIF(data!$B:$B,B10,data!$F:$F) -> 151502967 | AB10: =IF(Z10>0,AA10/Z10,0) -> 293610.4 | AC10: =W10+Z10 -> 927 | AD10: =X10+AA10 -> 204003927 | AE10: =IF(AC10>0,AD10/AC10,0) -> 220068.96
A11: Đường Láng | B11: Trần Ngọc Dung | C11: DSXC | D11: 150000 | E11: =AE11 -> 217054.66 | F11: {=IFERROR( ROUND( _xludf.LET( nt,$A11, nv,$B11, songay,DAY(EOMONTH($C$1,0)), doanhthungay,$I11, duan_nv,SUM_xlfn.IFS('Dự án T8'!$D:$D,'Dự án T8'!$A:$A,nt,'Dự án T8'!$B:$B,nv), duan_nt,SUM_xlfn.IFS('Dự án T8'!$D:$D,'Dự án T8'!$A:$A,nt), tyle,duan_nv/duan_nt, muc2_ngay,_xlfn.XLOOKUP(nt,'kpi nhà thuốc'!$B:$B,'kpi nhà thuốc'!$P:$P), muc3_ngay,_xlfn.XLOOKUP(nt,'kpi nhà thuốc'!$B:$B,'kpi nhà thuốc'!$T:$T), hangdiem1,_xlfn.XLOOKUP(nt,'kpi nhà thuốc'!$B:$B,'kpi nhà thuốc'!$I:$I), hangdiem2,_xlfn.XLOOKUP(nt,'kpi nhà thuốc'!$B:$B,'kpi nhà thuốc'!$N:$N), hangdiem3,_xlfn.XLOOKUP(nt,'kpi nhà thuốc'!$B:$B,'kpi nhà thuốc'!$R:$R), _xludf.SWITCH(TRUE, doanhthungay>=muc3_ngay,hangdiem3, doanhthungay>=muc2_ngay,hangdiem2, TRUE,hangdiem1 )/songay*tyle ), -3), 0)} -> 0 | G11: {=_xlfn.XLOOKUP(B11,'Dự án T8'!B:B,'Dự án T8'!D:D,0)} -> 763078.43 | H11: =Q11 -> 6500000 | I11: =(AD11/DAY($C$1)) -> 4705435 | J11: {=_xlfn.XLOOKUP(B11,'kpi nhà thuốc'!A:A,'kpi nhà thuốc'!F:F,(AD11/DAY($C$1))/U11)} -> 0.72934243 | K11: {=_xlfn.XLOOKUP( B11, 'kpi nhà thuốc'!A:A, 'kpi nhà thuốc'!G:G, IF( AND( OR(C11="DSXC",C11="DSCD"), G11>=F11),IF(AND(I11>=T11,E11>=D11),AD11*1.5%,IF(AND(I11>=T11,E11<D11),AD11*1.3%,IF(AND(I11>=S11,E11>=D11),AD11*1.3%,IF(AND(I11>=S11,E11<D11),AD11*1.1%,IF(AND(I11>=R11,E11>=D11),AD11*1.2%,IF(AND(I11>=R11,E11<D11),AD11*1%,"")))))),"" ) )} -> #NAME? | L11: =IF(C11="DSTV","", IF(J11<0.6, 0.8, 1)) -> 1 | M11: {=IFERROR( _xlfn.XLOOKUP( $A11&$B11, 'Dự án T8'!$A:$A&'Dự án T8'!$B:$B, 'Dự án T8'!$M:$M, 0 )*$L11, 0)} -> 0 | N11: =K11+M11*L11 -> #NAME? | O11: =CEILING(R11,100000) -> 5200000 | P11: =CEILING(S11,100000) -> 5900000 | Q11: =CEILING(T11,100000) -> 6500000 | R11: =U11*$R$2 -> 5161290.3 | S11: =U11*$S$2 -> 5806451.6 | T11: =U11*$T$2 -> 6451612.9 | U11: =V11/DAY('kpi nhà thuốc'!$T$1) -> 6451612.9 | V11: 200000000 | W11: =SUMIF(data!$B:$B,B11,data!$C:$C) -> 257 | X11: =SUMIF(data!$B:$B,B11,data!$D:$D) -> 25130380 | Y11: =IF(W11>0,X11/W11,0) -> 97783.58 | Z11: =SUMIF(data!$B:$B,B11,data!$E:$E) -> 350 | AA11: =SUMIF(data!$B:$B,B11,data!$F:$F) -> 106621800 | AB11: =IF(Z11>0,AA11/Z11,0) -> 304633.71 | AC11: =W11+Z11 -> 607 | AD11: =X11+AA11 -> 131752180 | AE11: =IF(AC11>0,AD11/AC11,0) -> 217054.66
A12: Trường Sa | B12: Nguyễn Trần Ngọc Phương | C12: Q.CHT | D12: 150000 | E12: =AE12 -> 98864.721 | F12: {=IFERROR( ROUND( _xludf.LET( nt,$A12, nv,$B12, songay,DAY(EOMONTH($C$1,0)), doanhthungay,$I12, duan_nv,SUM_xlfn.IFS('Dự án T8'!$D:$D,'Dự án T8'!$A:$A,nt,'Dự án T8'!$B:$B,nv), duan_nt,SUM_xlfn.IFS('Dự án T8'!$D:$D,'Dự án T8'!$A:$A,nt), tyle,duan_nv/duan_nt, muc2_ngay,_xlfn.XLOOKUP(nt,'kpi nhà thuốc'!$B:$B,'kpi nhà thuốc'!$P:$P), muc3_ngay,_xlfn.XLOOKUP(nt,'kpi nhà thuốc'!$B:$B,'kpi nhà thuốc'!$T:$T), hangdiem1,_xlfn.XLOOKUP(nt,'kpi nhà thuốc'!$B:$B,'kpi nhà thuốc'!$I:$I), hangdiem2,_xlfn.XLOOKUP(nt,'kpi nhà thuốc'!$B:$B,'kpi nhà thuốc'!$N:$N), hangdiem3,_xlfn.XLOOKUP(nt,'kpi nhà thuốc'!$B:$B,'kpi nhà thuốc'!$R:$R), _xludf.SWITCH(TRUE, doanhthungay>=muc3_ngay,hangdiem3, doanhthungay>=muc2_ngay,hangdiem2, TRUE,hangdiem1 )/songay*tyle ), -3), 0)} -> 0 | G12: {=_xlfn.XLOOKUP(B12,'Dự án T8'!B:B,'Dự án T8'!D:D,0)} -> 820280.39 | H12: =Q12 -> 3600000 | I12: =(AD12/DAY($C$1)) -> 2051443 | J12: {=_xlfn.XLOOKUP(B12,'kpi nhà thuốc'!A:A,'kpi nhà thuốc'!F:F,(AD12/DAY($C$1))/U12)} -> 0.73144283 | K12: {=_xlfn.XLOOKUP( B12, 'kpi nhà thuốc'!A:A, 'kpi nhà thuốc'!G:G, IF( AND( OR(C12="DSXC",C12="DSCD"), G12>=F12),IF(AND(I12>=T12,E12>=D12),AD12*1.5%,IF(AND(I12>=T12,E12<D12),AD12*1.3%,IF(AND(I12>=S12,E12>=D12),AD12*1.3%,IF(AND(I12>=S12,E12<D12),AD12*1.1%,IF(AND(I12>=R12,E12>=D12),AD12*1.2%,IF(AND(I12>=R12,E12<D12),AD12*1%,"")))))),"" ) )} -> 0 | L12: =IF(C12="DSTV","", IF(J12<0.6, 0.8, 1)) -> 1 | M12: {=IFERROR( _xlfn.XLOOKUP( $A12&$B12, 'Dự án T8'!$A:$A&'Dự án T8'!$B:$B, 'Dự án T8'!$M:$M, 0 )*$L12, 0)} -> 0 | N12: =K12+M12*L12 -> 0 | O12: =CEILING(R12,100000) -> 2900000 | P12: =CEILING(S12,100000) -> 3200000 | Q12: =CEILING(T12,100000) -> 3600000 | R12: =U12*$R$2 -> 2838709.7 | S12: =U12*$S$2 -> 3193548.4 | T12: =U12*$T$2 -> 3548387.1 | U12: =V12/DAY('kpi nhà thuốc'!$T$1) -> 3548387.1 | V12: 110000000 | W12: =SUMIF(data!$B:$B,B12,data!$C:$C) -> 359 | X12: =SUMIF(data!$B:$B,B12,data!$D:$D) -> 24147102 | Y12: =IF(W12>0,X12/W12,0) -> 67262.123 | Z12: =SUMIF(data!$B:$B,B12,data!$E:$E) -> 222 | AA12: =SUMIF(data!$B:$B,B12,data!$F:$F) -> 33293301 | AB12: =IF(Z12>0,AA12/Z12,0) -> 149969.82 | AC12: =W12+Z12 -> 581 | AD12: =X12+AA12 -> 57440403 | AE12: =IF(AC12>0,AD12/AC12,0) -> 98864.721
A13: Trường Sa | B13: Phạm Nguyễn Ngọc Quý | C13: DSXC | D13: 175000 | E13: =AE13 -> 115875.27 | F13: {=IFERROR( ROUND( _xludf.LET( nt,$A13, nv,$B13, songay,DAY(EOMONTH($C$1,0)), doanhthungay,$I13, duan_nv,SUM_xlfn.IFS('Dự án T8'!$D:$D,'Dự án T8'!$A:$A,nt,'Dự án T8'!$B:$B,nv), duan_nt,SUM_xlfn.IFS('Dự án T8'!$D:$D,'Dự án T8'!$A:$A,nt), tyle,duan_nv/duan_nt, muc2_ngay,_xlfn.XLOOKUP(nt,'kpi nhà thuốc'!$B:$B,'kpi nhà thuốc'!$P:$P), muc3_ngay,_xlfn.XLOOKUP(nt,'kpi nhà thuốc'!$B:$B,'kpi nhà thuốc'!$T:$T), hangdiem1,_xlfn.XLOOKUP(nt,'kpi nhà thuốc'!$B:$B,'kpi nhà thuốc'!$I:$I), hangdiem2,_xlfn.XLOOKUP(nt,'kpi nhà thuốc'!$B:$B,'kpi nhà thuốc'!$N:$N), hangdiem3,_xlfn.XLOOKUP(nt,'kpi nhà thuốc'!$B:$B,'kpi nhà thuốc'!$R:$R), _xludf.SWITCH(TRUE, doanhthungay>=muc3_ngay,hangdiem3, doanhthungay>=muc2_ngay,hangdiem2, TRUE,hangdiem1 )/songay*tyle ), -3), 0)} -> 0 | G13: {=_xlfn.XLOOKUP(B13,'Dự án T8'!B:B,'Dự án T8'!D:D,0)} -> 835680.64 | H13: =Q13 -> 3800000 | I13: =(AD13/DAY($C$1)) -> 2317505.4 | J13: {=_xlfn.XLOOKUP(B13,'kpi nhà thuốc'!A:A,'kpi nhà thuốc'!F:F,(AD13/DAY($C$1))/U13)} -> 0.62471884 | K13: {=_xlfn.XLOOKUP( B13, 'kpi nhà thuốc'!A:A, 'kpi nhà thuốc'!G:G, IF( AND( OR(C13="DSXC",C13="DSCD"), G13>=F13),IF(AND(I13>=T13,E13>=D13),AD13*1.5%,IF(AND(I13>=T13,E13<D13),AD13*1.3%,IF(AND(I13>=S13,E13>=D13),AD13*1.3%,IF(AND(I13>=S13,E13<D13),AD13*1.1%,IF(AND(I13>=R13,E13>=D13),AD13*1.2%,IF(AND(I13>=R13,E13<D13),AD13*1%,"")))))),"" ) )} -> #NAME? | L13: =IF(C13="DSTV","", IF(J13<0.6, 0.8, 1)) -> 1 | M13: {=IFERROR( _xlfn.XLOOKUP( $A13&$B13, 'Dự án T8'!$A:$A&'Dự án T8'!$B:$B, 'Dự án T8'!$M:$M, 0 )*$L13, 0)} -> 0 | N13: =K13+M13*L13 -> #NAME? | O13: =CEILING(R13,100000) -> 3000000 | P13: =CEILING(S13,100000) -> 3400000 | Q13: =CEILING(T13,100000) -> 3800000 | R13: =U13*$R$2 -> 2967741.9 | S13: =U13*$S$2 -> 3338709.7 | T13: =U13*$T$2 -> 3709677.4 | U13: =V13/DAY('kpi nhà thuốc'!$T$1) -> 3709677.4 | V13: 115000000 | W13: =SUMIF(data!$B:$B,B13,data!$C:$C) -> 357 | X13: =SUMIF(data!$B:$B,B13,data!$D:$D) -> 25728300 | Y13: =IF(W13>0,X13/W13,0) -> 72068.067 | Z13: =SUMIF(data!$B:$B,B13,data!$E:$E) -> 203 | AA13: =SUMIF(data!$B:$B,B13,data!$F:$F) -> 39161850 | AB13: =IF(Z13>0,AA13/Z13,0) -> 192915.52 | AC13: =W13+Z13 -> 560 | AD13: =X13+AA13 -> 64890150 | AE13: =IF(AC13>0,AD13/AC13,0) -> 115875.27
A14: Trường Sa | B14: Nguyễn Ngọc Anh Thư | C14: DSCD (TV) | D14: 150000 | E14: =AE14 -> 95087.021 | F14: {=IFERROR( ROUND( _xludf.LET( nt,$A14, nv,$B14, songay,DAY(EOMONTH($C$1,0)), doanhthungay,$I14, duan_nv,SUM_xlfn.IFS('Dự án T8'!$D:$D,'Dự án T8'!$A:$A,nt,'Dự án T8'!$B:$B,nv), duan_nt,SUM_xlfn.IFS('Dự án T8'!$D:$D,'Dự án T8'!$A:$A,nt), tyle,duan_nv/duan_nt, muc2_ngay,_xlfn.XLOOKUP(nt,'kpi nhà thuốc'!$B:$B,'kpi nhà thuốc'!$P:$P), muc3_ngay,_xlfn.XLOOKUP(nt,'kpi nhà thuốc'!$B:$B,'kpi nhà thuốc'!$T:$T), hangdiem1,_xlfn.XLOOKUP(nt,'kpi nhà thuốc'!$B:$B,'kpi nhà thuốc'!$I:$I), hangdiem2,_xlfn.XLOOKUP(nt,'kpi nhà thuốc'!$B:$B,'kpi nhà thuốc'!$N:$N), hangdiem3,_xlfn.XLOOKUP(nt,'kpi nhà thuốc'!$B:$B,'kpi nhà thuốc'!$R:$R), _xludf.SWITCH(TRUE, doanhthungay>=muc3_ngay,hangdiem3, doanhthungay>=muc2_ngay,hangdiem2, TRUE,hangdiem1 )/songay*tyle ), -3), 0)} -> 0 | G14: {=_xlfn.XLOOKUP(B14,'Dự án T8'!B:B,'Dự án T8'!D:D,0)} -> 323234.29 | H14: =Q14 -> 3100000 | I14: =(AD14/DAY($C$1)) -> 798051.79 | J14: {=_xlfn.XLOOKUP(B14,'kpi nhà thuốc'!A:A,'kpi nhà thuốc'!F:F,(AD14/DAY($C$1))/U14)} -> 0.2604169 | K14: {=_xlfn.XLOOKUP( B14, 'kpi nhà thuốc'!A:A, 'kpi nhà thuốc'!G:G, IF( AND( OR(C14="DSXC",C14="DSCD"), G14>=F14),IF(AND(I14>=T14,E14>=D14),AD14*1.5%,IF(AND(I14>=T14,E14<D14),AD14*1.3%,IF(AND(I14>=S14,E14>=D14),AD14*1.3%,IF(AND(I14>=S14,E14<D14),AD14*1.1%,IF(AND(I14>=R14,E14>=D14),AD14*1.2%,IF(AND(I14>=R14,E14<D14),AD14*1%,"")))))),"" ) )} | L14: =IF(C14="DSTV","", IF(J14<0.6, 0.8, 1)) -> 0.8 | M14: {=IFERROR( _xlfn.XLOOKUP( $A14&$B14, 'Dự án T8'!$A:$A&'Dự án T8'!$B:$B, 'Dự án T8'!$M:$M, 0 )*$L14, 0)} -> 0 | N14: =K14+M14*L14 -> #VALUE! | O14: =CEILING(R14,100000) -> 2500000 | P14: =CEILING(S14,100000) -> 2800000 | Q14: =CEILING(T14,100000) -> 3100000 | R14: =U14*$R$2 -> 2451612.9 | S14: =U14*$S$2 -> 2758064.5 | T14: =U14*$T$2 -> 3064516.1 | U14: =V14/DAY('kpi nhà thuốc'!$T$1) -> 3064516.1 | V14: 95000000 | W14: =SUMIF(data!$B:$B,B14,data!$C:$C) -> 124 | X14: =SUMIF(data!$B:$B,B14,data!$D:$D) -> 7987200 | Y14: =IF(W14>0,X14/W14,0) -> 64412.903 | Z14: =SUMIF(data!$B:$B,B14,data!$E:$E) -> 111 | AA14: =SUMIF(data!$B:$B,B14,data!$F:$F) -> 14358250 | AB14: =IF(Z14>0,AA14/Z14,0) -> 129353.6 | AC14: =W14+Z14 -> 235 | AD14: =X14+AA14 -> 22345450 | AE14: =IF(AC14>0,AD14/AC14,0) -> 95087.021
... A25: Minh Châu | B25: Nguyễn Ngọc Thùy | C25: DSHV | D25: 100000 | E25: =AE25 -> 74170.301 | F25: {=IFERROR( ROUND( _xludf.LET( nt,$A25, nv,$B25, songay,DAY(EOMONTH($C$1,0)), doanhthungay,$I25, duan_nv,SUM_xlfn.IFS('Dự án T8'!$D:$D,'Dự án T8'!$A:$A,nt,'Dự án T8'!$B:$B,nv), duan_nt,SUM_xlfn.IFS('Dự án T8'!$D:$D,'Dự án T8'!$A:$A,nt), tyle,duan_nv/duan_nt, muc2_ngay,_xlfn.XLOOKUP(nt,'kpi nhà thuốc'!$B:$B,'kpi nhà thuốc'!$P:$P), muc3_ngay,_xlfn.XLOOKUP(nt,'kpi nhà thuốc'!$B:$B,'kpi nhà thuốc'!$T:$T), hangdiem1,_xlfn.XLOOKUP(nt,'kpi nhà thuốc'!$B:$B,'kpi nhà thuốc'!$I:$I), hangdiem2,_xlfn.XLOOKUP(nt,'kpi nhà thuốc'!$B:$B,'kpi nhà thuốc'!$N:$N), hangdiem3,_xlfn.XLOOKUP(nt,'kpi nhà thuốc'!$B:$B,'kpi nhà thuốc'!$R:$R), _xludf.SWITCH(TRUE, doanhthungay>=muc3_ngay,hangdiem3, doanhthungay>=muc2_ngay,hangdiem2, TRUE,hangdiem1 )/songay*tyle ), -3), 0)} -> 0 | G25: {=_xlfn.XLOOKUP(B25,'Dự án T8'!B:B,'Dự án T8'!D:D,0)} -> 115239.75 | H25: =Q25 -> 3300000 | I25: =(AD25/DAY($C$1)) -> 352308.93 | J25: {=_xlfn.XLOOKUP(B25,'kpi nhà thuốc'!A:A,'kpi nhà thuốc'!F:F,(AD25/DAY($C$1))/U25)} -> 0.10921577 | K25: {=_xlfn.XLOOKUP( B25, 'kpi nhà thuốc'!A:A, 'kpi nhà thuốc'!G:G, IF( AND( OR(C25="DSXC",C25="DSCD"), G25>=F25),IF(AND(I25>=T25,E25>=D25),AD25*1.5%,IF(AND(I25>=T25,E25<D25),AD25*1.3%,IF(AND(I25>=S25,E25>=D25),AD25*1.3%,IF(AND(I25>=S25,E25<D25),AD25*1.1%,IF(AND(I25>=R25,E25>=D25),AD25*1.2%,IF(AND(I25>=R25,E25<D25),AD25*1%,"")))))),"" ) )} | L25: =IF(C25="DSTV","", IF(J25<0.6, 0.8, 1)) -> 0.8 | M25: {=IFERROR( _xlfn.XLOOKUP( $A25&$B25, 'Dự án T8'!$A:$A&'Dự án T8'!$B:$B, 'Dự án T8'!$M:$M, 0 )*$L25, 0)} -> 0 | N25: =K25+M25*L25 -> #VALUE! | O25: =CEILING(R25,100000) -> 2600000 | P25: =CEILING(S25,100000) -> 3000000 | Q25: =CEILING(T25,100000) -> 3300000 | R25: =U25*$R$2 -> 2580645.2 | S25: =U25*$S$2 -> 2903225.8 | T25: =U25*$T$2 -> 3225806.5 | U25: =V25/DAY('kpi nhà thuốc'!$T$1) -> 3225806.5 | V25: 100000000 | W25: =SUMIF(data!$B:$B,B25,data!$C:$C) -> 118 | X25: =SUMIF(data!$B:$B,B25,data!$D:$D) -> 8323800 | Y25: =IF(W25>0,X25/W25,0) -> 70540.678 | Z25: =SUMIF(data!$B:$B,B25,data!$E:$E) -> 15 | AA25: =SUMIF(data!$B:$B,B25,data!$F:$F) -> 1540850 | AB25: =IF(Z25>0,AA25/Z25,0) -> 102723.33 | AC25: =W25+Z25 -> 133 | AD25: =X25+AA25 -> 9864650 | AE25: =IF(AC25>0,AD25/AC25,0) -> 74170.301
A26: Minh Châu | B26: Trịnh Thị Phượng | C26: DSCD | E26: =AE26 -> 97201.507 | F26: {=IFERROR( ROUND( _xludf.LET( nt,$A26, nv,$B26, songay,DAY(EOMONTH($C$1,0)), doanhthungay,$I26, duan_nv,SUM_xlfn.IFS('Dự án T8'!$D:$D,'Dự án T8'!$A:$A,nt,'Dự án T8'!$B:$B,nv), duan_nt,SUM_xlfn.IFS('Dự án T8'!$D:$D,'Dự án T8'!$A:$A,nt), tyle,duan_nv/duan_nt, muc2_ngay,_xlfn.XLOOKUP(nt,'kpi nhà thuốc'!$B:$B,'kpi nhà thuốc'!$P:$P), muc3_ngay,_xlfn.XLOOKUP(nt,'kpi nhà thuốc'!$B:$B,'kpi nhà thuốc'!$T:$T), hangdiem1,_xlfn.XLOOKUP(nt,'kpi nhà thuốc'!$B:$B,'kpi nhà thuốc'!$I:$I), hangdiem2,_xlfn.XLOOKUP(nt,'kpi nhà thuốc'!$B:$B,'kpi nhà thuốc'!$N:$N), hangdiem3,_xlfn.XLOOKUP(nt,'kpi nhà thuốc'!$B:$B,'kpi nhà thuốc'!$R:$R), _xludf.SWITCH(TRUE, doanhthungay>=muc3_ngay,hangdiem3, doanhthungay>=muc2_ngay,hangdiem2, TRUE,hangdiem1 )/songay*tyle ), -3), 0)} -> 0 | G26: {=_xlfn.XLOOKUP(B26,'Dự án T8'!B:B,'Dự án T8'!D:D,0)} -> 1875086.3 | H26: =Q26 -> 3800000 | I26: =(AD26/DAY($C$1)) -> 3547855 | J26: {=_xlfn.XLOOKUP(B26,'kpi nhà thuốc'!A:A,'kpi nhà thuốc'!F:F,(AD26/DAY($C$1))/U26)} -> 0.9563783 | K26: {=_xlfn.XLOOKUP( B26, 'kpi nhà thuốc'!A:A, 'kpi nhà thuốc'!G:G, IF( AND( OR(C26="DSXC",C26="DSCD"), G26>=F26),IF(AND(I26>=T26,E26>=D26),AD26*1.5%,IF(AND(I26>=T26,E26<D26),AD26*1.3%,IF(AND(I26>=S26,E26>=D26),AD26*1.3%,IF(AND(I26>=S26,E26<D26),AD26*1.1%,IF(AND(I26>=R26,E26>=D26),AD26*1.2%,IF(AND(I26>=R26,E26<D26),AD26*1%,"")))))),"" ) )} -> #NAME? | L26: =IF(C26="DSTV","", IF(J26<0.6, 0.8, 1)) -> 1 | M26: {=IFERROR( _xlfn.XLOOKUP( $A26&$B26, 'Dự án T8'!$A:$A&'Dự án T8'!$B:$B, 'Dự án T8'!$M:$M, 0 )*$L26, 0)} -> 0 | N26: =K26+M26*L26 -> #NAME? | O26: =CEILING(R26,100000) -> 3000000 | P26: =CEILING(S26,100000) -> 3400000 | Q26: =CEILING(T26,100000) -> 3800000 | R26: =U26*$R$2 -> 2967741.9 | S26: =U26*$S$2 -> 3338709.7 | T26: =U26*$T$2 -> 3709677.4 | U26: =V26/DAY('kpi nhà thuốc'!$T$1) -> 3709677.4 | V26: 115000000 | W26: =SUMIF(data!$B:$B,B26,data!$C:$C) -> 842 | X26: =SUMIF(data!$B:$B,B26,data!$D:$D) -> 74277000 | Y26: =IF(W26>0,X26/W26,0) -> 88214.964 | Z26: =SUMIF(data!$B:$B,B26,data!$E:$E) -> 180 | AA26: =SUMIF(data!$B:$B,B26,data!$F:$F) -> 25062940 | AB26: =IF(Z26>0,AA26/Z26,0) -> 139238.56 | AC26: =W26+Z26 -> 1022 | AD26: =X26+AA26 -> 99339940 | AE26: =IF(AC26>0,AD26/AC26,0) -> 97201.507
A27: Nam Hòa | B27: Trần Thị Ánh Nguyệt | C27: DSCD | D27: 120000 | E27: =AE27 -> 94801.427 | F27: {=IFERROR( ROUND( _xludf.LET( nt,$A27, nv,$B27, songay,DAY(EOMONTH($C$1,0)), doanhthungay,$I27, duan_nv,SUM_xlfn.IFS('Dự án T8'!$D:$D,'Dự án T8'!$A:$A,nt,'Dự án T8'!$B:$B,nv), duan_nt,SUM_xlfn.IFS('Dự án T8'!$D:$D,'Dự án T8'!$A:$A,nt), tyle,duan_nv/duan_nt, muc2_ngay,_xlfn.XLOOKUP(nt,'kpi nhà thuốc'!$B:$B,'kpi nhà thuốc'!$P:$P), muc3_ngay,_xlfn.XLOOKUP(nt,'kpi nhà thuốc'!$B:$B,'kpi nhà thuốc'!$T:$T), hangdiem1,_xlfn.XLOOKUP(nt,'kpi nhà thuốc'!$B:$B,'kpi nhà thuốc'!$I:$I), hangdiem2,_xlfn.XLOOKUP(nt,'kpi nhà thuốc'!$B:$B,'kpi nhà thuốc'!$N:$N), hangdiem3,_xlfn.XLOOKUP(nt,'kpi nhà thuốc'!$B:$B,'kpi nhà thuốc'!$R:$R), _xludf.SWITCH(TRUE, doanhthungay>=muc3_ngay,hangdiem3, doanhthungay>=muc2_ngay,hangdiem2, TRUE,hangdiem1 )/songay*tyle ), -3), 0)} -> 0 | G27: {=_xlfn.XLOOKUP(B27,'Dự án T8'!B:B,'Dự án T8'!D:D,0)} -> 1382847.9 | H27: =Q27 -> 3300000 | I27: =(AD27/DAY($C$1)) -> 2610425 | J27: {=_xlfn.XLOOKUP(B27,'kpi nhà thuốc'!A:A,'kpi nhà thuốc'!F:F,(AD27/DAY($C$1))/U27)} -> 0.80923175 | K27: {=_xlfn.XLOOKUP( B27, 'kpi nhà thuốc'!A:A, 'kpi nhà thuốc'!G:G, IF( AND( OR(C27="DSXC",C27="DSCD"), G27>=F27),IF(AND(I27>=T27,E27>=D27),AD27*1.5%,IF(AND(I27>=T27,E27<D27),AD27*1.3%,IF(AND(I27>=S27,E27>=D27),AD27*1.3%,IF(AND(I27>=S27,E27<D27),AD27*1.1%,IF(AND(I27>=R27,E27>=D27),AD27*1.2%,IF(AND(I27>=R27,E27<D27),AD27*1%,"")))))),"" ) )} -> #NAME? | L27: =IF(C27="DSTV","", IF(J27<0.6, 0.8, 1)) -> 1 | M27: {=IFERROR( _xlfn.XLOOKUP( $A27&$B27, 'Dự án T8'!$A:$A&'Dự án T8'!$B:$B, 'Dự án T8'!$M:$M, 0 )*$L27, 0)} -> 500000 | N27: =K27+M27*L27 -> #NAME? | O27: =CEILING(R27,100000) -> 2600000 | P27: =CEILING(S27,100000) -> 3000000 | Q27: =CEILING(T27,100000) -> 3300000 | R27: =U27*$R$2 -> 2580645.2 | S27: =U27*$S$2 -> 2903225.8 | T27: =U27*$T$2 -> 3225806.5 | U27: =V27/DAY('kpi nhà thuốc'!$T$1) -> 3225806.5 | V27: 100000000 | W27: =SUMIF(data!$B:$B,B27,data!$C:$C) -> 593 | X27: =SUMIF(data!$B:$B,B27,data!$D:$D) -> 45493300 | Y27: =IF(W27>0,X27/W27,0) -> 76717.201 | Z27: =SUMIF(data!$B:$B,B27,data!$E:$E) -> 178 | AA27: =SUMIF(data!$B:$B,B27,data!$F:$F) -> 27598600 | AB27: =IF(Z27>0,AA27/Z27,0) -> 155048.31 | AC27: =W27+Z27 -> 771 | AD27: =X27+AA27 -> 73091900 | AE27: =IF(AC27>0,AD27/AC27,0) -> 94801.427
A28: Nam Hòa | B28: Nguyễn Thị Huyền Trang | C28: DSXC (TV) | E28: =AE28 -> 125547.79 | F28: {=IFERROR( ROUND( _xludf.LET( nt,$A28, nv,$B28, songay,DAY(EOMONTH($C$1,0)), doanhthungay,$I28, duan_nv,SUM_xlfn.IFS('Dự án T8'!$D:$D,'Dự án T8'!$A:$A,nt,'Dự án T8'!$B:$B,nv), duan_nt,SUM_xlfn.IFS('Dự án T8'!$D:$D,'Dự án T8'!$A:$A,nt), tyle,duan_nv/duan_nt, muc2_ngay,_xlfn.XLOOKUP(nt,'kpi nhà thuốc'!$B:$B,'kpi nhà thuốc'!$P:$P), muc3_ngay,_xlfn.XLOOKUP(nt,'kpi nhà thuốc'!$B:$B,'kpi nhà thuốc'!$T:$T), hangdiem1,_xlfn.XLOOKUP(nt,'kpi nhà thuốc'!$B:$B,'kpi nhà thuốc'!$I:$I), hangdiem2,_xlfn.XLOOKUP(nt,'kpi nhà thuốc'!$B:$B,'kpi nhà thuốc'!$N:$N), hangdiem3,_xlfn.XLOOKUP(nt,'kpi nhà thuốc'!$B:$B,'kpi nhà thuốc'!$R:$R), _xludf.SWITCH(TRUE, doanhthungay>=muc3_ngay,hangdiem3, doanhthungay>=muc2_ngay,hangdiem2, TRUE,hangdiem1 )/songay*tyle ), -3), 0)} -> 0 | G28: {=_xlfn.XLOOKUP(B28,'Dự án T8'!B:B,'Dự án T8'!D:D,0)} -> 334543 | H28: =Q28 -> 2000000 | I28: =(AD28/DAY($C$1)) -> 1623153.6 | J28: {=_xlfn.XLOOKUP(B28,'kpi nhà thuốc'!A:A,'kpi nhà thuốc'!F:F,(AD28/DAY($C$1))/U28)} -> 0.83862935 | K28: {=_xlfn.XLOOKUP( B28, 'kpi nhà thuốc'!A:A, 'kpi nhà thuốc'!G:G, IF( AND( OR(C28="DSXC",C28="DSCD"), G28>=F28),IF(AND(I28>=T28,E28>=D28),AD28*1.5%,IF(AND(I28>=T28,E28<D28),AD28*1.3%,IF(AND(I28>=S28,E28>=D28),AD28*1.3%,IF(AND(I28>=S28,E28<D28),AD28*1.1%,IF(AND(I28>=R28,E28>=D28),AD28*1.2%,IF(AND(I28>=R28,E28<D28),AD28*1%,"")))))),"" ) )} | L28: =IF(C28="DSTV","", IF(J28<0.6, 0.8, 1)) -> 1 | M28: {=IFERROR( _xlfn.XLOOKUP( $A28&$B28, 'Dự án T8'!$A:$A&'Dự án T8'!$B:$B, 'Dự án T8'!$M:$M, 0 )*$L28, 0)} -> 0 | N28: =K28+M28*L28 -> #VALUE! | O28: =CEILING(R28,100000) -> 1600000 | P28: =CEILING(S28,100000) -> 1800000 | Q28: =CEILING(T28,100000) -> 2000000 | R28: =U28*$R$2 -> 1548387.1 | S28: =U28*$S$2 -> 1741935.5 | T28: =U28*$T$2 -> 1935483.9 | U28: =V28/DAY('kpi nhà thuốc'!$T$1) -> 1935483.9 | V28: 60000000 | W28: =SUMIF(data!$B:$B,B28,data!$C:$C) -> 253 | X28: =SUMIF(data!$B:$B,B28,data!$D:$D) -> 16117800 | Y28: =IF(W28>0,X28/W28,0) -> 63706.719 | Z28: =SUMIF(data!$B:$B,B28,data!$E:$E) -> 109 | AA28: =SUMIF(data!$B:$B,B28,data!$F:$F) -> 29330500 | AB28: =IF(Z28>0,AA28/Z28,0) -> 269087.16 | AC28: =W28+Z28 -> 362 | AD28: =X28+AA28 -> 45448300 | AE28: =IF(AC28>0,AD28/AC28,0) -> 125547.79
A29: Nam Hòa | B29: Đỗ Thị Kim Tiến | C29: DSCD (TV) | E29: =AE29 -> 115926.45 | F29: {=IFERROR( ROUND( _xludf.LET( nt,$A29, nv,$B29, songay,DAY(EOMONTH($C$1,0)), doanhthungay,$I29, duan_nv,SUM_xlfn.IFS('Dự án T8'!$D:$D,'Dự án T8'!$A:$A,nt,'Dự án T8'!$B:$B,nv), duan_nt,SUM_xlfn.IFS('Dự án T8'!$D:$D,'Dự án T8'!$A:$A,nt), tyle,duan_nv/duan_nt, muc2_ngay,_xlfn.XLOOKUP(nt,'kpi nhà thuốc'!$B:$B,'kpi nhà thuốc'!$P:$P), muc3_ngay,_xlfn.XLOOKUP(nt,'kpi nhà thuốc'!$B:$B,'kpi nhà thuốc'!$T:$T), hangdiem1,_xlfn.XLOOKUP(nt,'kpi nhà thuốc'!$B:$B,'kpi nhà thuốc'!$I:$I), hangdiem2,_xlfn.XLOOKUP(nt,'kpi nhà thuốc'!$B:$B,'kpi nhà thuốc'!$N:$N), hangdiem3,_xlfn.XLOOKUP(nt,'kpi nhà thuốc'!$B:$B,'kpi nhà thuốc'!$R:$R), _xludf.SWITCH(TRUE, doanhthungay>=muc3_ngay,hangdiem3, doanhthungay>=muc2_ngay,hangdiem2, TRUE,hangdiem1 )/songay*tyle ), -3), 0)} -> 0 | G29: {=_xlfn.XLOOKUP(B29,'Dự án T8'!B:B,'Dự án T8'!D:D,0)} -> 272429.64 | H29: =Q29 -> 2000000 | I29: =(AD29/DAY($C$1)) -> 641735.71 | J29: {=_xlfn.XLOOKUP(B29,'kpi nhà thuốc'!A:A,'kpi nhà thuốc'!F:F,(AD29/DAY($C$1))/U29)} -> 0.33156345 | K29: {=_xlfn.XLOOKUP( B29, 'kpi nhà thuốc'!A:A, 'kpi nhà thuốc'!G:G, IF( AND( OR(C29="DSXC",C29="DSCD"), G29>=F29),IF(AND(I29>=T29,E29>=D29),AD29*1.5%,IF(AND(I29>=T29,E29<D29),AD29*1.3%,IF(AND(I29>=S29,E29>=D29),AD29*1.3%,IF(AND(I29>=S29,E29<D29),AD29*1.1%,IF(AND(I29>=R29,E29>=D29),AD29*1.2%,IF(AND(I29>=R29,E29<D29),AD29*1%,"")))))),"" ) )} | L29: =IF(C29="DSTV","", IF(J29<0.6, 0.8, 1)) -> 0.8 | M29: {=IFERROR( _xlfn.XLOOKUP( $A29&$B29, 'Dự án T8'!$A:$A&'Dự án T8'!$B:$B, 'Dự án T8'!$M:$M, 0 )*$L29, 0)} -> 0 | N29: =K29+M29*L29 -> #VALUE! | O29: =CEILING(R29,100000) -> 1600000 | P29: =CEILING(S29,100000) -> 1800000 | Q29: =CEILING(T29,100000) -> 2000000 | R29: =U29*$R$2 -> 1548387.1 | S29: =U29*$S$2 -> 1741935.5 | T29: =U29*$T$2 -> 1935483.9 | U29: =V29/DAY('kpi nhà thuốc'!$T$1) -> 1935483.9 | V29: 60000000 | W29: =SUMIF(data!$B:$B,B29,data!$C:$C) -> 120 | X29: =SUMIF(data!$B:$B,B29,data!$D:$D) -> 10080700 | Y29: =IF(W29>0,X29/W29,0) -> 84005.833 | Z29: =SUMIF(data!$B:$B,B29,data!$E:$E) -> 35 | AA29: =SUMIF(data!$B:$B,B29,data!$F:$F) -> 7887900 | AB29: =IF(Z29>0,AA29/Z29,0) -> 225368.57 | AC29: =W29+Z29 -> 155 | AD29: =X29+AA29 -> 17968600 | AE29: =IF(AC29>0,AD29/AC29,0) -> 115926.45
A30: Nam Hòa | B30: Dương Thị Huỳnh Như | C30: DSCD (TV) | E30: =AE30 -> 78494.186 | F30: {=IFERROR( ROUND( _xludf.LET( nt,$A30, nv,$B30, songay,DAY(EOMONTH($C$1,0)), doanhthungay,$I30, duan_nv,SUM_xlfn.IFS('Dự án T8'!$D:$D,'Dự án T8'!$A:$A,nt,'Dự án T8'!$B:$B,nv), duan_nt,SUM_xlfn.IFS('Dự án T8'!$D:$D,'Dự án T8'!$A:$A,nt), tyle,duan_nv/duan_nt, muc2_ngay,_xlfn.XLOOKUP(nt,'kpi nhà thuốc'!$B:$B,'kpi nhà thuốc'!$P:$P), muc3_ngay,_xlfn.XLOOKUP(nt,'kpi nhà thuốc'!$B:$B,'kpi nhà thuốc'!$T:$T), hangdiem1,_xlfn.XLOOKUP(nt,'kpi nhà thuốc'!$B:$B,'kpi nhà thuốc'!$I:$I), hangdiem2,_xlfn.XLOOKUP(nt,'kpi nhà thuốc'!$B:$B,'kpi nhà thuốc'!$N:$N), hangdiem3,_xlfn.XLOOKUP(nt,'kpi nhà thuốc'!$B:$B,'kpi nhà thuốc'!$R:$R), _xludf.SWITCH(TRUE, doanhthungay>=muc3_ngay,hangdiem3, doanhthungay>=muc2_ngay,hangdiem2, TRUE,hangdiem1 )/songay*tyle ), -3), 0)} -> 0 | G30: {=_xlfn.XLOOKUP(B30,'Dự án T8'!B:B,'Dự án T8'!D:D,0)} -> 454234.64 | H30: =Q30 -> 1700000 | I30: =(AD30/DAY($C$1)) -> 241089.29 | J30: {=_xlfn.XLOOKUP(B30,'kpi nhà thuốc'!A:A,'kpi nhà thuốc'!F:F,(AD30/DAY($C$1))/U30)} -> 0.14947536 | K30: {=_xlfn.XLOOKUP( B30, 'kpi nhà thuốc'!A:A, 'kpi nhà thuốc'!G:G, IF( AND( OR(C30="DSXC",C30="DSCD"), G30>=F30),IF(AND(I30>=T30,E30>=D30),AD30*1.5%,IF(AND(I30>=T30,E30<D30),AD30*1.3%,IF(AND(I30>=S30,E30>=D30),AD30*1.3%,IF(AND(I30>=S30,E30<D30),AD30*1.1%,IF(AND(I30>=R30,E30>=D30),AD30*1.2%,IF(AND(I30>=R30,E30<D30),AD30*1%,"")))))),"" ) )} | L30: =IF(C30="DSTV","", IF(J30<0.6, 0.8, 1)) -> 0.8 | M30: {=IFERROR( _xlfn.XLOOKUP( $A30&$B30, 'Dự án T8'!$A:$A&'Dự án T8'!$B:$B, 'Dự án T8'!$M:$M, 0 )*$L30, 0)} -> 0 | N30: =K30+M30*L30 -> #VALUE! | O30: =CEILING(R30,100000) -> 1300000 | P30: =CEILING(S30,100000) -> 1500000 | Q30: =CEILING(T30,100000) -> 1700000 | R30: =U30*$R$2 -> 1290322.6 | S30: =U30*$S$2 -> 1451612.9 | T30: =U30*$T$2 -> 1612903.2 | U30: =V30/DAY('kpi nhà thuốc'!$T$1) -> 1612903.2 | V30: 50000000 | W30: =SUMIF(data!$B:$B,B30,data!$C:$C) -> 72 | X30: =SUMIF(data!$B:$B,B30,data!$D:$D) -> 5530200 | Y30: =IF(W30>0,X30/W30,0) -> 76808.333 | Z30: =SUMIF(data!$B:$B,B30,data!$E:$E) -> 14 | AA30: =SUMIF(data!$B:$B,B30,data!$F:$F) -> 1220300 | AB30: =IF(Z30>0,AA30/Z30,0) -> 87164.286 | AC30: =W30+Z30 -> 86 | AD30: =X30+AA30 -> 6750500 | AE30: =IF(AC30>0,AD30/AC30,0) -> 78494.186
A31: Nam Hòa | B31: Bùi Thị Thanh Thủy | C31: DSXC (TV) | E31: =AE31 -> 125779.99 | F31: {=IFERROR( ROUND( _xludf.LET( nt,$A31, nv,$B31, songay,DAY(EOMONTH($C$1,0)), doanhthungay,$I31, duan_nv,SUM_xlfn.IFS('Dự án T8'!$D:$D,'Dự án T8'!$A:$A,nt,'Dự án T8'!$B:$B,nv), duan_nt,SUM_xlfn.IFS('Dự án T8'!$D:$D,'Dự án T8'!$A:$A,nt), tyle,duan_nv/duan_nt, muc2_ngay,_xlfn.XLOOKUP(nt,'kpi nhà thuốc'!$B:$B,'kpi nhà thuốc'!$P:$P), muc3_ngay,_xlfn.XLOOKUP(nt,'kpi nhà thuốc'!$B:$B,'kpi nhà thuốc'!$T:$T), hangdiem1,_xlfn.XLOOKUP(nt,'kpi nhà thuốc'!$B:$B,'kpi nhà thuốc'!$I:$I), hangdiem2,_xlfn.XLOOKUP(nt,'kpi nhà thuốc'!$B:$B,'kpi nhà thuốc'!$N:$N), hangdiem3,_xlfn.XLOOKUP(nt,'kpi nhà thuốc'!$B:$B,'kpi nhà thuốc'!$R:$R), _xludf.SWITCH(TRUE, doanhthungay>=muc3_ngay,hangdiem3, doanhthungay>=muc2_ngay,hangdiem2, TRUE,hangdiem1 )/songay*tyle ), -3), 0)} -> 0 | G31: {=_xlfn.XLOOKUP(B31,'Dự án T8'!B:B,'Dự án T8'!D:D,0)} -> 430331.89 | H31: =Q31 -> 2000000 | I31: =(AD31/DAY($C$1)) -> 1621663.5 | J31: {=_xlfn.XLOOKUP(B31,'kpi nhà thuốc'!A:A,'kpi nhà thuốc'!F:F,(AD31/DAY($C$1))/U31)} -> 0.83785948 | K31: {=_xlfn.XLOOKUP( B31, 'kpi nhà thuốc'!A:A, 'kpi nhà thuốc'!G:G, IF( AND( OR(C31="DSXC",C31="DSCD"), G31>=F31),IF(AND(I31>=T31,E31>=D31),AD31*1.5%,IF(AND(I31>=T31,E31<D31),AD31*1.3%,IF(AND(I31>=S31,E31>=D31),AD31*1.3%,IF(AND(I31>=S31,E31<D31),AD31*1.1%,IF(AND(I31>=R31,E31>=D31),AD31*1.2%,IF(AND(I31>=R31,E31<D31),AD31*1%,"")))))),"" ) )} | L31: =IF(C31="DSTV","", IF(J31<0.6, 0.8, 1)) -> 1 | M31: {=IFERROR( _xlfn.XLOOKUP( $A31&$B31, 'Dự án T8'!$A:$A&'Dự án T8'!$B:$B, 'Dự án T8'!$M:$M, 0 )*$L31, 0)} -> 0 | N31: =K31+M31*L31 -> #VALUE! | O31: =CEILING(R31,100000) -> 1600000 | P31: =CEILING(S31,100000) -> 1800000 | Q31: =CEILING(T31,100000) -> 2000000 | R31: =U31*$R$2 -> 1548387.1 | S31: =U31*$S$2 -> 1741935.5 | T31: =U31*$T$2 -> 1935483.9 | U31: =V31/DAY('kpi nhà thuốc'!$T$1) -> 1935483.9 | V31: 60000000 | W31: =SUMIF(data!$B:$B,B31,data!$C:$C) -> 248 | X31: =SUMIF(data!$B:$B,B31,data!$D:$D) -> 17563028 | Y31: =IF(W31>0,X31/W31,0) -> 70818.661 | Z31: =SUMIF(data!$B:$B,B31,data!$E:$E) -> 113 | AA31: =SUMIF(data!$B:$B,B31,data!$F:$F) -> 27843550 | AB31: =IF(Z31>0,AA31/Z31,0) -> 246403.1 | AC31: =W31+Z31 -> 361 | AD31: =X31+AA31 -> 45406578 | AE31: =IF(AC31>0,AD31/AC31,0) -> 125779.99
A32: Nguyễn Chí Thanh | B32: Lê Thị Quỳnh Trâm | C32: CHT | D32: 194000 | E32: =AE32 -> 262336.49 | F32: {=IFERROR( ROUND( _xludf.LET( nt,$A32, nv,$B32, songay,DAY(EOMONTH($C$1,0)), doanhthungay,$I32, duan_nv,SUM_xlfn.IFS('Dự án T8'!$D:$D,'Dự án T8'!$A:$A,nt,'Dự án T8'!$B:$B,nv), duan_nt,SUM_xlfn.IFS('Dự án T8'!$D:$D,'Dự án T8'!$A:$A,nt), tyle,duan_nv/duan_nt, muc2_ngay,_xlfn.XLOOKUP(nt,'kpi nhà thuốc'!$B:$B,'kpi nhà thuốc'!$P:$P), muc3_ngay,_xlfn.XLOOKUP(nt,'kpi nhà thuốc'!$B:$B,'kpi nhà thuốc'!$T:$T), hangdiem1,_xlfn.XLOOKUP(nt,'kpi nhà thuốc'!$B:$B,'kpi nhà thuốc'!$I:$I), hangdiem2,_xlfn.XLOOKUP(nt,'kpi nhà thuốc'!$B:$B,'kpi nhà thuốc'!$N:$N), hangdiem3,_xlfn.XLOOKUP(nt,'kpi nhà thuốc'!$B:$B,'kpi nhà thuốc'!$R:$R), _xludf.SWITCH(TRUE, doanhthungay>=muc3_ngay,hangdiem3, doanhthungay>=muc2_ngay,hangdiem2, TRUE,hangdiem1 )/songay*tyle ), -3), 0)} -> 0 | G32: {=_xlfn.XLOOKUP(B32,'Dự án T8'!B:B,'Dự án T8'!D:D,0)} -> 253045.14 | H32: =Q32 -> 3900000 | I32: =(AD32/DAY($C$1)) -> 4647103.6 | J32: {=_xlfn.XLOOKUP(B32,'kpi nhà thuốc'!A:A,'kpi nhà thuốc'!F:F,(AD32/DAY($C$1))/U32)} -> 0.74429047 | K32: {=_xlfn.XLOOKUP( B32, 'kpi nhà thuốc'!A:A, 'kpi nhà thuốc'!G:G, IF( AND( OR(C32="DSXC",C32="DSCD"), G32>=F32),IF(AND(I32>=T32,E32>=D32),AD32*1.5%,IF(AND(I32>=T32,E32<D32),AD32*1.3%,IF(AND(I32>=S32,E32>=D32),AD32*1.3%,IF(AND(I32>=S32,E32<D32),AD32*1.1%,IF(AND(I32>=R32,E32>=D32),AD32*1.2%,IF(AND(I32>=R32,E32<D32),AD32*1%,"")))))),"" ) )} -> #N/A | L32: =IF(C32="DSTV","", IF(J32<0.6, 0.8, 1)) -> 1 | M32: {=IFERROR( _xlfn.XLOOKUP( $A32&$B32, 'Dự án T8'!$A:$A&'Dự án T8'!$B:$B, 'Dự án T8'!$M:$M, 0 )*$L32, 0)} -> 0 | N32: =K32+M32*L32 -> #N/A | O32: =CEILING(R32,100000) -> 3100000 | P32: =CEILING(S32,100000) -> 3500000 | Q32: =CEILING(T32,100000) -> 3900000 | R32: =U32*$R$2 -> 3096774.2 | S32: =U32*$S$2 -> 3483871 | T32: =U32*$T$2 -> 3870967.7 | U32: =V32/DAY('kpi nhà thuốc'!$T$1) -> 3870967.7 | V32: 120000000 | W32: =SUMIF(data!$B:$B,B32,data!$C:$C) -> 290 | X32: =SUMIF(data!$B:$B,B32,data!$D:$D) -> 25411600 | Y32: =IF(W32>0,X32/W32,0) -> 87626.207 | Z32: =SUMIF(data!$B:$B,B32,data!$E:$E) -> 206 | AA32: =SUMIF(data!$B:$B,B32,data!$F:$F) -> 104707300 | AB32: =IF(Z32>0,AA32/Z32,0) -> 508287.86 | AC32: =W32+Z32 -> 496 | AD32: =X32+AA32 -> 130118900 | AE32: =IF(AC32>0,AD32/AC32,0) -> 262336.49
A33: Nguyễn Chí Thanh | B33: Đỗ Thị Phương Thảo | C33: DSXC | D33: 250000 | E33: =AE33 -> 144616.15 | F33: {=IFERROR( ROUND( _xludf.LET( nt,$A33, nv,$B33, songay,DAY(EOMONTH($C$1,0)), doanhthungay,$I33, duan_nv,SUM_xlfn.IFS('Dự án T8'!$D:$D,'Dự án T8'!$A:$A,nt,'Dự án T8'!$B:$B,nv), duan_nt,SUM_xlfn.IFS('Dự án T8'!$D:$D,'Dự án T8'!$A:$A,nt), tyle,duan_nv/duan_nt, muc2_ngay,_xlfn.XLOOKUP(nt,'kpi nhà thuốc'!$B:$B,'kpi nhà thuốc'!$P:$P), muc3_ngay,_xlfn.XLOOKUP(nt,'kpi nhà thuốc'!$B:$B,'kpi nhà thuốc'!$T:$T), hangdiem1,_xlfn.XLOOKUP(nt,'kpi nhà thuốc'!$B:$B,'kpi nhà thuốc'!$I:$I), hangdiem2,_xlfn.XLOOKUP(nt,'kpi nhà thuốc'!$B:$B,'kpi nhà thuốc'!$N:$N), hangdiem3,_xlfn.XLOOKUP(nt,'kpi nhà thuốc'!$B:$B,'kpi nhà thuốc'!$R:$R), _xludf.SWITCH(TRUE, doanhthungay>=muc3_ngay,hangdiem3, doanhthungay>=muc2_ngay,hangdiem2, TRUE,hangdiem1 )/songay*tyle ), -3), 0)} -> 0 | G33: {=_xlfn.XLOOKUP(B33,'Dự án T8'!B:B,'Dự án T8'!D:D,0)} -> 478506.79 | H33: =Q33 -> 3900000 | I33: =(AD33/DAY($C$1)) -> 2918147.3 | J33: {=_xlfn.XLOOKUP(B33,'kpi nhà thuốc'!A:A,'kpi nhà thuốc'!F:F,(AD33/DAY($C$1))/U33)} -> 0.75385472 | K33: {=_xlfn.XLOOKUP( B33, 'kpi nhà thuốc'!A:A, 'kpi nhà thuốc'!G:G, IF( AND( OR(C33="DSXC",C33="DSCD"), G33>=F33),IF(AND(I33>=T33,E33>=D33),AD33*1.5%,IF(AND(I33>=T33,E33<D33),AD33*1.3%,IF(AND(I33>=S33,E33>=D33),AD33*1.3%,IF(AND(I33>=S33,E33<D33),AD33*1.1%,IF(AND(I33>=R33,E33>=D33),AD33*1.2%,IF(AND(I33>=R33,E33<D33),AD33*1%,"")))))),"" ) )} -> #NAME? | L33: =IF(C33="DSTV","", IF(J33<0.6, 0.8, 1)) -> 1 | M33: {=IFERROR( _xlfn.XLOOKUP( $A33&$B33, 'Dự án T8'!$A:$A&'Dự án T8'!$B:$B, 'Dự án T8'!$M:$M, 0 )*$L33, 0)} -> 0 | N33: =K33+M33*L33 -> #NAME? | O33: =CEILING(R33,100000) -> 3100000 | P33: =CEILING(S33,100000) -> 3500000 | Q33: =CEILING(T33,100000) -> 3900000 | R33: =U33*$R$2 -> 3096774.2 | S33: =U33*$S$2 -> 3483871 | T33: =U33*$T$2 -> 3870967.7 | U33: =V33/DAY('kpi nhà thuốc'!$T$1) -> 3870967.7 | V33: 120000000 | W33: =SUMIF(data!$B:$B,B33,data!$C:$C) -> 346 | X33: =SUMIF(data!$B:$B,B33,data!$D:$D) -> 41488625 | Y33: =IF(W33>0,X33/W33,0) -> 119909.32 | Z33: =SUMIF(data!$B:$B,B33,data!$E:$E) -> 219 | AA33: =SUMIF(data!$B:$B,B33,data!$F:$F) -> 40219500 | AB33: =IF(Z33>0,AA33/Z33,0) -> 183650.68 | AC33: =W33+Z33 -> 565 | AD33: =X33+AA33 -> 81708125 | AE33: =IF(AC33>0,AD33/AC33,0) -> 144616.15
A34: Nguyễn Chí Thanh | B34: Nguyễn Thị Hồng Hạnh | C34: DSCD | D34: 104000 | E34: =AE34 -> 86997.442 | F34: {=IFERROR( ROUND( _xludf.LET( nt,$A34, nv,$B34, songay,DAY(EOMONTH($C$1,0)), doanhthungay,$I34, duan_nv,SUM_xlfn.IFS('Dự án T8'!$D:$D,'Dự án T8'!$A:$A,nt,'Dự án T8'!$B:$B,nv), duan_nt,SUM_xlfn.IFS('Dự án T8'!$D:$D,'Dự án T8'!$A:$A,nt), tyle,duan_nv/duan_nt, muc2_ngay,_xlfn.XLOOKUP(nt,'kpi nhà thuốc'!$B:$B,'kpi nhà thuốc'!$P:$P), muc3_ngay,_xlfn.XLOOKUP(nt,'kpi nhà thuốc'!$B:$B,'kpi nhà thuốc'!$T:$T), hangdiem1,_xlfn.XLOOKUP(nt,'kpi nhà thuốc'!$B:$B,'kpi nhà thuốc'!$I:$I), hangdiem2,_xlfn.XLOOKUP(nt,'kpi nhà thuốc'!$B:$B,'kpi nhà thuốc'!$N:$N), hangdiem3,_xlfn.XLOOKUP(nt,'kpi nhà thuốc'!$B:$B,'kpi nhà thuốc'!$R:$R), _xludf.SWITCH(TRUE, doanhthungay>=muc3_ngay,hangdiem3, doanhthungay>=muc2_ngay,hangdiem2, TRUE,hangdiem1 )/songay*tyle ), -3), 0)} -> 0 | G34: {=_xlfn.XLOOKUP(B34,'Dự án T8'!B:B,'Dự án T8'!D:D,0)} -> 798616.14 | H34: =Q34 -> 3900000 | I34: =(AD34/DAY($C$1)) -> 2544675.2 | J34: {=_xlfn.XLOOKUP(B34,'kpi nhà thuốc'!A:A,'kpi nhà thuốc'!F:F,(AD34/DAY($C$1))/U34)} -> 0.65737442 | K34: {=_xlfn.XLOOKUP( B34, 'kpi nhà thuốc'!A:A, 'kpi nhà thuốc'!G:G, IF( AND( OR(C34="DSXC",C34="DSCD"), G34>=F34),IF(AND(I34>=T34,E34>=D34),AD34*1.5%,IF(AND(I34>=T34,E34<D34),AD34*1.3%,IF(AND(I34>=S34,E34>=D34),AD34*1.3%,IF(AND(I34>=S34,E34<D34),AD34*1.1%,IF(AND(I34>=R34,E34>=D34),AD34*1.2%,IF(AND(I34>=R34,E34<D34),AD34*1%,"")))))),"" ) )} -> #NAME? | L34: =IF(C34="DSTV","", IF(J34<0.6, 0.8, 1)) -> 1 | M34: {=IFERROR( _xlfn.XLOOKUP( $A34&$B34, 'Dự án T8'!$A:$A&'Dự án T8'!$B:$B, 'Dự án T8'!$M:$M, 0 )*$L34, 0)} -> 0 | N34: =K34+M34*L34 -> #NAME? | O34: =CEILING(R34,100000) -> 3100000 | P34: =CEILING(S34,100000) -> 3500000 | Q34: =CEILING(T34,100000) -> 3900000 | R34: =U34*$R$2 -> 3096774.2 | S34: =U34*$S$2 -> 3483871 | T34: =U34*$T$2 -> 3870967.7 | U34: =V34/DAY('kpi nhà thuốc'!$T$1) -> 3870967.7 | V34: 120000000 | W34: =SUMIF(data!$B:$B,B34,data!$C:$C) -> 725 | X34: =SUMIF(data!$B:$B,B34,data!$D:$D) -> 59614300 | Y34: =IF(W34>0,X34/W34,0) -> 82226.621 | Z34: =SUMIF(data!$B:$B,B34,data!$E:$E) -> 94 | AA34: =SUMIF(data!$B:$B,B34,data!$F:$F) -> 11636605 | AB34: =IF(Z34>0,AA34/Z34,0) -> 123793.67 | AC34: =W34+Z34 -> 819 | AD34: =X34+AA34 -> 71250905 | AE34: =IF(AC34>0,AD34/AC34,0) -> 86997.442
A35: Nguyễn Chí Thanh | B35: Trần Hoàng Khánh | C35: DSCD | D35: 157000 | E35: =AE35 -> 88521.209 | F35: {=IFERROR( ROUND( _xludf.LET( nt,$A35, nv,$B35, songay,DAY(EOMONTH($C$1,0)), doanhthungay,$I35, duan_nv,SUM_xlfn.IFS('Dự án T8'!$D:$D,'Dự án T8'!$A:$A,nt,'Dự án T8'!$B:$B,nv), duan_nt,SUM_xlfn.IFS('Dự án T8'!$D:$D,'Dự án T8'!$A:$A,nt), tyle,duan_nv/duan_nt, muc2_ngay,_xlfn.XLOOKUP(nt,'kpi nhà thuốc'!$B:$B,'kpi nhà thuốc'!$P:$P), muc3_ngay,_xlfn.XLOOKUP(nt,'kpi nhà thuốc'!$B:$B,'kpi nhà thuốc'!$T:$T), hangdiem1,_xlfn.XLOOKUP(nt,'kpi nhà thuốc'!$B:$B,'kpi nhà thuốc'!$I:$I), hangdiem2,_xlfn.XLOOKUP(nt,'kpi nhà thuốc'!$B:$B,'kpi nhà thuốc'!$N:$N), hangdiem3,_xlfn.XLOOKUP(nt,'kpi nhà thuốc'!$B:$B,'kpi nhà thuốc'!$R:$R), _xludf.SWITCH(TRUE, doanhthungay>=muc3_ngay,hangdiem3, doanhthungay>=muc2_ngay,hangdiem2, TRUE,hangdiem1 )/songay*tyle ), -3), 0)} -> 0 | G35: {=_xlfn.XLOOKUP(B35,'Dự án T8'!B:B,'Dự án T8'!D:D,0)} -> 1047070.1 | H35: =Q35 -> 3900000 | I35: =(AD35/DAY($C$1)) -> 2902231.1 | J35: {=_xlfn.XLOOKUP(B35,'kpi nhà thuốc'!A:A,'kpi nhà thuốc'!F:F,(AD35/DAY($C$1))/U35)} -> 0.74974303 | K35: {=_xlfn.XLOOKUP( B35, 'kpi nhà thuốc'!A:A, 'kpi nhà thuốc'!G:G, IF( AND( OR(C35="DSXC",C35="DSCD"), G35>=F35),IF(AND(I35>=T35,E35>=D35),AD35*1.5%,IF(AND(I35>=T35,E35<D35),AD35*1.3%,IF(AND(I35>=S35,E35>=D35),AD35*1.3%,IF(AND(I35>=S35,E35<D35),AD35*1.1%,IF(AND(I35>=R35,E35>=D35),AD35*1.2%,IF(AND(I35>=R35,E35<D35),AD35*1%,"")))))),"" ) )} -> #NAME? | L35: =IF(C35="DSTV","", IF(J35<0.6, 0.8, 1)) -> 1 | M35: {=IFERROR( _xlfn.XLOOKUP( $A35&$B35, 'Dự án T8'!$A:$A&'Dự án T8'!$B:$B, 'Dự án T8'!$M:$M, 0 )*$L35, 0)} -> 500000 | N35: =K35+M35*L35 -> #NAME? | O35: =CEILING(R35,100000) -> 3100000 | P35: =CEILING(S35,100000) -> 3500000 | Q35: =CEILING(T35,100000) -> 3900000 | R35: =U35*$R$2 -> 3096774.2 | S35: =U35*$S$2 -> 3483871 | T35: =U35*$T$2 -> 3870967.7 | U35: =V35/DAY('kpi nhà thuốc'!$T$1) -> 3870967.7 | V35: 120000000 | W35: =SUMIF(data!$B:$B,B35,data!$C:$C) -> 737 | X35: =SUMIF(data!$B:$B,B35,data!$D:$D) -> 52913400 | Y35: =IF(W35>0,X35/W35,0) -> 71795.658 | Z35: =SUMIF(data!$B:$B,B35,data!$E:$E) -> 181 | AA35: =SUMIF(data!$B:$B,B35,data!$F:$F) -> 28349070 | AB35: =IF(Z35>0,AA35/Z35,0) -> 156624.7 | AC35: =W35+Z35 -> 918 | AD35: =X35+AA35 -> 81262470 | AE35: =IF(AC35>0,AD35/AC35,0) -> 88521.209
A36: Nguyễn Chí Thanh | B36: Lý Thục Mi | C36: DSXC (TV) | E36: =AE36 -> 0 | F36: {=IFERROR( ROUND( _xludf.LET( nt,$A36, nv,$B36, songay,DAY(EOMONTH($C$1,0)), doanhthungay,$I36, duan_nv,SUM_xlfn.IFS('Dự án T8'!$D:$D,'Dự án T8'!$A:$A,nt,'Dự án T8'!$B:$B,nv), duan_nt,SUM_xlfn.IFS('Dự án T8'!$D:$D,'Dự án T8'!$A:$A,nt), tyle,duan_nv/duan_nt, muc2_ngay,_xlfn.XLOOKUP(nt,'kpi nhà thuốc'!$B:$B,'kpi nhà thuốc'!$P:$P), muc3_ngay,_xlfn.XLOOKUP(nt,'kpi nhà thuốc'!$B:$B,'kpi nhà thuốc'!$T:$T), hangdiem1,_xlfn.XLOOKUP(nt,'kpi nhà thuốc'!$B:$B,'kpi nhà thuốc'!$I:$I), hangdiem2,_xlfn.XLOOKUP(nt,'kpi nhà thuốc'!$B:$B,'kpi nhà thuốc'!$N:$N), hangdiem3,_xlfn.XLOOKUP(nt,'kpi nhà thuốc'!$B:$B,'kpi nhà thuốc'!$R:$R), _xludf.SWITCH(TRUE, doanhthungay>=muc3_ngay,hangdiem3, doanhthungay>=muc2_ngay,hangdiem2, TRUE,hangdiem1 )/songay*tyle ), -3), 0)} -> 0 | G36: {=_xlfn.XLOOKUP(B36,'Dự án T8'!B:B,'Dự án T8'!D:D,0)} -> #N/A | H36: =Q36 -> 2300000 | I36: =(AD36/DAY($C$1)) -> 0 | J36: {=_xlfn.XLOOKUP(B36,'kpi nhà thuốc'!A:A,'kpi nhà thuốc'!F:F,(AD36/DAY($C$1))/U36)} -> 0 | K36: {=_xlfn.XLOOKUP( B36, 'kpi nhà thuốc'!A:A, 'kpi nhà thuốc'!G:G, IF( AND( OR(C36="DSXC",C36="DSCD"), G36>=F36),IF(AND(I36>=T36,E36>=D36),AD36*1.5%,IF(AND(I36>=T36,E36<D36),AD36*1.3%,IF(AND(I36>=S36,E36>=D36),AD36*1.3%,IF(AND(I36>=S36,E36<D36),AD36*1.1%,IF(AND(I36>=R36,E36>=D36),AD36*1.2%,IF(AND(I36>=R36,E36<D36),AD36*1%,"")))))),"" ) )} -> #N/A | L36: =IF(C36="DSTV","", IF(J36<0.6, 0.8, 1)) -> 0.8 | M36: {=IFERROR( _xlfn.XLOOKUP( $A36&$B36, 'Dự án T8'!$A:$A&'Dự án T8'!$B:$B, 'Dự án T8'!$M:$M, 0 )*$L36, 0)} -> 0 | N36: =K36+M36*L36 -> #N/A | O36: =CEILING(R36,100000) -> 1900000 | P36: =CEILING(S36,100000) -> 2100000 | Q36: =CEILING(T36,100000) -> 2300000 | R36: =U36*$R$2 -> 1806451.6 | S36: =U36*$S$2 -> 2032258.1 | T36: =U36*$T$2 -> 2258064.5 | U36: =V36/DAY('kpi nhà thuốc'!$T$1) -> 2258064.5 | V36: 70000000 | W36: =SUMIF(data!$B:$B,B36,data!$C:$C) -> 0 | X36: =SUMIF(data!$B:$B,B36,data!$D:$D) -> 0 | Y36: =IF(W36>0,X36/W36,0) -> 0 | Z36: =SUMIF(data!$B:$B,B36,data!$E:$E) -> 0 | AA36: =SUMIF(data!$B:$B,B36,data!$F:$F) -> 0 | AB36: =IF(Z36>0,AA36/Z36,0) -> 0 | AC36: =W36+Z36 -> 0 | AD36: =X36+AA36 -> 0 | AE36: =IF(AC36>0,AD36/AC36,0) -> 0
